Workbook
Name ContractValue: 'بيانات العقد'!$C$16
Name VOApproved: 'بيانات العقد'!$C$17
Name RevisedContract: 'بيانات العقد'!$C$18
Name AdvPct: 'بيانات العقد'!$C$20
Name AdvAmount: 'بيانات العقد'!$C$21
Name RecRate: 'بيانات العقد'!$C$23
Name RecStart: 'بيانات العقد'!$C$24
Name RecFull: 'بيانات العقد'!$C$25
Name RetPct: 'بيانات العقد'!$C$27
Name RetCap: 'بيانات العقد'!$C$29
Name VATPct: 'بيانات العقد'!$C$31
Name VATBeforeRet: 'بيانات العقد'!$C$32
Name WHTPct: 'بيانات العقد'!$C$33
Name StartDate: 'بيانات العقد'!$C$11
Name EndDate: 'بيانات العقد'!$C$13
Name L_Sections: 'بيانات العقد'!$F$6:$F$17
Name L_IPCStatus: 'بيانات العقد'!$G$6:$G$17
Name L_VOStatus: 'بيانات العقد'!$H$6:$H$17
Name L_TDType: 'بيانات العقد'!$I$6:$I$17

Sheet التعليمات
B1: 📘 ملف مستخلصات المشروع رقم 07 — 20 مستخلص مترابط
B2: =IF('بيانات العقد'!$C$5="","مشروع رقم 07 — أدخل بيانات العقد",'بيانات العقد'!$C$5&" | عقد رقم: "&'بيانات العقد'!$C$6)&" | المبالغ بـ "&'بيانات العقد'!$C$14
B3: ⚙ ابدأ ببيانات العقد | C3: 🧾 الانتقال إلى المستخلص الأول
B5: دليل الألوان
B6: إدخال يدوي | C6: خلايا صفراء بخط أزرق — هي الخلايا الوحيدة التي تُعدّل.
B7: معادلة محسوبة | C7: خط أسود — لا تكتب فوقها.
B8: ربط | C8: خط أخضر — قيمة مسحوبة من شيت آخر (مثل «السابق» من المستخلص الذي قبله).
B9: تنبيه | C9: تظليل أحمر: تجاوز الكمية التعاقدية، كود مكرر، تأخر عن البرنامج.
B11: خطوات العمل
B12: بيانات العقد | C12: أدخل بيانات المشروع والنسب التعاقدية (مرة واحدة).
B13: جدول الكميات | C13: أدخل بنود جدول الكميات والأسعار (حتى 100 بند).
B14: مستخلص 01 | C14: في كل مستخلص: أدخل الفترة والتواريخ والحالة والنسبة المخططة، ثم «الكمية الحالية» لكل بند، ورصيد المواد والغرامات والإفراج عن الضمان إن وجد، وبيانات التحصيل. «السابق» يُسحب آلياً من المستخلص الذي قبله، والتراكمي = السابق + الحالي.
B15: الأوامر التغييرية | C15: سجل الأوامر التغييرية واختر رقم المستخلص الذي تُدرج به.
B16: الاستقطاعات الفنية | C16: سجل الاستقطاعات الفنية برقم المستخلص، وحدد مستخلص الإفراج عند المعالجة.
B17: سجل المستخلصات | C17: يتجمع كل شيء آلياً في السجل، ومنه ينتقل إلى ملف التقارير المجمع لكل المشاريع.
B19: الربط مع ملف التقارير
B20: • | C20: اسم هذا الملف يجب أن يبقى «IPC_Project_07.xlsx» وفي نفس فولدر «Projects_Billing_Reports.xlsx».
B21: • | C21: بعد حفظ هذا الملف، افتح ملف التقارير واضغط «تمكين المحتوى / تحديث» ليتم سحب الأرقام الجديدة.
B22: • | C22: لا تحذف صفوفاً أو أعمدة ولا تغيّر أسماء الشيتات حتى لا ينقطع الربط.

Sheet بيانات العقد
B1: ⚙ بيانات العقد والإعدادات التعاقدية — مشروع رقم 07
B2: =IF('بيانات العقد'!$C$5="","مشروع رقم 07 — أدخل بيانات العقد",'بيانات العقد'!$C$5&" | عقد رقم: "&'بيانات العقد'!$C$6)&" | المبالغ بـ "&'بيانات العقد'!$C$14
B3: 🗂 سجل المستخلصات | C3: 📋 جدول الكميات | D3: 🔁 التغييرية | F3: ✂ الاستقطاعات | G3: 🧾 مستخلص 01
B4: البيان | C4: القيمة | D4: ملاحظات / الأساس التعاقدي | F4: القوائم المنسدلة (قابلة للتعديل)
B5: اسم المشروع | D5: يظهر في جميع الشيتات وفي ملف التقارير المجمع | F5: أقسام الأعمال | G5: حالة المستخلص | H5: حالة الأمر التغييري | I5: نوع الاستقطاع الفني
B6: رقم العقد | F6: أعمال الحفر والردم | G6: مسودة | H6: معتمد | I6: أعمال غير مطابقة
B7: صاحب العمل (المالك) | F7: الخرسانة العادية والمسلحة | G7: مقدم للاستشاري | H7: قيد الدراسة | I7: أعمال ناقصة
B8: الاستشاري / المهندس | F8: أعمال المباني | G8: تحت المراجعة | H8: مرفوض | I8: ملاحظات فنية
B9: المقاول | F9: أعمال العزل | G9: معتمد | I9: اختبارات غير مستكملة
B10: تاريخ توقيع العقد | F10: أعمال التشطيبات | G10: مرفوض | I10: مستندات غير مستكملة
B11: تاريخ بدء الأعمال (أمر المباشرة) | D11: بداية احتساب المدة الزمنية | F11: الأعمال الكهربائية | I11: أخرى
B12: مدة العقد (بالشهور) | F12: الأعمال الصحية
B13: تاريخ الانتهاء التعاقدي | C13: =IF(OR(C11="",C12=""),"",EDATE(C11,C12)-1) | D13: محسوب = البدء + المدة | F13: أعمال التكييف
B14: العملة | C14: جنيه مصري | F14: أعمال الموقع العام
B15: القيم التعاقدية
B16: قيمة العقد الأصلية | C16: ='جدول الكميات'!H106 | D16: مرتبطة تلقائياً بإجمالي جدول الكميات
B17: صافي الأوامر التغييرية المعتمدة | C17: =SUMIFS('الأوامر التغييرية'!$G$6:$G$55,'الأوامر التغييرية'!$H$6:$H$55,"معتمد") | D17: مرتبطة بشيت الأوامر التغييرية (المعتمدة فقط)
B18: قيمة العقد المعدلة | C18: =C16+C17 | D18: الأصلية + صافي التغييرية المعتمدة
B19: الدفعة المقدمة واستردادها
B20: نسبة الدفعة المقدمة | C20: 0.1 | D20: من قيمة العقد الأصلية
B21: قيمة الدفعة المقدمة | C21: =C16*C20 | D21: محسوبة
B22: تاريخ صرف الدفعة المقدمة
B23: نسبة الاسترداد من قيمة الأعمال | C23: 0.125 | D23: تُخصم من كل مستخلص كنسبة من (الأعمال المنفذة + التغييرية)
B24: بدء الاسترداد عند نسبة إنجاز | C24: 0 | D24: مثال FIDIC: يبدأ الاسترداد بعد تجاوز 10% من قيمة العقد
B25: استرداد كامل الرصيد عند نسبة إنجاز | C25: 0.8 | D25: عند بلوغ هذه النسبة يُسترد كامل الرصيد المتبقي
B26: ضمان الأعمال
B27: نسبة ضمان الأعمال (المحتجزات) | C27: 0.1 | D27: تُحتجز من إجمالي قيمة الأعمال التراكمية
B28: الحد الأقصى للضمان (% من العقد المعدل) | C28: 0.05 | D28: يتوقف الاحتجاز عند بلوغ الحد
B29: الحد الأقصى للضمان (قيمة) | C29: =C18*C28 | D29: محسوب
B30: الضرائب
B31: نسبة ضريبة القيمة المضافة | C31: 0.14 | D31: ضع 0% إن لم تكن مطبقة
B32: احتساب الضريبة قبل خصم الضمان؟ | C32: نعم | D32: نعم = وعاء الضريبة يشمل مبلغ الضمان المحتجز
B33: نسبة ضريبة الخصم من المنبع | C33: 0.01 | D33: تُحسب على صافي القيمة قبل خصم الضمان - ضع 0% إن لم تطبق

Sheet جدول الكميات
A1: 📋 جدول الكميات والأسعار التعاقدي (BOQ)
A2: =IF('بيانات العقد'!$C$5="","مشروع رقم 07 — أدخل بيانات العقد",'بيانات العقد'!$C$5&" | عقد رقم: "&'بيانات العقد'!$C$6)&" | المبالغ بـ "&'بيانات العقد'!$C$14
A3: 🗂 سجل المستخلصات | B3: ⚙ بيانات العقد | C3: 🔁 التغييرية | D3: ✂ الاستقطاعات | F3: 🧾 مستخلص 01
A4: أدخل بنود العقد في الخلايا الصفراء فقط (حتى 100 بند) — الإجمالي يغذي قيمة العقد وكل المستخلصات تلقائياً.
A5: م | B5: كود البند | C5: القسم | D5: وصف البند | E5: الوحدة | F5: الكمية التعاقدية | G5: سعر الوحدة | H5: الإجمالي | I5: الوزن النسبي
A6: =IF(B6="","",COUNTA($B$6:B6)) | H6: =F6*G6 | I6: =IF($H$106>0,H6/$H$106,0)
A7: =IF(B7="","",COUNTA($B$6:B7)) | H7: =F7*G7 | I7: =IF($H$106>0,H7/$H$106,0)
A8: =IF(B8="","",COUNTA($B$6:B8)) | H8: =F8*G8 | I8: =IF($H$106>0,H8/$H$106,0)
A9: =IF(B9="","",COUNTA($B$6:B9)) | H9: =F9*G9 | I9: =IF($H$106>0,H9/$H$106,0)
A10: =IF(B10="","",COUNTA($B$6:B10)) | H10: =F10*G10 | I10: =IF($H$106>0,H10/$H$106,0)
A11: =IF(B11="","",COUNTA($B$6:B11)) | H11: =F11*G11 | I11: =IF($H$106>0,H11/$H$106,0)
A12: =IF(B12="","",COUNTA($B$6:B12)) | H12: =F12*G12 | I12: =IF($H$106>0,H12/$H$106,0)
A13: =IF(B13="","",COUNTA($B$6:B13)) | H13: =F13*G13 | I13: =IF($H$106>0,H13/$H$106,0)
A14: =IF(B14="","",COUNTA($B$6:B14)) | H14: =F14*G14 | I14: =IF($H$106>0,H14/$H$106,0)
A15: =IF(B15="","",COUNTA($B$6:B15)) | H15: =F15*G15 | I15: =IF($H$106>0,H15/$H$106,0)
A16: =IF(B16="","",COUNTA($B$6:B16)) | H16: =F16*G16 | I16: =IF($H$106>0,H16/$H$106,0)
A17: =IF(B17="","",COUNTA($B$6:B17)) | H17: =F17*G17 | I17: =IF($H$106>0,H17/$H$106,0)
... A105: =IF(B105="","",COUNTA($B$6:B105)) | H105: =F105*G105 | I105: =IF($H$106>0,H105/$H$106,0)
A106: إجمالي قيمة العقد الأصلية | H106: =SUM(H6:H105) | I106: =SUM(I6:I105)

Sheet الأوامر التغييرية
A1: 🔁 سجل الأوامر التغييرية (Variation Orders)
A2: =IF('بيانات العقد'!$C$5="","مشروع رقم 07 — أدخل بيانات العقد",'بيانات العقد'!$C$5&" | عقد رقم: "&'بيانات العقد'!$C$6)&" | المبالغ بـ "&'بيانات العقد'!$C$14
A3: 🗂 سجل المستخلصات | B3: ⚙ بيانات العقد | C3: 📋 جدول الكميات | D3: ✂ الاستقطاعات | F3: 🧾 مستخلص 01
A4: «قيمة الأمر» تعدّل قيمة العقد عند الاعتماد — «القيمة المدرجة» تُصرف في المستخلص المحدد (للصرف على دفعات: كرر الأمر في سطر جديد بقيمة أمر = 0 ومستخلص مختلف).
A5: م | B5: رقم الأمر | C5: تاريخ الأمر | D5: وصف الأمر التغييري | E5: النوع | F5: قيمة الأمر | G5: الأثر على العقد (±) | H5: الحالة | I5: القيمة المدرجة بالمستخلص | J5: الأثر على المستخلص (±) | K5: رقم المستخلص المدرج به | L5: ملاحظات
A6: =IF(B6="","",COUNTA($B$6:B6)) | G6: =IF(E6="خصم",-1,1)*N(F6) | J6: =IF(E6="خصم",-1,1)*N(I6)
A7: =IF(B7="","",COUNTA($B$6:B7)) | G7: =IF(E7="خصم",-1,1)*N(F7) | J7: =IF(E7="خصم",-1,1)*N(I7)
A8: =IF(B8="","",COUNTA($B$6:B8)) | G8: =IF(E8="خصم",-1,1)*N(F8) | J8: =IF(E8="خصم",-1,1)*N(I8)
A9: =IF(B9="","",COUNTA($B$6:B9)) | G9: =IF(E9="خصم",-1,1)*N(F9) | J9: =IF(E9="خصم",-1,1)*N(I9)
A10: =IF(B10="","",COUNTA($B$6:B10)) | G10: =IF(E10="خصم",-1,1)*N(F10) | J10: =IF(E10="خصم",-1,1)*N(I10)
A11: =IF(B11="","",COUNTA($B$6:B11)) | G11: =IF(E11="خصم",-1,1)*N(F11) | J11: =IF(E11="خصم",-1,1)*N(I11)
A12: =IF(B12="","",COUNTA($B$6:B12)) | G12: =IF(E12="خصم",-1,1)*N(F12) | J12: =IF(E12="خصم",-1,1)*N(I12)
A13: =IF(B13="","",COUNTA($B$6:B13)) | G13: =IF(E13="خصم",-1,1)*N(F13) | J13: =IF(E13="خصم",-1,1)*N(I13)
A14: =IF(B14="","",COUNTA($B$6:B14)) | G14: =IF(E14="خصم",-1,1)*N(F14) | J14: =IF(E14="خصم",-1,1)*N(I14)
A15: =IF(B15="","",COUNTA($B$6:B15)) | G15: =IF(E15="خصم",-1,1)*N(F15) | J15: =IF(E15="خصم",-1,1)*N(I15)
A16: =IF(B16="","",COUNTA($B$6:B16)) | G16: =IF(E16="خصم",-1,1)*N(F16) | J16: =IF(E16="خصم",-1,1)*N(I16)
A17: =IF(B17="","",COUNTA($B$6:B17)) | G17: =IF(E17="خصم",-1,1)*N(F17) | J17: =IF(E17="خصم",-1,1)*N(I17)
... A55: =IF(B55="","",COUNTA($B$6:B55)) | G55: =IF(E55="خصم",-1,1)*N(F55) | J55: =IF(E55="خصم",-1,1)*N(I55)
A56: الإجمالي | F56: =SUM(F6:F55) | G56: =SUM(G6:G55) | H56: ="معتمد: "&COUNTIF(H6:H55,"معتمد") | I56: =SUM(I6:I55) | J56: =SUM(J6:J55)

Sheet الاستقطاعات الفنية
A1: ✂ سجل الاستقطاعات الفنية (Technical Deductions)
A2: =IF('بيانات العقد'!$C$5="","مشروع رقم 07 — أدخل بيانات العقد",'بيانات العقد'!$C$5&" | عقد رقم: "&'بيانات العقد'!$C$6)&" | المبالغ بـ "&'بيانات العقد'!$C$14
A3: 🗂 سجل المستخلصات | B3: ⚙ بيانات العقد | C3: 📋 جدول الكميات | D3: 🔁 التغييرية | F3: 🧾 مستخلص 01
A4: يُخصم المبلغ من المستخلص المحدد ويستمر محتجزاً تراكمياً حتى يتم الإفراج عنه في «مستخلص الإفراج».
A5: م | B5: رقم الاستقطاع | C5: التاريخ | D5: رقم المستخلص | E5: كود البند | F5: وصف البند (آلي) | G5: سبب الاستقطاع | H5: نوع الاستقطاع | I5: المبلغ المستقطع | J5: تم الإفراج؟ | K5: مستخلص الإفراج | L5: الرصيد المحتجز | M5: ملاحظات
A6: =IF(B6="","",COUNTA($B$6:B6)) | F6: =IF(E6="","",IFERROR(INDEX('جدول الكميات'!$D$6:$D$105,MATCH(E6,'جدول الكميات'!$B$6:$B$105,0)),"⚠ كود غير موجود")) | L6: =IF(J6="نعم",0,N(I6))
A7: =IF(B7="","",COUNTA($B$6:B7)) | F7: =IF(E7="","",IFERROR(INDEX('جدول الكميات'!$D$6:$D$105,MATCH(E7,'جدول الكميات'!$B$6:$B$105,0)),"⚠ كود غير موجود")) | L7: =IF(J7="نعم",0,N(I7))
A8: =IF(B8="","",COUNTA($B$6:B8)) | F8: =IF(E8="","",IFERROR(INDEX('جدول الكميات'!$D$6:$D$105,MATCH(E8,'جدول الكميات'!$B$6:$B$105,0)),"⚠ كود غير موجود")) | L8: =IF(J8="نعم",0,N(I8))
A9: =IF(B9="","",COUNTA($B$6:B9)) | F9: =IF(E9="","",IFERROR(INDEX('جدول الكميات'!$D$6:$D$105,MATCH(E9,'جدول الكميات'!$B$6:$B$105,0)),"⚠ كود غير موجود")) | L9: =IF(J9="نعم",0,N(I9))
A10: =IF(B10="","",COUNTA($B$6:B10)) | F10: =IF(E10="","",IFERROR(INDEX('جدول الكميات'!$D$6:$D$105,MATCH(E10,'جدول الكميات'!$B$6:$B$105,0)),"⚠ كود غير موجود")) | L10: =IF(J10="نعم",0,N(I10))
A11: =IF(B11="","",COUNTA($B$6:B11)) | F11: =IF(E11="","",IFERROR(INDEX('جدول الكميات'!$D$6:$D$105,MATCH(E11,'جدول الكميات'!$B$6:$B$105,0)),"⚠ كود غير موجود")) | L11: =IF(J11="نعم",0,N(I11))
A12: =IF(B12="","",COUNTA($B$6:B12)) | F12: =IF(E12="","",IFERROR(INDEX('جدول الكميات'!$D$6:$D$105,MATCH(E12,'جدول الكميات'!$B$6:$B$105,0)),"⚠ كود غير موجود")) | L12: =IF(J12="نعم",0,N(I12))
A13: =IF(B13="","",COUNTA($B$6:B13)) | F13: =IF(E13="","",IFERROR(INDEX('جدول الكميات'!$D$6:$D$105,MATCH(E13,'جدول الكميات'!$B$6:$B$105,0)),"⚠ كود غير موجود")) | L13: =IF(J13="نعم",0,N(I13))
A14: =IF(B14="","",COUNTA($B$6:B14)) | F14: =IF(E14="","",IFERROR(INDEX('جدول الكميات'!$D$6:$D$105,MATCH(E14,'جدول الكميات'!$B$6:$B$105,0)),"⚠ كود غير موجود")) | L14: =IF(J14="نعم",0,N(I14))
A15: =IF(B15="","",COUNTA($B$6:B15)) | F15: =IF(E15="","",IFERROR(INDEX('جدول الكميات'!$D$6:$D$105,MATCH(E15,'جدول الكميات'!$B$6:$B$105,0)),"⚠ كود غير موجود")) | L15: =IF(J15="نعم",0,N(I15))
A16: =IF(B16="","",COUNTA($B$6:B16)) | F16: =IF(E16="","",IFERROR(INDEX('جدول الكميات'!$D$6:$D$105,MATCH(E16,'جدول الكميات'!$B$6:$B$105,0)),"⚠ كود غير موجود")) | L16: =IF(J16="نعم",0,N(I16))
A17: =IF(B17="","",COUNTA($B$6:B17)) | F17: =IF(E17="","",IFERROR(INDEX('جدول الكميات'!$D$6:$D$105,MATCH(E17,'جدول الكميات'!$B$6:$B$105,0)),"⚠ كود غير موجود")) | L17: =IF(J17="نعم",0,N(I17))
... A105: =IF(B105="","",COUNTA($B$6:B105)) | F105: =IF(E105="","",IFERROR(INDEX('جدول الكميات'!$D$6:$D$105,MATCH(E105,'جدول الكميات'!$B$6:$B$105,0)),"⚠ كود غير موجود")) | L105: =IF(J105="نعم",0,N(I105))
A106: الإجمالي | I106: =SUM(I6:I105) | J106: =I106-L106 | L106: =SUM(L6:L105)

Sheet سجل المستخلصات
A1: 🗂 سجل المستخلصات — مشروع رقم 07 (يُحدَّث آلياً من شيتات المستخلصات ويغذي ملف التقارير)
A2: =IF('بيانات العقد'!$C$5="","مشروع رقم 07 — أدخل بيانات العقد",'بيانات العقد'!$C$5&" | عقد رقم: "&'بيانات العقد'!$C$6)&" | المبالغ بـ "&'بيانات العقد'!$C$14
B3: ⚙ بيانات العقد | D3: 📋 جدول الكميات | F3: 🔁 التغييرية | H3: ✂ الاستقطاعات | J3: 🧾 مستخلص 01 | AF3: آخر مستخلص: | AG3: =SUMPRODUCT(MAX((C6:C25<>"")*A6:A25))
A4: بيانات المستخلص | G4: قيمة الأعمال ونسب الإنجاز | O4: الاستقطاعات (تراكمي) | U4: صافي المستحق والضرائب | AA4: التحصيل
A5: رقم المستخلص | B5: الفترة من | C5: الفترة إلى | D5: تاريخ التقديم | E5: تاريخ الاعتماد | F5: حالة المستخلص | G5: قيمة الأعمال المنفذة التراكمية | H5: أعمال الفترة | I5: الأوامر التغييرية التراكمية | J5: رصيد المواد بالموقع | K5: إجمالي القيمة التراكمية | L5: نسبة الإنجاز الفعلية | M5: نسبة الإنجاز المخططة | N5: الانحراف عن المخطط | O5: استرداد الدفعة المقدمة التراكمي | P5: ضمان الأعمال المحتسب | Q5: المفرج عنه من الضمان | R5: صافي الضمان المحتجز | S5: الاستقطاعات الفنية المحتجزة | T5: الغرامات والخصومات التراكمية | U5: الصافي التراكمي قبل الضرائب | V5: ضريبة القيمة المضافة | W5: ضريبة الخصم من المنبع | X5: صافي المستحق التراكمي | Y5: المعتمد في المستخلصات السابقة | Z5: صافي المستحق للمستخلص الحالي | AA5: المبلغ المحصل | AB5: تاريخ التحصيل | AC5: المتبقي غير المحصل | AD5: مدة التحصيل (يوم) | AE5: حالة التحصيل
A6: 1 | B6: =IF(OR('مستخلص 01'!$J$7="",'مستخلص 01'!$J$6=""),"",'مستخلص 01'!$J$6) | C6: =IF('مستخلص 01'!$J$7="","",'مستخلص 01'!$J$7) | D6: =IF(OR('مستخلص 01'!$J$7="",'مستخلص 01'!$J$8=""),"",'مستخلص 01'!$J$8) | E6: =IF(OR('مستخلص 01'!$J$7="",'مستخلص 01'!$J$9=""),"",'مستخلص 01'!$J$9) | F6: =IF(OR('مستخلص 01'!$J$7="",'مستخلص 01'!$J$5=""),"",'مستخلص 01'!$J$5) | G6: =IF('مستخلص 01'!$J$7="","",'مستخلص 01'!$L$19) | H6: =IF('مستخلص 01'!$J$7="","",'مستخلص 01'!$J$19) | I6: =IF('مستخلص 01'!$J$7="","",'مستخلص 01'!$L$20) | J6: =IF('مستخلص 01'!$J$7="","",'مستخلص 01'!$L$21) | K6: =IF('مستخلص 01'!$J$7="","",'مستخلص 01'!$L$22) | L6: =IF('مستخلص 01'!$J$7="","",'مستخلص 01'!$L$6) | M6: =IF(OR('مستخلص 01'!$J$7="",'مستخلص 01'!$L$8=""),"",'مستخلص 01'!$L$8) | N6: =IF(OR('مستخلص 01'!$J$7="",M6=""),"",L6-M6) | O6: =IF('مستخلص 01'!$J$7="","",-'مستخلص 01'!$L$23) | P6: =IF('مستخلص 01'!$J$7="","",-'مستخلص 01'!$L$24) | Q6: =IF('مستخلص 01'!$J$7="","",'مستخلص 01'!$L$25) | R6: =IF('مستخلص 01'!$J$7="","",P6-Q6) | S6: =IF('مستخلص 01'!$J$7="","",-'مستخلص 01'!$L$26) | T6: =IF('مستخلص 01'!$J$7="","",-'مستخلص 01'!$L$27) | U6: =IF('مستخلص 01'!$J$7="","",'مستخلص 01'!$L$28) | V6: =IF('مستخلص 01'!$J$7="","",'مستخلص 01'!$L$29) | W6: =IF('مستخلص 01'!$J$7="","",-'مستخلص 01'!$L$30) | X6: =IF('مستخلص 01'!$J$7="","",'مستخلص 01'!$L$31) | Y6: =IF('مستخلص 01'!$J$7="","",'مستخلص 01'!$H$31) | Z6: =IF('مستخلص 01'!$J$7="","",'مستخلص 01'!$J$31) | AA6: =IF('مستخلص 01'!$J$7="","",N('مستخلص 01'!$E$15)) | AB6: =IF(OR('مستخلص 01'!$J$7="",'مستخلص 01'!$K$15=""),"",'مستخلص 01'!$K$15) | AC6: =IF('مستخلص 01'!$J$7="","",Z6-AA6) | AD6: =IF(OR(AB6="",E6=""),"",AB6-E6) | AE6: =IF('مستخلص 01'!$J$7="","",IF(N(AA6)=0,IF(E6="","⏳ بانتظار الاعتماد","✖ غير محصل"),IF(AC6<=1,"✔ محصل بالكامل","⚠ محصل جزئياً")))
A7: 2 | B7: =IF(OR('مستخلص 02'!$J$7="",'مستخلص 02'!$J$6=""),"",'مستخلص 02'!$J$6) | C7: =IF('مستخلص 02'!$J$7="","",'مستخلص 02'!$J$7) | D7: =IF(OR('مستخلص 02'!$J$7="",'مستخلص 02'!$J$8=""),"",'مستخلص 02'!$J$8) | E7: =IF(OR('مستخلص 02'!$J$7="",'مستخلص 02'!$J$9=""),"",'مستخلص 02'!$J$9) | F7: =IF(OR('مستخلص 02'!$J$7="",'مستخلص 02'!$J$5=""),"",'مستخلص 02'!$J$5) | G7: =IF('مستخلص 02'!$J$7="","",'مستخلص 02'!$L$19) | H7: =IF('مستخلص 02'!$J$7="","",'مستخلص 02'!$J$19) | I7: =IF('مستخلص 02'!$J$7="","",'مستخلص 02'!$L$20) | J7: =IF('مستخلص 02'!$J$7="","",'مستخلص 02'!$L$21) | K7: =IF('مستخلص 02'!$J$7="","",'مستخلص 02'!$L$22) | L7: =IF('مستخلص 02'!$J$7="","",'مستخلص 02'!$L$6) | M7: =IF(OR('مستخلص 02'!$J$7="",'مستخلص 02'!$L$8=""),"",'مستخلص 02'!$L$8) | N7: =IF(OR('مستخلص 02'!$J$7="",M7=""),"",L7-M7) | O7: =IF('مستخلص 02'!$J$7="","",-'مستخلص 02'!$L$23) | P7: =IF('مستخلص 02'!$J$7="","",-'مستخلص 02'!$L$24) | Q7: =IF('مستخلص 02'!$J$7="","",'مستخلص 02'!$L$25) | R7: =IF('مستخلص 02'!$J$7="","",P7-Q7) | S7: =IF('مستخلص 02'!$J$7="","",-'مستخلص 02'!$L$26) | T7: =IF('مستخلص 02'!$J$7="","",-'مستخلص 02'!$L$27) | U7: =IF('مستخلص 02'!$J$7="","",'مستخلص 02'!$L$28) | V7: =IF('مستخلص 02'!$J$7="","",'مستخلص 02'!$L$29) | W7: =IF('مستخلص 02'!$J$7="","",-'مستخلص 02'!$L$30) | X7: =IF('مستخلص 02'!$J$7="","",'مستخلص 02'!$L$31) | Y7: =IF('مستخلص 02'!$J$7="","",'مستخلص 02'!$H$31) | Z7: =IF('مستخلص 02'!$J$7="","",'مستخلص 02'!$J$31) | AA7: =IF('مستخلص 02'!$J$7="","",N('مستخلص 02'!$E$15)) | AB7: =IF(OR('مستخلص 02'!$J$7="",'مستخلص 02'!$K$15=""),"",'مستخلص 02'!$K$15) | AC7: =IF('مستخلص 02'!$J$7="","",Z7-AA7) | AD7: =IF(OR(AB7="",E7=""),"",AB7-E7) | AE7: =IF('مستخلص 02'!$J$7="","",IF(N(AA7)=0,IF(E7="","⏳ بانتظار الاعتماد","✖ غير محصل"),IF(AC7<=1,"✔ محصل بالكامل","⚠ محصل جزئياً")))
A8: 3 | B8: =IF(OR('مستخلص 03'!$J$7="",'مستخلص 03'!$J$6=""),"",'مستخلص 03'!$J$6) | C8: =IF('مستخلص 03'!$J$7="","",'مستخلص 03'!$J$7) | D8: =IF(OR('مستخلص 03'!$J$7="",'مستخلص 03'!$J$8=""),"",'مستخلص 03'!$J$8) | E8: =IF(OR('مستخلص 03'!$J$7="",'مستخلص 03'!$J$9=""),"",'مستخلص 03'!$J$9) | F8: =IF(OR('مستخلص 03'!$J$7="",'مستخلص 03'!$J$5=""),"",'مستخلص 03'!$J$5) | G8: =IF('مستخلص 03'!$J$7="","",'مستخلص 03'!$L$19) | H8: =IF('مستخلص 03'!$J$7="","",'مستخلص 03'!$J$19) | I8: =IF('مستخلص 03'!$J$7="","",'مستخلص 03'!$L$20) | J8: =IF('مستخلص 03'!$J$7="","",'مستخلص 03'!$L$21) | K8: =IF('مستخلص 03'!$J$7="","",'مستخلص 03'!$L$22) | L8: =IF('مستخلص 03'!$J$7="","",'مستخلص 03'!$L$6) | M8: =IF(OR('مستخلص 03'!$J$7="",'مستخلص 03'!$L$8=""),"",'مستخلص 03'!$L$8) | N8: =IF(OR('مستخلص 03'!$J$7="",M8=""),"",L8-M8) | O8: =IF('مستخلص 03'!$J$7="","",-'مستخلص 03'!$L$23) | P8: =IF('مستخلص 03'!$J$7="","",-'مستخلص 03'!$L$24) | Q8: =IF('مستخلص 03'!$J$7="","",'مستخلص 03'!$L$25) | R8: =IF('مستخلص 03'!$J$7="","",P8-Q8) | S8: =IF('مستخلص 03'!$J$7="","",-'مستخلص 03'!$L$26) | T8: =IF('مستخلص 03'!$J$7="","",-'مستخلص 03'!$L$27) | U8: =IF('مستخلص 03'!$J$7="","",'مستخلص 03'!$L$28) | V8: =IF('مستخلص 03'!$J$7="","",'مستخلص 03'!$L$29) | W8: =IF('مستخلص 03'!$J$7="","",-'مستخلص 03'!$L$30) | X8: =IF('مستخلص 03'!$J$7="","",'مستخلص 03'!$L$31) | Y8: =IF('مستخلص 03'!$J$7="","",'مستخلص 03'!$H$31) | Z8: =IF('مستخلص 03'!$J$7="","",'مستخلص 03'!$J$31) | AA8: =IF('مستخلص 03'!$J$7="","",N('مستخلص 03'!$E$15)) | AB8: =IF(OR('مستخلص 03'!$J$7="",'مستخلص 03'!$K$15=""),"",'مستخلص 03'!$K$15) | AC8: =IF('مستخلص 03'!$J$7="","",Z8-AA8) | AD8: =IF(OR(AB8="",E8=""),"",AB8-E8) | AE8: =IF('مستخلص 03'!$J$7="","",IF(N(AA8)=0,IF(E8="","⏳ بانتظار الاعتماد","✖ غير محصل"),IF(AC8<=1,"✔ محصل بالكامل","⚠ محصل جزئياً")))
A9: 4 | B9: =IF(OR('مستخلص 04'!$J$7="",'مستخلص 04'!$J$6=""),"",'مستخلص 04'!$J$6) | C9: =IF('مستخلص 04'!$J$7="","",'مستخلص 04'!$J$7) | D9: =IF(OR('مستخلص 04'!$J$7="",'مستخلص 04'!$J$8=""),"",'مستخلص 04'!$J$8) | E9: =IF(OR('مستخلص 04'!$J$7="",'مستخلص 04'!$J$9=""),"",'مستخلص 04'!$J$9) | F9: =IF(OR('مستخلص 04'!$J$7="",'مستخلص 04'!$J$5=""),"",'مستخلص 04'!$J$5) | G9: =IF('مستخلص 04'!$J$7="","",'مستخلص 04'!$L$19) | H9: =IF('مستخلص 04'!$J$7="","",'مستخلص 04'!$J$19) | I9: =IF('مستخلص 04'!$J$7="","",'مستخلص 04'!$L$20) | J9: =IF('مستخلص 04'!$J$7="","",'مستخلص 04'!$L$21) | K9: =IF('مستخلص 04'!$J$7="","",'مستخلص 04'!$L$22) | L9: =IF('مستخلص 04'!$J$7="","",'مستخلص 04'!$L$6) | M9: =IF(OR('مستخلص 04'!$J$7="",'مستخلص 04'!$L$8=""),"",'مستخلص 04'!$L$8) | N9: =IF(OR('مستخلص 04'!$J$7="",M9=""),"",L9-M9) | O9: =IF('مستخلص 04'!$J$7="","",-'مستخلص 04'!$L$23) | P9: =IF('مستخلص 04'!$J$7="","",-'مستخلص 04'!$L$24) | Q9: =IF('مستخلص 04'!$J$7="","",'مستخلص 04'!$L$25) | R9: =IF('مستخلص 04'!$J$7="","",P9-Q9) | S9: =IF('مستخلص 04'!$J$7="","",-'مستخلص 04'!$L$26) | T9: =IF('مستخلص 04'!$J$7="","",-'مستخلص 04'!$L$27) | U9: =IF('مستخلص 04'!$J$7="","",'مستخلص 04'!$L$28) | V9: =IF('مستخلص 04'!$J$7="","",'مستخلص 04'!$L$29) | W9: =IF('مستخلص 04'!$J$7="","",-'مستخلص 04'!$L$30) | X9: =IF('مستخلص 04'!$J$7="","",'مستخلص 04'!$L$31) | Y9: =IF('مستخلص 04'!$J$7="","",'مستخلص 04'!$H$31) | Z9: =IF('مستخلص 04'!$J$7="","",'مستخلص 04'!$J$31) | AA9: =IF('مستخلص 04'!$J$7="","",N('مستخلص 04'!$E$15)) | AB9: =IF(OR('مستخلص 04'!$J$7="",'مستخلص 04'!$K$15=""),"",'مستخلص 04'!$K$15) | AC9: =IF('مستخلص 04'!$J$7="","",Z9-AA9) | AD9: =IF(OR(AB9="",E9=""),"",AB9-E9) | AE9: =IF('مستخلص 04'!$J$7="","",IF(N(AA9)=0,IF(E9="","⏳ بانتظار الاعتماد","✖ غير محصل"),IF(AC9<=1,"✔ محصل بالكامل","⚠ محصل جزئياً")))
A10: 5 | B10: =IF(OR('مستخلص 05'!$J$7="",'مستخلص 05'!$J$6=""),"",'مستخلص 05'!$J$6) | C10: =IF('مستخلص 05'!$J$7="","",'مستخلص 05'!$J$7) | D10: =IF(OR('مستخلص 05'!$J$7="",'مستخلص 05'!$J$8=""),"",'مستخلص 05'!$J$8) | E10: =IF(OR('مستخلص 05'!$J$7="",'مستخلص 05'!$J$9=""),"",'مستخلص 05'!$J$9) | F10: =IF(OR('مستخلص 05'!$J$7="",'مستخلص 05'!$J$5=""),"",'مستخلص 05'!$J$5) | G10: =IF('مستخلص 05'!$J$7="","",'مستخلص 05'!$L$19) | H10: =IF('مستخلص 05'!$J$7="","",'مستخلص 05'!$J$19) | I10: =IF('مستخلص 05'!$J$7="","",'مستخلص 05'!$L$20) | J10: =IF('مستخلص 05'!$J$7="","",'مستخلص 05'!$L$21) | K10: =IF('مستخلص 05'!$J$7="","",'مستخلص 05'!$L$22) | L10: =IF('مستخلص 05'!$J$7="","",'مستخلص 05'!$L$6) | M10: =IF(OR('مستخلص 05'!$J$7="",'مستخلص 05'!$L$8=""),"",'مستخلص 05'!$L$8) | N10: =IF(OR('مستخلص 05'!$J$7="",M10=""),"",L10-M10) | O10: =IF('مستخلص 05'!$J$7="","",-'مستخلص 05'!$L$23) | P10: =IF('مستخلص 05'!$J$7="","",-'مستخلص 05'!$L$24) | Q10: =IF('مستخلص 05'!$J$7="","",'مستخلص 05'!$L$25) | R10: =IF('مستخلص 05'!$J$7="","",P10-Q10) | S10: =IF('مستخلص 05'!$J$7="","",-'مستخلص 05'!$L$26) | T10: =IF('مستخلص 05'!$J$7="","",-'مستخلص 05'!$L$27) | U10: =IF('مستخلص 05'!$J$7="","",'مستخلص 05'!$L$28) | V10: =IF('مستخلص 05'!$J$7="","",'مستخلص 05'!$L$29) | W10: =IF('مستخلص 05'!$J$7="","",-'مستخلص 05'!$L$30) | X10: =IF('مستخلص 05'!$J$7="","",'مستخلص 05'!$L$31) | Y10: =IF('مستخلص 05'!$J$7="","",'مستخلص 05'!$H$31) | Z10: =IF('مستخلص 05'!$J$7="","",'مستخلص 05'!$J$31) | AA10: =IF('مستخلص 05'!$J$7="","",N('مستخلص 05'!$E$15)) | AB10: =IF(OR('مستخلص 05'!$J$7="",'مستخلص 05'!$K$15=""),"",'مستخلص 05'!$K$15) | AC10: =IF('مستخلص 05'!$J$7="","",Z10-AA10) | AD10: =IF(OR(AB10="",E10=""),"",AB10-E10) | AE10: =IF('مستخلص 05'!$J$7="","",IF(N(AA10)=0,IF(E10="","⏳ بانتظار الاعتماد","✖ غير محصل"),IF(AC10<=1,"✔ محصل بالكامل","⚠ محصل جزئياً")))
A11: 6 | B11: =IF(OR('مستخلص 06'!$J$7="",'مستخلص 06'!$J$6=""),"",'مستخلص 06'!$J$6) | C11: =IF('مستخلص 06'!$J$7="","",'مستخلص 06'!$J$7) | D11: =IF(OR('مستخلص 06'!$J$7="",'مستخلص 06'!$J$8=""),"",'مستخلص 06'!$J$8) | E11: =IF(OR('مستخلص 06'!$J$7="",'مستخلص 06'!$J$9=""),"",'مستخلص 06'!$J$9) | F11: =IF(OR('مستخلص 06'!$J$7="",'مستخلص 06'!$J$5=""),"",'مستخلص 06'!$J$5) | G11: =IF('مستخلص 06'!$J$7="","",'مستخلص 06'!$L$19) | H11: =IF('مستخلص 06'!$J$7="","",'مستخلص 06'!$J$19) | I11: =IF('مستخلص 06'!$J$7="","",'مستخلص 06'!$L$20) | J11: =IF('مستخلص 06'!$J$7="","",'مستخلص 06'!$L$21) | K11: =IF('مستخلص 06'!$J$7="","",'مستخلص 06'!$L$22) | L11: =IF('مستخلص 06'!$J$7="","",'مستخلص 06'!$L$6) | M11: =IF(OR('مستخلص 06'!$J$7="",'مستخلص 06'!$L$8=""),"",'مستخلص 06'!$L$8) | N11: =IF(OR('مستخلص 06'!$J$7="",M11=""),"",L11-M11) | O11: =IF('مستخلص 06'!$J$7="","",-'مستخلص 06'!$L$23) | P11: =IF('مستخلص 06'!$J$7="","",-'مستخلص 06'!$L$24) | Q11: =IF('مستخلص 06'!$J$7="","",'مستخلص 06'!$L$25) | R11: =IF('مستخلص 06'!$J$7="","",P11-Q11) | S11: =IF('مستخلص 06'!$J$7="","",-'مستخلص 06'!$L$26) | T11: =IF('مستخلص 06'!$J$7="","",-'مستخلص 06'!$L$27) | U11: =IF('مستخلص 06'!$J$7="","",'مستخلص 06'!$L$28) | V11: =IF('مستخلص 06'!$J$7="","",'مستخلص 06'!$L$29) | W11: =IF('مستخلص 06'!$J$7="","",-'مستخلص 06'!$L$30) | X11: =IF('مستخلص 06'!$J$7="","",'مستخلص 06'!$L$31) | Y11: =IF('مستخلص 06'!$J$7="","",'مستخلص 06'!$H$31) | Z11: =IF('مستخلص 06'!$J$7="","",'مستخلص 06'!$J$31) | AA11: =IF('مستخلص 06'!$J$7="","",N('مستخلص 06'!$E$15)) | AB11: =IF(OR('مستخلص 06'!$J$7="",'مستخلص 06'!$K$15=""),"",'مستخلص 06'!$K$15) | AC11: =IF('مستخلص 06'!$J$7="","",Z11-AA11) | AD11: =IF(OR(AB11="",E11=""),"",AB11-E11) | AE11: =IF('مستخلص 06'!$J$7="","",IF(N(AA11)=0,IF(E11="","⏳ بانتظار الاعتماد","✖ غير محصل"),IF(AC11<=1,"✔ محصل بالكامل","⚠ محصل جزئياً")))
A12: 7 | B12: =IF(OR('مستخلص 07'!$J$7="",'مستخلص 07'!$J$6=""),"",'مستخلص 07'!$J$6) | C12: =IF('مستخلص 07'!$J$7="","",'مستخلص 07'!$J$7) | D12: =IF(OR('مستخلص 07'!$J$7="",'مستخلص 07'!$J$8=""),"",'مستخلص 07'!$J$8) | E12: =IF(OR('مستخلص 07'!$J$7="",'مستخلص 07'!$J$9=""),"",'مستخلص 07'!$J$9) | F12: =IF(OR('مستخلص 07'!$J$7="",'مستخلص 07'!$J$5=""),"",'مستخلص 07'!$J$5) | G12: =IF('مستخلص 07'!$J$7="","",'مستخلص 07'!$L$19) | H12: =IF('مستخلص 07'!$J$7="","",'مستخلص 07'!$J$19) | I12: =IF('مستخلص 07'!$J$7="","",'مستخلص 07'!$L$20) | J12: =IF('مستخلص 07'!$J$7="","",'مستخلص 07'!$L$21) | K12: =IF('مستخلص 07'!$J$7="","",'مستخلص 07'!$L$22) | L12: =IF('مستخلص 07'!$J$7="","",'مستخلص 07'!$L$6) | M12: =IF(OR('مستخلص 07'!$J$7="",'مستخلص 07'!$L$8=""),"",'مستخلص 07'!$L$8) | N12: =IF(OR('مستخلص 07'!$J$7="",M12=""),"",L12-M12) | O12: =IF('مستخلص 07'!$J$7="","",-'مستخلص 07'!$L$23) | P12: =IF('مستخلص 07'!$J$7="","",-'مستخلص 07'!$L$24) | Q12: =IF('مستخلص 07'!$J$7="","",'مستخلص 07'!$L$25) | R12: =IF('مستخلص 07'!$J$7="","",P12-Q12) | S12: =IF('مستخلص 07'!$J$7="","",-'مستخلص 07'!$L$26) | T12: =IF('مستخلص 07'!$J$7="","",-'مستخلص 07'!$L$27) | U12: =IF('مستخلص 07'!$J$7="","",'مستخلص 07'!$L$28) | V12: =IF('مستخلص 07'!$J$7="","",'مستخلص 07'!$L$29) | W12: =IF('مستخلص 07'!$J$7="","",-'مستخلص 07'!$L$30) | X12: =IF('مستخلص 07'!$J$7="","",'مستخلص 07'!$L$31) | Y12: =IF('مستخلص 07'!$J$7="","",'مستخلص 07'!$H$31) | Z12: =IF('مستخلص 07'!$J$7="","",'مستخلص 07'!$J$31) | AA12: =IF('مستخلص 07'!$J$7="","",N('مستخلص 07'!$E$15)) | AB12: =IF(OR('مستخلص 07'!$J$7="",'مستخلص 07'!$K$15=""),"",'مستخلص 07'!$K$15) | AC12: =IF('مستخلص 07'!$J$7="","",Z12-AA12) | AD12: =IF(OR(AB12="",E12=""),"",AB12-E12) | AE12: =IF('مستخلص 07'!$J$7="","",IF(N(AA12)=0,IF(E12="","⏳ بانتظار الاعتماد","✖ غير محصل"),IF(AC12<=1,"✔ محصل بالكامل","⚠ محصل جزئياً")))
A13: 8 | B13: =IF(OR('مستخلص 08'!$J$7="",'مستخلص 08'!$J$6=""),"",'مستخلص 08'!$J$6) | C13: =IF('مستخلص 08'!$J$7="","",'مستخلص 08'!$J$7) | D13: =IF(OR('مستخلص 08'!$J$7="",'مستخلص 08'!$J$8=""),"",'مستخلص 08'!$J$8) | E13: =IF(OR('مستخلص 08'!$J$7="",'مستخلص 08'!$J$9=""),"",'مستخلص 08'!$J$9) | F13: =IF(OR('مستخلص 08'!$J$7="",'مستخلص 08'!$J$5=""),"",'مستخلص 08'!$J$5) | G13: =IF('مستخلص 08'!$J$7="","",'مستخلص 08'!$L$19) | H13: =IF('مستخلص 08'!$J$7="","",'مستخلص 08'!$J$19) | I13: =IF('مستخلص 08'!$J$7="","",'مستخلص 08'!$L$20) | J13: =IF('مستخلص 08'!$J$7="","",'مستخلص 08'!$L$21) | K13: =IF('مستخلص 08'!$J$7="","",'مستخلص 08'!$L$22) | L13: =IF('مستخلص 08'!$J$7="","",'مستخلص 08'!$L$6) | M13: =IF(OR('مستخلص 08'!$J$7="",'مستخلص 08'!$L$8=""),"",'مستخلص 08'!$L$8) | N13: =IF(OR('مستخلص 08'!$J$7="",M13=""),"",L13-M13) | O13: =IF('مستخلص 08'!$J$7="","",-'مستخلص 08'!$L$23) | P13: =IF('مستخلص 08'!$J$7="","",-'مستخلص 08'!$L$24) | Q13: =IF('مستخلص 08'!$J$7="","",'مستخلص 08'!$L$25) | R13: =IF('مستخلص 08'!$J$7="","",P13-Q13) | S13: =IF('مستخلص 08'!$J$7="","",-'مستخلص 08'!$L$26) | T13: =IF('مستخلص 08'!$J$7="","",-'مستخلص 08'!$L$27) | U13: =IF('مستخلص 08'!$J$7="","",'مستخلص 08'!$L$28) | V13: =IF('مستخلص 08'!$J$7="","",'مستخلص 08'!$L$29) | W13: =IF('مستخلص 08'!$J$7="","",-'مستخلص 08'!$L$30) | X13: =IF('مستخلص 08'!$J$7="","",'مستخلص 08'!$L$31) | Y13: =IF('مستخلص 08'!$J$7="","",'مستخلص 08'!$H$31) | Z13: =IF('مستخلص 08'!$J$7="","",'مستخلص 08'!$J$31) | AA13: =IF('مستخلص 08'!$J$7="","",N('مستخلص 08'!$E$15)) | AB13: =IF(OR('مستخلص 08'!$J$7="",'مستخلص 08'!$K$15=""),"",'مستخلص 08'!$K$15) | AC13: =IF('مستخلص 08'!$J$7="","",Z13-AA13) | AD13: =IF(OR(AB13="",E13=""),"",AB13-E13) | AE13: =IF('مستخلص 08'!$J$7="","",IF(N(AA13)=0,IF(E13="","⏳ بانتظار الاعتماد","✖ غير محصل"),IF(AC13<=1,"✔ محصل بالكامل","⚠ محصل جزئياً")))
A14: 9 | B14: =IF(OR('مستخلص 09'!$J$7="",'مستخلص 09'!$J$6=""),"",'مستخلص 09'!$J$6) | C14: =IF('مستخلص 09'!$J$7="","",'مستخلص 09'!$J$7) | D14: =IF(OR('مستخلص 09'!$J$7="",'مستخلص 09'!$J$8=""),"",'مستخلص 09'!$J$8) | E14: =IF(OR('مستخلص 09'!$J$7="",'مستخلص 09'!$J$9=""),"",'مستخلص 09'!$J$9) | F14: =IF(OR('مستخلص 09'!$J$7="",'مستخلص 09'!$J$5=""),"",'مستخلص 09'!$J$5) | G14: =IF('مستخلص 09'!$J$7="","",'مستخلص 09'!$L$19) | H14: =IF('مستخلص 09'!$J$7="","",'مستخلص 09'!$J$19) | I14: =IF('مستخلص 09'!$J$7="","",'مستخلص 09'!$L$20) | J14: =IF('مستخلص 09'!$J$7="","",'مستخلص 09'!$L$21) | K14: =IF('مستخلص 09'!$J$7="","",'مستخلص 09'!$L$22) | L14: =IF('مستخلص 09'!$J$7="","",'مستخلص 09'!$L$6) | M14: =IF(OR('مستخلص 09'!$J$7="",'مستخلص 09'!$L$8=""),"",'مستخلص 09'!$L$8) | N14: =IF(OR('مستخلص 09'!$J$7="",M14=""),"",L14-M14) | O14: =IF('مستخلص 09'!$J$7="","",-'مستخلص 09'!$L$23) | P14: =IF('مستخلص 09'!$J$7="","",-'مستخلص 09'!$L$24) | Q14: =IF('مستخلص 09'!$J$7="","",'مستخلص 09'!$L$25) | R14: =IF('مستخلص 09'!$J$7="","",P14-Q14) | S14: =IF('مستخلص 09'!$J$7="","",-'مستخلص 09'!$L$26) | T14: =IF('مستخلص 09'!$J$7="","",-'مستخلص 09'!$L$27) | U14: =IF('مستخلص 09'!$J$7="","",'مستخلص 09'!$L$28) | V14: =IF('مستخلص 09'!$J$7="","",'مستخلص 09'!$L$29) | W14: =IF('مستخلص 09'!$J$7="","",-'مستخلص 09'!$L$30) | X14: =IF('مستخلص 09'!$J$7="","",'مستخلص 09'!$L$31) | Y14: =IF('مستخلص 09'!$J$7="","",'مستخلص 09'!$H$31) | Z14: =IF('مستخلص 09'!$J$7="","",'مستخلص 09'!$J$31) | AA14: =IF('مستخلص 09'!$J$7="","",N('مستخلص 09'!$E$15)) | AB14: =IF(OR('مستخلص 09'!$J$7="",'مستخلص 09'!$K$15=""),"",'مستخلص 09'!$K$15) | AC14: =IF('مستخلص 09'!$J$7="","",Z14-AA14) | AD14: =IF(OR(AB14="",E14=""),"",AB14-E14) | AE14: =IF('مستخلص 09'!$J$7="","",IF(N(AA14)=0,IF(E14="","⏳ بانتظار الاعتماد","✖ غير محصل"),IF(AC14<=1,"✔ محصل بالكامل","⚠ محصل جزئياً")))
A15: 10 | B15: =IF(OR('مستخلص 10'!$J$7="",'مستخلص 10'!$J$6=""),"",'مستخلص 10'!$J$6) | C15: =IF('مستخلص 10'!$J$7="","",'مستخلص 10'!$J$7) | D15: =IF(OR('مستخلص 10'!$J$7="",'مستخلص 10'!$J$8=""),"",'مستخلص 10'!$J$8) | E15: =IF(OR('مستخلص 10'!$J$7="",'مستخلص 10'!$J$9=""),"",'مستخلص 10'!$J$9) | F15: =IF(OR('مستخلص 10'!$J$7="",'مستخلص 10'!$J$5=""),"",'مستخلص 10'!$J$5) | G15: =IF('مستخلص 10'!$J$7="","",'مستخلص 10'!$L$19) | H15: =IF('مستخلص 10'!$J$7="","",'مستخلص 10'!$J$19) | I15: =IF('مستخلص 10'!$J$7="","",'مستخلص 10'!$L$20) | J15: =IF('مستخلص 10'!$J$7="","",'مستخلص 10'!$L$21) | K15: =IF('مستخلص 10'!$J$7="","",'مستخلص 10'!$L$22) | L15: =IF('مستخلص 10'!$J$7="","",'مستخلص 10'!$L$6) | M15: =IF(OR('مستخلص 10'!$J$7="",'مستخلص 10'!$L$8=""),"",'مستخلص 10'!$L$8) | N15: =IF(OR('مستخلص 10'!$J$7="",M15=""),"",L15-M15) | O15: =IF('مستخلص 10'!$J$7="","",-'مستخلص 10'!$L$23) | P15: =IF('مستخلص 10'!$J$7="","",-'مستخلص 10'!$L$24) | Q15: =IF('مستخلص 10'!$J$7="","",'مستخلص 10'!$L$25) | R15: =IF('مستخلص 10'!$J$7="","",P15-Q15) | S15: =IF('مستخلص 10'!$J$7="","",-'مستخلص 10'!$L$26) | T15: =IF('مستخلص 10'!$J$7="","",-'مستخلص 10'!$L$27) | U15: =IF('مستخلص 10'!$J$7="","",'مستخلص 10'!$L$28) | V15: =IF('مستخلص 10'!$J$7="","",'مستخلص 10'!$L$29) | W15: =IF('مستخلص 10'!$J$7="","",-'مستخلص 10'!$L$30) | X15: =IF('مستخلص 10'!$J$7="","",'مستخلص 10'!$L$31) | Y15: =IF('مستخلص 10'!$J$7="","",'مستخلص 10'!$H$31) | Z15: =IF('مستخلص 10'!$J$7="","",'مستخلص 10'!$J$31) | AA15: =IF('مستخلص 10'!$J$7="","",N('مستخلص 10'!$E$15)) | AB15: =IF(OR('مستخلص 10'!$J$7="",'مستخلص 10'!$K$15=""),"",'مستخلص 10'!$K$15) | AC15: =IF('مستخلص 10'!$J$7="","",Z15-AA15) | AD15: =IF(OR(AB15="",E15=""),"",AB15-E15) | AE15: =IF('مستخلص 10'!$J$7="","",IF(N(AA15)=0,IF(E15="","⏳ بانتظار الاعتماد","✖ غير محصل"),IF(AC15<=1,"✔ محصل بالكامل","⚠ محصل جزئياً")))
A16: 11 | B16: =IF(OR('مستخلص 11'!$J$7="",'مستخلص 11'!$J$6=""),"",'مستخلص 11'!$J$6) | C16: =IF('مستخلص 11'!$J$7="","",'مستخلص 11'!$J$7) | D16: =IF(OR('مستخلص 11'!$J$7="",'مستخلص 11'!$J$8=""),"",'مستخلص 11'!$J$8) | E16: =IF(OR('مستخلص 11'!$J$7="",'مستخلص 11'!$J$9=""),"",'مستخلص 11'!$J$9) | F16: =IF(OR('مستخلص 11'!$J$7="",'مستخلص 11'!$J$5=""),"",'مستخلص 11'!$J$5) | G16: =IF('مستخلص 11'!$J$7="","",'مستخلص 11'!$L$19) | H16: =IF('مستخلص 11'!$J$7="","",'مستخلص 11'!$J$19) | I16: =IF('مستخلص 11'!$J$7="","",'مستخلص 11'!$L$20) | J16: =IF('مستخلص 11'!$J$7="","",'مستخلص 11'!$L$21) | K16: =IF('مستخلص 11'!$J$7="","",'مستخلص 11'!$L$22) | L16: =IF('مستخلص 11'!$J$7="","",'مستخلص 11'!$L$6) | M16: =IF(OR('مستخلص 11'!$J$7="",'مستخلص 11'!$L$8=""),"",'مستخلص 11'!$L$8) | N16: =IF(OR('مستخلص 11'!$J$7="",M16=""),"",L16-M16) | O16: =IF('مستخلص 11'!$J$7="","",-'مستخلص 11'!$L$23) | P16: =IF('مستخلص 11'!$J$7="","",-'مستخلص 11'!$L$24) | Q16: =IF('مستخلص 11'!$J$7="","",'مستخلص 11'!$L$25) | R16: =IF('مستخلص 11'!$J$7="","",P16-Q16) | S16: =IF('مستخلص 11'!$J$7="","",-'مستخلص 11'!$L$26) | T16: =IF('مستخلص 11'!$J$7="","",-'مستخلص 11'!$L$27) | U16: =IF('مستخلص 11'!$J$7="","",'مستخلص 11'!$L$28) | V16: =IF('مستخلص 11'!$J$7="","",'مستخلص 11'!$L$29) | W16: =IF('مستخلص 11'!$J$7="","",-'مستخلص 11'!$L$30) | X16: =IF('مستخلص 11'!$J$7="","",'مستخلص 11'!$L$31) | Y16: =IF('مستخلص 11'!$J$7="","",'مستخلص 11'!$H$31) | Z16: =IF('مستخلص 11'!$J$7="","",'مستخلص 11'!$J$31) | AA16: =IF('مستخلص 11'!$J$7="","",N('مستخلص 11'!$E$15)) | AB16: =IF(OR('مستخلص 11'!$J$7="",'مستخلص 11'!$K$15=""),"",'مستخلص 11'!$K$15) | AC16: =IF('مستخلص 11'!$J$7="","",Z16-AA16) | AD16: =IF(OR(AB16="",E16=""),"",AB16-E16) | AE16: =IF('مستخلص 11'!$J$7="","",IF(N(AA16)=0,IF(E16="","⏳ بانتظار الاعتماد","✖ غير محصل"),IF(AC16<=1,"✔ محصل بالكامل","⚠ محصل جزئياً")))
A17: 12 | B17: =IF(OR('مستخلص 12'!$J$7="",'مستخلص 12'!$J$6=""),"",'مستخلص 12'!$J$6) | C17: =IF('مستخلص 12'!$J$7="","",'مستخلص 12'!$J$7) | D17: =IF(OR('مستخلص 12'!$J$7="",'مستخلص 12'!$J$8=""),"",'مستخلص 12'!$J$8) | E17: =IF(OR('مستخلص 12'!$J$7="",'مستخلص 12'!$J$9=""),"",'مستخلص 12'!$J$9) | F17: =IF(OR('مستخلص 12'!$J$7="",'مستخلص 12'!$J$5=""),"",'مستخلص 12'!$J$5) | G17: =IF('مستخلص 12'!$J$7="","",'مستخلص 12'!$L$19) | H17: =IF('مستخلص 12'!$J$7="","",'مستخلص 12'!$J$19) | I17: =IF('مستخلص 12'!$J$7="","",'مستخلص 12'!$L$20) | J17: =IF('مستخلص 12'!$J$7="","",'مستخلص 12'!$L$21) | K17: =IF('مستخلص 12'!$J$7="","",'مستخلص 12'!$L$22) | L17: =IF('مستخلص 12'!$J$7="","",'مستخلص 12'!$L$6) | M17: =IF(OR('مستخلص 12'!$J$7="",'مستخلص 12'!$L$8=""),"",'مستخلص 12'!$L$8) | N17: =IF(OR('مستخلص 12'!$J$7="",M17=""),"",L17-M17) | O17: =IF('مستخلص 12'!$J$7="","",-'مستخلص 12'!$L$23) | P17: =IF('مستخلص 12'!$J$7="","",-'مستخلص 12'!$L$24) | Q17: =IF('مستخلص 12'!$J$7="","",'مستخلص 12'!$L$25) | R17: =IF('مستخلص 12'!$J$7="","",P17-Q17) | S17: =IF('مستخلص 12'!$J$7="","",-'مستخلص 12'!$L$26) | T17: =IF('مستخلص 12'!$J$7="","",-'مستخلص 12'!$L$27) | U17: =IF('مستخلص 12'!$J$7="","",'مستخلص 12'!$L$28) | V17: =IF('مستخلص 12'!$J$7="","",'مستخلص 12'!$L$29) | W17: =IF('مستخلص 12'!$J$7="","",-'مستخلص 12'!$L$30) | X17: =IF('مستخلص 12'!$J$7="","",'مستخلص 12'!$L$31) | Y17: =IF('مستخلص 12'!$J$7="","",'مستخلص 12'!$H$31) | Z17: =IF('مستخلص 12'!$J$7="","",'مستخلص 12'!$J$31) | AA17: =IF('مستخلص 12'!$J$7="","",N('مستخلص 12'!$E$15)) | AB17: =IF(OR('مستخلص 12'!$J$7="",'مستخلص 12'!$K$15=""),"",'مستخلص 12'!$K$15) | AC17: =IF('مستخلص 12'!$J$7="","",Z17-AA17) | AD17: =IF(OR(AB17="",E17=""),"",AB17-E17) | AE17: =IF('مستخلص 12'!$J$7="","",IF(N(AA17)=0,IF(E17="","⏳ بانتظار الاعتماد","✖ غير محصل"),IF(AC17<=1,"✔ محصل بالكامل","⚠ محصل جزئياً")))
A18: 13 | B18: =IF(OR('مستخلص 13'!$J$7="",'مستخلص 13'!$J$6=""),"",'مستخلص 13'!$J$6) | C18: =IF('مستخلص 13'!$J$7="","",'مستخلص 13'!$J$7) | D18: =IF(OR('مستخلص 13'!$J$7="",'مستخلص 13'!$J$8=""),"",'مستخلص 13'!$J$8) | E18: =IF(OR('مستخلص 13'!$J$7="",'مستخلص 13'!$J$9=""),"",'مستخلص 13'!$J$9) | F18: =IF(OR('مستخلص 13'!$J$7="",'مستخلص 13'!$J$5=""),"",'مستخلص 13'!$J$5) | G18: =IF('مستخلص 13'!$J$7="","",'مستخلص 13'!$L$19) | H18: =IF('مستخلص 13'!$J$7="","",'مستخلص 13'!$J$19) | I18: =IF('مستخلص 13'!$J$7="","",'مستخلص 13'!$L$20) | J18: =IF('مستخلص 13'!$J$7="","",'مستخلص 13'!$L$21) | K18: =IF('مستخلص 13'!$J$7="","",'مستخلص 13'!$L$22) | L18: =IF('مستخلص 13'!$J$7="","",'مستخلص 13'!$L$6) | M18: =IF(OR('مستخلص 13'!$J$7="",'مستخلص 13'!$L$8=""),"",'مستخلص 13'!$L$8) | N18: =IF(OR('مستخلص 13'!$J$7="",M18=""),"",L18-M18) | O18: =IF('مستخلص 13'!$J$7="","",-'مستخلص 13'!$L$23) | P18: =IF('مستخلص 13'!$J$7="","",-'مستخلص 13'!$L$24) | Q18: =IF('مستخلص 13'!$J$7="","",'مستخلص 13'!$L$25) | R18: =IF('مستخلص 13'!$J$7="","",P18-Q18) | S18: =IF('مستخلص 13'!$J$7="","",-'مستخلص 13'!$L$26) | T18: =IF('مستخلص 13'!$J$7="","",-'مستخلص 13'!$L$27) | U18: =IF('مستخلص 13'!$J$7="","",'مستخلص 13'!$L$28) | V18: =IF('مستخلص 13'!$J$7="","",'مستخلص 13'!$L$29) | W18: =IF('مستخلص 13'!$J$7="","",-'مستخلص 13'!$L$30) | X18: =IF('مستخلص 13'!$J$7="","",'مستخلص 13'!$L$31) | Y18: =IF('مستخلص 13'!$J$7="","",'مستخلص 13'!$H$31) | Z18: =IF('مستخلص 13'!$J$7="","",'مستخلص 13'!$J$31) | AA18: =IF('مستخلص 13'!$J$7="","",N('مستخلص 13'!$E$15)) | AB18: =IF(OR('مستخلص 13'!$J$7="",'مستخلص 13'!$K$15=""),"",'مستخلص 13'!$K$15) | AC18: =IF('مستخلص 13'!$J$7="","",Z18-AA18) | AD18: =IF(OR(AB18="",E18=""),"",AB18-E18) | AE18: =IF('مستخلص 13'!$J$7="","",IF(N(AA18)=0,IF(E18="","⏳ بانتظار الاعتماد","✖ غير محصل"),IF(AC18<=1,"✔ محصل بالكامل","⚠ محصل جزئياً")))
A19: 14 | B19: =IF(OR('مستخلص 14'!$J$7="",'مستخلص 14'!$J$6=""),"",'مستخلص 14'!$J$6) | C19: =IF('مستخلص 14'!$J$7="","",'مستخلص 14'!$J$7) | D19: =IF(OR('مستخلص 14'!$J$7="",'مستخلص 14'!$J$8=""),"",'مستخلص 14'!$J$8) | E19: =IF(OR('مستخلص 14'!$J$7="",'مستخلص 14'!$J$9=""),"",'مستخلص 14'!$J$9) | F19: =IF(OR('مستخلص 14'!$J$7="",'مستخلص 14'!$J$5=""),"",'مستخلص 14'!$J$5) | G19: =IF('مستخلص 14'!$J$7="","",'مستخلص 14'!$L$19) | H19: =IF('مستخلص 14'!$J$7="","",'مستخلص 14'!$J$19) | I19: =IF('مستخلص 14'!$J$7="","",'مستخلص 14'!$L$20) | J19: =IF('مستخلص 14'!$J$7="","",'مستخلص 14'!$L$21) | K19: =IF('مستخلص 14'!$J$7="","",'مستخلص 14'!$L$22) | L19: =IF('مستخلص 14'!$J$7="","",'مستخلص 14'!$L$6) | M19: =IF(OR('مستخلص 14'!$J$7="",'مستخلص 14'!$L$8=""),"",'مستخلص 14'!$L$8) | N19: =IF(OR('مستخلص 14'!$J$7="",M19=""),"",L19-M19) | O19: =IF('مستخلص 14'!$J$7="","",-'مستخلص 14'!$L$23) | P19: =IF('مستخلص 14'!$J$7="","",-'مستخلص 14'!$L$24) | Q19: =IF('مستخلص 14'!$J$7="","",'مستخلص 14'!$L$25) | R19: =IF('مستخلص 14'!$J$7="","",P19-Q19) | S19: =IF('مستخلص 14'!$J$7="","",-'مستخلص 14'!$L$26) | T19: =IF('مستخلص 14'!$J$7="","",-'مستخلص 14'!$L$27) | U19: =IF('مستخلص 14'!$J$7="","",'مستخلص 14'!$L$28) | V19: =IF('مستخلص 14'!$J$7="","",'مستخلص 14'!$L$29) | W19: =IF('مستخلص 14'!$J$7="","",-'مستخلص 14'!$L$30) | X19: =IF('مستخلص 14'!$J$7="","",'مستخلص 14'!$L$31) | Y19: =IF('مستخلص 14'!$J$7="","",'مستخلص 14'!$H$31) | Z19: =IF('مستخلص 14'!$J$7="","",'مستخلص 14'!$J$31) | AA19: =IF('مستخلص 14'!$J$7="","",N('مستخلص 14'!$E$15)) | AB19: =IF(OR('مستخلص 14'!$J$7="",'مستخلص 14'!$K$15=""),"",'مستخلص 14'!$K$15) | AC19: =IF('مستخلص 14'!$J$7="","",Z19-AA19) | AD19: =IF(OR(AB19="",E19=""),"",AB19-E19) | AE19: =IF('مستخلص 14'!$J$7="","",IF(N(AA19)=0,IF(E19="","⏳ بانتظار الاعتماد","✖ غير محصل"),IF(AC19<=1,"✔ محصل بالكامل","⚠ محصل جزئياً")))
A20: 15 | B20: =IF(OR('مستخلص 15'!$J$7="",'مستخلص 15'!$J$6=""),"",'مستخلص 15'!$J$6) | C20: =IF('مستخلص 15'!$J$7="","",'مستخلص 15'!$J$7) | D20: =IF(OR('مستخلص 15'!$J$7="",'مستخلص 15'!$J$8=""),"",'مستخلص 15'!$J$8) | E20: =IF(OR('مستخلص 15'!$J$7="",'مستخلص 15'!$J$9=""),"",'مستخلص 15'!$J$9) | F20: =IF(OR('مستخلص 15'!$J$7="",'مستخلص 15'!$J$5=""),"",'مستخلص 15'!$J$5) | G20: =IF('مستخلص 15'!$J$7="","",'مستخلص 15'!$L$19) | H20: =IF('مستخلص 15'!$J$7="","",'مستخلص 15'!$J$19) | I20: =IF('مستخلص 15'!$J$7="","",'مستخلص 15'!$L$20) | J20: =IF('مستخلص 15'!$J$7="","",'مستخلص 15'!$L$21) | K20: =IF('مستخلص 15'!$J$7="","",'مستخلص 15'!$L$22) | L20: =IF('مستخلص 15'!$J$7="","",'مستخلص 15'!$L$6) | M20: =IF(OR('مستخلص 15'!$J$7="",'مستخلص 15'!$L$8=""),"",'مستخلص 15'!$L$8) | N20: =IF(OR('مستخلص 15'!$J$7="",M20=""),"",L20-M20) | O20: =IF('مستخلص 15'!$J$7="","",-'مستخلص 15'!$L$23) | P20: =IF('مستخلص 15'!$J$7="","",-'مستخلص 15'!$L$24) | Q20: =IF('مستخلص 15'!$J$7="","",'مستخلص 15'!$L$25) | R20: =IF('مستخلص 15'!$J$7="","",P20-Q20) | S20: =IF('مستخلص 15'!$J$7="","",-'مستخلص 15'!$L$26) | T20: =IF('مستخلص 15'!$J$7="","",-'مستخلص 15'!$L$27) | U20: =IF('مستخلص 15'!$J$7="","",'مستخلص 15'!$L$28) | V20: =IF('مستخلص 15'!$J$7="","",'مستخلص 15'!$L$29) | W20: =IF('مستخلص 15'!$J$7="","",-'مستخلص 15'!$L$30) | X20: =IF('مستخلص 15'!$J$7="","",'مستخلص 15'!$L$31) | Y20: =IF('مستخلص 15'!$J$7="","",'مستخلص 15'!$H$31) | Z20: =IF('مستخلص 15'!$J$7="","",'مستخلص 15'!$J$31) | AA20: =IF('مستخلص 15'!$J$7="","",N('مستخلص 15'!$E$15)) | AB20: =IF(OR('مستخلص 15'!$J$7="",'مستخلص 15'!$K$15=""),"",'مستخلص 15'!$K$15) | AC20: =IF('مستخلص 15'!$J$7="","",Z20-AA20) | AD20: =IF(OR(AB20="",E20=""),"",AB20-E20) | AE20: =IF('مستخلص 15'!$J$7="","",IF(N(AA20)=0,IF(E20="","⏳ بانتظار الاعتماد","✖ غير محصل"),IF(AC20<=1,"✔ محصل بالكامل","⚠ محصل جزئياً")))
A21: 16 | B21: =IF(OR('مستخلص 16'!$J$7="",'مستخلص 16'!$J$6=""),"",'مستخلص 16'!$J$6) | C21: =IF('مستخلص 16'!$J$7="","",'مستخلص 16'!$J$7) | D21: =IF(OR('مستخلص 16'!$J$7="",'مستخلص 16'!$J$8=""),"",'مستخلص 16'!$J$8) | E21: =IF(OR('مستخلص 16'!$J$7="",'مستخلص 16'!$J$9=""),"",'مستخلص 16'!$J$9) | F21: =IF(OR('مستخلص 16'!$J$7="",'مستخلص 16'!$J$5=""),"",'مستخلص 16'!$J$5) | G21: =IF('مستخلص 16'!$J$7="","",'مستخلص 16'!$L$19) | H21: =IF('مستخلص 16'!$J$7="","",'مستخلص 16'!$J$19) | I21: =IF('مستخلص 16'!$J$7="","",'مستخلص 16'!$L$20) | J21: =IF('مستخلص 16'!$J$7="","",'مستخلص 16'!$L$21) | K21: =IF('مستخلص 16'!$J$7="","",'مستخلص 16'!$L$22) | L21: =IF('مستخلص 16'!$J$7="","",'مستخلص 16'!$L$6) | M21: =IF(OR('مستخلص 16'!$J$7="",'مستخلص 16'!$L$8=""),"",'مستخلص 16'!$L$8) | N21: =IF(OR('مستخلص 16'!$J$7="",M21=""),"",L21-M21) | O21: =IF('مستخلص 16'!$J$7="","",-'مستخلص 16'!$L$23) | P21: =IF('مستخلص 16'!$J$7="","",-'مستخلص 16'!$L$24) | Q21: =IF('مستخلص 16'!$J$7="","",'مستخلص 16'!$L$25) | R21: =IF('مستخلص 16'!$J$7="","",P21-Q21) | S21: =IF('مستخلص 16'!$J$7="","",-'مستخلص 16'!$L$26) | T21: =IF('مستخلص 16'!$J$7="","",-'مستخلص 16'!$L$27) | U21: =IF('مستخلص 16'!$J$7="","",'مستخلص 16'!$L$28) | V21: =IF('مستخلص 16'!$J$7="","",'مستخلص 16'!$L$29) | W21: =IF('مستخلص 16'!$J$7="","",-'مستخلص 16'!$L$30) | X21: =IF('مستخلص 16'!$J$7="","",'مستخلص 16'!$L$31) | Y21: =IF('مستخلص 16'!$J$7="","",'مستخلص 16'!$H$31) | Z21: =IF('مستخلص 16'!$J$7="","",'مستخلص 16'!$J$31) | AA21: =IF('مستخلص 16'!$J$7="","",N('مستخلص 16'!$E$15)) | AB21: =IF(OR('مستخلص 16'!$J$7="",'مستخلص 16'!$K$15=""),"",'مستخلص 16'!$K$15) | AC21: =IF('مستخلص 16'!$J$7="","",Z21-AA21) | AD21: =IF(OR(AB21="",E21=""),"",AB21-E21) | AE21: =IF('مستخلص 16'!$J$7="","",IF(N(AA21)=0,IF(E21="","⏳ بانتظار الاعتماد","✖ غير محصل"),IF(AC21<=1,"✔ محصل بالكامل","⚠ محصل جزئياً")))
A22: 17 | B22: =IF(OR('مستخلص 17'!$J$7="",'مستخلص 17'!$J$6=""),"",'مستخلص 17'!$J$6) | C22: =IF('مستخلص 17'!$J$7="","",'مستخلص 17'!$J$7) | D22: =IF(OR('مستخلص 17'!$J$7="",'مستخلص 17'!$J$8=""),"",'مستخلص 17'!$J$8) | E22: =IF(OR('مستخلص 17'!$J$7="",'مستخلص 17'!$J$9=""),"",'مستخلص 17'!$J$9) | F22: =IF(OR('مستخلص 17'!$J$7="",'مستخلص 17'!$J$5=""),"",'مستخلص 17'!$J$5) | G22: =IF('مستخلص 17'!$J$7="","",'مستخلص 17'!$L$19) | H22: =IF('مستخلص 17'!$J$7="","",'مستخلص 17'!$J$19) | I22: =IF('مستخلص 17'!$J$7="","",'مستخلص 17'!$L$20) | J22: =IF('مستخلص 17'!$J$7="","",'مستخلص 17'!$L$21) | K22: =IF('مستخلص 17'!$J$7="","",'مستخلص 17'!$L$22) | L22: =IF('مستخلص 17'!$J$7="","",'مستخلص 17'!$L$6) | M22: =IF(OR('مستخلص 17'!$J$7="",'مستخلص 17'!$L$8=""),"",'مستخلص 17'!$L$8) | N22: =IF(OR('مستخلص 17'!$J$7="",M22=""),"",L22-M22) | O22: =IF('مستخلص 17'!$J$7="","",-'مستخلص 17'!$L$23) | P22: =IF('مستخلص 17'!$J$7="","",-'مستخلص 17'!$L$24) | Q22: =IF('مستخلص 17'!$J$7="","",'مستخلص 17'!$L$25) | R22: =IF('مستخلص 17'!$J$7="","",P22-Q22) | S22: =IF('مستخلص 17'!$J$7="","",-'مستخلص 17'!$L$26) | T22: =IF('مستخلص 17'!$J$7="","",-'مستخلص 17'!$L$27) | U22: =IF('مستخلص 17'!$J$7="","",'مستخلص 17'!$L$28) | V22: =IF('مستخلص 17'!$J$7="","",'مستخلص 17'!$L$29) | W22: =IF('مستخلص 17'!$J$7="","",-'مستخلص 17'!$L$30) | X22: =IF('مستخلص 17'!$J$7="","",'مستخلص 17'!$L$31) | Y22: =IF('مستخلص 17'!$J$7="","",'مستخلص 17'!$H$31) | Z22: =IF('مستخلص 17'!$J$7="","",'مستخلص 17'!$J$31) | AA22: =IF('مستخلص 17'!$J$7="","",N('مستخلص 17'!$E$15)) | AB22: =IF(OR('مستخلص 17'!$J$7="",'مستخلص 17'!$K$15=""),"",'مستخلص 17'!$K$15) | AC22: =IF('مستخلص 17'!$J$7="","",Z22-AA22) | AD22: =IF(OR(AB22="",E22=""),"",AB22-E22) | AE22: =IF('مستخلص 17'!$J$7="","",IF(N(AA22)=0,IF(E22="","⏳ بانتظار الاعتماد","✖ غير محصل"),IF(AC22<=1,"✔ محصل بالكامل","⚠ محصل جزئياً")))
A23: 18 | B23: =IF(OR('مستخلص 18'!$J$7="",'مستخلص 18'!$J$6=""),"",'مستخلص 18'!$J$6) | C23: =IF('مستخلص 18'!$J$7="","",'مستخلص 18'!$J$7) | D23: =IF(OR('مستخلص 18'!$J$7="",'مستخلص 18'!$J$8=""),"",'مستخلص 18'!$J$8) | E23: =IF(OR('مستخلص 18'!$J$7="",'مستخلص 18'!$J$9=""),"",'مستخلص 18'!$J$9) | F23: =IF(OR('مستخلص 18'!$J$7="",'مستخلص 18'!$J$5=""),"",'مستخلص 18'!$J$5) | G23: =IF('مستخلص 18'!$J$7="","",'مستخلص 18'!$L$19) | H23: =IF('مستخلص 18'!$J$7="","",'مستخلص 18'!$J$19) | I23: =IF('مستخلص 18'!$J$7="","",'مستخلص 18'!$L$20) | J23: =IF('مستخلص 18'!$J$7="","",'مستخلص 18'!$L$21) | K23: =IF('مستخلص 18'!$J$7="","",'مستخلص 18'!$L$22) | L23: =IF('مستخلص 18'!$J$7="","",'مستخلص 18'!$L$6) | M23: =IF(OR('مستخلص 18'!$J$7="",'مستخلص 18'!$L$8=""),"",'مستخلص 18'!$L$8) | N23: =IF(OR('مستخلص 18'!$J$7="",M23=""),"",L23-M23) | O23: =IF('مستخلص 18'!$J$7="","",-'مستخلص 18'!$L$23) | P23: =IF('مستخلص 18'!$J$7="","",-'مستخلص 18'!$L$24) | Q23: =IF('مستخلص 18'!$J$7="","",'مستخلص 18'!$L$25) | R23: =IF('مستخلص 18'!$J$7="","",P23-Q23) | S23: =IF('مستخلص 18'!$J$7="","",-'مستخلص 18'!$L$26) | T23: =IF('مستخلص 18'!$J$7="","",-'مستخلص 18'!$L$27) | U23: =IF('مستخلص 18'!$J$7="","",'مستخلص 18'!$L$28) | V23: =IF('مستخلص 18'!$J$7="","",'مستخلص 18'!$L$29) | W23: =IF('مستخلص 18'!$J$7="","",-'مستخلص 18'!$L$30) | X23: =IF('مستخلص 18'!$J$7="","",'مستخلص 18'!$L$31) | Y23: =IF('مستخلص 18'!$J$7="","",'مستخلص 18'!$H$31) | Z23: =IF('مستخلص 18'!$J$7="","",'مستخلص 18'!$J$31) | AA23: =IF('مستخلص 18'!$J$7="","",N('مستخلص 18'!$E$15)) | AB23: =IF(OR('مستخلص 18'!$J$7="",'مستخلص 18'!$K$15=""),"",'مستخلص 18'!$K$15) | AC23: =IF('مستخلص 18'!$J$7="","",Z23-AA23) | AD23: =IF(OR(AB23="",E23=""),"",AB23-E23) | AE23: =IF('مستخلص 18'!$J$7="","",IF(N(AA23)=0,IF(E23="","⏳ بانتظار الاعتماد","✖ غير محصل"),IF(AC23<=1,"✔ محصل بالكامل","⚠ محصل جزئياً")))
A24: 19 | B24: =IF(OR('مستخلص 19'!$J$7="",'مستخلص 19'!$J$6=""),"",'مستخلص 19'!$J$6) | C24: =IF('مستخلص 19'!$J$7="","",'مستخلص 19'!$J$7) | D24: =IF(OR('مستخلص 19'!$J$7="",'مستخلص 19'!$J$8=""),"",'مستخلص 19'!$J$8) | E24: =IF(OR('مستخلص 19'!$J$7="",'مستخلص 19'!$J$9=""),"",'مستخلص 19'!$J$9) | F24: =IF(OR('مستخلص 19'!$J$7="",'مستخلص 19'!$J$5=""),"",'مستخلص 19'!$J$5) | G24: =IF('مستخلص 19'!$J$7="","",'مستخلص 19'!$L$19) | H24: =IF('مستخلص 19'!$J$7="","",'مستخلص 19'!$J$19) | I24: =IF('مستخلص 19'!$J$7="","",'مستخلص 19'!$L$20) | J24: =IF('مستخلص 19'!$J$7="","",'مستخلص 19'!$L$21) | K24: =IF('مستخلص 19'!$J$7="","",'مستخلص 19'!$L$22) | L24: =IF('مستخلص 19'!$J$7="","",'مستخلص 19'!$L$6) | M24: =IF(OR('مستخلص 19'!$J$7="",'مستخلص 19'!$L$8=""),"",'مستخلص 19'!$L$8) | N24: =IF(OR('مستخلص 19'!$J$7="",M24=""),"",L24-M24) | O24: =IF('مستخلص 19'!$J$7="","",-'مستخلص 19'!$L$23) | P24: =IF('مستخلص 19'!$J$7="","",-'مستخلص 19'!$L$24) | Q24: =IF('مستخلص 19'!$J$7="","",'مستخلص 19'!$L$25) | R24: =IF('مستخلص 19'!$J$7="","",P24-Q24) | S24: =IF('مستخلص 19'!$J$7="","",-'مستخلص 19'!$L$26) | T24: =IF('مستخلص 19'!$J$7="","",-'مستخلص 19'!$L$27) | U24: =IF('مستخلص 19'!$J$7="","",'مستخلص 19'!$L$28) | V24: =IF('مستخلص 19'!$J$7="","",'مستخلص 19'!$L$29) | W24: =IF('مستخلص 19'!$J$7="","",-'مستخلص 19'!$L$30) | X24: =IF('مستخلص 19'!$J$7="","",'مستخلص 19'!$L$31) | Y24: =IF('مستخلص 19'!$J$7="","",'مستخلص 19'!$H$31) | Z24: =IF('مستخلص 19'!$J$7="","",'مستخلص 19'!$J$31) | AA24: =IF('مستخلص 19'!$J$7="","",N('مستخلص 19'!$E$15)) | AB24: =IF(OR('مستخلص 19'!$J$7="",'مستخلص 19'!$K$15=""),"",'مستخلص 19'!$K$15) | AC24: =IF('مستخلص 19'!$J$7="","",Z24-AA24) | AD24: =IF(OR(AB24="",E24=""),"",AB24-E24) | AE24: =IF('مستخلص 19'!$J$7="","",IF(N(AA24)=0,IF(E24="","⏳ بانتظار الاعتماد","✖ غير محصل"),IF(AC24<=1,"✔ محصل بالكامل","⚠ محصل جزئياً")))
A25: 20 | B25: =IF(OR('مستخلص 20'!$J$7="",'مستخلص 20'!$J$6=""),"",'مستخلص 20'!$J$6) | C25: =IF('مستخلص 20'!$J$7="","",'مستخلص 20'!$J$7) | D25: =IF(OR('مستخلص 20'!$J$7="",'مستخلص 20'!$J$8=""),"",'مستخلص 20'!$J$8) | E25: =IF(OR('مستخلص 20'!$J$7="",'مستخلص 20'!$J$9=""),"",'مستخلص 20'!$J$9) | F25: =IF(OR('مستخلص 20'!$J$7="",'مستخلص 20'!$J$5=""),"",'مستخلص 20'!$J$5) | G25: =IF('مستخلص 20'!$J$7="","",'مستخلص 20'!$L$19) | H25: =IF('مستخلص 20'!$J$7="","",'مستخلص 20'!$J$19) | I25: =IF('مستخلص 20'!$J$7="","",'مستخلص 20'!$L$20) | J25: =IF('مستخلص 20'!$J$7="","",'مستخلص 20'!$L$21) | K25: =IF('مستخلص 20'!$J$7="","",'مستخلص 20'!$L$22) | L25: =IF('مستخلص 20'!$J$7="","",'مستخلص 20'!$L$6) | M25: =IF(OR('مستخلص 20'!$J$7="",'مستخلص 20'!$L$8=""),"",'مستخلص 20'!$L$8) | N25: =IF(OR('مستخلص 20'!$J$7="",M25=""),"",L25-M25) | O25: =IF('مستخلص 20'!$J$7="","",-'مستخلص 20'!$L$23) | P25: =IF('مستخلص 20'!$J$7="","",-'مستخلص 20'!$L$24) | Q25: =IF('مستخلص 20'!$J$7="","",'مستخلص 20'!$L$25) | R25: =IF('مستخلص 20'!$J$7="","",P25-Q25) | S25: =IF('مستخلص 20'!$J$7="","",-'مستخلص 20'!$L$26) | T25: =IF('مستخلص 20'!$J$7="","",-'مستخلص 20'!$L$27) | U25: =IF('مستخلص 20'!$J$7="","",'مستخلص 20'!$L$28) | V25: =IF('مستخلص 20'!$J$7="","",'مستخلص 20'!$L$29) | W25: =IF('مستخلص 20'!$J$7="","",-'مستخلص 20'!$L$30) | X25: =IF('مستخلص 20'!$J$7="","",'مستخلص 20'!$L$31) | Y25: =IF('مستخلص 20'!$J$7="","",'مستخلص 20'!$H$31) | Z25: =IF('مستخلص 20'!$J$7="","",'مستخلص 20'!$J$31) | AA25: =IF('مستخلص 20'!$J$7="","",N('مستخلص 20'!$E$15)) | AB25: =IF(OR('مستخلص 20'!$J$7="",'مستخلص 20'!$K$15=""),"",'مستخلص 20'!$K$15) | AC25: =IF('مستخلص 20'!$J$7="","",Z25-AA25) | AD25: =IF(OR(AB25="",E25=""),"",AB25-E25) | AE25: =IF('مستخلص 20'!$J$7="","",IF(N(AA25)=0,IF(E25="","⏳ بانتظار الاعتماد","✖ غير محصل"),IF(AC25<=1,"✔ محصل بالكامل","⚠ محصل جزئياً")))
A26: الإجمالي / آخر رصيد | G26: =IF($AG$3=0,0,INDEX(G6:G25,$AG$3)) | H26: =SUM(H6:H25) | I26: =IF($AG$3=0,0,INDEX(I6:I25,$AG$3)) | J26: =IF($AG$3=0,0,INDEX(J6:J25,$AG$3)) | K26: =IF($AG$3=0,0,INDEX(K6:K25,$AG$3)) | L26: =IF($AG$3=0,0,INDEX(L6:L25,$AG$3)) | O26: =IF($AG$3=0,0,INDEX(O6:O25,$AG$3)) | P26: =IF($AG$3=0,0,INDEX(P6:P25,$AG$3)) | Q26: =IF($AG$3=0,0,INDEX(Q6:Q25,$AG$3)) | R26: =IF($AG$3=0,0,INDEX(R6:R25,$AG$3)) | S26: =IF($AG$3=0,0,INDEX(S6:S25,$AG$3)) | T26: =IF($AG$3=0,0,INDEX(T6:T25,$AG$3)) | U26: =IF($AG$3=0,0,INDEX(U6:U25,$AG$3)) | V26: =IF($AG$3=0,0,INDEX(V6:V25,$AG$3)) | ... X26: =IF($AG$3=0,0,INDEX(X6:X25,$AG$3)) | Z26: =SUM(Z6:Z25) | AA26: =SUM(AA6:AA25) | AC26: =SUM(AC6:AC25) | AD26: =IFERROR(AVERAGE(AD6:AD25),0)
A28: هذا السجل للعرض فقط (لا يُدخل فيه شيء) — كل البيانات تُدخل في شيت كل مستخلص. يصبح المستخلص فعالاً بمجرد إدخال «الفترة إلى» في شيته. اضغط على رقم المستخلص للانتقال إليه.
B30: الإنجاز حسب أقسام الأعمال
B31: القسم | E31: القيمة التعاقدية | F31: القيمة المنفذة التراكمية | G31: نسبة الإنجاز | H31: الوزن من العقد
B32: =IF('بيانات العقد'!F6="","",'بيانات العقد'!F6) | E32: =IF(B32="",0,SUMIF('جدول الكميات'!$C$6:$C$105,B32,'جدول الكميات'!$H$6:$H$105)) | F32: =IF(B32="",0,SUMIF('جدول الكميات'!$C$6:$C$105,B32,'مستخلص 20'!$M$43:$M$142)) | G32: =IF(E32>0,F32/E32,0) | H32: =IF(ContractValue>0,E32/ContractValue,0)
B33: =IF('بيانات العقد'!F7="","",'بيانات العقد'!F7) | E33: =IF(B33="",0,SUMIF('جدول الكميات'!$C$6:$C$105,B33,'جدول الكميات'!$H$6:$H$105)) | F33: =IF(B33="",0,SUMIF('جدول الكميات'!$C$6:$C$105,B33,'مستخلص 20'!$M$43:$M$142)) | G33: =IF(E33>0,F33/E33,0) | H33: =IF(ContractValue>0,E33/ContractValue,0)
B34: =IF('بيانات العقد'!F8="","",'بيانات العقد'!F8) | E34: =IF(B34="",0,SUMIF('جدول الكميات'!$C$6:$C$105,B34,'جدول الكميات'!$H$6:$H$105)) | F34: =IF(B34="",0,SUMIF('جدول الكميات'!$C$6:$C$105,B34,'مستخلص 20'!$M$43:$M$142)) | G34: =IF(E34>0,F34/E34,0) | H34: =IF(ContractValue>0,E34/ContractValue,0)
B35: =IF('بيانات العقد'!F9="","",'بيانات العقد'!F9) | E35: =IF(B35="",0,SUMIF('جدول الكميات'!$C$6:$C$105,B35,'جدول الكميات'!$H$6:$H$105)) | F35: =IF(B35="",0,SUMIF('جدول الكميات'!$C$6:$C$105,B35,'مستخلص 20'!$M$43:$M$142)) | G35: =IF(E35>0,F35/E35,0) | H35: =IF(ContractValue>0,E35/ContractValue,0)
B36: =IF('بيانات العقد'!F10="","",'بيانات العقد'!F10) | E36: =IF(B36="",0,SUMIF('جدول الكميات'!$C$6:$C$105,B36,'جدول الكميات'!$H$6:$H$105)) | F36: =IF(B36="",0,SUMIF('جدول الكميات'!$C$6:$C$105,B36,'مستخلص 20'!$M$43:$M$142)) | G36: =IF(E36>0,F36/E36,0) | H36: =IF(ContractValue>0,E36/ContractValue,0)
B37: =IF('بيانات العقد'!F11="","",'بيانات العقد'!F11) | E37: =IF(B37="",0,SUMIF('جدول الكميات'!$C$6:$C$105,B37,'جدول الكميات'!$H$6:$H$105)) | F37: =IF(B37="",0,SUMIF('جدول الكميات'!$C$6:$C$105,B37,'مستخلص 20'!$M$43:$M$142)) | G37: =IF(E37>0,F37/E37,0) | H37: =IF(ContractValue>0,E37/ContractValue,0)
B38: =IF('بيانات العقد'!F12="","",'بيانات العقد'!F12) | E38: =IF(B38="",0,SUMIF('جدول الكميات'!$C$6:$C$105,B38,'جدول الكميات'!$H$6:$H$105)) | F38: =IF(B38="",0,SUMIF('جدول الكميات'!$C$6:$C$105,B38,'مستخلص 20'!$M$43:$M$142)) | G38: =IF(E38>0,F38/E38,0) | H38: =IF(ContractValue>0,E38/ContractValue,0)
B39: =IF('بيانات العقد'!F13="","",'بيانات العقد'!F13) | E39: =IF(B39="",0,SUMIF('جدول الكميات'!$C$6:$C$105,B39,'جدول الكميات'!$H$6:$H$105)) | F39: =IF(B39="",0,SUMIF('جدول الكميات'!$C$6:$C$105,B39,'مستخلص 20'!$M$43:$M$142)) | G39: =IF(E39>0,F39/E39,0) | H39: =IF(ContractValue>0,E39/ContractValue,0)
B40: =IF('بيانات العقد'!F14="","",'بيانات العقد'!F14) | E40: =IF(B40="",0,SUMIF('جدول الكميات'!$C$6:$C$105,B40,'جدول الكميات'!$H$6:$H$105)) | F40: =IF(B40="",0,SUMIF('جدول الكميات'!$C$6:$C$105,B40,'مستخلص 20'!$M$43:$M$142)) | G40: =IF(E40>0,F40/E40,0) | H40: =IF(ContractValue>0,E40/ContractValue,0)
B41: =IF('بيانات العقد'!F15="","",'بيانات العقد'!F15) | E41: =IF(B41="",0,SUMIF('جدول الكميات'!$C$6:$C$105,B41,'جدول الكميات'!$H$6:$H$105)) | F41: =IF(B41="",0,SUMIF('جدول الكميات'!$C$6:$C$105,B41,'مستخلص 20'!$M$43:$M$142)) | G41: =IF(E41>0,F41/E41,0) | H41: =IF(ContractValue>0,E41/ContractValue,0)
B42: =IF('بيانات العقد'!F16="","",'بيانات العقد'!F16) | E42: =IF(B42="",0,SUMIF('جدول الكميات'!$C$6:$C$105,B42,'جدول الكميات'!$H$6:$H$105)) | F42: =IF(B42="",0,SUMIF('جدول الكميات'!$C$6:$C$105,B42,'مستخلص 20'!$M$43:$M$142)) | G42: =IF(E42>0,F42/E42,0) | H42: =IF(ContractValue>0,E42/ContractValue,0)
...

Sheet مستخلص 01
B1: 🧾 مستخلص أعمال رقم (1) — شهادة دفع مؤقتة (Interim Payment Certificate)
B2: =IF('بيانات العقد'!$C$5="","مشروع رقم 07 — أدخل بيانات العقد",'بيانات العقد'!$C$5&" | عقد رقم: "&'بيانات العقد'!$C$6)&" | المبالغ بـ "&'بيانات العقد'!$C$14
B3: 🗂 سجل المستخلصات | C3: ⚙ بيانات العقد | E3: 📋 جدول الكميات | G3: 🔁 التغييرية | I3: ✂ الاستقطاعات | L3: المستخلص التالي ►
B5: رقم المستخلص | C5: 1 | H5: حالة المستخلص | L5: نسبة الإنجاز الفعلية
B6: المشروع | C6: ='بيانات العقد'!C5 | H6: الفترة من | L6: =IF(ContractValue+L20>0,(L19+L20)/(ContractValue+L20),0)
B7: رقم العقد | C7: ='بيانات العقد'!C6 | H7: الفترة إلى | L7: نسبة الإنجاز المخططة (من البرنامج)
B8: صاحب العمل | C8: ='بيانات العقد'!C7 | H8: تاريخ التقديم
B9: الاستشاري | C9: ='بيانات العقد'!C8 | H9: تاريخ الاعتماد | L9: الانحراف عن المخطط
B10: المقاول | C10: ='بيانات العقد'!C9 | H10: قيمة العقد المعدلة | J10: =RevisedContract | L10: =IF(L8="","",L6-L8)
B12: أولاً: بيانات الفترة (إدخال)
B13: رصيد المواد الموردة بالموقع (نهاية الفترة) | H13: إفراج عن ضمان الأعمال خلال الفترة
B14: غرامات تأخير / خصومات أخرى خلال الفترة | H14: سبب الغرامة / الخصم
B15: المبلغ المحصل من هذا المستخلص | H15: تاريخ التحصيل
B17: ثانياً: الملخص المالي للمستخلص
B18: م | C18: البيان | H18: السابق | J18: الحالي | L18: الإجمالي التراكمي
B19: 1 | C19: قيمة الأعمال المنفذة طبقاً لحصر البنود | H19: 0 | J19: =L19-H19 | L19: =M143
B20: 2 | C20: قيمة الأوامر التغييرية المعتمدة | H20: 0 | J20: =L20-H20 | L20: =SUMIFS('الأوامر التغييرية'!$J$6:$J$55,'الأوامر التغييرية'!$H$6:$H$55,"معتمد",'الأوامر التغييرية'!$K$6:$K$55,"<="&$C$5)
B21: 3 | C21: المواد الموردة بالموقع (رصيد) | H21: 0 | J21: =L21-H21 | L21: =N(E13)
B22: 4 | C22: إجمالي قيمة الأعمال | H22: 0 | J22: =L22-H22 | L22: =SUM(L19:L21)
B23: 5 | C23: يُخصم: استرداد الدفعة المقدمة | H23: 0 | J23: =L23-H23 | L23: =-ROUND(IF(L6>=RecFull,AdvAmount,MIN(AdvAmount,MAX(0,L19+L20-RecStart*ContractValue)*RecRate)),2)
B24: 6 | C24: يُخصم: ضمان الأعمال المحتسب | H24: 0 | J24: =L24-H24 | L24: =-ROUND(MIN(L22*RetPct,RetCap),2)
B25: 7 | C25: يُضاف: المفرج عنه من ضمان الأعمال | H25: 0 | J25: =L25-H25 | L25: =H25+N(K13)
B26: 8 | C26: يُخصم: الاستقطاعات الفنية المحتجزة | H26: 0 | J26: =L26-H26 | L26: =-(SUMIFS('الاستقطاعات الفنية'!$I$6:$I$105,'الاستقطاعات الفنية'!$D$6:$D$105,"<="&$C$5)-SUMIFS('الاستقطاعات الفنية'!$I$6:$I$105,'الاستقطاعات الفنية'!$J$6:$J$105,"نعم",'الاستقطاعات الفنية'!$K$6:$K$105,"<="&$C$5))
B27: 9 | C27: يُخصم: الغرامات والخصومات الأخرى | H27: 0 | J27: =L27-H27 | L27: =H27-N(E14)
B28: 10 | C28: صافي القيمة قبل الضرائب | H28: 0 | J28: =L28-H28 | L28: =SUM(L22:L27)
B29: 11 | C29: يُضاف: ضريبة القيمة المضافة | H29: 0 | J29: =L29-H29 | L29: =ROUND(VATPct*(L28+IF(VATBeforeRet="نعم",-(L24+L25),0)),2)
B30: 12 | C30: يُخصم: ضريبة الخصم من المنبع | H30: 0 | J30: =L30-H30 | L30: =-ROUND(WHTPct*(L28-(L24+L25)),2)
B31: 13 | C31: صافي المستحق | H31: 0 | J31: =L31-H31 | L31: =L28+L29+L30
B32: صافي المبلغ المستحق صرفه عن هذا المستخلص | J32: =J31
B33: المحصل من هذا المستخلص | J33: =N(E15)
B34: المتبقي غير المحصل | J34: =J32-J33
B35: فقط وقدره:
B37: ثالثاً: الاعتمادات
B38: إعداد: مهندس المقاول | F38: مراجعة: المهندس الاستشاري | J38: اعتماد: صاحب العمل
B39: الاسم: .................... التوقيع: .................. التاريخ: .................. | F39: الاسم: .................... التوقيع: .................. التاريخ: .................. | J39: الاسم: .................... التوقيع: .................. التاريخ: ..................
B41: رابعاً: حصر الأعمال المنفذة حسب بنود جدول الكميات — أدخل «الكمية الحالية» فقط
B42: كود البند | C42: الوصف | D42: الوحدة | E42: الكمية التعاقدية | F42: سعر الوحدة | G42: الكمية السابقة | H42: الكمية الحالية | I42: الكمية التراكمية | J42: نسبة الإنجاز | K42: القيمة السابقة | L42: القيمة الحالية | M42: القيمة التراكمية
B43: =IF('جدول الكميات'!B6="","",'جدول الكميات'!B6) | C43: =IF('جدول الكميات'!D6="","",'جدول الكميات'!D6) | D43: =IF('جدول الكميات'!E6="","",'جدول الكميات'!E6) | E43: =N('جدول الكميات'!F6) | F43: =N('جدول الكميات'!G6) | G43: 0 | I43: =G43+H43 | J43: =IF(E43>0,I43/E43,0) | K43: =G43*F43 | L43: =N(H43)*F43 | M43: =I43*F43
B44: =IF('جدول الكميات'!B7="","",'جدول الكميات'!B7) | C44: =IF('جدول الكميات'!D7="","",'جدول الكميات'!D7) | D44: =IF('جدول الكميات'!E7="","",'جدول الكميات'!E7) | E44: =N('جدول الكميات'!F7) | F44: =N('جدول الكميات'!G7) | G44: 0 | I44: =G44+H44 | J44: =IF(E44>0,I44/E44,0) | K44: =G44*F44 | L44: =N(H44)*F44 | M44: =I44*F44
B45: =IF('جدول الكميات'!B8="","",'جدول الكميات'!B8) | C45: =IF('جدول الكميات'!D8="","",'جدول الكميات'!D8) | D45: =IF('جدول الكميات'!E8="","",'جدول الكميات'!E8) | E45: =N('جدول الكميات'!F8) | F45: =N('جدول الكميات'!G8) | G45: 0 | I45: =G45+H45 | J45: =IF(E45>0,I45/E45,0) | K45: =G45*F45 | L45: =N(H45)*F45 | M45: =I45*F45
...

Sheet مستخلص 02
B1: 🧾 مستخلص أعمال رقم (2) — شهادة دفع مؤقتة (Interim Payment Certificate)
B2: =IF('بيانات العقد'!$C$5="","مشروع رقم 07 — أدخل بيانات العقد",'بيانات العقد'!$C$5&" | عقد رقم: "&'بيانات العقد'!$C$6)&" | المبالغ بـ "&'بيانات العقد'!$C$14
B3: 🗂 سجل المستخلصات | C3: ⚙ بيانات العقد | E3: 📋 جدول الكميات | G3: 🔁 التغييرية | I3: ✂ الاستقطاعات | K3: ◄ المستخلص السابق | L3: المستخلص التالي ►
B5: رقم المستخلص | C5: 2 | H5: حالة المستخلص | L5: نسبة الإنجاز الفعلية
B6: المشروع | C6: ='بيانات العقد'!C5 | H6: الفترة من | L6: =IF(ContractValue+L20>0,(L19+L20)/(ContractValue+L20),0)
B7: رقم العقد | C7: ='بيانات العقد'!C6 | H7: الفترة إلى | L7: نسبة الإنجاز المخططة (من البرنامج)
B8: صاحب العمل | C8: ='بيانات العقد'!C7 | H8: تاريخ التقديم
B9: الاستشاري | C9: ='بيانات العقد'!C8 | H9: تاريخ الاعتماد | L9: الانحراف عن المخطط
B10: المقاول | C10: ='بيانات العقد'!C9 | H10: قيمة العقد المعدلة | J10: =RevisedContract | L10: =IF(L8="","",L6-L8)
B12: أولاً: بيانات الفترة (إدخال)
B13: رصيد المواد الموردة بالموقع (نهاية الفترة) | H13: إفراج عن ضمان الأعمال خلال الفترة
B14: غرامات تأخير / خصومات أخرى خلال الفترة | H14: سبب الغرامة / الخصم
B15: المبلغ المحصل من هذا المستخلص | H15: تاريخ التحصيل
B17: ثانياً: الملخص المالي للمستخلص
