Workbook

Sheet التعليمات
B1: 📘 نظام تتبع المستخلصات متعدد المشاريع — دليل الاستخدام والربط
B2: ="تقارير المستخلصات المجمعة لكل المشاريع | تاريخ التقرير: "&TEXT(TODAY(),"yyyy/mm/dd")
B3: 🏠 الإجمالي العام | C3: 📊 تقرير المشروع 01
B5: مكونات النظام (فولدر رئيسي: ملف التقارير + فولدر مستقل لكل مشروع)
B6: Projects_Billing_Reports.xlsx | C6: ملف التقارير (هذا الملف): 50 شيتات تقرير — شيت لكل مشروع — والشيت الأخير «الإجمالي العام» يجمع كل المشاريع.
B7: Project_01/IPC_Project_01.xlsx … Project_50/IPC_Project_50.xlsx | C7: ملف مستخلصات لكل مشروع: بيانات العقد، جدول الكميات، التغييرية، الاستقطاعات، 20 شيت مستخلص مترابطة، وسجل المستخلصات.
B9: طريقة العمل
B10: 1. افتح ملف المشروع | C10: مثلاً Project_01/IPC_Project_01.xlsx — أدخل بيانات العقد وجدول الكميات مرة واحدة، وضع مستندات المشروع (عقود، محاضر، فواتير) في نفس فولدره.
B11: 2. اعمل المستخلص | C11: في شيت «مستخلص NN»: الفترة والتواريخ والكميات الحالية والمواد والغرامات والتحصيل. السابق يُسحب آلياً من المستخلص الذي قبله.
B12: 3. احفظ الملف | C12: كل الحسابات تتجمع في «سجل المستخلصات» داخل ملف المشروع.
B13: 4. افتح ملف التقارير | C13: اضغط «تمكين المحتوى» ثم «تحديث» عند ظهور رسالة الروابط — تنتقل الأرقام آلياً لتقرير المشروع وللإجمالي العام. (يمكن أيضاً: بيانات ← تحرير الارتباطات ← تحديث القيم).
B14: مشروع جديد | C14: المشاريع 4 إلى 50 قوالب فارغة جاهزة كل منها في فولدره: افتح ملف المشروع وابدأ بإدخال البيانات، وسيظهر آلياً في التقارير.
B15: تغيير مكان الملفات | C15: انقل الفولدر الرئيسي كاملاً بما فيه فولدرات المشاريع. لا تغيّر أسماء الفولدرات أو الملفات؛ وإن لزم: بيانات ← تحرير الارتباطات ← تغيير المصدر.
B17: التوافق مع الأنظمة السعودية
B18: ضريبة القيمة المضافة | C18: 15% (نظام ضريبة القيمة المضافة). وعاء الضريبة = صافي المستخلص بعد استرداد الدفعة المقدمة، ويشمل المحتجزات إذا فُوترت مع المستخلص، ولا تُخفضه غرامات التأخير افتراضياً — كلها قابلة للضبط في «بيانات العقد».
B19: الفاتورة الضريبية | C19: يُسجل رقم وتاريخ الفاتورة الضريبية لكل مستخلص. الفاتورة نفسها تُصدر من نظام فوترة إلكترونية متوافق مع متطلبات «فاتورة» لهيئة الزكاة والضريبة والجمارك (رمز QR والربط في المرحلة الثانية) — المستخلص ليس بديلاً عنها.
B20: الرقم الضريبي | C20: 15 رقماً يبدأ وينتهي بالرقم 3 — مع تحقق آلي من الصيغة للمقاول وصاحب العمل.
B21: الدفعة المقدمة | C21: في العقود الحكومية لا تتجاوز 10% من قيمة العقد وبمقابل ضمان بنكي مساوٍ لها، وتُسترد من المستخلصات.
B22: الضمان النهائي | C22: 5% من قيمة العقد (خطاب ضمان بنكي) مع تنبيه آلي قبل انتهاء الصلاحية بـ 30 يوماً.
B23: غرامات التأخير | C23: حد أقصى قابل للضبط (افتراضياً 10% من قيمة العقد) مع تنبيه عند تجاوزه.
B24: ضريبة الاستقطاع | C24: لا تُطبق على المقاول المقيم (0%)، وتُستخدم فقط للمدفوعات لغير المقيم وفق نظام ضريبة الدخل.
B25: المستندات النظامية | C25: قائمة تحقق لكل مستخلص: الزكاة، التأمينات الاجتماعية (GOSI)، نطاقات، السجل التجاري والغرفة، الضمانات، التأمين (CAR).
B26: التاريخ الهجري | C26: تظهر فترة كل مستخلص بالتاريخ الهجري بجوار الميلادي.
B27: تنبيه مهم | C27: النسب والحدود الافتراضية مبنية على الممارسة الشائعة؛ تُراجع مع شروط عقدك والمستشار القانوني والضريبي قبل الاعتماد.
B29: منطق الاحتساب (كل القيم تراكمية — الحالي = التراكمي − السابق)
B30: قيمة الأعمال | C30: Σ (الكمية التراكمية لكل بند × سعر الوحدة)، والكمية التراكمية = السابقة + الحالية.
B31: نسبة الإنجاز | C31: (الأعمال + التغييرية المدرجة) ÷ (قيمة العقد الأصلية + التغييرية المدرجة).
B32: استرداد الدفعة المقدمة | C32: MIN(قيمة الدفعة ، MAX(0 ، الأعمال − نسبة البدء × العقد) × نسبة الاسترداد)، ويُسترد الرصيد كاملاً عند نسبة الاسترداد الكامل.
B33: ضمان الأعمال | C33: MIN(إجمالي القيمة × نسبة الضمان ، الحد الأقصى) − المفرج عنه تراكمياً.
B34: الاستقطاعات الفنية | C34: المستقطع حتى المستخلص − المفرج عنه حتى المستخلص.
B35: الضرائب | C35: ض.ق.م على الصافي (+ الضمان إن كان الإعداد «نعم»)، وضريبة الاستقطاع (لغير المقيم فقط) على الصافي قبل خصم الضمان، والغرامات لا تُخفض وعاء الضريبة افتراضياً.
B36: SPI | C36: الإنجاز الفعلي ÷ المخطط — أقل من 1 = تأخر.
B37: الموازنة والربحية | C37: BAC = التكلفة المباشرة + العمومية + الطوارئ. الربح = إجمالي قيمة الأعمال − التكلفة الفعلية. CPI = (BAC × نسبة الإنجاز) ÷ التكلفة الفعلية؛ أقل من 0.95 = تجاوز. EAC = BAC ÷ CPI.
B38: الإجمالي العام | C38: متوسطات الإنجاز مرجحة بقيمة العقد المعدلة لكل مشروع.

Sheet مشروع 01
B1: ="📊 "&IF('[1]بيانات العقد'!$C$5="","مشروع رقم 01 — غير مُفعّل",'[1]بيانات العقد'!$C$5)
B2: ="تقارير المستخلصات المجمعة لكل المشاريع | تاريخ التقرير: "&TEXT(TODAY(),"yyyy/mm/dd")
B3: 🏠 الإجمالي العام | D3: المشروع التالي ► | F3: 📂 فتح ملف المستخلصات: Project_01/IPC_Project_01.xlsx | N3: يُحدَّث آلياً من ملف المستخلصات (تمكين المحتوى ← تحديث الروابط)
AA4: بيانات مرتبطة من ملف المستخلصات
B5: المشروع | C5: =IF('[1]بيانات العقد'!$C$5="","",'[1]بيانات العقد'!$C$5) | G5: رقم العقد | H5: =IF('[1]بيانات العقد'!$C$6="","",'[1]بيانات العقد'!$C$6) | L5: صاحب العمل | M5: =IF('[1]بيانات العقد'!$C$7="","",'[1]بيانات العقد'!$C$7) | R5: الاستشاري | S5: =IF('[1]بيانات العقد'!$C$8="","",'[1]بيانات العقد'!$C$8) | AA5: قيمة العقد الأصلية | AB5: =N('[1]بيانات العقد'!$C$16)
B6: المقاول | C6: =IF('[1]بيانات العقد'!$C$9="","",'[1]بيانات العقد'!$C$9) | G6: تاريخ البدء | H6: =IF('[1]بيانات العقد'!$C$11="","",'[1]بيانات العقد'!$C$11) | L6: الانتهاء التعاقدي | M6: =IF('[1]بيانات العقد'!$C$13="","",'[1]بيانات العقد'!$C$13) | R6: العملة | S6: =IF('[1]بيانات العقد'!$C$14="","",'[1]بيانات العقد'!$C$14) | AA6: صافي التغييرية المعتمدة | AB6: =N('[1]بيانات العقد'!$C$17)
AA7: قيمة العقد المعدلة | AB7: =N('[1]بيانات العقد'!$C$18)
B8: قيمة العقد الأصلية | F8: صافي الأوامر التغييرية | J8: قيمة العقد المعدلة | N8: إجمالي قيمة الأعمال التراكمية | R8: الأعمال المتبقية | V8: آخر مستخلص فعال | AA8: نسبة الدفعة المقدمة | AB8: =N('[1]بيانات العقد'!$C$20)
B9: =$AB$5 | F9: =$AB$6 | J9: =$AB$7 | N9: =IF($V$9=0,0,N(INDEX($J$25:$J$44,$V$9))) | R9: =MAX(0,$AB$7-IF($V$9=0,0,N(INDEX($G$25:$G$44,$V$9)))-IF($V$9=0,0,N(INDEX($H$25:$H$44,$V$9)))) | V9: =SUMPRODUCT(MAX((C25:C44<>"")*B25:B44)) | AA9: قيمة الدفعة المقدمة | AB9: =N('[1]بيانات العقد'!$C$21)
AA10: نسبة ضمان الأعمال | AB10: =N('[1]بيانات العقد'!$C$27)
B11: نسبة الإنجاز الفعلية | F11: نسبة الإنجاز المخططة | J11: الانحراف (فعلي - مخطط) | N11: نسبة المدة المنقضية | R11: مؤشر أداء الجدول (SPI) | V11: حالة المشروع | AA11: الحد الأقصى للضمان | AB11: =N('[1]بيانات العقد'!$C$29)
B12: =IF($V$9=0,0,N(INDEX($K$25:$K$44,$V$9))) | F12: =IF($V$9=0,0,N(INDEX($L$25:$L$44,$V$9))) | J12: =B12-F12 | N12: =IF(OR($V$9=0,$AB$14="",$AB$15=""),0,MIN(1,MAX(0,(INDEX(C25:C44,$V$9)-$AB$14+1)/($AB$15-$AB$14+1)))) | R12: =IF(F12>0,B12/F12,0) | V12: =IF($AB$7=0,"غير مُفعّل",IF($V$9=0,"لم يبدأ الصرف",IF(J12<-0.05,"⚠ متأخر",IF(J12<0,"متأخر قليلاً","✔ مطابق / متقدم")))) | AA12: ضريبة القيمة المضافة | AB12: =N('[1]بيانات العقد'!$C$31)
AA13: ضريبة الاستقطاع (غير المقيم) | AB13: =N('[1]بيانات العقد'!$C$33)
B14: صافي المستحق التراكمي | F14: إجمالي المحصل | J14: مستحقات غير محصلة | N14: نسبة التحصيل | R14: متوسط مدة التحصيل (يوم) | V14: تاريخ آخر مستخلص | AA14: تاريخ البدء | AB14: =IF('[1]بيانات العقد'!$C$11="","",'[1]بيانات العقد'!$C$11)
B15: =IF($V$9=0,0,N(INDEX($T$25:$T$44,$V$9))) | F15: =V45 | J15: =W45 | N15: =IF(B15>0,F15/B15,0) | R15: =X45 | V15: =IF($V$9=0,"",INDEX(C25:C44,$V$9)) | AA15: تاريخ الانتهاء التعاقدي | AB15: =IF('[1]بيانات العقد'!$C$13="","",'[1]بيانات العقد'!$C$13)
AA16: المدة (شهر) | AB16: =IF('[1]بيانات العقد'!$C$12="","",'[1]بيانات العقد'!$C$12)
B17: ضمان الأعمال المحتجز | F17: رصيد الدفعة المقدمة غير المسترد | J17: الاستقطاعات الفنية المحتجزة | N17: الغرامات والخصومات | R17: مستحق آخر مستخلص | V17: عدد المستخلصات المعتمدة | AA17: نوع العقد | AB17: =IF('[1]بيانات العقد'!$C$36="","",'[1]بيانات العقد'!$C$36)
B18: =IF($V$9=0,0,N(INDEX($O$25:$O$44,$V$9))) | F18: =MAX(0,$AB$9-IF($V$9=0,0,N(INDEX($N$25:$N$44,$V$9)))) | J18: =IF($V$9=0,0,N(INDEX($P$25:$P$44,$V$9))) | N18: =IF($V$9=0,0,N(INDEX($Q$25:$Q$44,$V$9))) | R18: =IF($V$9=0,0,N(INDEX($U$25:$U$44,$V$9))) | V18: =COUNTIF(E25:E44,"معتمد") | AA18: الرقم الضريبي للمقاول | AB18: =IF('[1]بيانات العقد'!$C$37="","",'[1]بيانات العقد'!$C$37)
AA19: الرقم الضريبي لصاحب العمل | AB19: =IF('[1]بيانات العقد'!$C$39="","",'[1]بيانات العقد'!$C$39)
B20: الموازنة التقديرية (BAC) | F20: التكلفة الفعلية التراكمية | J20: الربح الفعلي التراكمي | N20: هامش الربح الفعلي | R20: مؤشر أداء التكلفة (CPI) | V20: الربح المتوقع عند الإنجاز | AA20: انتهاء الضمان النهائي | AB20: =IF('[1]بيانات العقد'!$C$42="","",'[1]بيانات العقد'!$C$42)
B21: =N('[1]الموازنة والتكاليف'!$D$66) | F21: =N('[1]الموازنة والتكاليف'!$D$70) | J21: =N('[1]الموازنة والتكاليف'!$D$72) | N21: =N('[1]الموازنة والتكاليف'!$D$73) | R21: =N('[1]الموازنة والتكاليف'!$D$74) | V21: =N('[1]الموازنة والتكاليف'!$D$76) | AA21: انتهاء ضمان الدفعة المقدمة | AB21: =IF('[1]بيانات العقد'!$C$43="","",'[1]بيانات العقد'!$C$43)
AA22: حالة غرامات التأخير | AB22: =IF('[1]بيانات العقد'!$C$47="","",'[1]بيانات العقد'!$C$47)
B23: سجل المستخلصات (مرتبط)
B24: رقم المستخلص | C24: الفترة إلى | D24: تاريخ الاعتماد | E24: حالة المستخلص | F24: أعمال الفترة | G24: الأعمال المنفذة التراكمية | H24: التغييرية التراكمية | I24: رصيد المواد بالموقع | J24: إجمالي القيمة التراكمية | K24: نسبة الإنجاز الفعلية | L24: نسبة الإنجاز المخططة | M24: الانحراف | N24: استرداد الدفعة المقدمة | O24: صافي الضمان المحتجز | P24: الاستقطاعات الفنية | Q24: الغرامات والخصومات | R24: ضريبة القيمة المضافة | S24: ضريبة الاستقطاع | T24: صافي المستحق التراكمي | U24: المستحق للمستخلص الحالي | V24: المحصل | W24: المتبقي | X24: مدة التحصيل (يوم) | Y24: حالة التحصيل | AA24: التنبيهات النظامية
B25: 1 | C25: =IF('[1]سجل المستخلصات'!$C$6="","",'[1]سجل المستخلصات'!$C$6) | D25: =IF('[1]سجل المستخلصات'!$E$6="","",'[1]سجل المستخلصات'!$E$6) | E25: =IF('[1]سجل المستخلصات'!$F$6="","",'[1]سجل المستخلصات'!$F$6) | F25: =IF('[1]سجل المستخلصات'!$H$6="","",'[1]سجل المستخلصات'!$H$6) | G25: =IF('[1]سجل المستخلصات'!$G$6="","",'[1]سجل المستخلصات'!$G$6) | H25: =IF('[1]سجل المستخلصات'!$I$6="","",'[1]سجل المستخلصات'!$I$6) | I25: =IF('[1]سجل المستخلصات'!$J$6="","",'[1]سجل المستخلصات'!$J$6) | J25: =IF('[1]سجل المستخلصات'!$K$6="","",'[1]سجل المستخلصات'!$K$6) | K25: =IF('[1]سجل المستخلصات'!$L$6="","",'[1]سجل المستخلصات'!$L$6) | L25: =IF('[1]سجل المستخلصات'!$M$6="","",'[1]سجل المستخلصات'!$M$6) | M25: =IF('[1]سجل المستخلصات'!$N$6="","",'[1]سجل المستخلصات'!$N$6) | N25: =IF('[1]سجل المستخلصات'!$O$6="","",'[1]سجل المستخلصات'!$O$6) | O25: =IF('[1]سجل المستخلصات'!$R$6="","",'[1]سجل المستخلصات'!$R$6) | P25: =IF('[1]سجل المستخلصات'!$S$6="","",'[1]سجل المستخلصات'!$S$6) | Q25: =IF('[1]سجل المستخلصات'!$T$6="","",'[1]سجل المستخلصات'!$T$6) | R25: =IF('[1]سجل المستخلصات'!$V$6="","",'[1]سجل المستخلصات'!$V$6) | S25: =IF('[1]سجل المستخلصات'!$W$6="","",'[1]سجل المستخلصات'!$W$6) | T25: =IF('[1]سجل المستخلصات'!$X$6="","",'[1]سجل المستخلصات'!$X$6) | U25: =IF('[1]سجل المستخلصات'!$Z$6="","",'[1]سجل المستخلصات'!$Z$6) | V25: =IF('[1]سجل المستخلصات'!$AA$6="","",'[1]سجل المستخلصات'!$AA$6) | W25: =IF('[1]سجل المستخلصات'!$AC$6="","",'[1]سجل المستخلصات'!$AC$6) | X25: =IF('[1]سجل المستخلصات'!$AD$6="","",'[1]سجل المستخلصات'!$AD$6) | Y25: =IF('[1]سجل المستخلصات'!$AE$6="","",'[1]سجل المستخلصات'!$AE$6) | AA25: =IF($AB$7=0,"",IF(AND($AB$20<>"",N($AB$20)-TODAY()<=30),"⚠ الضمان النهائي ينتهي خلال 30 يوماً — ","")&IF(AND($AB$21<>"",N($AB$21)-TODAY()<=30,$F$18>0),"⚠ ضمان الدفعة المقدمة ينتهي والرصيد لم يُسترد — ","")&IF(ISNUMBER(SEARCH("⚠",$AB$22)),"⚠ الغرامات تجاوزت الحد الأقصى — ","")&IF($J$15>0,"مستحقات غير محصلة","")&"")
B26: 2 | C26: =IF('[1]سجل المستخلصات'!$C$7="","",'[1]سجل المستخلصات'!$C$7) | D26: =IF('[1]سجل المستخلصات'!$E$7="","",'[1]سجل المستخلصات'!$E$7) | E26: =IF('[1]سجل المستخلصات'!$F$7="","",'[1]سجل المستخلصات'!$F$7) | F26: =IF('[1]سجل المستخلصات'!$H$7="","",'[1]سجل المستخلصات'!$H$7) | G26: =IF('[1]سجل المستخلصات'!$G$7="","",'[1]سجل المستخلصات'!$G$7) | H26: =IF('[1]سجل المستخلصات'!$I$7="","",'[1]سجل المستخلصات'!$I$7) | I26: =IF('[1]سجل المستخلصات'!$J$7="","",'[1]سجل المستخلصات'!$J$7) | J26: =IF('[1]سجل المستخلصات'!$K$7="","",'[1]سجل المستخلصات'!$K$7) | K26: =IF('[1]سجل المستخلصات'!$L$7="","",'[1]سجل المستخلصات'!$L$7) | L26: =IF('[1]سجل المستخلصات'!$M$7="","",'[1]سجل المستخلصات'!$M$7) | M26: =IF('[1]سجل المستخلصات'!$N$7="","",'[1]سجل المستخلصات'!$N$7) | N26: =IF('[1]سجل المستخلصات'!$O$7="","",'[1]سجل المستخلصات'!$O$7) | O26: =IF('[1]سجل المستخلصات'!$R$7="","",'[1]سجل المستخلصات'!$R$7) | P26: =IF('[1]سجل المستخلصات'!$S$7="","",'[1]سجل المستخلصات'!$S$7) | Q26: =IF('[1]سجل المستخلصات'!$T$7="","",'[1]سجل المستخلصات'!$T$7) | R26: =IF('[1]سجل المستخلصات'!$V$7="","",'[1]سجل المستخلصات'!$V$7) | S26: =IF('[1]سجل المستخلصات'!$W$7="","",'[1]سجل المستخلصات'!$W$7) | T26: =IF('[1]سجل المستخلصات'!$X$7="","",'[1]سجل المستخلصات'!$X$7) | U26: =IF('[1]سجل المستخلصات'!$Z$7="","",'[1]سجل المستخلصات'!$Z$7) | V26: =IF('[1]سجل المستخلصات'!$AA$7="","",'[1]سجل المستخلصات'!$AA$7) | W26: =IF('[1]سجل المستخلصات'!$AC$7="","",'[1]سجل المستخلصات'!$AC$7) | X26: =IF('[1]سجل المستخلصات'!$AD$7="","",'[1]سجل المستخلصات'!$AD$7) | Y26: =IF('[1]سجل المستخلصات'!$AE$7="","",'[1]سجل المستخلصات'!$AE$7)
B27: 3 | C27: =IF('[1]سجل المستخلصات'!$C$8="","",'[1]سجل المستخلصات'!$C$8) | D27: =IF('[1]سجل المستخلصات'!$E$8="","",'[1]سجل المستخلصات'!$E$8) | E27: =IF('[1]سجل المستخلصات'!$F$8="","",'[1]سجل المستخلصات'!$F$8) | F27: =IF('[1]سجل المستخلصات'!$H$8="","",'[1]سجل المستخلصات'!$H$8) | G27: =IF('[1]سجل المستخلصات'!$G$8="","",'[1]سجل المستخلصات'!$G$8) | H27: =IF('[1]سجل المستخلصات'!$I$8="","",'[1]سجل المستخلصات'!$I$8) | I27: =IF('[1]سجل المستخلصات'!$J$8="","",'[1]سجل المستخلصات'!$J$8) | J27: =IF('[1]سجل المستخلصات'!$K$8="","",'[1]سجل المستخلصات'!$K$8) | K27: =IF('[1]سجل المستخلصات'!$L$8="","",'[1]سجل المستخلصات'!$L$8) | L27: =IF('[1]سجل المستخلصات'!$M$8="","",'[1]سجل المستخلصات'!$M$8) | M27: =IF('[1]سجل المستخلصات'!$N$8="","",'[1]سجل المستخلصات'!$N$8) | N27: =IF('[1]سجل المستخلصات'!$O$8="","",'[1]سجل المستخلصات'!$O$8) | O27: =IF('[1]سجل المستخلصات'!$R$8="","",'[1]سجل المستخلصات'!$R$8) | P27: =IF('[1]سجل المستخلصات'!$S$8="","",'[1]سجل المستخلصات'!$S$8) | Q27: =IF('[1]سجل المستخلصات'!$T$8="","",'[1]سجل المستخلصات'!$T$8) | R27: =IF('[1]سجل المستخلصات'!$V$8="","",'[1]سجل المستخلصات'!$V$8) | S27: =IF('[1]سجل المستخلصات'!$W$8="","",'[1]سجل المستخلصات'!$W$8) | T27: =IF('[1]سجل المستخلصات'!$X$8="","",'[1]سجل المستخلصات'!$X$8) | U27: =IF('[1]سجل المستخلصات'!$Z$8="","",'[1]سجل المستخلصات'!$Z$8) | V27: =IF('[1]سجل المستخلصات'!$AA$8="","",'[1]سجل المستخلصات'!$AA$8) | W27: =IF('[1]سجل المستخلصات'!$AC$8="","",'[1]سجل المستخلصات'!$AC$8) | X27: =IF('[1]سجل المستخلصات'!$AD$8="","",'[1]سجل المستخلصات'!$AD$8) | Y27: =IF('[1]سجل المستخلصات'!$AE$8="","",'[1]سجل المستخلصات'!$AE$8)
B28: 4 | C28: =IF('[1]سجل المستخلصات'!$C$9="","",'[1]سجل المستخلصات'!$C$9) | D28: =IF('[1]سجل المستخلصات'!$E$9="","",'[1]سجل المستخلصات'!$E$9) | E28: =IF('[1]سجل المستخلصات'!$F$9="","",'[1]سجل المستخلصات'!$F$9) | F28: =IF('[1]سجل المستخلصات'!$H$9="","",'[1]سجل المستخلصات'!$H$9) | G28: =IF('[1]سجل المستخلصات'!$G$9="","",'[1]سجل المستخلصات'!$G$9) | H28: =IF('[1]سجل المستخلصات'!$I$9="","",'[1]سجل المستخلصات'!$I$9) | I28: =IF('[1]سجل المستخلصات'!$J$9="","",'[1]سجل المستخلصات'!$J$9) | J28: =IF('[1]سجل المستخلصات'!$K$9="","",'[1]سجل المستخلصات'!$K$9) | K28: =IF('[1]سجل المستخلصات'!$L$9="","",'[1]سجل المستخلصات'!$L$9) | L28: =IF('[1]سجل المستخلصات'!$M$9="","",'[1]سجل المستخلصات'!$M$9) | M28: =IF('[1]سجل المستخلصات'!$N$9="","",'[1]سجل المستخلصات'!$N$9) | N28: =IF('[1]سجل المستخلصات'!$O$9="","",'[1]سجل المستخلصات'!$O$9) | O28: =IF('[1]سجل المستخلصات'!$R$9="","",'[1]سجل المستخلصات'!$R$9) | P28: =IF('[1]سجل المستخلصات'!$S$9="","",'[1]سجل المستخلصات'!$S$9) | Q28: =IF('[1]سجل المستخلصات'!$T$9="","",'[1]سجل المستخلصات'!$T$9) | R28: =IF('[1]سجل المستخلصات'!$V$9="","",'[1]سجل المستخلصات'!$V$9) | S28: =IF('[1]سجل المستخلصات'!$W$9="","",'[1]سجل المستخلصات'!$W$9) | T28: =IF('[1]سجل المستخلصات'!$X$9="","",'[1]سجل المستخلصات'!$X$9) | U28: =IF('[1]سجل المستخلصات'!$Z$9="","",'[1]سجل المستخلصات'!$Z$9) | V28: =IF('[1]سجل المستخلصات'!$AA$9="","",'[1]سجل المستخلصات'!$AA$9) | W28: =IF('[1]سجل المستخلصات'!$AC$9="","",'[1]سجل المستخلصات'!$AC$9) | X28: =IF('[1]سجل المستخلصات'!$AD$9="","",'[1]سجل المستخلصات'!$AD$9) | Y28: =IF('[1]سجل المستخلصات'!$AE$9="","",'[1]سجل المستخلصات'!$AE$9)
B29: 5 | C29: =IF('[1]سجل المستخلصات'!$C$10="","",'[1]سجل المستخلصات'!$C$10) | D29: =IF('[1]سجل المستخلصات'!$E$10="","",'[1]سجل المستخلصات'!$E$10) | E29: =IF('[1]سجل المستخلصات'!$F$10="","",'[1]سجل المستخلصات'!$F$10) | F29: =IF('[1]سجل المستخلصات'!$H$10="","",'[1]سجل المستخلصات'!$H$10) | G29: =IF('[1]سجل المستخلصات'!$G$10="","",'[1]سجل المستخلصات'!$G$10) | H29: =IF('[1]سجل المستخلصات'!$I$10="","",'[1]سجل المستخلصات'!$I$10) | I29: =IF('[1]سجل المستخلصات'!$J$10="","",'[1]سجل المستخلصات'!$J$10) | J29: =IF('[1]سجل المستخلصات'!$K$10="","",'[1]سجل المستخلصات'!$K$10) | K29: =IF('[1]سجل المستخلصات'!$L$10="","",'[1]سجل المستخلصات'!$L$10) | L29: =IF('[1]سجل المستخلصات'!$M$10="","",'[1]سجل المستخلصات'!$M$10) | M29: =IF('[1]سجل المستخلصات'!$N$10="","",'[1]سجل المستخلصات'!$N$10) | N29: =IF('[1]سجل المستخلصات'!$O$10="","",'[1]سجل المستخلصات'!$O$10) | O29: =IF('[1]سجل المستخلصات'!$R$10="","",'[1]سجل المستخلصات'!$R$10) | P29: =IF('[1]سجل المستخلصات'!$S$10="","",'[1]سجل المستخلصات'!$S$10) | Q29: =IF('[1]سجل المستخلصات'!$T$10="","",'[1]سجل المستخلصات'!$T$10) | R29: =IF('[1]سجل المستخلصات'!$V$10="","",'[1]سجل المستخلصات'!$V$10) | S29: =IF('[1]سجل المستخلصات'!$W$10="","",'[1]سجل المستخلصات'!$W$10) | T29: =IF('[1]سجل المستخلصات'!$X$10="","",'[1]سجل المستخلصات'!$X$10) | U29: =IF('[1]سجل المستخلصات'!$Z$10="","",'[1]سجل المستخلصات'!$Z$10) | V29: =IF('[1]سجل المستخلصات'!$AA$10="","",'[1]سجل المستخلصات'!$AA$10) | W29: =IF('[1]سجل المستخلصات'!$AC$10="","",'[1]سجل المستخلصات'!$AC$10) | X29: =IF('[1]سجل المستخلصات'!$AD$10="","",'[1]سجل المستخلصات'!$AD$10) | Y29: =IF('[1]سجل المستخلصات'!$AE$10="","",'[1]سجل المستخلصات'!$AE$10)
B30: 6 | C30: =IF('[1]سجل المستخلصات'!$C$11="","",'[1]سجل المستخلصات'!$C$11) | D30: =IF('[1]سجل المستخلصات'!$E$11="","",'[1]سجل المستخلصات'!$E$11) | E30: =IF('[1]سجل المستخلصات'!$F$11="","",'[1]سجل المستخلصات'!$F$11) | F30: =IF('[1]سجل المستخلصات'!$H$11="","",'[1]سجل المستخلصات'!$H$11) | G30: =IF('[1]سجل المستخلصات'!$G$11="","",'[1]سجل المستخلصات'!$G$11) | H30: =IF('[1]سجل المستخلصات'!$I$11="","",'[1]سجل المستخلصات'!$I$11) | I30: =IF('[1]سجل المستخلصات'!$J$11="","",'[1]سجل المستخلصات'!$J$11) | J30: =IF('[1]سجل المستخلصات'!$K$11="","",'[1]سجل المستخلصات'!$K$11) | K30: =IF('[1]سجل المستخلصات'!$L$11="","",'[1]سجل المستخلصات'!$L$11) | L30: =IF('[1]سجل المستخلصات'!$M$11="","",'[1]سجل المستخلصات'!$M$11) | M30: =IF('[1]سجل المستخلصات'!$N$11="","",'[1]سجل المستخلصات'!$N$11) | N30: =IF('[1]سجل المستخلصات'!$O$11="","",'[1]سجل المستخلصات'!$O$11) | O30: =IF('[1]سجل المستخلصات'!$R$11="","",'[1]سجل المستخلصات'!$R$11) | P30: =IF('[1]سجل المستخلصات'!$S$11="","",'[1]سجل المستخلصات'!$S$11) | Q30: =IF('[1]سجل المستخلصات'!$T$11="","",'[1]سجل المستخلصات'!$T$11) | R30: =IF('[1]سجل المستخلصات'!$V$11="","",'[1]سجل المستخلصات'!$V$11) | S30: =IF('[1]سجل المستخلصات'!$W$11="","",'[1]سجل المستخلصات'!$W$11) | T30: =IF('[1]سجل المستخلصات'!$X$11="","",'[1]سجل المستخلصات'!$X$11) | U30: =IF('[1]سجل المستخلصات'!$Z$11="","",'[1]سجل المستخلصات'!$Z$11) | V30: =IF('[1]سجل المستخلصات'!$AA$11="","",'[1]سجل المستخلصات'!$AA$11) | W30: =IF('[1]سجل المستخلصات'!$AC$11="","",'[1]سجل المستخلصات'!$AC$11) | X30: =IF('[1]سجل المستخلصات'!$AD$11="","",'[1]سجل المستخلصات'!$AD$11) | Y30: =IF('[1]سجل المستخلصات'!$AE$11="","",'[1]سجل المستخلصات'!$AE$11)
B31: 7 | C31: =IF('[1]سجل المستخلصات'!$C$12="","",'[1]سجل المستخلصات'!$C$12) | D31: =IF('[1]سجل المستخلصات'!$E$12="","",'[1]سجل المستخلصات'!$E$12) | E31: =IF('[1]سجل المستخلصات'!$F$12="","",'[1]سجل المستخلصات'!$F$12) | F31: =IF('[1]سجل المستخلصات'!$H$12="","",'[1]سجل المستخلصات'!$H$12) | G31: =IF('[1]سجل المستخلصات'!$G$12="","",'[1]سجل المستخلصات'!$G$12) | H31: =IF('[1]سجل المستخلصات'!$I$12="","",'[1]سجل المستخلصات'!$I$12) | I31: =IF('[1]سجل المستخلصات'!$J$12="","",'[1]سجل المستخلصات'!$J$12) | J31: =IF('[1]سجل المستخلصات'!$K$12="","",'[1]سجل المستخلصات'!$K$12) | K31: =IF('[1]سجل المستخلصات'!$L$12="","",'[1]سجل المستخلصات'!$L$12) | L31: =IF('[1]سجل المستخلصات'!$M$12="","",'[1]سجل المستخلصات'!$M$12) | M31: =IF('[1]سجل المستخلصات'!$N$12="","",'[1]سجل المستخلصات'!$N$12) | N31: =IF('[1]سجل المستخلصات'!$O$12="","",'[1]سجل المستخلصات'!$O$12) | O31: =IF('[1]سجل المستخلصات'!$R$12="","",'[1]سجل المستخلصات'!$R$12) | P31: =IF('[1]سجل المستخلصات'!$S$12="","",'[1]سجل المستخلصات'!$S$12) | Q31: =IF('[1]سجل المستخلصات'!$T$12="","",'[1]سجل المستخلصات'!$T$12) | R31: =IF('[1]سجل المستخلصات'!$V$12="","",'[1]سجل المستخلصات'!$V$12) | S31: =IF('[1]سجل المستخلصات'!$W$12="","",'[1]سجل المستخلصات'!$W$12) | T31: =IF('[1]سجل المستخلصات'!$X$12="","",'[1]سجل المستخلصات'!$X$12) | U31: =IF('[1]سجل المستخلصات'!$Z$12="","",'[1]سجل المستخلصات'!$Z$12) | V31: =IF('[1]سجل المستخلصات'!$AA$12="","",'[1]سجل المستخلصات'!$AA$12) | W31: =IF('[1]سجل المستخلصات'!$AC$12="","",'[1]سجل المستخلصات'!$AC$12) | X31: =IF('[1]سجل المستخلصات'!$AD$12="","",'[1]سجل المستخلصات'!$AD$12) | Y31: =IF('[1]سجل المستخلصات'!$AE$12="","",'[1]سجل المستخلصات'!$AE$12)
B32: 8 | C32: =IF('[1]سجل المستخلصات'!$C$13="","",'[1]سجل المستخلصات'!$C$13) | D32: =IF('[1]سجل المستخلصات'!$E$13="","",'[1]سجل المستخلصات'!$E$13) | E32: =IF('[1]سجل المستخلصات'!$F$13="","",'[1]سجل المستخلصات'!$F$13) | F32: =IF('[1]سجل المستخلصات'!$H$13="","",'[1]سجل المستخلصات'!$H$13) | G32: =IF('[1]سجل المستخلصات'!$G$13="","",'[1]سجل المستخلصات'!$G$13) | H32: =IF('[1]سجل المستخلصات'!$I$13="","",'[1]سجل المستخلصات'!$I$13) | I32: =IF('[1]سجل المستخلصات'!$J$13="","",'[1]سجل المستخلصات'!$J$13) | J32: =IF('[1]سجل المستخلصات'!$K$13="","",'[1]سجل المستخلصات'!$K$13) | K32: =IF('[1]سجل المستخلصات'!$L$13="","",'[1]سجل المستخلصات'!$L$13) | L32: =IF('[1]سجل المستخلصات'!$M$13="","",'[1]سجل المستخلصات'!$M$13) | M32: =IF('[1]سجل المستخلصات'!$N$13="","",'[1]سجل المستخلصات'!$N$13) | N32: =IF('[1]سجل المستخلصات'!$O$13="","",'[1]سجل المستخلصات'!$O$13) | O32: =IF('[1]سجل المستخلصات'!$R$13="","",'[1]سجل المستخلصات'!$R$13) | P32: =IF('[1]سجل المستخلصات'!$S$13="","",'[1]سجل المستخلصات'!$S$13) | Q32: =IF('[1]سجل المستخلصات'!$T$13="","",'[1]سجل المستخلصات'!$T$13) | R32: =IF('[1]سجل المستخلصات'!$V$13="","",'[1]سجل المستخلصات'!$V$13) | S32: =IF('[1]سجل المستخلصات'!$W$13="","",'[1]سجل المستخلصات'!$W$13) | T32: =IF('[1]سجل المستخلصات'!$X$13="","",'[1]سجل المستخلصات'!$X$13) | U32: =IF('[1]سجل المستخلصات'!$Z$13="","",'[1]سجل المستخلصات'!$Z$13) | V32: =IF('[1]سجل المستخلصات'!$AA$13="","",'[1]سجل المستخلصات'!$AA$13) | W32: =IF('[1]سجل المستخلصات'!$AC$13="","",'[1]سجل المستخلصات'!$AC$13) | X32: =IF('[1]سجل المستخلصات'!$AD$13="","",'[1]سجل المستخلصات'!$AD$13) | Y32: =IF('[1]سجل المستخلصات'!$AE$13="","",'[1]سجل المستخلصات'!$AE$13)
B33: 9 | C33: =IF('[1]سجل المستخلصات'!$C$14="","",'[1]سجل المستخلصات'!$C$14) | D33: =IF('[1]سجل المستخلصات'!$E$14="","",'[1]سجل المستخلصات'!$E$14) | E33: =IF('[1]سجل المستخلصات'!$F$14="","",'[1]سجل المستخلصات'!$F$14) | F33: =IF('[1]سجل المستخلصات'!$H$14="","",'[1]سجل المستخلصات'!$H$14) | G33: =IF('[1]سجل المستخلصات'!$G$14="","",'[1]سجل المستخلصات'!$G$14) | H33: =IF('[1]سجل المستخلصات'!$I$14="","",'[1]سجل المستخلصات'!$I$14) | I33: =IF('[1]سجل المستخلصات'!$J$14="","",'[1]سجل المستخلصات'!$J$14) | J33: =IF('[1]سجل المستخلصات'!$K$14="","",'[1]سجل المستخلصات'!$K$14) | K33: =IF('[1]سجل المستخلصات'!$L$14="","",'[1]سجل المستخلصات'!$L$14) | L33: =IF('[1]سجل المستخلصات'!$M$14="","",'[1]سجل المستخلصات'!$M$14) | M33: =IF('[1]سجل المستخلصات'!$N$14="","",'[1]سجل المستخلصات'!$N$14) | N33: =IF('[1]سجل المستخلصات'!$O$14="","",'[1]سجل المستخلصات'!$O$14) | O33: =IF('[1]سجل المستخلصات'!$R$14="","",'[1]سجل المستخلصات'!$R$14) | P33: =IF('[1]سجل المستخلصات'!$S$14="","",'[1]سجل المستخلصات'!$S$14) | Q33: =IF('[1]سجل المستخلصات'!$T$14="","",'[1]سجل المستخلصات'!$T$14) | R33: =IF('[1]سجل المستخلصات'!$V$14="","",'[1]سجل المستخلصات'!$V$14) | S33: =IF('[1]سجل المستخلصات'!$W$14="","",'[1]سجل المستخلصات'!$W$14) | T33: =IF('[1]سجل المستخلصات'!$X$14="","",'[1]سجل المستخلصات'!$X$14) | U33: =IF('[1]سجل المستخلصات'!$Z$14="","",'[1]سجل المستخلصات'!$Z$14) | V33: =IF('[1]سجل المستخلصات'!$AA$14="","",'[1]سجل المستخلصات'!$AA$14) | W33: =IF('[1]سجل المستخلصات'!$AC$14="","",'[1]سجل المستخلصات'!$AC$14) | X33: =IF('[1]سجل المستخلصات'!$AD$14="","",'[1]سجل المستخلصات'!$AD$14) | Y33: =IF('[1]سجل المستخلصات'!$AE$14="","",'[1]سجل المستخلصات'!$AE$14)
B34: 10 | C34: =IF('[1]سجل المستخلصات'!$C$15="","",'[1]سجل المستخلصات'!$C$15) | D34: =IF('[1]سجل المستخلصات'!$E$15="","",'[1]سجل المستخلصات'!$E$15) | E34: =IF('[1]سجل المستخلصات'!$F$15="","",'[1]سجل المستخلصات'!$F$15) | F34: =IF('[1]سجل المستخلصات'!$H$15="","",'[1]سجل المستخلصات'!$H$15) | G34: =IF('[1]سجل المستخلصات'!$G$15="","",'[1]سجل المستخلصات'!$G$15) | H34: =IF('[1]سجل المستخلصات'!$I$15="","",'[1]سجل المستخلصات'!$I$15) | I34: =IF('[1]سجل المستخلصات'!$J$15="","",'[1]سجل المستخلصات'!$J$15) | J34: =IF('[1]سجل المستخلصات'!$K$15="","",'[1]سجل المستخلصات'!$K$15) | K34: =IF('[1]سجل المستخلصات'!$L$15="","",'[1]سجل المستخلصات'!$L$15) | L34: =IF('[1]سجل المستخلصات'!$M$15="","",'[1]سجل المستخلصات'!$M$15) | M34: =IF('[1]سجل المستخلصات'!$N$15="","",'[1]سجل المستخلصات'!$N$15) | N34: =IF('[1]سجل المستخلصات'!$O$15="","",'[1]سجل المستخلصات'!$O$15) | O34: =IF('[1]سجل المستخلصات'!$R$15="","",'[1]سجل المستخلصات'!$R$15) | P34: =IF('[1]سجل المستخلصات'!$S$15="","",'[1]سجل المستخلصات'!$S$15) | Q34: =IF('[1]سجل المستخلصات'!$T$15="","",'[1]سجل المستخلصات'!$T$15) | R34: =IF('[1]سجل المستخلصات'!$V$15="","",'[1]سجل المستخلصات'!$V$15) | S34: =IF('[1]سجل المستخلصات'!$W$15="","",'[1]سجل المستخلصات'!$W$15) | T34: =IF('[1]سجل المستخلصات'!$X$15="","",'[1]سجل المستخلصات'!$X$15) | U34: =IF('[1]سجل المستخلصات'!$Z$15="","",'[1]سجل المستخلصات'!$Z$15) | V34: =IF('[1]سجل المستخلصات'!$AA$15="","",'[1]سجل المستخلصات'!$AA$15) | W34: =IF('[1]سجل المستخلصات'!$AC$15="","",'[1]سجل المستخلصات'!$AC$15) | X34: =IF('[1]سجل المستخلصات'!$AD$15="","",'[1]سجل المستخلصات'!$AD$15) | Y34: =IF('[1]سجل المستخلصات'!$AE$15="","",'[1]سجل المستخلصات'!$AE$15)
B35: 11 | C35: =IF('[1]سجل المستخلصات'!$C$16="","",'[1]سجل المستخلصات'!$C$16) | D35: =IF('[1]سجل المستخلصات'!$E$16="","",'[1]سجل المستخلصات'!$E$16) | E35: =IF('[1]سجل المستخلصات'!$F$16="","",'[1]سجل المستخلصات'!$F$16) | F35: =IF('[1]سجل المستخلصات'!$H$16="","",'[1]سجل المستخلصات'!$H$16) | G35: =IF('[1]سجل المستخلصات'!$G$16="","",'[1]سجل المستخلصات'!$G$16) | H35: =IF('[1]سجل المستخلصات'!$I$16="","",'[1]سجل المستخلصات'!$I$16) | I35: =IF('[1]سجل المستخلصات'!$J$16="","",'[1]سجل المستخلصات'!$J$16) | J35: =IF('[1]سجل المستخلصات'!$K$16="","",'[1]سجل المستخلصات'!$K$16) | K35: =IF('[1]سجل المستخلصات'!$L$16="","",'[1]سجل المستخلصات'!$L$16) | L35: =IF('[1]سجل المستخلصات'!$M$16="","",'[1]سجل المستخلصات'!$M$16) | M35: =IF('[1]سجل المستخلصات'!$N$16="","",'[1]سجل المستخلصات'!$N$16) | N35: =IF('[1]سجل المستخلصات'!$O$16="","",'[1]سجل المستخلصات'!$O$16) | O35: =IF('[1]سجل المستخلصات'!$R$16="","",'[1]سجل المستخلصات'!$R$16) | P35: =IF('[1]سجل المستخلصات'!$S$16="","",'[1]سجل المستخلصات'!$S$16) | Q35: =IF('[1]سجل المستخلصات'!$T$16="","",'[1]سجل المستخلصات'!$T$16) | R35: =IF('[1]سجل المستخلصات'!$V$16="","",'[1]سجل المستخلصات'!$V$16) | S35: =IF('[1]سجل المستخلصات'!$W$16="","",'[1]سجل المستخلصات'!$W$16) | T35: =IF('[1]سجل المستخلصات'!$X$16="","",'[1]سجل المستخلصات'!$X$16) | U35: =IF('[1]سجل المستخلصات'!$Z$16="","",'[1]سجل المستخلصات'!$Z$16) | V35: =IF('[1]سجل المستخلصات'!$AA$16="","",'[1]سجل المستخلصات'!$AA$16) | W35: =IF('[1]سجل المستخلصات'!$AC$16="","",'[1]سجل المستخلصات'!$AC$16) | X35: =IF('[1]سجل المستخلصات'!$AD$16="","",'[1]سجل المستخلصات'!$AD$16) | Y35: =IF('[1]سجل المستخلصات'!$AE$16="","",'[1]سجل المستخلصات'!$AE$16)
B36: 12 | C36: =IF('[1]سجل المستخلصات'!$C$17="","",'[1]سجل المستخلصات'!$C$17) | D36: =IF('[1]سجل المستخلصات'!$E$17="","",'[1]سجل المستخلصات'!$E$17) | E36: =IF('[1]سجل المستخلصات'!$F$17="","",'[1]سجل المستخلصات'!$F$17) | F36: =IF('[1]سجل المستخلصات'!$H$17="","",'[1]سجل المستخلصات'!$H$17) | G36: =IF('[1]سجل المستخلصات'!$G$17="","",'[1]سجل المستخلصات'!$G$17) | H36: =IF('[1]سجل المستخلصات'!$I$17="","",'[1]سجل المستخلصات'!$I$17) | I36: =IF('[1]سجل المستخلصات'!$J$17="","",'[1]سجل المستخلصات'!$J$17) | J36: =IF('[1]سجل المستخلصات'!$K$17="","",'[1]سجل المستخلصات'!$K$17) | K36: =IF('[1]سجل المستخلصات'!$L$17="","",'[1]سجل المستخلصات'!$L$17) | L36: =IF('[1]سجل المستخلصات'!$M$17="","",'[1]سجل المستخلصات'!$M$17) | M36: =IF('[1]سجل المستخلصات'!$N$17="","",'[1]سجل المستخلصات'!$N$17) | N36: =IF('[1]سجل المستخلصات'!$O$17="","",'[1]سجل المستخلصات'!$O$17) | O36: =IF('[1]سجل المستخلصات'!$R$17="","",'[1]سجل المستخلصات'!$R$17) | P36: =IF('[1]سجل المستخلصات'!$S$17="","",'[1]سجل المستخلصات'!$S$17) | Q36: =IF('[1]سجل المستخلصات'!$T$17="","",'[1]سجل المستخلصات'!$T$17) | R36: =IF('[1]سجل المستخلصات'!$V$17="","",'[1]سجل المستخلصات'!$V$17) | S36: =IF('[1]سجل المستخلصات'!$W$17="","",'[1]سجل المستخلصات'!$W$17) | T36: =IF('[1]سجل المستخلصات'!$X$17="","",'[1]سجل المستخلصات'!$X$17) | U36: =IF('[1]سجل المستخلصات'!$Z$17="","",'[1]سجل المستخلصات'!$Z$17) | V36: =IF('[1]سجل المستخلصات'!$AA$17="","",'[1]سجل المستخلصات'!$AA$17) | W36: =IF('[1]سجل المستخلصات'!$AC$17="","",'[1]سجل المستخلصات'!$AC$17) | X36: =IF('[1]سجل المستخلصات'!$AD$17="","",'[1]سجل المستخلصات'!$AD$17) | Y36: =IF('[1]سجل المستخلصات'!$AE$17="","",'[1]سجل المستخلصات'!$AE$17)
B37: 13 | C37: =IF('[1]سجل المستخلصات'!$C$18="","",'[1]سجل المستخلصات'!$C$18) | D37: =IF('[1]سجل المستخلصات'!$E$18="","",'[1]سجل المستخلصات'!$E$18) | E37: =IF('[1]سجل المستخلصات'!$F$18="","",'[1]سجل المستخلصات'!$F$18) | F37: =IF('[1]سجل المستخلصات'!$H$18="","",'[1]سجل المستخلصات'!$H$18) | G37: =IF('[1]سجل المستخلصات'!$G$18="","",'[1]سجل المستخلصات'!$G$18) | H37: =IF('[1]سجل المستخلصات'!$I$18="","",'[1]سجل المستخلصات'!$I$18) | I37: =IF('[1]سجل المستخلصات'!$J$18="","",'[1]سجل المستخلصات'!$J$18) | J37: =IF('[1]سجل المستخلصات'!$K$18="","",'[1]سجل المستخلصات'!$K$18) | K37: =IF('[1]سجل المستخلصات'!$L$18="","",'[1]سجل المستخلصات'!$L$18) | L37: =IF('[1]سجل المستخلصات'!$M$18="","",'[1]سجل المستخلصات'!$M$18) | M37: =IF('[1]سجل المستخلصات'!$N$18="","",'[1]سجل المستخلصات'!$N$18) | N37: =IF('[1]سجل المستخلصات'!$O$18="","",'[1]سجل المستخلصات'!$O$18) | O37: =IF('[1]سجل المستخلصات'!$R$18="","",'[1]سجل المستخلصات'!$R$18) | P37: =IF('[1]سجل المستخلصات'!$S$18="","",'[1]سجل المستخلصات'!$S$18) | Q37: =IF('[1]سجل المستخلصات'!$T$18="","",'[1]سجل المستخلصات'!$T$18) | R37: =IF('[1]سجل المستخلصات'!$V$18="","",'[1]سجل المستخلصات'!$V$18) | S37: =IF('[1]سجل المستخلصات'!$W$18="","",'[1]سجل المستخلصات'!$W$18) | T37: =IF('[1]سجل المستخلصات'!$X$18="","",'[1]سجل المستخلصات'!$X$18) | U37: =IF('[1]سجل المستخلصات'!$Z$18="","",'[1]سجل المستخلصات'!$Z$18) | V37: =IF('[1]سجل المستخلصات'!$AA$18="","",'[1]سجل المستخلصات'!$AA$18) | W37: =IF('[1]سجل المستخلصات'!$AC$18="","",'[1]سجل المستخلصات'!$AC$18) | X37: =IF('[1]سجل المستخلصات'!$AD$18="","",'[1]سجل المستخلصات'!$AD$18) | Y37: =IF('[1]سجل المستخلصات'!$AE$18="","",'[1]سجل المستخلصات'!$AE$18)
B38: 14 | C38: =IF('[1]سجل المستخلصات'!$C$19="","",'[1]سجل المستخلصات'!$C$19) | D38: =IF('[1]سجل المستخلصات'!$E$19="","",'[1]سجل المستخلصات'!$E$19) | E38: =IF('[1]سجل المستخلصات'!$F$19="","",'[1]سجل المستخلصات'!$F$19) | F38: =IF('[1]سجل المستخلصات'!$H$19="","",'[1]سجل المستخلصات'!$H$19) | G38: =IF('[1]سجل المستخلصات'!$G$19="","",'[1]سجل المستخلصات'!$G$19) | H38: =IF('[1]سجل المستخلصات'!$I$19="","",'[1]سجل المستخلصات'!$I$19) | I38: =IF('[1]سجل المستخلصات'!$J$19="","",'[1]سجل المستخلصات'!$J$19) | J38: =IF('[1]سجل المستخلصات'!$K$19="","",'[1]سجل المستخلصات'!$K$19) | K38: =IF('[1]سجل المستخلصات'!$L$19="","",'[1]سجل المستخلصات'!$L$19) | L38: =IF('[1]سجل المستخلصات'!$M$19="","",'[1]سجل المستخلصات'!$M$19) | M38: =IF('[1]سجل المستخلصات'!$N$19="","",'[1]سجل المستخلصات'!$N$19) | N38: =IF('[1]سجل المستخلصات'!$O$19="","",'[1]سجل المستخلصات'!$O$19) | O38: =IF('[1]سجل المستخلصات'!$R$19="","",'[1]سجل المستخلصات'!$R$19) | P38: =IF('[1]سجل المستخلصات'!$S$19="","",'[1]سجل المستخلصات'!$S$19) | Q38: =IF('[1]سجل المستخلصات'!$T$19="","",'[1]سجل المستخلصات'!$T$19) | R38: =IF('[1]سجل المستخلصات'!$V$19="","",'[1]سجل المستخلصات'!$V$19) | S38: =IF('[1]سجل المستخلصات'!$W$19="","",'[1]سجل المستخلصات'!$W$19) | T38: =IF('[1]سجل المستخلصات'!$X$19="","",'[1]سجل المستخلصات'!$X$19) | U38: =IF('[1]سجل المستخلصات'!$Z$19="","",'[1]سجل المستخلصات'!$Z$19) | V38: =IF('[1]سجل المستخلصات'!$AA$19="","",'[1]سجل المستخلصات'!$AA$19) | W38: =IF('[1]سجل المستخلصات'!$AC$19="","",'[1]سجل المستخلصات'!$AC$19) | X38: =IF('[1]سجل المستخلصات'!$AD$19="","",'[1]سجل المستخلصات'!$AD$19) | Y38: =IF('[1]سجل المستخلصات'!$AE$19="","",'[1]سجل المستخلصات'!$AE$19)
B39: 15 | C39: =IF('[1]سجل المستخلصات'!$C$20="","",'[1]سجل المستخلصات'!$C$20) | D39: =IF('[1]سجل المستخلصات'!$E$20="","",'[1]سجل المستخلصات'!$E$20) | E39: =IF('[1]سجل المستخلصات'!$F$20="","",'[1]سجل المستخلصات'!$F$20) | F39: =IF('[1]سجل المستخلصات'!$H$20="","",'[1]سجل المستخلصات'!$H$20) | G39: =IF('[1]سجل المستخلصات'!$G$20="","",'[1]سجل المستخلصات'!$G$20) | H39: =IF('[1]سجل المستخلصات'!$I$20="","",'[1]سجل المستخلصات'!$I$20) | I39: =IF('[1]سجل المستخلصات'!$J$20="","",'[1]سجل المستخلصات'!$J$20) | J39: =IF('[1]سجل المستخلصات'!$K$20="","",'[1]سجل المستخلصات'!$K$20) | K39: =IF('[1]سجل المستخلصات'!$L$20="","",'[1]سجل المستخلصات'!$L$20) | L39: =IF('[1]سجل المستخلصات'!$M$20="","",'[1]سجل المستخلصات'!$M$20) | M39: =IF('[1]سجل المستخلصات'!$N$20="","",'[1]سجل المستخلصات'!$N$20) | N39: =IF('[1]سجل المستخلصات'!$O$20="","",'[1]سجل المستخلصات'!$O$20) | O39: =IF('[1]سجل المستخلصات'!$R$20="","",'[1]سجل المستخلصات'!$R$20) | P39: =IF('[1]سجل المستخلصات'!$S$20="","",'[1]سجل المستخلصات'!$S$20) | Q39: =IF('[1]سجل المستخلصات'!$T$20="","",'[1]سجل المستخلصات'!$T$20) | R39: =IF('[1]سجل المستخلصات'!$V$20="","",'[1]سجل المستخلصات'!$V$20) | S39: =IF('[1]سجل المستخلصات'!$W$20="","",'[1]سجل المستخلصات'!$W$20) | T39: =IF('[1]سجل المستخلصات'!$X$20="","",'[1]سجل المستخلصات'!$X$20) | U39: =IF('[1]سجل المستخلصات'!$Z$20="","",'[1]سجل المستخلصات'!$Z$20) | V39: =IF('[1]سجل المستخلصات'!$AA$20="","",'[1]سجل المستخلصات'!$AA$20) | W39: =IF('[1]سجل المستخلصات'!$AC$20="","",'[1]سجل المستخلصات'!$AC$20) | X39: =IF('[1]سجل المستخلصات'!$AD$20="","",'[1]سجل المستخلصات'!$AD$20) | Y39: =IF('[1]سجل المستخلصات'!$AE$20="","",'[1]سجل المستخلصات'!$AE$20)
B40: 16 | C40: =IF('[1]سجل المستخلصات'!$C$21="","",'[1]سجل المستخلصات'!$C$21) | D40: =IF('[1]سجل المستخلصات'!$E$21="","",'[1]سجل المستخلصات'!$E$21) | E40: =IF('[1]سجل المستخلصات'!$F$21="","",'[1]سجل المستخلصات'!$F$21) | F40: =IF('[1]سجل المستخلصات'!$H$21="","",'[1]سجل المستخلصات'!$H$21) | G40: =IF('[1]سجل المستخلصات'!$G$21="","",'[1]سجل المستخلصات'!$G$21) | H40: =IF('[1]سجل المستخلصات'!$I$21="","",'[1]سجل المستخلصات'!$I$21) | I40: =IF('[1]سجل المستخلصات'!$J$21="","",'[1]سجل المستخلصات'!$J$21) | J40: =IF('[1]سجل المستخلصات'!$K$21="","",'[1]سجل المستخلصات'!$K$21) | K40: =IF('[1]سجل المستخلصات'!$L$21="","",'[1]سجل المستخلصات'!$L$21) | L40: =IF('[1]سجل المستخلصات'!$M$21="","",'[1]سجل المستخلصات'!$M$21) | M40: =IF('[1]سجل المستخلصات'!$N$21="","",'[1]سجل المستخلصات'!$N$21) | N40: =IF('[1]سجل المستخلصات'!$O$21="","",'[1]سجل المستخلصات'!$O$21) | O40: =IF('[1]سجل المستخلصات'!$R$21="","",'[1]سجل المستخلصات'!$R$21) | P40: =IF('[1]سجل المستخلصات'!$S$21="","",'[1]سجل المستخلصات'!$S$21) | Q40: =IF('[1]سجل المستخلصات'!$T$21="","",'[1]سجل المستخلصات'!$T$21) | R40: =IF('[1]سجل المستخلصات'!$V$21="","",'[1]سجل المستخلصات'!$V$21) | S40: =IF('[1]سجل المستخلصات'!$W$21="","",'[1]سجل المستخلصات'!$W$21) | T40: =IF('[1]سجل المستخلصات'!$X$21="","",'[1]سجل المستخلصات'!$X$21) | U40: =IF('[1]سجل المستخلصات'!$Z$21="","",'[1]سجل المستخلصات'!$Z$21) | V40: =IF('[1]سجل المستخلصات'!$AA$21="","",'[1]سجل المستخلصات'!$AA$21) | W40: =IF('[1]سجل المستخلصات'!$AC$21="","",'[1]سجل المستخلصات'!$AC$21) | X40: =IF('[1]سجل المستخلصات'!$AD$21="","",'[1]سجل المستخلصات'!$AD$21) | Y40: =IF('[1]سجل المستخلصات'!$AE$21="","",'[1]سجل المستخلصات'!$AE$21)
...

Sheet مشروع 02
B1: ="📊 "&IF('[2]بيانات العقد'!$C$5="","مشروع رقم 02 — غير مُفعّل",'[2]بيانات العقد'!$C$5)
B2: ="تقارير المستخلصات المجمعة لكل المشاريع | تاريخ التقرير: "&TEXT(TODAY(),"yyyy/mm/dd")
B3: 🏠 الإجمالي العام | C3: ◄ المشروع السابق | D3: المشروع التالي ► | F3: 📂 فتح ملف المستخلصات: Project_02/IPC_Project_02.xlsx | N3: يُحدَّث آلياً من ملف المستخلصات (تمكين المحتوى ← تحديث الروابط)
AA4: بيانات مرتبطة من ملف المستخلصات
B5: المشروع | C5: =IF('[2]بيانات العقد'!$C$5="","",'[2]بيانات العقد'!$C$5) | G5: رقم العقد | H5: =IF('[2]بيانات العقد'!$C$6="","",'[2]بيانات العقد'!$C$6) | L5: صاحب العمل | M5: =IF('[2]بيانات العقد'!$C$7="","",'[2]بيانات العقد'!$C$7) | R5: الاستشاري | S5: =IF('[2]بيانات العقد'!$C$8="","",'[2]بيانات العقد'!$C$8) | AA5: قيمة العقد الأصلية | AB5: =N('[2]بيانات العقد'!$C$16)
B6: المقاول | C6: =IF('[2]بيانات العقد'!$C$9="","",'[2]بيانات العقد'!$C$9) | G6: تاريخ البدء | H6: =IF('[2]بيانات العقد'!$C$11="","",'[2]بيانات العقد'!$C$11) | L6: الانتهاء التعاقدي | M6: =IF('[2]بيانات العقد'!$C$13="","",'[2]بيانات العقد'!$C$13) | R6: العملة | S6: =IF('[2]بيانات العقد'!$C$14="","",'[2]بيانات العقد'!$C$14) | AA6: صافي التغييرية المعتمدة | AB6: =N('[2]بيانات العقد'!$C$17)
AA7: قيمة العقد المعدلة | AB7: =N('[2]بيانات العقد'!$C$18)
B8: قيمة العقد الأصلية | F8: صافي الأوامر التغييرية | J8: قيمة العقد المعدلة | N8: إجمالي قيمة الأعمال التراكمية | R8: الأعمال المتبقية | V8: آخر مستخلص فعال | AA8: نسبة الدفعة المقدمة | AB8: =N('[2]بيانات العقد'!$C$20)
B9: =$AB$5 | F9: =$AB$6 | J9: =$AB$7 | N9: =IF($V$9=0,0,N(INDEX($J$25:$J$44,$V$9))) | R9: =MAX(0,$AB$7-IF($V$9=0,0,N(INDEX($G$25:$G$44,$V$9)))-IF($V$9=0,0,N(INDEX($H$25:$H$44,$V$9)))) | V9: =SUMPRODUCT(MAX((C25:C44<>"")*B25:B44)) | AA9: قيمة الدفعة المقدمة | AB9: =N('[2]بيانات العقد'!$C$21)
AA10: نسبة ضمان الأعمال | AB10: =N('[2]بيانات العقد'!$C$27)
B11: نسبة الإنجاز الفعلية | F11: نسبة الإنجاز المخططة | J11: الانحراف (فعلي - مخطط) | N11: نسبة المدة المنقضية | R11: مؤشر أداء الجدول (SPI) | V11: حالة المشروع | AA11: الحد الأقصى للضمان | AB11: =N('[2]بيانات العقد'!$C$29)
B12: =IF($V$9=0,0,N(INDEX($K$25:$K$44,$V$9))) | F12: =IF($V$9=0,0,N(INDEX($L$25:$L$44,$V$9))) | J12: =B12-F12 | N12: =IF(OR($V$9=0,$AB$14="",$AB$15=""),0,MIN(1,MAX(0,(INDEX(C25:C44,$V$9)-$AB$14+1)/($AB$15-$AB$14+1)))) | R12: =IF(F12>0,B12/F12,0) | V12: =IF($AB$7=0,"غير مُفعّل",IF($V$9=0,"لم يبدأ الصرف",IF(J12<-0.05,"⚠ متأخر",IF(J12<0,"متأخر قليلاً","✔ مطابق / متقدم")))) | AA12: ضريبة القيمة المضافة | AB12: =N('[2]بيانات العقد'!$C$31)
AA13: ضريبة الاستقطاع (غير المقيم) | AB13: =N('[2]بيانات العقد'!$C$33)
B14: صافي المستحق التراكمي | F14: إجمالي المحصل | J14: مستحقات غير محصلة | N14: نسبة التحصيل | R14: متوسط مدة التحصيل (يوم) | V14: تاريخ آخر مستخلص | AA14: تاريخ البدء | AB14: =IF('[2]بيانات العقد'!$C$11="","",'[2]بيانات العقد'!$C$11)
B15: =IF($V$9=0,0,N(INDEX($T$25:$T$44,$V$9))) | F15: =V45 | J15: =W45 | N15: =IF(B15>0,F15/B15,0) | R15: =X45 | V15: =IF($V$9=0,"",INDEX(C25:C44,$V$9)) | AA15: تاريخ الانتهاء التعاقدي | AB15: =IF('[2]بيانات العقد'!$C$13="","",'[2]بيانات العقد'!$C$13)
AA16: المدة (شهر) | AB16: =IF('[2]بيانات العقد'!$C$12="","",'[2]بيانات العقد'!$C$12)
B17: ضمان الأعمال المحتجز | F17: رصيد الدفعة المقدمة غير المسترد | J17: الاستقطاعات الفنية المحتجزة | N17: الغرامات والخصومات | R17: مستحق آخر مستخلص | V17: عدد المستخلصات المعتمدة | AA17: نوع العقد | AB17: =IF('[2]بيانات العقد'!$C$36="","",'[2]بيانات العقد'!$C$36)
B18: =IF($V$9=0,0,N(INDEX($O$25:$O$44,$V$9))) | F18: =MAX(0,$AB$9-IF($V$9=0,0,N(INDEX($N$25:$N$44,$V$9)))) | J18: =IF($V$9=0,0,N(INDEX($P$25:$P$44,$V$9))) | N18: =IF($V$9=0,0,N(INDEX($Q$25:$Q$44,$V$9))) | R18: =IF($V$9=0,0,N(INDEX($U$25:$U$44,$V$9))) | V18: =COUNTIF(E25:E44,"معتمد") | AA18: الرقم الضريبي للمقاول | AB18: =IF('[2]بيانات العقد'!$C$37="","",'[2]بيانات العقد'!$C$37)
AA19: الرقم الضريبي لصاحب العمل | AB19: =IF('[2]بيانات العقد'!$C$39="","",'[2]بيانات العقد'!$C$39)
B20: الموازنة التقديرية (BAC) | F20: التكلفة الفعلية التراكمية | J20: الربح الفعلي التراكمي | N20: هامش الربح الفعلي | R20: مؤشر أداء التكلفة (CPI) | V20: الربح المتوقع عند الإنجاز | AA20: انتهاء الضمان النهائي | AB20: =IF('[2]بيانات العقد'!$C$42="","",'[2]بيانات العقد'!$C$42)
B21: =N('[2]الموازنة والتكاليف'!$D$66) | F21: =N('[2]الموازنة والتكاليف'!$D$70) | J21: =N('[2]الموازنة والتكاليف'!$D$72) | N21: =N('[2]الموازنة والتكاليف'!$D$73) | R21: =N('[2]الموازنة والتكاليف'!$D$74) | V21: =N('[2]الموازنة والتكاليف'!$D$76) | AA21: انتهاء ضمان الدفعة المقدمة | AB21: =IF('[2]بيانات العقد'!$C$43="","",'[2]بيانات العقد'!$C$43)
AA22: حالة غرامات التأخير | AB22: =IF('[2]بيانات العقد'!$C$47="","",'[2]بيانات العقد'!$C$47)
B23: سجل المستخلصات (مرتبط)
B24: رقم المستخلص | C24: الفترة إلى | D24: تاريخ الاعتماد | E24: حالة المستخلص | F24: أعمال الفترة | G24: الأعمال المنفذة التراكمية | H24: التغييرية التراكمية | I24: رصيد المواد بالموقع | J24: إجمالي القيمة التراكمية | K24: نسبة الإنجاز الفعلية | L24: نسبة الإنجاز المخططة | M24: الانحراف | N24: استرداد الدفعة المقدمة | O24: صافي الضمان المحتجز | P24: الاستقطاعات الفنية | Q24: الغرامات والخصومات | R24: ضريبة القيمة المضافة | S24: ضريبة الاستقطاع | T24: صافي المستحق التراكمي | U24: المستحق للمستخلص الحالي | V24: المحصل | W24: المتبقي | X24: مدة التحصيل (يوم) | Y24: حالة التحصيل | AA24: التنبيهات النظامية
B25: 1 | C25: =IF('[2]سجل المستخلصات'!$C$6="","",'[2]سجل المستخلصات'!$C$6) | D25: =IF('[2]سجل المستخلصات'!$E$6="","",'[2]سجل المستخلصات'!$E$6) | E25: =IF('[2]سجل المستخلصات'!$F$6="","",'[2]سجل المستخلصات'!$F$6) | F25: =IF('[2]سجل المستخلصات'!$H$6="","",'[2]سجل المستخلصات'!$H$6) | G25: =IF('[2]سجل المستخلصات'!$G$6="","",'[2]سجل المستخلصات'!$G$6) | H25: =IF('[2]سجل المستخلصات'!$I$6="","",'[2]سجل المستخلصات'!$I$6) | I25: =IF('[2]سجل المستخلصات'!$J$6="","",'[2]سجل المستخلصات'!$J$6) | J25: =IF('[2]سجل المستخلصات'!$K$6="","",'[2]سجل المستخلصات'!$K$6) | K25: =IF('[2]سجل المستخلصات'!$L$6="","",'[2]سجل المستخلصات'!$L$6) | L25: =IF('[2]سجل المستخلصات'!$M$6="","",'[2]سجل المستخلصات'!$M$6) | M25: =IF('[2]سجل المستخلصات'!$N$6="","",'[2]سجل المستخلصات'!$N$6) | N25: =IF('[2]سجل المستخلصات'!$O$6="","",'[2]سجل المستخلصات'!$O$6) | O25: =IF('[2]سجل المستخلصات'!$R$6="","",'[2]سجل المستخلصات'!$R$6) | P25: =IF('[2]سجل المستخلصات'!$S$6="","",'[2]سجل المستخلصات'!$S$6) | Q25: =IF('[2]سجل المستخلصات'!$T$6="","",'[2]سجل المستخلصات'!$T$6) | R25: =IF('[2]سجل المستخلصات'!$V$6="","",'[2]سجل المستخلصات'!$V$6) | S25: =IF('[2]سجل المستخلصات'!$W$6="","",'[2]سجل المستخلصات'!$W$6) | T25: =IF('[2]سجل المستخلصات'!$X$6="","",'[2]سجل المستخلصات'!$X$6) | U25: =IF('[2]سجل المستخلصات'!$Z$6="","",'[2]سجل المستخلصات'!$Z$6) | V25: =IF('[2]سجل المستخلصات'!$AA$6="","",'[2]سجل المستخلصات'!$AA$6) | W25: =IF('[2]سجل المستخلصات'!$AC$6="","",'[2]سجل المستخلصات'!$AC$6) | X25: =IF('[2]سجل المستخلصات'!$AD$6="","",'[2]سجل المستخلصات'!$AD$6) | Y25: =IF('[2]سجل المستخلصات'!$AE$6="","",'[2]سجل المستخلصات'!$AE$6) | AA25: =IF($AB$7=0,"",IF(AND($AB$20<>"",N($AB$20)-TODAY()<=30),"⚠ الضمان النهائي ينتهي خلال 30 يوماً — ","")&IF(AND($AB$21<>"",N($AB$21)-TODAY()<=30,$F$18>0),"⚠ ضمان الدفعة المقدمة ينتهي والرصيد لم يُسترد — ","")&IF(ISNUMBER(SEARCH("⚠",$AB$22)),"⚠ الغرامات تجاوزت الحد الأقصى — ","")&IF($J$15>0,"مستحقات غير محصلة","")&"")
B26: 2 | C26: =IF('[2]سجل المستخلصات'!$C$7="","",'[2]سجل المستخلصات'!$C$7) | D26: =IF('[2]سجل المستخلصات'!$E$7="","",'[2]سجل المستخلصات'!$E$7) | E26: =IF('[2]سجل المستخلصات'!$F$7="","",'[2]سجل المستخلصات'!$F$7) | F26: =IF('[2]سجل المستخلصات'!$H$7="","",'[2]سجل المستخلصات'!$H$7) | G26: =IF('[2]سجل المستخلصات'!$G$7="","",'[2]سجل المستخلصات'!$G$7) | H26: =IF('[2]سجل المستخلصات'!$I$7="","",'[2]سجل المستخلصات'!$I$7) | I26: =IF('[2]سجل المستخلصات'!$J$7="","",'[2]سجل المستخلصات'!$J$7) | J26: =IF('[2]سجل المستخلصات'!$K$7="","",'[2]سجل المستخلصات'!$K$7) | K26: =IF('[2]سجل المستخلصات'!$L$7="","",'[2]سجل المستخلصات'!$L$7) | L26: =IF('[2]سجل المستخلصات'!$M$7="","",'[2]سجل المستخلصات'!$M$7) | M26: =IF('[2]سجل المستخلصات'!$N$7="","",'[2]سجل المستخلصات'!$N$7) | N26: =IF('[2]سجل المستخلصات'!$O$7="","",'[2]سجل المستخلصات'!$O$7) | O26: =IF('[2]سجل المستخلصات'!$R$7="","",'[2]سجل المستخلصات'!$R$7) | P26: =IF('[2]سجل المستخلصات'!$S$7="","",'[2]سجل المستخلصات'!$S$7) | Q26: =IF('[2]سجل المستخلصات'!$T$7="","",'[2]سجل المستخلصات'!$T$7) | R26: =IF('[2]سجل المستخلصات'!$V$7="","",'[2]سجل المستخلصات'!$V$7) | S26: =IF('[2]سجل المستخلصات'!$W$7="","",'[2]سجل المستخلصات'!$W$7) | T26: =IF('[2]سجل المستخلصات'!$X$7="","",'[2]سجل المستخلصات'!$X$7) | U26: =IF('[2]سجل المستخلصات'!$Z$7="","",'[2]سجل المستخلصات'!$Z$7) | V26: =IF('[2]سجل المستخلصات'!$AA$7="","",'[2]سجل المستخلصات'!$AA$7) | W26: =IF('[2]سجل المستخلصات'!$AC$7="","",'[2]سجل المستخلصات'!$AC$7) | X26: =IF('[2]سجل المستخلصات'!$AD$7="","",'[2]سجل المستخلصات'!$AD$7) | Y26: =IF('[2]سجل المستخلصات'!$AE$7="","",'[2]سجل المستخلصات'!$AE$7)
B27: 3 | C27: =IF('[2]سجل المستخلصات'!$C$8="","",'[2]سجل المستخلصات'!$C$8) | D27: =IF('[2]سجل المستخلصات'!$E$8="","",'[2]سجل المستخلصات'!$E$8) | E27: =IF('[2]سجل المستخلصات'!$F$8="","",'[2]سجل المستخلصات'!$F$8) | F27: =IF('[2]سجل المستخلصات'!$H$8="","",'[2]سجل المستخلصات'!$H$8) | G27: =IF('[2]سجل المستخلصات'!$G$8="","",'[2]سجل المستخلصات'!$G$8) | H27: =IF('[2]سجل المستخلصات'!$I$8="","",'[2]سجل المستخلصات'!$I$8) | I27: =IF('[2]سجل المستخلصات'!$J$8="","",'[2]سجل المستخلصات'!$J$8) | J27: =IF('[2]سجل المستخلصات'!$K$8="","",'[2]سجل المستخلصات'!$K$8) | K27: =IF('[2]سجل المستخلصات'!$L$8="","",'[2]سجل المستخلصات'!$L$8) | L27: =IF('[2]سجل المستخلصات'!$M$8="","",'[2]سجل المستخلصات'!$M$8) | M27: =IF('[2]سجل المستخلصات'!$N$8="","",'[2]سجل المستخلصات'!$N$8) | N27: =IF('[2]سجل المستخلصات'!$O$8="","",'[2]سجل المستخلصات'!$O$8) | O27: =IF('[2]سجل المستخلصات'!$R$8="","",'[2]سجل المستخلصات'!$R$8) | P27: =IF('[2]سجل المستخلصات'!$S$8="","",'[2]سجل المستخلصات'!$S$8) | Q27: =IF('[2]سجل المستخلصات'!$T$8="","",'[2]سجل المستخلصات'!$T$8) | R27: =IF('[2]سجل المستخلصات'!$V$8="","",'[2]سجل المستخلصات'!$V$8) | S27: =IF('[2]سجل المستخلصات'!$W$8="","",'[2]سجل المستخلصات'!$W$8) | T27: =IF('[2]سجل المستخلصات'!$X$8="","",'[2]سجل المستخلصات'!$X$8) | U27: =IF('[2]سجل المستخلصات'!$Z$8="","",'[2]سجل المستخلصات'!$Z$8) | V27: =IF('[2]سجل المستخلصات'!$AA$8="","",'[2]سجل المستخلصات'!$AA$8) | W27: =IF('[2]سجل المستخلصات'!$AC$8="","",'[2]سجل المستخلصات'!$AC$8) | X27: =IF('[2]سجل المستخلصات'!$AD$8="","",'[2]سجل المستخلصات'!$AD$8) | Y27: =IF('[2]سجل المستخلصات'!$AE$8="","",'[2]سجل المستخلصات'!$AE$8)
B28: 4 | C28: =IF('[2]سجل المستخلصات'!$C$9="","",'[2]سجل المستخلصات'!$C$9) | D28: =IF('[2]سجل المستخلصات'!$E$9="","",'[2]سجل المستخلصات'!$E$9) | E28: =IF('[2]سجل المستخلصات'!$F$9="","",'[2]سجل المستخلصات'!$F$9) | F28: =IF('[2]سجل المستخلصات'!$H$9="","",'[2]سجل المستخلصات'!$H$9) | G28: =IF('[2]سجل المستخلصات'!$G$9="","",'[2]سجل المستخلصات'!$G$9) | H28: =IF('[2]سجل المستخلصات'!$I$9="","",'[2]سجل المستخلصات'!$I$9) | I28: =IF('[2]سجل المستخلصات'!$J$9="","",'[2]سجل المستخلصات'!$J$9) | J28: =IF('[2]سجل المستخلصات'!$K$9="","",'[2]سجل المستخلصات'!$K$9) | K28: =IF('[2]سجل المستخلصات'!$L$9="","",'[2]سجل المستخلصات'!$L$9) | L28: =IF('[2]سجل المستخلصات'!$M$9="","",'[2]سجل المستخلصات'!$M$9) | M28: =IF('[2]سجل المستخلصات'!$N$9="","",'[2]سجل المستخلصات'!$N$9) | N28: =IF('[2]سجل المستخلصات'!$O$9="","",'[2]سجل المستخلصات'!$O$9) | O28: =IF('[2]سجل المستخلصات'!$R$9="","",'[2]سجل المستخلصات'!$R$9) | P28: =IF('[2]سجل المستخلصات'!$S$9="","",'[2]سجل المستخلصات'!$S$9) | Q28: =IF('[2]سجل المستخلصات'!$T$9="","",'[2]سجل المستخلصات'!$T$9) | R28: =IF('[2]سجل المستخلصات'!$V$9="","",'[2]سجل المستخلصات'!$V$9) | S28: =IF('[2]سجل المستخلصات'!$W$9="","",'[2]سجل المستخلصات'!$W$9) | T28: =IF('[2]سجل المستخلصات'!$X$9="","",'[2]سجل المستخلصات'!$X$9) | U28: =IF('[2]سجل المستخلصات'!$Z$9="","",'[2]سجل المستخلصات'!$Z$9) | V28: =IF('[2]سجل المستخلصات'!$AA$9="","",'[2]سجل المستخلصات'!$AA$9) | W28: =IF('[2]سجل المستخلصات'!$AC$9="","",'[2]سجل المستخلصات'!$AC$9) | X28: =IF('[2]سجل المستخلصات'!$AD$9="","",'[2]سجل المستخلصات'!$AD$9) | Y28: =IF('[2]سجل المستخلصات'!$AE$9="","",'[2]سجل المستخلصات'!$AE$9)
B29: 5 | C29: =IF('[2]سجل المستخلصات'!$C$10="","",'[2]سجل المستخلصات'!$C$10) | D29: =IF('[2]سجل المستخلصات'!$E$10="","",'[2]سجل المستخلصات'!$E$10) | E29: =IF('[2]سجل المستخلصات'!$F$10="","",'[2]سجل المستخلصات'!$F$10) | F29: =IF('[2]سجل المستخلصات'!$H$10="","",'[2]سجل المستخلصات'!$H$10) | G29: =IF('[2]سجل المستخلصات'!$G$10="","",'[2]سجل المستخلصات'!$G$10) | H29: =IF('[2]سجل المستخلصات'!$I$10="","",'[2]سجل المستخلصات'!$I$10) | I29: =IF('[2]سجل المستخلصات'!$J$10="","",'[2]سجل المستخلصات'!$J$10) | J29: =IF('[2]سجل المستخلصات'!$K$10="","",'[2]سجل المستخلصات'!$K$10) | K29: =IF('[2]سجل المستخلصات'!$L$10="","",'[2]سجل المستخلصات'!$L$10) | L29: =IF('[2]سجل المستخلصات'!$M$10="","",'[2]سجل المستخلصات'!$M$10) | M29: =IF('[2]سجل المستخلصات'!$N$10="","",'[2]سجل المستخلصات'!$N$10) | N29: =IF('[2]سجل المستخلصات'!$O$10="","",'[2]سجل المستخلصات'!$O$10) | O29: =IF('[2]سجل المستخلصات'!$R$10="","",'[2]سجل المستخلصات'!$R$10) | P29: =IF('[2]سجل المستخلصات'!$S$10="","",'[2]سجل المستخلصات'!$S$10) | Q29: =IF('[2]سجل المستخلصات'!$T$10="","",'[2]سجل المستخلصات'!$T$10) | R29: =IF('[2]سجل المستخلصات'!$V$10="","",'[2]سجل المستخلصات'!$V$10) | S29: =IF('[2]سجل المستخلصات'!$W$10="","",'[2]سجل المستخلصات'!$W$10) | T29: =IF('[2]سجل المستخلصات'!$X$10="","",'[2]سجل المستخلصات'!$X$10) | U29: =IF('[2]سجل المستخلصات'!$Z$10="","",'[2]سجل المستخلصات'!$Z$10) | V29: =IF('[2]سجل المستخلصات'!$AA$10="","",'[2]سجل المستخلصات'!$AA$10) | W29: =IF('[2]سجل المستخلصات'!$AC$10="","",'[2]سجل المستخلصات'!$AC$10) | X29: =IF('[2]سجل المستخلصات'!$AD$10="","",'[2]سجل المستخلصات'!$AD$10) | Y29: =IF('[2]سجل المستخلصات'!$AE$10="","",'[2]سجل المستخلصات'!$AE$10)
B30: 6 | C30: =IF('[2]سجل المستخلصات'!$C$11="","",'[2]سجل المستخلصات'!$C$11) | D30: =IF('[2]سجل المستخلصات'!$E$11="","",'[2]سجل المستخلصات'!$E$11) | E30: =IF('[2]سجل المستخلصات'!$F$11="","",'[2]سجل المستخلصات'!$F$11) | F30: =IF('[2]سجل المستخلصات'!$H$11="","",'[2]سجل المستخلصات'!$H$11) | G30: =IF('[2]سجل المستخلصات'!$G$11="","",'[2]سجل المستخلصات'!$G$11) | H30: =IF('[2]سجل المستخلصات'!$I$11="","",'[2]سجل المستخلصات'!$I$11) | I30: =IF('[2]سجل المستخلصات'!$J$11="","",'[2]سجل المستخلصات'!$J$11) | J30: =IF('[2]سجل المستخلصات'!$K$11="","",'[2]سجل المستخلصات'!$K$11) | K30: =IF('[2]سجل المستخلصات'!$L$11="","",'[2]سجل المستخلصات'!$L$11) | L30: =IF('[2]سجل المستخلصات'!$M$11="","",'[2]سجل المستخلصات'!$M$11) | M30: =IF('[2]سجل المستخلصات'!$N$11="","",'[2]سجل المستخلصات'!$N$11) | N30: =IF('[2]سجل المستخلصات'!$O$11="","",'[2]سجل المستخلصات'!$O$11) | O30: =IF('[2]سجل المستخلصات'!$R$11="","",'[2]سجل المستخلصات'!$R$11) | P30: =IF('[2]سجل المستخلصات'!$S$11="","",'[2]سجل المستخلصات'!$S$11) | Q30: =IF('[2]سجل المستخلصات'!$T$11="","",'[2]سجل المستخلصات'!$T$11) | R30: =IF('[2]سجل المستخلصات'!$V$11="","",'[2]سجل المستخلصات'!$V$11) | S30: =IF('[2]سجل المستخلصات'!$W$11="","",'[2]سجل المستخلصات'!$W$11) | T30: =IF('[2]سجل المستخلصات'!$X$11="","",'[2]سجل المستخلصات'!$X$11) | U30: =IF('[2]سجل المستخلصات'!$Z$11="","",'[2]سجل المستخلصات'!$Z$11) | V30: =IF('[2]سجل المستخلصات'!$AA$11="","",'[2]سجل المستخلصات'!$AA$11) | W30: =IF('[2]سجل المستخلصات'!$AC$11="","",'[2]سجل المستخلصات'!$AC$11) | X30: =IF('[2]سجل المستخلصات'!$AD$11="","",'[2]سجل المستخلصات'!$AD$11) | Y30: =IF('[2]سجل المستخلصات'!$AE$11="","",'[2]سجل المستخلصات'!$AE$11)
B31: 7 | C31: =IF('[2]سجل المستخلصات'!$C$12="","",'[2]سجل المستخلصات'!$C$12) | D31: =IF('[2]سجل المستخلصات'!$E$12="","",'[2]سجل المستخلصات'!$E$12) | E31: =IF('[2]سجل المستخلصات'!$F$12="","",'[2]سجل المستخلصات'!$F$12) | F31: =IF('[2]سجل المستخلصات'!$H$12="","",'[2]سجل المستخلصات'!$H$12) | G31: =IF('[2]سجل المستخلصات'!$G$12="","",'[2]سجل المستخلصات'!$G$12) | H31: =IF('[2]سجل المستخلصات'!$I$12="","",'[2]سجل المستخلصات'!$I$12) | I31: =IF('[2]سجل المستخلصات'!$J$12="","",'[2]سجل المستخلصات'!$J$12) | J31: =IF('[2]سجل المستخلصات'!$K$12="","",'[2]سجل المستخلصات'!$K$12) | K31: =IF('[2]سجل المستخلصات'!$L$12="","",'[2]سجل المستخلصات'!$L$12) | L31: =IF('[2]سجل المستخلصات'!$M$12="","",'[2]سجل المستخلصات'!$M$12) | M31: =IF('[2]سجل المستخلصات'!$N$12="","",'[2]سجل المستخلصات'!$N$12) | N31: =IF('[2]سجل المستخلصات'!$O$12="","",'[2]سجل المستخلصات'!$O$12) | O31: =IF('[2]سجل المستخلصات'!$R$12="","",'[2]سجل المستخلصات'!$R$12) | P31: =IF('[2]سجل المستخلصات'!$S$12="","",'[2]سجل المستخلصات'!$S$12) | Q31: =IF('[2]سجل المستخلصات'!$T$12="","",'[2]سجل المستخلصات'!$T$12) | R31: =IF('[2]سجل المستخلصات'!$V$12="","",'[2]سجل المستخلصات'!$V$12) | S31: =IF('[2]سجل المستخلصات'!$W$12="","",'[2]سجل المستخلصات'!$W$12) | T31: =IF('[2]سجل المستخلصات'!$X$12="","",'[2]سجل المستخلصات'!$X$12) | U31: =IF('[2]سجل المستخلصات'!$Z$12="","",'[2]سجل المستخلصات'!$Z$12) | V31: =IF('[2]سجل المستخلصات'!$AA$12="","",'[2]سجل المستخلصات'!$AA$12) | W31: =IF('[2]سجل المستخلصات'!$AC$12="","",'[2]سجل المستخلصات'!$AC$12) | X31: =IF('[2]سجل المستخلصات'!$AD$12="","",'[2]سجل المستخلصات'!$AD$12) | Y31: =IF('[2]سجل المستخلصات'!$AE$12="","",'[2]سجل المستخلصات'!$AE$12)
B32: 8 | C32: =IF('[2]سجل المستخلصات'!$C$13="","",'[2]سجل المستخلصات'!$C$13) | D32: =IF('[2]سجل المستخلصات'!$E$13="","",'[2]سجل المستخلصات'!$E$13) | E32: =IF('[2]سجل المستخلصات'!$F$13="","",'[2]سجل المستخلصات'!$F$13) | F32: =IF('[2]سجل المستخلصات'!$H$13="","",'[2]سجل المستخلصات'!$H$13) | G32: =IF('[2]سجل المستخلصات'!$G$13="","",'[2]سجل المستخلصات'!$G$13) | H32: =IF('[2]سجل المستخلصات'!$I$13="","",'[2]سجل المستخلصات'!$I$13) | I32: =IF('[2]سجل المستخلصات'!$J$13="","",'[2]سجل المستخلصات'!$J$13) | J32: =IF('[2]سجل المستخلصات'!$K$13="","",'[2]سجل المستخلصات'!$K$13) | K32: =IF('[2]سجل المستخلصات'!$L$13="","",'[2]سجل المستخلصات'!$L$13) | L32: =IF('[2]سجل المستخلصات'!$M$13="","",'[2]سجل المستخلصات'!$M$13) | M32: =IF('[2]سجل المستخلصات'!$N$13="","",'[2]سجل المستخلصات'!$N$13) | N32: =IF('[2]سجل المستخلصات'!$O$13="","",'[2]سجل المستخلصات'!$O$13) | O32: =IF('[2]سجل المستخلصات'!$R$13="","",'[2]سجل المستخلصات'!$R$13) | P32: =IF('[2]سجل المستخلصات'!$S$13="","",'[2]سجل المستخلصات'!$S$13) | Q32: =IF('[2]سجل المستخلصات'!$T$13="","",'[2]سجل المستخلصات'!$T$13) | R32: =IF('[2]سجل المستخلصات'!$V$13="","",'[2]سجل المستخلصات'!$V$13) | S32: =IF('[2]سجل المستخلصات'!$W$13="","",'[2]سجل المستخلصات'!$W$13) | T32: =IF('[2]سجل المستخلصات'!$X$13="","",'[2]سجل المستخلصات'!$X$13) | U32: =IF('[2]سجل المستخلصات'!$Z$13="","",'[2]سجل المستخلصات'!$Z$13) | V32: =IF('[2]سجل المستخلصات'!$AA$13="","",'[2]سجل المستخلصات'!$AA$13) | W32: =IF('[2]سجل المستخلصات'!$AC$13="","",'[2]سجل المستخلصات'!$AC$13) | X32: =IF('[2]سجل المستخلصات'!$AD$13="","",'[2]سجل المستخلصات'!$AD$13) | Y32: =IF('[2]سجل المستخلصات'!$AE$13="","",'[2]سجل المستخلصات'!$AE$13)
B33: 9 | C33: =IF('[2]سجل المستخلصات'!$C$14="","",'[2]سجل المستخلصات'!$C$14) | D33: =IF('[2]سجل المستخلصات'!$E$14="","",'[2]سجل المستخلصات'!$E$14) | E33: =IF('[2]سجل المستخلصات'!$F$14="","",'[2]سجل المستخلصات'!$F$14) | F33: =IF('[2]سجل المستخلصات'!$H$14="","",'[2]سجل المستخلصات'!$H$14) | G33: =IF('[2]سجل المستخلصات'!$G$14="","",'[2]سجل المستخلصات'!$G$14) | H33: =IF('[2]سجل المستخلصات'!$I$14="","",'[2]سجل المستخلصات'!$I$14) | I33: =IF('[2]سجل المستخلصات'!$J$14="","",'[2]سجل المستخلصات'!$J$14) | J33: =IF('[2]سجل المستخلصات'!$K$14="","",'[2]سجل المستخلصات'!$K$14) | K33: =IF('[2]سجل المستخلصات'!$L$14="","",'[2]سجل المستخلصات'!$L$14) | L33: =IF('[2]سجل المستخلصات'!$M$14="","",'[2]سجل المستخلصات'!$M$14) | M33: =IF('[2]سجل المستخلصات'!$N$14="","",'[2]سجل المستخلصات'!$N$14) | N33: =IF('[2]سجل المستخلصات'!$O$14="","",'[2]سجل المستخلصات'!$O$14) | O33: =IF('[2]سجل المستخلصات'!$R$14="","",'[2]سجل المستخلصات'!$R$14) | P33: =IF('[2]سجل المستخلصات'!$S$14="","",'[2]سجل المستخلصات'!$S$14) | Q33: =IF('[2]سجل المستخلصات'!$T$14="","",'[2]سجل المستخلصات'!$T$14) | R33: =IF('[2]سجل المستخلصات'!$V$14="","",'[2]سجل المستخلصات'!$V$14) | S33: =IF('[2]سجل المستخلصات'!$W$14="","",'[2]سجل المستخلصات'!$W$14) | T33: =IF('[2]سجل المستخلصات'!$X$14="","",'[2]سجل المستخلصات'!$X$14) | U33: =IF('[2]سجل المستخلصات'!$Z$14="","",'[2]سجل المستخلصات'!$Z$14) | V33: =IF('[2]سجل المستخلصات'!$AA$14="","",'[2]سجل المستخلصات'!$AA$14) | W33: =IF('[2]سجل المستخلصات'!$AC$14="","",'[2]سجل المستخلصات'!$AC$14) | X33: =IF('[2]سجل المستخلصات'!$AD$14="","",'[2]سجل المستخلصات'!$AD$14) | Y33: =IF('[2]سجل المستخلصات'!$AE$14="","",'[2]سجل المستخلصات'!$AE$14)
B34: 10 | C34: =IF('[2]سجل المستخلصات'!$C$15="","",'[2]سجل المستخلصات'!$C$15) | D34: =IF('[2]سجل المستخلصات'!$E$15="","",'[2]سجل المستخلصات'!$E$15) | E34: =IF('[2]سجل المستخلصات'!$F$15="","",'[2]سجل المستخلصات'!$F$15) | F34: =IF('[2]سجل المستخلصات'!$H$15="","",'[2]سجل المستخلصات'!$H$15) | G34: =IF('[2]سجل المستخلصات'!$G$15="","",'[2]سجل المستخلصات'!$G$15) | H34: =IF('[2]سجل المستخلصات'!$I$15="","",'[2]سجل المستخلصات'!$I$15) | I34: =IF('[2]سجل المستخلصات'!$J$15="","",'[2]سجل المستخلصات'!$J$15) | J34: =IF('[2]سجل المستخلصات'!$K$15="","",'[2]سجل المستخلصات'!$K$15) | K34: =IF('[2]سجل المستخلصات'!$L$15="","",'[2]سجل المستخلصات'!$L$15) | L34: =IF('[2]سجل المستخلصات'!$M$15="","",'[2]سجل المستخلصات'!$M$15) | M34: =IF('[2]سجل المستخلصات'!$N$15="","",'[2]سجل المستخلصات'!$N$15) | N34: =IF('[2]سجل المستخلصات'!$O$15="","",'[2]سجل المستخلصات'!$O$15) | O34: =IF('[2]سجل المستخلصات'!$R$15="","",'[2]سجل المستخلصات'!$R$15) | P34: =IF('[2]سجل المستخلصات'!$S$15="","",'[2]سجل المستخلصات'!$S$15) | Q34: =IF('[2]سجل المستخلصات'!$T$15="","",'[2]سجل المستخلصات'!$T$15) | R34: =IF('[2]سجل المستخلصات'!$V$15="","",'[2]سجل المستخلصات'!$V$15) | S34: =IF('[2]سجل المستخلصات'!$W$15="","",'[2]سجل المستخلصات'!$W$15) | T34: =IF('[2]سجل المستخلصات'!$X$15="","",'[2]سجل المستخلصات'!$X$15) | U34: =IF('[2]سجل المستخلصات'!$Z$15="","",'[2]سجل المستخلصات'!$Z$15) | V34: =IF('[2]سجل المستخلصات'!$AA$15="","",'[2]سجل المستخلصات'!$AA$15) | W34: =IF('[2]سجل المستخلصات'!$AC$15="","",'[2]سجل المستخلصات'!$AC$15) | X34: =IF('[2]سجل المستخلصات'!$AD$15="","",'[2]سجل المستخلصات'!$AD$15) | Y34: =IF('[2]سجل المستخلصات'!$AE$15="","",'[2]سجل المستخلصات'!$AE$15)
B35: 11 | C35: =IF('[2]سجل المستخلصات'!$C$16="","",'[2]سجل المستخلصات'!$C$16) | D35: =IF('[2]سجل المستخلصات'!$E$16="","",'[2]سجل المستخلصات'!$E$16) | E35: =IF('[2]سجل المستخلصات'!$F$16="","",'[2]سجل المستخلصات'!$F$16) | F35: =IF('[2]سجل المستخلصات'!$H$16="","",'[2]سجل المستخلصات'!$H$16) | G35: =IF('[2]سجل المستخلصات'!$G$16="","",'[2]سجل المستخلصات'!$G$16) | H35: =IF('[2]سجل المستخلصات'!$I$16="","",'[2]سجل المستخلصات'!$I$16) | I35: =IF('[2]سجل المستخلصات'!$J$16="","",'[2]سجل المستخلصات'!$J$16) | J35: =IF('[2]سجل المستخلصات'!$K$16="","",'[2]سجل المستخلصات'!$K$16) | K35: =IF('[2]سجل المستخلصات'!$L$16="","",'[2]سجل المستخلصات'!$L$16) | L35: =IF('[2]سجل المستخلصات'!$M$16="","",'[2]سجل المستخلصات'!$M$16) | M35: =IF('[2]سجل المستخلصات'!$N$16="","",'[2]سجل المستخلصات'!$N$16) | N35: =IF('[2]سجل المستخلصات'!$O$16="","",'[2]سجل المستخلصات'!$O$16) | O35: =IF('[2]سجل المستخلصات'!$R$16="","",'[2]سجل المستخلصات'!$R$16) | P35: =IF('[2]سجل المستخلصات'!$S$16="","",'[2]سجل المستخلصات'!$S$16) | Q35: =IF('[2]سجل المستخلصات'!$T$16="","",'[2]سجل المستخلصات'!$T$16) | R35: =IF('[2]سجل المستخلصات'!$V$16="","",'[2]سجل المستخلصات'!$V$16) | S35: =IF('[2]سجل المستخلصات'!$W$16="","",'[2]سجل المستخلصات'!$W$16) | T35: =IF('[2]سجل المستخلصات'!$X$16="","",'[2]سجل المستخلصات'!$X$16) | U35: =IF('[2]سجل المستخلصات'!$Z$16="","",'[2]سجل المستخلصات'!$Z$16) | V35: =IF('[2]سجل المستخلصات'!$AA$16="","",'[2]سجل المستخلصات'!$AA$16) | W35: =IF('[2]سجل المستخلصات'!$AC$16="","",'[2]سجل المستخلصات'!$AC$16) | X35: =IF('[2]سجل المستخلصات'!$AD$16="","",'[2]سجل المستخلصات'!$AD$16) | Y35: =IF('[2]سجل المستخلصات'!$AE$16="","",'[2]سجل المستخلصات'!$AE$16)
