Workbook

Sheet الرئيسية
B1: نظام المحاسبة المتكامل لشركات المقاولات
B2: =الرئيسية!$C$6&" | الفترة المنتهية في: "&TEXT(الرئيسية!$C$7,"yyyy/mm/dd")&" | المبالغ بـ "&الرئيسية!$G$7 -> شركة الإعمار الحديثة للمقاولات العامة | الفترة المنتهية في: 2026/03/31 | المبالغ بـ ريال
B5: ⚙ بيانات الشركة والإعدادات العامة
B6: اسم الشركة | C6: شركة الإعمار الحديثة للمقاولات العامة | F6: السنة المالية | G6: 2026
B7: تاريخ نهاية الفترة | C7: 46112 | F7: العملة | G7: ريال
B9: 📊 لوحة المؤشرات الرئيسية (تتحدث تلقائياً)
B10: إجمالي إيرادات العقود | D10: مجمل الربح | F10: صافي ربح الفترة | H10: إجمالي الأصول
B11: ='قائمة الدخل'!$D$8 -> 2700000 | D11: ='قائمة الدخل'!$D$17 -> 625000 | F11: ='قائمة الدخل'!$D$24 -> 507300 | H11: ='المركز المالي'!$D$20 -> 5332300
B13: النقدية وما في حكمها | D13: حالة ميزان المراجعة | F13: حالة المركز المالي | H13: قيود غير مرحّلة
B14: ='المركز المالي'!$C$8 -> 2892300 | D14: ='ميزان المراجعة'!$A$6 -> ✔ الميزان متوازن | F14: =IF(LEFT('المركز المالي'!$B$44,1)="✔","✔ متوازن","✖ غير متوازن") -> ✔ متوازن | H14: ='قيود اليومية'!$I$6 -> 1
B16: 🧭 الانتقال السريع بين الواجهات
B17: 🌳 تعديل شجرة الحسابات | D17: ✍ إدخال القيود اليومية | F17: 🏗 تجميع المشروعات | H17: 📄 كشف حساب مشروع
B19: 📒 دفتر الأستاذ العام | D19: ⚖ ميزان المراجعة | F19: 📈 قائمة الدخل | H19: 🏦 قائمة المركز المالي
B21: 📘 دليل الاستخدام السريع
B22: 1) الخلايا ذات الخلفية الصفراء والخط الأزرق هي خلايا الإدخال فقط، وباقي الخلايا معادلات تلقائية لا يُنصح بتعديلها.
B23: 2) ابدأ بمراجعة «شجرة الحسابات»: أضف أي حساب جديد في أول صف فارغ، وحدد المستوى (تحليلي للحسابات التي يُرحّل إليها) والنوع والطبيعة وبند القائمة.
B24: 3) أضف المشروعات في «تجميع المشروعات» (الكود، الاسم، العميل، قيمة العقد، التكلفة التقديرية) لتظهر في القائمة المنسدلة للقيود.
B25: 4) سجّل القيود في «قيود اليومية»: اختر رقم الحساب من القائمة المنسدلة، ويظهر اسم الحساب تلقائياً؛ ولكل قيد عدة أسطر بنفس رقم القيد.
B26: 5) عمود «حالة القيد» يفحص التوازن: القيد المتوازن فقط يُرحّل تلقائياً للميزان والقوائم، والقيد غير المتوازن يظهر باللون الأحمر ولا يُرحّل.
B27: 6) الميزان وقائمة الدخل والمركز المالي وكشوف المشروعات تتحدث فوراً، مع مؤشرات تحقق ذاتي من التوازن.
B28: 7) القيد رقم 28 في البيانات التجريبية غير متوازن عمداً لتوضيح آلية التنبيه ومنع الترحيل — صحّحه أو احذفه.
B30: مفتاح الألوان: | C30: خلية إدخال | D30: معادلة تلقائية | E30: ✔ سليم / متوازن | F30: ✖ خطأ / غير متوازن | G30: ⚠ تنبيه

Sheet شجرة الحسابات
A1: واجهة تعديل الحسابات الأساسية وشجرة الحسابات
A2: =الرئيسية!$C$6&" | الفترة المنتهية في: "&TEXT(الرئيسية!$C$7,"yyyy/mm/dd")&" | المبالغ بـ "&الرئيسية!$G$7 -> شركة الإعمار الحديثة للمقاولات العامة | الفترة المنتهية في: 2026/03/31 | المبالغ بـ ريال
A3: 🏠 الرئيسية | B3: ✍ القيود | C3: 🏗 المشروعات | D3: 📄 كشف مشروع | E3: 📒 الأستاذ | F3: ⚖ الميزان | G3: 📈 الدخل | H3: 🏦 المركز المالي
A5: عدد الحسابات التحليلية | C5: حسابات الأصول | E5: حسابات الخصوم | F5: حسابات حقوق الملكية | H5: حسابات الإيرادات | I5: حسابات المصروفات | J5: تنبيهات تحتاج مراجعة
A6: =COUNTIFS('شجرة الحسابات'!$C$9:$C$208,"تحليلي") -> 40 | C6: =COUNTIFS('شجرة الحسابات'!$E$9:$E$208,"الأصول",'شجرة الحسابات'!$C$9:$C$208,"تحليلي") -> 14 | E6: =COUNTIFS('شجرة الحسابات'!$E$9:$E$208,"الخصوم",'شجرة الحسابات'!$C$9:$C$208,"تحليلي") -> 8 | F6: =COUNTIFS('شجرة الحسابات'!$E$9:$E$208,"حقوق الملكية",'شجرة الحسابات'!$C$9:$C$208,"تحليلي") -> 4 | H6: =COUNTIFS('شجرة الحسابات'!$E$9:$E$208,"الإيرادات",'شجرة الحسابات'!$C$9:$C$208,"تحليلي") -> 3 | I6: =COUNTIFS('شجرة الحسابات'!$E$9:$E$208,"المصروفات",'شجرة الحسابات'!$C$9:$C$208,"تحليلي") -> 11 | J6: =COUNTIF('شجرة الحسابات'!$K$9:$K$208,"⚠*") -> 0
A7: ➕ لإضافة حساب: اكتب في أول صف فارغ بالجدول (الخلايا الصفراء) — المستوى «تحليلي» للحسابات التي يُرحّل إليها، و«رئيسي/فرعي» للتجميع. رقم الحساب التحليلي يبدأ بأرقام الحساب الأب (مثال: 1111 تحت 11) ليتجمع تلقائياً في الميزان.
A8: رقم الحساب | B8: اسم الحساب | C8: المستوى | D8: الحساب الأب | E8: نوع الحساب | F8: الطبيعة | G8: القائمة المالية | H8: بند القائمة المالية | I8: عنصر تكلفة المشروع | J8: الرصيد الحالي | K8: التحقق
A9: 1 | B9: الأصول | C9: رئيسي | E9: الأصول | F9: مدين | G9: =IF(E9="","",IF(OR(E9="الأصول",E9="الخصوم",E9="حقوق الملكية"),"المركز المالي","قائمة الدخل")) -> المركز المالي | J9: =IF(A9="","",IF(F9="دائن",'ميزان المراجعة'!D9-'ميزان المراجعة'!C9,'ميزان المراجعة'!C9-'ميزان المراجعة'!D9)) -> 5332300 | K9: =IF(A9="","",IF(COUNTIF('شجرة الحسابات'!$A$9:$A$208,A9)>1,"⚠ رقم مكرر",IF(OR(B9="",C9="",E9="",F9=""),"⚠ بيانات ناقصة",IF(C9<>"تحليلي","● حساب تجميعي",IF(H9="","⚠ حدد بند القائمة",IF(COUNTIF(L_LINES,H9)=0,"⚠ بند غير معروف","✔ سليم")))))) -> ● حساب تجميعي
A10: 11 | B10: الأصول المتداولة | C10: فرعي | D10: 1 | E10: الأصول | F10: مدين | G10: =IF(E10="","",IF(OR(E10="الأصول",E10="الخصوم",E10="حقوق الملكية"),"المركز المالي","قائمة الدخل")) -> المركز المالي | J10: =IF(A10="","",IF(F10="دائن",'ميزان المراجعة'!D10-'ميزان المراجعة'!C10,'ميزان المراجعة'!C10-'ميزان المراجعة'!D10)) -> 3837300 | K10: =IF(A10="","",IF(COUNTIF('شجرة الحسابات'!$A$9:$A$208,A10)>1,"⚠ رقم مكرر",IF(OR(B10="",C10="",E10="",F10=""),"⚠ بيانات ناقصة",IF(C10<>"تحليلي","● حساب تجميعي",IF(H10="","⚠ حدد بند القائمة",IF(COUNTIF(L_LINES,H10)=0,"⚠ بند غير معروف","✔ سليم")))))) -> ● حساب تجميعي
A11: 1101 | B11: الصندوق (النقدية بالخزينة) | C11: تحليلي | D11: 11 | E11: الأصول | F11: مدين | G11: =IF(E11="","",IF(OR(E11="الأصول",E11="الخصوم",E11="حقوق الملكية"),"المركز المالي","قائمة الدخل")) -> المركز المالي | H11: النقدية وما في حكمها | J11: =IF(A11="","",IF(F11="دائن",'ميزان المراجعة'!D11-'ميزان المراجعة'!C11,'ميزان المراجعة'!C11-'ميزان المراجعة'!D11)) -> 25500 | K11: =IF(A11="","",IF(COUNTIF('شجرة الحسابات'!$A$9:$A$208,A11)>1,"⚠ رقم مكرر",IF(OR(B11="",C11="",E11="",F11=""),"⚠ بيانات ناقصة",IF(C11<>"تحليلي","● حساب تجميعي",IF(H11="","⚠ حدد بند القائمة",IF(COUNTIF(L_LINES,H11)=0,"⚠ بند غير معروف","✔ سليم")))))) -> ✔ سليم
A12: 1102 | B12: البنك - الحساب الجاري | C12: تحليلي | D12: 11 | E12: الأصول | F12: مدين | G12: =IF(E12="","",IF(OR(E12="الأصول",E12="الخصوم",E12="حقوق الملكية"),"المركز المالي","قائمة الدخل")) -> المركز المالي | H12: النقدية وما في حكمها | J12: =IF(A12="","",IF(F12="دائن",'ميزان المراجعة'!D12-'ميزان المراجعة'!C12,'ميزان المراجعة'!C12-'ميزان المراجعة'!D12)) -> 2866800 | K12: =IF(A12="","",IF(COUNTIF('شجرة الحسابات'!$A$9:$A$208,A12)>1,"⚠ رقم مكرر",IF(OR(B12="",C12="",E12="",F12=""),"⚠ بيانات ناقصة",IF(C12<>"تحليلي","● حساب تجميعي",IF(H12="","⚠ حدد بند القائمة",IF(COUNTIF(L_LINES,H12)=0,"⚠ بند غير معروف","✔ سليم")))))) -> ✔ سليم
A13: 1103 | B13: عملاء المقاولات | C13: تحليلي | D13: 11 | E13: الأصول | F13: مدين | G13: =IF(E13="","",IF(OR(E13="الأصول",E13="الخصوم",E13="حقوق الملكية"),"المركز المالي","قائمة الدخل")) -> المركز المالي | H13: عملاء المقاولات | J13: =IF(A13="","",IF(F13="دائن",'ميزان المراجعة'!D13-'ميزان المراجعة'!C13,'ميزان المراجعة'!C13-'ميزان المراجعة'!D13)) -> 385000 | K13: =IF(A13="","",IF(COUNTIF('شجرة الحسابات'!$A$9:$A$208,A13)>1,"⚠ رقم مكرر",IF(OR(B13="",C13="",E13="",F13=""),"⚠ بيانات ناقصة",IF(C13<>"تحليلي","● حساب تجميعي",IF(H13="","⚠ حدد بند القائمة",IF(COUNTIF(L_LINES,H13)=0,"⚠ بند غير معروف","✔ سليم")))))) -> ✔ سليم
A14: 1104 | B14: محتجزات ضمان لدى العملاء | C14: تحليلي | D14: 11 | E14: الأصول | F14: مدين | G14: =IF(E14="","",IF(OR(E14="الأصول",E14="الخصوم",E14="حقوق الملكية"),"المركز المالي","قائمة الدخل")) -> المركز المالي | H14: محتجزات ضمان لدى العملاء | J14: =IF(A14="","",IF(F14="دائن",'ميزان المراجعة'!D14-'ميزان المراجعة'!C14,'ميزان المراجعة'!C14-'ميزان المراجعة'!D14)) -> 195000 | K14: =IF(A14="","",IF(COUNTIF('شجرة الحسابات'!$A$9:$A$208,A14)>1,"⚠ رقم مكرر",IF(OR(B14="",C14="",E14="",F14=""),"⚠ بيانات ناقصة",IF(C14<>"تحليلي","● حساب تجميعي",IF(H14="","⚠ حدد بند القائمة",IF(COUNTIF(L_LINES,H14)=0,"⚠ بند غير معروف","✔ سليم")))))) -> ✔ سليم
A15: 1105 | B15: إيرادات مستحقة - أعمال منفذة غير مفوترة | C15: تحليلي | D15: 11 | E15: الأصول | F15: مدين | G15: =IF(E15="","",IF(OR(E15="الأصول",E15="الخصوم",E15="حقوق الملكية"),"المركز المالي","قائمة الدخل")) -> المركز المالي | H15: إيرادات مستحقة (أعمال منفذة غير مفوترة) | J15: =IF(A15="","",IF(F15="دائن",'ميزان المراجعة'!D15-'ميزان المراجعة'!C15,'ميزان المراجعة'!C15-'ميزان المراجعة'!D15)) -> 180000 | K15: =IF(A15="","",IF(COUNTIF('شجرة الحسابات'!$A$9:$A$208,A15)>1,"⚠ رقم مكرر",IF(OR(B15="",C15="",E15="",F15=""),"⚠ بيانات ناقصة",IF(C15<>"تحليلي","● حساب تجميعي",IF(H15="","⚠ حدد بند القائمة",IF(COUNTIF(L_LINES,H15)=0,"⚠ بند غير معروف","✔ سليم")))))) -> ✔ سليم
A16: 1106 | B16: دفعات مقدمة لمقاولي الباطن | C16: تحليلي | D16: 11 | E16: الأصول | F16: مدين | G16: =IF(E16="","",IF(OR(E16="الأصول",E16="الخصوم",E16="حقوق الملكية"),"المركز المالي","قائمة الدخل")) -> المركز المالي | H16: دفعات مقدمة وأرصدة مدينة أخرى | J16: =IF(A16="","",IF(F16="دائن",'ميزان المراجعة'!D16-'ميزان المراجعة'!C16,'ميزان المراجعة'!C16-'ميزان المراجعة'!D16)) -> 90000 | K16: =IF(A16="","",IF(COUNTIF('شجرة الحسابات'!$A$9:$A$208,A16)>1,"⚠ رقم مكرر",IF(OR(B16="",C16="",E16="",F16=""),"⚠ بيانات ناقصة",IF(C16<>"تحليلي","● حساب تجميعي",IF(H16="","⚠ حدد بند القائمة",IF(COUNTIF(L_LINES,H16)=0,"⚠ بند غير معروف","✔ سليم")))))) -> ✔ سليم
A17: 1107 | B17: مخزون مواد البناء | C17: تحليلي | D17: 11 | E17: الأصول | F17: مدين | G17: =IF(E17="","",IF(OR(E17="الأصول",E17="الخصوم",E17="حقوق الملكية"),"المركز المالي","قائمة الدخل")) -> المركز المالي | H17: مخزون المواد | J17: =IF(A17="","",IF(F17="دائن",'ميزان المراجعة'!D17-'ميزان المراجعة'!C17,'ميزان المراجعة'!C17-'ميزان المراجعة'!D17)) -> 0 | K17: =IF(A17="","",IF(COUNTIF('شجرة الحسابات'!$A$9:$A$208,A17)>1,"⚠ رقم مكرر",IF(OR(B17="",C17="",E17="",F17=""),"⚠ بيانات ناقصة",IF(C17<>"تحليلي","● حساب تجميعي",IF(H17="","⚠ حدد بند القائمة",IF(COUNTIF(L_LINES,H17)=0,"⚠ بند غير معروف","✔ سليم")))))) -> ✔ سليم
A18: 1108 | B18: مشروعات تحت التنفيذ | C18: تحليلي | D18: 11 | E18: الأصول | F18: مدين | G18: =IF(E18="","",IF(OR(E18="الأصول",E18="الخصوم",E18="حقوق الملكية"),"المركز المالي","قائمة الدخل")) -> المركز المالي | H18: مشروعات تحت التنفيذ | J18: =IF(A18="","",IF(F18="دائن",'ميزان المراجعة'!D18-'ميزان المراجعة'!C18,'ميزان المراجعة'!C18-'ميزان المراجعة'!D18)) -> 95000 | K18: =IF(A18="","",IF(COUNTIF('شجرة الحسابات'!$A$9:$A$208,A18)>1,"⚠ رقم مكرر",IF(OR(B18="",C18="",E18="",F18=""),"⚠ بيانات ناقصة",IF(C18<>"تحليلي","● حساب تجميعي",IF(H18="","⚠ حدد بند القائمة",IF(COUNTIF(L_LINES,H18)=0,"⚠ بند غير معروف","✔ سليم")))))) -> ✔ سليم
A19: 1109 | B19: مصروفات مدفوعة مقدماً | C19: تحليلي | D19: 11 | E19: الأصول | F19: مدين | G19: =IF(E19="","",IF(OR(E19="الأصول",E19="الخصوم",E19="حقوق الملكية"),"المركز المالي","قائمة الدخل")) -> المركز المالي | H19: دفعات مقدمة وأرصدة مدينة أخرى | J19: =IF(A19="","",IF(F19="دائن",'ميزان المراجعة'!D19-'ميزان المراجعة'!C19,'ميزان المراجعة'!C19-'ميزان المراجعة'!D19)) -> 0 | K19: =IF(A19="","",IF(COUNTIF('شجرة الحسابات'!$A$9:$A$208,A19)>1,"⚠ رقم مكرر",IF(OR(B19="",C19="",E19="",F19=""),"⚠ بيانات ناقصة",IF(C19<>"تحليلي","● حساب تجميعي",IF(H19="","⚠ حدد بند القائمة",IF(COUNTIF(L_LINES,H19)=0,"⚠ بند غير معروف","✔ سليم")))))) -> ✔ سليم
A20: 1110 | B20: تأمينات خطابات الضمان | C20: تحليلي | D20: 11 | E20: الأصول | F20: مدين | G20: =IF(E20="","",IF(OR(E20="الأصول",E20="الخصوم",E20="حقوق الملكية"),"المركز المالي","قائمة الدخل")) -> المركز المالي | H20: دفعات مقدمة وأرصدة مدينة أخرى | J20: =IF(A20="","",IF(F20="دائن",'ميزان المراجعة'!D20-'ميزان المراجعة'!C20,'ميزان المراجعة'!C20-'ميزان المراجعة'!D20)) -> 0 | K20: =IF(A20="","",IF(COUNTIF('شجرة الحسابات'!$A$9:$A$208,A20)>1,"⚠ رقم مكرر",IF(OR(B20="",C20="",E20="",F20=""),"⚠ بيانات ناقصة",IF(C20<>"تحليلي","● حساب تجميعي",IF(H20="","⚠ حدد بند القائمة",IF(COUNTIF(L_LINES,H20)=0,"⚠ بند غير معروف","✔ سليم")))))) -> ✔ سليم
A21: 12 | B21: الأصول غير المتداولة | C21: فرعي | D21: 1 | E21: الأصول | F21: مدين | G21: =IF(E21="","",IF(OR(E21="الأصول",E21="الخصوم",E21="حقوق الملكية"),"المركز المالي","قائمة الدخل")) -> المركز المالي | J21: =IF(A21="","",IF(F21="دائن",'ميزان المراجعة'!D21-'ميزان المراجعة'!C21,'ميزان المراجعة'!C21-'ميزان المراجعة'!D21)) -> 1495000 | K21: =IF(A21="","",IF(COUNTIF('شجرة الحسابات'!$A$9:$A$208,A21)>1,"⚠ رقم مكرر",IF(OR(B21="",C21="",E21="",F21=""),"⚠ بيانات ناقصة",IF(C21<>"تحليلي","● حساب تجميعي",IF(H21="","⚠ حدد بند القائمة",IF(COUNTIF(L_LINES,H21)=0,"⚠ بند غير معروف","✔ سليم")))))) -> ● حساب تجميعي
A22: 1201 | B22: المعدات والآلات الثقيلة | C22: تحليلي | D22: 12 | E22: الأصول | F22: مدين | G22: =IF(E22="","",IF(OR(E22="الأصول",E22="الخصوم",E22="حقوق الملكية"),"المركز المالي","قائمة الدخل")) -> المركز المالي | H22: الممتلكات والمعدات - بالتكلفة | J22: =IF(A22="","",IF(F22="دائن",'ميزان المراجعة'!D22-'ميزان المراجعة'!C22,'ميزان المراجعة'!C22-'ميزان المراجعة'!D22)) -> 1200000 | K22: =IF(A22="","",IF(COUNTIF('شجرة الحسابات'!$A$9:$A$208,A22)>1,"⚠ رقم مكرر",IF(OR(B22="",C22="",E22="",F22=""),"⚠ بيانات ناقصة",IF(C22<>"تحليلي","● حساب تجميعي",IF(H22="","⚠ حدد بند القائمة",IF(COUNTIF(L_LINES,H22)=0,"⚠ بند غير معروف","✔ سليم")))))) -> ✔ سليم
A23: 1202 | B23: السيارات ووسائل النقل | C23: تحليلي | D23: 12 | E23: الأصول | F23: مدين | G23: =IF(E23="","",IF(OR(E23="الأصول",E23="الخصوم",E23="حقوق الملكية"),"المركز المالي","قائمة الدخل")) -> المركز المالي | H23: الممتلكات والمعدات - بالتكلفة | J23: =IF(A23="","",IF(F23="دائن",'ميزان المراجعة'!D23-'ميزان المراجعة'!C23,'ميزان المراجعة'!C23-'ميزان المراجعة'!D23)) -> 250000 | K23: =IF(A23="","",IF(COUNTIF('شجرة الحسابات'!$A$9:$A$208,A23)>1,"⚠ رقم مكرر",IF(OR(B23="",C23="",E23="",F23=""),"⚠ بيانات ناقصة",IF(C23<>"تحليلي","● حساب تجميعي",IF(H23="","⚠ حدد بند القائمة",IF(COUNTIF(L_LINES,H23)=0,"⚠ بند غير معروف","✔ سليم")))))) -> ✔ سليم
A24: 1203 | B24: الأثاث والتجهيزات المكتبية | C24: تحليلي | D24: 12 | E24: الأصول | F24: مدين | G24: =IF(E24="","",IF(OR(E24="الأصول",E24="الخصوم",E24="حقوق الملكية"),"المركز المالي","قائمة الدخل")) -> المركز المالي | H24: الممتلكات والمعدات - بالتكلفة | J24: =IF(A24="","",IF(F24="دائن",'ميزان المراجعة'!D24-'ميزان المراجعة'!C24,'ميزان المراجعة'!C24-'ميزان المراجعة'!D24)) -> 80000 | K24: =IF(A24="","",IF(COUNTIF('شجرة الحسابات'!$A$9:$A$208,A24)>1,"⚠ رقم مكرر",IF(OR(B24="",C24="",E24="",F24=""),"⚠ بيانات ناقصة",IF(C24<>"تحليلي","● حساب تجميعي",IF(H24="","⚠ حدد بند القائمة",IF(COUNTIF(L_LINES,H24)=0,"⚠ بند غير معروف","✔ سليم")))))) -> ✔ سليم
A25: 1204 | B25: مجمع إهلاك الأصول الثابتة | C25: تحليلي | D25: 12 | E25: الأصول | F25: دائن | G25: =IF(E25="","",IF(OR(E25="الأصول",E25="الخصوم",E25="حقوق الملكية"),"المركز المالي","قائمة الدخل")) -> المركز المالي | H25: مجمع الإهلاك | J25: =IF(A25="","",IF(F25="دائن",'ميزان المراجعة'!D25-'ميزان المراجعة'!C25,'ميزان المراجعة'!C25-'ميزان المراجعة'!D25)) -> 35000 | K25: =IF(A25="","",IF(COUNTIF('شجرة الحسابات'!$A$9:$A$208,A25)>1,"⚠ رقم مكرر",IF(OR(B25="",C25="",E25="",F25=""),"⚠ بيانات ناقصة",IF(C25<>"تحليلي","● حساب تجميعي",IF(H25="","⚠ حدد بند القائمة",IF(COUNTIF(L_LINES,H25)=0,"⚠ بند غير معروف","✔ سليم")))))) -> ✔ سليم
A26: 2 | B26: الخصوم | C26: رئيسي | E26: الخصوم | F26: دائن | G26: =IF(E26="","",IF(OR(E26="الأصول",E26="الخصوم",E26="حقوق الملكية"),"المركز المالي","قائمة الدخل")) -> المركز المالي | J26: =IF(A26="","",IF(F26="دائن",'ميزان المراجعة'!D26-'ميزان المراجعة'!C26,'ميزان المراجعة'!C26-'ميزان المراجعة'!D26)) -> 1865000 | K26: =IF(A26="","",IF(COUNTIF('شجرة الحسابات'!$A$9:$A$208,A26)>1,"⚠ رقم مكرر",IF(OR(B26="",C26="",E26="",F26=""),"⚠ بيانات ناقصة",IF(C26<>"تحليلي","● حساب تجميعي",IF(H26="","⚠ حدد بند القائمة",IF(COUNTIF(L_LINES,H26)=0,"⚠ بند غير معروف","✔ سليم")))))) -> ● حساب تجميعي
A27: 21 | B27: الخصوم المتداولة | C27: فرعي | D27: 2 | E27: الخصوم | F27: دائن | G27: =IF(E27="","",IF(OR(E27="الأصول",E27="الخصوم",E27="حقوق الملكية"),"المركز المالي","قائمة الدخل")) -> المركز المالي | J27: =IF(A27="","",IF(F27="دائن",'ميزان المراجعة'!D27-'ميزان المراجعة'!C27,'ميزان المراجعة'!C27-'ميزان المراجعة'!D27)) -> 1365000 | K27: =IF(A27="","",IF(COUNTIF('شجرة الحسابات'!$A$9:$A$208,A27)>1,"⚠ رقم مكرر",IF(OR(B27="",C27="",E27="",F27=""),"⚠ بيانات ناقصة",IF(C27<>"تحليلي","● حساب تجميعي",IF(H27="","⚠ حدد بند القائمة",IF(COUNTIF(L_LINES,H27)=0,"⚠ بند غير معروف","✔ سليم")))))) -> ● حساب تجميعي
A28: 2101 | B28: الموردون | C28: تحليلي | D28: 21 | E28: الخصوم | F28: دائن | G28: =IF(E28="","",IF(OR(E28="الأصول",E28="الخصوم",E28="حقوق الملكية"),"المركز المالي","قائمة الدخل")) -> المركز المالي | H28: الموردون | J28: =IF(A28="","",IF(F28="دائن",'ميزان المراجعة'!D28-'ميزان المراجعة'!C28,'ميزان المراجعة'!C28-'ميزان المراجعة'!D28)) -> 180000 | K28: =IF(A28="","",IF(COUNTIF('شجرة الحسابات'!$A$9:$A$208,A28)>1,"⚠ رقم مكرر",IF(OR(B28="",C28="",E28="",F28=""),"⚠ بيانات ناقصة",IF(C28<>"تحليلي","● حساب تجميعي",IF(H28="","⚠ حدد بند القائمة",IF(COUNTIF(L_LINES,H28)=0,"⚠ بند غير معروف","✔ سليم")))))) -> ✔ سليم
A29: 2102 | B29: مقاولو الباطن | C29: تحليلي | D29: 21 | E29: الخصوم | F29: دائن | G29: =IF(E29="","",IF(OR(E29="الأصول",E29="الخصوم",E29="حقوق الملكية"),"المركز المالي","قائمة الدخل")) -> المركز المالي | H29: مقاولو الباطن | J29: =IF(A29="","",IF(F29="دائن",'ميزان المراجعة'!D29-'ميزان المراجعة'!C29,'ميزان المراجعة'!C29-'ميزان المراجعة'!D29)) -> 347500 | K29: =IF(A29="","",IF(COUNTIF('شجرة الحسابات'!$A$9:$A$208,A29)>1,"⚠ رقم مكرر",IF(OR(B29="",C29="",E29="",F29=""),"⚠ بيانات ناقصة",IF(C29<>"تحليلي","● حساب تجميعي",IF(H29="","⚠ حدد بند القائمة",IF(COUNTIF(L_LINES,H29)=0,"⚠ بند غير معروف","✔ سليم")))))) -> ✔ سليم
A30: 2103 | B30: محتجزات ضمان مقاولي الباطن | C30: تحليلي | D30: 21 | E30: الخصوم | F30: دائن | G30: =IF(E30="","",IF(OR(E30="الأصول",E30="الخصوم",E30="حقوق الملكية"),"المركز المالي","قائمة الدخل")) -> المركز المالي | H30: محتجزات ضمان مقاولي الباطن | J30: =IF(A30="","",IF(F30="دائن",'ميزان المراجعة'!D30-'ميزان المراجعة'!C30,'ميزان المراجعة'!C30-'ميزان المراجعة'!D30)) -> 42500 | K30: =IF(A30="","",IF(COUNTIF('شجرة الحسابات'!$A$9:$A$208,A30)>1,"⚠ رقم مكرر",IF(OR(B30="",C30="",E30="",F30=""),"⚠ بيانات ناقصة",IF(C30<>"تحليلي","● حساب تجميعي",IF(H30="","⚠ حدد بند القائمة",IF(COUNTIF(L_LINES,H30)=0,"⚠ بند غير معروف","✔ سليم")))))) -> ✔ سليم
A31: 2104 | B31: دفعات مقدمة من العملاء | C31: تحليلي | D31: 21 | E31: الخصوم | F31: دائن | G31: =IF(E31="","",IF(OR(E31="الأصول",E31="الخصوم",E31="حقوق الملكية"),"المركز المالي","قائمة الدخل")) -> المركز المالي | H31: دفعات مقدمة من العملاء | J31: =IF(A31="","",IF(F31="دائن",'ميزان المراجعة'!D31-'ميزان المراجعة'!C31,'ميزان المراجعة'!C31-'ميزان المراجعة'!D31)) -> 755000 | K31: =IF(A31="","",IF(COUNTIF('شجرة الحسابات'!$A$9:$A$208,A31)>1,"⚠ رقم مكرر",IF(OR(B31="",C31="",E31="",F31=""),"⚠ بيانات ناقصة",IF(C31<>"تحليلي","● حساب تجميعي",IF(H31="","⚠ حدد بند القائمة",IF(COUNTIF(L_LINES,H31)=0,"⚠ بند غير معروف","✔ سليم")))))) -> ✔ سليم
A32: 2105 | B32: مصروفات مستحقة | C32: تحليلي | D32: 21 | E32: الخصوم | F32: دائن | G32: =IF(E32="","",IF(OR(E32="الأصول",E32="الخصوم",E32="حقوق الملكية"),"المركز المالي","قائمة الدخل")) -> المركز المالي | H32: مصروفات مستحقة وأرصدة دائنة أخرى | J32: =IF(A32="","",IF(F32="دائن",'ميزان المراجعة'!D32-'ميزان المراجعة'!C32,'ميزان المراجعة'!C32-'ميزان المراجعة'!D32)) -> 0 | K32: =IF(A32="","",IF(COUNTIF('شجرة الحسابات'!$A$9:$A$208,A32)>1,"⚠ رقم مكرر",IF(OR(B32="",C32="",E32="",F32=""),"⚠ بيانات ناقصة",IF(C32<>"تحليلي","● حساب تجميعي",IF(H32="","⚠ حدد بند القائمة",IF(COUNTIF(L_LINES,H32)=0,"⚠ بند غير معروف","✔ سليم")))))) -> ✔ سليم
A33: 2106 | B33: رواتب وأجور مستحقة | C33: تحليلي | D33: 21 | E33: الخصوم | F33: دائن | G33: =IF(E33="","",IF(OR(E33="الأصول",E33="الخصوم",E33="حقوق الملكية"),"المركز المالي","قائمة الدخل")) -> المركز المالي | H33: مصروفات مستحقة وأرصدة دائنة أخرى | J33: =IF(A33="","",IF(F33="دائن",'ميزان المراجعة'!D33-'ميزان المراجعة'!C33,'ميزان المراجعة'!C33-'ميزان المراجعة'!D33)) -> 40000 | K33: =IF(A33="","",IF(COUNTIF('شجرة الحسابات'!$A$9:$A$208,A33)>1,"⚠ رقم مكرر",IF(OR(B33="",C33="",E33="",F33=""),"⚠ بيانات ناقصة",IF(C33<>"تحليلي","● حساب تجميعي",IF(H33="","⚠ حدد بند القائمة",IF(COUNTIF(L_LINES,H33)=0,"⚠ بند غير معروف","✔ سليم")))))) -> ✔ سليم
A34: 22 | B34: الخصوم غير المتداولة | C34: فرعي | D34: 2 | E34: الخصوم | F34: دائن | G34: =IF(E34="","",IF(OR(E34="الأصول",E34="الخصوم",E34="حقوق الملكية"),"المركز المالي","قائمة الدخل")) -> المركز المالي | J34: =IF(A34="","",IF(F34="دائن",'ميزان المراجعة'!D34-'ميزان المراجعة'!C34,'ميزان المراجعة'!C34-'ميزان المراجعة'!D34)) -> 500000 | K34: =IF(A34="","",IF(COUNTIF('شجرة الحسابات'!$A$9:$A$208,A34)>1,"⚠ رقم مكرر",IF(OR(B34="",C34="",E34="",F34=""),"⚠ بيانات ناقصة",IF(C34<>"تحليلي","● حساب تجميعي",IF(H34="","⚠ حدد بند القائمة",IF(COUNTIF(L_LINES,H34)=0,"⚠ بند غير معروف","✔ سليم")))))) -> ● حساب تجميعي
A35: 2201 | B35: قروض بنكية طويلة الأجل | C35: تحليلي | D35: 22 | E35: الخصوم | F35: دائن | G35: =IF(E35="","",IF(OR(E35="الأصول",E35="الخصوم",E35="حقوق الملكية"),"المركز المالي","قائمة الدخل")) -> المركز المالي | H35: قروض طويلة الأجل | J35: =IF(A35="","",IF(F35="دائن",'ميزان المراجعة'!D35-'ميزان المراجعة'!C35,'ميزان المراجعة'!C35-'ميزان المراجعة'!D35)) -> 500000 | K35: =IF(A35="","",IF(COUNTIF('شجرة الحسابات'!$A$9:$A$208,A35)>1,"⚠ رقم مكرر",IF(OR(B35="",C35="",E35="",F35=""),"⚠ بيانات ناقصة",IF(C35<>"تحليلي","● حساب تجميعي",IF(H35="","⚠ حدد بند القائمة",IF(COUNTIF(L_LINES,H35)=0,"⚠ بند غير معروف","✔ سليم")))))) -> ✔ سليم
A36: 2202 | B36: مخصص مكافأة نهاية الخدمة | C36: تحليلي | D36: 22 | E36: الخصوم | F36: دائن | G36: =IF(E36="","",IF(OR(E36="الأصول",E36="الخصوم",E36="حقوق الملكية"),"المركز المالي","قائمة الدخل")) -> المركز المالي | H36: مخصص مكافأة نهاية الخدمة | J36: =IF(A36="","",IF(F36="دائن",'ميزان المراجعة'!D36-'ميزان المراجعة'!C36,'ميزان المراجعة'!C36-'ميزان المراجعة'!D36)) -> 0 | K36: =IF(A36="","",IF(COUNTIF('شجرة الحسابات'!$A$9:$A$208,A36)>1,"⚠ رقم مكرر",IF(OR(B36="",C36="",E36="",F36=""),"⚠ بيانات ناقصة",IF(C36<>"تحليلي","● حساب تجميعي",IF(H36="","⚠ حدد بند القائمة",IF(COUNTIF(L_LINES,H36)=0,"⚠ بند غير معروف","✔ سليم")))))) -> ✔ سليم
A37: 3 | B37: حقوق الملكية | C37: رئيسي | E37: حقوق الملكية | F37: دائن | G37: =IF(E37="","",IF(OR(E37="الأصول",E37="الخصوم",E37="حقوق الملكية"),"المركز المالي","قائمة الدخل")) -> المركز المالي | J37: =IF(A37="","",IF(F37="دائن",'ميزان المراجعة'!D37-'ميزان المراجعة'!C37,'ميزان المراجعة'!C37-'ميزان المراجعة'!D37)) -> 2960000 | K37: =IF(A37="","",IF(COUNTIF('شجرة الحسابات'!$A$9:$A$208,A37)>1,"⚠ رقم مكرر",IF(OR(B37="",C37="",E37="",F37=""),"⚠ بيانات ناقصة",IF(C37<>"تحليلي","● حساب تجميعي",IF(H37="","⚠ حدد بند القائمة",IF(COUNTIF(L_LINES,H37)=0,"⚠ بند غير معروف","✔ سليم")))))) -> ● حساب تجميعي
A38: 31 | B38: رأس المال والاحتياطيات | C38: فرعي | D38: 3 | E38: حقوق الملكية | F38: دائن | G38: =IF(E38="","",IF(OR(E38="الأصول",E38="الخصوم",E38="حقوق الملكية"),"المركز المالي","قائمة الدخل")) -> المركز المالي | J38: =IF(A38="","",IF(F38="دائن",'ميزان المراجعة'!D38-'ميزان المراجعة'!C38,'ميزان المراجعة'!C38-'ميزان المراجعة'!D38)) -> 2960000 | K38: =IF(A38="","",IF(COUNTIF('شجرة الحسابات'!$A$9:$A$208,A38)>1,"⚠ رقم مكرر",IF(OR(B38="",C38="",E38="",F38=""),"⚠ بيانات ناقصة",IF(C38<>"تحليلي","● حساب تجميعي",IF(H38="","⚠ حدد بند القائمة",IF(COUNTIF(L_LINES,H38)=0,"⚠ بند غير معروف","✔ سليم")))))) -> ● حساب تجميعي
A39: 3101 | B39: رأس المال المدفوع | C39: تحليلي | D39: 31 | E39: حقوق الملكية | F39: دائن | G39: =IF(E39="","",IF(OR(E39="الأصول",E39="الخصوم",E39="حقوق الملكية"),"المركز المالي","قائمة الدخل")) -> المركز المالي | H39: رأس المال | J39: =IF(A39="","",IF(F39="دائن",'ميزان المراجعة'!D39-'ميزان المراجعة'!C39,'ميزان المراجعة'!C39-'ميزان المراجعة'!D39)) -> 3000000 | K39: =IF(A39="","",IF(COUNTIF('شجرة الحسابات'!$A$9:$A$208,A39)>1,"⚠ رقم مكرر",IF(OR(B39="",C39="",E39="",F39=""),"⚠ بيانات ناقصة",IF(C39<>"تحليلي","● حساب تجميعي",IF(H39="","⚠ حدد بند القائمة",IF(COUNTIF(L_LINES,H39)=0,"⚠ بند غير معروف","✔ سليم")))))) -> ✔ سليم
A40: 3102 | B40: الاحتياطي النظامي | C40: تحليلي | D40: 31 | E40: حقوق الملكية | F40: دائن | G40: =IF(E40="","",IF(OR(E40="الأصول",E40="الخصوم",E40="حقوق الملكية"),"المركز المالي","قائمة الدخل")) -> المركز المالي | H40: الاحتياطيات | J40: =IF(A40="","",IF(F40="دائن",'ميزان المراجعة'!D40-'ميزان المراجعة'!C40,'ميزان المراجعة'!C40-'ميزان المراجعة'!D40)) -> 0 | K40: =IF(A40="","",IF(COUNTIF('شجرة الحسابات'!$A$9:$A$208,A40)>1,"⚠ رقم مكرر",IF(OR(B40="",C40="",E40="",F40=""),"⚠ بيانات ناقصة",IF(C40<>"تحليلي","● حساب تجميعي",IF(H40="","⚠ حدد بند القائمة",IF(COUNTIF(L_LINES,H40)=0,"⚠ بند غير معروف","✔ سليم")))))) -> ✔ سليم
A41: 3103 | B41: الأرباح المحتجزة | C41: تحليلي | D41: 31 | E41: حقوق الملكية | F41: دائن | G41: =IF(E41="","",IF(OR(E41="الأصول",E41="الخصوم",E41="حقوق الملكية"),"المركز المالي","قائمة الدخل")) -> المركز المالي | H41: الأرباح المحتجزة | J41: =IF(A41="","",IF(F41="دائن",'ميزان المراجعة'!D41-'ميزان المراجعة'!C41,'ميزان المراجعة'!C41-'ميزان المراجعة'!D41)) -> 0 | K41: =IF(A41="","",IF(COUNTIF('شجرة الحسابات'!$A$9:$A$208,A41)>1,"⚠ رقم مكرر",IF(OR(B41="",C41="",E41="",F41=""),"⚠ بيانات ناقصة",IF(C41<>"تحليلي","● حساب تجميعي",IF(H41="","⚠ حدد بند القائمة",IF(COUNTIF(L_LINES,H41)=0,"⚠ بند غير معروف","✔ سليم")))))) -> ✔ سليم
...

Sheet قيود اليومية
A1: واجهة إدخال القيود اليومية
A2: =الرئيسية!$C$6&" | الفترة المنتهية في: "&TEXT(الرئيسية!$C$7,"yyyy/mm/dd")&" | المبالغ بـ "&الرئيسية!$G$7 -> شركة الإعمار الحديثة للمقاولات العامة | الفترة المنتهية في: 2026/03/31 | المبالغ بـ ريال
A3: 🏠 الرئيسية | B3: 🌳 الشجرة | C3: 🏗 المشروعات | D3: 📄 كشف مشروع | E3: 📒 الأستاذ | F3: ⚖ الميزان | G3: 📈 الدخل | H3: 🏦 المركز المالي
A5: 🔎 فحص قيد قبل الترحيل | C5: مدين القيد | D5: دائن القيد | E5: الفرق | F5: حالة القيد المختار | G5: إجمالي المدين (كل القيود) | H5: إجمالي الدائن (كل القيود) | I5: قيود غير مرحّلة
A6: رقم القيد: | B6: 12 | C6: =SUMIFS('قيود اليومية'!$G$11:$G$1010,'قيود اليومية'!$A$11:$A$1010,$B$6) -> 1500000 | D6: =SUMIFS('قيود اليومية'!$H$11:$H$1010,'قيود اليومية'!$A$11:$A$1010,$B$6) -> 1500000 | E6: =ROUND(C6-D6,2) -> 0 | F6: =IF($B$6="","— أدخل رقم القيد —",IF(COUNTIF('قيود اليومية'!$A$11:$A$1010,$B$6)=0,"⚠ القيد غير موجود",IF(COUNTIFS('قيود اليومية'!$A$11:$A$1010,$B$6,'قيود اليومية'!$I$11:$I$1010,"مرحل ✔")>0,"✔ القيد متوازن وتم ترحيله",IF(E6<>0,"✖ غير متوازن - لن يُرحّل (الفرق "&TEXT(ABS(E6),"#,##0.00")&")","✖ به خطأ في الحسابات - راجع عمود الفحص")))) -> ✔ القيد متوازن وتم ترحيله | G6: =SUM('قيود اليومية'!$G$11:$G$1010) -> 13413700 | H6: =SUM('قيود اليومية'!$H$11:$H$1010) -> 13410700 | I6: =SUMPRODUCT(('قيود اليومية'!$A$11:$A$1010<>"")*('قيود اليومية'!$I$11:$I$1010<>"مرحل ✔")/COUNTIF('قيود اليومية'!$A$11:$A$1010,'قيود اليومية'!$A$11:$A$1010&"")) -> 1
A7: رقم القيد التالي: | B7: =MAX('قيود اليومية'!$A$11:$A$1010)+1 -> 29
A8: =IF(I6>0,"⚠ تنبيه: يوجد "&TEXT(I6,"0")&" قيد غير متوازن أو به خطأ — هذه القيود لا تُرحّل للميزان والقوائم حتى تصحيحها (الأسطر المظللة بالأحمر).","✔ جميع القيود متوازنة ومرحّلة للميزان والقوائم المالية.") -> ⚠ تنبيه: يوجد 1 قيد غير متوازن أو به خطأ — هذه القيود لا تُرحّل للميزان والقوائم حتى تصحيحها (الأسطر المظللة بالأحمر).
A9: طريقة الإدخال: لكل قيد عدة أسطر بنفس الرقم والتاريخ — اختر رقم الحساب من القائمة المنسدلة واسم المشروع (اختياري للمصاريف العامة) — أدخل المبلغ في المدين أو الدائن فقط. الأعمدة J:O مساعدة تلقائية (مخفية، اضغط + لإظهارها).
A10: رقم القيد | B10: التاريخ | C10: رقم الحساب | D10: اسم الحساب | E10: اسم المشروع | F10: البيان / الشرح | G10: مدين | H10: دائن | I10: حالة القيد | J10: نوع الحساب | K10: عنصر التكلفة | L10: المستوى | M10: فحص السطر | N10: تسلسل المشروع | O10: تسلسل الحساب
A11: 1 | B11: 46023 | C11: 1102 | D11: =IF(C11="","",IFERROR(INDEX('شجرة الحسابات'!$B$9:$B$208,MATCH(C11,'شجرة الحسابات'!$A$9:$A$208,0)),"⚠ حساب غير معرف")) -> البنك - الحساب الجاري | F11: إيداع رأس المال المدفوع بالبنك | G11: 3000000 | I11: =IF(A11="",IF(M11="فارغ","","✖ بدون رقم قيد"),IF(COUNTIFS('قيود اليومية'!$A$11:$A$1010,A11,'قيود اليومية'!$M$11:$M$1010,"<>OK",'قيود اليومية'!$M$11:$M$1010,"<>فارغ")>0,"✖ خطأ بالحساب",IF(ROUND(SUMIFS('قيود اليومية'!$G$11:$G$1010,'قيود اليومية'!$A$11:$A$1010,A11)-SUMIFS('قيود اليومية'!$H$11:$H$1010,'قيود اليومية'!$A$11:$A$1010,A11),2)<>0,"✖ غير متوازن","مرحل ✔"))) -> مرحل ✔ | J11: =IF(C11="","",IFERROR(INDEX('شجرة الحسابات'!$E$9:$E$208,MATCH(C11,'شجرة الحسابات'!$A$9:$A$208,0))&"","")) -> الأصول | K11: =IF(C11="","",IFERROR(INDEX('شجرة الحسابات'!$I$9:$I$208,MATCH(C11,'شجرة الحسابات'!$A$9:$A$208,0))&"","")) | L11: =IF(C11="","",IFERROR(INDEX('شجرة الحسابات'!$C$9:$C$208,MATCH(C11,'شجرة الحسابات'!$A$9:$A$208,0))&"","")) -> تحليلي | M11: =IF(AND(C11="",G11="",H11=""),"فارغ",IF(ISNA(MATCH(C11,'شجرة الحسابات'!$A$9:$A$208,0)),"حساب غير معرف",IF(L11<>"تحليلي","حساب تجميعي",IF(AND(N(G11)>0,N(H11)>0),"مدين ودائن معاً",IF(N(G11)+N(H11)=0,"بدون قيمة","OK"))))) -> OK | N11: =IF(AND(E11<>"",E11='كشف حساب مشروع'!$C$6,I11="مرحل ✔"),COUNTIFS($E$11:E11,'كشف حساب مشروع'!$C$6,$I$11:I11,"مرحل ✔"),"") | O11: =IF(AND(C11<>"",C11='دفتر الأستاذ'!$C$6,I11="مرحل ✔"),COUNTIFS($C$11:C11,'دفتر الأستاذ'!$C$6,$I$11:I11,"مرحل ✔"),"") -> 1
A12: 1 | B12: 46023 | C12: 3101 | D12: =IF(C12="","",IFERROR(INDEX('شجرة الحسابات'!$B$9:$B$208,MATCH(C12,'شجرة الحسابات'!$A$9:$A$208,0)),"⚠ حساب غير معرف")) -> رأس المال المدفوع | F12: إيداع رأس المال المدفوع بالبنك | H12: 3000000 | I12: =IF(A12="",IF(M12="فارغ","","✖ بدون رقم قيد"),IF(COUNTIFS('قيود اليومية'!$A$11:$A$1010,A12,'قيود اليومية'!$M$11:$M$1010,"<>OK",'قيود اليومية'!$M$11:$M$1010,"<>فارغ")>0,"✖ خطأ بالحساب",IF(ROUND(SUMIFS('قيود اليومية'!$G$11:$G$1010,'قيود اليومية'!$A$11:$A$1010,A12)-SUMIFS('قيود اليومية'!$H$11:$H$1010,'قيود اليومية'!$A$11:$A$1010,A12),2)<>0,"✖ غير متوازن","مرحل ✔"))) -> مرحل ✔ | J12: =IF(C12="","",IFERROR(INDEX('شجرة الحسابات'!$E$9:$E$208,MATCH(C12,'شجرة الحسابات'!$A$9:$A$208,0))&"","")) -> حقوق الملكية | K12: =IF(C12="","",IFERROR(INDEX('شجرة الحسابات'!$I$9:$I$208,MATCH(C12,'شجرة الحسابات'!$A$9:$A$208,0))&"","")) | L12: =IF(C12="","",IFERROR(INDEX('شجرة الحسابات'!$C$9:$C$208,MATCH(C12,'شجرة الحسابات'!$A$9:$A$208,0))&"","")) -> تحليلي | M12: =IF(AND(C12="",G12="",H12=""),"فارغ",IF(ISNA(MATCH(C12,'شجرة الحسابات'!$A$9:$A$208,0)),"حساب غير معرف",IF(L12<>"تحليلي","حساب تجميعي",IF(AND(N(G12)>0,N(H12)>0),"مدين ودائن معاً",IF(N(G12)+N(H12)=0,"بدون قيمة","OK"))))) -> OK | N12: =IF(AND(E12<>"",E12='كشف حساب مشروع'!$C$6,I12="مرحل ✔"),COUNTIFS($E$11:E12,'كشف حساب مشروع'!$C$6,$I$11:I12,"مرحل ✔"),"") | O12: =IF(AND(C12<>"",C12='دفتر الأستاذ'!$C$6,I12="مرحل ✔"),COUNTIFS($C$11:C12,'دفتر الأستاذ'!$C$6,$I$11:I12,"مرحل ✔"),"")
A13: 2 | B13: 46027 | C13: 1201 | D13: =IF(C13="","",IFERROR(INDEX('شجرة الحسابات'!$B$9:$B$208,MATCH(C13,'شجرة الحسابات'!$A$9:$A$208,0)),"⚠ حساب غير معرف")) -> المعدات والآلات الثقيلة | F13: شراء معدات ثقيلة (حفار + رافعة) | G13: 1200000 | I13: =IF(A13="",IF(M13="فارغ","","✖ بدون رقم قيد"),IF(COUNTIFS('قيود اليومية'!$A$11:$A$1010,A13,'قيود اليومية'!$M$11:$M$1010,"<>OK",'قيود اليومية'!$M$11:$M$1010,"<>فارغ")>0,"✖ خطأ بالحساب",IF(ROUND(SUMIFS('قيود اليومية'!$G$11:$G$1010,'قيود اليومية'!$A$11:$A$1010,A13)-SUMIFS('قيود اليومية'!$H$11:$H$1010,'قيود اليومية'!$A$11:$A$1010,A13),2)<>0,"✖ غير متوازن","مرحل ✔"))) -> مرحل ✔ | J13: =IF(C13="","",IFERROR(INDEX('شجرة الحسابات'!$E$9:$E$208,MATCH(C13,'شجرة الحسابات'!$A$9:$A$208,0))&"","")) -> الأصول | K13: =IF(C13="","",IFERROR(INDEX('شجرة الحسابات'!$I$9:$I$208,MATCH(C13,'شجرة الحسابات'!$A$9:$A$208,0))&"","")) | L13: =IF(C13="","",IFERROR(INDEX('شجرة الحسابات'!$C$9:$C$208,MATCH(C13,'شجرة الحسابات'!$A$9:$A$208,0))&"","")) -> تحليلي | M13: =IF(AND(C13="",G13="",H13=""),"فارغ",IF(ISNA(MATCH(C13,'شجرة الحسابات'!$A$9:$A$208,0)),"حساب غير معرف",IF(L13<>"تحليلي","حساب تجميعي",IF(AND(N(G13)>0,N(H13)>0),"مدين ودائن معاً",IF(N(G13)+N(H13)=0,"بدون قيمة","OK"))))) -> OK | N13: =IF(AND(E13<>"",E13='كشف حساب مشروع'!$C$6,I13="مرحل ✔"),COUNTIFS($E$11:E13,'كشف حساب مشروع'!$C$6,$I$11:I13,"مرحل ✔"),"") | O13: =IF(AND(C13<>"",C13='دفتر الأستاذ'!$C$6,I13="مرحل ✔"),COUNTIFS($C$11:C13,'دفتر الأستاذ'!$C$6,$I$11:I13,"مرحل ✔"),"")
A14: 2 | B14: 46027 | C14: 1202 | D14: =IF(C14="","",IFERROR(INDEX('شجرة الحسابات'!$B$9:$B$208,MATCH(C14,'شجرة الحسابات'!$A$9:$A$208,0)),"⚠ حساب غير معرف")) -> السيارات ووسائل النقل | F14: شراء سيارات نقل وبيك أب | G14: 250000 | I14: =IF(A14="",IF(M14="فارغ","","✖ بدون رقم قيد"),IF(COUNTIFS('قيود اليومية'!$A$11:$A$1010,A14,'قيود اليومية'!$M$11:$M$1010,"<>OK",'قيود اليومية'!$M$11:$M$1010,"<>فارغ")>0,"✖ خطأ بالحساب",IF(ROUND(SUMIFS('قيود اليومية'!$G$11:$G$1010,'قيود اليومية'!$A$11:$A$1010,A14)-SUMIFS('قيود اليومية'!$H$11:$H$1010,'قيود اليومية'!$A$11:$A$1010,A14),2)<>0,"✖ غير متوازن","مرحل ✔"))) -> مرحل ✔ | J14: =IF(C14="","",IFERROR(INDEX('شجرة الحسابات'!$E$9:$E$208,MATCH(C14,'شجرة الحسابات'!$A$9:$A$208,0))&"","")) -> الأصول | K14: =IF(C14="","",IFERROR(INDEX('شجرة الحسابات'!$I$9:$I$208,MATCH(C14,'شجرة الحسابات'!$A$9:$A$208,0))&"","")) | L14: =IF(C14="","",IFERROR(INDEX('شجرة الحسابات'!$C$9:$C$208,MATCH(C14,'شجرة الحسابات'!$A$9:$A$208,0))&"","")) -> تحليلي | M14: =IF(AND(C14="",G14="",H14=""),"فارغ",IF(ISNA(MATCH(C14,'شجرة الحسابات'!$A$9:$A$208,0)),"حساب غير معرف",IF(L14<>"تحليلي","حساب تجميعي",IF(AND(N(G14)>0,N(H14)>0),"مدين ودائن معاً",IF(N(G14)+N(H14)=0,"بدون قيمة","OK"))))) -> OK | N14: =IF(AND(E14<>"",E14='كشف حساب مشروع'!$C$6,I14="مرحل ✔"),COUNTIFS($E$11:E14,'كشف حساب مشروع'!$C$6,$I$11:I14,"مرحل ✔"),"") | O14: =IF(AND(C14<>"",C14='دفتر الأستاذ'!$C$6,I14="مرحل ✔"),COUNTIFS($C$11:C14,'دفتر الأستاذ'!$C$6,$I$11:I14,"مرحل ✔"),"")
A15: 2 | B15: 46027 | C15: 1203 | D15: =IF(C15="","",IFERROR(INDEX('شجرة الحسابات'!$B$9:$B$208,MATCH(C15,'شجرة الحسابات'!$A$9:$A$208,0)),"⚠ حساب غير معرف")) -> الأثاث والتجهيزات المكتبية | F15: أثاث وتجهيزات المكتب الرئيسي | G15: 80000 | I15: =IF(A15="",IF(M15="فارغ","","✖ بدون رقم قيد"),IF(COUNTIFS('قيود اليومية'!$A$11:$A$1010,A15,'قيود اليومية'!$M$11:$M$1010,"<>OK",'قيود اليومية'!$M$11:$M$1010,"<>فارغ")>0,"✖ خطأ بالحساب",IF(ROUND(SUMIFS('قيود اليومية'!$G$11:$G$1010,'قيود اليومية'!$A$11:$A$1010,A15)-SUMIFS('قيود اليومية'!$H$11:$H$1010,'قيود اليومية'!$A$11:$A$1010,A15),2)<>0,"✖ غير متوازن","مرحل ✔"))) -> مرحل ✔ | J15: =IF(C15="","",IFERROR(INDEX('شجرة الحسابات'!$E$9:$E$208,MATCH(C15,'شجرة الحسابات'!$A$9:$A$208,0))&"","")) -> الأصول | K15: =IF(C15="","",IFERROR(INDEX('شجرة الحسابات'!$I$9:$I$208,MATCH(C15,'شجرة الحسابات'!$A$9:$A$208,0))&"","")) | L15: =IF(C15="","",IFERROR(INDEX('شجرة الحسابات'!$C$9:$C$208,MATCH(C15,'شجرة الحسابات'!$A$9:$A$208,0))&"","")) -> تحليلي | M15: =IF(AND(C15="",G15="",H15=""),"فارغ",IF(ISNA(MATCH(C15,'شجرة الحسابات'!$A$9:$A$208,0)),"حساب غير معرف",IF(L15<>"تحليلي","حساب تجميعي",IF(AND(N(G15)>0,N(H15)>0),"مدين ودائن معاً",IF(N(G15)+N(H15)=0,"بدون قيمة","OK"))))) -> OK | N15: =IF(AND(E15<>"",E15='كشف حساب مشروع'!$C$6,I15="مرحل ✔"),COUNTIFS($E$11:E15,'كشف حساب مشروع'!$C$6,$I$11:I15,"مرحل ✔"),"") | O15: =IF(AND(C15<>"",C15='دفتر الأستاذ'!$C$6,I15="مرحل ✔"),COUNTIFS($C$11:C15,'دفتر الأستاذ'!$C$6,$I$11:I15,"مرحل ✔"),"")
A16: 2 | B16: 46027 | C16: 1102 | D16: =IF(C16="","",IFERROR(INDEX('شجرة الحسابات'!$B$9:$B$208,MATCH(C16,'شجرة الحسابات'!$A$9:$A$208,0)),"⚠ حساب غير معرف")) -> البنك - الحساب الجاري | F16: سداد جزء من ثمن الأصول | H16: 1030000 | I16: =IF(A16="",IF(M16="فارغ","","✖ بدون رقم قيد"),IF(COUNTIFS('قيود اليومية'!$A$11:$A$1010,A16,'قيود اليومية'!$M$11:$M$1010,"<>OK",'قيود اليومية'!$M$11:$M$1010,"<>فارغ")>0,"✖ خطأ بالحساب",IF(ROUND(SUMIFS('قيود اليومية'!$G$11:$G$1010,'قيود اليومية'!$A$11:$A$1010,A16)-SUMIFS('قيود اليومية'!$H$11:$H$1010,'قيود اليومية'!$A$11:$A$1010,A16),2)<>0,"✖ غير متوازن","مرحل ✔"))) -> مرحل ✔ | J16: =IF(C16="","",IFERROR(INDEX('شجرة الحسابات'!$E$9:$E$208,MATCH(C16,'شجرة الحسابات'!$A$9:$A$208,0))&"","")) -> الأصول | K16: =IF(C16="","",IFERROR(INDEX('شجرة الحسابات'!$I$9:$I$208,MATCH(C16,'شجرة الحسابات'!$A$9:$A$208,0))&"","")) | L16: =IF(C16="","",IFERROR(INDEX('شجرة الحسابات'!$C$9:$C$208,MATCH(C16,'شجرة الحسابات'!$A$9:$A$208,0))&"","")) -> تحليلي | M16: =IF(AND(C16="",G16="",H16=""),"فارغ",IF(ISNA(MATCH(C16,'شجرة الحسابات'!$A$9:$A$208,0)),"حساب غير معرف",IF(L16<>"تحليلي","حساب تجميعي",IF(AND(N(G16)>0,N(H16)>0),"مدين ودائن معاً",IF(N(G16)+N(H16)=0,"بدون قيمة","OK"))))) -> OK | N16: =IF(AND(E16<>"",E16='كشف حساب مشروع'!$C$6,I16="مرحل ✔"),COUNTIFS($E$11:E16,'كشف حساب مشروع'!$C$6,$I$11:I16,"مرحل ✔"),"") | O16: =IF(AND(C16<>"",C16='دفتر الأستاذ'!$C$6,I16="مرحل ✔"),COUNTIFS($C$11:C16,'دفتر الأستاذ'!$C$6,$I$11:I16,"مرحل ✔"),"") -> 2
A17: 2 | B17: 46027 | C17: 2201 | D17: =IF(C17="","",IFERROR(INDEX('شجرة الحسابات'!$B$9:$B$208,MATCH(C17,'شجرة الحسابات'!$A$9:$A$208,0)),"⚠ حساب غير معرف")) -> قروض بنكية طويلة الأجل | F17: قرض بنكي لتمويل المعدات | H17: 500000 | I17: =IF(A17="",IF(M17="فارغ","","✖ بدون رقم قيد"),IF(COUNTIFS('قيود اليومية'!$A$11:$A$1010,A17,'قيود اليومية'!$M$11:$M$1010,"<>OK",'قيود اليومية'!$M$11:$M$1010,"<>فارغ")>0,"✖ خطأ بالحساب",IF(ROUND(SUMIFS('قيود اليومية'!$G$11:$G$1010,'قيود اليومية'!$A$11:$A$1010,A17)-SUMIFS('قيود اليومية'!$H$11:$H$1010,'قيود اليومية'!$A$11:$A$1010,A17),2)<>0,"✖ غير متوازن","مرحل ✔"))) -> مرحل ✔ | J17: =IF(C17="","",IFERROR(INDEX('شجرة الحسابات'!$E$9:$E$208,MATCH(C17,'شجرة الحسابات'!$A$9:$A$208,0))&"","")) -> الخصوم | K17: =IF(C17="","",IFERROR(INDEX('شجرة الحسابات'!$I$9:$I$208,MATCH(C17,'شجرة الحسابات'!$A$9:$A$208,0))&"","")) | L17: =IF(C17="","",IFERROR(INDEX('شجرة الحسابات'!$C$9:$C$208,MATCH(C17,'شجرة الحسابات'!$A$9:$A$208,0))&"","")) -> تحليلي | M17: =IF(AND(C17="",G17="",H17=""),"فارغ",IF(ISNA(MATCH(C17,'شجرة الحسابات'!$A$9:$A$208,0)),"حساب غير معرف",IF(L17<>"تحليلي","حساب تجميعي",IF(AND(N(G17)>0,N(H17)>0),"مدين ودائن معاً",IF(N(G17)+N(H17)=0,"بدون قيمة","OK"))))) -> OK | N17: =IF(AND(E17<>"",E17='كشف حساب مشروع'!$C$6,I17="مرحل ✔"),COUNTIFS($E$11:E17,'كشف حساب مشروع'!$C$6,$I$11:I17,"مرحل ✔"),"") | O17: =IF(AND(C17<>"",C17='دفتر الأستاذ'!$C$6,I17="مرحل ✔"),COUNTIFS($C$11:C17,'دفتر الأستاذ'!$C$6,$I$11:I17,"مرحل ✔"),"")
A18: 3 | B18: 46030 | C18: 1101 | D18: =IF(C18="","",IFERROR(INDEX('شجرة الحسابات'!$B$9:$B$208,MATCH(C18,'شجرة الحسابات'!$A$9:$A$208,0)),"⚠ حساب غير معرف")) -> الصندوق (النقدية بالخزينة) | F18: تغذية الخزينة (عهدة نقدية) | G18: 80000 | I18: =IF(A18="",IF(M18="فارغ","","✖ بدون رقم قيد"),IF(COUNTIFS('قيود اليومية'!$A$11:$A$1010,A18,'قيود اليومية'!$M$11:$M$1010,"<>OK",'قيود اليومية'!$M$11:$M$1010,"<>فارغ")>0,"✖ خطأ بالحساب",IF(ROUND(SUMIFS('قيود اليومية'!$G$11:$G$1010,'قيود اليومية'!$A$11:$A$1010,A18)-SUMIFS('قيود اليومية'!$H$11:$H$1010,'قيود اليومية'!$A$11:$A$1010,A18),2)<>0,"✖ غير متوازن","مرحل ✔"))) -> مرحل ✔ | J18: =IF(C18="","",IFERROR(INDEX('شجرة الحسابات'!$E$9:$E$208,MATCH(C18,'شجرة الحسابات'!$A$9:$A$208,0))&"","")) -> الأصول | K18: =IF(C18="","",IFERROR(INDEX('شجرة الحسابات'!$I$9:$I$208,MATCH(C18,'شجرة الحسابات'!$A$9:$A$208,0))&"","")) | L18: =IF(C18="","",IFERROR(INDEX('شجرة الحسابات'!$C$9:$C$208,MATCH(C18,'شجرة الحسابات'!$A$9:$A$208,0))&"","")) -> تحليلي | M18: =IF(AND(C18="",G18="",H18=""),"فارغ",IF(ISNA(MATCH(C18,'شجرة الحسابات'!$A$9:$A$208,0)),"حساب غير معرف",IF(L18<>"تحليلي","حساب تجميعي",IF(AND(N(G18)>0,N(H18)>0),"مدين ودائن معاً",IF(N(G18)+N(H18)=0,"بدون قيمة","OK"))))) -> OK | N18: =IF(AND(E18<>"",E18='كشف حساب مشروع'!$C$6,I18="مرحل ✔"),COUNTIFS($E$11:E18,'كشف حساب مشروع'!$C$6,$I$11:I18,"مرحل ✔"),"") | O18: =IF(AND(C18<>"",C18='دفتر الأستاذ'!$C$6,I18="مرحل ✔"),COUNTIFS($C$11:C18,'دفتر الأستاذ'!$C$6,$I$11:I18,"مرحل ✔"),"")
A19: 3 | B19: 46030 | C19: 1102 | D19: =IF(C19="","",IFERROR(INDEX('شجرة الحسابات'!$B$9:$B$208,MATCH(C19,'شجرة الحسابات'!$A$9:$A$208,0)),"⚠ حساب غير معرف")) -> البنك - الحساب الجاري | F19: تغذية الخزينة (عهدة نقدية) | H19: 80000 | I19: =IF(A19="",IF(M19="فارغ","","✖ بدون رقم قيد"),IF(COUNTIFS('قيود اليومية'!$A$11:$A$1010,A19,'قيود اليومية'!$M$11:$M$1010,"<>OK",'قيود اليومية'!$M$11:$M$1010,"<>فارغ")>0,"✖ خطأ بالحساب",IF(ROUND(SUMIFS('قيود اليومية'!$G$11:$G$1010,'قيود اليومية'!$A$11:$A$1010,A19)-SUMIFS('قيود اليومية'!$H$11:$H$1010,'قيود اليومية'!$A$11:$A$1010,A19),2)<>0,"✖ غير متوازن","مرحل ✔"))) -> مرحل ✔ | J19: =IF(C19="","",IFERROR(INDEX('شجرة الحسابات'!$E$9:$E$208,MATCH(C19,'شجرة الحسابات'!$A$9:$A$208,0))&"","")) -> الأصول | K19: =IF(C19="","",IFERROR(INDEX('شجرة الحسابات'!$I$9:$I$208,MATCH(C19,'شجرة الحسابات'!$A$9:$A$208,0))&"","")) | L19: =IF(C19="","",IFERROR(INDEX('شجرة الحسابات'!$C$9:$C$208,MATCH(C19,'شجرة الحسابات'!$A$9:$A$208,0))&"","")) -> تحليلي | M19: =IF(AND(C19="",G19="",H19=""),"فارغ",IF(ISNA(MATCH(C19,'شجرة الحسابات'!$A$9:$A$208,0)),"حساب غير معرف",IF(L19<>"تحليلي","حساب تجميعي",IF(AND(N(G19)>0,N(H19)>0),"مدين ودائن معاً",IF(N(G19)+N(H19)=0,"بدون قيمة","OK"))))) -> OK | N19: =IF(AND(E19<>"",E19='كشف حساب مشروع'!$C$6,I19="مرحل ✔"),COUNTIFS($E$11:E19,'كشف حساب مشروع'!$C$6,$I$11:I19,"مرحل ✔"),"") | O19: =IF(AND(C19<>"",C19='دفتر الأستاذ'!$C$6,I19="مرحل ✔"),COUNTIFS($C$11:C19,'دفتر الأستاذ'!$C$6,$I$11:I19,"مرحل ✔"),"") -> 3
A20: 4 | B20: 46032 | C20: 1102 | D20: =IF(C20="","",IFERROR(INDEX('شجرة الحسابات'!$B$9:$B$208,MATCH(C20,'شجرة الحسابات'!$A$9:$A$208,0)),"⚠ حساب غير معرف")) -> البنك - الحساب الجاري | E20: برج الريان التجاري | F20: استلام دفعة مقدمة 15% من العميل | G20: 750000 | I20: =IF(A20="",IF(M20="فارغ","","✖ بدون رقم قيد"),IF(COUNTIFS('قيود اليومية'!$A$11:$A$1010,A20,'قيود اليومية'!$M$11:$M$1010,"<>OK",'قيود اليومية'!$M$11:$M$1010,"<>فارغ")>0,"✖ خطأ بالحساب",IF(ROUND(SUMIFS('قيود اليومية'!$G$11:$G$1010,'قيود اليومية'!$A$11:$A$1010,A20)-SUMIFS('قيود اليومية'!$H$11:$H$1010,'قيود اليومية'!$A$11:$A$1010,A20),2)<>0,"✖ غير متوازن","مرحل ✔"))) -> مرحل ✔ | J20: =IF(C20="","",IFERROR(INDEX('شجرة الحسابات'!$E$9:$E$208,MATCH(C20,'شجرة الحسابات'!$A$9:$A$208,0))&"","")) -> الأصول | K20: =IF(C20="","",IFERROR(INDEX('شجرة الحسابات'!$I$9:$I$208,MATCH(C20,'شجرة الحسابات'!$A$9:$A$208,0))&"","")) | L20: =IF(C20="","",IFERROR(INDEX('شجرة الحسابات'!$C$9:$C$208,MATCH(C20,'شجرة الحسابات'!$A$9:$A$208,0))&"","")) -> تحليلي | M20: =IF(AND(C20="",G20="",H20=""),"فارغ",IF(ISNA(MATCH(C20,'شجرة الحسابات'!$A$9:$A$208,0)),"حساب غير معرف",IF(L20<>"تحليلي","حساب تجميعي",IF(AND(N(G20)>0,N(H20)>0),"مدين ودائن معاً",IF(N(G20)+N(H20)=0,"بدون قيمة","OK"))))) -> OK | N20: =IF(AND(E20<>"",E20='كشف حساب مشروع'!$C$6,I20="مرحل ✔"),COUNTIFS($E$11:E20,'كشف حساب مشروع'!$C$6,$I$11:I20,"مرحل ✔"),"") -> 1 | O20: =IF(AND(C20<>"",C20='دفتر الأستاذ'!$C$6,I20="مرحل ✔"),COUNTIFS($C$11:C20,'دفتر الأستاذ'!$C$6,$I$11:I20,"مرحل ✔"),"") -> 4
A21: 4 | B21: 46032 | C21: 2104 | D21: =IF(C21="","",IFERROR(INDEX('شجرة الحسابات'!$B$9:$B$208,MATCH(C21,'شجرة الحسابات'!$A$9:$A$208,0)),"⚠ حساب غير معرف")) -> دفعات مقدمة من العملاء | E21: برج الريان التجاري | F21: استلام دفعة مقدمة 15% من العميل | H21: 750000 | I21: =IF(A21="",IF(M21="فارغ","","✖ بدون رقم قيد"),IF(COUNTIFS('قيود اليومية'!$A$11:$A$1010,A21,'قيود اليومية'!$M$11:$M$1010,"<>OK",'قيود اليومية'!$M$11:$M$1010,"<>فارغ")>0,"✖ خطأ بالحساب",IF(ROUND(SUMIFS('قيود اليومية'!$G$11:$G$1010,'قيود اليومية'!$A$11:$A$1010,A21)-SUMIFS('قيود اليومية'!$H$11:$H$1010,'قيود اليومية'!$A$11:$A$1010,A21),2)<>0,"✖ غير متوازن","مرحل ✔"))) -> مرحل ✔ | J21: =IF(C21="","",IFERROR(INDEX('شجرة الحسابات'!$E$9:$E$208,MATCH(C21,'شجرة الحسابات'!$A$9:$A$208,0))&"","")) -> الخصوم | K21: =IF(C21="","",IFERROR(INDEX('شجرة الحسابات'!$I$9:$I$208,MATCH(C21,'شجرة الحسابات'!$A$9:$A$208,0))&"","")) | L21: =IF(C21="","",IFERROR(INDEX('شجرة الحسابات'!$C$9:$C$208,MATCH(C21,'شجرة الحسابات'!$A$9:$A$208,0))&"","")) -> تحليلي | M21: =IF(AND(C21="",G21="",H21=""),"فارغ",IF(ISNA(MATCH(C21,'شجرة الحسابات'!$A$9:$A$208,0)),"حساب غير معرف",IF(L21<>"تحليلي","حساب تجميعي",IF(AND(N(G21)>0,N(H21)>0),"مدين ودائن معاً",IF(N(G21)+N(H21)=0,"بدون قيمة","OK"))))) -> OK | N21: =IF(AND(E21<>"",E21='كشف حساب مشروع'!$C$6,I21="مرحل ✔"),COUNTIFS($E$11:E21,'كشف حساب مشروع'!$C$6,$I$11:I21,"مرحل ✔"),"") -> 2 | O21: =IF(AND(C21<>"",C21='دفتر الأستاذ'!$C$6,I21="مرحل ✔"),COUNTIFS($C$11:C21,'دفتر الأستاذ'!$C$6,$I$11:I21,"مرحل ✔"),"")
A22: 5 | B22: 46034 | C22: 1102 | D22: =IF(C22="","",IFERROR(INDEX('شجرة الحسابات'!$B$9:$B$208,MATCH(C22,'شجرة الحسابات'!$A$9:$A$208,0)),"⚠ حساب غير معرف")) -> البنك - الحساب الجاري | E22: مجمع فلل النخيل السكني | F22: استلام دفعة مقدمة 10% من العميل | G22: 320000 | I22: =IF(A22="",IF(M22="فارغ","","✖ بدون رقم قيد"),IF(COUNTIFS('قيود اليومية'!$A$11:$A$1010,A22,'قيود اليومية'!$M$11:$M$1010,"<>OK",'قيود اليومية'!$M$11:$M$1010,"<>فارغ")>0,"✖ خطأ بالحساب",IF(ROUND(SUMIFS('قيود اليومية'!$G$11:$G$1010,'قيود اليومية'!$A$11:$A$1010,A22)-SUMIFS('قيود اليومية'!$H$11:$H$1010,'قيود اليومية'!$A$11:$A$1010,A22),2)<>0,"✖ غير متوازن","مرحل ✔"))) -> مرحل ✔ | J22: =IF(C22="","",IFERROR(INDEX('شجرة الحسابات'!$E$9:$E$208,MATCH(C22,'شجرة الحسابات'!$A$9:$A$208,0))&"","")) -> الأصول | K22: =IF(C22="","",IFERROR(INDEX('شجرة الحسابات'!$I$9:$I$208,MATCH(C22,'شجرة الحسابات'!$A$9:$A$208,0))&"","")) | L22: =IF(C22="","",IFERROR(INDEX('شجرة الحسابات'!$C$9:$C$208,MATCH(C22,'شجرة الحسابات'!$A$9:$A$208,0))&"","")) -> تحليلي | M22: =IF(AND(C22="",G22="",H22=""),"فارغ",IF(ISNA(MATCH(C22,'شجرة الحسابات'!$A$9:$A$208,0)),"حساب غير معرف",IF(L22<>"تحليلي","حساب تجميعي",IF(AND(N(G22)>0,N(H22)>0),"مدين ودائن معاً",IF(N(G22)+N(H22)=0,"بدون قيمة","OK"))))) -> OK | N22: =IF(AND(E22<>"",E22='كشف حساب مشروع'!$C$6,I22="مرحل ✔"),COUNTIFS($E$11:E22,'كشف حساب مشروع'!$C$6,$I$11:I22,"مرحل ✔"),"") | O22: =IF(AND(C22<>"",C22='دفتر الأستاذ'!$C$6,I22="مرحل ✔"),COUNTIFS($C$11:C22,'دفتر الأستاذ'!$C$6,$I$11:I22,"مرحل ✔"),"") -> 5
A23: 5 | B23: 46034 | C23: 2104 | D23: =IF(C23="","",IFERROR(INDEX('شجرة الحسابات'!$B$9:$B$208,MATCH(C23,'شجرة الحسابات'!$A$9:$A$208,0)),"⚠ حساب غير معرف")) -> دفعات مقدمة من العملاء | E23: مجمع فلل النخيل السكني | F23: استلام دفعة مقدمة 10% من العميل | H23: 320000 | I23: =IF(A23="",IF(M23="فارغ","","✖ بدون رقم قيد"),IF(COUNTIFS('قيود اليومية'!$A$11:$A$1010,A23,'قيود اليومية'!$M$11:$M$1010,"<>OK",'قيود اليومية'!$M$11:$M$1010,"<>فارغ")>0,"✖ خطأ بالحساب",IF(ROUND(SUMIFS('قيود اليومية'!$G$11:$G$1010,'قيود اليومية'!$A$11:$A$1010,A23)-SUMIFS('قيود اليومية'!$H$11:$H$1010,'قيود اليومية'!$A$11:$A$1010,A23),2)<>0,"✖ غير متوازن","مرحل ✔"))) -> مرحل ✔ | J23: =IF(C23="","",IFERROR(INDEX('شجرة الحسابات'!$E$9:$E$208,MATCH(C23,'شجرة الحسابات'!$A$9:$A$208,0))&"","")) -> الخصوم | K23: =IF(C23="","",IFERROR(INDEX('شجرة الحسابات'!$I$9:$I$208,MATCH(C23,'شجرة الحسابات'!$A$9:$A$208,0))&"","")) | L23: =IF(C23="","",IFERROR(INDEX('شجرة الحسابات'!$C$9:$C$208,MATCH(C23,'شجرة الحسابات'!$A$9:$A$208,0))&"","")) -> تحليلي | M23: =IF(AND(C23="",G23="",H23=""),"فارغ",IF(ISNA(MATCH(C23,'شجرة الحسابات'!$A$9:$A$208,0)),"حساب غير معرف",IF(L23<>"تحليلي","حساب تجميعي",IF(AND(N(G23)>0,N(H23)>0),"مدين ودائن معاً",IF(N(G23)+N(H23)=0,"بدون قيمة","OK"))))) -> OK | N23: =IF(AND(E23<>"",E23='كشف حساب مشروع'!$C$6,I23="مرحل ✔"),COUNTIFS($E$11:E23,'كشف حساب مشروع'!$C$6,$I$11:I23,"مرحل ✔"),"") | O23: =IF(AND(C23<>"",C23='دفتر الأستاذ'!$C$6,I23="مرحل ✔"),COUNTIFS($C$11:C23,'دفتر الأستاذ'!$C$6,$I$11:I23,"مرحل ✔"),"")
A24: 6 | B24: 46037 | C24: 5101 | D24: =IF(C24="","",IFERROR(INDEX('شجرة الحسابات'!$B$9:$B$208,MATCH(C24,'شجرة الحسابات'!$A$9:$A$208,0)),"⚠ حساب غير معرف")) -> تكلفة المواد المستخدمة | E24: برج الريان التجاري | F24: توريد حديد تسليح وخرسانة جاهزة | G24: 420000 | I24: =IF(A24="",IF(M24="فارغ","","✖ بدون رقم قيد"),IF(COUNTIFS('قيود اليومية'!$A$11:$A$1010,A24,'قيود اليومية'!$M$11:$M$1010,"<>OK",'قيود اليومية'!$M$11:$M$1010,"<>فارغ")>0,"✖ خطأ بالحساب",IF(ROUND(SUMIFS('قيود اليومية'!$G$11:$G$1010,'قيود اليومية'!$A$11:$A$1010,A24)-SUMIFS('قيود اليومية'!$H$11:$H$1010,'قيود اليومية'!$A$11:$A$1010,A24),2)<>0,"✖ غير متوازن","مرحل ✔"))) -> مرحل ✔ | J24: =IF(C24="","",IFERROR(INDEX('شجرة الحسابات'!$E$9:$E$208,MATCH(C24,'شجرة الحسابات'!$A$9:$A$208,0))&"","")) -> المصروفات | K24: =IF(C24="","",IFERROR(INDEX('شجرة الحسابات'!$I$9:$I$208,MATCH(C24,'شجرة الحسابات'!$A$9:$A$208,0))&"","")) -> مواد | L24: =IF(C24="","",IFERROR(INDEX('شجرة الحسابات'!$C$9:$C$208,MATCH(C24,'شجرة الحسابات'!$A$9:$A$208,0))&"","")) -> تحليلي | M24: =IF(AND(C24="",G24="",H24=""),"فارغ",IF(ISNA(MATCH(C24,'شجرة الحسابات'!$A$9:$A$208,0)),"حساب غير معرف",IF(L24<>"تحليلي","حساب تجميعي",IF(AND(N(G24)>0,N(H24)>0),"مدين ودائن معاً",IF(N(G24)+N(H24)=0,"بدون قيمة","OK"))))) -> OK | N24: =IF(AND(E24<>"",E24='كشف حساب مشروع'!$C$6,I24="مرحل ✔"),COUNTIFS($E$11:E24,'كشف حساب مشروع'!$C$6,$I$11:I24,"مرحل ✔"),"") -> 3 | O24: =IF(AND(C24<>"",C24='دفتر الأستاذ'!$C$6,I24="مرحل ✔"),COUNTIFS($C$11:C24,'دفتر الأستاذ'!$C$6,$I$11:I24,"مرحل ✔"),"")
A25: 6 | B25: 46037 | C25: 2101 | D25: =IF(C25="","",IFERROR(INDEX('شجرة الحسابات'!$B$9:$B$208,MATCH(C25,'شجرة الحسابات'!$A$9:$A$208,0)),"⚠ حساب غير معرف")) -> الموردون | E25: برج الريان التجاري | F25: مستحق للمورد - فاتورة مواد | H25: 420000 | I25: =IF(A25="",IF(M25="فارغ","","✖ بدون رقم قيد"),IF(COUNTIFS('قيود اليومية'!$A$11:$A$1010,A25,'قيود اليومية'!$M$11:$M$1010,"<>OK",'قيود اليومية'!$M$11:$M$1010,"<>فارغ")>0,"✖ خطأ بالحساب",IF(ROUND(SUMIFS('قيود اليومية'!$G$11:$G$1010,'قيود اليومية'!$A$11:$A$1010,A25)-SUMIFS('قيود اليومية'!$H$11:$H$1010,'قيود اليومية'!$A$11:$A$1010,A25),2)<>0,"✖ غير متوازن","مرحل ✔"))) -> مرحل ✔ | J25: =IF(C25="","",IFERROR(INDEX('شجرة الحسابات'!$E$9:$E$208,MATCH(C25,'شجرة الحسابات'!$A$9:$A$208,0))&"","")) -> الخصوم | K25: =IF(C25="","",IFERROR(INDEX('شجرة الحسابات'!$I$9:$I$208,MATCH(C25,'شجرة الحسابات'!$A$9:$A$208,0))&"","")) | L25: =IF(C25="","",IFERROR(INDEX('شجرة الحسابات'!$C$9:$C$208,MATCH(C25,'شجرة الحسابات'!$A$9:$A$208,0))&"","")) -> تحليلي | M25: =IF(AND(C25="",G25="",H25=""),"فارغ",IF(ISNA(MATCH(C25,'شجرة الحسابات'!$A$9:$A$208,0)),"حساب غير معرف",IF(L25<>"تحليلي","حساب تجميعي",IF(AND(N(G25)>0,N(H25)>0),"مدين ودائن معاً",IF(N(G25)+N(H25)=0,"بدون قيمة","OK"))))) -> OK | N25: =IF(AND(E25<>"",E25='كشف حساب مشروع'!$C$6,I25="مرحل ✔"),COUNTIFS($E$11:E25,'كشف حساب مشروع'!$C$6,$I$11:I25,"مرحل ✔"),"") -> 4 | O25: =IF(AND(C25<>"",C25='دفتر الأستاذ'!$C$6,I25="مرحل ✔"),COUNTIFS($C$11:C25,'دفتر الأستاذ'!$C$6,$I$11:I25,"مرحل ✔"),"")
A26: 7 | B26: 46042 | C26: 1106 | D26: =IF(C26="","",IFERROR(INDEX('شجرة الحسابات'!$B$9:$B$208,MATCH(C26,'شجرة الحسابات'!$A$9:$A$208,0)),"⚠ حساب غير معرف")) -> دفعات مقدمة لمقاولي الباطن | E26: برج الريان التجاري | F26: دفعة مقدمة لمقاول باطن الأعمال الكهربائية | G26: 150000 | I26: =IF(A26="",IF(M26="فارغ","","✖ بدون رقم قيد"),IF(COUNTIFS('قيود اليومية'!$A$11:$A$1010,A26,'قيود اليومية'!$M$11:$M$1010,"<>OK",'قيود اليومية'!$M$11:$M$1010,"<>فارغ")>0,"✖ خطأ بالحساب",IF(ROUND(SUMIFS('قيود اليومية'!$G$11:$G$1010,'قيود اليومية'!$A$11:$A$1010,A26)-SUMIFS('قيود اليومية'!$H$11:$H$1010,'قيود اليومية'!$A$11:$A$1010,A26),2)<>0,"✖ غير متوازن","مرحل ✔"))) -> مرحل ✔ | J26: =IF(C26="","",IFERROR(INDEX('شجرة الحسابات'!$E$9:$E$208,MATCH(C26,'شجرة الحسابات'!$A$9:$A$208,0))&"","")) -> الأصول | K26: =IF(C26="","",IFERROR(INDEX('شجرة الحسابات'!$I$9:$I$208,MATCH(C26,'شجرة الحسابات'!$A$9:$A$208,0))&"","")) | L26: =IF(C26="","",IFERROR(INDEX('شجرة الحسابات'!$C$9:$C$208,MATCH(C26,'شجرة الحسابات'!$A$9:$A$208,0))&"","")) -> تحليلي | M26: =IF(AND(C26="",G26="",H26=""),"فارغ",IF(ISNA(MATCH(C26,'شجرة الحسابات'!$A$9:$A$208,0)),"حساب غير معرف",IF(L26<>"تحليلي","حساب تجميعي",IF(AND(N(G26)>0,N(H26)>0),"مدين ودائن معاً",IF(N(G26)+N(H26)=0,"بدون قيمة","OK"))))) -> OK | N26: =IF(AND(E26<>"",E26='كشف حساب مشروع'!$C$6,I26="مرحل ✔"),COUNTIFS($E$11:E26,'كشف حساب مشروع'!$C$6,$I$11:I26,"مرحل ✔"),"") -> 5 | O26: =IF(AND(C26<>"",C26='دفتر الأستاذ'!$C$6,I26="مرحل ✔"),COUNTIFS($C$11:C26,'دفتر الأستاذ'!$C$6,$I$11:I26,"مرحل ✔"),"")
A27: 7 | B27: 46042 | C27: 1102 | D27: =IF(C27="","",IFERROR(INDEX('شجرة الحسابات'!$B$9:$B$208,MATCH(C27,'شجرة الحسابات'!$A$9:$A$208,0)),"⚠ حساب غير معرف")) -> البنك - الحساب الجاري | E27: برج الريان التجاري | F27: دفعة مقدمة لمقاول باطن الأعمال الكهربائية | H27: 150000 | I27: =IF(A27="",IF(M27="فارغ","","✖ بدون رقم قيد"),IF(COUNTIFS('قيود اليومية'!$A$11:$A$1010,A27,'قيود اليومية'!$M$11:$M$1010,"<>OK",'قيود اليومية'!$M$11:$M$1010,"<>فارغ")>0,"✖ خطأ بالحساب",IF(ROUND(SUMIFS('قيود اليومية'!$G$11:$G$1010,'قيود اليومية'!$A$11:$A$1010,A27)-SUMIFS('قيود اليومية'!$H$11:$H$1010,'قيود اليومية'!$A$11:$A$1010,A27),2)<>0,"✖ غير متوازن","مرحل ✔"))) -> مرحل ✔ | J27: =IF(C27="","",IFERROR(INDEX('شجرة الحسابات'!$E$9:$E$208,MATCH(C27,'شجرة الحسابات'!$A$9:$A$208,0))&"","")) -> الأصول | K27: =IF(C27="","",IFERROR(INDEX('شجرة الحسابات'!$I$9:$I$208,MATCH(C27,'شجرة الحسابات'!$A$9:$A$208,0))&"","")) | L27: =IF(C27="","",IFERROR(INDEX('شجرة الحسابات'!$C$9:$C$208,MATCH(C27,'شجرة الحسابات'!$A$9:$A$208,0))&"","")) -> تحليلي | M27: =IF(AND(C27="",G27="",H27=""),"فارغ",IF(ISNA(MATCH(C27,'شجرة الحسابات'!$A$9:$A$208,0)),"حساب غير معرف",IF(L27<>"تحليلي","حساب تجميعي",IF(AND(N(G27)>0,N(H27)>0),"مدين ودائن معاً",IF(N(G27)+N(H27)=0,"بدون قيمة","OK"))))) -> OK | N27: =IF(AND(E27<>"",E27='كشف حساب مشروع'!$C$6,I27="مرحل ✔"),COUNTIFS($E$11:E27,'كشف حساب مشروع'!$C$6,$I$11:I27,"مرحل ✔"),"") -> 6 | O27: =IF(AND(C27<>"",C27='دفتر الأستاذ'!$C$6,I27="مرحل ✔"),COUNTIFS($C$11:C27,'دفتر الأستاذ'!$C$6,$I$11:I27,"مرحل ✔"),"") -> 6
A28: 8 | B28: 46053 | C28: 5102 | D28: =IF(C28="","",IFERROR(INDEX('شجرة الحسابات'!$B$9:$B$208,MATCH(C28,'شجرة الحسابات'!$A$9:$A$208,0)),"⚠ حساب غير معرف")) -> أجور العمالة المباشرة | E28: برج الريان التجاري | F28: أجور عمالة موقع برج الريان - يناير | G28: 180000 | I28: =IF(A28="",IF(M28="فارغ","","✖ بدون رقم قيد"),IF(COUNTIFS('قيود اليومية'!$A$11:$A$1010,A28,'قيود اليومية'!$M$11:$M$1010,"<>OK",'قيود اليومية'!$M$11:$M$1010,"<>فارغ")>0,"✖ خطأ بالحساب",IF(ROUND(SUMIFS('قيود اليومية'!$G$11:$G$1010,'قيود اليومية'!$A$11:$A$1010,A28)-SUMIFS('قيود اليومية'!$H$11:$H$1010,'قيود اليومية'!$A$11:$A$1010,A28),2)<>0,"✖ غير متوازن","مرحل ✔"))) -> مرحل ✔ | J28: =IF(C28="","",IFERROR(INDEX('شجرة الحسابات'!$E$9:$E$208,MATCH(C28,'شجرة الحسابات'!$A$9:$A$208,0))&"","")) -> المصروفات | K28: =IF(C28="","",IFERROR(INDEX('شجرة الحسابات'!$I$9:$I$208,MATCH(C28,'شجرة الحسابات'!$A$9:$A$208,0))&"","")) -> أجور عمال | L28: =IF(C28="","",IFERROR(INDEX('شجرة الحسابات'!$C$9:$C$208,MATCH(C28,'شجرة الحسابات'!$A$9:$A$208,0))&"","")) -> تحليلي | M28: =IF(AND(C28="",G28="",H28=""),"فارغ",IF(ISNA(MATCH(C28,'شجرة الحسابات'!$A$9:$A$208,0)),"حساب غير معرف",IF(L28<>"تحليلي","حساب تجميعي",IF(AND(N(G28)>0,N(H28)>0),"مدين ودائن معاً",IF(N(G28)+N(H28)=0,"بدون قيمة","OK"))))) -> OK | N28: =IF(AND(E28<>"",E28='كشف حساب مشروع'!$C$6,I28="مرحل ✔"),COUNTIFS($E$11:E28,'كشف حساب مشروع'!$C$6,$I$11:I28,"مرحل ✔"),"") -> 7 | O28: =IF(AND(C28<>"",C28='دفتر الأستاذ'!$C$6,I28="مرحل ✔"),COUNTIFS($C$11:C28,'دفتر الأستاذ'!$C$6,$I$11:I28,"مرحل ✔"),"")
A29: 8 | B29: 46053 | C29: 5102 | D29: =IF(C29="","",IFERROR(INDEX('شجرة الحسابات'!$B$9:$B$208,MATCH(C29,'شجرة الحسابات'!$A$9:$A$208,0)),"⚠ حساب غير معرف")) -> أجور العمالة المباشرة | E29: مجمع فلل النخيل السكني | F29: أجور عمالة موقع فلل النخيل - يناير | G29: 120000 | I29: =IF(A29="",IF(M29="فارغ","","✖ بدون رقم قيد"),IF(COUNTIFS('قيود اليومية'!$A$11:$A$1010,A29,'قيود اليومية'!$M$11:$M$1010,"<>OK",'قيود اليومية'!$M$11:$M$1010,"<>فارغ")>0,"✖ خطأ بالحساب",IF(ROUND(SUMIFS('قيود اليومية'!$G$11:$G$1010,'قيود اليومية'!$A$11:$A$1010,A29)-SUMIFS('قيود اليومية'!$H$11:$H$1010,'قيود اليومية'!$A$11:$A$1010,A29),2)<>0,"✖ غير متوازن","مرحل ✔"))) -> مرحل ✔ | J29: =IF(C29="","",IFERROR(INDEX('شجرة الحسابات'!$E$9:$E$208,MATCH(C29,'شجرة الحسابات'!$A$9:$A$208,0))&"","")) -> المصروفات | K29: =IF(C29="","",IFERROR(INDEX('شجرة الحسابات'!$I$9:$I$208,MATCH(C29,'شجرة الحسابات'!$A$9:$A$208,0))&"","")) -> أجور عمال | L29: =IF(C29="","",IFERROR(INDEX('شجرة الحسابات'!$C$9:$C$208,MATCH(C29,'شجرة الحسابات'!$A$9:$A$208,0))&"","")) -> تحليلي | M29: =IF(AND(C29="",G29="",H29=""),"فارغ",IF(ISNA(MATCH(C29,'شجرة الحسابات'!$A$9:$A$208,0)),"حساب غير معرف",IF(L29<>"تحليلي","حساب تجميعي",IF(AND(N(G29)>0,N(H29)>0),"مدين ودائن معاً",IF(N(G29)+N(H29)=0,"بدون قيمة","OK"))))) -> OK | N29: =IF(AND(E29<>"",E29='كشف حساب مشروع'!$C$6,I29="مرحل ✔"),COUNTIFS($E$11:E29,'كشف حساب مشروع'!$C$6,$I$11:I29,"مرحل ✔"),"") | O29: =IF(AND(C29<>"",C29='دفتر الأستاذ'!$C$6,I29="مرحل ✔"),COUNTIFS($C$11:C29,'دفتر الأستاذ'!$C$6,$I$11:I29,"مرحل ✔"),"")
A30: 8 | B30: 46053 | C30: 6101 | D30: =IF(C30="","",IFERROR(INDEX('شجرة الحسابات'!$B$9:$B$208,MATCH(C30,'شجرة الحسابات'!$A$9:$A$208,0)),"⚠ حساب غير معرف")) -> رواتب الإدارة العامة | F30: رواتب الإدارة العامة - يناير | G30: 60000 | I30: =IF(A30="",IF(M30="فارغ","","✖ بدون رقم قيد"),IF(COUNTIFS('قيود اليومية'!$A$11:$A$1010,A30,'قيود اليومية'!$M$11:$M$1010,"<>OK",'قيود اليومية'!$M$11:$M$1010,"<>فارغ")>0,"✖ خطأ بالحساب",IF(ROUND(SUMIFS('قيود اليومية'!$G$11:$G$1010,'قيود اليومية'!$A$11:$A$1010,A30)-SUMIFS('قيود اليومية'!$H$11:$H$1010,'قيود اليومية'!$A$11:$A$1010,A30),2)<>0,"✖ غير متوازن","مرحل ✔"))) -> مرحل ✔ | J30: =IF(C30="","",IFERROR(INDEX('شجرة الحسابات'!$E$9:$E$208,MATCH(C30,'شجرة الحسابات'!$A$9:$A$208,0))&"","")) -> المصروفات | K30: =IF(C30="","",IFERROR(INDEX('شجرة الحسابات'!$I$9:$I$208,MATCH(C30,'شجرة الحسابات'!$A$9:$A$208,0))&"","")) | L30: =IF(C30="","",IFERROR(INDEX('شجرة الحسابات'!$C$9:$C$208,MATCH(C30,'شجرة الحسابات'!$A$9:$A$208,0))&"","")) -> تحليلي | M30: =IF(AND(C30="",G30="",H30=""),"فارغ",IF(ISNA(MATCH(C30,'شجرة الحسابات'!$A$9:$A$208,0)),"حساب غير معرف",IF(L30<>"تحليلي","حساب تجميعي",IF(AND(N(G30)>0,N(H30)>0),"مدين ودائن معاً",IF(N(G30)+N(H30)=0,"بدون قيمة","OK"))))) -> OK | N30: =IF(AND(E30<>"",E30='كشف حساب مشروع'!$C$6,I30="مرحل ✔"),COUNTIFS($E$11:E30,'كشف حساب مشروع'!$C$6,$I$11:I30,"مرحل ✔"),"") | O30: =IF(AND(C30<>"",C30='دفتر الأستاذ'!$C$6,I30="مرحل ✔"),COUNTIFS($C$11:C30,'دفتر الأستاذ'!$C$6,$I$11:I30,"مرحل ✔"),"")
A31: 8 | B31: 46053 | C31: 1102 | D31: =IF(C31="","",IFERROR(INDEX('شجرة الحسابات'!$B$9:$B$208,MATCH(C31,'شجرة الحسابات'!$A$9:$A$208,0)),"⚠ حساب غير معرف")) -> البنك - الحساب الجاري | F31: صرف رواتب وأجور يناير | H31: 360000 | I31: =IF(A31="",IF(M31="فارغ","","✖ بدون رقم قيد"),IF(COUNTIFS('قيود اليومية'!$A$11:$A$1010,A31,'قيود اليومية'!$M$11:$M$1010,"<>OK",'قيود اليومية'!$M$11:$M$1010,"<>فارغ")>0,"✖ خطأ بالحساب",IF(ROUND(SUMIFS('قيود اليومية'!$G$11:$G$1010,'قيود اليومية'!$A$11:$A$1010,A31)-SUMIFS('قيود اليومية'!$H$11:$H$1010,'قيود اليومية'!$A$11:$A$1010,A31),2)<>0,"✖ غير متوازن","مرحل ✔"))) -> مرحل ✔ | J31: =IF(C31="","",IFERROR(INDEX('شجرة الحسابات'!$E$9:$E$208,MATCH(C31,'شجرة الحسابات'!$A$9:$A$208,0))&"","")) -> الأصول | K31: =IF(C31="","",IFERROR(INDEX('شجرة الحسابات'!$I$9:$I$208,MATCH(C31,'شجرة الحسابات'!$A$9:$A$208,0))&"","")) | L31: =IF(C31="","",IFERROR(INDEX('شجرة الحسابات'!$C$9:$C$208,MATCH(C31,'شجرة الحسابات'!$A$9:$A$208,0))&"","")) -> تحليلي | M31: =IF(AND(C31="",G31="",H31=""),"فارغ",IF(ISNA(MATCH(C31,'شجرة الحسابات'!$A$9:$A$208,0)),"حساب غير معرف",IF(L31<>"تحليلي","حساب تجميعي",IF(AND(N(G31)>0,N(H31)>0),"مدين ودائن معاً",IF(N(G31)+N(H31)=0,"بدون قيمة","OK"))))) -> OK | N31: =IF(AND(E31<>"",E31='كشف حساب مشروع'!$C$6,I31="مرحل ✔"),COUNTIFS($E$11:E31,'كشف حساب مشروع'!$C$6,$I$11:I31,"مرحل ✔"),"") | O31: =IF(AND(C31<>"",C31='دفتر الأستاذ'!$C$6,I31="مرحل ✔"),COUNTIFS($C$11:C31,'دفتر الأستاذ'!$C$6,$I$11:I31,"مرحل ✔"),"") -> 7
A32: 9 | B32: 46058 | C32: 5104 | D32: =IF(C32="","",IFERROR(INDEX('شجرة الحسابات'!$B$9:$B$208,MATCH(C32,'شجرة الحسابات'!$A$9:$A$208,0)),"⚠ حساب غير معرف")) -> إيجار وتشغيل المعدات | E32: مجمع فلل النخيل السكني | F32: إيجار معدات (لودر + خلاطة) | G32: 85000 | I32: =IF(A32="",IF(M32="فارغ","","✖ بدون رقم قيد"),IF(COUNTIFS('قيود اليومية'!$A$11:$A$1010,A32,'قيود اليومية'!$M$11:$M$1010,"<>OK",'قيود اليومية'!$M$11:$M$1010,"<>فارغ")>0,"✖ خطأ بالحساب",IF(ROUND(SUMIFS('قيود اليومية'!$G$11:$G$1010,'قيود اليومية'!$A$11:$A$1010,A32)-SUMIFS('قيود اليومية'!$H$11:$H$1010,'قيود اليومية'!$A$11:$A$1010,A32),2)<>0,"✖ غير متوازن","مرحل ✔"))) -> مرحل ✔ | J32: =IF(C32="","",IFERROR(INDEX('شجرة الحسابات'!$E$9:$E$208,MATCH(C32,'شجرة الحسابات'!$A$9:$A$208,0))&"","")) -> المصروفات | K32: =IF(C32="","",IFERROR(INDEX('شجرة الحسابات'!$I$9:$I$208,MATCH(C32,'شجرة الحسابات'!$A$9:$A$208,0))&"","")) -> معدات | L32: =IF(C32="","",IFERROR(INDEX('شجرة الحسابات'!$C$9:$C$208,MATCH(C32,'شجرة الحسابات'!$A$9:$A$208,0))&"","")) -> تحليلي | M32: =IF(AND(C32="",G32="",H32=""),"فارغ",IF(ISNA(MATCH(C32,'شجرة الحسابات'!$A$9:$A$208,0)),"حساب غير معرف",IF(L32<>"تحليلي","حساب تجميعي",IF(AND(N(G32)>0,N(H32)>0),"مدين ودائن معاً",IF(N(G32)+N(H32)=0,"بدون قيمة","OK"))))) -> OK | N32: =IF(AND(E32<>"",E32='كشف حساب مشروع'!$C$6,I32="مرحل ✔"),COUNTIFS($E$11:E32,'كشف حساب مشروع'!$C$6,$I$11:I32,"مرحل ✔"),"") | O32: =IF(AND(C32<>"",C32='دفتر الأستاذ'!$C$6,I32="مرحل ✔"),COUNTIFS($C$11:C32,'دفتر الأستاذ'!$C$6,$I$11:I32,"مرحل ✔"),"")
