Workbook

Sheet الرئيسية
B1: 🏢 نظام الرواتب والمخصصات المتكامل
B2: =cfg_CO&" | السنة المالية "&cfg_FY&" | شهر التقرير: "&INDEX(L_MONTH,cfg_VAL_M)&" | المبالغ بـ "&cfg_CUR -> شركة النخبة للتجارة والمقاولات | السنة المالية 2026 | شهر التقرير: سبتمبر | المبالغ بـ ريال سعودي
B3: مسير رواتب 12 شهراً • مكافأة نهاية الخدمة • مخصص الإجازات • مخصص تذاكر السفر • التأمينات الاجتماعية • القيود المحاسبية • قسيمة الراتب • لوحة التحكم
B5: 🧭 خطوات العمل الشهرية | F5: 📅 مسيرات الأشهر
B6: # | C6: الورقة | D6: ماذا تفعل | F6: مسير يناير | G6: مسير يوليو
B7: 1 | C7: الإعدادات | D7: أدخل اسم المنشأة والسنة المالية وشهر التقرير وراجع النسب النظامية (مرة واحدة). | F7: مسير فبراير | G7: مسير أغسطس
B8: 2 | C8: الموظفون | D8: سجّل الموظفين: الرواتب والبدلات، تاريخ التعيين، التذاكر، والأرصدة الافتتاحية في 1/1. | F8: مسير مارس | G8: مسير سبتمبر
B9: 3 | C9: الحركات الشهرية | D9: كل شهر: سجّل الغياب والإضافي والمكافآت والسلف والإجازات والتذاكر ومستحقات نهاية الخدمة. | F9: مسير أبريل | G9: مسير أكتوبر
B10: 4 | C10: مسير يناير | D10: راجع مسير الشهر (12 ورقة جاهزة يناير ← ديسمبر) — كل شيء محسوب آلياً. | F10: مسير مايو | G10: مسير نوفمبر
B11: 5 | C11: مخصص نهاية الخدمة | D11: المخصصات كما في شهر التقرير: نهاية الخدمة ← الإجازات ← التذاكر مع الفحوصات. | F11: مسير يونيو | G11: مسير ديسمبر
B12: 6 | C12: قيود الرواتب | D12: انسخ القيود الشهرية المتوازنة إلى نظامك المحاسبي.
B13: 7 | C13: قسيمة الراتب | D13: اطبع قسيمة راتب أي موظف لأي شهر. | F13: 📅 الملخص الشهري | G13: 📑 ملخص الموظفين
B14: 8 | C14: لوحة التحكم | D14: تابع المؤشرات والتنبيهات والرسوم البيانية. | F14: 🌴 مخصص الإجازات | G14: ✈ مخصص التذاكر
B16: 🎨 دليل الألوان
C17: 123 | D17: خلية إدخال — اكتب فيها (خط أزرق على خلفية صفراء).
C18: ƒx معادلة | D18: خلية معادلة — لا تعدّلها؛ تتحدث تلقائياً.
C19: ✔ سليم | D19: فحص ناجح.
C20: ⚠ تنبيه | D20: يحتاج مراجعة.
C21: ✖ خطأ | D21: خطأ يجب تصحيحه.
B23: 🔗 خريطة الترابط
B24: الإعدادات ➜ الموظفون ➜ الحركات الشهرية ➜ مسيرات 12 شهراً ➜ الملخص الشهري + ملخص الموظفين ➜ المخصصات (نهاية الخدمة / الإجازات / التذاكر) ➜ القيود المحاسبية ➜ قسيمة الراتب + لوحة التحكم
B26: البيانات الحالية (12 موظفاً وحركاتهم) أمثلة توضيحية لإظهار طريقة العمل — امسح خلايا الإدخال الصفراء في «الموظفون» و«الحركات الشهرية» وأدخل بياناتك. يستوعب الملف 100 موظف و1,000 حركة. الأحكام مبنية على نظام العمل السعودي (المواد 84، 85، 98، 107، 109) ونظام التأمينات الاجتماعية، وجميع النسب قابلة للتعديل من الإعدادات.

Sheet لوحة التحكم
B1: 📊 لوحة التحكم — الرواتب والمخصصات
B2: =cfg_CO&" | السنة المالية "&cfg_FY&" | شهر التقرير: "&INDEX(L_MONTH,cfg_VAL_M)&" | المبالغ بـ "&cfg_CUR -> شركة النخبة للتجارة والمقاولات | السنة المالية 2026 | شهر التقرير: سبتمبر | المبالغ بـ ريال سعودي
B3: 🏠 الرئيسية | C3: ⚙ الإعدادات | D3: 👥 الموظفون | E3: ✍ الحركات | F3: 📅 الملخص الشهري | G3: 🧾 القيود | H3: 💳 القسيمة | J3: شهر التقرير ← | K3: =INDEX(L_MONTH,cfg_VAL_M)&" "&cfg_FY -> سبتمبر 2026 | M3: ⚙ تغيير الشهر
B5: 👥 القوى العاملة
B6: الموظفون على رأس العمل | E6: نسبة التوطين (السعودة) | H6: متوسط إجمالي الراتب الشهري | K6: إجمالي الرواتب الشهرية الثابتة
B7: =COUNTIF(الموظفون!$Z$6:$Z$105,"✔ على رأس العمل") -> 11 | E7: =IFERROR(COUNTIFS(الموظفون!$Z$6:$Z$105,"✔ على رأس العمل",الموظفون!$E$6:$E$105,"سعودي")/B7,0) -> 0.63636364 | H7: =IFERROR(AVERAGEIF(الموظفون!$Z$6:$Z$105,"✔ على رأس العمل",الموظفون!$N$6:$N$105),0) -> 17688.636 | K7: =SUMIF(الموظفون!$Z$6:$Z$105,"✔ على رأس العمل",الموظفون!$N$6:$N$105) -> 194575
B9: ="💵 الرواتب من بداية السنة حتى "&INDEX(L_MONTH,cfg_VAL_M) -> 💵 الرواتب من بداية السنة حتى سبتمبر
B10: إجمالي المستحقات | E10: صافي الرواتب المدفوعة | H10: التأمينات (موظف + منشأة) | K10: إجمالي تكلفة العمالة
B11: ='الملخص الشهري'!I19 -> 1773190.6 | E11: ='الملخص الشهري'!L19 -> 1660310.3 | H11: ='الملخص الشهري'!J19+'الملخص الشهري'!M19 -> 245743.12 | K11: ='الملخص الشهري'!Q19 -> 2174335
B13: ="🏦 أرصدة المخصصات كما في "&TEXT(cfg_VAL_DATE,"yyyy/mm/dd") -> 🏦 أرصدة المخصصات كما في 2026/09/30
B14: مخصص نهاية الخدمة | E14: مخصص الإجازات | H14: مخصص تذاكر السفر | K14: إجمالي المخصصات
B15: ='مخصص نهاية الخدمة'!S106 -> 1161972.7 | E15: ='مخصص الإجازات'!P106 -> 152443.6 | H15: ='مخصص التذاكر'!N106 -> 7324.1096 | K15: =B15+E15+H15 -> 1321740.5
B17: 🔔 تنبيهات وفحوصات الترابط | I17: 🌍 التوزيع حسب الفئة
B18: هويات / إقامات منتهية أو تنتهي خلال 60 يوماً | F18: =COUNTIFS(الموظفون!$I$6:$I$105,"<="&(cfg_VAL_DATE+60),الموظفون!$Z$6:$Z$105,"✔ على رأس العمل") -> 2 | G18: =IF(F18=0,"✔","⚠") -> ⚠ | I18: الفئة | J18: العدد | K18: النسبة | L18: الرواتب الشهرية
B19: موظفون منتهية خدماتهم بمستحقات لم تُصرف | F19: =COUNTIF('مخصص نهاية الخدمة'!$T$6:$T$105,"⚠*") -> 0 | G19: =IF(F19=0,"✔","⚠") -> ✔ | I19: سعودي | J19: =COUNTIFS(الموظفون!$Z$6:$Z$105,"✔ على رأس العمل",الموظفون!$E$6:$E$105,I19) -> 7 | K19: =IFERROR(J19/SUM($J$19:$J$20),0) -> 0.63636364 | L19: =SUMIFS(الموظفون!$N$6:$N$105,الموظفون!$Z$6:$Z$105,"✔ على رأس العمل",الموظفون!$E$6:$E$105,I19) -> 145025
B20: أرصدة إجازات سالبة أو مرتفعة | F20: =COUNTIF('مخصص الإجازات'!$S$6:$S$105,"✖*")+COUNTIF('مخصص الإجازات'!$S$6:$S$105,"⚠ رصيد مرتفع*") -> 0 | G20: =IF(F20=0,"✔","⚠") -> ✔ | I20: غير سعودي | J20: =COUNTIFS(الموظفون!$Z$6:$Z$105,"✔ على رأس العمل",الموظفون!$E$6:$E$105,I20) -> 4 | K20: =IFERROR(J20/SUM($J$19:$J$20),0) -> 0.36363636 | L20: =SUMIFS(الموظفون!$N$6:$N$105,الموظفون!$Z$6:$Z$105,"✔ على رأس العمل",الموظفون!$E$6:$E$105,I20) -> 49550
B21: تذاكر مستحقة للصرف | F21: =COUNTIF('مخصص التذاكر'!$P$6:$P$105,"⚠ تذكرة*") -> 0 | G21: =IF(F21=0,"✔","⚠") -> ✔
B22: حركات برقم وظيفي غير صحيح | F22: =COUNTIF('الحركات الشهرية'!$C$6:$C$1005,"✖*") -> 0 | G22: =IF(F22=0,"✔","⚠") -> ✔
B23: رواتب صافية بالسالب (كل الأشهر) | F23: =COUNTIF('مسير يناير'!$W$6:$W$105,"<0")+COUNTIF('مسير فبراير'!$W$6:$W$105,"<0")+COUNTIF('مسير مارس'!$W$6:$W$105,"<0")+COUNTIF('مسير أبريل'!$W$6:$W$105,"<0")+COUNTIF('مسير مايو'!$W$6:$W$105,"<0")+COUNTIF('مسير يونيو'!$W$6:$W$105,"<0")+COUNTIF('مسير يوليو'!$W$6:$W$105,"<0")+COUNTIF('مسير أغسطس'!$W$6:$W$105,"<0")+COUNTIF('مسير سبتمبر'!$W$6:$W$105,"<0")+COUNTIF('مسير أكتوبر'!$W$6:$W$105,"<0")+COUNTIF('مسير نوفمبر'!$W$6:$W$105,"<0")+COUNTIF('مسير ديسمبر'!$W$6:$W$105,"<0") -> 0 | G23: =IF(F23=0,"✔","⚠") -> ✔
B24: توازن قيود الرواتب (حتى شهر التقرير) | F24: ='قيود الرواتب'!$R$31 -> ✔ متوازن
B34: ="🏢 تحليل التكلفة حسب القسم حتى "&INDEX(L_MONTH,cfg_VAL_M) -> 🏢 تحليل التكلفة حسب القسم حتى سبتمبر
B35: القسم | C35: عدد الموظفين | D35: الرواتب الشهرية | E35: المستحقات حتى تاريخه | F35: التكلفة الكاملة حتى تاريخه | G35: النسبة من التكلفة
B36: =IF(INDEX(L_DEPT,1)="","",INDEX(L_DEPT,1)) -> الإدارة العليا | C36: =IF(B36="","",COUNTIFS(الموظفون!$Z$6:$Z$105,"✔ على رأس العمل",الموظفون!$F$6:$F$105,B36)) -> 1 | D36: =IF(B36="","",SUMIFS(الموظفون!$N$6:$N$105,الموظفون!$Z$6:$Z$105,"✔ على رأس العمل",الموظفون!$F$6:$F$105,B36)) -> 40800 | E36: =IF(B36="","",SUMIF('ملخص الموظفين السنوي'!$D$6:$D$105,B36,'ملخص الموظفين السنوي'!$R$6:$R$105)) -> 367200 | F36: =IF(B36="","",SUMIF('ملخص الموظفين السنوي'!$D$6:$D$105,B36,'ملخص الموظفين السنوي'!$AF$6:$AF$105)) -> 460757.16 | G36: =IF(B36="","",IFERROR(F36/SUM($F$36:$F$50),0)) -> 0.21190716
B37: =IF(INDEX(L_DEPT,2)="","",INDEX(L_DEPT,2)) -> المالية | C37: =IF(B37="","",COUNTIFS(الموظفون!$Z$6:$Z$105,"✔ على رأس العمل",الموظفون!$F$6:$F$105,B37)) -> 3 | D37: =IF(B37="","",SUMIFS(الموظفون!$N$6:$N$105,الموظفون!$Z$6:$Z$105,"✔ على رأس العمل",الموظفون!$F$6:$F$105,B37)) -> 47400 | E37: =IF(B37="","",SUMIF('ملخص الموظفين السنوي'!$D$6:$D$105,B37,'ملخص الموظفين السنوي'!$R$6:$R$105)) -> 426939.58 | F37: =IF(B37="","",SUMIF('ملخص الموظفين السنوي'!$D$6:$D$105,B37,'ملخص الموظفين السنوي'!$AF$6:$AF$105)) -> 526359.62 | G37: =IF(B37="","",IFERROR(F37/SUM($F$36:$F$50),0)) -> 0.24207844
B38: =IF(INDEX(L_DEPT,3)="","",INDEX(L_DEPT,3)) -> الموارد البشرية | C38: =IF(B38="","",COUNTIFS(الموظفون!$Z$6:$Z$105,"✔ على رأس العمل",الموظفون!$F$6:$F$105,B38)) -> 1 | D38: =IF(B38="","",SUMIFS(الموظفون!$N$6:$N$105,الموظفون!$Z$6:$Z$105,"✔ على رأس العمل",الموظفون!$F$6:$F$105,B38)) -> 18900 | E38: =IF(B38="","",SUMIF('ملخص الموظفين السنوي'!$D$6:$D$105,B38,'ملخص الموظفين السنوي'!$R$6:$R$105)) -> 170100 | F38: =IF(B38="","",SUMIF('ملخص الموظفين السنوي'!$D$6:$D$105,B38,'ملخص الموظفين السنوي'!$AF$6:$AF$105)) -> 216878.58 | G38: =IF(B38="","",IFERROR(F38/SUM($F$36:$F$50),0)) -> 0.099744785
B39: =IF(INDEX(L_DEPT,4)="","",INDEX(L_DEPT,4)) -> المبيعات | C39: =IF(B39="","",COUNTIFS(الموظفون!$Z$6:$Z$105,"✔ على رأس العمل",الموظفون!$F$6:$F$105,B39)) -> 2 | D39: =IF(B39="","",SUMIFS(الموظفون!$N$6:$N$105,الموظفون!$Z$6:$Z$105,"✔ على رأس العمل",الموظفون!$F$6:$F$105,B39)) -> 32200 | E39: =IF(B39="","",SUMIF('ملخص الموظفين السنوي'!$D$6:$D$105,B39,'ملخص الموظفين السنوي'!$R$6:$R$105)) -> 261096.25 | F39: =IF(B39="","",SUMIF('ملخص الموظفين السنوي'!$D$6:$D$105,B39,'ملخص الموظفين السنوي'!$AF$6:$AF$105)) -> 318598.62 | G39: =IF(B39="","",IFERROR(F39/SUM($F$36:$F$50),0)) -> 0.14652692
B40: =IF(INDEX(L_DEPT,5)="","",INDEX(L_DEPT,5)) -> العمليات | C40: =IF(B40="","",COUNTIFS(الموظفون!$Z$6:$Z$105,"✔ على رأس العمل",الموظفون!$F$6:$F$105,B40)) -> 1 | D40: =IF(B40="","",SUMIFS(الموظفون!$N$6:$N$105,الموظفون!$Z$6:$Z$105,"✔ على رأس العمل",الموظفون!$F$6:$F$105,B40)) -> 9075 | E40: =IF(B40="","",SUMIF('ملخص الموظفين السنوي'!$D$6:$D$105,B40,'ملخص الموظفين السنوي'!$R$6:$R$105)) -> 131196.84 | F40: =IF(B40="","",SUMIF('ملخص الموظفين السنوي'!$D$6:$D$105,B40,'ملخص الموظفين السنوي'!$AF$6:$AF$105)) -> 154697.7 | G40: =IF(B40="","",IFERROR(F40/SUM($F$36:$F$50),0)) -> 0.071147131
B41: =IF(INDEX(L_DEPT,6)="","",INDEX(L_DEPT,6)) -> تقنية المعلومات | C41: =IF(B41="","",COUNTIFS(الموظفون!$Z$6:$Z$105,"✔ على رأس العمل",الموظفون!$F$6:$F$105,B41)) -> 2 | D41: =IF(B41="","",SUMIFS(الموظفون!$N$6:$N$105,الموظفون!$Z$6:$Z$105,"✔ على رأس العمل",الموظفون!$F$6:$F$105,B41)) -> 30550 | E41: =IF(B41="","",SUMIF('ملخص الموظفين السنوي'!$D$6:$D$105,B41,'ملخص الموظفين السنوي'!$R$6:$R$105)) -> 274926.67 | F41: =IF(B41="","",SUMIF('ملخص الموظفين السنوي'!$D$6:$D$105,B41,'ملخص الموظفين السنوي'!$AF$6:$AF$105)) -> 327623.54 | G41: =IF(B41="","",IFERROR(F41/SUM($F$36:$F$50),0)) -> 0.15067758
B42: =IF(INDEX(L_DEPT,7)="","",INDEX(L_DEPT,7)) -> المشاريع | C42: =IF(B42="","",COUNTIFS(الموظفون!$Z$6:$Z$105,"✔ على رأس العمل",الموظفون!$F$6:$F$105,B42)) -> 1 | D42: =IF(B42="","",SUMIFS(الموظفون!$N$6:$N$105,الموظفون!$Z$6:$Z$105,"✔ على رأس العمل",الموظفون!$F$6:$F$105,B42)) -> 15650 | E42: =IF(B42="","",SUMIF('ملخص الموظفين السنوي'!$D$6:$D$105,B42,'ملخص الموظفين السنوي'!$R$6:$R$105)) -> 141731.25 | F42: =IF(B42="","",SUMIF('ملخص الموظفين السنوي'!$D$6:$D$105,B42,'ملخص الموظفين السنوي'!$AF$6:$AF$105)) -> 169419.81 | G42: =IF(B42="","",IFERROR(F42/SUM($F$36:$F$50),0)) -> 0.077917989
B43: =IF(INDEX(L_DEPT,8)="","",INDEX(L_DEPT,8)) | C43: =IF(B43="","",COUNTIFS(الموظفون!$Z$6:$Z$105,"✔ على رأس العمل",الموظفون!$F$6:$F$105,B43)) | D43: =IF(B43="","",SUMIFS(الموظفون!$N$6:$N$105,الموظفون!$Z$6:$Z$105,"✔ على رأس العمل",الموظفون!$F$6:$F$105,B43)) | E43: =IF(B43="","",SUMIF('ملخص الموظفين السنوي'!$D$6:$D$105,B43,'ملخص الموظفين السنوي'!$R$6:$R$105)) | F43: =IF(B43="","",SUMIF('ملخص الموظفين السنوي'!$D$6:$D$105,B43,'ملخص الموظفين السنوي'!$AF$6:$AF$105)) | G43: =IF(B43="","",IFERROR(F43/SUM($F$36:$F$50),0))
B44: =IF(INDEX(L_DEPT,9)="","",INDEX(L_DEPT,9)) | C44: =IF(B44="","",COUNTIFS(الموظفون!$Z$6:$Z$105,"✔ على رأس العمل",الموظفون!$F$6:$F$105,B44)) | D44: =IF(B44="","",SUMIFS(الموظفون!$N$6:$N$105,الموظفون!$Z$6:$Z$105,"✔ على رأس العمل",الموظفون!$F$6:$F$105,B44)) | E44: =IF(B44="","",SUMIF('ملخص الموظفين السنوي'!$D$6:$D$105,B44,'ملخص الموظفين السنوي'!$R$6:$R$105)) | F44: =IF(B44="","",SUMIF('ملخص الموظفين السنوي'!$D$6:$D$105,B44,'ملخص الموظفين السنوي'!$AF$6:$AF$105)) | G44: =IF(B44="","",IFERROR(F44/SUM($F$36:$F$50),0))
B45: =IF(INDEX(L_DEPT,10)="","",INDEX(L_DEPT,10)) | C45: =IF(B45="","",COUNTIFS(الموظفون!$Z$6:$Z$105,"✔ على رأس العمل",الموظفون!$F$6:$F$105,B45)) | D45: =IF(B45="","",SUMIFS(الموظفون!$N$6:$N$105,الموظفون!$Z$6:$Z$105,"✔ على رأس العمل",الموظفون!$F$6:$F$105,B45)) | E45: =IF(B45="","",SUMIF('ملخص الموظفين السنوي'!$D$6:$D$105,B45,'ملخص الموظفين السنوي'!$R$6:$R$105)) | F45: =IF(B45="","",SUMIF('ملخص الموظفين السنوي'!$D$6:$D$105,B45,'ملخص الموظفين السنوي'!$AF$6:$AF$105)) | G45: =IF(B45="","",IFERROR(F45/SUM($F$36:$F$50),0))
B46: =IF(INDEX(L_DEPT,11)="","",INDEX(L_DEPT,11)) | C46: =IF(B46="","",COUNTIFS(الموظفون!$Z$6:$Z$105,"✔ على رأس العمل",الموظفون!$F$6:$F$105,B46)) | D46: =IF(B46="","",SUMIFS(الموظفون!$N$6:$N$105,الموظفون!$Z$6:$Z$105,"✔ على رأس العمل",الموظفون!$F$6:$F$105,B46)) | E46: =IF(B46="","",SUMIF('ملخص الموظفين السنوي'!$D$6:$D$105,B46,'ملخص الموظفين السنوي'!$R$6:$R$105)) | F46: =IF(B46="","",SUMIF('ملخص الموظفين السنوي'!$D$6:$D$105,B46,'ملخص الموظفين السنوي'!$AF$6:$AF$105)) | G46: =IF(B46="","",IFERROR(F46/SUM($F$36:$F$50),0))
B47: =IF(INDEX(L_DEPT,12)="","",INDEX(L_DEPT,12)) | C47: =IF(B47="","",COUNTIFS(الموظفون!$Z$6:$Z$105,"✔ على رأس العمل",الموظفون!$F$6:$F$105,B47)) | D47: =IF(B47="","",SUMIFS(الموظفون!$N$6:$N$105,الموظفون!$Z$6:$Z$105,"✔ على رأس العمل",الموظفون!$F$6:$F$105,B47)) | E47: =IF(B47="","",SUMIF('ملخص الموظفين السنوي'!$D$6:$D$105,B47,'ملخص الموظفين السنوي'!$R$6:$R$105)) | F47: =IF(B47="","",SUMIF('ملخص الموظفين السنوي'!$D$6:$D$105,B47,'ملخص الموظفين السنوي'!$AF$6:$AF$105)) | G47: =IF(B47="","",IFERROR(F47/SUM($F$36:$F$50),0))
B48: =IF(INDEX(L_DEPT,13)="","",INDEX(L_DEPT,13)) | C48: =IF(B48="","",COUNTIFS(الموظفون!$Z$6:$Z$105,"✔ على رأس العمل",الموظفون!$F$6:$F$105,B48)) | D48: =IF(B48="","",SUMIFS(الموظفون!$N$6:$N$105,الموظفون!$Z$6:$Z$105,"✔ على رأس العمل",الموظفون!$F$6:$F$105,B48)) | E48: =IF(B48="","",SUMIF('ملخص الموظفين السنوي'!$D$6:$D$105,B48,'ملخص الموظفين السنوي'!$R$6:$R$105)) | F48: =IF(B48="","",SUMIF('ملخص الموظفين السنوي'!$D$6:$D$105,B48,'ملخص الموظفين السنوي'!$AF$6:$AF$105)) | G48: =IF(B48="","",IFERROR(F48/SUM($F$36:$F$50),0))
B49: =IF(INDEX(L_DEPT,14)="","",INDEX(L_DEPT,14)) | C49: =IF(B49="","",COUNTIFS(الموظفون!$Z$6:$Z$105,"✔ على رأس العمل",الموظفون!$F$6:$F$105,B49)) | D49: =IF(B49="","",SUMIFS(الموظفون!$N$6:$N$105,الموظفون!$Z$6:$Z$105,"✔ على رأس العمل",الموظفون!$F$6:$F$105,B49)) | E49: =IF(B49="","",SUMIF('ملخص الموظفين السنوي'!$D$6:$D$105,B49,'ملخص الموظفين السنوي'!$R$6:$R$105)) | F49: =IF(B49="","",SUMIF('ملخص الموظفين السنوي'!$D$6:$D$105,B49,'ملخص الموظفين السنوي'!$AF$6:$AF$105)) | G49: =IF(B49="","",IFERROR(F49/SUM($F$36:$F$50),0))
B50: =IF(INDEX(L_DEPT,15)="","",INDEX(L_DEPT,15)) | C50: =IF(B50="","",COUNTIFS(الموظفون!$Z$6:$Z$105,"✔ على رأس العمل",الموظفون!$F$6:$F$105,B50)) | D50: =IF(B50="","",SUMIFS(الموظفون!$N$6:$N$105,الموظفون!$Z$6:$Z$105,"✔ على رأس العمل",الموظفون!$F$6:$F$105,B50)) | E50: =IF(B50="","",SUMIF('ملخص الموظفين السنوي'!$D$6:$D$105,B50,'ملخص الموظفين السنوي'!$R$6:$R$105)) | F50: =IF(B50="","",SUMIF('ملخص الموظفين السنوي'!$D$6:$D$105,B50,'ملخص الموظفين السنوي'!$AF$6:$AF$105)) | G50: =IF(B50="","",IFERROR(F50/SUM($F$36:$F$50),0))
B51: الإجمالي | C51: =SUM(C36:C50) -> 11 | D51: =SUM(D36:D50) -> 194575 | E51: =SUM(E36:E50) -> 1773190.6 | F51: =SUM(F36:F50) -> 2174335 | G51: =SUM(G36:G50) -> 1
B52: =IF(ROUND(F51-'الملخص الشهري'!Q19,0)=0,"✔ مطابق للملخص الشهري","⚠ يوجد موظفون بدون قسم أو قسم غير مدرج") -> ✔ مطابق للملخص الشهري
B54: 📈 الاتجاه الشهري لمكونات تكلفة العمالة (12 شهراً)
...

Sheet الإعدادات
B1: ⚙ الإعدادات والثوابت النظامية
B2: =cfg_CO&" | السنة المالية "&cfg_FY&" | شهر التقرير: "&INDEX(L_MONTH,cfg_VAL_M)&" | المبالغ بـ "&cfg_CUR -> شركة النخبة للتجارة والمقاولات | السنة المالية 2026 | شهر التقرير: سبتمبر | المبالغ بـ ريال سعودي
B3: 🏠 الرئيسية | C3: 📊 لوحة التحكم | D3: 👥 الموظفون | F3: ✍ الحركات | G3: 📅 الملخص الشهري | H3: 🧾 القيود | I3: 💳 القسيمة
B5: البند | C5: القيمة | D5: الشرح / المصدر | F5: الأقسام | G5: أسباب انتهاء الخدمة | H5: نعم / لا | I5: فئة التأمينات | J5: الأشهر | K5: أوراق المسير
B6: اسم المنشأة | C6: شركة النخبة للتجارة والمقاولات | D6: يظهر في رؤوس جميع الأوراق والقسائم. | F6: الإدارة العليا | G6: استقالة | H6: نعم | I6: سعودي | J6: يناير | K6: مسير يناير
B7: السنة المالية | C7: 2026 | D7: كل التواريخ الشهرية تُبنى على هذه السنة. | F7: المالية | G7: إنهاء من صاحب العمل | H7: لا | I7: غير سعودي | J7: فبراير | K7: مسير فبراير
B8: العملة | C8: ريال سعودي | F8: الموارد البشرية | G8: انتهاء مدة العقد | J8: مارس | K8: مسير مارس
B9: شهر التقرير (1-12) | C9: 9 | D9: يتحكم في: المخصصات كما في نهاية الشهر، مؤشرات لوحة التحكم (من بداية السنة حتى هذا الشهر)، وتمييز الأشهر الفعلية عن المتوقعة. | F9: المبيعات | G9: اتفاق الطرفين | J9: أبريل | K9: مسير أبريل
B10: بداية السنة المالية | C10: =DATE(cfg_FY,1,1) -> 46023 | D10: معادلة — لا تعدّل. | F10: العمليات | G10: وفاة أو عجز | J10: مايو | K10: مسير مايو
B11: تاريخ التقرير (نهاية شهر التقرير) | C11: =EOMONTH(DATE(cfg_FY,cfg_VAL_M,1),0) -> 46295 | D11: معادلة — لا تعدّل. | F11: تقنية المعلومات | J11: يونيو | K11: مسير يونيو
B12: 💰 الرواتب والعمل الإضافي | F12: المشاريع | J12: يوليو | K12: مسير يوليو
B13: أساس أيام الشهر | C13: 30 | D13: الأجر اليومي = الأجر الشهري ÷ 30 (العرف المحاسبي ونظام العمل). | J13: أغسطس | K13: مسير أغسطس
B14: ساعات العمل اليومية | C14: 8 | D14: المادة 98 من نظام العمل: 8 ساعات يومياً. | J14: سبتمبر | K14: مسير سبتمبر
B15: علاوة العمل الإضافي على الأجر الأساسي | C15: 0.5 | D15: المادة 107: أجر الساعة + 50% من الأجر الأساسي للساعة. | J15: أكتوبر | K15: مسير أكتوبر
B16: 🏛 التأمينات الاجتماعية (GOSI) | J16: نوفمبر | K16: مسير نوفمبر
B17: سعودي — حصة الموظف | C17: 0.0975 | D17: معاشات 9% + ساند 0.75%. المشتركون الجدد بعد 3/7/2025 تتدرج نسبتهم سنوياً — عدّل عند الحاجة. | J17: ديسمبر | K17: مسير ديسمبر
B18: سعودي — حصة المنشأة | C18: 0.1175 | D18: معاشات 9% + ساند 0.75% + أخطار مهنية 2%.
B19: غير سعودي — حصة الموظف | C19: 0 | D19: لا يُستقطع من غير السعودي.
B20: غير سعودي — حصة المنشأة | C20: 0.02 | D20: أخطار مهنية 2%.
B21: الحد الأعلى لأجر الاشتراك | C21: 45000 | D21: أجر الاشتراك = الأساسي + السكن بحد أقصى 45,000.
B22: 🎁 مكافأة نهاية الخدمة
B23: عدد السنوات الأولى | C23: 5 | D23: المادة 84: نصف شهر عن كل سنة من السنوات الخمس الأولى.
B24: أجر كل سنة من السنوات الأولى (بالأشهر) | C24: 0.5
B25: أجر كل سنة بعدها (بالأشهر) | C25: 1 | D25: أجر شهر كامل عن كل سنة تالية.
B26: يدخل بدل السكن في أجر نهاية الخدمة؟ | C26: نعم | D26: الأجر الفعلي حسب المادة 2: الأساسي + البدلات الثابتة.
B27: يدخل بدل النقل في أجر نهاية الخدمة؟ | C27: نعم
B28: تدخل البدلات الأخرى في أجر نهاية الخدمة؟ | C28: لا
B29: 🌴 الإجازات السنوية
B30: أيام الإجازة السنوية (قبل الحد) | C30: 21 | D30: المادة 109: 21 يوماً.
B31: أيام الإجازة السنوية (بعد الحد) | C31: 30 | D31: 30 يوماً بعد إتمام 5 سنوات متصلة.
B32: عدد سنوات الحد للإجازة | C32: 5
B33: يدخل السكن في أجر الإجازة؟ | C33: نعم
B34: يدخل النقل في أجر الإجازة؟ | C34: نعم
B35: تدخل البدلات الأخرى في أجر الإجازة؟ | C35: لا
B36: عدد أيام السنة لاحتساب مدة الخدمة | C36: 365
B37: 📐 نسب استحقاق مكافأة نهاية الخدمة عند الاستقالة (المادة 85)
B38: مدة الخدمة من (سنة) | C38: نسبة الاستحقاق | D38: الشرح
B39: 0 | C39: 0 | D39: أقل من سنتين: لا يستحق
B40: 2 | C40: =1/3 -> 0.33333333 | D40: من سنتين إلى أقل من 5: ثلث المكافأة
B41: 5 | C41: =2/3 -> 0.66666667 | D41: من 5 إلى أقل من 10: ثلثا المكافأة
...

Sheet الموظفون
A1: 👥 سجل بيانات الموظفين الرئيسي
A2: =cfg_CO&" | السنة المالية "&cfg_FY&" | شهر التقرير: "&INDEX(L_MONTH,cfg_VAL_M)&" | المبالغ بـ "&cfg_CUR -> شركة النخبة للتجارة والمقاولات | السنة المالية 2026 | شهر التقرير: سبتمبر | المبالغ بـ ريال سعودي
B3: 🏠 الرئيسية | C3: 📊 لوحة التحكم | E3: ⚙ الإعدادات | F3: ✍ الحركات | G3: 📅 الملخص الشهري | H3: 🧾 القيود | J3: 💳 القسيمة
A5: م | B5: الرقم الوظيفي | C5: اسم الموظف | D5: الجنسية | E5: فئة التأمينات | F5: القسم | G5: المسمى الوظيفي | H5: تاريخ التعيين | I5: انتهاء الهوية / الإقامة | J5: الراتب الأساسي | K5: بدل السكن | L5: بدل النقل | M5: بدلات أخرى | N5: إجمالي الراتب الشهري | O5: أجر احتساب نهاية الخدمة | P5: أجر احتساب الإجازة | Q5: أجر الاشتراك في التأمينات | R5: أيام الإجازة السنوية (اختياري — يلغي الآلي) | S5: يستحق تذكرة سفر؟ | T5: قيمة التذكرة (له ولمن يعول) | U5: دورية التذكرة (شهر) | V5: رصيد إجازات افتتاحي (يوم) في 1/1 | W5: رصيد مخصص تذاكر افتتاحي في 1/1 | X5: تاريخ انتهاء الخدمة | Y5: سبب انتهاء الخدمة | Z5: الحالة في تاريخ التقرير | AA5: البنك | AB5: رقم الآيبان IBAN | AC5: ملاحظات
A6: =IF(B6="","",ROW()-5) -> 1 | B6: E001 | C6: عبدالله محمد العتيبي | D6: سعودي | E6: سعودي | F6: الإدارة العليا | G6: المدير العام | H6: 40923 | I6: 47248 | J6: 28000 | K6: 7000 | L6: 2800 | M6: 3000 | N6: =IF(B6="","",SUM(J6:M6)) -> 40800 | O6: =IF(B6="","",J6+IF(cfg_EOS_H="نعم",K6,0)+IF(cfg_EOS_T="نعم",L6,0)+IF(cfg_EOS_O="نعم",M6,0)) -> 37800 | P6: =IF(B6="","",J6+IF(cfg_LV_H="نعم",K6,0)+IF(cfg_LV_T="نعم",L6,0)+IF(cfg_LV_O="نعم",M6,0)) -> 37800 | Q6: =IF(B6="","",MIN(cfg_G_CAP,J6+K6)) -> 35000 | S6: لا | T6: 0 | U6: 12 | V6: 18 | W6: 0 | Z6: =IF(B6="","",IF(AND(X6<>"",X6<=cfg_VAL_DATE),"✖ منتهي الخدمة",IF(H6>cfg_VAL_DATE,"⚠ لم يباشر بعد","✔ على رأس العمل"))) -> ✔ على رأس العمل | AA6: الراجحي | AB6: SA0380000000608010167519
A7: =IF(B7="","",ROW()-5) -> 2 | B7: E002 | C7: أحمد سعيد القحطاني | D7: سعودي | E7: سعودي | F7: المالية | G7: مدير مالي | H7: 42522 | I7: 46786 | J7: 18000 | K7: 4500 | L7: 1800 | M7: 1000 | N7: =IF(B7="","",SUM(J7:M7)) -> 25300 | O7: =IF(B7="","",J7+IF(cfg_EOS_H="نعم",K7,0)+IF(cfg_EOS_T="نعم",L7,0)+IF(cfg_EOS_O="نعم",M7,0)) -> 24300 | P7: =IF(B7="","",J7+IF(cfg_LV_H="نعم",K7,0)+IF(cfg_LV_T="نعم",L7,0)+IF(cfg_LV_O="نعم",M7,0)) -> 24300 | Q7: =IF(B7="","",MIN(cfg_G_CAP,J7+K7)) -> 22500 | S7: لا | T7: 0 | U7: 12 | V7: 12 | W7: 0 | Z7: =IF(B7="","",IF(AND(X7<>"",X7<=cfg_VAL_DATE),"✖ منتهي الخدمة",IF(H7>cfg_VAL_DATE,"⚠ لم يباشر بعد","✔ على رأس العمل"))) -> ✔ على رأس العمل | AA7: الأهلي | AB7: SA4410000011100000000001
A8: =IF(B8="","",ROW()-5) -> 3 | B8: E003 | C8: محمد علي حسن | D8: مصري | E8: غير سعودي | F8: المالية | G8: محاسب أول | H8: 43353 | I8: 46346 | J8: 8500 | K8: 2125 | L8: 850 | M8: 500 | N8: =IF(B8="","",SUM(J8:M8)) -> 11975 | O8: =IF(B8="","",J8+IF(cfg_EOS_H="نعم",K8,0)+IF(cfg_EOS_T="نعم",L8,0)+IF(cfg_EOS_O="نعم",M8,0)) -> 11475 | P8: =IF(B8="","",J8+IF(cfg_LV_H="نعم",K8,0)+IF(cfg_LV_T="نعم",L8,0)+IF(cfg_LV_O="نعم",M8,0)) -> 11475 | Q8: =IF(B8="","",MIN(cfg_G_CAP,J8+K8)) -> 10625 | S8: نعم | T8: 3200 | U8: 24 | V8: 20 | W8: 1600 | Z8: =IF(B8="","",IF(AND(X8<>"",X8<=cfg_VAL_DATE),"✖ منتهي الخدمة",IF(H8>cfg_VAL_DATE,"⚠ لم يباشر بعد","✔ على رأس العمل"))) -> ✔ على رأس العمل | AA8: الراجحي | AB8: SA0380000000608010167520
A9: =IF(B9="","",ROW()-5) -> 4 | B9: E004 | C9: نورة خالد الدوسري | D9: سعودية | E9: سعودي | F9: الموارد البشرية | G9: مديرة موارد بشرية | H9: 43497 | I9: 47678 | J9: 14000 | K9: 3500 | L9: 1400 | M9: 0 | N9: =IF(B9="","",SUM(J9:M9)) -> 18900 | O9: =IF(B9="","",J9+IF(cfg_EOS_H="نعم",K9,0)+IF(cfg_EOS_T="نعم",L9,0)+IF(cfg_EOS_O="نعم",M9,0)) -> 18900 | P9: =IF(B9="","",J9+IF(cfg_LV_H="نعم",K9,0)+IF(cfg_LV_T="نعم",L9,0)+IF(cfg_LV_O="نعم",M9,0)) -> 18900 | Q9: =IF(B9="","",MIN(cfg_G_CAP,J9+K9)) -> 17500 | S9: لا | T9: 0 | U9: 12 | V9: 9 | W9: 0 | Z9: =IF(B9="","",IF(AND(X9<>"",X9<=cfg_VAL_DATE),"✖ منتهي الخدمة",IF(H9>cfg_VAL_DATE,"⚠ لم يباشر بعد","✔ على رأس العمل"))) -> ✔ على رأس العمل | AA9: الإنماء | AB9: SA6005000068200000000002
A10: =IF(B10="","",ROW()-5) -> 5 | B10: E005 | C10: راجيش كومار | D10: هندي | E10: غير سعودي | F10: تقنية المعلومات | G10: مهندس شبكات | H10: 43933 | I10: 46417 | J10: 9000 | K10: 2250 | L10: 900 | M10: 700 | N10: =IF(B10="","",SUM(J10:M10)) -> 12850 | O10: =IF(B10="","",J10+IF(cfg_EOS_H="نعم",K10,0)+IF(cfg_EOS_T="نعم",L10,0)+IF(cfg_EOS_O="نعم",M10,0)) -> 12150 | P10: =IF(B10="","",J10+IF(cfg_LV_H="نعم",K10,0)+IF(cfg_LV_T="نعم",L10,0)+IF(cfg_LV_O="نعم",M10,0)) -> 12150 | Q10: =IF(B10="","",MIN(cfg_G_CAP,J10+K10)) -> 11250 | S10: نعم | T10: 2800 | U10: 12 | V10: 14 | W10: 900 | Z10: =IF(B10="","",IF(AND(X10<>"",X10<=cfg_VAL_DATE),"✖ منتهي الخدمة",IF(H10>cfg_VAL_DATE,"⚠ لم يباشر بعد","✔ على رأس العمل"))) -> ✔ على رأس العمل | AA10: الأهلي | AB10: SA4410000011100000000003
A11: =IF(B11="","",ROW()-5) -> 6 | B11: E006 | C11: فهد ناصر الشمري | D11: سعودي | E11: سعودي | F11: المبيعات | G11: مدير مبيعات | H11: 43044 | I11: 47929 | J11: 13000 | K11: 3250 | L11: 1300 | M11: 2500 | N11: =IF(B11="","",SUM(J11:M11)) -> 20050 | O11: =IF(B11="","",J11+IF(cfg_EOS_H="نعم",K11,0)+IF(cfg_EOS_T="نعم",L11,0)+IF(cfg_EOS_O="نعم",M11,0)) -> 17550 | P11: =IF(B11="","",J11+IF(cfg_LV_H="نعم",K11,0)+IF(cfg_LV_T="نعم",L11,0)+IF(cfg_LV_O="نعم",M11,0)) -> 17550 | Q11: =IF(B11="","",MIN(cfg_G_CAP,J11+K11)) -> 16250 | S11: لا | T11: 0 | U11: 12 | V11: 25 | W11: 0 | Z11: =IF(B11="","",IF(AND(X11<>"",X11<=cfg_VAL_DATE),"✖ منتهي الخدمة",IF(H11>cfg_VAL_DATE,"⚠ لم يباشر بعد","✔ على رأس العمل"))) -> ✔ على رأس العمل | AA11: الراجحي | AB11: SA0380000000608010167521
A12: =IF(B12="","",ROW()-5) -> 7 | B12: E007 | C12: خالد يوسف الأحمد | D12: أردني | E12: غير سعودي | F12: المشاريع | G12: مهندس مشاريع | H12: 44216 | I12: 46320 | J12: 11000 | K12: 2750 | L12: 1100 | M12: 800 | N12: =IF(B12="","",SUM(J12:M12)) -> 15650 | O12: =IF(B12="","",J12+IF(cfg_EOS_H="نعم",K12,0)+IF(cfg_EOS_T="نعم",L12,0)+IF(cfg_EOS_O="نعم",M12,0)) -> 14850 | P12: =IF(B12="","",J12+IF(cfg_LV_H="نعم",K12,0)+IF(cfg_LV_T="نعم",L12,0)+IF(cfg_LV_O="نعم",M12,0)) -> 14850 | Q12: =IF(B12="","",MIN(cfg_G_CAP,J12+K12)) -> 13750 | S12: نعم | T12: 4500 | U12: 12 | V12: 16 | W12: 2400 | Z12: =IF(B12="","",IF(AND(X12<>"",X12<=cfg_VAL_DATE),"✖ منتهي الخدمة",IF(H12>cfg_VAL_DATE,"⚠ لم يباشر بعد","✔ على رأس العمل"))) -> ✔ على رأس العمل | AA12: البلاد | AB12: SA1515000999100000000004
A13: =IF(B13="","",ROW()-5) -> 8 | B13: E008 | C13: سارة عبدالرحمن الزهراني | D13: سعودية | E13: سعودي | F13: المالية | G13: محاسبة | H13: 44986 | I13: 48466 | J13: 7500 | K13: 1875 | L13: 750 | M13: 0 | N13: =IF(B13="","",SUM(J13:M13)) -> 10125 | O13: =IF(B13="","",J13+IF(cfg_EOS_H="نعم",K13,0)+IF(cfg_EOS_T="نعم",L13,0)+IF(cfg_EOS_O="نعم",M13,0)) -> 10125 | P13: =IF(B13="","",J13+IF(cfg_LV_H="نعم",K13,0)+IF(cfg_LV_T="نعم",L13,0)+IF(cfg_LV_O="نعم",M13,0)) -> 10125 | Q13: =IF(B13="","",MIN(cfg_G_CAP,J13+K13)) -> 9375 | S13: لا | T13: 0 | U13: 12 | V13: 6 | W13: 0 | Z13: =IF(B13="","",IF(AND(X13<>"",X13<=cfg_VAL_DATE),"✖ منتهي الخدمة",IF(H13>cfg_VAL_DATE,"⚠ لم يباشر بعد","✔ على رأس العمل"))) -> ✔ على رأس العمل | AA13: الإنماء | AB13: SA6005000068200000000005
A14: =IF(B14="","",ROW()-5) -> 9 | B14: E009 | C14: محمد رفيق | D14: باكستاني | E14: غير سعودي | F14: العمليات | G14: مشرف عمليات | H14: 41869 | I14: 46539 | J14: 6500 | K14: 1625 | L14: 650 | M14: 300 | N14: =IF(B14="","",SUM(J14:M14)) -> 9075 | O14: =IF(B14="","",J14+IF(cfg_EOS_H="نعم",K14,0)+IF(cfg_EOS_T="نعم",L14,0)+IF(cfg_EOS_O="نعم",M14,0)) -> 8775 | P14: =IF(B14="","",J14+IF(cfg_LV_H="نعم",K14,0)+IF(cfg_LV_T="نعم",L14,0)+IF(cfg_LV_O="نعم",M14,0)) -> 8775 | Q14: =IF(B14="","",MIN(cfg_G_CAP,J14+K14)) -> 8125 | R14: 30 | S14: نعم | T14: 2200 | U14: 24 | V14: 35 | W14: 2000 | Z14: =IF(B14="","",IF(AND(X14<>"",X14<=cfg_VAL_DATE),"✖ منتهي الخدمة",IF(H14>cfg_VAL_DATE,"⚠ لم يباشر بعد","✔ على رأس العمل"))) -> ✔ على رأس العمل | AA14: الراجحي | AB14: SA0380000000608010167522
A15: =IF(B15="","",ROW()-5) -> 10 | B15: E010 | C15: ريم سلطان المطيري | D15: سعودية | E15: سعودي | F15: المبيعات | G15: أخصائية تسويق | H15: 46127 | I15: 48580 | J15: 9000 | K15: 2250 | L15: 900 | M15: 0 | N15: =IF(B15="","",SUM(J15:M15)) -> 12150 | O15: =IF(B15="","",J15+IF(cfg_EOS_H="نعم",K15,0)+IF(cfg_EOS_T="نعم",L15,0)+IF(cfg_EOS_O="نعم",M15,0)) -> 12150 | P15: =IF(B15="","",J15+IF(cfg_LV_H="نعم",K15,0)+IF(cfg_LV_T="نعم",L15,0)+IF(cfg_LV_O="نعم",M15,0)) -> 12150 | Q15: =IF(B15="","",MIN(cfg_G_CAP,J15+K15)) -> 11250 | S15: لا | T15: 0 | U15: 12 | V15: 0 | W15: 0 | Z15: =IF(B15="","",IF(AND(X15<>"",X15<=cfg_VAL_DATE),"✖ منتهي الخدمة",IF(H15>cfg_VAL_DATE,"⚠ لم يباشر بعد","✔ على رأس العمل"))) -> ✔ على رأس العمل | AA15: الأهلي | AB15: SA4410000011100000000006
A16: =IF(B16="","",ROW()-5) -> 11 | B16: E011 | C16: جون ماتيو | D16: فلبيني | E16: غير سعودي | F16: العمليات | G16: فني صيانة | H16: 43525 | I16: 46481 | J16: 5000 | K16: 1250 | L16: 500 | M16: 0 | N16: =IF(B16="","",SUM(J16:M16)) -> 6750 | O16: =IF(B16="","",J16+IF(cfg_EOS_H="نعم",K16,0)+IF(cfg_EOS_T="نعم",L16,0)+IF(cfg_EOS_O="نعم",M16,0)) -> 6750 | P16: =IF(B16="","",J16+IF(cfg_LV_H="نعم",K16,0)+IF(cfg_LV_T="نعم",L16,0)+IF(cfg_LV_O="نعم",M16,0)) -> 6750 | Q16: =IF(B16="","",MIN(cfg_G_CAP,J16+K16)) -> 6250 | S16: نعم | T16: 2600 | U16: 24 | V16: 22 | W16: 1800 | X16: 46203 | Y16: استقالة | Z16: =IF(B16="","",IF(AND(X16<>"",X16<=cfg_VAL_DATE),"✖ منتهي الخدمة",IF(H16>cfg_VAL_DATE,"⚠ لم يباشر بعد","✔ على رأس العمل"))) -> ✖ منتهي الخدمة | AA16: الراجحي | AB16: SA0380000000608010167523
A17: =IF(B17="","",ROW()-5) -> 12 | B17: E012 | C17: عمر حسين البيشي | D17: سعودي | E17: سعودي | F17: تقنية المعلومات | G17: مطور برمجيات | H17: 44752 | I17: 47464 | J17: 12000 | K17: 3000 | L17: 1200 | M17: 1500 | N17: =IF(B17="","",SUM(J17:M17)) -> 17700 | O17: =IF(B17="","",J17+IF(cfg_EOS_H="نعم",K17,0)+IF(cfg_EOS_T="نعم",L17,0)+IF(cfg_EOS_O="نعم",M17,0)) -> 16200 | P17: =IF(B17="","",J17+IF(cfg_LV_H="نعم",K17,0)+IF(cfg_LV_T="نعم",L17,0)+IF(cfg_LV_O="نعم",M17,0)) -> 16200 | Q17: =IF(B17="","",MIN(cfg_G_CAP,J17+K17)) -> 15000 | S17: لا | T17: 0 | U17: 12 | V17: 10 | W17: 0 | Z17: =IF(B17="","",IF(AND(X17<>"",X17<=cfg_VAL_DATE),"✖ منتهي الخدمة",IF(H17>cfg_VAL_DATE,"⚠ لم يباشر بعد","✔ على رأس العمل"))) -> ✔ على رأس العمل | AA17: البلاد | AB17: SA1515000999100000000007
A18: =IF(B18="","",ROW()-5) | N18: =IF(B18="","",SUM(J18:M18)) | O18: =IF(B18="","",J18+IF(cfg_EOS_H="نعم",K18,0)+IF(cfg_EOS_T="نعم",L18,0)+IF(cfg_EOS_O="نعم",M18,0)) | P18: =IF(B18="","",J18+IF(cfg_LV_H="نعم",K18,0)+IF(cfg_LV_T="نعم",L18,0)+IF(cfg_LV_O="نعم",M18,0)) | Q18: =IF(B18="","",MIN(cfg_G_CAP,J18+K18)) | Z18: =IF(B18="","",IF(AND(X18<>"",X18<=cfg_VAL_DATE),"✖ منتهي الخدمة",IF(H18>cfg_VAL_DATE,"⚠ لم يباشر بعد","✔ على رأس العمل")))
A19: =IF(B19="","",ROW()-5) | N19: =IF(B19="","",SUM(J19:M19)) | O19: =IF(B19="","",J19+IF(cfg_EOS_H="نعم",K19,0)+IF(cfg_EOS_T="نعم",L19,0)+IF(cfg_EOS_O="نعم",M19,0)) | P19: =IF(B19="","",J19+IF(cfg_LV_H="نعم",K19,0)+IF(cfg_LV_T="نعم",L19,0)+IF(cfg_LV_O="نعم",M19,0)) | Q19: =IF(B19="","",MIN(cfg_G_CAP,J19+K19)) | Z19: =IF(B19="","",IF(AND(X19<>"",X19<=cfg_VAL_DATE),"✖ منتهي الخدمة",IF(H19>cfg_VAL_DATE,"⚠ لم يباشر بعد","✔ على رأس العمل")))
A20: =IF(B20="","",ROW()-5) | N20: =IF(B20="","",SUM(J20:M20)) | O20: =IF(B20="","",J20+IF(cfg_EOS_H="نعم",K20,0)+IF(cfg_EOS_T="نعم",L20,0)+IF(cfg_EOS_O="نعم",M20,0)) | P20: =IF(B20="","",J20+IF(cfg_LV_H="نعم",K20,0)+IF(cfg_LV_T="نعم",L20,0)+IF(cfg_LV_O="نعم",M20,0)) | Q20: =IF(B20="","",MIN(cfg_G_CAP,J20+K20)) | Z20: =IF(B20="","",IF(AND(X20<>"",X20<=cfg_VAL_DATE),"✖ منتهي الخدمة",IF(H20>cfg_VAL_DATE,"⚠ لم يباشر بعد","✔ على رأس العمل")))
A21: =IF(B21="","",ROW()-5) | N21: =IF(B21="","",SUM(J21:M21)) | O21: =IF(B21="","",J21+IF(cfg_EOS_H="نعم",K21,0)+IF(cfg_EOS_T="نعم",L21,0)+IF(cfg_EOS_O="نعم",M21,0)) | P21: =IF(B21="","",J21+IF(cfg_LV_H="نعم",K21,0)+IF(cfg_LV_T="نعم",L21,0)+IF(cfg_LV_O="نعم",M21,0)) | Q21: =IF(B21="","",MIN(cfg_G_CAP,J21+K21)) | Z21: =IF(B21="","",IF(AND(X21<>"",X21<=cfg_VAL_DATE),"✖ منتهي الخدمة",IF(H21>cfg_VAL_DATE,"⚠ لم يباشر بعد","✔ على رأس العمل")))
A22: =IF(B22="","",ROW()-5) | N22: =IF(B22="","",SUM(J22:M22)) | O22: =IF(B22="","",J22+IF(cfg_EOS_H="نعم",K22,0)+IF(cfg_EOS_T="نعم",L22,0)+IF(cfg_EOS_O="نعم",M22,0)) | P22: =IF(B22="","",J22+IF(cfg_LV_H="نعم",K22,0)+IF(cfg_LV_T="نعم",L22,0)+IF(cfg_LV_O="نعم",M22,0)) | Q22: =IF(B22="","",MIN(cfg_G_CAP,J22+K22)) | Z22: =IF(B22="","",IF(AND(X22<>"",X22<=cfg_VAL_DATE),"✖ منتهي الخدمة",IF(H22>cfg_VAL_DATE,"⚠ لم يباشر بعد","✔ على رأس العمل")))
A23: =IF(B23="","",ROW()-5) | N23: =IF(B23="","",SUM(J23:M23)) | O23: =IF(B23="","",J23+IF(cfg_EOS_H="نعم",K23,0)+IF(cfg_EOS_T="نعم",L23,0)+IF(cfg_EOS_O="نعم",M23,0)) | P23: =IF(B23="","",J23+IF(cfg_LV_H="نعم",K23,0)+IF(cfg_LV_T="نعم",L23,0)+IF(cfg_LV_O="نعم",M23,0)) | Q23: =IF(B23="","",MIN(cfg_G_CAP,J23+K23)) | Z23: =IF(B23="","",IF(AND(X23<>"",X23<=cfg_VAL_DATE),"✖ منتهي الخدمة",IF(H23>cfg_VAL_DATE,"⚠ لم يباشر بعد","✔ على رأس العمل")))
A24: =IF(B24="","",ROW()-5) | N24: =IF(B24="","",SUM(J24:M24)) | O24: =IF(B24="","",J24+IF(cfg_EOS_H="نعم",K24,0)+IF(cfg_EOS_T="نعم",L24,0)+IF(cfg_EOS_O="نعم",M24,0)) | P24: =IF(B24="","",J24+IF(cfg_LV_H="نعم",K24,0)+IF(cfg_LV_T="نعم",L24,0)+IF(cfg_LV_O="نعم",M24,0)) | Q24: =IF(B24="","",MIN(cfg_G_CAP,J24+K24)) | Z24: =IF(B24="","",IF(AND(X24<>"",X24<=cfg_VAL_DATE),"✖ منتهي الخدمة",IF(H24>cfg_VAL_DATE,"⚠ لم يباشر بعد","✔ على رأس العمل")))
A25: =IF(B25="","",ROW()-5) | N25: =IF(B25="","",SUM(J25:M25)) | O25: =IF(B25="","",J25+IF(cfg_EOS_H="نعم",K25,0)+IF(cfg_EOS_T="نعم",L25,0)+IF(cfg_EOS_O="نعم",M25,0)) | P25: =IF(B25="","",J25+IF(cfg_LV_H="نعم",K25,0)+IF(cfg_LV_T="نعم",L25,0)+IF(cfg_LV_O="نعم",M25,0)) | Q25: =IF(B25="","",MIN(cfg_G_CAP,J25+K25)) | Z25: =IF(B25="","",IF(AND(X25<>"",X25<=cfg_VAL_DATE),"✖ منتهي الخدمة",IF(H25>cfg_VAL_DATE,"⚠ لم يباشر بعد","✔ على رأس العمل")))
A26: =IF(B26="","",ROW()-5) | N26: =IF(B26="","",SUM(J26:M26)) | O26: =IF(B26="","",J26+IF(cfg_EOS_H="نعم",K26,0)+IF(cfg_EOS_T="نعم",L26,0)+IF(cfg_EOS_O="نعم",M26,0)) | P26: =IF(B26="","",J26+IF(cfg_LV_H="نعم",K26,0)+IF(cfg_LV_T="نعم",L26,0)+IF(cfg_LV_O="نعم",M26,0)) | Q26: =IF(B26="","",MIN(cfg_G_CAP,J26+K26)) | Z26: =IF(B26="","",IF(AND(X26<>"",X26<=cfg_VAL_DATE),"✖ منتهي الخدمة",IF(H26>cfg_VAL_DATE,"⚠ لم يباشر بعد","✔ على رأس العمل")))
A27: =IF(B27="","",ROW()-5) | N27: =IF(B27="","",SUM(J27:M27)) | O27: =IF(B27="","",J27+IF(cfg_EOS_H="نعم",K27,0)+IF(cfg_EOS_T="نعم",L27,0)+IF(cfg_EOS_O="نعم",M27,0)) | P27: =IF(B27="","",J27+IF(cfg_LV_H="نعم",K27,0)+IF(cfg_LV_T="نعم",L27,0)+IF(cfg_LV_O="نعم",M27,0)) | Q27: =IF(B27="","",MIN(cfg_G_CAP,J27+K27)) | Z27: =IF(B27="","",IF(AND(X27<>"",X27<=cfg_VAL_DATE),"✖ منتهي الخدمة",IF(H27>cfg_VAL_DATE,"⚠ لم يباشر بعد","✔ على رأس العمل")))
A28: =IF(B28="","",ROW()-5) | N28: =IF(B28="","",SUM(J28:M28)) | O28: =IF(B28="","",J28+IF(cfg_EOS_H="نعم",K28,0)+IF(cfg_EOS_T="نعم",L28,0)+IF(cfg_EOS_O="نعم",M28,0)) | P28: =IF(B28="","",J28+IF(cfg_LV_H="نعم",K28,0)+IF(cfg_LV_T="نعم",L28,0)+IF(cfg_LV_O="نعم",M28,0)) | Q28: =IF(B28="","",MIN(cfg_G_CAP,J28+K28)) | Z28: =IF(B28="","",IF(AND(X28<>"",X28<=cfg_VAL_DATE),"✖ منتهي الخدمة",IF(H28>cfg_VAL_DATE,"⚠ لم يباشر بعد","✔ على رأس العمل")))
A29: =IF(B29="","",ROW()-5) | N29: =IF(B29="","",SUM(J29:M29)) | O29: =IF(B29="","",J29+IF(cfg_EOS_H="نعم",K29,0)+IF(cfg_EOS_T="نعم",L29,0)+IF(cfg_EOS_O="نعم",M29,0)) | P29: =IF(B29="","",J29+IF(cfg_LV_H="نعم",K29,0)+IF(cfg_LV_T="نعم",L29,0)+IF(cfg_LV_O="نعم",M29,0)) | Q29: =IF(B29="","",MIN(cfg_G_CAP,J29+K29)) | Z29: =IF(B29="","",IF(AND(X29<>"",X29<=cfg_VAL_DATE),"✖ منتهي الخدمة",IF(H29>cfg_VAL_DATE,"⚠ لم يباشر بعد","✔ على رأس العمل")))
... A105: =IF(B105="","",ROW()-5) | N105: =IF(B105="","",SUM(J105:M105)) | O105: =IF(B105="","",J105+IF(cfg_EOS_H="نعم",K105,0)+IF(cfg_EOS_T="نعم",L105,0)+IF(cfg_EOS_O="نعم",M105,0)) | P105: =IF(B105="","",J105+IF(cfg_LV_H="نعم",K105,0)+IF(cfg_LV_T="نعم",L105,0)+IF(cfg_LV_O="نعم",M105,0)) | Q105: =IF(B105="","",MIN(cfg_G_CAP,J105+K105)) | Z105: =IF(B105="","",IF(AND(X105<>"",X105<=cfg_VAL_DATE),"✖ منتهي الخدمة",IF(H105>cfg_VAL_DATE,"⚠ لم يباشر بعد","✔ على رأس العمل")))
B106: =COUNTA(B6:B105)&" موظف" -> 12 موظف | C106: الإجمالي | J106: =SUM(J6:J105) -> 141500 | K106: =SUM(K6:K105) -> 35375 | L106: =SUM(L6:L105) -> 14150 | M106: =SUM(M6:M105) -> 10300 | N106: =SUM(N6:N105) -> 201325 | O106: =SUM(O6:O105) -> 191025 | P106: =SUM(P6:P105) -> 191025 | Q106: =SUM(Q6:Q105) -> 176875 | T106: =SUM(T6:T105) -> 15300 | W106: =SUM(W6:W105) -> 8700

Sheet الحركات الشهرية
A1: ✍ الحركات الشهرية المتغيرة (غياب — إضافي — مكافآت — سلف — إجازات — تذاكر)
A2: =cfg_CO&" | السنة المالية "&cfg_FY&" | شهر التقرير: "&INDEX(L_MONTH,cfg_VAL_M)&" | المبالغ بـ "&cfg_CUR -> شركة النخبة للتجارة والمقاولات | السنة المالية 2026 | شهر التقرير: سبتمبر | المبالغ بـ ريال سعودي
A3: 🏠 الرئيسية | B3: 📊 لوحة التحكم | C3: ⚙ الإعدادات | D3: 👥 الموظفون | E3: 📅 الملخص الشهري | F3: 🧾 القيود | G3: 💳 القسيمة
A5: الشهر (1-12) | B5: الرقم الوظيفي | C5: اسم الموظف (تلقائي) | D5: أيام غياب | E5: إجازة بدون راتب (يوم) | F5: ساعات عمل إضافي | G5: مكافآت وعمولات | H5: إضافات أخرى / فروقات | I5: أقساط سلف | J5: خصومات وجزاءات | K5: إجازة سنوية مأخوذة (يوم) | L5: إجازة مصروفة نقداً (يوم) | M5: قيمة تذاكر مستخدمة | N5: مكافأة نهاية خدمة مدفوعة | O5: ملاحظات
A6: 1 | B6: E003 | C6: =IF(B6="","",IFERROR(INDEX(الموظفون!$C$6:$C$105,MATCH(B6,الموظفون!$B$6:$B$105,0)),"✖ رقم غير موجود")) -> محمد علي حسن | F6: 12 | I6: 1000 | O6: قسط سلفة 1/5
A7: 1 | B7: E009 | C7: =IF(B7="","",IFERROR(INDEX(الموظفون!$C$6:$C$105,MATCH(B7,الموظفون!$B$6:$B$105,0)),"✖ رقم غير موجود")) -> محمد رفيق | D7: 1 | F7: 20 | J7: 100 | O7: غياب يوم
A8: 2 | B8: E003 | C8: =IF(B8="","",IFERROR(INDEX(الموظفون!$C$6:$C$105,MATCH(B8,الموظفون!$B$6:$B$105,0)),"✖ رقم غير موجود")) -> محمد علي حسن | F8: 8 | I8: 1000 | O8: قسط سلفة 2/5
A9: 2 | B9: E006 | C9: =IF(B9="","",IFERROR(INDEX(الموظفون!$C$6:$C$105,MATCH(B9,الموظفون!$B$6:$B$105,0)),"✖ رقم غير موجود")) -> فهد ناصر الشمري | G9: 5000 | O9: عمولة مبيعات الربع الرابع
A10: 3 | B10: E003 | C10: =IF(B10="","",IFERROR(INDEX(الموظفون!$C$6:$C$105,MATCH(B10,الموظفون!$B$6:$B$105,0)),"✖ رقم غير موجود")) -> محمد علي حسن | I10: 1000 | O10: قسط سلفة 3/5
A11: 3 | B11: E001 | C11: =IF(B11="","",IFERROR(INDEX(الموظفون!$C$6:$C$105,MATCH(B11,الموظفون!$B$6:$B$105,0)),"✖ رقم غير موجود")) -> عبدالله محمد العتيبي | K11: 10 | O11: إجازة سنوية
A12: 3 | B12: E007 | C12: =IF(B12="","",IFERROR(INDEX(الموظفون!$C$6:$C$105,MATCH(B12,الموظفون!$B$6:$B$105,0)),"✖ رقم غير موجود")) -> خالد يوسف الأحمد | F12: 10 | K12: 21 | M12: 4500 | O12: إجازة سنوية + تذكرة
A13: 4 | B13: E003 | C13: =IF(B13="","",IFERROR(INDEX(الموظفون!$C$6:$C$105,MATCH(B13,الموظفون!$B$6:$B$105,0)),"✖ رقم غير موجود")) -> محمد علي حسن | I13: 1000 | O13: قسط سلفة 4/5
A14: 4 | B14: E012 | C14: =IF(B14="","",IFERROR(INDEX(الموظفون!$C$6:$C$105,MATCH(B14,الموظفون!$B$6:$B$105,0)),"✖ رقم غير موجود")) -> عمر حسين البيشي | D14: 2 | O14: غياب يومين
A15: 5 | B15: E003 | C15: =IF(B15="","",IFERROR(INDEX(الموظفون!$C$6:$C$105,MATCH(B15,الموظفون!$B$6:$B$105,0)),"✖ رقم غير موجود")) -> محمد علي حسن | I15: 1000 | O15: قسط سلفة 5/5
A16: 5 | B16: E005 | C16: =IF(B16="","",IFERROR(INDEX(الموظفون!$C$6:$C$105,MATCH(B16,الموظفون!$B$6:$B$105,0)),"✖ رقم غير موجود")) -> راجيش كومار | F16: 16
A17: 6 | B17: E009 | C17: =IF(B17="","",IFERROR(INDEX(الموظفون!$C$6:$C$105,MATCH(B17,الموظفون!$B$6:$B$105,0)),"✖ رقم غير موجود")) -> محمد رفيق | K17: 30 | M17: 2200 | O17: إجازة سنوية + تذكرة
A18: 6 | B18: E006 | C18: =IF(B18="","",IFERROR(INDEX(الموظفون!$C$6:$C$105,MATCH(B18,الموظفون!$B$6:$B$105,0)),"✖ رقم غير موجود")) -> فهد ناصر الشمري | G18: 6500 | O18: عمولة مبيعات
A19: 6 | B19: E011 | C19: =IF(B19="","",IFERROR(INDEX(الموظفون!$C$6:$C$105,MATCH(B19,الموظفون!$B$6:$B$105,0)),"✖ رقم غير موجود")) -> جون ماتيو | O19: آخر يوم عمل 30/06
A20: 7 | B20: E011 | C20: =IF(B20="","",IFERROR(INDEX(الموظفون!$C$6:$C$105,MATCH(B20,الموظفون!$B$6:$B$105,0)),"✖ رقم غير موجود")) -> جون ماتيو | H20: =L20*INDEX('مخصص الإجازات'!$G$6:$G$105,MATCH(B20,'مخصص الإجازات'!$B$6:$B$105,0)) -> 8297.2603 | L20: =INDEX('مخصص الإجازات'!$H$6:$H$105,MATCH(B20,'مخصص الإجازات'!$B$6:$B$105,0))+INDEX('مخصص الإجازات'!$L$6:$L$105,MATCH(B20,'مخصص الإجازات'!$B$6:$B$105,0))-INDEX('مخصص الإجازات'!$M$6:$M$105,MATCH(B20,'مخصص الإجازات'!$B$6:$B$105,0)) -> 36.876712 | N20: =INDEX('مخصص نهاية الخدمة'!$O$6:$O$105,MATCH(B20,'مخصص نهاية الخدمة'!$B$6:$B$105,0)) -> 21778.767 | O20: تسوية نهاية خدمة: المكافأة + صرف رصيد الإجازات نقداً (في الإضافات)
A21: 7 | B21: E004 | C21: =IF(B21="","",IFERROR(INDEX(الموظفون!$C$6:$C$105,MATCH(B21,الموظفون!$B$6:$B$105,0)),"✖ رقم غير موجود")) -> نورة خالد الدوسري | K21: 15 | O21: إجازة سنوية
A22: 7 | B22: E002 | C22: =IF(B22="","",IFERROR(INDEX(الموظفون!$C$6:$C$105,MATCH(B22,الموظفون!$B$6:$B$105,0)),"✖ رقم غير موجود")) -> أحمد سعيد القحطاني | K22: 20 | O22: إجازة سنوية
A23: 8 | B23: E008 | C23: =IF(B23="","",IFERROR(INDEX(الموظفون!$C$6:$C$105,MATCH(B23,الموظفون!$B$6:$B$105,0)),"✖ رقم غير موجود")) -> سارة عبدالرحمن الزهراني | E23: 3 | O23: إجازة بدون راتب
A24: 8 | B24: E005 | C24: =IF(B24="","",IFERROR(INDEX(الموظفون!$C$6:$C$105,MATCH(B24,الموظفون!$B$6:$B$105,0)),"✖ رقم غير موجود")) -> راجيش كومار | K24: 21 | M24: 2800 | O24: إجازة سنوية + تذكرة
A25: 9 | B25: E010 | C25: =IF(B25="","",IFERROR(INDEX(الموظفون!$C$6:$C$105,MATCH(B25,الموظفون!$B$6:$B$105,0)),"✖ رقم غير موجود")) -> ريم سلطان المطيري | F25: 6 | H25: 1500 | O25: بدل مهمة عمل
A26: 9 | B26: E006 | C26: =IF(B26="","",IFERROR(INDEX(الموظفون!$C$6:$C$105,MATCH(B26,الموظفون!$B$6:$B$105,0)),"✖ رقم غير موجود")) -> فهد ناصر الشمري | J26: 250 | O26: جزاء تأخير
C27: =IF(B27="","",IFERROR(INDEX(الموظفون!$C$6:$C$105,MATCH(B27,الموظفون!$B$6:$B$105,0)),"✖ رقم غير موجود"))
C28: =IF(B28="","",IFERROR(INDEX(الموظفون!$C$6:$C$105,MATCH(B28,الموظفون!$B$6:$B$105,0)),"✖ رقم غير موجود"))
C29: =IF(B29="","",IFERROR(INDEX(الموظفون!$C$6:$C$105,MATCH(B29,الموظفون!$B$6:$B$105,0)),"✖ رقم غير موجود"))
C30: =IF(B30="","",IFERROR(INDEX(الموظفون!$C$6:$C$105,MATCH(B30,الموظفون!$B$6:$B$105,0)),"✖ رقم غير موجود"))
C31: =IF(B31="","",IFERROR(INDEX(الموظفون!$C$6:$C$105,MATCH(B31,الموظفون!$B$6:$B$105,0)),"✖ رقم غير موجود"))
C32: =IF(B32="","",IFERROR(INDEX(الموظفون!$C$6:$C$105,MATCH(B32,الموظفون!$B$6:$B$105,0)),"✖ رقم غير موجود"))
C33: =IF(B33="","",IFERROR(INDEX(الموظفون!$C$6:$C$105,MATCH(B33,الموظفون!$B$6:$B$105,0)),"✖ رقم غير موجود"))
C34: =IF(B34="","",IFERROR(INDEX(الموظفون!$C$6:$C$105,MATCH(B34,الموظفون!$B$6:$B$105,0)),"✖ رقم غير موجود"))
C35: =IF(B35="","",IFERROR(INDEX(الموظفون!$C$6:$C$105,MATCH(B35,الموظفون!$B$6:$B$105,0)),"✖ رقم غير موجود"))
C36: =IF(B36="","",IFERROR(INDEX(الموظفون!$C$6:$C$105,MATCH(B36,الموظفون!$B$6:$B$105,0)),"✖ رقم غير موجود"))
C37: =IF(B37="","",IFERROR(INDEX(الموظفون!$C$6:$C$105,MATCH(B37,الموظفون!$B$6:$B$105,0)),"✖ رقم غير موجود"))
C38: =IF(B38="","",IFERROR(INDEX(الموظفون!$C$6:$C$105,MATCH(B38,الموظفون!$B$6:$B$105,0)),"✖ رقم غير موجود"))
... C1005: =IF(B1005="","",IFERROR(INDEX(الموظفون!$C$6:$C$105,MATCH(B1005,الموظفون!$B$6:$B$105,0)),"✖ رقم غير موجود"))

Sheet مسير يناير
A1: ="💵 مسير رواتب شهر يناير "&cfg_FY -> 💵 مسير رواتب شهر يناير 2026
A2: =cfg_CO&" | السنة المالية "&cfg_FY&" | شهر التقرير: "&INDEX(L_MONTH,cfg_VAL_M)&" | المبالغ بـ "&cfg_CUR -> شركة النخبة للتجارة والمقاولات | السنة المالية 2026 | شهر التقرير: سبتمبر | المبالغ بـ ريال سعودي
B3: الشهر | C3: 1 | D3: من | E3: =DATE(cfg_FY,C3,1) -> 46023 | F3: إلى | G3: =EOMONTH(E3,0) -> 46053 | H3: =IF(C3<=cfg_VAL_M,"✔ فعلي","⚠ متوقع") -> ✔ فعلي | L3: الشهر التالي ▶ | O3: 🏠 الرئيسية | P3: 📊 لوحة التحكم | R3: 👥 الموظفون | S3: ✍ الحركات | U3: 📅 الملخص الشهري | W3: 🧾 القيود
A5: م | B5: الرقم الوظيفي | C5: اسم الموظف | D5: القسم | E5: الفئة | F5: أيام الاستحقاق | G5: أيام الغياب | H5: بدون راتب | I5: أيام مدفوعة | J5: الأساسي | K5: السكن | L5: النقل | M5: أخرى | N5: ساعات إضافي | O5: قيمة الإضافي | P5: مكافآت وعمولات | Q5: إضافات أخرى | R5: إجمالي المستحقات | S5: تأمينات (حصة الموظف) | T5: أقساط سلف | U5: خصومات وجزاءات | V5: إجمالي الاستقطاعات | W5: صافي الراتب | X5: تأمينات (حصة المنشأة) | Y5: مخصص نهاية الخدمة للشهر | Z5: مخصص الإجازات للشهر | AA5: مخصص التذاكر للشهر | AB5: إجمالي تكلفة الموظف | AC5: سنوات الخدمة نهاية الشهر | AD5: سنوات الخدمة نهاية الشهر السابق | AE5: أيام العمل الفعلية (تقويمي)
A6: =IF($B6="","",الموظفون!$A6) -> 1 | B6: =IF(الموظفون!$B6="","",الموظفون!$B6) -> E001 | C6: =IF($B6="","",الموظفون!$C6) -> عبدالله محمد العتيبي | D6: =IF($B6="","",الموظفون!$F6) -> الإدارة العليا | E6: =IF($B6="","",الموظفون!$E6) -> سعودي | F6: =IF($B6="","",IF(AE6>=DAY($G$3),cfg_DAYS_M,MIN(AE6,cfg_DAYS_M))) -> 30 | G6: =IF($B6="","",SUMIFS('الحركات الشهرية'!$D$6:$D$1005,'الحركات الشهرية'!$B$6:$B$1005,$B6,'الحركات الشهرية'!$A$6:$A$1005,$C$3)) -> 0 | H6: =IF($B6="","",SUMIFS('الحركات الشهرية'!$E$6:$E$1005,'الحركات الشهرية'!$B$6:$B$1005,$B6,'الحركات الشهرية'!$A$6:$A$1005,$C$3)) -> 0 | I6: =IF($B6="","",MAX(0,F6-G6-H6)) -> 30 | J6: =IF($B6="","",الموظفون!$J6*$I6/cfg_DAYS_M) -> 28000 | K6: =IF($B6="","",الموظفون!$K6*$I6/cfg_DAYS_M) -> 7000 | L6: =IF($B6="","",الموظفون!$L6*$I6/cfg_DAYS_M) -> 2800 | M6: =IF($B6="","",الموظفون!$M6*$I6/cfg_DAYS_M) -> 3000 | N6: =IF($B6="","",SUMIFS('الحركات الشهرية'!$F$6:$F$1005,'الحركات الشهرية'!$B$6:$B$1005,$B6,'الحركات الشهرية'!$A$6:$A$1005,$C$3)) -> 0 | O6: =IF($B6="","",N6*(الموظفون!$N6+الموظفون!$J6*cfg_OT_P)/cfg_DAYS_M/cfg_HRS) -> 0 | P6: =IF($B6="","",SUMIFS('الحركات الشهرية'!$G$6:$G$1005,'الحركات الشهرية'!$B$6:$B$1005,$B6,'الحركات الشهرية'!$A$6:$A$1005,$C$3)) -> 0 | Q6: =IF($B6="","",SUMIFS('الحركات الشهرية'!$H$6:$H$1005,'الحركات الشهرية'!$B$6:$B$1005,$B6,'الحركات الشهرية'!$A$6:$A$1005,$C$3)) -> 0 | R6: =IF($B6="","",SUM(J6:M6)+SUM(O6:Q6)) -> 40800 | S6: =IF($B6="","",الموظفون!$Q6*IF(E6="سعودي",cfg_G_SE,cfg_G_NE)*F6/cfg_DAYS_M) -> 3412.5 | T6: =IF($B6="","",SUMIFS('الحركات الشهرية'!$I$6:$I$1005,'الحركات الشهرية'!$B$6:$B$1005,$B6,'الحركات الشهرية'!$A$6:$A$1005,$C$3)) -> 0 | U6: =IF($B6="","",SUMIFS('الحركات الشهرية'!$J$6:$J$1005,'الحركات الشهرية'!$B$6:$B$1005,$B6,'الحركات الشهرية'!$A$6:$A$1005,$C$3)) -> 0 | V6: =IF($B6="","",SUM(S6:U6)) -> 3412.5 | W6: =IF($B6="","",R6-V6) -> 37387.5 | X6: =IF($B6="","",الموظفون!$Q6*IF(E6="سعودي",cfg_G_SR,cfg_G_NR)*F6/cfg_DAYS_M) -> 4112.5 | Y6: =IF($B6="","",الموظفون!$O6*(cfg_EOS_R1*(MIN(AC6,cfg_EOS_TH)-MIN(AD6,cfg_EOS_TH))+cfg_EOS_R2*(MAX(AC6-cfg_EOS_TH,0)-MAX(AD6-cfg_EOS_TH,0)))) -> 3210.411 | Z6: =IF($B6="","",IF(الموظفون!$R6<>"",الموظفون!$R6,IF(AC6>=cfg_LV_TH,cfg_LV_D2,cfg_LV_D1))/cfg_DAYS_Y*AE6*الموظفون!$P6/cfg_DAYS_M) -> 3210.411 | AA6: =IF($B6="","",IF(AND(الموظفون!$S6="نعم",N(الموظفون!$U6)>0),الموظفون!$T6/الموظفون!$U6*12/cfg_DAYS_Y*AE6,0)) -> 0 | AB6: =IF($B6="","",R6+SUM(X6:AA6)) -> 51333.322 | AC6: =IF($B6="","",MAX(0,IF(OR(الموظفون!$X6="",الموظفون!$X6>$G$3),$G$3,الموظفون!$X6)-الموظفون!$H6+1)/cfg_DAYS_Y) -> 14.057534 | AD6: =IF($B6="","",MAX(0,IF(OR(الموظفون!$X6="",الموظفون!$X6>($E$3-1)),($E$3-1),الموظفون!$X6)-الموظفون!$H6+1)/cfg_DAYS_Y) -> 13.972603 | AE6: =IF($B6="","",MAX(0,IF(OR(الموظفون!$X6="",الموظفون!$X6>$G$3),$G$3,الموظفون!$X6)-MAX($E$3,الموظفون!$H6)+1)) -> 31
A7: =IF($B7="","",الموظفون!$A7) -> 2 | B7: =IF(الموظفون!$B7="","",الموظفون!$B7) -> E002 | C7: =IF($B7="","",الموظفون!$C7) -> أحمد سعيد القحطاني | D7: =IF($B7="","",الموظفون!$F7) -> المالية | E7: =IF($B7="","",الموظفون!$E7) -> سعودي | F7: =IF($B7="","",IF(AE7>=DAY($G$3),cfg_DAYS_M,MIN(AE7,cfg_DAYS_M))) -> 30 | G7: =IF($B7="","",SUMIFS('الحركات الشهرية'!$D$6:$D$1005,'الحركات الشهرية'!$B$6:$B$1005,$B7,'الحركات الشهرية'!$A$6:$A$1005,$C$3)) -> 0 | H7: =IF($B7="","",SUMIFS('الحركات الشهرية'!$E$6:$E$1005,'الحركات الشهرية'!$B$6:$B$1005,$B7,'الحركات الشهرية'!$A$6:$A$1005,$C$3)) -> 0 | I7: =IF($B7="","",MAX(0,F7-G7-H7)) -> 30 | J7: =IF($B7="","",الموظفون!$J7*$I7/cfg_DAYS_M) -> 18000 | K7: =IF($B7="","",الموظفون!$K7*$I7/cfg_DAYS_M) -> 4500 | L7: =IF($B7="","",الموظفون!$L7*$I7/cfg_DAYS_M) -> 1800 | M7: =IF($B7="","",الموظفون!$M7*$I7/cfg_DAYS_M) -> 1000 | N7: =IF($B7="","",SUMIFS('الحركات الشهرية'!$F$6:$F$1005,'الحركات الشهرية'!$B$6:$B$1005,$B7,'الحركات الشهرية'!$A$6:$A$1005,$C$3)) -> 0 | O7: =IF($B7="","",N7*(الموظفون!$N7+الموظفون!$J7*cfg_OT_P)/cfg_DAYS_M/cfg_HRS) -> 0 | P7: =IF($B7="","",SUMIFS('الحركات الشهرية'!$G$6:$G$1005,'الحركات الشهرية'!$B$6:$B$1005,$B7,'الحركات الشهرية'!$A$6:$A$1005,$C$3)) -> 0 | Q7: =IF($B7="","",SUMIFS('الحركات الشهرية'!$H$6:$H$1005,'الحركات الشهرية'!$B$6:$B$1005,$B7,'الحركات الشهرية'!$A$6:$A$1005,$C$3)) -> 0 | R7: =IF($B7="","",SUM(J7:M7)+SUM(O7:Q7)) -> 25300 | S7: =IF($B7="","",الموظفون!$Q7*IF(E7="سعودي",cfg_G_SE,cfg_G_NE)*F7/cfg_DAYS_M) -> 2193.75 | T7: =IF($B7="","",SUMIFS('الحركات الشهرية'!$I$6:$I$1005,'الحركات الشهرية'!$B$6:$B$1005,$B7,'الحركات الشهرية'!$A$6:$A$1005,$C$3)) -> 0 | U7: =IF($B7="","",SUMIFS('الحركات الشهرية'!$J$6:$J$1005,'الحركات الشهرية'!$B$6:$B$1005,$B7,'الحركات الشهرية'!$A$6:$A$1005,$C$3)) -> 0 | V7: =IF($B7="","",SUM(S7:U7)) -> 2193.75 | W7: =IF($B7="","",R7-V7) -> 23106.25 | X7: =IF($B7="","",الموظفون!$Q7*IF(E7="سعودي",cfg_G_SR,cfg_G_NR)*F7/cfg_DAYS_M) -> 2643.75 | Y7: =IF($B7="","",الموظفون!$O7*(cfg_EOS_R1*(MIN(AC7,cfg_EOS_TH)-MIN(AD7,cfg_EOS_TH))+cfg_EOS_R2*(MAX(AC7-cfg_EOS_TH,0)-MAX(AD7-cfg_EOS_TH,0)))) -> 2063.8356 | Z7: =IF($B7="","",IF(الموظفون!$R7<>"",الموظفون!$R7,IF(AC7>=cfg_LV_TH,cfg_LV_D2,cfg_LV_D1))/cfg_DAYS_Y*AE7*الموظفون!$P7/cfg_DAYS_M) -> 2063.8356 | AA7: =IF($B7="","",IF(AND(الموظفون!$S7="نعم",N(الموظفون!$U7)>0),الموظفون!$T7/الموظفون!$U7*12/cfg_DAYS_Y*AE7,0)) -> 0 | AB7: =IF($B7="","",R7+SUM(X7:AA7)) -> 32071.421 | AC7: =IF($B7="","",MAX(0,IF(OR(الموظفون!$X7="",الموظفون!$X7>$G$3),$G$3,الموظفون!$X7)-الموظفون!$H7+1)/cfg_DAYS_Y) -> 9.6767123 | AD7: =IF($B7="","",MAX(0,IF(OR(الموظفون!$X7="",الموظفون!$X7>($E$3-1)),($E$3-1),الموظفون!$X7)-الموظفون!$H7+1)/cfg_DAYS_Y) -> 9.5917808 | AE7: =IF($B7="","",MAX(0,IF(OR(الموظفون!$X7="",الموظفون!$X7>$G$3),$G$3,الموظفون!$X7)-MAX($E$3,الموظفون!$H7)+1)) -> 31
A8: =IF($B8="","",الموظفون!$A8) -> 3 | B8: =IF(الموظفون!$B8="","",الموظفون!$B8) -> E003 | C8: =IF($B8="","",الموظفون!$C8) -> محمد علي حسن | D8: =IF($B8="","",الموظفون!$F8) -> المالية | E8: =IF($B8="","",الموظفون!$E8) -> غير سعودي | F8: =IF($B8="","",IF(AE8>=DAY($G$3),cfg_DAYS_M,MIN(AE8,cfg_DAYS_M))) -> 30 | G8: =IF($B8="","",SUMIFS('الحركات الشهرية'!$D$6:$D$1005,'الحركات الشهرية'!$B$6:$B$1005,$B8,'الحركات الشهرية'!$A$6:$A$1005,$C$3)) -> 0 | H8: =IF($B8="","",SUMIFS('الحركات الشهرية'!$E$6:$E$1005,'الحركات الشهرية'!$B$6:$B$1005,$B8,'الحركات الشهرية'!$A$6:$A$1005,$C$3)) -> 0 | I8: =IF($B8="","",MAX(0,F8-G8-H8)) -> 30 | J8: =IF($B8="","",الموظفون!$J8*$I8/cfg_DAYS_M) -> 8500 | K8: =IF($B8="","",الموظفون!$K8*$I8/cfg_DAYS_M) -> 2125 | L8: =IF($B8="","",الموظفون!$L8*$I8/cfg_DAYS_M) -> 850 | M8: =IF($B8="","",الموظفون!$M8*$I8/cfg_DAYS_M) -> 500 | N8: =IF($B8="","",SUMIFS('الحركات الشهرية'!$F$6:$F$1005,'الحركات الشهرية'!$B$6:$B$1005,$B8,'الحركات الشهرية'!$A$6:$A$1005,$C$3)) -> 12 | O8: =IF($B8="","",N8*(الموظفون!$N8+الموظفون!$J8*cfg_OT_P)/cfg_DAYS_M/cfg_HRS) -> 811.25 | P8: =IF($B8="","",SUMIFS('الحركات الشهرية'!$G$6:$G$1005,'الحركات الشهرية'!$B$6:$B$1005,$B8,'الحركات الشهرية'!$A$6:$A$1005,$C$3)) -> 0 | Q8: =IF($B8="","",SUMIFS('الحركات الشهرية'!$H$6:$H$1005,'الحركات الشهرية'!$B$6:$B$1005,$B8,'الحركات الشهرية'!$A$6:$A$1005,$C$3)) -> 0 | R8: =IF($B8="","",SUM(J8:M8)+SUM(O8:Q8)) -> 12786.25 | S8: =IF($B8="","",الموظفون!$Q8*IF(E8="سعودي",cfg_G_SE,cfg_G_NE)*F8/cfg_DAYS_M) -> 0 | T8: =IF($B8="","",SUMIFS('الحركات الشهرية'!$I$6:$I$1005,'الحركات الشهرية'!$B$6:$B$1005,$B8,'الحركات الشهرية'!$A$6:$A$1005,$C$3)) -> 1000 | U8: =IF($B8="","",SUMIFS('الحركات الشهرية'!$J$6:$J$1005,'الحركات الشهرية'!$B$6:$B$1005,$B8,'الحركات الشهرية'!$A$6:$A$1005,$C$3)) -> 0 | V8: =IF($B8="","",SUM(S8:U8)) -> 1000 | W8: =IF($B8="","",R8-V8) -> 11786.25 | X8: =IF($B8="","",الموظفون!$Q8*IF(E8="سعودي",cfg_G_SR,cfg_G_NR)*F8/cfg_DAYS_M) -> 212.5 | Y8: =IF($B8="","",الموظفون!$O8*(cfg_EOS_R1*(MIN(AC8,cfg_EOS_TH)-MIN(AD8,cfg_EOS_TH))+cfg_EOS_R2*(MAX(AC8-cfg_EOS_TH,0)-MAX(AD8-cfg_EOS_TH,0)))) -> 974.58904 | Z8: =IF($B8="","",IF(الموظفون!$R8<>"",الموظفون!$R8,IF(AC8>=cfg_LV_TH,cfg_LV_D2,cfg_LV_D1))/cfg_DAYS_Y*AE8*الموظفون!$P8/cfg_DAYS_M) -> 974.58904 | AA8: =IF($B8="","",IF(AND(الموظفون!$S8="نعم",N(الموظفون!$U8)>0),الموظفون!$T8/الموظفون!$U8*12/cfg_DAYS_Y*AE8,0)) -> 135.89041 | AB8: =IF($B8="","",R8+SUM(X8:AA8)) -> 15083.818 | AC8: =IF($B8="","",MAX(0,IF(OR(الموظفون!$X8="",الموظفون!$X8>$G$3),$G$3,الموظفون!$X8)-الموظفون!$H8+1)/cfg_DAYS_Y) -> 7.4 | AD8: =IF($B8="","",MAX(0,IF(OR(الموظفون!$X8="",الموظفون!$X8>($E$3-1)),($E$3-1),الموظفون!$X8)-الموظفون!$H8+1)/cfg_DAYS_Y) -> 7.3150685 | AE8: =IF($B8="","",MAX(0,IF(OR(الموظفون!$X8="",الموظفون!$X8>$G$3),$G$3,الموظفون!$X8)-MAX($E$3,الموظفون!$H8)+1)) -> 31
A9: =IF($B9="","",الموظفون!$A9) -> 4 | B9: =IF(الموظفون!$B9="","",الموظفون!$B9) -> E004 | C9: =IF($B9="","",الموظفون!$C9) -> نورة خالد الدوسري | D9: =IF($B9="","",الموظفون!$F9) -> الموارد البشرية | E9: =IF($B9="","",الموظفون!$E9) -> سعودي | F9: =IF($B9="","",IF(AE9>=DAY($G$3),cfg_DAYS_M,MIN(AE9,cfg_DAYS_M))) -> 30 | G9: =IF($B9="","",SUMIFS('الحركات الشهرية'!$D$6:$D$1005,'الحركات الشهرية'!$B$6:$B$1005,$B9,'الحركات الشهرية'!$A$6:$A$1005,$C$3)) -> 0 | H9: =IF($B9="","",SUMIFS('الحركات الشهرية'!$E$6:$E$1005,'الحركات الشهرية'!$B$6:$B$1005,$B9,'الحركات الشهرية'!$A$6:$A$1005,$C$3)) -> 0 | I9: =IF($B9="","",MAX(0,F9-G9-H9)) -> 30 | J9: =IF($B9="","",الموظفون!$J9*$I9/cfg_DAYS_M) -> 14000 | K9: =IF($B9="","",الموظفون!$K9*$I9/cfg_DAYS_M) -> 3500 | L9: =IF($B9="","",الموظفون!$L9*$I9/cfg_DAYS_M) -> 1400 | M9: =IF($B9="","",الموظفون!$M9*$I9/cfg_DAYS_M) -> 0 | N9: =IF($B9="","",SUMIFS('الحركات الشهرية'!$F$6:$F$1005,'الحركات الشهرية'!$B$6:$B$1005,$B9,'الحركات الشهرية'!$A$6:$A$1005,$C$3)) -> 0 | O9: =IF($B9="","",N9*(الموظفون!$N9+الموظفون!$J9*cfg_OT_P)/cfg_DAYS_M/cfg_HRS) -> 0 | P9: =IF($B9="","",SUMIFS('الحركات الشهرية'!$G$6:$G$1005,'الحركات الشهرية'!$B$6:$B$1005,$B9,'الحركات الشهرية'!$A$6:$A$1005,$C$3)) -> 0 | Q9: =IF($B9="","",SUMIFS('الحركات الشهرية'!$H$6:$H$1005,'الحركات الشهرية'!$B$6:$B$1005,$B9,'الحركات الشهرية'!$A$6:$A$1005,$C$3)) -> 0 | R9: =IF($B9="","",SUM(J9:M9)+SUM(O9:Q9)) -> 18900 | S9: =IF($B9="","",الموظفون!$Q9*IF(E9="سعودي",cfg_G_SE,cfg_G_NE)*F9/cfg_DAYS_M) -> 1706.25 | T9: =IF($B9="","",SUMIFS('الحركات الشهرية'!$I$6:$I$1005,'الحركات الشهرية'!$B$6:$B$1005,$B9,'الحركات الشهرية'!$A$6:$A$1005,$C$3)) -> 0 | U9: =IF($B9="","",SUMIFS('الحركات الشهرية'!$J$6:$J$1005,'الحركات الشهرية'!$B$6:$B$1005,$B9,'الحركات الشهرية'!$A$6:$A$1005,$C$3)) -> 0 | V9: =IF($B9="","",SUM(S9:U9)) -> 1706.25 | W9: =IF($B9="","",R9-V9) -> 17193.75 | X9: =IF($B9="","",الموظفون!$Q9*IF(E9="سعودي",cfg_G_SR,cfg_G_NR)*F9/cfg_DAYS_M) -> 2056.25 | Y9: =IF($B9="","",الموظفون!$O9*(cfg_EOS_R1*(MIN(AC9,cfg_EOS_TH)-MIN(AD9,cfg_EOS_TH))+cfg_EOS_R2*(MAX(AC9-cfg_EOS_TH,0)-MAX(AD9-cfg_EOS_TH,0)))) -> 1605.2055 | Z9: =IF($B9="","",IF(الموظفون!$R9<>"",الموظفون!$R9,IF(AC9>=cfg_LV_TH,cfg_LV_D2,cfg_LV_D1))/cfg_DAYS_Y*AE9*الموظفون!$P9/cfg_DAYS_M) -> 1605.2055 | AA9: =IF($B9="","",IF(AND(الموظفون!$S9="نعم",N(الموظفون!$U9)>0),الموظفون!$T9/الموظفون!$U9*12/cfg_DAYS_Y*AE9,0)) -> 0 | AB9: =IF($B9="","",R9+SUM(X9:AA9)) -> 24166.661 | AC9: =IF($B9="","",MAX(0,IF(OR(الموظفون!$X9="",الموظفون!$X9>$G$3),$G$3,الموظفون!$X9)-الموظفون!$H9+1)/cfg_DAYS_Y) -> 7.0054795 | AD9: =IF($B9="","",MAX(0,IF(OR(الموظفون!$X9="",الموظفون!$X9>($E$3-1)),($E$3-1),الموظفون!$X9)-الموظفون!$H9+1)/cfg_DAYS_Y) -> 6.9205479 | AE9: =IF($B9="","",MAX(0,IF(OR(الموظفون!$X9="",الموظفون!$X9>$G$3),$G$3,الموظفون!$X9)-MAX($E$3,الموظفون!$H9)+1)) -> 31
A10: =IF($B10="","",الموظفون!$A10) -> 5 | B10: =IF(الموظفون!$B10="","",الموظفون!$B10) -> E005 | C10: =IF($B10="","",الموظفون!$C10) -> راجيش كومار | D10: =IF($B10="","",الموظفون!$F10) -> تقنية المعلومات | E10: =IF($B10="","",الموظفون!$E10) -> غير سعودي | F10: =IF($B10="","",IF(AE10>=DAY($G$3),cfg_DAYS_M,MIN(AE10,cfg_DAYS_M))) -> 30 | G10: =IF($B10="","",SUMIFS('الحركات الشهرية'!$D$6:$D$1005,'الحركات الشهرية'!$B$6:$B$1005,$B10,'الحركات الشهرية'!$A$6:$A$1005,$C$3)) -> 0 | H10: =IF($B10="","",SUMIFS('الحركات الشهرية'!$E$6:$E$1005,'الحركات الشهرية'!$B$6:$B$1005,$B10,'الحركات الشهرية'!$A$6:$A$1005,$C$3)) -> 0 | I10: =IF($B10="","",MAX(0,F10-G10-H10)) -> 30 | J10: =IF($B10="","",الموظفون!$J10*$I10/cfg_DAYS_M) -> 9000 | K10: =IF($B10="","",الموظفون!$K10*$I10/cfg_DAYS_M) -> 2250 | L10: =IF($B10="","",الموظفون!$L10*$I10/cfg_DAYS_M) -> 900 | M10: =IF($B10="","",الموظفون!$M10*$I10/cfg_DAYS_M) -> 700 | N10: =IF($B10="","",SUMIFS('الحركات الشهرية'!$F$6:$F$1005,'الحركات الشهرية'!$B$6:$B$1005,$B10,'الحركات الشهرية'!$A$6:$A$1005,$C$3)) -> 0 | O10: =IF($B10="","",N10*(الموظفون!$N10+الموظفون!$J10*cfg_OT_P)/cfg_DAYS_M/cfg_HRS) -> 0 | P10: =IF($B10="","",SUMIFS('الحركات الشهرية'!$G$6:$G$1005,'الحركات الشهرية'!$B$6:$B$1005,$B10,'الحركات الشهرية'!$A$6:$A$1005,$C$3)) -> 0 | Q10: =IF($B10="","",SUMIFS('الحركات الشهرية'!$H$6:$H$1005,'الحركات الشهرية'!$B$6:$B$1005,$B10,'الحركات الشهرية'!$A$6:$A$1005,$C$3)) -> 0 | R10: =IF($B10="","",SUM(J10:M10)+SUM(O10:Q10)) -> 12850 | S10: =IF($B10="","",الموظفون!$Q10*IF(E10="سعودي",cfg_G_SE,cfg_G_NE)*F10/cfg_DAYS_M) -> 0 | T10: =IF($B10="","",SUMIFS('الحركات الشهرية'!$I$6:$I$1005,'الحركات الشهرية'!$B$6:$B$1005,$B10,'الحركات الشهرية'!$A$6:$A$1005,$C$3)) -> 0 | U10: =IF($B10="","",SUMIFS('الحركات الشهرية'!$J$6:$J$1005,'الحركات الشهرية'!$B$6:$B$1005,$B10,'الحركات الشهرية'!$A$6:$A$1005,$C$3)) -> 0 | V10: =IF($B10="","",SUM(S10:U10)) -> 0 | W10: =IF($B10="","",R10-V10) -> 12850 | X10: =IF($B10="","",الموظفون!$Q10*IF(E10="سعودي",cfg_G_SR,cfg_G_NR)*F10/cfg_DAYS_M) -> 225 | Y10: =IF($B10="","",الموظفون!$O10*(cfg_EOS_R1*(MIN(AC10,cfg_EOS_TH)-MIN(AD10,cfg_EOS_TH))+cfg_EOS_R2*(MAX(AC10-cfg_EOS_TH,0)-MAX(AD10-cfg_EOS_TH,0)))) -> 1031.9178 | Z10: =IF($B10="","",IF(الموظفون!$R10<>"",الموظفون!$R10,IF(AC10>=cfg_LV_TH,cfg_LV_D2,cfg_LV_D1))/cfg_DAYS_Y*AE10*الموظفون!$P10/cfg_DAYS_M) -> 1031.9178 | AA10: =IF($B10="","",IF(AND(الموظفون!$S10="نعم",N(الموظفون!$U10)>0),الموظفون!$T10/الموظفون!$U10*12/cfg_DAYS_Y*AE10,0)) -> 237.80822 | AB10: =IF($B10="","",R10+SUM(X10:AA10)) -> 15376.644 | AC10: =IF($B10="","",MAX(0,IF(OR(الموظفون!$X10="",الموظفون!$X10>$G$3),$G$3,الموظفون!$X10)-الموظفون!$H10+1)/cfg_DAYS_Y) -> 5.8109589 | AD10: =IF($B10="","",MAX(0,IF(OR(الموظفون!$X10="",الموظفون!$X10>($E$3-1)),($E$3-1),الموظفون!$X10)-الموظفون!$H10+1)/cfg_DAYS_Y) -> 5.7260274 | AE10: =IF($B10="","",MAX(0,IF(OR(الموظفون!$X10="",الموظفون!$X10>$G$3),$G$3,الموظفون!$X10)-MAX($E$3,الموظفون!$H10)+1)) -> 31
A11: =IF($B11="","",الموظفون!$A11) -> 6 | B11: =IF(الموظفون!$B11="","",الموظفون!$B11) -> E006 | C11: =IF($B11="","",الموظفون!$C11) -> فهد ناصر الشمري | D11: =IF($B11="","",الموظفون!$F11) -> المبيعات | E11: =IF($B11="","",الموظفون!$E11) -> سعودي | F11: =IF($B11="","",IF(AE11>=DAY($G$3),cfg_DAYS_M,MIN(AE11,cfg_DAYS_M))) -> 30 | G11: =IF($B11="","",SUMIFS('الحركات الشهرية'!$D$6:$D$1005,'الحركات الشهرية'!$B$6:$B$1005,$B11,'الحركات الشهرية'!$A$6:$A$1005,$C$3)) -> 0 | H11: =IF($B11="","",SUMIFS('الحركات الشهرية'!$E$6:$E$1005,'الحركات الشهرية'!$B$6:$B$1005,$B11,'الحركات الشهرية'!$A$6:$A$1005,$C$3)) -> 0 | I11: =IF($B11="","",MAX(0,F11-G11-H11)) -> 30 | J11: =IF($B11="","",الموظفون!$J11*$I11/cfg_DAYS_M) -> 13000 | K11: =IF($B11="","",الموظفون!$K11*$I11/cfg_DAYS_M) -> 3250 | L11: =IF($B11="","",الموظفون!$L11*$I11/cfg_DAYS_M) -> 1300 | M11: =IF($B11="","",الموظفون!$M11*$I11/cfg_DAYS_M) -> 2500 | N11: =IF($B11="","",SUMIFS('الحركات الشهرية'!$F$6:$F$1005,'الحركات الشهرية'!$B$6:$B$1005,$B11,'الحركات الشهرية'!$A$6:$A$1005,$C$3)) -> 0 | O11: =IF($B11="","",N11*(الموظفون!$N11+الموظفون!$J11*cfg_OT_P)/cfg_DAYS_M/cfg_HRS) -> 0 | P11: =IF($B11="","",SUMIFS('الحركات الشهرية'!$G$6:$G$1005,'الحركات الشهرية'!$B$6:$B$1005,$B11,'الحركات الشهرية'!$A$6:$A$1005,$C$3)) -> 0 | Q11: =IF($B11="","",SUMIFS('الحركات الشهرية'!$H$6:$H$1005,'الحركات الشهرية'!$B$6:$B$1005,$B11,'الحركات الشهرية'!$A$6:$A$1005,$C$3)) -> 0 | R11: =IF($B11="","",SUM(J11:M11)+SUM(O11:Q11)) -> 20050 | S11: =IF($B11="","",الموظفون!$Q11*IF(E11="سعودي",cfg_G_SE,cfg_G_NE)*F11/cfg_DAYS_M) -> 1584.375 | T11: =IF($B11="","",SUMIFS('الحركات الشهرية'!$I$6:$I$1005,'الحركات الشهرية'!$B$6:$B$1005,$B11,'الحركات الشهرية'!$A$6:$A$1005,$C$3)) -> 0 | U11: =IF($B11="","",SUMIFS('الحركات الشهرية'!$J$6:$J$1005,'الحركات الشهرية'!$B$6:$B$1005,$B11,'الحركات الشهرية'!$A$6:$A$1005,$C$3)) -> 0 | V11: =IF($B11="","",SUM(S11:U11)) -> 1584.375 | W11: =IF($B11="","",R11-V11) -> 18465.625 | X11: =IF($B11="","",الموظفون!$Q11*IF(E11="سعودي",cfg_G_SR,cfg_G_NR)*F11/cfg_DAYS_M) -> 1909.375 | Y11: =IF($B11="","",الموظفون!$O11*(cfg_EOS_R1*(MIN(AC11,cfg_EOS_TH)-MIN(AD11,cfg_EOS_TH))+cfg_EOS_R2*(MAX(AC11-cfg_EOS_TH,0)-MAX(AD11-cfg_EOS_TH,0)))) -> 1490.5479 | Z11: =IF($B11="","",IF(الموظفون!$R11<>"",الموظفون!$R11,IF(AC11>=cfg_LV_TH,cfg_LV_D2,cfg_LV_D1))/cfg_DAYS_Y*AE11*الموظفون!$P11/cfg_DAYS_M) -> 1490.5479 | AA11: =IF($B11="","",IF(AND(الموظفون!$S11="نعم",N(الموظفون!$U11)>0),الموظفون!$T11/الموظفون!$U11*12/cfg_DAYS_Y*AE11,0)) -> 0 | AB11: =IF($B11="","",R11+SUM(X11:AA11)) -> 24940.471 | AC11: =IF($B11="","",MAX(0,IF(OR(الموظفون!$X11="",الموظفون!$X11>$G$3),$G$3,الموظفون!$X11)-الموظفون!$H11+1)/cfg_DAYS_Y) -> 8.2465753 | AD11: =IF($B11="","",MAX(0,IF(OR(الموظفون!$X11="",الموظفون!$X11>($E$3-1)),($E$3-1),الموظفون!$X11)-الموظفون!$H11+1)/cfg_DAYS_Y) -> 8.1616438 | AE11: =IF($B11="","",MAX(0,IF(OR(الموظفون!$X11="",الموظفون!$X11>$G$3),$G$3,الموظفون!$X11)-MAX($E$3,الموظفون!$H11)+1)) -> 31
