Workbook

Sheet الرئيسية
B1: 🏢 نظام الرواتب والمخصصات المتكامل 🔒 نسخة تجريبية
B2: ="🛒 نسخة تجريبية — للنسخة الكاملة اضغط هنا ← accopro.net | "&cfg_CO&" | السنة المالية "&cfg_FY&" | شهر التقرير: "&INDEX(L_MONTH,cfg_VAL_M)&" | المبالغ بـ "&cfg_CUR -> 🛒 نسخة تجريبية — للنسخة الكاملة اضغط هنا ← accopro.net | شركة النخبة للتجارة والمقاولات | السنة المالية 2026 | شهر التقرير: سبتمبر | المبالغ بـ ريال سعودي
B3: 🛒 نسخة تجريبية كاملة الوظائف بخانات محدودة — اشترِ النسخة الكاملة من accopro.net (اضغط هنا)
B5: 🧭 خطوات العمل | F5: 📅 مسيرات الأشهر
B6: # | C6: الورقة | D6: ماذا تفعل | F6: مسير يناير | G6: مسير يوليو
B7: 1 | C7: الإعدادات | D7: مرة واحدة: اسم المنشأة والسنة وشهر التقرير، النسب النظامية، رسوم الإقامة ورخصة العمل، وأنواع الإجازات. | F7: مسير فبراير | G7: مسير أغسطس
B8: 2 | C8: الموظفون | D8: سجّل الموظفين: الرواتب والبدلات، الإقامة ورخصة العمل وتكلفتها، التأمين الطبي، التذاكر، والأرصدة الافتتاحية. | F8: مسير مارس | G8: مسير سبتمبر
B9: 3 | C9: سجل الإجازات والحالات | D9: عند أي إجازة أو إيقاف: سجّل النوع ومن/إلى — المسير يخصم الأيام تلقائياً ولا حاجة لحذف الموظف. | F9: مسير أبريل | G9: مسير أكتوبر
B10: 4 | C10: الحركات الشهرية | D10: كل شهر: الغياب والإضافي والمكافآت والسلف والجزاءات والتذاكر ومستحقات نهاية الخدمة. | F10: مسير مايو | G10: مسير نوفمبر
B11: 5 | C11: مسير يناير | D11: راجع مسير الشهر (12 ورقة جاهزة) — عمود «الوضع خلال الشهر» يوضح حالة كل موظف. | F11: مسير يونيو | G11: مسير ديسمبر
B12: 6 | C12: الإقامات ورخص العمل | D12: تابع انتهاء الإقامات ورخص العمل وتكلفتها وتجديداتها المتوقعة.
B13: 7 | C13: مخصص نهاية الخدمة | D13: المخصصات كما في شهر التقرير: نهاية الخدمة ← الإجازات ← التذاكر مع الفحوصات. | F13: 📅 الملخص الشهري | G13: 📑 ملخص الموظفين
B14: 8 | C14: قيود الرواتب | D14: انسخ القيود الشهرية المتوازنة إلى نظامك المحاسبي. | F14: 🌴 مخصص الإجازات | G14: ✈ مخصص التذاكر
B15: 9 | C15: قسيمة الراتب | D15: اطبع قسيمة راتب أي موظف لأي شهر.
B16: 10 | C16: لوحة التحكم | D16: تابع المؤشرات والتنبيهات والرسوم البيانية.
B18: 🎨 دليل الألوان والرموز
C19: 123 | D19: خلية إدخال — اكتب فيها (خط أزرق على خلفية صفراء).
C20: ƒx معادلة | D20: خلية معادلة — لا تعدّلها؛ تتحدث تلقائياً.
C21: ✔ سليم | D21: فحص ناجح / على رأس العمل.
C22: ✈ إجازة | D22: في إجازة أو إيقاف (من سجل الإجازات).
C23: ⚠ تنبيه | D23: يحتاج مراجعة.
C24: ✖ خطأ | D24: خطأ يجب تصحيحه / منتهي.
B26: 🔗 خريطة الترابط
B27: الإعدادات ➜ الموظفون + سجل الإجازات والحالات + الحركات الشهرية ➜ مسيرات 12 شهراً ➜ الملخص الشهري + ملخص الموظفين + الإقامات ورخص العمل ➜ المخصصات (نهاية الخدمة / الإجازات / التذاكر) ➜ القيود المحاسبية ➜ قسيمة الراتب + لوحة التحكم
B29: ❓ أمثلة سريعة
B30: موظف سافر إجازة بدون راتب شهرين | D30: سجل الإجازات: النوع «إجازة بدون راتب» + من/إلى ← يُخصم من المسيرين تلقائياً، ولا تُحتسب المدة في الخدمة ولا تُكتسب عنها إجازة أو تذكرة.
B31: موظف صُرف راتب إجازته قبل السفر | D31: النوع «إجازة سنوية (راتب مقدم قبل السفر)» ← يُصرف المبلغ في شهر البداية، ولا راتب عن أيام الإجازة في المسيرات، ويُخصم الرصيد.
B32: موظف موقوف أو متغيب (بلاغ) | D32: النوع «إيقاف عن العمل» أو «انقطاع عن العمل» ← يتوقف الراتب في الأيام المحددة؛ ويظهر «⛔ بدون راتب» في المسير.
B33: إجازة مرضية بنسبة خاصة | D33: اختر النوع المرضي، أو اكتب النسبة في عمود «نسبة أجر مخصصة» (مثلاً 50%).
B34: موظف ترك العمل نهائياً | D34: ورقة الموظفين: تاريخ انتهاء الخدمة + السبب ← يتوقف كل شيء بعده، وتُحسب المكافأة والتسوية.
B36: البيانات الحالية (12 موظفاً وإجازاتهم وحركاتهم) أمثلة توضيحية لإظهار طريقة العمل — امسح خلايا الإدخال الصفراء في «الموظفون» و«سجل الإجازات» و«الحركات الشهرية» وأدخل بياناتك. يستوعب الملف 100 موظف و500 إجازة و1,000 حركة. الأحكام مبنية على نظام العمل السعودي (المواد 84، 85، 98، 107، 109، 113، 116، 117) ونظام التأمينات الاجتماعية، وجميع النسب والرسوم قابلة للتعديل من الإعدادات.

Sheet 🛒 النسخة الكاملة
B1: 🛒 احصل على النسخة الكاملة من نظام الرواتب والمخصصات
B2: النسخة التجريبية تعمل بكامل المعادلات والتقارير، لكن الخلايا مقفلة ما عدا خانات التجربة: 5 موظفين، 10 إجازات، 20 حركة، وشهر التقرير.
B4: 🛒 اضغط هنا لشراء النسخة الكاملة ← https://accopro.net/
B7: الميزة | C7: النسخة المجانية | D7: النسخة الكاملة
B8: مسير رواتب 12 شهراً بكل المعادلات | C8: ✔ يعمل | D8: ✔ يعمل
B9: عدد الموظفين القابل للإدخال والتعديل | C9: 🧪 5 موظفين | D9: ✔ حتى 100 موظف
B10: سجل الإجازات والإيقاف ووقف الراتب بالتواريخ | C10: 🧪 10 سجلات | D10: ✔ حتى 500 سجل
B11: الحركات الشهرية (غياب، إضافي، سلف، مكافآت...) | C11: 🧪 20 حركة | D11: ✔ حتى 1,000 حركة
B12: الإقامات ورخص العمل وتكلفتها وتنبيهات الانتهاء | C12: ✔ يعمل | D12: ✔ يعمل
B13: مخصصات نهاية الخدمة والإجازات والتذاكر | C13: ✔ يعمل | D13: ✔ يعمل
B14: القيود المحاسبية الشهرية ولوحة التحكم | C14: ✔ يعمل | D14: ✔ يعمل
B15: قسيمة الراتب لأي موظف وأي شهر | C15: ✔ يعمل | D15: ✔ يعمل
B16: تغيير شهر التقرير | C16: ✔ متاح | D16: ✔ متاح
B17: تعديل اسم المنشأة والسنة والنسب والرسوم وأنواع الإجازات | C17: ✖ مقفل | D17: ✔
B18: رؤية المعادلات وتعديلها وتخصيص الملف | C18: ✖ مخفية ومقفلة | D18: ✔ مفتوحة بالكامل
... B20: الدعم الفني والتحديثات | C20: ✖ | D20: ✔
B22: 🛒 اشترِ الآن من accopro.net
B25: 🏠 العودة إلى الرئيسية

Sheet لوحة التحكم
B1: 📊 لوحة التحكم — الرواتب والمخصصات والتكاليف الحكومية 🔒 نسخة تجريبية
B2: ="🛒 نسخة تجريبية — للنسخة الكاملة اضغط هنا ← accopro.net | "&cfg_CO&" | السنة المالية "&cfg_FY&" | شهر التقرير: "&INDEX(L_MONTH,cfg_VAL_M)&" | المبالغ بـ "&cfg_CUR -> 🛒 نسخة تجريبية — للنسخة الكاملة اضغط هنا ← accopro.net | شركة النخبة للتجارة والمقاولات | السنة المالية 2026 | شهر التقرير: سبتمبر | المبالغ بـ ريال سعودي
B3: 🏠 الرئيسية | C3: ⚙ الإعدادات | D3: 👥 الموظفون | E3: 🌴 سجل الإجازات | F3: ✍ الحركات | G3: 🪪 الإقامات | H3: 📅 الملخص الشهري | J3: شهر التقرير ← | K3: =INDEX(L_MONTH,cfg_VAL_M)&" "&cfg_FY -> سبتمبر 2026 | M3: 🛒 اشترِ الكاملة
B5: 👥 القوى العاملة
B6: الموظفون على رأس العمل | E6: في إجازة / إيقاف حالياً | H6: نسبة التوطين (السعودة) | K6: متوسط إجمالي الراتب الشهري
B7: =COUNTIF(الموظفون!$AG$6:$AG$105,"✔ على رأس العمل") -> 11 | E7: =COUNTIF(الموظفون!$AH$6:$AH$105,"✈*") -> 1 | H7: =IFERROR(COUNTIFS(الموظفون!$AG$6:$AG$105,"✔ على رأس العمل",الموظفون!$E$6:$E$105,"سعودي")/B7,0) -> 0.63636364 | K7: =IFERROR(AVERAGEIF(الموظفون!$AG$6:$AG$105,"✔ على رأس العمل",الموظفون!$P$6:$P$105),0) -> 17688.636
B9: ="💵 الرواتب من بداية السنة حتى "&INDEX(L_MONTH,cfg_VAL_M) -> 💵 الرواتب من بداية السنة حتى سبتمبر
B10: إجمالي المستحقات | E10: صافي الرواتب المدفوعة | H10: التأمينات (موظف + منشأة) | K10: إجمالي تكلفة العمالة
B11: ='الملخص الشهري'!K19 -> 1763573.9 | E11: ='الملخص الشهري'!N19 -> 1650693.6 | H11: ='الملخص الشهري'!L19+'الملخص الشهري'!O19 -> 245743.12 | K11: ='الملخص الشهري'!U19 -> 2227092.4
B13: 🪪 الإقامات ورخص العمل والتأمين الطبي
B14: المحمّل حتى تاريخه (إقامة + رخص + طبي) | E14: التكلفة السنوية المتوقعة | H14: تجديدات متوقعة خلال فترة التنبيه | K14: متوسط تكلفة الموظف الشهرية الكاملة
B15: ='الملخص الشهري'!S19+'الملخص الشهري'!T19 -> 63531.667 | E15: ='الإقامات ورخص العمل'!R106 -> 77600 | H15: ='الإقامات ورخص العمل'!U106 -> 20500 | K15: =IFERROR('الملخص الشهري'!U19/SUMIF('الملخص الشهري'!$C$6:$C$17,"<="&cfg_VAL_M,'الملخص الشهري'!$D$6:$D$17),0) -> 21834.239
B17: ="🏦 أرصدة المخصصات كما في "&TEXT(cfg_VAL_DATE,"yyyy/mm/dd") -> 🏦 أرصدة المخصصات كما في 2026/09/30
B18: مخصص نهاية الخدمة | E18: مخصص الإجازات | H18: مخصص تذاكر السفر | K18: إجمالي المخصصات
B19: ='مخصص نهاية الخدمة'!S106 -> 1161402.2 | E19: ='مخصص الإجازات'!P106 -> 151856.45 | H19: ='مخصص التذاكر'!N106 -> 7324.1096 | K19: =B19+E19+H19 -> 1320582.8
B21: 🔔 تنبيهات وفحوصات الترابط | I21: 🌍 التوزيع حسب الفئة
B22: إقامات منتهية أو تنتهي قريباً | F22: =COUNTIF('الإقامات ورخص العمل'!$J$6:$J$105,"✖*")+COUNTIF('الإقامات ورخص العمل'!$J$6:$J$105,"⚠*") -> 2 | G22: =IF(F22=0,"✔","⚠") -> ⚠ | I22: الفئة | J22: العدد | K22: النسبة | L22: الرواتب الشهرية
B23: رخص عمل منتهية أو تنتهي قريباً | F23: =COUNTIF('الإقامات ورخص العمل'!$M$6:$M$105,"✖*")+COUNTIF('الإقامات ورخص العمل'!$M$6:$M$105,"⚠*") -> 2 | G23: =IF(F23=0,"✔","⚠") -> ⚠ | I23: سعودي | J23: =COUNTIFS(الموظفون!$AG$6:$AG$105,"✔ على رأس العمل",الموظفون!$E$6:$E$105,I23) -> 7 | K23: =IFERROR(J23/SUM($J$23:$J$24),0) -> 0.63636364 | L23: =SUMIFS(الموظفون!$P$6:$P$105,الموظفون!$AG$6:$AG$105,"✔ على رأس العمل",الموظفون!$E$6:$E$105,I23) -> 145025
B24: أخطاء أو تداخل في سجل الإجازات | F24: =COUNTIF('سجل الإجازات والحالات'!$P$6:$P$505,"✖*")+COUNTIF('سجل الإجازات والحالات'!$P$6:$P$505,"⚠*") -> 0 | G24: =IF(F24=0,"✔","⚠") -> ✔ | I24: غير سعودي | J24: =COUNTIFS(الموظفون!$AG$6:$AG$105,"✔ على رأس العمل",الموظفون!$E$6:$E$105,I24) -> 4 | K24: =IFERROR(J24/SUM($J$23:$J$24),0) -> 0.36363636 | L24: =SUMIFS(الموظفون!$P$6:$P$105,الموظفون!$AG$6:$AG$105,"✔ على رأس العمل",الموظفون!$E$6:$E$105,I24) -> 49550
B25: موظفون منتهية خدماتهم بمستحقات لم تُصرف | F25: =COUNTIF('مخصص نهاية الخدمة'!$T$6:$T$105,"⚠*") -> 0 | G25: =IF(F25=0,"✔","⚠") -> ✔
B26: أرصدة إجازات سالبة أو مرتفعة | F26: =COUNTIF('مخصص الإجازات'!$S$6:$S$105,"✖*")+COUNTIF('مخصص الإجازات'!$S$6:$S$105,"⚠ رصيد مرتفع*") -> 0 | G26: =IF(F26=0,"✔","⚠") -> ✔
B27: تذاكر مستحقة للصرف | F27: =COUNTIF('مخصص التذاكر'!$P$6:$P$105,"⚠ تذكرة*") -> 0 | G27: =IF(F27=0,"✔","⚠") -> ✔
B28: حركات برقم وظيفي غير صحيح | F28: =COUNTIF('الحركات الشهرية'!$C$6:$C$1005,"✖*")+COUNTIF('سجل الإجازات والحالات'!$C$6:$C$505,"✖*") -> 0 | G28: =IF(F28=0,"✔","⚠") -> ✔
B29: رواتب صافية بالسالب (كل الأشهر) | F29: =COUNTIF('مسير يناير'!$Y$6:$Y$105,"<0")+COUNTIF('مسير فبراير'!$Y$6:$Y$105,"<0")+COUNTIF('مسير مارس'!$Y$6:$Y$105,"<0")+COUNTIF('مسير أبريل'!$Y$6:$Y$105,"<0")+COUNTIF('مسير مايو'!$Y$6:$Y$105,"<0")+COUNTIF('مسير يونيو'!$Y$6:$Y$105,"<0")+COUNTIF('مسير يوليو'!$Y$6:$Y$105,"<0")+COUNTIF('مسير أغسطس'!$Y$6:$Y$105,"<0")+COUNTIF('مسير سبتمبر'!$Y$6:$Y$105,"<0")+COUNTIF('مسير أكتوبر'!$Y$6:$Y$105,"<0")+COUNTIF('مسير نوفمبر'!$Y$6:$Y$105,"<0")+COUNTIF('مسير ديسمبر'!$Y$6:$Y$105,"<0") -> 0 | G29: =IF(F29=0,"✔","⚠") -> ✔
B30: توازن قيود الرواتب (حتى شهر التقرير) | F30: ='قيود الرواتب'!$R$42 -> ✔ متوازن
B38: ="🏢 تحليل التكلفة حسب القسم حتى "&INDEX(L_MONTH,cfg_VAL_M) -> 🏢 تحليل التكلفة حسب القسم حتى سبتمبر
B39: القسم | C39: عدد الموظفين | D39: الرواتب الشهرية | E39: المستحقات حتى تاريخه | F39: التكلفة الكاملة حتى تاريخه | G39: النسبة من التكلفة
B40: =IF(INDEX(L_DEPT,1)="","",INDEX(L_DEPT,1)) -> الإدارة العليا | C40: =IF(B40="","",COUNTIFS(الموظفون!$AG$6:$AG$105,"✔ على رأس العمل",الموظفون!$F$6:$F$105,B40)) -> 1 | D40: =IF(B40="","",SUMIFS(الموظفون!$P$6:$P$105,الموظفون!$AG$6:$AG$105,"✔ على رأس العمل",الموظفون!$F$6:$F$105,B40)) -> 40800 | E40: =IF(B40="","",SUMIF('ملخص الموظفين السنوي'!$D$6:$D$105,B40,'ملخص الموظفين السنوي'!$R$6:$R$105)) -> 367200 | F40: =IF(B40="","",SUMIF('ملخص الموظفين السنوي'!$D$6:$D$105,B40,'ملخص الموظفين السنوي'!$AF$6:$AF$105)) -> 464357.16 | G40: =IF(B40="","",IFERROR(F40/SUM($F$40:$F$54),0)) -> 0.20850377
B41: =IF(INDEX(L_DEPT,2)="","",INDEX(L_DEPT,2)) -> المالية | C41: =IF(B41="","",COUNTIFS(الموظفون!$AG$6:$AG$105,"✔ على رأس العمل",الموظفون!$F$6:$F$105,B41)) -> 3 | D41: =IF(B41="","",SUMIFS(الموظفون!$P$6:$P$105,الموظفون!$AG$6:$AG$105,"✔ على رأس العمل",الموظفون!$F$6:$F$105,B41)) -> 47400 | E41: =IF(B41="","",SUMIF('ملخص الموظفين السنوي'!$D$6:$D$105,B41,'ملخص الموظفين السنوي'!$R$6:$R$105)) -> 426939.58 | F41: =IF(B41="","",SUMIF('ملخص الموظفين السنوي'!$D$6:$D$105,B41,'ملخص الموظفين السنوي'!$AF$6:$AF$105)) -> 540247.26 | G41: =IF(B41="","",IFERROR(F41/SUM($F$40:$F$54),0)) -> 0.24257964
B42: =IF(INDEX(L_DEPT,3)="","",INDEX(L_DEPT,3)) -> الموارد البشرية | C42: =IF(B42="","",COUNTIFS(الموظفون!$AG$6:$AG$105,"✔ على رأس العمل",الموظفون!$F$6:$F$105,B42)) -> 1 | D42: =IF(B42="","",SUMIFS(الموظفون!$P$6:$P$105,الموظفون!$AG$6:$AG$105,"✔ على رأس العمل",الموظفون!$F$6:$F$105,B42)) -> 18900 | E42: =IF(B42="","",SUMIF('ملخص الموظفين السنوي'!$D$6:$D$105,B42,'ملخص الموظفين السنوي'!$R$6:$R$105)) -> 170100 | F42: =IF(B42="","",SUMIF('ملخص الموظفين السنوي'!$D$6:$D$105,B42,'ملخص الموظفين السنوي'!$AF$6:$AF$105)) -> 219578.58 | G42: =IF(B42="","",IFERROR(F42/SUM($F$40:$F$54),0)) -> 0.098594285
B43: =IF(INDEX(L_DEPT,4)="","",INDEX(L_DEPT,4)) -> المبيعات | C43: =IF(B43="","",COUNTIFS(الموظفون!$AG$6:$AG$105,"✔ على رأس العمل",الموظفون!$F$6:$F$105,B43)) -> 2 | D43: =IF(B43="","",SUMIFS(الموظفون!$P$6:$P$105,الموظفون!$AG$6:$AG$105,"✔ على رأس العمل",الموظفون!$F$6:$F$105,B43)) -> 32200 | E43: =IF(B43="","",SUMIF('ملخص الموظفين السنوي'!$D$6:$D$105,B43,'ملخص الموظفين السنوي'!$R$6:$R$105)) -> 253744.58 | F43: =IF(B43="","",SUMIF('ملخص الموظفين السنوي'!$D$6:$D$105,B43,'ملخص الموظفين السنوي'!$AF$6:$AF$105)) -> 313995.81 | G43: =IF(B43="","",IFERROR(F43/SUM($F$40:$F$54),0)) -> 0.14098913
B44: =IF(INDEX(L_DEPT,5)="","",INDEX(L_DEPT,5)) -> العمليات | C44: =IF(B44="","",COUNTIFS(الموظفون!$AG$6:$AG$105,"✔ على رأس العمل",الموظفون!$F$6:$F$105,B44)) -> 1 | D44: =IF(B44="","",SUMIFS(الموظفون!$P$6:$P$105,الموظفون!$AG$6:$AG$105,"✔ على رأس العمل",الموظفون!$F$6:$F$105,B44)) -> 9075 | E44: =IF(B44="","",SUMIF('ملخص الموظفين السنوي'!$D$6:$D$105,B44,'ملخص الموظفين السنوي'!$R$6:$R$105)) -> 130896.84 | F44: =IF(B44="","",SUMIF('ملخص الموظفين السنوي'!$D$6:$D$105,B44,'ملخص الموظفين السنوي'!$AF$6:$AF$105)) -> 169460.2 | G44: =IF(B44="","",IFERROR(F44/SUM($F$40:$F$54),0)) -> 0.076090334
B45: =IF(INDEX(L_DEPT,6)="","",INDEX(L_DEPT,6)) -> تقنية المعلومات | C45: =IF(B45="","",COUNTIFS(الموظفون!$AG$6:$AG$105,"✔ على رأس العمل",الموظفون!$F$6:$F$105,B45)) -> 2 | D45: =IF(B45="","",SUMIFS(الموظفون!$P$6:$P$105,الموظفون!$AG$6:$AG$105,"✔ على رأس العمل",الموظفون!$F$6:$F$105,B45)) -> 30550 | E45: =IF(B45="","",SUMIF('ملخص الموظفين السنوي'!$D$6:$D$105,B45,'ملخص الموظفين السنوي'!$R$6:$R$105)) -> 272961.67 | F45: =IF(B45="","",SUMIF('ملخص الموظفين السنوي'!$D$6:$D$105,B45,'ملخص الموظفين السنوي'!$AF$6:$AF$105)) -> 336946.04 | G45: =IF(B45="","",IFERROR(F45/SUM($F$40:$F$54),0)) -> 0.15129415
B46: =IF(INDEX(L_DEPT,7)="","",INDEX(L_DEPT,7)) -> المشاريع | C46: =IF(B46="","",COUNTIFS(الموظفون!$AG$6:$AG$105,"✔ على رأس العمل",الموظفون!$F$6:$F$105,B46)) -> 1 | D46: =IF(B46="","",SUMIFS(الموظفون!$P$6:$P$105,الموظفون!$AG$6:$AG$105,"✔ على رأس العمل",الموظفون!$F$6:$F$105,B46)) -> 15650 | E46: =IF(B46="","",SUMIF('ملخص الموظفين السنوي'!$D$6:$D$105,B46,'ملخص الموظفين السنوي'!$R$6:$R$105)) -> 141731.25 | F46: =IF(B46="","",SUMIF('ملخص الموظفين السنوي'!$D$6:$D$105,B46,'ملخص الموظفين السنوي'!$AF$6:$AF$105)) -> 182507.31 | G46: =IF(B46="","",IFERROR(F46/SUM($F$40:$F$54),0)) -> 0.081948695
B47: =IF(INDEX(L_DEPT,8)="","",INDEX(L_DEPT,8)) | C47: =IF(B47="","",COUNTIFS(الموظفون!$AG$6:$AG$105,"✔ على رأس العمل",الموظفون!$F$6:$F$105,B47)) | D47: =IF(B47="","",SUMIFS(الموظفون!$P$6:$P$105,الموظفون!$AG$6:$AG$105,"✔ على رأس العمل",الموظفون!$F$6:$F$105,B47)) | E47: =IF(B47="","",SUMIF('ملخص الموظفين السنوي'!$D$6:$D$105,B47,'ملخص الموظفين السنوي'!$R$6:$R$105)) | F47: =IF(B47="","",SUMIF('ملخص الموظفين السنوي'!$D$6:$D$105,B47,'ملخص الموظفين السنوي'!$AF$6:$AF$105)) | G47: =IF(B47="","",IFERROR(F47/SUM($F$40:$F$54),0))
B48: =IF(INDEX(L_DEPT,9)="","",INDEX(L_DEPT,9)) | C48: =IF(B48="","",COUNTIFS(الموظفون!$AG$6:$AG$105,"✔ على رأس العمل",الموظفون!$F$6:$F$105,B48)) | D48: =IF(B48="","",SUMIFS(الموظفون!$P$6:$P$105,الموظفون!$AG$6:$AG$105,"✔ على رأس العمل",الموظفون!$F$6:$F$105,B48)) | E48: =IF(B48="","",SUMIF('ملخص الموظفين السنوي'!$D$6:$D$105,B48,'ملخص الموظفين السنوي'!$R$6:$R$105)) | F48: =IF(B48="","",SUMIF('ملخص الموظفين السنوي'!$D$6:$D$105,B48,'ملخص الموظفين السنوي'!$AF$6:$AF$105)) | G48: =IF(B48="","",IFERROR(F48/SUM($F$40:$F$54),0))
B49: =IF(INDEX(L_DEPT,10)="","",INDEX(L_DEPT,10)) | C49: =IF(B49="","",COUNTIFS(الموظفون!$AG$6:$AG$105,"✔ على رأس العمل",الموظفون!$F$6:$F$105,B49)) | D49: =IF(B49="","",SUMIFS(الموظفون!$P$6:$P$105,الموظفون!$AG$6:$AG$105,"✔ على رأس العمل",الموظفون!$F$6:$F$105,B49)) | E49: =IF(B49="","",SUMIF('ملخص الموظفين السنوي'!$D$6:$D$105,B49,'ملخص الموظفين السنوي'!$R$6:$R$105)) | F49: =IF(B49="","",SUMIF('ملخص الموظفين السنوي'!$D$6:$D$105,B49,'ملخص الموظفين السنوي'!$AF$6:$AF$105)) | G49: =IF(B49="","",IFERROR(F49/SUM($F$40:$F$54),0))
B50: =IF(INDEX(L_DEPT,11)="","",INDEX(L_DEPT,11)) | C50: =IF(B50="","",COUNTIFS(الموظفون!$AG$6:$AG$105,"✔ على رأس العمل",الموظفون!$F$6:$F$105,B50)) | D50: =IF(B50="","",SUMIFS(الموظفون!$P$6:$P$105,الموظفون!$AG$6:$AG$105,"✔ على رأس العمل",الموظفون!$F$6:$F$105,B50)) | E50: =IF(B50="","",SUMIF('ملخص الموظفين السنوي'!$D$6:$D$105,B50,'ملخص الموظفين السنوي'!$R$6:$R$105)) | F50: =IF(B50="","",SUMIF('ملخص الموظفين السنوي'!$D$6:$D$105,B50,'ملخص الموظفين السنوي'!$AF$6:$AF$105)) | G50: =IF(B50="","",IFERROR(F50/SUM($F$40:$F$54),0))
B51: =IF(INDEX(L_DEPT,12)="","",INDEX(L_DEPT,12)) | C51: =IF(B51="","",COUNTIFS(الموظفون!$AG$6:$AG$105,"✔ على رأس العمل",الموظفون!$F$6:$F$105,B51)) | D51: =IF(B51="","",SUMIFS(الموظفون!$P$6:$P$105,الموظفون!$AG$6:$AG$105,"✔ على رأس العمل",الموظفون!$F$6:$F$105,B51)) | E51: =IF(B51="","",SUMIF('ملخص الموظفين السنوي'!$D$6:$D$105,B51,'ملخص الموظفين السنوي'!$R$6:$R$105)) | F51: =IF(B51="","",SUMIF('ملخص الموظفين السنوي'!$D$6:$D$105,B51,'ملخص الموظفين السنوي'!$AF$6:$AF$105)) | G51: =IF(B51="","",IFERROR(F51/SUM($F$40:$F$54),0))
B52: =IF(INDEX(L_DEPT,13)="","",INDEX(L_DEPT,13)) | C52: =IF(B52="","",COUNTIFS(الموظفون!$AG$6:$AG$105,"✔ على رأس العمل",الموظفون!$F$6:$F$105,B52)) | D52: =IF(B52="","",SUMIFS(الموظفون!$P$6:$P$105,الموظفون!$AG$6:$AG$105,"✔ على رأس العمل",الموظفون!$F$6:$F$105,B52)) | E52: =IF(B52="","",SUMIF('ملخص الموظفين السنوي'!$D$6:$D$105,B52,'ملخص الموظفين السنوي'!$R$6:$R$105)) | F52: =IF(B52="","",SUMIF('ملخص الموظفين السنوي'!$D$6:$D$105,B52,'ملخص الموظفين السنوي'!$AF$6:$AF$105)) | G52: =IF(B52="","",IFERROR(F52/SUM($F$40:$F$54),0))
...

Sheet الإعدادات
B1: ⚙ الإعدادات والثوابت النظامية 🔒 نسخة تجريبية
B2: ="🛒 نسخة تجريبية — للنسخة الكاملة اضغط هنا ← accopro.net | "&cfg_CO&" | السنة المالية "&cfg_FY&" | شهر التقرير: "&INDEX(L_MONTH,cfg_VAL_M)&" | المبالغ بـ "&cfg_CUR -> 🛒 نسخة تجريبية — للنسخة الكاملة اضغط هنا ← accopro.net | شركة النخبة للتجارة والمقاولات | السنة المالية 2026 | شهر التقرير: سبتمبر | المبالغ بـ ريال سعودي
B3: 🏠 الرئيسية | C3: 📊 لوحة التحكم | D3: 👥 الموظفون | F3: 🌴 سجل الإجازات | G3: ✍ الحركات | H3: 🪪 الإقامات | I3: 📅 الملخص الشهري | J3: 🧾 القيود | K3: 💳 القسيمة
B5: البند | C5: القيمة | D5: الشرح / المصدر | F5: الأقسام | G5: أسباب انتهاء الخدمة | H5: نعم / لا | I5: فئة التأمينات | J5: الأشهر | K5: أوراق المسير | M5: نوع الإجازة / الحالة | N5: نسبة الأجر المدفوع | O5: يُخصم من رصيد الإجازة السنوية؟ | P5: يُحتسب ضمن مدة الخدمة؟ | Q5: يُصرف راتبها مقدماً؟ | R5: الشرح
B6: اسم المنشأة | C6: شركة النخبة للتجارة والمقاولات | D6: يظهر في رؤوس جميع الأوراق والقسائم. | F6: الإدارة العليا | G6: استقالة | H6: نعم | I6: سعودي | J6: يناير | K6: مسير يناير | M6: إجازة سنوية (تُصرف مع الراتب) | N6: 1 | O6: نعم | P6: نعم | Q6: لا | R6: يستمر الراتب في المسير، وتُخصم الأيام من رصيد الإجازة ويُحمَّل راتبها على المخصص.
B7: السنة المالية | C7: 2026 | D7: كل التواريخ الشهرية تُبنى على هذه السنة. | F7: المالية | G7: إنهاء من صاحب العمل | H7: لا | I7: غير سعودي | J7: فبراير | K7: مسير فبراير | M7: إجازة سنوية (راتب مقدم قبل السفر) | N7: 1 | O7: نعم | P7: نعم | Q7: نعم | R7: يُصرف راتب الإجازة كاملاً في شهر بدايتها، ولا يُصرف راتب عن أيامها في المسيرات.
B8: العملة | C8: ريال سعودي | F8: الموارد البشرية | G8: انتهاء مدة العقد | J8: مارس | K8: مسير مارس | M8: إجازة بدون راتب | N8: 0 | O8: لا | P8: لا | Q8: لا | R8: لا راتب ولا تحتسب في الخدمة ولا تكتسب عنها إجازة أو تذكرة (المادة 116).
B9: شهر التقرير (1-12) | C9: 9 | D9: يتحكم في: المخصصات كما في نهاية الشهر، حالة الموظفين، مؤشرات لوحة التحكم (من بداية السنة حتى هذا الشهر)، وتمييز الأشهر الفعلية عن المتوقعة. | E9: 🧪 | F9: المبيعات | G9: اتفاق الطرفين | J9: أبريل | K9: مسير أبريل | M9: إجازة مرضية بأجر كامل | N9: 1 | O9: لا | P9: نعم | Q9: لا | R9: المادة 117: أول 30 يوماً في السنة بأجر كامل.
B10: بداية السنة المالية | C10: =DATE(cfg_FY,1,1) -> 46023 | D10: معادلة — لا تعدّل. | F10: العمليات | G10: وفاة أو عجز | J10: مايو | K10: مسير مايو | M10: إجازة مرضية بثلاثة أرباع الأجر | N10: 0.75 | O10: لا | P10: نعم | Q10: لا | R10: المادة 117: الستون يوماً التالية بثلاثة أرباع الأجر.
B11: تاريخ التقرير (نهاية شهر التقرير) | C11: =EOMONTH(DATE(cfg_FY,cfg_VAL_M,1),0) -> 46295 | D11: معادلة — لا تعدّل. | F11: تقنية المعلومات | J11: يونيو | K11: مسير يونيو | M11: إجازة مرضية بدون أجر | N11: 0 | O11: لا | P11: نعم | Q11: لا | R11: المادة 117: الثلاثون يوماً التالية بدون أجر.
B12: 💰 الرواتب والعمل الإضافي | F12: المشاريع | J12: يوليو | K12: مسير يوليو | M12: إجازة استثنائية مدفوعة (زواج/وفاة/مولود/حج) | N12: 1 | O12: لا | P12: نعم | Q12: لا | R12: المادتان 113 و114.
B13: أساس أيام الشهر | C13: 30 | D13: الأجر اليومي = الأجر الشهري ÷ 30 (العرف المحاسبي ونظام العمل). | J13: أغسطس | K13: مسير أغسطس | M13: إيقاف عن العمل (تحقيق/جزاء) | N13: 0 | O13: لا | P13: نعم | Q13: لا | R13: يوقف الراتب خلال مدة الإيقاف.
B14: ساعات العمل اليومية | C14: 8 | D14: المادة 98 من نظام العمل: 8 ساعات يومياً. | J14: سبتمبر | K14: مسير سبتمبر | M14: انقطاع عن العمل / بلاغ تغيب | N14: 0 | O14: لا | P14: لا | Q14: لا | R14: يوقف الراتب ولا تحتسب المدة في الخدمة.
B15: علاوة العمل الإضافي على الأجر الأساسي | C15: 0.5 | D15: المادة 107: أجر الساعة + 50% من الأجر الأساسي للساعة. | J15: أكتوبر | K15: مسير أكتوبر | M15: إيقاف الراتب مؤقتاً | N15: 0 | O15: لا | P15: نعم | Q15: لا | R15: لأي سبب إداري آخر (مثلاً: خارج المملكة بانتظار العودة).
B16: 🏛 التأمينات الاجتماعية (GOSI) | J16: نوفمبر | K16: مسير نوفمبر
B17: سعودي — حصة الموظف | C17: 0.0975 | D17: معاشات 9% + ساند 0.75%. المشتركون الجدد بعد 3/7/2025 تتدرج نسبتهم سنوياً — عدّل عند الحاجة. | J17: ديسمبر | K17: مسير ديسمبر
B18: سعودي — حصة المنشأة | C18: 0.1175 | D18: معاشات 9% + ساند 0.75% + أخطار مهنية 2%.
B19: غير سعودي — حصة الموظف | C19: 0 | D19: لا يُستقطع من غير السعودي. | M19: يمكنك إضافة نوعين إضافيين في الصفين الفارغين أو تعديل النسب. أي تغيير هنا ينعكس فوراً على سجل الإجازات والمسيرات.
B20: غير سعودي — حصة المنشأة | C20: 0.02 | D20: أخطار مهنية 2%.
B21: الحد الأعلى لأجر الاشتراك | C21: 45000 | D21: أجر الاشتراك = الأساسي + السكن بحد أقصى 45,000. تستمر الاشتراكات خلال الإجازات والإيقاف ما دام العامل على رأس العمل.
B22: 🎁 مكافأة نهاية الخدمة
B23: عدد السنوات الأولى | C23: 5 | D23: المادة 84: نصف شهر عن كل سنة من السنوات الخمس الأولى.
B24: أجر كل سنة من السنوات الأولى (بالأشهر) | C24: 0.5
B25: أجر كل سنة بعدها (بالأشهر) | C25: 1 | D25: أجر شهر كامل عن كل سنة تالية.
B26: يدخل بدل السكن في أجر نهاية الخدمة؟ | C26: نعم | D26: الأجر الفعلي حسب المادة 2: الأساسي + البدلات الثابتة.
B27: يدخل بدل النقل في أجر نهاية الخدمة؟ | C27: نعم
B28: تدخل البدلات الأخرى في أجر نهاية الخدمة؟ | C28: لا
B29: 🌴 الإجازات السنوية
B30: أيام الإجازة السنوية (قبل الحد) | C30: 21 | D30: المادة 109: 21 يوماً.
B31: أيام الإجازة السنوية (بعد الحد) | C31: 30 | D31: 30 يوماً بعد إتمام 5 سنوات متصلة.
B32: عدد سنوات الحد للإجازة | C32: 5
B33: يدخل السكن في أجر الإجازة؟ | C33: نعم
B34: يدخل النقل في أجر الإجازة؟ | C34: نعم
B35: تدخل البدلات الأخرى في أجر الإجازة؟ | C35: لا
B36: عدد أيام السنة لاحتساب مدة الخدمة | C36: 365
B37: 📐 نسب استحقاق مكافأة نهاية الخدمة عند الاستقالة (المادة 85)
B38: مدة الخدمة من (سنة) | C38: نسبة الاستحقاق | D38: الشرح
B39: 0 | C39: 0 | D39: أقل من سنتين: لا يستحق
B40: 2 | C40: =1/3 -> 0.33333333 | D40: من سنتين إلى أقل من 5: ثلث المكافأة
B41: 5 | C41: =2/3 -> 0.66666667 | D41: من 5 إلى أقل من 10: ثلثا المكافأة
...

Sheet الموظفون
A1: 👥 سجل بيانات الموظفين الرئيسي 🔒 نسخة تجريبية
A2: ="🛒 نسخة تجريبية — للنسخة الكاملة اضغط هنا ← accopro.net | "&cfg_CO&" | السنة المالية "&cfg_FY&" | شهر التقرير: "&INDEX(L_MONTH,cfg_VAL_M)&" | المبالغ بـ "&cfg_CUR -> 🛒 نسخة تجريبية — للنسخة الكاملة اضغط هنا ← accopro.net | شركة النخبة للتجارة والمقاولات | السنة المالية 2026 | شهر التقرير: سبتمبر | المبالغ بـ ريال سعودي
B3: 🏠 الرئيسية | C3: 📊 لوحة التحكم | E3: ⚙ الإعدادات | F3: 🌴 سجل الإجازات | G3: ✍ الحركات | H3: 🪪 الإقامات | J3: 📅 الملخص الشهري | L3: 🧾 القيود | M3: 💳 القسيمة
A4: 🧪 خانات التجربة: أول 5 موظفين (الخلايا الصفراء) — باقي الصفوف مقفلة في النسخة المجانية
A5: م | B5: الرقم الوظيفي | C5: اسم الموظف | D5: الجنسية | E5: فئة التأمينات | F5: القسم | G5: المسمى الوظيفي | H5: تاريخ التعيين | I5: رقم الإقامة / الهوية | J5: تاريخ انتهاء الإقامة / الهوية | K5: تاريخ انتهاء رخصة العمل | L5: الراتب الأساسي | M5: بدل السكن | N5: بدل النقل | O5: بدلات أخرى | P5: إجمالي الراتب الشهري | Q5: أجر احتساب نهاية الخدمة | R5: أجر احتساب الإجازة | S5: أجر الاشتراك في التأمينات | T5: أيام الإجازة السنوية (اختياري — يلغي الآلي) | U5: يستحق تذكرة سفر؟ | V5: قيمة التذكرة (له ولمن يعول) | W5: دورية التذكرة (شهر) | X5: رسوم الإقامة السنوية (فارغ = الافتراضي) | Y5: المقابل المالي لرخصة العمل سنوياً (فارغ = الافتراضي) | Z5: التأمين الطبي السنوي (فارغ = الافتراضي) | AA5: رسوم أخرى سنوية على المنشأة (مرافقين، خروج وعودة...) | AB5: إجمالي التكاليف الحكومية والتأمين السنوية | AC5: رصيد إجازات افتتاحي (يوم) في 1/1 | AD5: رصيد مخصص تذاكر افتتاحي في 1/1 | AE5: تاريخ انتهاء الخدمة | AF5: سبب انتهاء الخدمة | AG5: حالة التوظيف | AH5: الوضع في تاريخ التقرير | AI5: البنك | AJ5: رقم الآيبان IBAN | AK5: ملاحظات
A6: =IF(B6="","",ROW()-5) -> 1 | B6: E001 | C6: عبدالله محمد العتيبي | D6: سعودي | E6: سعودي | F6: الإدارة العليا | G6: المدير العام | H6: 40923 | I6: 1012345678 | J6: 47248 | L6: 28000 | M6: 7000 | N6: 2800 | O6: 3000 | P6: =IF(B6="","",SUM(L6:O6)) -> 40800 | Q6: =IF(B6="","",L6+IF(cfg_EOS_H="نعم",M6,0)+IF(cfg_EOS_T="نعم",N6,0)+IF(cfg_EOS_O="نعم",O6,0)) -> 37800 | R6: =IF(B6="","",L6+IF(cfg_LV_H="نعم",M6,0)+IF(cfg_LV_T="نعم",N6,0)+IF(cfg_LV_O="نعم",O6,0)) -> 37800 | S6: =IF(B6="","",MIN(cfg_G_CAP,L6+M6)) -> 35000 | U6: لا | V6: 0 | W6: 12 | Z6: 4800 | AB6: =IF(B6="","",IF(X6<>"",X6,IF(E6="غير سعودي",cfg_IQ,0))+IF(Y6<>"",Y6,IF(E6="غير سعودي",cfg_WP,0))+IF(Z6<>"",Z6,cfg_MED)+N(AA6)) -> 4800 | AC6: 18 | AD6: 0 | AG6: =IF(B6="","",IF(AND(AE6<>"",AE6<=cfg_VAL_DATE),"✖ منتهي الخدمة",IF(H6>cfg_VAL_DATE,"⏳ لم يباشر بعد","✔ على رأس العمل"))) -> ✔ على رأس العمل | AH6: =IF(B6="","",IF(AG6<>"✔ على رأس العمل",AG6,IF(COUNTIFS('سجل الإجازات والحالات'!$B$6:$B$505,B6,'سجل الإجازات والحالات'!$E$6:$E$505,"<="&cfg_VAL_DATE,'سجل الإجازات والحالات'!$F$6:$F$505,">="&cfg_VAL_DATE)>0,"✈ "&INDEX('سجل الإجازات والحالات'!$D$6:$D$505,MATCH(1,INDEX(('سجل الإجازات والحالات'!$B$6:$B$505=B6)*('سجل الإجازات والحالات'!$E$6:$E$505<=cfg_VAL_DATE)*('سجل الإجازات والحالات'!$F$6:$F$505>=cfg_VAL_DATE),0),0)),"✔ على رأس العمل"))) -> ✔ على رأس العمل | AI6: الراجحي | AJ6: SA0380000000608010167519
A7: =IF(B7="","",ROW()-5) -> 2 | B7: E002 | C7: أحمد سعيد القحطاني | D7: سعودي | E7: سعودي | F7: المالية | G7: مدير مالي | H7: 42522 | I7: 1023456789 | J7: 46786 | L7: 18000 | M7: 4500 | N7: 1800 | O7: 1000 | P7: =IF(B7="","",SUM(L7:O7)) -> 25300 | Q7: =IF(B7="","",L7+IF(cfg_EOS_H="نعم",M7,0)+IF(cfg_EOS_T="نعم",N7,0)+IF(cfg_EOS_O="نعم",O7,0)) -> 24300 | R7: =IF(B7="","",L7+IF(cfg_LV_H="نعم",M7,0)+IF(cfg_LV_T="نعم",N7,0)+IF(cfg_LV_O="نعم",O7,0)) -> 24300 | S7: =IF(B7="","",MIN(cfg_G_CAP,L7+M7)) -> 22500 | U7: لا | V7: 0 | W7: 12 | Z7: 3600 | AB7: =IF(B7="","",IF(X7<>"",X7,IF(E7="غير سعودي",cfg_IQ,0))+IF(Y7<>"",Y7,IF(E7="غير سعودي",cfg_WP,0))+IF(Z7<>"",Z7,cfg_MED)+N(AA7)) -> 3600 | AC7: 12 | AD7: 0 | AG7: =IF(B7="","",IF(AND(AE7<>"",AE7<=cfg_VAL_DATE),"✖ منتهي الخدمة",IF(H7>cfg_VAL_DATE,"⏳ لم يباشر بعد","✔ على رأس العمل"))) -> ✔ على رأس العمل | AH7: =IF(B7="","",IF(AG7<>"✔ على رأس العمل",AG7,IF(COUNTIFS('سجل الإجازات والحالات'!$B$6:$B$505,B7,'سجل الإجازات والحالات'!$E$6:$E$505,"<="&cfg_VAL_DATE,'سجل الإجازات والحالات'!$F$6:$F$505,">="&cfg_VAL_DATE)>0,"✈ "&INDEX('سجل الإجازات والحالات'!$D$6:$D$505,MATCH(1,INDEX(('سجل الإجازات والحالات'!$B$6:$B$505=B7)*('سجل الإجازات والحالات'!$E$6:$E$505<=cfg_VAL_DATE)*('سجل الإجازات والحالات'!$F$6:$F$505>=cfg_VAL_DATE),0),0)),"✔ على رأس العمل"))) -> ✔ على رأس العمل | AI7: الأهلي | AJ7: SA4410000011100000000001
A8: =IF(B8="","",ROW()-5) -> 3 | B8: E003 | C8: محمد علي حسن | D8: مصري | E8: غير سعودي | F8: المالية | G8: محاسب أول | H8: 43353 | I8: 2312345678 | J8: 46346 | K8: 46346 | L8: 8500 | M8: 2125 | N8: 850 | O8: 500 | P8: =IF(B8="","",SUM(L8:O8)) -> 11975 | Q8: =IF(B8="","",L8+IF(cfg_EOS_H="نعم",M8,0)+IF(cfg_EOS_T="نعم",N8,0)+IF(cfg_EOS_O="نعم",O8,0)) -> 11475 | R8: =IF(B8="","",L8+IF(cfg_LV_H="نعم",M8,0)+IF(cfg_LV_T="نعم",N8,0)+IF(cfg_LV_O="نعم",O8,0)) -> 11475 | S8: =IF(B8="","",MIN(cfg_G_CAP,L8+M8)) -> 10625 | U8: نعم | V8: 3200 | W8: 24 | Z8: 2400 | AB8: =IF(B8="","",IF(X8<>"",X8,IF(E8="غير سعودي",cfg_IQ,0))+IF(Y8<>"",Y8,IF(E8="غير سعودي",cfg_WP,0))+IF(Z8<>"",Z8,cfg_MED)+N(AA8)) -> 12650 | AC8: 20 | AD8: 1600 | AG8: =IF(B8="","",IF(AND(AE8<>"",AE8<=cfg_VAL_DATE),"✖ منتهي الخدمة",IF(H8>cfg_VAL_DATE,"⏳ لم يباشر بعد","✔ على رأس العمل"))) -> ✔ على رأس العمل | AH8: =IF(B8="","",IF(AG8<>"✔ على رأس العمل",AG8,IF(COUNTIFS('سجل الإجازات والحالات'!$B$6:$B$505,B8,'سجل الإجازات والحالات'!$E$6:$E$505,"<="&cfg_VAL_DATE,'سجل الإجازات والحالات'!$F$6:$F$505,">="&cfg_VAL_DATE)>0,"✈ "&INDEX('سجل الإجازات والحالات'!$D$6:$D$505,MATCH(1,INDEX(('سجل الإجازات والحالات'!$B$6:$B$505=B8)*('سجل الإجازات والحالات'!$E$6:$E$505<=cfg_VAL_DATE)*('سجل الإجازات والحالات'!$F$6:$F$505>=cfg_VAL_DATE),0),0)),"✔ على رأس العمل"))) -> ✔ على رأس العمل | AI8: الراجحي | AJ8: SA0380000000608010167520
A9: =IF(B9="","",ROW()-5) -> 4 | B9: E004 | C9: نورة خالد الدوسري | D9: سعودية | E9: سعودي | F9: الموارد البشرية | G9: مديرة موارد بشرية | H9: 43497 | I9: 1034567890 | J9: 47678 | L9: 14000 | M9: 3500 | N9: 1400 | O9: 0 | P9: =IF(B9="","",SUM(L9:O9)) -> 18900 | Q9: =IF(B9="","",L9+IF(cfg_EOS_H="نعم",M9,0)+IF(cfg_EOS_T="نعم",N9,0)+IF(cfg_EOS_O="نعم",O9,0)) -> 18900 | R9: =IF(B9="","",L9+IF(cfg_LV_H="نعم",M9,0)+IF(cfg_LV_T="نعم",N9,0)+IF(cfg_LV_O="نعم",O9,0)) -> 18900 | S9: =IF(B9="","",MIN(cfg_G_CAP,L9+M9)) -> 17500 | U9: لا | V9: 0 | W9: 12 | Z9: 3600 | AB9: =IF(B9="","",IF(X9<>"",X9,IF(E9="غير سعودي",cfg_IQ,0))+IF(Y9<>"",Y9,IF(E9="غير سعودي",cfg_WP,0))+IF(Z9<>"",Z9,cfg_MED)+N(AA9)) -> 3600 | AC9: 9 | AD9: 0 | AG9: =IF(B9="","",IF(AND(AE9<>"",AE9<=cfg_VAL_DATE),"✖ منتهي الخدمة",IF(H9>cfg_VAL_DATE,"⏳ لم يباشر بعد","✔ على رأس العمل"))) -> ✔ على رأس العمل | AH9: =IF(B9="","",IF(AG9<>"✔ على رأس العمل",AG9,IF(COUNTIFS('سجل الإجازات والحالات'!$B$6:$B$505,B9,'سجل الإجازات والحالات'!$E$6:$E$505,"<="&cfg_VAL_DATE,'سجل الإجازات والحالات'!$F$6:$F$505,">="&cfg_VAL_DATE)>0,"✈ "&INDEX('سجل الإجازات والحالات'!$D$6:$D$505,MATCH(1,INDEX(('سجل الإجازات والحالات'!$B$6:$B$505=B9)*('سجل الإجازات والحالات'!$E$6:$E$505<=cfg_VAL_DATE)*('سجل الإجازات والحالات'!$F$6:$F$505>=cfg_VAL_DATE),0),0)),"✔ على رأس العمل"))) -> ✔ على رأس العمل | AI9: الإنماء | AJ9: SA6005000068200000000002
A10: =IF(B10="","",ROW()-5) -> 5 | B10: E005 | C10: راجيش كومار | D10: هندي | E10: غير سعودي | F10: تقنية المعلومات | G10: مهندس شبكات | H10: 43933 | I10: 2323456789 | J10: 46417 | K10: 46417 | L10: 9000 | M10: 2250 | N10: 900 | O10: 700 | P10: =IF(B10="","",SUM(L10:O10)) -> 12850 | Q10: =IF(B10="","",L10+IF(cfg_EOS_H="نعم",M10,0)+IF(cfg_EOS_T="نعم",N10,0)+IF(cfg_EOS_O="نعم",O10,0)) -> 12150 | R10: =IF(B10="","",L10+IF(cfg_LV_H="نعم",M10,0)+IF(cfg_LV_T="نعم",N10,0)+IF(cfg_LV_O="نعم",O10,0)) -> 12150 | S10: =IF(B10="","",MIN(cfg_G_CAP,L10+M10)) -> 11250 | U10: نعم | V10: 2800 | W10: 12 | Z10: 2400 | AB10: =IF(B10="","",IF(X10<>"",X10,IF(E10="غير سعودي",cfg_IQ,0))+IF(Y10<>"",Y10,IF(E10="غير سعودي",cfg_WP,0))+IF(Z10<>"",Z10,cfg_MED)+N(AA10)) -> 12650 | AC10: 14 | AD10: 900 | AG10: =IF(B10="","",IF(AND(AE10<>"",AE10<=cfg_VAL_DATE),"✖ منتهي الخدمة",IF(H10>cfg_VAL_DATE,"⏳ لم يباشر بعد","✔ على رأس العمل"))) -> ✔ على رأس العمل | AH10: =IF(B10="","",IF(AG10<>"✔ على رأس العمل",AG10,IF(COUNTIFS('سجل الإجازات والحالات'!$B$6:$B$505,B10,'سجل الإجازات والحالات'!$E$6:$E$505,"<="&cfg_VAL_DATE,'سجل الإجازات والحالات'!$F$6:$F$505,">="&cfg_VAL_DATE)>0,"✈ "&INDEX('سجل الإجازات والحالات'!$D$6:$D$505,MATCH(1,INDEX(('سجل الإجازات والحالات'!$B$6:$B$505=B10)*('سجل الإجازات والحالات'!$E$6:$E$505<=cfg_VAL_DATE)*('سجل الإجازات والحالات'!$F$6:$F$505>=cfg_VAL_DATE),0),0)),"✔ على رأس العمل"))) -> ✔ على رأس العمل | AI10: الأهلي | AJ10: SA4410000011100000000003
A11: =IF(B11="","",ROW()-5) -> 6 | B11: E006 | C11: فهد ناصر الشمري | D11: سعودي | E11: سعودي | F11: المبيعات | G11: مدير مبيعات | H11: 43044 | I11: 1045678901 | J11: 47929 | L11: 13000 | M11: 3250 | N11: 1300 | O11: 2500 | P11: =IF(B11="","",SUM(L11:O11)) -> 20050 | Q11: =IF(B11="","",L11+IF(cfg_EOS_H="نعم",M11,0)+IF(cfg_EOS_T="نعم",N11,0)+IF(cfg_EOS_O="نعم",O11,0)) -> 17550 | R11: =IF(B11="","",L11+IF(cfg_LV_H="نعم",M11,0)+IF(cfg_LV_T="نعم",N11,0)+IF(cfg_LV_O="نعم",O11,0)) -> 17550 | S11: =IF(B11="","",MIN(cfg_G_CAP,L11+M11)) -> 16250 | U11: لا | V11: 0 | W11: 12 | Z11: 3600 | AB11: =IF(B11="","",IF(X11<>"",X11,IF(E11="غير سعودي",cfg_IQ,0))+IF(Y11<>"",Y11,IF(E11="غير سعودي",cfg_WP,0))+IF(Z11<>"",Z11,cfg_MED)+N(AA11)) -> 3600 | AC11: 25 | AD11: 0 | AG11: =IF(B11="","",IF(AND(AE11<>"",AE11<=cfg_VAL_DATE),"✖ منتهي الخدمة",IF(H11>cfg_VAL_DATE,"⏳ لم يباشر بعد","✔ على رأس العمل"))) -> ✔ على رأس العمل | AH11: =IF(B11="","",IF(AG11<>"✔ على رأس العمل",AG11,IF(COUNTIFS('سجل الإجازات والحالات'!$B$6:$B$505,B11,'سجل الإجازات والحالات'!$E$6:$E$505,"<="&cfg_VAL_DATE,'سجل الإجازات والحالات'!$F$6:$F$505,">="&cfg_VAL_DATE)>0,"✈ "&INDEX('سجل الإجازات والحالات'!$D$6:$D$505,MATCH(1,INDEX(('سجل الإجازات والحالات'!$B$6:$B$505=B11)*('سجل الإجازات والحالات'!$E$6:$E$505<=cfg_VAL_DATE)*('سجل الإجازات والحالات'!$F$6:$F$505>=cfg_VAL_DATE),0),0)),"✔ على رأس العمل"))) -> ✈ إجازة بدون راتب | AI11: الراجحي | AJ11: SA0380000000608010167521
A12: =IF(B12="","",ROW()-5) -> 7 | B12: E007 | C12: خالد يوسف الأحمد | D12: أردني | E12: غير سعودي | F12: المشاريع | G12: مهندس مشاريع | H12: 44216 | I12: 2334567890 | J12: 46320 | K12: 46280 | L12: 11000 | M12: 2750 | N12: 1100 | O12: 800 | P12: =IF(B12="","",SUM(L12:O12)) -> 15650 | Q12: =IF(B12="","",L12+IF(cfg_EOS_H="نعم",M12,0)+IF(cfg_EOS_T="نعم",N12,0)+IF(cfg_EOS_O="نعم",O12,0)) -> 14850 | R12: =IF(B12="","",L12+IF(cfg_LV_H="نعم",M12,0)+IF(cfg_LV_T="نعم",N12,0)+IF(cfg_LV_O="نعم",O12,0)) -> 14850 | S12: =IF(B12="","",MIN(cfg_G_CAP,L12+M12)) -> 13750 | U12: نعم | V12: 4500 | W12: 12 | Z12: 2400 | AA12: 4800 | AB12: =IF(B12="","",IF(X12<>"",X12,IF(E12="غير سعودي",cfg_IQ,0))+IF(Y12<>"",Y12,IF(E12="غير سعودي",cfg_WP,0))+IF(Z12<>"",Z12,cfg_MED)+N(AA12)) -> 17450 | AC12: 16 | AD12: 2400 | AG12: =IF(B12="","",IF(AND(AE12<>"",AE12<=cfg_VAL_DATE),"✖ منتهي الخدمة",IF(H12>cfg_VAL_DATE,"⏳ لم يباشر بعد","✔ على رأس العمل"))) -> ✔ على رأس العمل | AH12: =IF(B12="","",IF(AG12<>"✔ على رأس العمل",AG12,IF(COUNTIFS('سجل الإجازات والحالات'!$B$6:$B$505,B12,'سجل الإجازات والحالات'!$E$6:$E$505,"<="&cfg_VAL_DATE,'سجل الإجازات والحالات'!$F$6:$F$505,">="&cfg_VAL_DATE)>0,"✈ "&INDEX('سجل الإجازات والحالات'!$D$6:$D$505,MATCH(1,INDEX(('سجل الإجازات والحالات'!$B$6:$B$505=B12)*('سجل الإجازات والحالات'!$E$6:$E$505<=cfg_VAL_DATE)*('سجل الإجازات والحالات'!$F$6:$F$505>=cfg_VAL_DATE),0),0)),"✔ على رأس العمل"))) -> ✔ على رأس العمل | AI12: البلاد | AJ12: SA1515000999100000000004 | AK12: المنشأة تتحمل رسوم مرافق واحد
A13: =IF(B13="","",ROW()-5) -> 8 | B13: E008 | C13: سارة عبدالرحمن الزهراني | D13: سعودية | E13: سعودي | F13: المالية | G13: محاسبة | H13: 44986 | I13: 1056789012 | J13: 48466 | L13: 7500 | M13: 1875 | N13: 750 | O13: 0 | P13: =IF(B13="","",SUM(L13:O13)) -> 10125 | Q13: =IF(B13="","",L13+IF(cfg_EOS_H="نعم",M13,0)+IF(cfg_EOS_T="نعم",N13,0)+IF(cfg_EOS_O="نعم",O13,0)) -> 10125 | R13: =IF(B13="","",L13+IF(cfg_LV_H="نعم",M13,0)+IF(cfg_LV_T="نعم",N13,0)+IF(cfg_LV_O="نعم",O13,0)) -> 10125 | S13: =IF(B13="","",MIN(cfg_G_CAP,L13+M13)) -> 9375 | U13: لا | V13: 0 | W13: 12 | Z13: 2400 | AB13: =IF(B13="","",IF(X13<>"",X13,IF(E13="غير سعودي",cfg_IQ,0))+IF(Y13<>"",Y13,IF(E13="غير سعودي",cfg_WP,0))+IF(Z13<>"",Z13,cfg_MED)+N(AA13)) -> 2400 | AC13: 6 | AD13: 0 | AG13: =IF(B13="","",IF(AND(AE13<>"",AE13<=cfg_VAL_DATE),"✖ منتهي الخدمة",IF(H13>cfg_VAL_DATE,"⏳ لم يباشر بعد","✔ على رأس العمل"))) -> ✔ على رأس العمل | AH13: =IF(B13="","",IF(AG13<>"✔ على رأس العمل",AG13,IF(COUNTIFS('سجل الإجازات والحالات'!$B$6:$B$505,B13,'سجل الإجازات والحالات'!$E$6:$E$505,"<="&cfg_VAL_DATE,'سجل الإجازات والحالات'!$F$6:$F$505,">="&cfg_VAL_DATE)>0,"✈ "&INDEX('سجل الإجازات والحالات'!$D$6:$D$505,MATCH(1,INDEX(('سجل الإجازات والحالات'!$B$6:$B$505=B13)*('سجل الإجازات والحالات'!$E$6:$E$505<=cfg_VAL_DATE)*('سجل الإجازات والحالات'!$F$6:$F$505>=cfg_VAL_DATE),0),0)),"✔ على رأس العمل"))) -> ✔ على رأس العمل | AI13: الإنماء | AJ13: SA6005000068200000000005
A14: =IF(B14="","",ROW()-5) -> 9 | B14: E009 | C14: محمد رفيق | D14: باكستاني | E14: غير سعودي | F14: العمليات | G14: مشرف عمليات | H14: 41869 | I14: 2345678901 | J14: 46539 | K14: 46539 | L14: 6500 | M14: 1625 | N14: 650 | O14: 300 | P14: =IF(B14="","",SUM(L14:O14)) -> 9075 | Q14: =IF(B14="","",L14+IF(cfg_EOS_H="نعم",M14,0)+IF(cfg_EOS_T="نعم",N14,0)+IF(cfg_EOS_O="نعم",O14,0)) -> 8775 | R14: =IF(B14="","",L14+IF(cfg_LV_H="نعم",M14,0)+IF(cfg_LV_T="نعم",N14,0)+IF(cfg_LV_O="نعم",O14,0)) -> 8775 | S14: =IF(B14="","",MIN(cfg_G_CAP,L14+M14)) -> 8125 | T14: 30 | U14: نعم | V14: 2200 | W14: 24 | Z14: 1800 | AB14: =IF(B14="","",IF(X14<>"",X14,IF(E14="غير سعودي",cfg_IQ,0))+IF(Y14<>"",Y14,IF(E14="غير سعودي",cfg_WP,0))+IF(Z14<>"",Z14,cfg_MED)+N(AA14)) -> 12050 | AC14: 35 | AD14: 2000 | AG14: =IF(B14="","",IF(AND(AE14<>"",AE14<=cfg_VAL_DATE),"✖ منتهي الخدمة",IF(H14>cfg_VAL_DATE,"⏳ لم يباشر بعد","✔ على رأس العمل"))) -> ✔ على رأس العمل | AH14: =IF(B14="","",IF(AG14<>"✔ على رأس العمل",AG14,IF(COUNTIFS('سجل الإجازات والحالات'!$B$6:$B$505,B14,'سجل الإجازات والحالات'!$E$6:$E$505,"<="&cfg_VAL_DATE,'سجل الإجازات والحالات'!$F$6:$F$505,">="&cfg_VAL_DATE)>0,"✈ "&INDEX('سجل الإجازات والحالات'!$D$6:$D$505,MATCH(1,INDEX(('سجل الإجازات والحالات'!$B$6:$B$505=B14)*('سجل الإجازات والحالات'!$E$6:$E$505<=cfg_VAL_DATE)*('سجل الإجازات والحالات'!$F$6:$F$505>=cfg_VAL_DATE),0),0)),"✔ على رأس العمل"))) -> ✔ على رأس العمل | AI14: الراجحي | AJ14: SA0380000000608010167522
A15: =IF(B15="","",ROW()-5) -> 10 | B15: E010 | C15: ريم سلطان المطيري | D15: سعودية | E15: سعودي | F15: المبيعات | G15: أخصائية تسويق | H15: 46127 | I15: 1067890123 | J15: 48580 | L15: 9000 | M15: 2250 | N15: 900 | O15: 0 | P15: =IF(B15="","",SUM(L15:O15)) -> 12150 | Q15: =IF(B15="","",L15+IF(cfg_EOS_H="نعم",M15,0)+IF(cfg_EOS_T="نعم",N15,0)+IF(cfg_EOS_O="نعم",O15,0)) -> 12150 | R15: =IF(B15="","",L15+IF(cfg_LV_H="نعم",M15,0)+IF(cfg_LV_T="نعم",N15,0)+IF(cfg_LV_O="نعم",O15,0)) -> 12150 | S15: =IF(B15="","",MIN(cfg_G_CAP,L15+M15)) -> 11250 | U15: لا | V15: 0 | W15: 12 | Z15: 2400 | AB15: =IF(B15="","",IF(X15<>"",X15,IF(E15="غير سعودي",cfg_IQ,0))+IF(Y15<>"",Y15,IF(E15="غير سعودي",cfg_WP,0))+IF(Z15<>"",Z15,cfg_MED)+N(AA15)) -> 2400 | AC15: 0 | AD15: 0 | AG15: =IF(B15="","",IF(AND(AE15<>"",AE15<=cfg_VAL_DATE),"✖ منتهي الخدمة",IF(H15>cfg_VAL_DATE,"⏳ لم يباشر بعد","✔ على رأس العمل"))) -> ✔ على رأس العمل | AH15: =IF(B15="","",IF(AG15<>"✔ على رأس العمل",AG15,IF(COUNTIFS('سجل الإجازات والحالات'!$B$6:$B$505,B15,'سجل الإجازات والحالات'!$E$6:$E$505,"<="&cfg_VAL_DATE,'سجل الإجازات والحالات'!$F$6:$F$505,">="&cfg_VAL_DATE)>0,"✈ "&INDEX('سجل الإجازات والحالات'!$D$6:$D$505,MATCH(1,INDEX(('سجل الإجازات والحالات'!$B$6:$B$505=B15)*('سجل الإجازات والحالات'!$E$6:$E$505<=cfg_VAL_DATE)*('سجل الإجازات والحالات'!$F$6:$F$505>=cfg_VAL_DATE),0),0)),"✔ على رأس العمل"))) -> ✔ على رأس العمل | AI15: الأهلي | AJ15: SA4410000011100000000006
A16: =IF(B16="","",ROW()-5) -> 11 | B16: E011 | C16: جون ماتيو | D16: فلبيني | E16: غير سعودي | F16: العمليات | G16: فني صيانة | H16: 43525 | I16: 2356789012 | J16: 46481 | K16: 46481 | L16: 5000 | M16: 1250 | N16: 500 | O16: 0 | P16: =IF(B16="","",SUM(L16:O16)) -> 6750 | Q16: =IF(B16="","",L16+IF(cfg_EOS_H="نعم",M16,0)+IF(cfg_EOS_T="نعم",N16,0)+IF(cfg_EOS_O="نعم",O16,0)) -> 6750 | R16: =IF(B16="","",L16+IF(cfg_LV_H="نعم",M16,0)+IF(cfg_LV_T="نعم",N16,0)+IF(cfg_LV_O="نعم",O16,0)) -> 6750 | S16: =IF(B16="","",MIN(cfg_G_CAP,L16+M16)) -> 6250 | U16: نعم | V16: 2600 | W16: 24 | Z16: 1800 | AB16: =IF(B16="","",IF(X16<>"",X16,IF(E16="غير سعودي",cfg_IQ,0))+IF(Y16<>"",Y16,IF(E16="غير سعودي",cfg_WP,0))+IF(Z16<>"",Z16,cfg_MED)+N(AA16)) -> 12050 | AC16: 22 | AD16: 1800 | AE16: 46203 | AF16: استقالة | AG16: =IF(B16="","",IF(AND(AE16<>"",AE16<=cfg_VAL_DATE),"✖ منتهي الخدمة",IF(H16>cfg_VAL_DATE,"⏳ لم يباشر بعد","✔ على رأس العمل"))) -> ✖ منتهي الخدمة | AH16: =IF(B16="","",IF(AG16<>"✔ على رأس العمل",AG16,IF(COUNTIFS('سجل الإجازات والحالات'!$B$6:$B$505,B16,'سجل الإجازات والحالات'!$E$6:$E$505,"<="&cfg_VAL_DATE,'سجل الإجازات والحالات'!$F$6:$F$505,">="&cfg_VAL_DATE)>0,"✈ "&INDEX('سجل الإجازات والحالات'!$D$6:$D$505,MATCH(1,INDEX(('سجل الإجازات والحالات'!$B$6:$B$505=B16)*('سجل الإجازات والحالات'!$E$6:$E$505<=cfg_VAL_DATE)*('سجل الإجازات والحالات'!$F$6:$F$505>=cfg_VAL_DATE),0),0)),"✔ على رأس العمل"))) -> ✖ منتهي الخدمة | AI16: الراجحي | AJ16: SA0380000000608010167523
A17: =IF(B17="","",ROW()-5) -> 12 | B17: E012 | C17: عمر حسين البيشي | D17: سعودي | E17: سعودي | F17: تقنية المعلومات | G17: مطور برمجيات | H17: 44752 | I17: 1078901234 | J17: 47464 | L17: 12000 | M17: 3000 | N17: 1200 | O17: 1500 | P17: =IF(B17="","",SUM(L17:O17)) -> 17700 | Q17: =IF(B17="","",L17+IF(cfg_EOS_H="نعم",M17,0)+IF(cfg_EOS_T="نعم",N17,0)+IF(cfg_EOS_O="نعم",O17,0)) -> 16200 | R17: =IF(B17="","",L17+IF(cfg_LV_H="نعم",M17,0)+IF(cfg_LV_T="نعم",N17,0)+IF(cfg_LV_O="نعم",O17,0)) -> 16200 | S17: =IF(B17="","",MIN(cfg_G_CAP,L17+M17)) -> 15000 | U17: لا | V17: 0 | W17: 12 | Z17: 2400 | AB17: =IF(B17="","",IF(X17<>"",X17,IF(E17="غير سعودي",cfg_IQ,0))+IF(Y17<>"",Y17,IF(E17="غير سعودي",cfg_WP,0))+IF(Z17<>"",Z17,cfg_MED)+N(AA17)) -> 2400 | AC17: 10 | AD17: 0 | AG17: =IF(B17="","",IF(AND(AE17<>"",AE17<=cfg_VAL_DATE),"✖ منتهي الخدمة",IF(H17>cfg_VAL_DATE,"⏳ لم يباشر بعد","✔ على رأس العمل"))) -> ✔ على رأس العمل | AH17: =IF(B17="","",IF(AG17<>"✔ على رأس العمل",AG17,IF(COUNTIFS('سجل الإجازات والحالات'!$B$6:$B$505,B17,'سجل الإجازات والحالات'!$E$6:$E$505,"<="&cfg_VAL_DATE,'سجل الإجازات والحالات'!$F$6:$F$505,">="&cfg_VAL_DATE)>0,"✈ "&INDEX('سجل الإجازات والحالات'!$D$6:$D$505,MATCH(1,INDEX(('سجل الإجازات والحالات'!$B$6:$B$505=B17)*('سجل الإجازات والحالات'!$E$6:$E$505<=cfg_VAL_DATE)*('سجل الإجازات والحالات'!$F$6:$F$505>=cfg_VAL_DATE),0),0)),"✔ على رأس العمل"))) -> ✔ على رأس العمل | AI17: البلاد | AJ17: SA1515000999100000000007
A18: =IF(B18="","",ROW()-5) | P18: =IF(B18="","",SUM(L18:O18)) | Q18: =IF(B18="","",L18+IF(cfg_EOS_H="نعم",M18,0)+IF(cfg_EOS_T="نعم",N18,0)+IF(cfg_EOS_O="نعم",O18,0)) | R18: =IF(B18="","",L18+IF(cfg_LV_H="نعم",M18,0)+IF(cfg_LV_T="نعم",N18,0)+IF(cfg_LV_O="نعم",O18,0)) | S18: =IF(B18="","",MIN(cfg_G_CAP,L18+M18)) | AB18: =IF(B18="","",IF(X18<>"",X18,IF(E18="غير سعودي",cfg_IQ,0))+IF(Y18<>"",Y18,IF(E18="غير سعودي",cfg_WP,0))+IF(Z18<>"",Z18,cfg_MED)+N(AA18)) | AG18: =IF(B18="","",IF(AND(AE18<>"",AE18<=cfg_VAL_DATE),"✖ منتهي الخدمة",IF(H18>cfg_VAL_DATE,"⏳ لم يباشر بعد","✔ على رأس العمل"))) | AH18: =IF(B18="","",IF(AG18<>"✔ على رأس العمل",AG18,IF(COUNTIFS('سجل الإجازات والحالات'!$B$6:$B$505,B18,'سجل الإجازات والحالات'!$E$6:$E$505,"<="&cfg_VAL_DATE,'سجل الإجازات والحالات'!$F$6:$F$505,">="&cfg_VAL_DATE)>0,"✈ "&INDEX('سجل الإجازات والحالات'!$D$6:$D$505,MATCH(1,INDEX(('سجل الإجازات والحالات'!$B$6:$B$505=B18)*('سجل الإجازات والحالات'!$E$6:$E$505<=cfg_VAL_DATE)*('سجل الإجازات والحالات'!$F$6:$F$505>=cfg_VAL_DATE),0),0)),"✔ على رأس العمل")))
A19: =IF(B19="","",ROW()-5) | P19: =IF(B19="","",SUM(L19:O19)) | Q19: =IF(B19="","",L19+IF(cfg_EOS_H="نعم",M19,0)+IF(cfg_EOS_T="نعم",N19,0)+IF(cfg_EOS_O="نعم",O19,0)) | R19: =IF(B19="","",L19+IF(cfg_LV_H="نعم",M19,0)+IF(cfg_LV_T="نعم",N19,0)+IF(cfg_LV_O="نعم",O19,0)) | S19: =IF(B19="","",MIN(cfg_G_CAP,L19+M19)) | AB19: =IF(B19="","",IF(X19<>"",X19,IF(E19="غير سعودي",cfg_IQ,0))+IF(Y19<>"",Y19,IF(E19="غير سعودي",cfg_WP,0))+IF(Z19<>"",Z19,cfg_MED)+N(AA19)) | AG19: =IF(B19="","",IF(AND(AE19<>"",AE19<=cfg_VAL_DATE),"✖ منتهي الخدمة",IF(H19>cfg_VAL_DATE,"⏳ لم يباشر بعد","✔ على رأس العمل"))) | AH19: =IF(B19="","",IF(AG19<>"✔ على رأس العمل",AG19,IF(COUNTIFS('سجل الإجازات والحالات'!$B$6:$B$505,B19,'سجل الإجازات والحالات'!$E$6:$E$505,"<="&cfg_VAL_DATE,'سجل الإجازات والحالات'!$F$6:$F$505,">="&cfg_VAL_DATE)>0,"✈ "&INDEX('سجل الإجازات والحالات'!$D$6:$D$505,MATCH(1,INDEX(('سجل الإجازات والحالات'!$B$6:$B$505=B19)*('سجل الإجازات والحالات'!$E$6:$E$505<=cfg_VAL_DATE)*('سجل الإجازات والحالات'!$F$6:$F$505>=cfg_VAL_DATE),0),0)),"✔ على رأس العمل")))
A20: =IF(B20="","",ROW()-5) | P20: =IF(B20="","",SUM(L20:O20)) | Q20: =IF(B20="","",L20+IF(cfg_EOS_H="نعم",M20,0)+IF(cfg_EOS_T="نعم",N20,0)+IF(cfg_EOS_O="نعم",O20,0)) | R20: =IF(B20="","",L20+IF(cfg_LV_H="نعم",M20,0)+IF(cfg_LV_T="نعم",N20,0)+IF(cfg_LV_O="نعم",O20,0)) | S20: =IF(B20="","",MIN(cfg_G_CAP,L20+M20)) | AB20: =IF(B20="","",IF(X20<>"",X20,IF(E20="غير سعودي",cfg_IQ,0))+IF(Y20<>"",Y20,IF(E20="غير سعودي",cfg_WP,0))+IF(Z20<>"",Z20,cfg_MED)+N(AA20)) | AG20: =IF(B20="","",IF(AND(AE20<>"",AE20<=cfg_VAL_DATE),"✖ منتهي الخدمة",IF(H20>cfg_VAL_DATE,"⏳ لم يباشر بعد","✔ على رأس العمل"))) | AH20: =IF(B20="","",IF(AG20<>"✔ على رأس العمل",AG20,IF(COUNTIFS('سجل الإجازات والحالات'!$B$6:$B$505,B20,'سجل الإجازات والحالات'!$E$6:$E$505,"<="&cfg_VAL_DATE,'سجل الإجازات والحالات'!$F$6:$F$505,">="&cfg_VAL_DATE)>0,"✈ "&INDEX('سجل الإجازات والحالات'!$D$6:$D$505,MATCH(1,INDEX(('سجل الإجازات والحالات'!$B$6:$B$505=B20)*('سجل الإجازات والحالات'!$E$6:$E$505<=cfg_VAL_DATE)*('سجل الإجازات والحالات'!$F$6:$F$505>=cfg_VAL_DATE),0),0)),"✔ على رأس العمل")))
A21: =IF(B21="","",ROW()-5) | P21: =IF(B21="","",SUM(L21:O21)) | Q21: =IF(B21="","",L21+IF(cfg_EOS_H="نعم",M21,0)+IF(cfg_EOS_T="نعم",N21,0)+IF(cfg_EOS_O="نعم",O21,0)) | R21: =IF(B21="","",L21+IF(cfg_LV_H="نعم",M21,0)+IF(cfg_LV_T="نعم",N21,0)+IF(cfg_LV_O="نعم",O21,0)) | S21: =IF(B21="","",MIN(cfg_G_CAP,L21+M21)) | AB21: =IF(B21="","",IF(X21<>"",X21,IF(E21="غير سعودي",cfg_IQ,0))+IF(Y21<>"",Y21,IF(E21="غير سعودي",cfg_WP,0))+IF(Z21<>"",Z21,cfg_MED)+N(AA21)) | AG21: =IF(B21="","",IF(AND(AE21<>"",AE21<=cfg_VAL_DATE),"✖ منتهي الخدمة",IF(H21>cfg_VAL_DATE,"⏳ لم يباشر بعد","✔ على رأس العمل"))) | AH21: =IF(B21="","",IF(AG21<>"✔ على رأس العمل",AG21,IF(COUNTIFS('سجل الإجازات والحالات'!$B$6:$B$505,B21,'سجل الإجازات والحالات'!$E$6:$E$505,"<="&cfg_VAL_DATE,'سجل الإجازات والحالات'!$F$6:$F$505,">="&cfg_VAL_DATE)>0,"✈ "&INDEX('سجل الإجازات والحالات'!$D$6:$D$505,MATCH(1,INDEX(('سجل الإجازات والحالات'!$B$6:$B$505=B21)*('سجل الإجازات والحالات'!$E$6:$E$505<=cfg_VAL_DATE)*('سجل الإجازات والحالات'!$F$6:$F$505>=cfg_VAL_DATE),0),0)),"✔ على رأس العمل")))
A22: =IF(B22="","",ROW()-5) | P22: =IF(B22="","",SUM(L22:O22)) | Q22: =IF(B22="","",L22+IF(cfg_EOS_H="نعم",M22,0)+IF(cfg_EOS_T="نعم",N22,0)+IF(cfg_EOS_O="نعم",O22,0)) | R22: =IF(B22="","",L22+IF(cfg_LV_H="نعم",M22,0)+IF(cfg_LV_T="نعم",N22,0)+IF(cfg_LV_O="نعم",O22,0)) | S22: =IF(B22="","",MIN(cfg_G_CAP,L22+M22)) | AB22: =IF(B22="","",IF(X22<>"",X22,IF(E22="غير سعودي",cfg_IQ,0))+IF(Y22<>"",Y22,IF(E22="غير سعودي",cfg_WP,0))+IF(Z22<>"",Z22,cfg_MED)+N(AA22)) | AG22: =IF(B22="","",IF(AND(AE22<>"",AE22<=cfg_VAL_DATE),"✖ منتهي الخدمة",IF(H22>cfg_VAL_DATE,"⏳ لم يباشر بعد","✔ على رأس العمل"))) | AH22: =IF(B22="","",IF(AG22<>"✔ على رأس العمل",AG22,IF(COUNTIFS('سجل الإجازات والحالات'!$B$6:$B$505,B22,'سجل الإجازات والحالات'!$E$6:$E$505,"<="&cfg_VAL_DATE,'سجل الإجازات والحالات'!$F$6:$F$505,">="&cfg_VAL_DATE)>0,"✈ "&INDEX('سجل الإجازات والحالات'!$D$6:$D$505,MATCH(1,INDEX(('سجل الإجازات والحالات'!$B$6:$B$505=B22)*('سجل الإجازات والحالات'!$E$6:$E$505<=cfg_VAL_DATE)*('سجل الإجازات والحالات'!$F$6:$F$505>=cfg_VAL_DATE),0),0)),"✔ على رأس العمل")))
A23: =IF(B23="","",ROW()-5) | P23: =IF(B23="","",SUM(L23:O23)) | Q23: =IF(B23="","",L23+IF(cfg_EOS_H="نعم",M23,0)+IF(cfg_EOS_T="نعم",N23,0)+IF(cfg_EOS_O="نعم",O23,0)) | R23: =IF(B23="","",L23+IF(cfg_LV_H="نعم",M23,0)+IF(cfg_LV_T="نعم",N23,0)+IF(cfg_LV_O="نعم",O23,0)) | S23: =IF(B23="","",MIN(cfg_G_CAP,L23+M23)) | AB23: =IF(B23="","",IF(X23<>"",X23,IF(E23="غير سعودي",cfg_IQ,0))+IF(Y23<>"",Y23,IF(E23="غير سعودي",cfg_WP,0))+IF(Z23<>"",Z23,cfg_MED)+N(AA23)) | AG23: =IF(B23="","",IF(AND(AE23<>"",AE23<=cfg_VAL_DATE),"✖ منتهي الخدمة",IF(H23>cfg_VAL_DATE,"⏳ لم يباشر بعد","✔ على رأس العمل"))) | AH23: =IF(B23="","",IF(AG23<>"✔ على رأس العمل",AG23,IF(COUNTIFS('سجل الإجازات والحالات'!$B$6:$B$505,B23,'سجل الإجازات والحالات'!$E$6:$E$505,"<="&cfg_VAL_DATE,'سجل الإجازات والحالات'!$F$6:$F$505,">="&cfg_VAL_DATE)>0,"✈ "&INDEX('سجل الإجازات والحالات'!$D$6:$D$505,MATCH(1,INDEX(('سجل الإجازات والحالات'!$B$6:$B$505=B23)*('سجل الإجازات والحالات'!$E$6:$E$505<=cfg_VAL_DATE)*('سجل الإجازات والحالات'!$F$6:$F$505>=cfg_VAL_DATE),0),0)),"✔ على رأس العمل")))
A24: =IF(B24="","",ROW()-5) | P24: =IF(B24="","",SUM(L24:O24)) | Q24: =IF(B24="","",L24+IF(cfg_EOS_H="نعم",M24,0)+IF(cfg_EOS_T="نعم",N24,0)+IF(cfg_EOS_O="نعم",O24,0)) | R24: =IF(B24="","",L24+IF(cfg_LV_H="نعم",M24,0)+IF(cfg_LV_T="نعم",N24,0)+IF(cfg_LV_O="نعم",O24,0)) | S24: =IF(B24="","",MIN(cfg_G_CAP,L24+M24)) | AB24: =IF(B24="","",IF(X24<>"",X24,IF(E24="غير سعودي",cfg_IQ,0))+IF(Y24<>"",Y24,IF(E24="غير سعودي",cfg_WP,0))+IF(Z24<>"",Z24,cfg_MED)+N(AA24)) | AG24: =IF(B24="","",IF(AND(AE24<>"",AE24<=cfg_VAL_DATE),"✖ منتهي الخدمة",IF(H24>cfg_VAL_DATE,"⏳ لم يباشر بعد","✔ على رأس العمل"))) | AH24: =IF(B24="","",IF(AG24<>"✔ على رأس العمل",AG24,IF(COUNTIFS('سجل الإجازات والحالات'!$B$6:$B$505,B24,'سجل الإجازات والحالات'!$E$6:$E$505,"<="&cfg_VAL_DATE,'سجل الإجازات والحالات'!$F$6:$F$505,">="&cfg_VAL_DATE)>0,"✈ "&INDEX('سجل الإجازات والحالات'!$D$6:$D$505,MATCH(1,INDEX(('سجل الإجازات والحالات'!$B$6:$B$505=B24)*('سجل الإجازات والحالات'!$E$6:$E$505<=cfg_VAL_DATE)*('سجل الإجازات والحالات'!$F$6:$F$505>=cfg_VAL_DATE),0),0)),"✔ على رأس العمل")))
A25: =IF(B25="","",ROW()-5) | P25: =IF(B25="","",SUM(L25:O25)) | Q25: =IF(B25="","",L25+IF(cfg_EOS_H="نعم",M25,0)+IF(cfg_EOS_T="نعم",N25,0)+IF(cfg_EOS_O="نعم",O25,0)) | R25: =IF(B25="","",L25+IF(cfg_LV_H="نعم",M25,0)+IF(cfg_LV_T="نعم",N25,0)+IF(cfg_LV_O="نعم",O25,0)) | S25: =IF(B25="","",MIN(cfg_G_CAP,L25+M25)) | AB25: =IF(B25="","",IF(X25<>"",X25,IF(E25="غير سعودي",cfg_IQ,0))+IF(Y25<>"",Y25,IF(E25="غير سعودي",cfg_WP,0))+IF(Z25<>"",Z25,cfg_MED)+N(AA25)) | AG25: =IF(B25="","",IF(AND(AE25<>"",AE25<=cfg_VAL_DATE),"✖ منتهي الخدمة",IF(H25>cfg_VAL_DATE,"⏳ لم يباشر بعد","✔ على رأس العمل"))) | AH25: =IF(B25="","",IF(AG25<>"✔ على رأس العمل",AG25,IF(COUNTIFS('سجل الإجازات والحالات'!$B$6:$B$505,B25,'سجل الإجازات والحالات'!$E$6:$E$505,"<="&cfg_VAL_DATE,'سجل الإجازات والحالات'!$F$6:$F$505,">="&cfg_VAL_DATE)>0,"✈ "&INDEX('سجل الإجازات والحالات'!$D$6:$D$505,MATCH(1,INDEX(('سجل الإجازات والحالات'!$B$6:$B$505=B25)*('سجل الإجازات والحالات'!$E$6:$E$505<=cfg_VAL_DATE)*('سجل الإجازات والحالات'!$F$6:$F$505>=cfg_VAL_DATE),0),0)),"✔ على رأس العمل")))
A26: =IF(B26="","",ROW()-5) | P26: =IF(B26="","",SUM(L26:O26)) | Q26: =IF(B26="","",L26+IF(cfg_EOS_H="نعم",M26,0)+IF(cfg_EOS_T="نعم",N26,0)+IF(cfg_EOS_O="نعم",O26,0)) | R26: =IF(B26="","",L26+IF(cfg_LV_H="نعم",M26,0)+IF(cfg_LV_T="نعم",N26,0)+IF(cfg_LV_O="نعم",O26,0)) | S26: =IF(B26="","",MIN(cfg_G_CAP,L26+M26)) | AB26: =IF(B26="","",IF(X26<>"",X26,IF(E26="غير سعودي",cfg_IQ,0))+IF(Y26<>"",Y26,IF(E26="غير سعودي",cfg_WP,0))+IF(Z26<>"",Z26,cfg_MED)+N(AA26)) | AG26: =IF(B26="","",IF(AND(AE26<>"",AE26<=cfg_VAL_DATE),"✖ منتهي الخدمة",IF(H26>cfg_VAL_DATE,"⏳ لم يباشر بعد","✔ على رأس العمل"))) | AH26: =IF(B26="","",IF(AG26<>"✔ على رأس العمل",AG26,IF(COUNTIFS('سجل الإجازات والحالات'!$B$6:$B$505,B26,'سجل الإجازات والحالات'!$E$6:$E$505,"<="&cfg_VAL_DATE,'سجل الإجازات والحالات'!$F$6:$F$505,">="&cfg_VAL_DATE)>0,"✈ "&INDEX('سجل الإجازات والحالات'!$D$6:$D$505,MATCH(1,INDEX(('سجل الإجازات والحالات'!$B$6:$B$505=B26)*('سجل الإجازات والحالات'!$E$6:$E$505<=cfg_VAL_DATE)*('سجل الإجازات والحالات'!$F$6:$F$505>=cfg_VAL_DATE),0),0)),"✔ على رأس العمل")))
A27: =IF(B27="","",ROW()-5) | P27: =IF(B27="","",SUM(L27:O27)) | Q27: =IF(B27="","",L27+IF(cfg_EOS_H="نعم",M27,0)+IF(cfg_EOS_T="نعم",N27,0)+IF(cfg_EOS_O="نعم",O27,0)) | R27: =IF(B27="","",L27+IF(cfg_LV_H="نعم",M27,0)+IF(cfg_LV_T="نعم",N27,0)+IF(cfg_LV_O="نعم",O27,0)) | S27: =IF(B27="","",MIN(cfg_G_CAP,L27+M27)) | AB27: =IF(B27="","",IF(X27<>"",X27,IF(E27="غير سعودي",cfg_IQ,0))+IF(Y27<>"",Y27,IF(E27="غير سعودي",cfg_WP,0))+IF(Z27<>"",Z27,cfg_MED)+N(AA27)) | AG27: =IF(B27="","",IF(AND(AE27<>"",AE27<=cfg_VAL_DATE),"✖ منتهي الخدمة",IF(H27>cfg_VAL_DATE,"⏳ لم يباشر بعد","✔ على رأس العمل"))) | AH27: =IF(B27="","",IF(AG27<>"✔ على رأس العمل",AG27,IF(COUNTIFS('سجل الإجازات والحالات'!$B$6:$B$505,B27,'سجل الإجازات والحالات'!$E$6:$E$505,"<="&cfg_VAL_DATE,'سجل الإجازات والحالات'!$F$6:$F$505,">="&cfg_VAL_DATE)>0,"✈ "&INDEX('سجل الإجازات والحالات'!$D$6:$D$505,MATCH(1,INDEX(('سجل الإجازات والحالات'!$B$6:$B$505=B27)*('سجل الإجازات والحالات'!$E$6:$E$505<=cfg_VAL_DATE)*('سجل الإجازات والحالات'!$F$6:$F$505>=cfg_VAL_DATE),0),0)),"✔ على رأس العمل")))
A28: =IF(B28="","",ROW()-5) | P28: =IF(B28="","",SUM(L28:O28)) | Q28: =IF(B28="","",L28+IF(cfg_EOS_H="نعم",M28,0)+IF(cfg_EOS_T="نعم",N28,0)+IF(cfg_EOS_O="نعم",O28,0)) | R28: =IF(B28="","",L28+IF(cfg_LV_H="نعم",M28,0)+IF(cfg_LV_T="نعم",N28,0)+IF(cfg_LV_O="نعم",O28,0)) | S28: =IF(B28="","",MIN(cfg_G_CAP,L28+M28)) | AB28: =IF(B28="","",IF(X28<>"",X28,IF(E28="غير سعودي",cfg_IQ,0))+IF(Y28<>"",Y28,IF(E28="غير سعودي",cfg_WP,0))+IF(Z28<>"",Z28,cfg_MED)+N(AA28)) | AG28: =IF(B28="","",IF(AND(AE28<>"",AE28<=cfg_VAL_DATE),"✖ منتهي الخدمة",IF(H28>cfg_VAL_DATE,"⏳ لم يباشر بعد","✔ على رأس العمل"))) | AH28: =IF(B28="","",IF(AG28<>"✔ على رأس العمل",AG28,IF(COUNTIFS('سجل الإجازات والحالات'!$B$6:$B$505,B28,'سجل الإجازات والحالات'!$E$6:$E$505,"<="&cfg_VAL_DATE,'سجل الإجازات والحالات'!$F$6:$F$505,">="&cfg_VAL_DATE)>0,"✈ "&INDEX('سجل الإجازات والحالات'!$D$6:$D$505,MATCH(1,INDEX(('سجل الإجازات والحالات'!$B$6:$B$505=B28)*('سجل الإجازات والحالات'!$E$6:$E$505<=cfg_VAL_DATE)*('سجل الإجازات والحالات'!$F$6:$F$505>=cfg_VAL_DATE),0),0)),"✔ على رأس العمل")))
A29: =IF(B29="","",ROW()-5) | P29: =IF(B29="","",SUM(L29:O29)) | Q29: =IF(B29="","",L29+IF(cfg_EOS_H="نعم",M29,0)+IF(cfg_EOS_T="نعم",N29,0)+IF(cfg_EOS_O="نعم",O29,0)) | R29: =IF(B29="","",L29+IF(cfg_LV_H="نعم",M29,0)+IF(cfg_LV_T="نعم",N29,0)+IF(cfg_LV_O="نعم",O29,0)) | S29: =IF(B29="","",MIN(cfg_G_CAP,L29+M29)) | AB29: =IF(B29="","",IF(X29<>"",X29,IF(E29="غير سعودي",cfg_IQ,0))+IF(Y29<>"",Y29,IF(E29="غير سعودي",cfg_WP,0))+IF(Z29<>"",Z29,cfg_MED)+N(AA29)) | AG29: =IF(B29="","",IF(AND(AE29<>"",AE29<=cfg_VAL_DATE),"✖ منتهي الخدمة",IF(H29>cfg_VAL_DATE,"⏳ لم يباشر بعد","✔ على رأس العمل"))) | AH29: =IF(B29="","",IF(AG29<>"✔ على رأس العمل",AG29,IF(COUNTIFS('سجل الإجازات والحالات'!$B$6:$B$505,B29,'سجل الإجازات والحالات'!$E$6:$E$505,"<="&cfg_VAL_DATE,'سجل الإجازات والحالات'!$F$6:$F$505,">="&cfg_VAL_DATE)>0,"✈ "&INDEX('سجل الإجازات والحالات'!$D$6:$D$505,MATCH(1,INDEX(('سجل الإجازات والحالات'!$B$6:$B$505=B29)*('سجل الإجازات والحالات'!$E$6:$E$505<=cfg_VAL_DATE)*('سجل الإجازات والحالات'!$F$6:$F$505>=cfg_VAL_DATE),0),0)),"✔ على رأس العمل")))
... A105: =IF(B105="","",ROW()-5) | P105: =IF(B105="","",SUM(L105:O105)) | Q105: =IF(B105="","",L105+IF(cfg_EOS_H="نعم",M105,0)+IF(cfg_EOS_T="نعم",N105,0)+IF(cfg_EOS_O="نعم",O105,0)) | R105: =IF(B105="","",L105+IF(cfg_LV_H="نعم",M105,0)+IF(cfg_LV_T="نعم",N105,0)+IF(cfg_LV_O="نعم",O105,0)) | S105: =IF(B105="","",MIN(cfg_G_CAP,L105+M105)) | AB105: =IF(B105="","",IF(X105<>"",X105,IF(E105="غير سعودي",cfg_IQ,0))+IF(Y105<>"",Y105,IF(E105="غير سعودي",cfg_WP,0))+IF(Z105<>"",Z105,cfg_MED)+N(AA105)) | AG105: =IF(B105="","",IF(AND(AE105<>"",AE105<=cfg_VAL_DATE),"✖ منتهي الخدمة",IF(H105>cfg_VAL_DATE,"⏳ لم يباشر بعد","✔ على رأس العمل"))) | AH105: =IF(B105="","",IF(AG105<>"✔ على رأس العمل",AG105,IF(COUNTIFS('سجل الإجازات والحالات'!$B$6:$B$505,B105,'سجل الإجازات والحالات'!$E$6:$E$505,"<="&cfg_VAL_DATE,'سجل الإجازات والحالات'!$F$6:$F$505,">="&cfg_VAL_DATE)>0,"✈ "&INDEX('سجل الإجازات والحالات'!$D$6:$D$505,MATCH(1,INDEX(('سجل الإجازات والحالات'!$B$6:$B$505=B105)*('سجل الإجازات والحالات'!$E$6:$E$505<=cfg_VAL_DATE)*('سجل الإجازات والحالات'!$F$6:$F$505>=cfg_VAL_DATE),0),0)),"✔ على رأس العمل")))
B106: =COUNTA(B6:B105)&" موظف" -> 12 موظف | C106: الإجمالي | L106: =SUM(L6:L105) -> 141500 | M106: =SUM(M6:M105) -> 35375 | N106: =SUM(N6:N105) -> 14150 | O106: =SUM(O6:O105) -> 10300 | P106: =SUM(P6:P105) -> 201325 | Q106: =SUM(Q6:Q105) -> 191025 | R106: =SUM(R6:R105) -> 191025 | S106: =SUM(S6:S105) -> 176875 | V106: =SUM(V6:V105) -> 15300 | AB106: =SUM(AB6:AB105) -> 89650 | AD106: =SUM(AD6:AD105) -> 8700

Sheet سجل الإجازات والحالات
A1: 🌴 سجل الإجازات والحالات — الإجازات والإيقاف ووقف الراتب بالتواريخ 🔒 نسخة تجريبية
A2: ="🛒 نسخة تجريبية — للنسخة الكاملة اضغط هنا ← accopro.net | "&cfg_CO&" | السنة المالية "&cfg_FY&" | شهر التقرير: "&INDEX(L_MONTH,cfg_VAL_M)&" | المبالغ بـ "&cfg_CUR -> 🛒 نسخة تجريبية — للنسخة الكاملة اضغط هنا ← accopro.net | شركة النخبة للتجارة والمقاولات | السنة المالية 2026 | شهر التقرير: سبتمبر | المبالغ بـ ريال سعودي
A3: 🏠 الرئيسية | B3: 📊 لوحة التحكم | C3: ⚙ الإعدادات | D3: 👥 الموظفون | E3: ✍ الحركات | F3: 🪪 الإقامات | G3: 📅 الملخص الشهري | H3: 🧾 القيود | I3: 💳 القسيمة
A4: 🧪 خانات التجربة: أول 10 سجلات — للمزيد اشترِ النسخة الكاملة | V4: أيام مخصومة من الراتب في كل شهر | AH4: أيام خارج الخدمة (تراكمي حتى نهاية الشهر) | AT4: أيام مخصومة من رصيد الإجازة في الشهر
A5: م | B5: الرقم الوظيفي | C5: اسم الموظف (تلقائي) | D5: نوع الإجازة / الحالة | E5: من تاريخ | F5: إلى تاريخ (آخر يوم) | G5: عدد الأيام | H5: نسبة الأجر حسب النوع | I5: نسبة أجر مخصصة (اختياري) | J5: نسبة الأجر المطبقة | K5: يخصم من رصيد الإجازة؟ | L5: يحتسب في الخدمة؟ | M5: راتب مقدم؟ | N5: مبلغ راتب الإجازة المقدم | O5: شهر صرف المقدم | P5: الحالة | Q5: ملاحظات | R5: أيام خارج الخدمة حتى 31/12 السابق | S5: أيام خارج الخدمة حتى تاريخ التقرير | T5: أيام مخصومة من رصيد الإجازة (السنة حتى تاريخ التقرير) | V5: يناير | W5: فبراير | X5: مارس | Y5: أبريل | Z5: مايو | AA5: يونيو | AB5: يوليو | AC5: أغسطس | AD5: سبتمبر | AE5: أكتوبر | AF5: نوفمبر | AG5: ديسمبر | AH5: يناير | AI5: فبراير | AJ5: مارس | AK5: أبريل | AL5: مايو | AM5: يونيو | AN5: يوليو | AO5: أغسطس | AP5: سبتمبر | AQ5: أكتوبر | AR5: نوفمبر | AS5: ديسمبر | AT5: يناير | AU5: فبراير | AV5: مارس | AW5: أبريل | AX5: مايو | AY5: يونيو | AZ5: يوليو | BA5: أغسطس | BB5: سبتمبر | BC5: أكتوبر | BD5: نوفمبر | BE5: ديسمبر
