Workbook
Name ContractValue: 'بيانات العقد'!$C$16
Name VOApproved: 'بيانات العقد'!$C$17
Name RevisedContract: 'بيانات العقد'!$C$18
Name AdvPct: 'بيانات العقد'!$C$20
Name AdvAmount: 'بيانات العقد'!$C$21
Name RecRate: 'بيانات العقد'!$C$23
Name RecStart: 'بيانات العقد'!$C$24
Name RecFull: 'بيانات العقد'!$C$25
Name RetPct: 'بيانات العقد'!$C$27
Name RetCapPct: 'بيانات العقد'!$C$28
Name RetCap: 'بيانات العقد'!$C$29
Name VATPct: 'بيانات العقد'!$C$31
Name VATBeforeRet: 'بيانات العقد'!$C$32
Name WHTPct: 'بيانات العقد'!$C$33
Name StartDate: 'بيانات العقد'!$C$11
Name EndDate: 'بيانات العقد'!$C$13
Name L_Sections: 'بيانات العقد'!$F$6:$F$17
Name L_IPCStatus: 'بيانات العقد'!$G$6:$G$17
Name L_VOStatus: 'بيانات العقد'!$H$6:$H$17
Name L_TDType: 'بيانات العقد'!$I$6:$I$17
Name LatestIPC: 'لوحة التحكم'!$L$3
Name SelIPC: 'نموذج المستخلص'!$D$5

Sheet التعليمات
B1: 📘 دليل استخدام شيت تتبع المستخلصات — Payment Certificates & Billing Tracker
B2: نظام متكامل لاحتساب نسب الإنجاز والدفعة المقدمة وضمان الأعمال والاستقطاعات الفنية لكل مستخلص بالتراكمي
B3: 📊 الانتقال للوحة التحكم | C3: ⚙ ابدأ ببيانات العقد
B5: دليل الألوان
B6: إدخال يدوي | C6: خلايا صفراء بخط أزرق — هي الخلايا الوحيدة التي تُعدّل.
B7: معادلة محسوبة | C7: خط أسود — لا تكتب فوقها.
B8: ربط من شيت آخر | C8: خط أخضر — قيمة مسحوبة آلياً من شيت آخر.
B9: تنبيه | C9: تظليل أحمر/برتقالي: تجاوز كمية، كود مكرر، بيانات ناقصة، تأخر عن البرنامج.
B11: خطوات العمل
B12: بيانات العقد | C12: أدخل بيانات المشروع والنسب التعاقدية: الدفعة المقدمة وطريقة استردادها، ضمان الأعمال وحده الأقصى، الضرائب. يمكن تعديل القوائم المنسدلة من نفس الشيت.
B13: جدول الكميات | C13: أدخل بنود جدول الكميات (كود فريد، القسم، الوصف، الوحدة، الكمية، السعر). الإجمالي = قيمة العقد الأصلية.
B14: الكميات المنفذة | C14: في كل مستخلص أدخل الكمية المنفذة خلال الفترة فقط تحت عمود رقم المستخلص؛ يتم حساب التراكمي ونسبة إنجاز كل بند وتنبيه تجاوز الكمية التعاقدية آلياً.
B15: الأوامر التغييرية | C15: سجل الأوامر التغييرية: قيمة الأمر تعدّل قيمة العقد عند الاعتماد، والقيمة المدرجة تدخل المستخلص المحدد.
B16: الاستقطاعات الفنية | C16: سجل الاستقطاعات الفنية برقم المستخلص الذي خُصمت منه، وعند المعالجة اختر «نعم» وحدد مستخلص الإفراج.
B17: سجل المستخلصات | C17: أدخل تواريخ المستخلص (إدخال «الفترة إلى» يُفعّل المستخلص)، الحالة، رصيد المواد بالموقع، النسبة المخططة، الإفراج عن الضمان والغرامات إن وجدت، ثم بيانات التحصيل. كل الحسابات تراكمية.
B18: نموذج المستخلص | C18: اختر رقم المستخلص من الخلية الصفراء لعرض شهادة الدفع (سابق / حالي / تراكمي) مع تفاصيل البنود، جاهزة للطباعة.
B19: لوحة التحكم | C19: تابع المؤشرات: الإنجاز الفعلي مقابل المخطط، SPI، الموقف المالي، التحصيل، المحتجزات، والرسوم البيانية.
B21: منطق الاحتساب (كل القيم تراكمية ثم: الحالي = التراكمي − السابق)
B22: قيمة الأعمال المنفذة | C22: Σ (سعر الوحدة × مجموع كميات البند حتى المستخلص الحالي) — SUMPRODUCT ديناميكي على مصفوفة الكميات.
B23: نسبة الإنجاز | C23: (الأعمال المنفذة + التغييرية المدرجة) ÷ (قيمة العقد الأصلية + التغييرية المدرجة).
B24: استرداد الدفعة المقدمة | C24: MIN(قيمة الدفعة ، MAX(0 ، الأعمال − نسبة البدء × العقد) × نسبة الاسترداد)، ويُسترد كامل الرصيد عند بلوغ نسبة «الاسترداد الكامل».
B25: ضمان الأعمال | C25: MIN(إجمالي القيمة التراكمية × نسبة الضمان ، الحد الأقصى) − مجموع المفرج عنه.
B26: الاستقطاعات الفنية | C26: مجموع المستقطع حتى المستخلص − مجموع المفرج عنه حتى المستخلص (SUMIFS).
B27: الصافي قبل الضرائب | C27: إجمالي القيمة − الاسترداد − صافي الضمان − الاستقطاعات الفنية − الغرامات التراكمية.
B28: ضريبة القيمة المضافة | C28: النسبة × (الصافي + الضمان إن كان الإعداد «نعم»).
B29: ضريبة الخصم من المنبع | C29: النسبة × (الصافي قبل خصم الضمان).
B30: المستحق الحالي | C30: صافي المستحق التراكمي للمستخلص − صافي المستحق التراكمي للمستخلص السابق.
B31: SPI | C31: نسبة الإنجاز الفعلية ÷ المخططة: أقل من 1 = تأخر، 1 أو أكثر = مطابق/متقدم.
B33: ملاحظات
B34: • | C34: البيانات الحالية مثال توضيحي لمشروع (6 مستخلصات) — امسح الخلايا الصفراء وابدأ ببيانات مشروعك.
B35: • | C35: السعة: 100 بند، 24 مستخلص، 50 أمر تغييري، 100 استقطاع فني. لا تحذف صفوفاً من داخل الجداول.
B36: • | C36: رقم «آخر مستخلص فعال» يُحدد آلياً ويُميَّز في السجل وفي شيت الكميات المنفذة باللون الذهبي.

Sheet لوحة التحكم
B1: 📊 لوحة تحكم المستخلصات — Payment Certificates & Billing Dashboard
B2: ='بيانات العقد'!$C$5&" | عقد رقم: "&'بيانات العقد'!$C$6&" | المبالغ بـ "&'بيانات العقد'!$C$14
B3: ⚙ بيانات العقد | C3: 📋 الكميات | D3: 📐 المنفذ | E3: 🔁 التغييرية | F3: ✂ الاستقطاعات | G3: 🗂 السجل | H3: 🧾 النموذج | J3: آخر مستخلص فعال: | L3: =SUMPRODUCT(MAX(('سجل المستخلصات'!$C$6:$C$29<>"")*'سجل المستخلصات'!$A$6:$A$29)) | N3: =IF(L3=0,"",TEXT(INDEX('سجل المستخلصات'!$C$6:$C$29,L3),"yyyy/mm/dd"))
B5: المؤشرات التعاقدية والإنجاز
B6: قيمة العقد الأصلية | E6: صافي الأوامر التغييرية | H6: قيمة العقد المعدلة | K6: إجمالي قيمة الأعمال التراكمية | N6: الأعمال المتبقية
B7: =ContractValue | E7: =VOApproved | H7: =RevisedContract | K7: =IF(LatestIPC=0,0,N(INDEX('سجل المستخلصات'!$K$6:$K$29,LatestIPC))) | N7: =RevisedContract-IF(LatestIPC=0,0,N(INDEX('سجل المستخلصات'!$G$6:$G$29,LatestIPC)))-IF(LatestIPC=0,0,N(INDEX('سجل المستخلصات'!$I$6:$I$29,LatestIPC)))
B9: نسبة الإنجاز الفعلية | E9: نسبة الإنجاز المخططة | H9: الانحراف (فعلي - مخطط) | K9: نسبة المدة المنقضية | N9: مؤشر أداء الجدول (SPI)
B10: =IF(LatestIPC=0,0,N(INDEX('سجل المستخلصات'!$L$6:$L$29,LatestIPC))) | E10: =IF(LatestIPC=0,0,N(INDEX('سجل المستخلصات'!$M$6:$M$29,LatestIPC))) | H10: =B10-E10 | K10: =IF(LatestIPC=0,0,MIN(1,MAX(0,(INDEX('سجل المستخلصات'!$C$6:$C$29,LatestIPC)-StartDate+1)/(EndDate-StartDate+1)))) | N10: =IF(E10>0,B10/E10,0)
B12: الموقف المالي والتحصيل
B13: صافي المستحق التراكمي | E13: إجمالي المحصل | H13: مستحقات غير محصلة | K13: نسبة التحصيل | N13: متوسط مدة التحصيل (يوم)
B14: =IF(LatestIPC=0,0,N(INDEX('سجل المستخلصات'!$X$6:$X$29,LatestIPC))) | E14: =SUM('سجل المستخلصات'!$AA$6:$AA$29) | H14: =SUM('سجل المستخلصات'!$AC$6:$AC$29) | K14: =IF(B14>0,E14/B14,0) | N14: =IFERROR(AVERAGE('سجل المستخلصات'!$AD$6:$AD$29),0)
B16: ضمان الأعمال المحتجز | E16: رصيد الدفعة المقدمة غير المسترد | H16: الاستقطاعات الفنية المحتجزة | K16: إجمالي الغرامات والخصومات | N16: صافي المستحق - آخر مستخلص
B17: =IF(LatestIPC=0,0,N(INDEX('سجل المستخلصات'!$R$6:$R$29,LatestIPC))) | E17: =AdvAmount-IF(LatestIPC=0,0,N(INDEX('سجل المستخلصات'!$O$6:$O$29,LatestIPC))) | H17: =IF(LatestIPC=0,0,N(INDEX('سجل المستخلصات'!$S$6:$S$29,LatestIPC))) | K17: =SUM('سجل المستخلصات'!$T$6:$T$29) | N17: =IF(LatestIPC=0,0,N(INDEX('سجل المستخلصات'!$Z$6:$Z$29,LatestIPC)))
B19: الإنجاز حسب أقسام الأعمال | J19: توزيع قيمة العقد المعدلة
B20: القسم | E20: القيمة التعاقدية | F20: القيمة المنفذة | G20: نسبة الإنجاز | H20: الوزن من العقد | J20: البند | N20: القيمة | P20: النسبة
B21: ='بيانات العقد'!F6 | E21: =SUMIF('جدول الكميات'!$C$6:$C$105,B21,'جدول الكميات'!$H$6:$H$105) | F21: =SUMIF('الكميات المنفذة'!$D$6:$D$105,B21,'الكميات المنفذة'!$AH$6:$AH$105) | G21: =IF(E21>0,F21/E21,0) | H21: =IF(ContractValue>0,E21/ContractValue,0) | J21: صافي الأعمال المعتمدة قبل الضرائب | N21: =IF(LatestIPC=0,0,N(INDEX('سجل المستخلصات'!$U$6:$U$29,LatestIPC))) | P21: =IF($N$27>0,N21/$N$27,0)
B22: ='بيانات العقد'!F7 | E22: =SUMIF('جدول الكميات'!$C$6:$C$105,B22,'جدول الكميات'!$H$6:$H$105) | F22: =SUMIF('الكميات المنفذة'!$D$6:$D$105,B22,'الكميات المنفذة'!$AH$6:$AH$105) | G22: =IF(E22>0,F22/E22,0) | H22: =IF(ContractValue>0,E22/ContractValue,0) | J22: دفعة مقدمة مستردة | N22: =IF(LatestIPC=0,0,N(INDEX('سجل المستخلصات'!$O$6:$O$29,LatestIPC))) | P22: =IF($N$27>0,N22/$N$27,0)
B23: ='بيانات العقد'!F8 | E23: =SUMIF('جدول الكميات'!$C$6:$C$105,B23,'جدول الكميات'!$H$6:$H$105) | F23: =SUMIF('الكميات المنفذة'!$D$6:$D$105,B23,'الكميات المنفذة'!$AH$6:$AH$105) | G23: =IF(E23>0,F23/E23,0) | H23: =IF(ContractValue>0,E23/ContractValue,0) | J23: ضمان أعمال محتجز | N23: =B17 | P23: =IF($N$27>0,N23/$N$27,0)
B24: ='بيانات العقد'!F9 | E24: =SUMIF('جدول الكميات'!$C$6:$C$105,B24,'جدول الكميات'!$H$6:$H$105) | F24: =SUMIF('الكميات المنفذة'!$D$6:$D$105,B24,'الكميات المنفذة'!$AH$6:$AH$105) | G24: =IF(E24>0,F24/E24,0) | H24: =IF(ContractValue>0,E24/ContractValue,0) | J24: استقطاعات فنية وغرامات | N24: =H17+K17 | P24: =IF($N$27>0,N24/$N$27,0)
B25: ='بيانات العقد'!F10 | E25: =SUMIF('جدول الكميات'!$C$6:$C$105,B25,'جدول الكميات'!$H$6:$H$105) | F25: =SUMIF('الكميات المنفذة'!$D$6:$D$105,B25,'الكميات المنفذة'!$AH$6:$AH$105) | G25: =IF(E25>0,F25/E25,0) | H25: =IF(ContractValue>0,E25/ContractValue,0) | J25: أعمال متبقية | N25: =MAX(0,N7) | P25: =IF($N$27>0,N25/$N$27,0)
B26: ='بيانات العقد'!F11 | E26: =SUMIF('جدول الكميات'!$C$6:$C$105,B26,'جدول الكميات'!$H$6:$H$105) | F26: =SUMIF('الكميات المنفذة'!$D$6:$D$105,B26,'الكميات المنفذة'!$AH$6:$AH$105) | G26: =IF(E26>0,F26/E26,0) | H26: =IF(ContractValue>0,E26/ContractValue,0) | J26: مواد موردة بالموقع | N26: =IF(LatestIPC=0,0,N(INDEX('سجل المستخلصات'!$J$6:$J$29,LatestIPC))) | P26: =IF($N$27>0,N26/$N$27,0)
B27: ='بيانات العقد'!F12 | E27: =SUMIF('جدول الكميات'!$C$6:$C$105,B27,'جدول الكميات'!$H$6:$H$105) | F27: =SUMIF('الكميات المنفذة'!$D$6:$D$105,B27,'الكميات المنفذة'!$AH$6:$AH$105) | G27: =IF(E27>0,F27/E27,0) | H27: =IF(ContractValue>0,E27/ContractValue,0) | J27: الإجمالي | N27: =SUM(N21:O26) | P27: =SUM(P21:P26)
B28: ='بيانات العقد'!F13 | E28: =SUMIF('جدول الكميات'!$C$6:$C$105,B28,'جدول الكميات'!$H$6:$H$105) | F28: =SUMIF('الكميات المنفذة'!$D$6:$D$105,B28,'الكميات المنفذة'!$AH$6:$AH$105) | G28: =IF(E28>0,F28/E28,0) | H28: =IF(ContractValue>0,E28/ContractValue,0) | J28: ملاحظة: الإجمالي = قيمة العقد المعدلة + رصيد المواد بالموقع (المبالغ قبل الضرائب).
B29: ='بيانات العقد'!F14 | E29: =SUMIF('جدول الكميات'!$C$6:$C$105,B29,'جدول الكميات'!$H$6:$H$105) | F29: =SUMIF('الكميات المنفذة'!$D$6:$D$105,B29,'الكميات المنفذة'!$AH$6:$AH$105) | G29: =IF(E29>0,F29/E29,0) | H29: =IF(ContractValue>0,E29/ContractValue,0)
B30: الإجمالي | E30: =SUM(E21:E29) | F30: =SUM(F21:F29) | G30: =IF(E30>0,F30/E30,0) | H30: =SUM(H21:H29)

Sheet بيانات العقد
B1: ⚙ بيانات العقد والإعدادات التعاقدية
B2: ='بيانات العقد'!$C$5&" | عقد رقم: "&'بيانات العقد'!$C$6&" | المبالغ بـ "&'بيانات العقد'!$C$14
B3: 📊 لوحة التحكم | C3: 📋 الكميات | D3: 📐 المنفذ | F3: 🔁 التغييرية | G3: ✂ الاستقطاعات | H3: 🗂 السجل | I3: 🧾 النموذج
B4: البيان | C4: القيمة | D4: ملاحظات / الأساس التعاقدي | F4: القوائم المنسدلة (قابلة للتعديل)
B5: اسم المشروع | C5: مشروع إنشاء المبنى الإداري - المرحلة الأولى | D5: يظهر في جميع الشيتات والنموذج | F5: أقسام الأعمال | G5: حالة المستخلص | H5: حالة الأمر التغييري | I5: نوع الاستقطاع الفني
B6: رقم العقد | C6: CT-2026-014 | F6: أعمال الحفر والردم | G6: مسودة | H6: معتمد | I6: أعمال غير مطابقة
B7: صاحب العمل (المالك) | C7: شركة النماء للتطوير العقاري | F7: الخرسانة العادية والمسلحة | G7: مقدم للاستشاري | H7: قيد الدراسة | I7: أعمال ناقصة
B8: الاستشاري / المهندس | C8: مكتب الهندسة المتحدة للاستشارات | F8: أعمال المباني | G8: تحت المراجعة | H8: مرفوض | I8: ملاحظات فنية
B9: المقاول | C9: شركة البناء الحديث للمقاولات | F9: أعمال العزل | G9: معتمد | I9: اختبارات غير مستكملة
B10: تاريخ توقيع العقد | C10: 46068 | F10: أعمال التشطيبات | G10: مرفوض | I10: مستندات غير مستكملة
B11: تاريخ بدء الأعمال (أمر المباشرة) | C11: 46082 | D11: بداية احتساب المدة الزمنية | F11: الأعمال الكهربائية | I11: أخرى
B12: مدة العقد (بالشهور) | C12: 18 | F12: الأعمال الصحية
B13: تاريخ الانتهاء التعاقدي | C13: =EDATE(C11,C12)-1 | D13: محسوب = البدء + المدة | F13: أعمال التكييف
B14: العملة | C14: جنيه مصري | D14: تظهر في عناوين الشيتات | F14: أعمال الموقع العام
B15: القيم التعاقدية
B16: قيمة العقد الأصلية | C16: ='جدول الكميات'!H106 | D16: مرتبطة تلقائياً بإجمالي جدول الكميات
B17: صافي الأوامر التغييرية المعتمدة | C17: =SUMIFS('الأوامر التغييرية'!$G$6:$G$55,'الأوامر التغييرية'!$H$6:$H$55,"معتمد") | D17: مرتبطة بشيت الأوامر التغييرية (المعتمدة فقط)
B18: قيمة العقد المعدلة | C18: =C16+C17 | D18: الأصلية + صافي التغييرية المعتمدة
B19: الدفعة المقدمة واستردادها
B20: نسبة الدفعة المقدمة | C20: 0.1 | D20: من قيمة العقد الأصلية
B21: قيمة الدفعة المقدمة | C21: =C16*C20 | D21: محسوبة
B22: تاريخ صرف الدفعة المقدمة | C22: 46091
B23: نسبة الاسترداد من قيمة الأعمال | C23: 0.125 | D23: تُخصم من كل مستخلص كنسبة من (الأعمال المنفذة + التغييرية)
B24: بدء الاسترداد عند نسبة إنجاز | C24: 0 | D24: مثال FIDIC: يبدأ الاسترداد بعد تجاوز 10% من قيمة العقد
B25: استرداد كامل الرصيد عند نسبة إنجاز | C25: 0.8 | D25: عند بلوغ هذه النسبة يُسترد كامل الرصيد المتبقي
B26: ضمان الأعمال
B27: نسبة ضمان الأعمال (المحتجزات) | C27: 0.1 | D27: تُحتجز من إجمالي قيمة الأعمال التراكمية
B28: الحد الأقصى للضمان (% من العقد المعدل) | C28: 0.05 | D28: يتوقف الاحتجاز عند بلوغ الحد
B29: الحد الأقصى للضمان (قيمة) | C29: =C18*C28 | D29: محسوب
B30: الضرائب
B31: نسبة ضريبة القيمة المضافة | C31: 0.14 | D31: ضع 0% إن لم تكن مطبقة
B32: احتساب الضريبة قبل خصم الضمان؟ | C32: نعم | D32: نعم = وعاء الضريبة يشمل مبلغ الضمان المحتجز
B33: نسبة ضريبة الخصم من المنبع | C33: 0.01 | D33: تُحسب على صافي القيمة قبل خصم الضمان - ضع 0% إن لم تطبق

Sheet جدول الكميات
A1: 📋 جدول الكميات والأسعار التعاقدي (BOQ)
A2: ='بيانات العقد'!$C$5&" | عقد رقم: "&'بيانات العقد'!$C$6&" | المبالغ بـ "&'بيانات العقد'!$C$14
A3: 📊 لوحة التحكم | B3: ⚙ بيانات العقد | C3: 📐 المنفذ | D3: 🔁 التغييرية | F3: ✂ الاستقطاعات | G3: 🗂 السجل | H3: 🧾 النموذج
A4: أدخل بنود العقد في الخلايا الصفراء فقط (حتى 100 بند) — الإجمالي يغذي قيمة العقد تلقائياً.
A5: م | B5: كود البند | C5: القسم | D5: وصف البند | E5: الوحدة | F5: الكمية التعاقدية | G5: سعر الوحدة | H5: الإجمالي | I5: الوزن النسبي
A6: =IF(B6="","",COUNTA($B$6:B6)) | B6: 01-001 | C6: أعمال الحفر والردم | D6: حفر عام للأساسات حتى المنسوب التصميمي مع نقل الناتج | E6: م3 | F6: 4500 | G6: 120 | H6: =F6*G6 | I6: =IF($H$106>0,H6/$H$106,0)
A7: =IF(B7="","",COUNTA($B$6:B7)) | B7: 01-002 | C7: أعمال الحفر والردم | D7: ردم بناتج الحفر على طبقات مع الدمك والرش | E7: م3 | F7: 2200 | G7: 85 | H7: =F7*G7 | I7: =IF($H$106>0,H7/$H$106,0)
A8: =IF(B8="","",COUNTA($B$6:B8)) | B8: 01-003 | C8: أعمال الحفر والردم | D8: إحلال تربة بخليط الزلط والرمل بنسبة 1:1 مع الدمك | E8: م3 | F8: 1800 | G8: 450 | H8: =F8*G8 | I8: =IF($H$106>0,H8/$H$106,0)
A9: =IF(B9="","",COUNTA($B$6:B9)) | B9: 02-001 | C9: الخرسانة العادية والمسلحة | D9: خرسانة عادية للأساسات عيار 250 كجم أسمنت | E9: م3 | F9: 380 | G9: 2600 | H9: =F9*G9 | I9: =IF($H$106>0,H9/$H$106,0)
A10: =IF(B10="","",COUNTA($B$6:B10)) | B10: 02-002 | C10: الخرسانة العادية والمسلحة | D10: خرسانة مسلحة للقواعد والسملات (بدون حديد) | E10: م3 | F10: 950 | G10: 6800 | H10: =F10*G10 | I10: =IF($H$106>0,H10/$H$106,0)
A11: =IF(B11="","",COUNTA($B$6:B11)) | B11: 02-003 | C11: الخرسانة العادية والمسلحة | D11: خرسانة مسلحة للأعمدة والحوائط الخرسانية | E11: م3 | F11: 420 | G11: 7500 | H11: =F11*G11 | I11: =IF($H$106>0,H11/$H$106,0)
A12: =IF(B12="","",COUNTA($B$6:B12)) | B12: 02-004 | C12: الخرسانة العادية والمسلحة | D12: خرسانة مسلحة للأسقف والكمرات والسلالم | E12: م3 | F12: 1650 | G12: 7200 | H12: =F12*G12 | I12: =IF($H$106>0,H12/$H$106,0)
A13: =IF(B13="","",COUNTA($B$6:B13)) | B13: 02-005 | C13: الخرسانة العادية والمسلحة | D13: توريد وتركيب حديد تسليح عالي المقاومة | E13: طن | F13: 480 | G13: 48000 | H13: =F13*G13 | I13: =IF($H$106>0,H13/$H$106,0)
A14: =IF(B14="","",COUNTA($B$6:B14)) | B14: 03-001 | C14: أعمال المباني | D14: مباني طوب أسمنتي مصمت سمك 20 سم | E14: م2 | F14: 7800 | G14: 380 | H14: =F14*G14 | I14: =IF($H$106>0,H14/$H$106,0)
A15: =IF(B15="","",COUNTA($B$6:B15)) | B15: 03-002 | C15: أعمال المباني | D15: مباني طوب أسمنتي سمك 12 سم للقواطيع | E15: م2 | F15: 3600 | G15: 290 | H15: =F15*G15 | I15: =IF($H$106>0,H15/$H$106,0)
A16: =IF(B16="","",COUNTA($B$6:B16)) | B16: 04-001 | C16: أعمال العزل | D16: عزل رطوبة للأساسات بالبيتومين على وجهين | E16: م2 | F16: 2400 | G16: 160 | H16: =F16*G16 | I16: =IF($H$106>0,H16/$H$106,0)
A17: =IF(B17="","",COUNTA($B$6:B17)) | B17: 04-002 | C17: أعمال العزل | D17: عزل مائي وحراري للأسطح بالأغشية والفوم | E17: م2 | F17: 1900 | G17: 650 | H17: =F17*G17 | I17: =IF($H$106>0,H17/$H$106,0)
... A35: =IF(B35="","",COUNTA($B$6:B35)) | B35: 09-002 | C35: أعمال الموقع العام | D35: أعمال إنترلوك سمك 8 سم على طبقة رمل | E35: م2 | F35: 3500 | G35: 420 | H35: =F35*G35 | I35: =IF($H$106>0,H35/$H$106,0)
A36: =IF(B36="","",COUNTA($B$6:B36)) | H36: =F36*G36 | I36: =IF($H$106>0,H36/$H$106,0)
A37: =IF(B37="","",COUNTA($B$6:B37)) | H37: =F37*G37 | I37: =IF($H$106>0,H37/$H$106,0)
A38: =IF(B38="","",COUNTA($B$6:B38)) | H38: =F38*G38 | I38: =IF($H$106>0,H38/$H$106,0)
A39: =IF(B39="","",COUNTA($B$6:B39)) | H39: =F39*G39 | I39: =IF($H$106>0,H39/$H$106,0)
A40: =IF(B40="","",COUNTA($B$6:B40)) | H40: =F40*G40 | I40: =IF($H$106>0,H40/$H$106,0)
A41: =IF(B41="","",COUNTA($B$6:B41)) | H41: =F41*G41 | I41: =IF($H$106>0,H41/$H$106,0)
A42: =IF(B42="","",COUNTA($B$6:B42)) | H42: =F42*G42 | I42: =IF($H$106>0,H42/$H$106,0)
A43: =IF(B43="","",COUNTA($B$6:B43)) | H43: =F43*G43 | I43: =IF($H$106>0,H43/$H$106,0)
A44: =IF(B44="","",COUNTA($B$6:B44)) | H44: =F44*G44 | I44: =IF($H$106>0,H44/$H$106,0)
A45: =IF(B45="","",COUNTA($B$6:B45)) | H45: =F45*G45 | I45: =IF($H$106>0,H45/$H$106,0)
A46: =IF(B46="","",COUNTA($B$6:B46)) | H46: =F46*G46 | I46: =IF($H$106>0,H46/$H$106,0)
A47: =IF(B47="","",COUNTA($B$6:B47)) | H47: =F47*G47 | I47: =IF($H$106>0,H47/$H$106,0)
... A105: =IF(B105="","",COUNTA($B$6:B105)) | H105: =F105*G105 | I105: =IF($H$106>0,H105/$H$106,0)
A106: إجمالي قيمة العقد الأصلية | H106: =SUM(H6:H105) | I106: =SUM(I6:I105)

Sheet الكميات المنفذة
A1: 📐 الكميات المنفذة خلال كل مستخلص (حصر الأعمال)
A2: ='بيانات العقد'!$C$5&" | عقد رقم: "&'بيانات العقد'!$C$6&" | المبالغ بـ "&'بيانات العقد'!$C$14
A3: 📊 لوحة التحكم | B3: ⚙ بيانات العقد | D3: 📋 الكميات | E3: 🔁 التغييرية | F3: ✂ الاستقطاعات | G3: 🗂 السجل | H3: 🧾 النموذج | J3: أدخل كمية الفترة فقط (غير تراكمية) أمام كل بند تحت رقم المستخلص — يتم حساب التراكمي آلياً.
G4: الكميات المنفذة خلال الفترة (إدخال) | AE4: التحليل التراكمي (محسوب)
A5: كود البند | B5: وصف البند | C5: الوحدة | D5: القسم | E5: الكمية التعاقدية | F5: سعر الوحدة | G5: 1 | H5: 2 | I5: 3 | J5: 4 | K5: 5 | L5: 6 | M5: 7 | N5: 8 | O5: 9 | P5: 10 | Q5: 11 | R5: 12 | S5: 13 | T5: 14 | U5: 15 | V5: 16 | W5: 17 | X5: 18 | Y5: 19 | Z5: 20 | AA5: 21 | AB5: 22 | AC5: 23 | AD5: 24 | AE5: إجمالي الكمية المنفذة | AF5: الكمية المتبقية | AG5: نسبة إنجاز البند | AH5: القيمة المنفذة التراكمية | AI5: حالة البند
A6: =IF('جدول الكميات'!B6="","",'جدول الكميات'!B6) | B6: =IF('جدول الكميات'!D6="","",'جدول الكميات'!D6) | C6: =IF('جدول الكميات'!E6="","",'جدول الكميات'!E6) | D6: =IF('جدول الكميات'!C6="","",'جدول الكميات'!C6) | E6: =N('جدول الكميات'!F6) | F6: =N('جدول الكميات'!G6) | G6: 1575 | H6: 1800 | I6: 900 | J6: 225 | AE6: =SUM(G6:AD6) | AF6: =E6-AE6 | AG6: =IF(E6>0,AE6/E6,0) | AH6: =AE6*F6 | AI6: =IF(A6="","",IF(AE6>E6+0.0001,"⚠ تجاوز الكمية",IF(AG6>=1,"✔ مكتمل",IF(AE6>0,"جاري التنفيذ","لم يبدأ"))))
A7: =IF('جدول الكميات'!B7="","",'جدول الكميات'!B7) | B7: =IF('جدول الكميات'!D7="","",'جدول الكميات'!D7) | C7: =IF('جدول الكميات'!E7="","",'جدول الكميات'!E7) | D7: =IF('جدول الكميات'!C7="","",'جدول الكميات'!C7) | E7: =N('جدول الكميات'!F7) | F7: =N('جدول الكميات'!G7) | H7: 330 | I7: 770 | J7: 660 | K7: 220 | AE7: =SUM(G7:AD7) | AF7: =E7-AE7 | AG7: =IF(E7>0,AE7/E7,0) | AH7: =AE7*F7 | AI7: =IF(A7="","",IF(AE7>E7+0.0001,"⚠ تجاوز الكمية",IF(AG7>=1,"✔ مكتمل",IF(AE7>0,"جاري التنفيذ","لم يبدأ"))))
A8: =IF('جدول الكميات'!B8="","",'جدول الكميات'!B8) | B8: =IF('جدول الكميات'!D8="","",'جدول الكميات'!D8) | C8: =IF('جدول الكميات'!E8="","",'جدول الكميات'!E8) | D8: =IF('جدول الكميات'!C8="","",'جدول الكميات'!C8) | E8: =N('جدول الكميات'!F8) | F8: =N('جدول الكميات'!G8) | G8: 720 | H8: 810 | I8: 270 | AE8: =SUM(G8:AD8) | AF8: =E8-AE8 | AG8: =IF(E8>0,AE8/E8,0) | AH8: =AE8*F8 | AI8: =IF(A8="","",IF(AE8>E8+0.0001,"⚠ تجاوز الكمية",IF(AG8>=1,"✔ مكتمل",IF(AE8>0,"جاري التنفيذ","لم يبدأ"))))
A9: =IF('جدول الكميات'!B9="","",'جدول الكميات'!B9) | B9: =IF('جدول الكميات'!D9="","",'جدول الكميات'!D9) | C9: =IF('جدول الكميات'!E9="","",'جدول الكميات'!E9) | D9: =IF('جدول الكميات'!C9="","",'جدول الكميات'!C9) | E9: =N('جدول الكميات'!F9) | F9: =N('جدول الكميات'!G9) | G9: 57 | H9: 171 | I9: 133 | J9: 19 | AE9: =SUM(G9:AD9) | AF9: =E9-AE9 | AG9: =IF(E9>0,AE9/E9,0) | AH9: =AE9*F9 | AI9: =IF(A9="","",IF(AE9>E9+0.0001,"⚠ تجاوز الكمية",IF(AG9>=1,"✔ مكتمل",IF(AE9>0,"جاري التنفيذ","لم يبدأ"))))
A10: =IF('جدول الكميات'!B10="","",'جدول الكميات'!B10) | B10: =IF('جدول الكميات'!D10="","",'جدول الكميات'!D10) | C10: =IF('جدول الكميات'!E10="","",'جدول الكميات'!E10) | D10: =IF('جدول الكميات'!C10="","",'جدول الكميات'!C10) | E10: =N('جدول الكميات'!F10) | F10: =N('جدول الكميات'!G10) | G10: 47.5 | H10: 332.5 | I10: 380 | J10: 142.5 | K10: 47.5 | AE10: =SUM(G10:AD10) | AF10: =E10-AE10 | AG10: =IF(E10>0,AE10/E10,0) | AH10: =AE10*F10 | AI10: =IF(A10="","",IF(AE10>E10+0.0001,"⚠ تجاوز الكمية",IF(AG10>=1,"✔ مكتمل",IF(AE10>0,"جاري التنفيذ","لم يبدأ"))))
A11: =IF('جدول الكميات'!B11="","",'جدول الكميات'!B11) | B11: =IF('جدول الكميات'!D11="","",'جدول الكميات'!D11) | C11: =IF('جدول الكميات'!E11="","",'جدول الكميات'!E11) | D11: =IF('جدول الكميات'!C11="","",'جدول الكميات'!C11) | E11: =N('جدول الكميات'!F11) | F11: =N('جدول الكميات'!G11) | H11: 21 | I11: 50.4 | J11: 58.8 | K11: 58.8 | L11: 63 | AE11: =SUM(G11:AD11) | AF11: =E11-AE11 | AG11: =IF(E11>0,AE11/E11,0) | AH11: =AE11*F11 | AI11: =IF(A11="","",IF(AE11>E11+0.0001,"⚠ تجاوز الكمية",IF(AG11>=1,"✔ مكتمل",IF(AE11>0,"جاري التنفيذ","لم يبدأ"))))
A12: =IF('جدول الكميات'!B12="","",'جدول الكميات'!B12) | B12: =IF('جدول الكميات'!D12="","",'جدول الكميات'!D12) | C12: =IF('جدول الكميات'!E12="","",'جدول الكميات'!E12) | D12: =IF('جدول الكميات'!C12="","",'جدول الكميات'!C12) | E12: =N('جدول الكميات'!F12) | F12: =N('جدول الكميات'!G12) | I12: 99 | J12: 165 | K12: 181.5 | L12: 198 | AE12: =SUM(G12:AD12) | AF12: =E12-AE12 | AG12: =IF(E12>0,AE12/E12,0) | AH12: =AE12*F12 | AI12: =IF(A12="","",IF(AE12>E12+0.0001,"⚠ تجاوز الكمية",IF(AG12>=1,"✔ مكتمل",IF(AE12>0,"جاري التنفيذ","لم يبدأ"))))
A13: =IF('جدول الكميات'!B13="","",'جدول الكميات'!B13) | B13: =IF('جدول الكميات'!D13="","",'جدول الكميات'!D13) | C13: =IF('جدول الكميات'!E13="","",'جدول الكميات'!E13) | D13: =IF('جدول الكميات'!C13="","",'جدول الكميات'!C13) | E13: =N('جدول الكميات'!F13) | F13: =N('جدول الكميات'!G13) | G13: 19.2 | H13: 67.2 | I13: 57.6 | J13: 48 | K13: 43.2 | L13: 48 | AE13: =SUM(G13:AD13) | AF13: =E13-AE13 | AG13: =IF(E13>0,AE13/E13,0) | AH13: =AE13*F13 | AI13: =IF(A13="","",IF(AE13>E13+0.0001,"⚠ تجاوز الكمية",IF(AG13>=1,"✔ مكتمل",IF(AE13>0,"جاري التنفيذ","لم يبدأ"))))
A14: =IF('جدول الكميات'!B14="","",'جدول الكميات'!B14) | B14: =IF('جدول الكميات'!D14="","",'جدول الكميات'!D14) | C14: =IF('جدول الكميات'!E14="","",'جدول الكميات'!E14) | D14: =IF('جدول الكميات'!C14="","",'جدول الكميات'!C14) | E14: =N('جدول الكميات'!F14) | F14: =N('جدول الكميات'!G14) | J14: 312 | K14: 546 | L14: 702 | AE14: =SUM(G14:AD14) | AF14: =E14-AE14 | AG14: =IF(E14>0,AE14/E14,0) | AH14: =AE14*F14 | AI14: =IF(A14="","",IF(AE14>E14+0.0001,"⚠ تجاوز الكمية",IF(AG14>=1,"✔ مكتمل",IF(AE14>0,"جاري التنفيذ","لم يبدأ"))))
A15: =IF('جدول الكميات'!B15="","",'جدول الكميات'!B15) | B15: =IF('جدول الكميات'!D15="","",'جدول الكميات'!D15) | C15: =IF('جدول الكميات'!E15="","",'جدول الكميات'!E15) | D15: =IF('جدول الكميات'!C15="","",'جدول الكميات'!C15) | E15: =N('جدول الكميات'!F15) | F15: =N('جدول الكميات'!G15) | K15: 108 | L15: 180 | AE15: =SUM(G15:AD15) | AF15: =E15-AE15 | AG15: =IF(E15>0,AE15/E15,0) | AH15: =AE15*F15 | AI15: =IF(A15="","",IF(AE15>E15+0.0001,"⚠ تجاوز الكمية",IF(AG15>=1,"✔ مكتمل",IF(AE15>0,"جاري التنفيذ","لم يبدأ"))))
A16: =IF('جدول الكميات'!B16="","",'جدول الكميات'!B16) | B16: =IF('جدول الكميات'!D16="","",'جدول الكميات'!D16) | C16: =IF('جدول الكميات'!E16="","",'جدول الكميات'!E16) | D16: =IF('جدول الكميات'!C16="","",'جدول الكميات'!C16) | E16: =N('جدول الكميات'!F16) | F16: =N('جدول الكميات'!G16) | H16: 720 | I16: 1200 | J16: 480 | AE16: =SUM(G16:AD16) | AF16: =E16-AE16 | AG16: =IF(E16>0,AE16/E16,0) | AH16: =AE16*F16 | AI16: =IF(A16="","",IF(AE16>E16+0.0001,"⚠ تجاوز الكمية",IF(AG16>=1,"✔ مكتمل",IF(AE16>0,"جاري التنفيذ","لم يبدأ"))))
A17: =IF('جدول الكميات'!B17="","",'جدول الكميات'!B17) | B17: =IF('جدول الكميات'!D17="","",'جدول الكميات'!D17) | C17: =IF('جدول الكميات'!E17="","",'جدول الكميات'!E17) | D17: =IF('جدول الكميات'!C17="","",'جدول الكميات'!C17) | E17: =N('جدول الكميات'!F17) | F17: =N('جدول الكميات'!G17) | AE17: =SUM(G17:AD17) | AF17: =E17-AE17 | AG17: =IF(E17>0,AE17/E17,0) | AH17: =AE17*F17 | AI17: =IF(A17="","",IF(AE17>E17+0.0001,"⚠ تجاوز الكمية",IF(AG17>=1,"✔ مكتمل",IF(AE17>0,"جاري التنفيذ","لم يبدأ"))))
A18: =IF('جدول الكميات'!B18="","",'جدول الكميات'!B18) | B18: =IF('جدول الكميات'!D18="","",'جدول الكميات'!D18) | C18: =IF('جدول الكميات'!E18="","",'جدول الكميات'!E18) | D18: =IF('جدول الكميات'!C18="","",'جدول الكميات'!C18) | E18: =N('جدول الكميات'!F18) | F18: =N('جدول الكميات'!G18) | AE18: =SUM(G18:AD18) | AF18: =E18-AE18 | AG18: =IF(E18>0,AE18/E18,0) | AH18: =AE18*F18 | AI18: =IF(A18="","",IF(AE18>E18+0.0001,"⚠ تجاوز الكمية",IF(AG18>=1,"✔ مكتمل",IF(AE18>0,"جاري التنفيذ","لم يبدأ"))))
A19: =IF('جدول الكميات'!B19="","",'جدول الكميات'!B19) | B19: =IF('جدول الكميات'!D19="","",'جدول الكميات'!D19) | C19: =IF('جدول الكميات'!E19="","",'جدول الكميات'!E19) | D19: =IF('جدول الكميات'!C19="","",'جدول الكميات'!C19) | E19: =N('جدول الكميات'!F19) | F19: =N('جدول الكميات'!G19) | AE19: =SUM(G19:AD19) | AF19: =E19-AE19 | AG19: =IF(E19>0,AE19/E19,0) | AH19: =AE19*F19 | AI19: =IF(A19="","",IF(AE19>E19+0.0001,"⚠ تجاوز الكمية",IF(AG19>=1,"✔ مكتمل",IF(AE19>0,"جاري التنفيذ","لم يبدأ"))))
A20: =IF('جدول الكميات'!B20="","",'جدول الكميات'!B20) | B20: =IF('جدول الكميات'!D20="","",'جدول الكميات'!D20) | C20: =IF('جدول الكميات'!E20="","",'جدول الكميات'!E20) | D20: =IF('جدول الكميات'!C20="","",'جدول الكميات'!C20) | E20: =N('جدول الكميات'!F20) | F20: =N('جدول الكميات'!G20) | AE20: =SUM(G20:AD20) | AF20: =E20-AE20 | AG20: =IF(E20>0,AE20/E20,0) | AH20: =AE20*F20 | AI20: =IF(A20="","",IF(AE20>E20+0.0001,"⚠ تجاوز الكمية",IF(AG20>=1,"✔ مكتمل",IF(AE20>0,"جاري التنفيذ","لم يبدأ"))))
A21: =IF('جدول الكميات'!B21="","",'جدول الكميات'!B21) | B21: =IF('جدول الكميات'!D21="","",'جدول الكميات'!D21) | C21: =IF('جدول الكميات'!E21="","",'جدول الكميات'!E21) | D21: =IF('جدول الكميات'!C21="","",'جدول الكميات'!C21) | E21: =N('جدول الكميات'!F21) | F21: =N('جدول الكميات'!G21) | AE21: =SUM(G21:AD21) | AF21: =E21-AE21 | AG21: =IF(E21>0,AE21/E21,0) | AH21: =AE21*F21 | AI21: =IF(A21="","",IF(AE21>E21+0.0001,"⚠ تجاوز الكمية",IF(AG21>=1,"✔ مكتمل",IF(AE21>0,"جاري التنفيذ","لم يبدأ"))))
A22: =IF('جدول الكميات'!B22="","",'جدول الكميات'!B22) | B22: =IF('جدول الكميات'!D22="","",'جدول الكميات'!D22) | C22: =IF('جدول الكميات'!E22="","",'جدول الكميات'!E22) | D22: =IF('جدول الكميات'!C22="","",'جدول الكميات'!C22) | E22: =N('جدول الكميات'!F22) | F22: =N('جدول الكميات'!G22) | AE22: =SUM(G22:AD22) | AF22: =E22-AE22 | AG22: =IF(E22>0,AE22/E22,0) | AH22: =AE22*F22 | AI22: =IF(A22="","",IF(AE22>E22+0.0001,"⚠ تجاوز الكمية",IF(AG22>=1,"✔ مكتمل",IF(AE22>0,"جاري التنفيذ","لم يبدأ"))))
A23: =IF('جدول الكميات'!B23="","",'جدول الكميات'!B23) | B23: =IF('جدول الكميات'!D23="","",'جدول الكميات'!D23) | C23: =IF('جدول الكميات'!E23="","",'جدول الكميات'!E23) | D23: =IF('جدول الكميات'!C23="","",'جدول الكميات'!C23) | E23: =N('جدول الكميات'!F23) | F23: =N('جدول الكميات'!G23) | AE23: =SUM(G23:AD23) | AF23: =E23-AE23 | AG23: =IF(E23>0,AE23/E23,0) | AH23: =AE23*F23 | AI23: =IF(A23="","",IF(AE23>E23+0.0001,"⚠ تجاوز الكمية",IF(AG23>=1,"✔ مكتمل",IF(AE23>0,"جاري التنفيذ","لم يبدأ"))))
A24: =IF('جدول الكميات'!B24="","",'جدول الكميات'!B24) | B24: =IF('جدول الكميات'!D24="","",'جدول الكميات'!D24) | C24: =IF('جدول الكميات'!E24="","",'جدول الكميات'!E24) | D24: =IF('جدول الكميات'!C24="","",'جدول الكميات'!C24) | E24: =N('جدول الكميات'!F24) | F24: =N('جدول الكميات'!G24) | AE24: =SUM(G24:AD24) | AF24: =E24-AE24 | AG24: =IF(E24>0,AE24/E24,0) | AH24: =AE24*F24 | AI24: =IF(A24="","",IF(AE24>E24+0.0001,"⚠ تجاوز الكمية",IF(AG24>=1,"✔ مكتمل",IF(AE24>0,"جاري التنفيذ","لم يبدأ"))))
A25: =IF('جدول الكميات'!B25="","",'جدول الكميات'!B25) | B25: =IF('جدول الكميات'!D25="","",'جدول الكميات'!D25) | C25: =IF('جدول الكميات'!E25="","",'جدول الكميات'!E25) | D25: =IF('جدول الكميات'!C25="","",'جدول الكميات'!C25) | E25: =N('جدول الكميات'!F25) | F25: =N('جدول الكميات'!G25) | J25: 64 | K25: 128 | L25: 192 | AE25: =SUM(G25:AD25) | AF25: =E25-AE25 | AG25: =IF(E25>0,AE25/E25,0) | AH25: =AE25*F25 | AI25: =IF(A25="","",IF(AE25>E25+0.0001,"⚠ تجاوز الكمية",IF(AG25>=1,"✔ مكتمل",IF(AE25>0,"جاري التنفيذ","لم يبدأ"))))
A26: =IF('جدول الكميات'!B26="","",'جدول الكميات'!B26) | B26: =IF('جدول الكميات'!D26="","",'جدول الكميات'!D26) | C26: =IF('جدول الكميات'!E26="","",'جدول الكميات'!E26) | D26: =IF('جدول الكميات'!C26="","",'جدول الكميات'!C26) | E26: =N('جدول الكميات'!F26) | F26: =N('جدول الكميات'!G26) | AE26: =SUM(G26:AD26) | AF26: =E26-AE26 | AG26: =IF(E26>0,AE26/E26,0) | AH26: =AE26*F26 | AI26: =IF(A26="","",IF(AE26>E26+0.0001,"⚠ تجاوز الكمية",IF(AG26>=1,"✔ مكتمل",IF(AE26>0,"جاري التنفيذ","لم يبدأ"))))
A27: =IF('جدول الكميات'!B27="","",'جدول الكميات'!B27) | B27: =IF('جدول الكميات'!D27="","",'جدول الكميات'!D27) | C27: =IF('جدول الكميات'!E27="","",'جدول الكميات'!E27) | D27: =IF('جدول الكميات'!C27="","",'جدول الكميات'!C27) | E27: =N('جدول الكميات'!F27) | F27: =N('جدول الكميات'!G27) | AE27: =SUM(G27:AD27) | AF27: =E27-AE27 | AG27: =IF(E27>0,AE27/E27,0) | AH27: =AE27*F27 | AI27: =IF(A27="","",IF(AE27>E27+0.0001,"⚠ تجاوز الكمية",IF(AG27>=1,"✔ مكتمل",IF(AE27>0,"جاري التنفيذ","لم يبدأ"))))
A28: =IF('جدول الكميات'!B28="","",'جدول الكميات'!B28) | B28: =IF('جدول الكميات'!D28="","",'جدول الكميات'!D28) | C28: =IF('جدول الكميات'!E28="","",'جدول الكميات'!E28) | D28: =IF('جدول الكميات'!C28="","",'جدول الكميات'!C28) | E28: =N('جدول الكميات'!F28) | F28: =N('جدول الكميات'!G28) | AE28: =SUM(G28:AD28) | AF28: =E28-AE28 | AG28: =IF(E28>0,AE28/E28,0) | AH28: =AE28*F28 | AI28: =IF(A28="","",IF(AE28>E28+0.0001,"⚠ تجاوز الكمية",IF(AG28>=1,"✔ مكتمل",IF(AE28>0,"جاري التنفيذ","لم يبدأ"))))
A29: =IF('جدول الكميات'!B29="","",'جدول الكميات'!B29) | B29: =IF('جدول الكميات'!D29="","",'جدول الكميات'!D29) | C29: =IF('جدول الكميات'!E29="","",'جدول الكميات'!E29) | D29: =IF('جدول الكميات'!C29="","",'جدول الكميات'!C29) | E29: =N('جدول الكميات'!F29) | F29: =N('جدول الكميات'!G29) | I29: 16.8 | J29: 21 | K29: 21 | L29: 25.2 | AE29: =SUM(G29:AD29) | AF29: =E29-AE29 | AG29: =IF(E29>0,AE29/E29,0) | AH29: =AE29*F29 | AI29: =IF(A29="","",IF(AE29>E29+0.0001,"⚠ تجاوز الكمية",IF(AG29>=1,"✔ مكتمل",IF(AE29>0,"جاري التنفيذ","لم يبدأ"))))
A30: =IF('جدول الكميات'!B30="","",'جدول الكميات'!B30) | B30: =IF('جدول الكميات'!D30="","",'جدول الكميات'!D30) | C30: =IF('جدول الكميات'!E30="","",'جدول الكميات'!E30) | D30: =IF('جدول الكميات'!C30="","",'جدول الكميات'!C30) | E30: =N('جدول الكميات'!F30) | F30: =N('جدول الكميات'!G30) | I30: 22.8 | J30: 19 | K30: 19 | L30: 19 | AE30: =SUM(G30:AD30) | AF30: =E30-AE30 | AG30: =IF(E30>0,AE30/E30,0) | AH30: =AE30*F30 | AI30: =IF(A30="","",IF(AE30>E30+0.0001,"⚠ تجاوز الكمية",IF(AG30>=1,"✔ مكتمل",IF(AE30>0,"جاري التنفيذ","لم يبدأ"))))
A31: =IF('جدول الكميات'!B31="","",'جدول الكميات'!B31) | B31: =IF('جدول الكميات'!D31="","",'جدول الكميات'!D31) | C31: =IF('جدول الكميات'!E31="","",'جدول الكميات'!E31) | D31: =IF('جدول الكميات'!C31="","",'جدول الكميات'!C31) | E31: =N('جدول الكميات'!F31) | F31: =N('جدول الكميات'!G31) | AE31: =SUM(G31:AD31) | AF31: =E31-AE31 | AG31: =IF(E31>0,AE31/E31,0) | AH31: =AE31*F31 | AI31: =IF(A31="","",IF(AE31>E31+0.0001,"⚠ تجاوز الكمية",IF(AG31>=1,"✔ مكتمل",IF(AE31>0,"جاري التنفيذ","لم يبدأ"))))
A32: =IF('جدول الكميات'!B32="","",'جدول الكميات'!B32) | B32: =IF('جدول الكميات'!D32="","",'جدول الكميات'!D32) | C32: =IF('جدول الكميات'!E32="","",'جدول الكميات'!E32) | D32: =IF('جدول الكميات'!C32="","",'جدول الكميات'!C32) | E32: =N('جدول الكميات'!F32) | F32: =N('جدول الكميات'!G32) | AE32: =SUM(G32:AD32) | AF32: =E32-AE32 | AG32: =IF(E32>0,AE32/E32,0) | AH32: =AE32*F32 | AI32: =IF(A32="","",IF(AE32>E32+0.0001,"⚠ تجاوز الكمية",IF(AG32>=1,"✔ مكتمل",IF(AE32>0,"جاري التنفيذ","لم يبدأ"))))
A33: =IF('جدول الكميات'!B33="","",'جدول الكميات'!B33) | B33: =IF('جدول الكميات'!D33="","",'جدول الكميات'!D33) | C33: =IF('جدول الكميات'!E33="","",'جدول الكميات'!E33) | D33: =IF('جدول الكميات'!C33="","",'جدول الكميات'!C33) | E33: =N('جدول الكميات'!F33) | F33: =N('جدول الكميات'!G33) | AE33: =SUM(G33:AD33) | AF33: =E33-AE33 | AG33: =IF(E33>0,AE33/E33,0) | AH33: =AE33*F33 | AI33: =IF(A33="","",IF(AE33>E33+0.0001,"⚠ تجاوز الكمية",IF(AG33>=1,"✔ مكتمل",IF(AE33>0,"جاري التنفيذ","لم يبدأ"))))
A34: =IF('جدول الكميات'!B34="","",'جدول الكميات'!B34) | B34: =IF('جدول الكميات'!D34="","",'جدول الكميات'!D34) | C34: =IF('جدول الكميات'!E34="","",'جدول الكميات'!E34) | D34: =IF('جدول الكميات'!C34="","",'جدول الكميات'!C34) | E34: =N('جدول الكميات'!F34) | F34: =N('جدول الكميات'!G34) | AE34: =SUM(G34:AD34) | AF34: =E34-AE34 | AG34: =IF(E34>0,AE34/E34,0) | AH34: =AE34*F34 | AI34: =IF(A34="","",IF(AE34>E34+0.0001,"⚠ تجاوز الكمية",IF(AG34>=1,"✔ مكتمل",IF(AE34>0,"جاري التنفيذ","لم يبدأ"))))
A35: =IF('جدول الكميات'!B35="","",'جدول الكميات'!B35) | B35: =IF('جدول الكميات'!D35="","",'جدول الكميات'!D35) | C35: =IF('جدول الكميات'!E35="","",'جدول الكميات'!E35) | D35: =IF('جدول الكميات'!C35="","",'جدول الكميات'!C35) | E35: =N('جدول الكميات'!F35) | F35: =N('جدول الكميات'!G35) | AE35: =SUM(G35:AD35) | AF35: =E35-AE35 | AG35: =IF(E35>0,AE35/E35,0) | AH35: =AE35*F35 | AI35: =IF(A35="","",IF(AE35>E35+0.0001,"⚠ تجاوز الكمية",IF(AG35>=1,"✔ مكتمل",IF(AE35>0,"جاري التنفيذ","لم يبدأ"))))
A36: =IF('جدول الكميات'!B36="","",'جدول الكميات'!B36) | B36: =IF('جدول الكميات'!D36="","",'جدول الكميات'!D36) | C36: =IF('جدول الكميات'!E36="","",'جدول الكميات'!E36) | D36: =IF('جدول الكميات'!C36="","",'جدول الكميات'!C36) | E36: =N('جدول الكميات'!F36) | F36: =N('جدول الكميات'!G36) | AE36: =SUM(G36:AD36) | AF36: =E36-AE36 | AG36: =IF(E36>0,AE36/E36,0) | AH36: =AE36*F36 | AI36: =IF(A36="","",IF(AE36>E36+0.0001,"⚠ تجاوز الكمية",IF(AG36>=1,"✔ مكتمل",IF(AE36>0,"جاري التنفيذ","لم يبدأ"))))
A37: =IF('جدول الكميات'!B37="","",'جدول الكميات'!B37) | B37: =IF('جدول الكميات'!D37="","",'جدول الكميات'!D37) | C37: =IF('جدول الكميات'!E37="","",'جدول الكميات'!E37) | D37: =IF('جدول الكميات'!C37="","",'جدول الكميات'!C37) | E37: =N('جدول الكميات'!F37) | F37: =N('جدول الكميات'!G37) | AE37: =SUM(G37:AD37) | AF37: =E37-AE37 | AG37: =IF(E37>0,AE37/E37,0) | AH37: =AE37*F37 | AI37: =IF(A37="","",IF(AE37>E37+0.0001,"⚠ تجاوز الكمية",IF(AG37>=1,"✔ مكتمل",IF(AE37>0,"جاري التنفيذ","لم يبدأ"))))
A38: =IF('جدول الكميات'!B38="","",'جدول الكميات'!B38) | B38: =IF('جدول الكميات'!D38="","",'جدول الكميات'!D38) | C38: =IF('جدول الكميات'!E38="","",'جدول الكميات'!E38) | D38: =IF('جدول الكميات'!C38="","",'جدول الكميات'!C38) | E38: =N('جدول الكميات'!F38) | F38: =N('جدول الكميات'!G38) | AE38: =SUM(G38:AD38) | AF38: =E38-AE38 | AG38: =IF(E38>0,AE38/E38,0) | AH38: =AE38*F38 | AI38: =IF(A38="","",IF(AE38>E38+0.0001,"⚠ تجاوز الكمية",IF(AG38>=1,"✔ مكتمل",IF(AE38>0,"جاري التنفيذ","لم يبدأ"))))
A39: =IF('جدول الكميات'!B39="","",'جدول الكميات'!B39) | B39: =IF('جدول الكميات'!D39="","",'جدول الكميات'!D39) | C39: =IF('جدول الكميات'!E39="","",'جدول الكميات'!E39) | D39: =IF('جدول الكميات'!C39="","",'جدول الكميات'!C39) | E39: =N('جدول الكميات'!F39) | F39: =N('جدول الكميات'!G39) | AE39: =SUM(G39:AD39) | AF39: =E39-AE39 | AG39: =IF(E39>0,AE39/E39,0) | AH39: =AE39*F39 | AI39: =IF(A39="","",IF(AE39>E39+0.0001,"⚠ تجاوز الكمية",IF(AG39>=1,"✔ مكتمل",IF(AE39>0,"جاري التنفيذ","لم يبدأ"))))
A40: =IF('جدول الكميات'!B40="","",'جدول الكميات'!B40) | B40: =IF('جدول الكميات'!D40="","",'جدول الكميات'!D40) | C40: =IF('جدول الكميات'!E40="","",'جدول الكميات'!E40) | D40: =IF('جدول الكميات'!C40="","",'جدول الكميات'!C40) | E40: =N('جدول الكميات'!F40) | F40: =N('جدول الكميات'!G40) | AE40: =SUM(G40:AD40) | AF40: =E40-AE40 | AG40: =IF(E40>0,AE40/E40,0) | AH40: =AE40*F40 | AI40: =IF(A40="","",IF(AE40>E40+0.0001,"⚠ تجاوز الكمية",IF(AG40>=1,"✔ مكتمل",IF(AE40>0,"جاري التنفيذ","لم يبدأ"))))
...

Sheet الأوامر التغييرية
A1: 🔁 سجل الأوامر التغييرية (Variation Orders)
A2: ='بيانات العقد'!$C$5&" | عقد رقم: "&'بيانات العقد'!$C$6&" | المبالغ بـ "&'بيانات العقد'!$C$14
A3: 📊 لوحة التحكم | B3: ⚙ بيانات العقد | C3: 📋 الكميات | D3: 📐 المنفذ | F3: ✂ الاستقطاعات | G3: 🗂 السجل | H3: 🧾 النموذج
A4: «قيمة الأمر» تعدّل قيمة العقد عند الاعتماد — «القيمة المدرجة» هي ما يُصرف في المستخلص المحدد (للصرف على دفعات: كرر الأمر في سطر جديد بقيمة أمر = 0 ومستخلص مختلف).
A5: م | B5: رقم الأمر | C5: تاريخ الأمر | D5: وصف الأمر التغييري | E5: النوع | F5: قيمة الأمر | G5: الأثر على العقد (±) | H5: الحالة | I5: القيمة المدرجة بالمستخلص | J5: الأثر على المستخلص (±) | K5: رقم المستخلص المدرج به | L5: ملاحظات
A6: =IF(B6="","",COUNTA($B$6:B6)) | B6: VO-01 | C6: 46160 | D6: إضافة غرفة محولات ولوحة جهد متوسط خارجية | E6: إضافة | F6: 1250000 | G6: =IF(E6="خصم",-1,1)*N(F6) | H6: معتمد | I6: 1250000 | J6: =IF(E6="خصم",-1,1)*N(I6) | K6: 4
A7: =IF(B7="","",COUNTA($B$6:B7)) | B7: VO-02 | C7: 46205 | D7: تعديل مواصفة البورسلين إلى فرز تجاري بموافقة المالك | E7: خصم | F7: 320000 | G7: =IF(E7="خصم",-1,1)*N(F7) | H7: معتمد | I7: 320000 | J7: =IF(E7="خصم",-1,1)*N(I7) | K7: 5
A8: =IF(B8="","",COUNTA($B$6:B8)) | B8: VO-03 | C8: 46259 | D8: أعمال تنسيق موقع وزراعة إضافية | E8: إضافة | F8: 900000 | G8: =IF(E8="خصم",-1,1)*N(F8) | H8: قيد الدراسة | J8: =IF(E8="خصم",-1,1)*N(I8)
A9: =IF(B9="","",COUNTA($B$6:B9)) | G9: =IF(E9="خصم",-1,1)*N(F9) | J9: =IF(E9="خصم",-1,1)*N(I9)
A10: =IF(B10="","",COUNTA($B$6:B10)) | G10: =IF(E10="خصم",-1,1)*N(F10) | J10: =IF(E10="خصم",-1,1)*N(I10)
A11: =IF(B11="","",COUNTA($B$6:B11)) | G11: =IF(E11="خصم",-1,1)*N(F11) | J11: =IF(E11="خصم",-1,1)*N(I11)
A12: =IF(B12="","",COUNTA($B$6:B12)) | G12: =IF(E12="خصم",-1,1)*N(F12) | J12: =IF(E12="خصم",-1,1)*N(I12)
A13: =IF(B13="","",COUNTA($B$6:B13)) | G13: =IF(E13="خصم",-1,1)*N(F13) | J13: =IF(E13="خصم",-1,1)*N(I13)
A14: =IF(B14="","",COUNTA($B$6:B14)) | G14: =IF(E14="خصم",-1,1)*N(F14) | J14: =IF(E14="خصم",-1,1)*N(I14)
A15: =IF(B15="","",COUNTA($B$6:B15)) | G15: =IF(E15="خصم",-1,1)*N(F15) | J15: =IF(E15="خصم",-1,1)*N(I15)
A16: =IF(B16="","",COUNTA($B$6:B16)) | G16: =IF(E16="خصم",-1,1)*N(F16) | J16: =IF(E16="خصم",-1,1)*N(I16)
A17: =IF(B17="","",COUNTA($B$6:B17)) | G17: =IF(E17="خصم",-1,1)*N(F17) | J17: =IF(E17="خصم",-1,1)*N(I17)
A18: =IF(B18="","",COUNTA($B$6:B18)) | G18: =IF(E18="خصم",-1,1)*N(F18) | J18: =IF(E18="خصم",-1,1)*N(I18)
A19: =IF(B19="","",COUNTA($B$6:B19)) | G19: =IF(E19="خصم",-1,1)*N(F19) | J19: =IF(E19="خصم",-1,1)*N(I19)
A20: =IF(B20="","",COUNTA($B$6:B20)) | G20: =IF(E20="خصم",-1,1)*N(F20) | J20: =IF(E20="خصم",-1,1)*N(I20)
... A55: =IF(B55="","",COUNTA($B$6:B55)) | G55: =IF(E55="خصم",-1,1)*N(F55) | J55: =IF(E55="خصم",-1,1)*N(I55)
A56: الإجمالي | F56: =SUM(F6:F55) | G56: =SUM(G6:G55) | H56: ="معتمد: "&COUNTIF(H6:H55,"معتمد") | I56: =SUM(I6:I55) | J56: =SUM(J6:J55)

Sheet الاستقطاعات الفنية
A1: ✂ سجل الاستقطاعات الفنية (Technical Deductions)
A2: ='بيانات العقد'!$C$5&" | عقد رقم: "&'بيانات العقد'!$C$6&" | المبالغ بـ "&'بيانات العقد'!$C$14
A3: 📊 لوحة التحكم | B3: ⚙ بيانات العقد | C3: 📋 الكميات | D3: 📐 المنفذ | F3: 🔁 التغييرية | G3: 🗂 السجل | H3: 🧾 النموذج
A4: يُخصم المبلغ من المستخلص المحدد ويستمر محتجزاً تراكمياً حتى يتم الإفراج عنه في «مستخلص الإفراج».
A5: م | B5: رقم الاستقطاع | C5: التاريخ | D5: رقم المستخلص | E5: كود البند | F5: وصف البند (آلي) | G5: سبب الاستقطاع | H5: نوع الاستقطاع | I5: المبلغ المستقطع | J5: تم الإفراج؟ | K5: مستخلص الإفراج | L5: الرصيد المحتجز | M5: ملاحظات
A6: =IF(B6="","",COUNTA($B$6:B6)) | B6: TD-01 | C6: 46145 | D6: 2 | E6: 02-002 | F6: =IF(E6="","",IFERROR(INDEX('جدول الكميات'!$D$6:$D$105,MATCH(E6,'جدول الكميات'!$B$6:$B$105,0)),"⚠ كود غير موجود")) | G6: تعشيش في خرسانة بعض القواعد يلزم معالجته | H6: أعمال غير مطابقة | I6: 85000 | J6: نعم | K6: 4 | L6: =IF(J6="نعم",0,N(I6))
A7: =IF(B7="","",COUNTA($B$6:B7)) | B7: TD-02 | C7: 46177 | D7: 3 | E7: 04-001 | F7: =IF(E7="","",IFERROR(INDEX('جدول الكميات'!$D$6:$D$105,MATCH(E7,'جدول الكميات'!$B$6:$B$105,0)),"⚠ كود غير موجود")) | G7: عدم تقديم نتائج اختبار التصاق العزل | H7: اختبارات غير مستكملة | I7: 40000 | J7: لا | L7: =IF(J7="نعم",0,N(I7))
A8: =IF(B8="","",COUNTA($B$6:B8)) | B8: TD-03 | C8: 46238 | D8: 5 | E8: 02-004 | F8: =IF(E8="","",IFERROR(INDEX('جدول الكميات'!$D$6:$D$105,MATCH(E8,'جدول الكميات'!$B$6:$B$105,0)),"⚠ كود غير موجود")) | G8: ملاحظات على استواء أسطح بلاطات الدور الأول | H8: ملاحظات فنية | I8: 120000 | J8: لا | L8: =IF(J8="نعم",0,N(I8))
A9: =IF(B9="","",COUNTA($B$6:B9)) | B9: TD-04 | C9: 46268 | D9: 6 | E9: 03-001 | F9: =IF(E9="","",IFERROR(INDEX('جدول الكميات'!$D$6:$D$105,MATCH(E9,'جدول الكميات'!$B$6:$B$105,0)),"⚠ كود غير موجود")) | G9: مباني غير مطابقة للمواصفات (عدم ضبط الرأسية) | H9: أعمال غير مطابقة | I9: 65000 | J9: لا | L9: =IF(J9="نعم",0,N(I9))
A10: =IF(B10="","",COUNTA($B$6:B10)) | F10: =IF(E10="","",IFERROR(INDEX('جدول الكميات'!$D$6:$D$105,MATCH(E10,'جدول الكميات'!$B$6:$B$105,0)),"⚠ كود غير موجود")) | L10: =IF(J10="نعم",0,N(I10))
A11: =IF(B11="","",COUNTA($B$6:B11)) | F11: =IF(E11="","",IFERROR(INDEX('جدول الكميات'!$D$6:$D$105,MATCH(E11,'جدول الكميات'!$B$6:$B$105,0)),"⚠ كود غير موجود")) | L11: =IF(J11="نعم",0,N(I11))
A12: =IF(B12="","",COUNTA($B$6:B12)) | F12: =IF(E12="","",IFERROR(INDEX('جدول الكميات'!$D$6:$D$105,MATCH(E12,'جدول الكميات'!$B$6:$B$105,0)),"⚠ كود غير موجود")) | L12: =IF(J12="نعم",0,N(I12))
A13: =IF(B13="","",COUNTA($B$6:B13)) | F13: =IF(E13="","",IFERROR(INDEX('جدول الكميات'!$D$6:$D$105,MATCH(E13,'جدول الكميات'!$B$6:$B$105,0)),"⚠ كود غير موجود")) | L13: =IF(J13="نعم",0,N(I13))
A14: =IF(B14="","",COUNTA($B$6:B14)) | F14: =IF(E14="","",IFERROR(INDEX('جدول الكميات'!$D$6:$D$105,MATCH(E14,'جدول الكميات'!$B$6:$B$105,0)),"⚠ كود غير موجود")) | L14: =IF(J14="نعم",0,N(I14))
A15: =IF(B15="","",COUNTA($B$6:B15)) | F15: =IF(E15="","",IFERROR(INDEX('جدول الكميات'!$D$6:$D$105,MATCH(E15,'جدول الكميات'!$B$6:$B$105,0)),"⚠ كود غير موجود")) | L15: =IF(J15="نعم",0,N(I15))
A16: =IF(B16="","",COUNTA($B$6:B16)) | F16: =IF(E16="","",IFERROR(INDEX('جدول الكميات'!$D$6:$D$105,MATCH(E16,'جدول الكميات'!$B$6:$B$105,0)),"⚠ كود غير موجود")) | L16: =IF(J16="نعم",0,N(I16))
A17: =IF(B17="","",COUNTA($B$6:B17)) | F17: =IF(E17="","",IFERROR(INDEX('جدول الكميات'!$D$6:$D$105,MATCH(E17,'جدول الكميات'!$B$6:$B$105,0)),"⚠ كود غير موجود")) | L17: =IF(J17="نعم",0,N(I17))
A18: =IF(B18="","",COUNTA($B$6:B18)) | F18: =IF(E18="","",IFERROR(INDEX('جدول الكميات'!$D$6:$D$105,MATCH(E18,'جدول الكميات'!$B$6:$B$105,0)),"⚠ كود غير موجود")) | L18: =IF(J18="نعم",0,N(I18))
A19: =IF(B19="","",COUNTA($B$6:B19)) | F19: =IF(E19="","",IFERROR(INDEX('جدول الكميات'!$D$6:$D$105,MATCH(E19,'جدول الكميات'!$B$6:$B$105,0)),"⚠ كود غير موجود")) | L19: =IF(J19="نعم",0,N(I19))
A20: =IF(B20="","",COUNTA($B$6:B20)) | F20: =IF(E20="","",IFERROR(INDEX('جدول الكميات'!$D$6:$D$105,MATCH(E20,'جدول الكميات'!$B$6:$B$105,0)),"⚠ كود غير موجود")) | L20: =IF(J20="نعم",0,N(I20))
A21: =IF(B21="","",COUNTA($B$6:B21)) | F21: =IF(E21="","",IFERROR(INDEX('جدول الكميات'!$D$6:$D$105,MATCH(E21,'جدول الكميات'!$B$6:$B$105,0)),"⚠ كود غير موجود")) | L21: =IF(J21="نعم",0,N(I21))
... A105: =IF(B105="","",COUNTA($B$6:B105)) | F105: =IF(E105="","",IFERROR(INDEX('جدول الكميات'!$D$6:$D$105,MATCH(E105,'جدول الكميات'!$B$6:$B$105,0)),"⚠ كود غير موجود")) | L105: =IF(J105="نعم",0,N(I105))
A106: الإجمالي | I106: =SUM(I6:I105) | J106: =I106-L106 | L106: =SUM(L6:L105)

Sheet سجل المستخلصات
A1: 🗂 سجل المستخلصات والحسابات التراكمية (Payment Certificates Register)
A2: ='بيانات العقد'!$C$5&" | عقد رقم: "&'بيانات العقد'!$C$6&" | المبالغ بـ "&'بيانات العقد'!$C$14
B3: 📊 لوحة التحكم | D3: ⚙ بيانات العقد | F3: 📋 الكميات | H3: 📐 المنفذ | J3: 🔁 التغييرية | L3: ✂ الاستقطاعات | N3: 🧾 النموذج
A4: بيانات المستخلص | G4: قيمة الأعمال ونسب الإنجاز | O4: الاستقطاعات (تراكمي) | U4: صافي المستحق والضرائب | AA4: التحصيل
A5: رقم المستخلص | B5: الفترة من | C5: الفترة إلى | D5: تاريخ التقديم | E5: تاريخ الاعتماد | F5: حالة المستخلص | G5: قيمة الأعمال المنفذة التراكمية | H5: أعمال الفترة | I5: الأوامر التغييرية التراكمية | J5: رصيد المواد الموردة بالموقع | K5: إجمالي القيمة التراكمية | L5: نسبة الإنجاز الفعلية | M5: نسبة الإنجاز المخططة | N5: الانحراف عن المخطط | O5: استرداد الدفعة المقدمة التراكمي | P5: ضمان الأعمال المحتسب التراكمي | Q5: إفراج عن الضمان خلال الفترة | R5: صافي الضمان المحتجز | S5: الاستقطاعات الفنية المحتجزة | T5: غرامات وخصومات خلال الفترة | U5: الصافي التراكمي قبل الضرائب | V5: ضريبة القيمة المضافة | W5: ضريبة الخصم من المنبع | X5: صافي المستحق التراكمي | Y5: المعتمد في المستخلصات السابقة | Z5: صافي المستحق للمستخلص الحالي | AA5: المبلغ المحصل | AB5: تاريخ التحصيل | AC5: المتبقي غير المحصل | AD5: مدة التحصيل (يوم) | AE5: حالة التحصيل
A6: 1 | B6: 46082 | C6: 46112 | D6: 46117 | E6: 46133 | F6: معتمد | G6: =IF($C6="","",SUMPRODUCT('الكميات المنفذة'!$F$6:$F$105*'الكميات المنفذة'!$G$6:$AD$105*('الكميات المنفذة'!$G$5:$AD$5<=$A6))) | H6: =IF($C6="","",G6-N(G5)) | I6: =IF($C6="","",SUMIFS('الأوامر التغييرية'!$J$6:$J$55,'الأوامر التغييرية'!$H$6:$H$55,"معتمد",'الأوامر التغييرية'!$K$6:$K$55,"<="&$A6)) | J6: 0 | K6: =IF($C6="","",G6+I6+N(J6)) | L6: =IF($C6="","",IF(ContractValue+I6>0,(G6+I6)/(ContractValue+I6),0)) | M6: 0.02 | N6: =IF(OR($C6="",M6=""),"",L6-M6) | O6: =IF($C6="","",ROUND(IF(L6>=RecFull,AdvAmount,MIN(AdvAmount,MAX(0,G6+I6-RecStart*ContractValue)*RecRate)),2)) | P6: =IF($C6="","",ROUND(MIN(K6*RetPct,RetCap),2)) | R6: =IF($C6="","",P6-SUM($Q$6:Q6)) | S6: =IF($C6="","",SUMIFS('الاستقطاعات الفنية'!$I$6:$I$105,'الاستقطاعات الفنية'!$D$6:$D$105,"<="&$A6)-SUMIFS('الاستقطاعات الفنية'!$I$6:$I$105,'الاستقطاعات الفنية'!$J$6:$J$105,"نعم",'الاستقطاعات الفنية'!$K$6:$K$105,"<="&$A6)) | U6: =IF($C6="","",K6-O6-R6-S6-SUM($T$6:T6)) | V6: =IF($C6="","",ROUND(VATPct*(U6+IF(VATBeforeRet="نعم",R6,0)),2)) | W6: =IF($C6="","",ROUND(WHTPct*(U6+R6),2)) | X6: =IF($C6="","",U6+V6-W6) | Y6: =IF($C6="","",N(X5)) | Z6: =IF($C6="","",X6-Y6) | AA6: 1693779.8 | AB6: 46161 | AC6: =IF($C6="","",Z6-N(AA6)) | AD6: =IF(OR(AB6="",E6=""),"",AB6-E6) | AE6: =IF($C6="","",IF(N(AA6)=0,IF(E6="","⏳ بانتظار الاعتماد","✖ غير محصل"),IF(AC6<=1,"✔ محصل بالكامل","⚠ محصل جزئياً")))
A7: 2 | B7: 46113 | C7: 46142 | D7: 46147 | E7: 46164 | F7: معتمد | G7: =IF($C7="","",SUMPRODUCT('الكميات المنفذة'!$F$6:$F$105*'الكميات المنفذة'!$G$6:$AD$105*('الكميات المنفذة'!$G$5:$AD$5<=$A7))) | H7: =IF($C7="","",G7-N(G6)) | I7: =IF($C7="","",SUMIFS('الأوامر التغييرية'!$J$6:$J$55,'الأوامر التغييرية'!$H$6:$H$55,"معتمد",'الأوامر التغييرية'!$K$6:$K$55,"<="&$A7)) | J7: 450000 | K7: =IF($C7="","",G7+I7+N(J7)) | L7: =IF($C7="","",IF(ContractValue+I7>0,(G7+I7)/(ContractValue+I7),0)) | M7: 0.05 | N7: =IF(OR($C7="",M7=""),"",L7-M7) | O7: =IF($C7="","",ROUND(IF(L7>=RecFull,AdvAmount,MIN(AdvAmount,MAX(0,G7+I7-RecStart*ContractValue)*RecRate)),2)) | P7: =IF($C7="","",ROUND(MIN(K7*RetPct,RetCap),2)) | R7: =IF($C7="","",P7-SUM($Q$6:Q7)) | S7: =IF($C7="","",SUMIFS('الاستقطاعات الفنية'!$I$6:$I$105,'الاستقطاعات الفنية'!$D$6:$D$105,"<="&$A7)-SUMIFS('الاستقطاعات الفنية'!$I$6:$I$105,'الاستقطاعات الفنية'!$J$6:$J$105,"نعم",'الاستقطاعات الفنية'!$K$6:$K$105,"<="&$A7)) | U7: =IF($C7="","",K7-O7-R7-S7-SUM($T$6:T7)) | V7: =IF($C7="","",ROUND(VATPct*(U7+IF(VATBeforeRet="نعم",R7,0)),2)) | W7: =IF($C7="","",ROUND(WHTPct*(U7+R7),2)) | X7: =IF($C7="","",U7+V7-W7) | Y7: =IF($C7="","",N(X6)) | Z7: =IF($C7="","",X7-Y7) | AA7: 6422014.9 | AB7: 46199 | AC7: =IF($C7="","",Z7-N(AA7)) | AD7: =IF(OR(AB7="",E7=""),"",AB7-E7) | AE7: =IF($C7="","",IF(N(AA7)=0,IF(E7="","⏳ بانتظار الاعتماد","✖ غير محصل"),IF(AC7<=1,"✔ محصل بالكامل","⚠ محصل جزئياً")))
A8: 3 | B8: 46143 | C8: 46173 | D8: 46178 | E8: 46193 | F8: معتمد | G8: =IF($C8="","",SUMPRODUCT('الكميات المنفذة'!$F$6:$F$105*'الكميات المنفذة'!$G$6:$AD$105*('الكميات المنفذة'!$G$5:$AD$5<=$A8))) | H8: =IF($C8="","",G8-N(G7)) | I8: =IF($C8="","",SUMIFS('الأوامر التغييرية'!$J$6:$J$55,'الأوامر التغييرية'!$H$6:$H$55,"معتمد",'الأوامر التغييرية'!$K$6:$K$55,"<="&$A8)) | J8: 900000 | K8: =IF($C8="","",G8+I8+N(J8)) | L8: =IF($C8="","",IF(ContractValue+I8>0,(G8+I8)/(ContractValue+I8),0)) | M8: 0.1 | N8: =IF(OR($C8="",M8=""),"",L8-M8) | O8: =IF($C8="","",ROUND(IF(L8>=RecFull,AdvAmount,MIN(AdvAmount,MAX(0,G8+I8-RecStart*ContractValue)*RecRate)),2)) | P8: =IF($C8="","",ROUND(MIN(K8*RetPct,RetCap),2)) | R8: =IF($C8="","",P8-SUM($Q$6:Q8)) | S8: =IF($C8="","",SUMIFS('الاستقطاعات الفنية'!$I$6:$I$105,'الاستقطاعات الفنية'!$D$6:$D$105,"<="&$A8)-SUMIFS('الاستقطاعات الفنية'!$I$6:$I$105,'الاستقطاعات الفنية'!$J$6:$J$105,"نعم",'الاستقطاعات الفنية'!$K$6:$K$105,"<="&$A8)) | U8: =IF($C8="","",K8-O8-R8-S8-SUM($T$6:T8)) | V8: =IF($C8="","",ROUND(VATPct*(U8+IF(VATBeforeRet="نعم",R8,0)),2)) | W8: =IF($C8="","",ROUND(WHTPct*(U8+R8),2)) | X8: =IF($C8="","",U8+V8-W8) | Y8: =IF($C8="","",N(X7)) | Z8: =IF($C8="","",X8-Y8) | AA8: 6938872.1 | AB8: 46224 | AC8: =IF($C8="","",Z8-N(AA8)) | AD8: =IF(OR(AB8="",E8=""),"",AB8-E8) | AE8: =IF($C8="","",IF(N(AA8)=0,IF(E8="","⏳ بانتظار الاعتماد","✖ غير محصل"),IF(AC8<=1,"✔ محصل بالكامل","⚠ محصل جزئياً")))
A9: 4 | B9: 46174 | C9: 46203 | D9: 46208 | E9: 46224 | F9: معتمد | G9: =IF($C9="","",SUMPRODUCT('الكميات المنفذة'!$F$6:$F$105*'الكميات المنفذة'!$G$6:$AD$105*('الكميات المنفذة'!$G$5:$AD$5<=$A9))) | H9: =IF($C9="","",G9-N(G8)) | I9: =IF($C9="","",SUMIFS('الأوامر التغييرية'!$J$6:$J$55,'الأوامر التغييرية'!$H$6:$H$55,"معتمد",'الأوامر التغييرية'!$K$6:$K$55,"<="&$A9)) | J9: 600000 | K9: =IF($C9="","",G9+I9+N(J9)) | L9: =IF($C9="","",IF(ContractValue+I9>0,(G9+I9)/(ContractValue+I9),0)) | M9: 0.16 | N9: =IF(OR($C9="",M9=""),"",L9-M9) | O9: =IF($C9="","",ROUND(IF(L9>=RecFull,AdvAmount,MIN(AdvAmount,MAX(0,G9+I9-RecStart*ContractValue)*RecRate)),2)) | P9: =IF($C9="","",ROUND(MIN(K9*RetPct,RetCap),2)) | R9: =IF($C9="","",P9-SUM($Q$6:Q9)) | S9: =IF($C9="","",SUMIFS('الاستقطاعات الفنية'!$I$6:$I$105,'الاستقطاعات الفنية'!$D$6:$D$105,"<="&$A9)-SUMIFS('الاستقطاعات الفنية'!$I$6:$I$105,'الاستقطاعات الفنية'!$J$6:$J$105,"نعم",'الاستقطاعات الفنية'!$K$6:$K$105,"<="&$A9)) | U9: =IF($C9="","",K9-O9-R9-S9-SUM($T$6:T9)) | V9: =IF($C9="","",ROUND(VATPct*(U9+IF(VATBeforeRet="نعم",R9,0)),2)) | W9: =IF($C9="","",ROUND(WHTPct*(U9+R9),2)) | X9: =IF($C9="","",U9+V9-W9) | Y9: =IF($C9="","",N(X8)) | Z9: =IF($C9="","",X9-Y9) | AA9: 5641921.7 | AB9: 46264 | AC9: =IF($C9="","",Z9-N(AA9)) | AD9: =IF(OR(AB9="",E9=""),"",AB9-E9) | AE9: =IF($C9="","",IF(N(AA9)=0,IF(E9="","⏳ بانتظار الاعتماد","✖ غير محصل"),IF(AC9<=1,"✔ محصل بالكامل","⚠ محصل جزئياً")))
A10: 5 | B10: 46204 | C10: 46234 | D10: 46239 | E10: 46256 | F10: معتمد | G10: =IF($C10="","",SUMPRODUCT('الكميات المنفذة'!$F$6:$F$105*'الكميات المنفذة'!$G$6:$AD$105*('الكميات المنفذة'!$G$5:$AD$5<=$A10))) | H10: =IF($C10="","",G10-N(G9)) | I10: =IF($C10="","",SUMIFS('الأوامر التغييرية'!$J$6:$J$55,'الأوامر التغييرية'!$H$6:$H$55,"معتمد",'الأوامر التغييرية'!$K$6:$K$55,"<="&$A10)) | J10: 1100000 | K10: =IF($C10="","",G10+I10+N(J10)) | L10: =IF($C10="","",IF(ContractValue+I10>0,(G10+I10)/(ContractValue+I10),0)) | M10: 0.23 | N10: =IF(OR($C10="",M10=""),"",L10-M10) | O10: =IF($C10="","",ROUND(IF(L10>=RecFull,AdvAmount,MIN(AdvAmount,MAX(0,G10+I10-RecStart*ContractValue)*RecRate)),2)) | P10: =IF($C10="","",ROUND(MIN(K10*RetPct,RetCap),2)) | R10: =IF($C10="","",P10-SUM($Q$6:Q10)) | S10: =IF($C10="","",SUMIFS('الاستقطاعات الفنية'!$I$6:$I$105,'الاستقطاعات الفنية'!$D$6:$D$105,"<="&$A10)-SUMIFS('الاستقطاعات الفنية'!$I$6:$I$105,'الاستقطاعات الفنية'!$J$6:$J$105,"نعم",'الاستقطاعات الفنية'!$K$6:$K$105,"<="&$A10)) | T10: 25000 | U10: =IF($C10="","",K10-O10-R10-S10-SUM($T$6:T10)) | V10: =IF($C10="","",ROUND(VATPct*(U10+IF(VATBeforeRet="نعم",R10,0)),2)) | W10: =IF($C10="","",ROUND(WHTPct*(U10+R10),2)) | X10: =IF($C10="","",U10+V10-W10) | Y10: =IF($C10="","",N(X9)) | Z10: =IF($C10="","",X10-Y10) | AA10: 2400000 | AB10: 46285 | AC10: =IF($C10="","",Z10-N(AA10)) | AD10: =IF(OR(AB10="",E10=""),"",AB10-E10) | AE10: =IF($C10="","",IF(N(AA10)=0,IF(E10="","⏳ بانتظار الاعتماد","✖ غير محصل"),IF(AC10<=1,"✔ محصل بالكامل","⚠ محصل جزئياً")))
A11: 6 | B11: 46235 | C11: 46265 | D11: 46270 | E11: 46285 | F11: معتمد | G11: =IF($C11="","",SUMPRODUCT('الكميات المنفذة'!$F$6:$F$105*'الكميات المنفذة'!$G$6:$AD$105*('الكميات المنفذة'!$G$5:$AD$5<=$A11))) | H11: =IF($C11="","",G11-N(G10)) | I11: =IF($C11="","",SUMIFS('الأوامر التغييرية'!$J$6:$J$55,'الأوامر التغييرية'!$H$6:$H$55,"معتمد",'الأوامر التغييرية'!$K$6:$K$55,"<="&$A11)) | J11: 750000 | K11: =IF($C11="","",G11+I11+N(J11)) | L11: =IF($C11="","",IF(ContractValue+I11>0,(G11+I11)/(ContractValue+I11),0)) | M11: 0.31 | N11: =IF(OR($C11="",M11=""),"",L11-M11) | O11: =IF($C11="","",ROUND(IF(L11>=RecFull,AdvAmount,MIN(AdvAmount,MAX(0,G11+I11-RecStart*ContractValue)*RecRate)),2)) | P11: =IF($C11="","",ROUND(MIN(K11*RetPct,RetCap),2)) | R11: =IF($C11="","",P11-SUM($Q$6:Q11)) | S11: =IF($C11="","",SUMIFS('الاستقطاعات الفنية'!$I$6:$I$105,'الاستقطاعات الفنية'!$D$6:$D$105,"<="&$A11)-SUMIFS('الاستقطاعات الفنية'!$I$6:$I$105,'الاستقطاعات الفنية'!$J$6:$J$105,"نعم",'الاستقطاعات الفنية'!$K$6:$K$105,"<="&$A11)) | U11: =IF($C11="","",K11-O11-R11-S11-SUM($T$6:T11)) | V11: =IF($C11="","",ROUND(VATPct*(U11+IF(VATBeforeRet="نعم",R11,0)),2)) | W11: =IF($C11="","",ROUND(WHTPct*(U11+R11),2)) | X11: =IF($C11="","",U11+V11-W11) | Y11: =IF($C11="","",N(X10)) | Z11: =IF($C11="","",X11-Y11) | AC11: =IF($C11="","",Z11-N(AA11)) | AD11: =IF(OR(AB11="",E11=""),"",AB11-E11) | AE11: =IF($C11="","",IF(N(AA11)=0,IF(E11="","⏳ بانتظار الاعتماد","✖ غير محصل"),IF(AC11<=1,"✔ محصل بالكامل","⚠ محصل جزئياً")))
A12: 7 | G12: =IF($C12="","",SUMPRODUCT('الكميات المنفذة'!$F$6:$F$105*'الكميات المنفذة'!$G$6:$AD$105*('الكميات المنفذة'!$G$5:$AD$5<=$A12))) | H12: =IF($C12="","",G12-N(G11)) | I12: =IF($C12="","",SUMIFS('الأوامر التغييرية'!$J$6:$J$55,'الأوامر التغييرية'!$H$6:$H$55,"معتمد",'الأوامر التغييرية'!$K$6:$K$55,"<="&$A12)) | K12: =IF($C12="","",G12+I12+N(J12)) | L12: =IF($C12="","",IF(ContractValue+I12>0,(G12+I12)/(ContractValue+I12),0)) | M12: 0.39 | N12: =IF(OR($C12="",M12=""),"",L12-M12) | O12: =IF($C12="","",ROUND(IF(L12>=RecFull,AdvAmount,MIN(AdvAmount,MAX(0,G12+I12-RecStart*ContractValue)*RecRate)),2)) | P12: =IF($C12="","",ROUND(MIN(K12*RetPct,RetCap),2)) | R12: =IF($C12="","",P12-SUM($Q$6:Q12)) | S12: =IF($C12="","",SUMIFS('الاستقطاعات الفنية'!$I$6:$I$105,'الاستقطاعات الفنية'!$D$6:$D$105,"<="&$A12)-SUMIFS('الاستقطاعات الفنية'!$I$6:$I$105,'الاستقطاعات الفنية'!$J$6:$J$105,"نعم",'الاستقطاعات الفنية'!$K$6:$K$105,"<="&$A12)) | U12: =IF($C12="","",K12-O12-R12-S12-SUM($T$6:T12)) | V12: =IF($C12="","",ROUND(VATPct*(U12+IF(VATBeforeRet="نعم",R12,0)),2)) | W12: =IF($C12="","",ROUND(WHTPct*(U12+R12),2)) | X12: =IF($C12="","",U12+V12-W12) | Y12: =IF($C12="","",N(X11)) | Z12: =IF($C12="","",X12-Y12) | AC12: =IF($C12="","",Z12-N(AA12)) | AD12: =IF(OR(AB12="",E12=""),"",AB12-E12) | AE12: =IF($C12="","",IF(N(AA12)=0,IF(E12="","⏳ بانتظار الاعتماد","✖ غير محصل"),IF(AC12<=1,"✔ محصل بالكامل","⚠ محصل جزئياً")))
A13: 8 | G13: =IF($C13="","",SUMPRODUCT('الكميات المنفذة'!$F$6:$F$105*'الكميات المنفذة'!$G$6:$AD$105*('الكميات المنفذة'!$G$5:$AD$5<=$A13))) | H13: =IF($C13="","",G13-N(G12)) | I13: =IF($C13="","",SUMIFS('الأوامر التغييرية'!$J$6:$J$55,'الأوامر التغييرية'!$H$6:$H$55,"معتمد",'الأوامر التغييرية'!$K$6:$K$55,"<="&$A13)) | K13: =IF($C13="","",G13+I13+N(J13)) | L13: =IF($C13="","",IF(ContractValue+I13>0,(G13+I13)/(ContractValue+I13),0)) | M13: 0.47 | N13: =IF(OR($C13="",M13=""),"",L13-M13) | O13: =IF($C13="","",ROUND(IF(L13>=RecFull,AdvAmount,MIN(AdvAmount,MAX(0,G13+I13-RecStart*ContractValue)*RecRate)),2)) | P13: =IF($C13="","",ROUND(MIN(K13*RetPct,RetCap),2)) | R13: =IF($C13="","",P13-SUM($Q$6:Q13)) | S13: =IF($C13="","",SUMIFS('الاستقطاعات الفنية'!$I$6:$I$105,'الاستقطاعات الفنية'!$D$6:$D$105,"<="&$A13)-SUMIFS('الاستقطاعات الفنية'!$I$6:$I$105,'الاستقطاعات الفنية'!$J$6:$J$105,"نعم",'الاستقطاعات الفنية'!$K$6:$K$105,"<="&$A13)) | U13: =IF($C13="","",K13-O13-R13-S13-SUM($T$6:T13)) | V13: =IF($C13="","",ROUND(VATPct*(U13+IF(VATBeforeRet="نعم",R13,0)),2)) | W13: =IF($C13="","",ROUND(WHTPct*(U13+R13),2)) | X13: =IF($C13="","",U13+V13-W13) | Y13: =IF($C13="","",N(X12)) | Z13: =IF($C13="","",X13-Y13) | AC13: =IF($C13="","",Z13-N(AA13)) | AD13: =IF(OR(AB13="",E13=""),"",AB13-E13) | AE13: =IF($C13="","",IF(N(AA13)=0,IF(E13="","⏳ بانتظار الاعتماد","✖ غير محصل"),IF(AC13<=1,"✔ محصل بالكامل","⚠ محصل جزئياً")))
A14: 9 | G14: =IF($C14="","",SUMPRODUCT('الكميات المنفذة'!$F$6:$F$105*'الكميات المنفذة'!$G$6:$AD$105*('الكميات المنفذة'!$G$5:$AD$5<=$A14))) | H14: =IF($C14="","",G14-N(G13)) | I14: =IF($C14="","",SUMIFS('الأوامر التغييرية'!$J$6:$J$55,'الأوامر التغييرية'!$H$6:$H$55,"معتمد",'الأوامر التغييرية'!$K$6:$K$55,"<="&$A14)) | K14: =IF($C14="","",G14+I14+N(J14)) | L14: =IF($C14="","",IF(ContractValue+I14>0,(G14+I14)/(ContractValue+I14),0)) | M14: 0.55 | N14: =IF(OR($C14="",M14=""),"",L14-M14) | O14: =IF($C14="","",ROUND(IF(L14>=RecFull,AdvAmount,MIN(AdvAmount,MAX(0,G14+I14-RecStart*ContractValue)*RecRate)),2)) | P14: =IF($C14="","",ROUND(MIN(K14*RetPct,RetCap),2)) | R14: =IF($C14="","",P14-SUM($Q$6:Q14)) | S14: =IF($C14="","",SUMIFS('الاستقطاعات الفنية'!$I$6:$I$105,'الاستقطاعات الفنية'!$D$6:$D$105,"<="&$A14)-SUMIFS('الاستقطاعات الفنية'!$I$6:$I$105,'الاستقطاعات الفنية'!$J$6:$J$105,"نعم",'الاستقطاعات الفنية'!$K$6:$K$105,"<="&$A14)) | U14: =IF($C14="","",K14-O14-R14-S14-SUM($T$6:T14)) | V14: =IF($C14="","",ROUND(VATPct*(U14+IF(VATBeforeRet="نعم",R14,0)),2)) | W14: =IF($C14="","",ROUND(WHTPct*(U14+R14),2)) | X14: =IF($C14="","",U14+V14-W14) | Y14: =IF($C14="","",N(X13)) | Z14: =IF($C14="","",X14-Y14) | AC14: =IF($C14="","",Z14-N(AA14)) | AD14: =IF(OR(AB14="",E14=""),"",AB14-E14) | AE14: =IF($C14="","",IF(N(AA14)=0,IF(E14="","⏳ بانتظار الاعتماد","✖ غير محصل"),IF(AC14<=1,"✔ محصل بالكامل","⚠ محصل جزئياً")))
A15: 10 | G15: =IF($C15="","",SUMPRODUCT('الكميات المنفذة'!$F$6:$F$105*'الكميات المنفذة'!$G$6:$AD$105*('الكميات المنفذة'!$G$5:$AD$5<=$A15))) | H15: =IF($C15="","",G15-N(G14)) | I15: =IF($C15="","",SUMIFS('الأوامر التغييرية'!$J$6:$J$55,'الأوامر التغييرية'!$H$6:$H$55,"معتمد",'الأوامر التغييرية'!$K$6:$K$55,"<="&$A15)) | K15: =IF($C15="","",G15+I15+N(J15)) | L15: =IF($C15="","",IF(ContractValue+I15>0,(G15+I15)/(ContractValue+I15),0)) | M15: 0.63 | N15: =IF(OR($C15="",M15=""),"",L15-M15) | O15: =IF($C15="","",ROUND(IF(L15>=RecFull,AdvAmount,MIN(AdvAmount,MAX(0,G15+I15-RecStart*ContractValue)*RecRate)),2)) | P15: =IF($C15="","",ROUND(MIN(K15*RetPct,RetCap),2)) | R15: =IF($C15="","",P15-SUM($Q$6:Q15)) | S15: =IF($C15="","",SUMIFS('الاستقطاعات الفنية'!$I$6:$I$105,'الاستقطاعات الفنية'!$D$6:$D$105,"<="&$A15)-SUMIFS('الاستقطاعات الفنية'!$I$6:$I$105,'الاستقطاعات الفنية'!$J$6:$J$105,"نعم",'الاستقطاعات الفنية'!$K$6:$K$105,"<="&$A15)) | U15: =IF($C15="","",K15-O15-R15-S15-SUM($T$6:T15)) | V15: =IF($C15="","",ROUND(VATPct*(U15+IF(VATBeforeRet="نعم",R15,0)),2)) | W15: =IF($C15="","",ROUND(WHTPct*(U15+R15),2)) | X15: =IF($C15="","",U15+V15-W15) | Y15: =IF($C15="","",N(X14)) | Z15: =IF($C15="","",X15-Y15) | AC15: =IF($C15="","",Z15-N(AA15)) | AD15: =IF(OR(AB15="",E15=""),"",AB15-E15) | AE15: =IF($C15="","",IF(N(AA15)=0,IF(E15="","⏳ بانتظار الاعتماد","✖ غير محصل"),IF(AC15<=1,"✔ محصل بالكامل","⚠ محصل جزئياً")))
A16: 11 | G16: =IF($C16="","",SUMPRODUCT('الكميات المنفذة'!$F$6:$F$105*'الكميات المنفذة'!$G$6:$AD$105*('الكميات المنفذة'!$G$5:$AD$5<=$A16))) | H16: =IF($C16="","",G16-N(G15)) | I16: =IF($C16="","",SUMIFS('الأوامر التغييرية'!$J$6:$J$55,'الأوامر التغييرية'!$H$6:$H$55,"معتمد",'الأوامر التغييرية'!$K$6:$K$55,"<="&$A16)) | K16: =IF($C16="","",G16+I16+N(J16)) | L16: =IF($C16="","",IF(ContractValue+I16>0,(G16+I16)/(ContractValue+I16),0)) | M16: 0.7 | N16: =IF(OR($C16="",M16=""),"",L16-M16) | O16: =IF($C16="","",ROUND(IF(L16>=RecFull,AdvAmount,MIN(AdvAmount,MAX(0,G16+I16-RecStart*ContractValue)*RecRate)),2)) | P16: =IF($C16="","",ROUND(MIN(K16*RetPct,RetCap),2)) | R16: =IF($C16="","",P16-SUM($Q$6:Q16)) | S16: =IF($C16="","",SUMIFS('الاستقطاعات الفنية'!$I$6:$I$105,'الاستقطاعات الفنية'!$D$6:$D$105,"<="&$A16)-SUMIFS('الاستقطاعات الفنية'!$I$6:$I$105,'الاستقطاعات الفنية'!$J$6:$J$105,"نعم",'الاستقطاعات الفنية'!$K$6:$K$105,"<="&$A16)) | U16: =IF($C16="","",K16-O16-R16-S16-SUM($T$6:T16)) | V16: =IF($C16="","",ROUND(VATPct*(U16+IF(VATBeforeRet="نعم",R16,0)),2)) | W16: =IF($C16="","",ROUND(WHTPct*(U16+R16),2)) | X16: =IF($C16="","",U16+V16-W16) | Y16: =IF($C16="","",N(X15)) | Z16: =IF($C16="","",X16-Y16) | AC16: =IF($C16="","",Z16-N(AA16)) | AD16: =IF(OR(AB16="",E16=""),"",AB16-E16) | AE16: =IF($C16="","",IF(N(AA16)=0,IF(E16="","⏳ بانتظار الاعتماد","✖ غير محصل"),IF(AC16<=1,"✔ محصل بالكامل","⚠ محصل جزئياً")))
