Workbook

Sheet لوحة التحكم
B1: 📊 لوحة التحكم — متابعة مستخلصات المشروع
B2: ='الإعدادات'!$C$6&" | المالك: "&'الإعدادات'!$C$8&" | المقاول: "&'الإعدادات'!$C$9&" | تاريخ التقرير: "&TEXT(TODAY(),"yyyy/mm/dd")
B3: ⚙ الإعدادات | D3: 📋 جدول الكميات | F3: 🗂 سجل المستخلصات | H3: 💵 الدفعات المقدمة | J3: 🔒 ضمان الأعمال | L3: 📄 مستخلص 1
P4: بيانات الرسم البياني (مساعدة)
B5: قيمة العقد (بدون ضريبة) | E5: الأعمال المنفذة تراكمياً | H5: نسبة الإنجاز المالي | K5: نسبة المدة المنقضية | P5: المستخلص | Q5: الأعمال الحالية | R5: الأعمال التراكمية | S5: المحصّل | U5: الحالة | V5: القيمة
B6: ='الإعدادات'!$C$19 | E6: ='سجل المستخلصات'!G31 | H6: =IF('الإعدادات'!$C$19=0,0,'سجل المستخلصات'!G31/'الإعدادات'!$C$19) | K6: =IF(OR('الإعدادات'!C13="",'الإعدادات'!C14=""),0,MAX(0,MIN(1,(TODAY()-'الإعدادات'!C13)/'الإعدادات'!C14))) | P6: ="م"&1 | Q6: ='سجل المستخلصات'!G6 | R6: ='سجل المستخلصات'!H6 | S6: ='سجل المستخلصات'!P6 | U6: المحصّل | V6: ='سجل المستخلصات'!P31
B7: ="شاملة الضريبة: "&TEXT('الإعدادات'!C20,"#,##0") | E7: ="المتبقي من العقد: "&TEXT('الإعدادات'!$C$19-'سجل المستخلصات'!G31,"#,##0") | H7: قيمة المنفذ ÷ قيمة العقد | K7: =IF('الإعدادات'!C15="","","تاريخ الانتهاء: "&TEXT('الإعدادات'!C15,"yyyy/mm/dd")) | P7: ="م"&2 | Q7: ='سجل المستخلصات'!G7 | R7: ='سجل المستخلصات'!H7 | S7: ='سجل المستخلصات'!P7 | U7: مستحق غير محصل | V7: =MAX(0,'سجل المستخلصات'!R31)
P8: ="م"&3 | Q8: ='سجل المستخلصات'!G8 | R8: ='سجل المستخلصات'!H8 | S8: ='سجل المستخلصات'!P8 | U8: ضمان محتجز | V8: ='ضمان الأعمال'!E11
B9: صافي المستحق التراكمي | E9: إجمالي المحصّل | H9: المتبقي لدى المالك (غير محصل) | K9: آخر مستخلص صادر | P9: ="م"&4 | Q9: ='سجل المستخلصات'!G9 | R9: ='سجل المستخلصات'!H9 | S9: ='سجل المستخلصات'!P9 | U9: متبقي من العقد (لم ينفذ) | V9: =MAX(0,'الإعدادات'!C20-'سجل المستخلصات'!K31)
B10: ='سجل المستخلصات'!O31 | E10: ='سجل المستخلصات'!P31 | H10: ='سجل المستخلصات'!R31 | K10: =SUMPRODUCT(MAX(('سجل المستخلصات'!C6:C30<>"")*'سجل المستخلصات'!B6:B30)) | P10: ="م"&5 | Q10: ='سجل المستخلصات'!G10 | R10: ='سجل المستخلصات'!H10 | S10: ='سجل المستخلصات'!P10
B11: بعد الضريبة والخصومات | E11: =TEXT(IF('سجل المستخلصات'!O31=0,0,'سجل المستخلصات'!P31/'سجل المستخلصات'!O31),"0%")&" من المستحق" | H11: مستحقات متأخرة | K11: =IF($K$10=0,"","صافي: "&TEXT(INDEX('سجل المستخلصات'!O6:O30,$K$10),"#,##0")&" | "&TEXT(INDEX('سجل المستخلصات'!C6:C30,$K$10),"yyyy/mm/dd")) | P11: ="م"&6 | Q11: ='سجل المستخلصات'!G11 | R11: ='سجل المستخلصات'!H11 | S11: ='سجل المستخلصات'!P11
P12: ="م"&7 | Q12: ='سجل المستخلصات'!G12 | R12: ='سجل المستخلصات'!H12 | S12: ='سجل المستخلصات'!P12
B13: الدفعات المقدمة المصروفة | E13: رصيد الدفعة المقدمة المتبقي | H13: ضمان الأعمال المحتجز | K13: تنبيهات الضمانات البنكية | P13: ="م"&8 | Q13: ='سجل المستخلصات'!G13 | R13: ='سجل المستخلصات'!H13 | S13: ='سجل المستخلصات'!P13
B14: ='الدفعات المقدمة'!E8 | E14: ='الدفعات المقدمة'!E11 | H14: ='ضمان الأعمال'!E11 | K14: =COUNTIF('الدفعات المقدمة'!I15:I20,"<=30")+COUNTIF('ضمان الأعمال'!K55:K60,"<=30") | P14: ="م"&9 | Q14: ='سجل المستخلصات'!G14 | R14: ='سجل المستخلصات'!H14 | S14: ='سجل المستخلصات'!P14
B15: ="المسترد: "&TEXT('الدفعات المقدمة'!E10,"#,##0") | E15: =TEXT('الدفعات المقدمة'!L50,"0%")&" تم استرداده" | H15: ="المفرج عنه: "&TEXT('ضمان الأعمال'!E10,"#,##0") | K15: ضمانات منتهية أو تنتهي خلال 30 يوماً | P15: ="م"&10 | Q15: ='سجل المستخلصات'!G15 | R15: ='سجل المستخلصات'!H15 | S15: ='سجل المستخلصات'!P15
P16: ="م"&11 | Q16: ='سجل المستخلصات'!G16 | R16: ='سجل المستخلصات'!H16 | S16: ='سجل المستخلصات'!P16
B17: الملخص المالي التراكمي | H17: حالة تنفيذ البنود | P17: ="م"&12 | Q17: ='سجل المستخلصات'!G17 | R17: ='سجل المستخلصات'!H17 | S17: ='سجل المستخلصات'!P17
B18: إجمالي قيمة الأعمال المنفذة | E18: ='سجل المستخلصات'!G31 | G18: =IF($E$18=0,0,E18/$E$18) | H18: إجمالي عدد البنود | J18: =SUMPRODUCT(('جدول الكميات'!C6:C105<>"")*1) | P18: ="م"&13 | Q18: ='سجل المستخلصات'!G18 | R18: ='سجل المستخلصات'!H18 | S18: ='سجل المستخلصات'!P18
B19: ضريبة القيمة المضافة | E19: ='سجل المستخلصات'!J31 | G19: =IF($E$18=0,0,E19/$E$18) | H19: ✔ بنود مكتملة 100% | J19: =COUNTIF('جدول الكميات'!M6:M105,"✔*") | K19: =IF($J$18=0,0,J19/$J$18) | P19: ="م"&14 | Q19: ='سجل المستخلصات'!G19 | R19: ='سجل المستخلصات'!H19 | S19: ='سجل المستخلصات'!P19
B20: الإجمالي شامل الضريبة | E20: ='سجل المستخلصات'!K31 | G20: =IF($E$18=0,0,E20/$E$18) | H20: ⚠ مركبة بالكامل وبها نواقص | J20: =COUNTIF('جدول الكميات'!M6:M105,"⚠*") | K20: =IF($J$18=0,0,J20/$J$18) | P20: ="م"&15 | Q20: ='سجل المستخلصات'!G20 | R20: ='سجل المستخلصات'!H20 | S20: ='سجل المستخلصات'!P20
B21: (-) استرداد الدفعة المقدمة | E21: ='سجل المستخلصات'!L31 | G21: =IF($E$18=0,0,E21/$E$18) | H21: ◔ بنود جارية | J21: =COUNTIF('جدول الكميات'!M6:M105,"◔*") | K21: =IF($J$18=0,0,J21/$J$18) | P21: ="م"&16 | Q21: ='سجل المستخلصات'!G21 | R21: ='سجل المستخلصات'!H21 | S21: ='سجل المستخلصات'!P21
B22: (-) ضمان الأعمال | E22: ='سجل المستخلصات'!M31 | G22: =IF($E$18=0,0,E22/$E$18) | H22: ○ بنود لم تبدأ | J22: =COUNTIF('جدول الكميات'!M6:M105,"○*") | K22: =IF($J$18=0,0,J22/$J$18) | P22: ="م"&17 | Q22: ='سجل المستخلصات'!G22 | R22: ='سجل المستخلصات'!H22 | S22: ='سجل المستخلصات'!P22
B23: (-) خصومات أخرى | E23: ='سجل المستخلصات'!N31 | G23: =IF($E$18=0,0,E23/$E$18) | H23: ✖ بنود تجاوزت الكمية التعاقدية | J23: =SUMPRODUCT(('جدول الكميات'!E6:E105>0)*('جدول الكميات'!I6:I105>'جدول الكميات'!E6:E105)) | K23: =IF($J$18=0,0,J23/$J$18) | P23: ="م"&18 | Q23: ='سجل المستخلصات'!G23 | R23: ='سجل المستخلصات'!H23 | S23: ='سجل المستخلصات'!P23
B24: صافي المستحق للمقاول | E24: ='سجل المستخلصات'!O31 | G24: =IF($E$18=0,0,E24/$E$18) | H24: متوسط نسبة الإنجاز الفعلية للبنود | J24: =IF(J18=0,0,SUMPRODUCT(('جدول الكميات'!C6:C105<>"")*('جدول الكميات'!L6:L105))/J18) | P24: ="م"&19 | Q24: ='سجل المستخلصات'!G24 | R24: ='سجل المستخلصات'!H24 | S24: ='سجل المستخلصات'!P24
B25: المحصّل | E25: ='سجل المستخلصات'!P31 | G25: =IF($E$18=0,0,E25/$E$18) | H25: الأداء (الإنجاز المالي مقابل المدة) | J25: =H6-K6 | L25: =IF(K6=0,"-",IF(H6>=K6,"✔ متقدم / حسب الجدول",IF(K6-H6<=0.1,"⚠ تأخر بسيط","✖ متأخر"))) | P25: ="م"&20 | Q25: ='سجل المستخلصات'!G25 | R25: ='سجل المستخلصات'!H25 | S25: ='سجل المستخلصات'!P25
B26: المتبقي غير المحصل | E26: ='سجل المستخلصات'!R31 | G26: =IF($E$18=0,0,E26/$E$18) | P26: ="م"&21 | Q26: ='سجل المستخلصات'!G26 | R26: ='سجل المستخلصات'!H26 | S26: ='سجل المستخلصات'!P26
P27: ="م"&22 | Q27: ='سجل المستخلصات'!G27 | R27: ='سجل المستخلصات'!H27 | S27: ='سجل المستخلصات'!P27
B28: التقدم حسب أقسام الأعمال | P28: ="م"&23 | Q28: ='سجل المستخلصات'!G28 | R28: ='سجل المستخلصات'!H28 | S28: ='سجل المستخلصات'!P28
B29: القسم | E29: قيمة العقد | G29: الوزن النسبي | H29: القيمة المنفذة | J29: المتبقي | L29: نسبة الإنجاز | P29: ="م"&24 | Q29: ='سجل المستخلصات'!G29 | R29: ='سجل المستخلصات'!H29 | S29: ='سجل المستخلصات'!P29
B30: =IF('الإعدادات'!C22="","",'الإعدادات'!C22) | E30: =IF(B30="",0,SUMIF('جدول الكميات'!B6:B105,B30,'جدول الكميات'!G6:G105)) | G30: =IF('الإعدادات'!$C$19=0,0,E30/'الإعدادات'!$C$19) | H30: =IF(B30="",0,SUMIF('جدول الكميات'!B6:B105,B30,'جدول الكميات'!K6:K105)) | J30: =E30-H30 | L30: =IF(E30=0,0,H30/E30) | P30: ="م"&25 | Q30: ='سجل المستخلصات'!G30 | R30: ='سجل المستخلصات'!H30 | S30: ='سجل المستخلصات'!P30
B31: =IF('الإعدادات'!C23="","",'الإعدادات'!C23) | E31: =IF(B31="",0,SUMIF('جدول الكميات'!B6:B105,B31,'جدول الكميات'!G6:G105)) | G31: =IF('الإعدادات'!$C$19=0,0,E31/'الإعدادات'!$C$19) | H31: =IF(B31="",0,SUMIF('جدول الكميات'!B6:B105,B31,'جدول الكميات'!K6:K105)) | J31: =E31-H31 | L31: =IF(E31=0,0,H31/E31)
B32: =IF('الإعدادات'!C24="","",'الإعدادات'!C24) | E32: =IF(B32="",0,SUMIF('جدول الكميات'!B6:B105,B32,'جدول الكميات'!G6:G105)) | G32: =IF('الإعدادات'!$C$19=0,0,E32/'الإعدادات'!$C$19) | H32: =IF(B32="",0,SUMIF('جدول الكميات'!B6:B105,B32,'جدول الكميات'!K6:K105)) | J32: =E32-H32 | L32: =IF(E32=0,0,H32/E32)
B33: =IF('الإعدادات'!C25="","",'الإعدادات'!C25) | E33: =IF(B33="",0,SUMIF('جدول الكميات'!B6:B105,B33,'جدول الكميات'!G6:G105)) | G33: =IF('الإعدادات'!$C$19=0,0,E33/'الإعدادات'!$C$19) | H33: =IF(B33="",0,SUMIF('جدول الكميات'!B6:B105,B33,'جدول الكميات'!K6:K105)) | J33: =E33-H33 | L33: =IF(E33=0,0,H33/E33)
B34: =IF('الإعدادات'!C26="","",'الإعدادات'!C26) | E34: =IF(B34="",0,SUMIF('جدول الكميات'!B6:B105,B34,'جدول الكميات'!G6:G105)) | G34: =IF('الإعدادات'!$C$19=0,0,E34/'الإعدادات'!$C$19) | H34: =IF(B34="",0,SUMIF('جدول الكميات'!B6:B105,B34,'جدول الكميات'!K6:K105)) | J34: =E34-H34 | L34: =IF(E34=0,0,H34/E34)
B35: =IF('الإعدادات'!C27="","",'الإعدادات'!C27) | E35: =IF(B35="",0,SUMIF('جدول الكميات'!B6:B105,B35,'جدول الكميات'!G6:G105)) | G35: =IF('الإعدادات'!$C$19=0,0,E35/'الإعدادات'!$C$19) | H35: =IF(B35="",0,SUMIF('جدول الكميات'!B6:B105,B35,'جدول الكميات'!K6:K105)) | J35: =E35-H35 | L35: =IF(E35=0,0,H35/E35)
B36: =IF('الإعدادات'!C28="","",'الإعدادات'!C28) | E36: =IF(B36="",0,SUMIF('جدول الكميات'!B6:B105,B36,'جدول الكميات'!G6:G105)) | G36: =IF('الإعدادات'!$C$19=0,0,E36/'الإعدادات'!$C$19) | H36: =IF(B36="",0,SUMIF('جدول الكميات'!B6:B105,B36,'جدول الكميات'!K6:K105)) | J36: =E36-H36 | L36: =IF(E36=0,0,H36/E36)
B37: =IF('الإعدادات'!C29="","",'الإعدادات'!C29) | E37: =IF(B37="",0,SUMIF('جدول الكميات'!B6:B105,B37,'جدول الكميات'!G6:G105)) | G37: =IF('الإعدادات'!$C$19=0,0,E37/'الإعدادات'!$C$19) | H37: =IF(B37="",0,SUMIF('جدول الكميات'!B6:B105,B37,'جدول الكميات'!K6:K105)) | J37: =E37-H37 | L37: =IF(E37=0,0,H37/E37)
B38: =IF('الإعدادات'!C30="","",'الإعدادات'!C30) | E38: =IF(B38="",0,SUMIF('جدول الكميات'!B6:B105,B38,'جدول الكميات'!G6:G105)) | G38: =IF('الإعدادات'!$C$19=0,0,E38/'الإعدادات'!$C$19) | H38: =IF(B38="",0,SUMIF('جدول الكميات'!B6:B105,B38,'جدول الكميات'!K6:K105)) | J38: =E38-H38 | L38: =IF(E38=0,0,H38/E38)
B39: =IF('الإعدادات'!C31="","",'الإعدادات'!C31) | E39: =IF(B39="",0,SUMIF('جدول الكميات'!B6:B105,B39,'جدول الكميات'!G6:G105)) | G39: =IF('الإعدادات'!$C$19=0,0,E39/'الإعدادات'!$C$19) | H39: =IF(B39="",0,SUMIF('جدول الكميات'!B6:B105,B39,'جدول الكميات'!K6:K105)) | J39: =E39-H39 | L39: =IF(E39=0,0,H39/E39)
B40: =IF('الإعدادات'!C32="","",'الإعدادات'!C32) | E40: =IF(B40="",0,SUMIF('جدول الكميات'!B6:B105,B40,'جدول الكميات'!G6:G105)) | G40: =IF('الإعدادات'!$C$19=0,0,E40/'الإعدادات'!$C$19) | H40: =IF(B40="",0,SUMIF('جدول الكميات'!B6:B105,B40,'جدول الكميات'!K6:K105)) | J40: =E40-H40 | L40: =IF(E40=0,0,H40/E40)
...

Sheet التعليمات
B1: 📘 طريقة استخدام القالب
B2: ='الإعدادات'!$C$6&" | العقد رقم: "&'الإعدادات'!$C$7&" | المالك: "&'الإعدادات'!$C$8&" | المقاول: "&'الإعدادات'!$C$9
B3: 🏠
B6: فكرة القالب
C7: قالب متكامل لإعداد مستخلصات المقاولات حتى 25 مستخلص و100 بند، جميع الصفحات مربوطة ببعضها؛ الكميات السابقة تنتقل تلقائياً من كل مستخلص إلى الذي يليه، وتتجمع النتائج في السجل ولوحة التحكم.
B9: خطوات العمل
B10: 1 | C10: صفحة (الإعدادات): أدخل بيانات المشروع والعقد ونسبة الضريبة وأسماء أقسام الأعمال وأسماء المعتمدين.
B11: 2 | C11: صفحة (جدول الكميات): أدخل البنود: رقم البند، القسم، الوصف، الوحدة، الكمية، سعر الوحدة (حتى 100 بند).
B12: 3 | C12: صفحة (الدفعات المقدمة): سجل الدفعات المقدمة وخطابات ضمانها ونسبة الاسترداد من كل مستخلص.
B13: 4 | C13: صفحة (ضمان الأعمال): حدد نسبة الضمان والحد الأقصى، وسجل الإفراجات والضمانات البنكية.
B14: 5 | C14: في كل مستخلص: أدخل التاريخ والحالة والفترة، ثم الكمية الحالية فقط لكل بند (العمود الأصفر 'حالي').
B15: 6 | C15: نسبة الإنجاز/الاستحقاق للبند (اختياري): مثال 1000 شباك مركبة بالكامل لكن تنقصها الإكسسوارات ← اكتب الكمية 1000 في عمود (حالي) واكتب 70% في عمود (حالية ✎)؛ تُحتسب القيمة 70% فقط، وتظهر نسبة الإنجاز الفعلية 70%، ويظهر البند في لوحة التحكم ضمن (مركبة بالكامل وبها نواقص).
B16: 7 | C16: عند استكمال النواقص: في المستخلص الجديد اكتب 100% في عمود (حالية ✎) بدون كمية؛ فيُصرف الفرق (30%) تلقائياً في هذا المستخلص ويتحول البند إلى (مكتمل). النسبة تنتقل للمستخلصات التالية حتى تغيّرها.
B17: 8 | C17: الخصومات الأخرى / الغرامات تُكتب يدوياً أسفل كل مستخلص في الخانة الصفراء.
B18: 9 | C18: صفحة (سجل المستخلصات): أدخل المبالغ المحصلة وتواريخها لمتابعة المستحقات.
B19: 10 | C19: صفحة (لوحة التحكم): تتحدث تلقائياً بالكامل ولا تحتاج أي إدخال.
B21: المعادلات الأساسية
B22: • | C22: قيمة البند الإجمالية = الكمية الإجمالية × سعر الوحدة × نسبة الإنجاز/الاستحقاق المعتمدة.
B23: • | C23: نسبة الإنجاز الفعلية = القيمة المستحقة ÷ (الكمية التعاقدية × سعر الوحدة)؛ بينما نسبة الكمية = المنفذ ÷ التعاقدي.
B24: • | C24: القيمة الحالية = القيمة الإجمالية − القيمة السابقة (من المستخلص السابق).
B25: • | C25: استرداد الدفعة المقدمة = قيمة الأعمال الحالية × نسبة الاسترداد، بحد أقصى الرصيد المتبقي من الدفعة.
B26: • | C26: ضمان الأعمال = قيمة الأعمال الحالية × نسبة الضمان، بحد أقصى (اختياري) نسبة من قيمة العقد.
B27: • | C27: صافي المستخلص = (قيمة الأعمال + الضريبة) − (استرداد الدفعة + ضمان الأعمال + الخصومات الأخرى).
B29: التخصيص بحرية دون التأثير على لوحة التحكم
B30: • | C30: يمكن تعديل أي نص أو اسم قسم أو بند أو وحدة أو سعر أو نسبة؛ لوحة التحكم تعتمد على الإجماليات فقط.
B31: • | C31: أضف البنود الجديدة (أعمال إضافية / أوامر تغيير) في الصفوف الفارغة بنهاية جدول الكميات — لا تُدرج صفوفاً بين البنود ولا تحذف صفوفاً، حتى تبقى المستخلصات مرتبطة بنفس البنود.
B32: • | C32: لإخفاء الصفوف الفارغة عند الطباعة: استخدم التصفية في جدول الكميات أو أخفِ الصفوف الفارغة في المستخلص.
B33: • | C33: يمكن تغيير الألوان والخطوط والشعار وعناوين الأعمدة بحرية. لا تغيّر ترتيب الأعمدة أو أسماء الصفحات.
B34: • | C34: المستخلص رقم 25 يحمل دائماً الكميات التراكمية لآخر وضع (لأن المستخلصات غير الصادرة كمياتها الحالية صفر).
B36: دليل الألوان والتنبيهات
B37: • | C37: الخلايا الصفراء بخط أزرق = إدخال. البيضاء/الرمادية = معادلات. الأرقام الخضراء = مسحوبة من صفحة أخرى.
B38: • | C38: خلفية حمراء على الكمية الإجمالية = البند تجاوز الكمية التعاقدية.
B39: • | C39: المستخلص يعتبر 'صادراً' بمجرد إدخال تاريخه؛ وغير الصادر يظهر رمادياً في السجل.
B41: ملاحظة
B42: • | C42: الملف الذي يحتوي على بيانات مثال (35 بند و3 مستخلصات) للتوضيح؛ والنسخة (Blank) فارغة وجاهزة للعمل.

Sheet الإعدادات
B1: ⚙ الإعدادات العامة للمشروع
B2: ='الإعدادات'!$C$6&" | العقد رقم: "&'الإعدادات'!$C$7&" | المالك: "&'الإعدادات'!$C$8&" | المقاول: "&'الإعدادات'!$C$9
B3: 🏠 لوحة التحكم | C3: 📋 جدول الكميات | D3: 🗂 سجل المستخلصات | E3: 💵 الدفعات المقدمة | G3: 🔒 ضمان الأعمال
B5: بيانات المشروع والعقد | G5: دليل الألوان
B6: اسم المشروع | C6: اسم المشروع | G6: خلية إدخال — اكتب هنا
B7: رقم العقد | G7: خلية محسوبة بمعادلة — لا تعدلها
B8: المالك / العميل | C8: اسم المالك | G8: عنوان / رأس جدول
B9: المقاول | C9: اسم المقاول
B10: الاستشاري / الجهة المشرفة | G10: • غيّر أسماء الأقسام بحرية؛ ستتحدث القوائم ولوحة التحكم تلقائياً.
B11: موقع المشروع | G11: • نسبة الضريبة تطبق على جميع المستخلصات.
B12: تاريخ توقيع العقد | G12: • نسب الدفعة المقدمة والضمان تُضبط من صفحاتها الخاصة.
B13: تاريخ بدء التنفيذ (استلام الموقع)
B14: مدة العقد (يوم)
B15: تاريخ الانتهاء المخطط | C15: =IF(OR(C13="",C14=""),"",C13+C14)
B16: العملة | C16: ريال سعودي
B17: النسب والقيم المالية العامة
B18: نسبة ضريبة القيمة المضافة | C18: 0.15
B19: قيمة العقد (محسوبة من جدول الكميات) | C19: ='جدول الكميات'!G106
B20: قيمة العقد شاملة الضريبة | C20: =C19*(1+C18)
B21: أقسام الأعمال (تظهر في جدول الكميات ولوحة التحكم)
B22: القسم 1 | C22: أعمال الهيكل والترميم
B23: القسم 2 | C23: الواجهات والزجاج
B24: القسم 3 | C24: الأعمال المعدنية
B25: القسم 4 | C25: التشطيبات الداخلية
B26: القسم 5 | C26: دورات المياه
B27: القسم 6 | C27: الأعمال الكهربائية
B28: القسم 7 | C28: الأعمال الصحية والتكييف
B29: القسم 8 | C29: أعمال عامة وخارجية
B30: القسم 9
B31: القسم 10
B32: القسم 11
B33: القسم 12
B35: أسماء المعتمدين (تظهر أسفل كل مستخلص)
B36: مهندس الموقع (المقاول)
B37: مدير المشروع (المقاول)
B38: المهندس المشرف (الاستشاري)
B39: ممثل المالك

Sheet جدول الكميات
A1: 📋 جدول الكميات والأسعار (BOQ) — ومتابعة تنفيذ البنود
A2: ='الإعدادات'!$C$6&" | العقد رقم: "&'الإعدادات'!$C$7&" | المالك: "&'الإعدادات'!$C$8&" | المقاول: "&'الإعدادات'!$C$9
A3: 🏠 لوحة التحكم | C3: ⚙ الإعدادات | D3: 🗂 سجل المستخلصات | F3: 💵 الدفعات المقدمة | H3: 🔒 ضمان الأعمال | J3: 📄 مستخلص 1
A4: أضف البنود في الصفوف الفارغة (حتى 100 بند). الأعمدة الصفراء إدخال، والأعمدة من I إلى M تُحسب تلقائياً من المستخلصات. (نسبة الكمية) = ما تم تركيبه، و(نسبة الإنجاز الفعلية) = القيمة المستحقة ÷ قيمة البند، فتظهر النواقص (مثل الإكسسوارات) حتى لو اكتملت الكمية. لا تحذف صفوفاً ولا تُدرج صفوفاً بين البنود.
A5: رقم البند | B5: القسم | C5: بيان الأعمال | D5: الوحدة | E5: الكمية التعاقدية | F5: سعر الوحدة | G5: الإجمالي | H5: الوزن النسبي | I5: الكمية المنفذة حتى تاريخه | J5: نسبة الكمية المنفذة | K5: القيمة المستحقة حتى تاريخه | L5: نسبة الإنجاز الفعلية | M5: حالة البند | N5: ملاحظات / النواقص
G6: =ROUND(E6*F6,2) | H6: =IF($G$106=0,0,G6/$G$106) | I6: ='مستخلص 25'!H8 | J6: =IF(E6=0,0,I6/E6) | K6: ='مستخلص 25'!N8 | L6: =IF(G6=0,0,K6/G6) | M6: =IF(C6="","",IF(I6=0,"○ لم يبدأ",IF(AND(G6>0,K6>=G6),"✔ مكتمل",IF(AND(E6>0,I6>=E6),"⚠ مركب بالكامل - نواقص","◔ جاري"))))
G7: =ROUND(E7*F7,2) | H7: =IF($G$106=0,0,G7/$G$106) | I7: ='مستخلص 25'!H9 | J7: =IF(E7=0,0,I7/E7) | K7: ='مستخلص 25'!N9 | L7: =IF(G7=0,0,K7/G7) | M7: =IF(C7="","",IF(I7=0,"○ لم يبدأ",IF(AND(G7>0,K7>=G7),"✔ مكتمل",IF(AND(E7>0,I7>=E7),"⚠ مركب بالكامل - نواقص","◔ جاري"))))
G8: =ROUND(E8*F8,2) | H8: =IF($G$106=0,0,G8/$G$106) | I8: ='مستخلص 25'!H10 | J8: =IF(E8=0,0,I8/E8) | K8: ='مستخلص 25'!N10 | L8: =IF(G8=0,0,K8/G8) | M8: =IF(C8="","",IF(I8=0,"○ لم يبدأ",IF(AND(G8>0,K8>=G8),"✔ مكتمل",IF(AND(E8>0,I8>=E8),"⚠ مركب بالكامل - نواقص","◔ جاري"))))
G9: =ROUND(E9*F9,2) | H9: =IF($G$106=0,0,G9/$G$106) | I9: ='مستخلص 25'!H11 | J9: =IF(E9=0,0,I9/E9) | K9: ='مستخلص 25'!N11 | L9: =IF(G9=0,0,K9/G9) | M9: =IF(C9="","",IF(I9=0,"○ لم يبدأ",IF(AND(G9>0,K9>=G9),"✔ مكتمل",IF(AND(E9>0,I9>=E9),"⚠ مركب بالكامل - نواقص","◔ جاري"))))
G10: =ROUND(E10*F10,2) | H10: =IF($G$106=0,0,G10/$G$106) | I10: ='مستخلص 25'!H12 | J10: =IF(E10=0,0,I10/E10) | K10: ='مستخلص 25'!N12 | L10: =IF(G10=0,0,K10/G10) | M10: =IF(C10="","",IF(I10=0,"○ لم يبدأ",IF(AND(G10>0,K10>=G10),"✔ مكتمل",IF(AND(E10>0,I10>=E10),"⚠ مركب بالكامل - نواقص","◔ جاري"))))
G11: =ROUND(E11*F11,2) | H11: =IF($G$106=0,0,G11/$G$106) | I11: ='مستخلص 25'!H13 | J11: =IF(E11=0,0,I11/E11) | K11: ='مستخلص 25'!N13 | L11: =IF(G11=0,0,K11/G11) | M11: =IF(C11="","",IF(I11=0,"○ لم يبدأ",IF(AND(G11>0,K11>=G11),"✔ مكتمل",IF(AND(E11>0,I11>=E11),"⚠ مركب بالكامل - نواقص","◔ جاري"))))
G12: =ROUND(E12*F12,2) | H12: =IF($G$106=0,0,G12/$G$106) | I12: ='مستخلص 25'!H14 | J12: =IF(E12=0,0,I12/E12) | K12: ='مستخلص 25'!N14 | L12: =IF(G12=0,0,K12/G12) | M12: =IF(C12="","",IF(I12=0,"○ لم يبدأ",IF(AND(G12>0,K12>=G12),"✔ مكتمل",IF(AND(E12>0,I12>=E12),"⚠ مركب بالكامل - نواقص","◔ جاري"))))
G13: =ROUND(E13*F13,2) | H13: =IF($G$106=0,0,G13/$G$106) | I13: ='مستخلص 25'!H15 | J13: =IF(E13=0,0,I13/E13) | K13: ='مستخلص 25'!N15 | L13: =IF(G13=0,0,K13/G13) | M13: =IF(C13="","",IF(I13=0,"○ لم يبدأ",IF(AND(G13>0,K13>=G13),"✔ مكتمل",IF(AND(E13>0,I13>=E13),"⚠ مركب بالكامل - نواقص","◔ جاري"))))
G14: =ROUND(E14*F14,2) | H14: =IF($G$106=0,0,G14/$G$106) | I14: ='مستخلص 25'!H16 | J14: =IF(E14=0,0,I14/E14) | K14: ='مستخلص 25'!N16 | L14: =IF(G14=0,0,K14/G14) | M14: =IF(C14="","",IF(I14=0,"○ لم يبدأ",IF(AND(G14>0,K14>=G14),"✔ مكتمل",IF(AND(E14>0,I14>=E14),"⚠ مركب بالكامل - نواقص","◔ جاري"))))
G15: =ROUND(E15*F15,2) | H15: =IF($G$106=0,0,G15/$G$106) | I15: ='مستخلص 25'!H17 | J15: =IF(E15=0,0,I15/E15) | K15: ='مستخلص 25'!N17 | L15: =IF(G15=0,0,K15/G15) | M15: =IF(C15="","",IF(I15=0,"○ لم يبدأ",IF(AND(G15>0,K15>=G15),"✔ مكتمل",IF(AND(E15>0,I15>=E15),"⚠ مركب بالكامل - نواقص","◔ جاري"))))
G16: =ROUND(E16*F16,2) | H16: =IF($G$106=0,0,G16/$G$106) | I16: ='مستخلص 25'!H18 | J16: =IF(E16=0,0,I16/E16) | K16: ='مستخلص 25'!N18 | L16: =IF(G16=0,0,K16/G16) | M16: =IF(C16="","",IF(I16=0,"○ لم يبدأ",IF(AND(G16>0,K16>=G16),"✔ مكتمل",IF(AND(E16>0,I16>=E16),"⚠ مركب بالكامل - نواقص","◔ جاري"))))
G17: =ROUND(E17*F17,2) | H17: =IF($G$106=0,0,G17/$G$106) | I17: ='مستخلص 25'!H19 | J17: =IF(E17=0,0,I17/E17) | K17: ='مستخلص 25'!N19 | L17: =IF(G17=0,0,K17/G17) | M17: =IF(C17="","",IF(I17=0,"○ لم يبدأ",IF(AND(G17>0,K17>=G17),"✔ مكتمل",IF(AND(E17>0,I17>=E17),"⚠ مركب بالكامل - نواقص","◔ جاري"))))
... G105: =ROUND(E105*F105,2) | H105: =IF($G$106=0,0,G105/$G$106) | I105: ='مستخلص 25'!H107 | J105: =IF(E105=0,0,I105/E105) | K105: ='مستخلص 25'!N107 | L105: =IF(G105=0,0,K105/G105) | M105: =IF(C105="","",IF(I105=0,"○ لم يبدأ",IF(AND(G105>0,K105>=G105),"✔ مكتمل",IF(AND(E105>0,I105>=E105),"⚠ مركب بالكامل - نواقص","◔ جاري"))))
A106: الإجمالي | G106: =SUM(G6:G105) | H106: =SUM(H6:H105) | K106: =SUM(K6:K105) | L106: =IF(G106=0,0,K106/G106)

Sheet سجل المستخلصات
B1: 🗂 سجل المستخلصات والتحصيل
B2: ='الإعدادات'!$C$6&" | العقد رقم: "&'الإعدادات'!$C$7&" | المالك: "&'الإعدادات'!$C$8&" | المقاول: "&'الإعدادات'!$C$9
B3: 🏠 لوحة التحكم | D3: ⚙ الإعدادات | F3: 📋 جدول الكميات | H3: 💵 الدفعات المقدمة | J3: 🔒 ضمان الأعمال | L3: 📄 مستخلص 1
B4: هذه الصفحة تتجمع تلقائياً من المستخلصات. أدخل فقط المبالغ المحصلة وتواريخ التحصيل (الأعمدة الصفراء). اضغط على رقم المستخلص للانتقال إليه.
B5: رقم المستخلص | C5: تاريخ المستخلص | D5: الحالة | E5: الفترة من | F5: الفترة إلى | G5: قيمة الأعمال الحالية | H5: قيمة الأعمال التراكمية | I5: نسبة الإنجاز التراكمية | J5: ضريبة القيمة المضافة | K5: الإجمالي شامل الضريبة | L5: استرداد الدفعة المقدمة | M5: ضمان الأعمال | N5: خصومات أخرى | O5: صافي المستحق | P5: المبلغ المحصّل ✎ | Q5: تاريخ التحصيل ✎ | R5: المتبقي غير المحصل | S5: حالة التحصيل
B6: 1 | C6: =IF('مستخلص 1'!E4="","",'مستخلص 1'!E4) | D6: =IF(C6="","لم يصدر",IF('مستخلص 1'!H4="","جاري",'مستخلص 1'!H4)) | E6: =IF('مستخلص 1'!L4="","",'مستخلص 1'!L4) | F6: =IF('مستخلص 1'!N4="","",'مستخلص 1'!N4) | G6: ='مستخلص 1'!M111 | H6: ='مستخلص 1'!N111 | I6: =IF('الإعدادات'!$C$19=0,0,H6/'الإعدادات'!$C$19) | J6: ='مستخلص 1'!M112 | K6: ='مستخلص 1'!M113 | L6: ='مستخلص 1'!M114 | M6: ='مستخلص 1'!M115 | N6: ='مستخلص 1'!M116 | O6: ='مستخلص 1'!M118 | R6: =ROUND(O6-P6,2) | S6: =IF(C6="","",IF(O6<=0,"-",IF(P6>=O6,"✔ محصل بالكامل",IF(P6>0,"⚠ محصل جزئياً","✖ غير محصل"))))
B7: 2 | C7: =IF('مستخلص 2'!E4="","",'مستخلص 2'!E4) | D7: =IF(C7="","لم يصدر",IF('مستخلص 2'!H4="","جاري",'مستخلص 2'!H4)) | E7: =IF('مستخلص 2'!L4="","",'مستخلص 2'!L4) | F7: =IF('مستخلص 2'!N4="","",'مستخلص 2'!N4) | G7: ='مستخلص 2'!M111 | H7: ='مستخلص 2'!N111 | I7: =IF('الإعدادات'!$C$19=0,0,H7/'الإعدادات'!$C$19) | J7: ='مستخلص 2'!M112 | K7: ='مستخلص 2'!M113 | L7: ='مستخلص 2'!M114 | M7: ='مستخلص 2'!M115 | N7: ='مستخلص 2'!M116 | O7: ='مستخلص 2'!M118 | R7: =ROUND(O7-P7,2) | S7: =IF(C7="","",IF(O7<=0,"-",IF(P7>=O7,"✔ محصل بالكامل",IF(P7>0,"⚠ محصل جزئياً","✖ غير محصل"))))
B8: 3 | C8: =IF('مستخلص 3'!E4="","",'مستخلص 3'!E4) | D8: =IF(C8="","لم يصدر",IF('مستخلص 3'!H4="","جاري",'مستخلص 3'!H4)) | E8: =IF('مستخلص 3'!L4="","",'مستخلص 3'!L4) | F8: =IF('مستخلص 3'!N4="","",'مستخلص 3'!N4) | G8: ='مستخلص 3'!M111 | H8: ='مستخلص 3'!N111 | I8: =IF('الإعدادات'!$C$19=0,0,H8/'الإعدادات'!$C$19) | J8: ='مستخلص 3'!M112 | K8: ='مستخلص 3'!M113 | L8: ='مستخلص 3'!M114 | M8: ='مستخلص 3'!M115 | N8: ='مستخلص 3'!M116 | O8: ='مستخلص 3'!M118 | R8: =ROUND(O8-P8,2) | S8: =IF(C8="","",IF(O8<=0,"-",IF(P8>=O8,"✔ محصل بالكامل",IF(P8>0,"⚠ محصل جزئياً","✖ غير محصل"))))
B9: 4 | C9: =IF('مستخلص 4'!E4="","",'مستخلص 4'!E4) | D9: =IF(C9="","لم يصدر",IF('مستخلص 4'!H4="","جاري",'مستخلص 4'!H4)) | E9: =IF('مستخلص 4'!L4="","",'مستخلص 4'!L4) | F9: =IF('مستخلص 4'!N4="","",'مستخلص 4'!N4) | G9: ='مستخلص 4'!M111 | H9: ='مستخلص 4'!N111 | I9: =IF('الإعدادات'!$C$19=0,0,H9/'الإعدادات'!$C$19) | J9: ='مستخلص 4'!M112 | K9: ='مستخلص 4'!M113 | L9: ='مستخلص 4'!M114 | M9: ='مستخلص 4'!M115 | N9: ='مستخلص 4'!M116 | O9: ='مستخلص 4'!M118 | R9: =ROUND(O9-P9,2) | S9: =IF(C9="","",IF(O9<=0,"-",IF(P9>=O9,"✔ محصل بالكامل",IF(P9>0,"⚠ محصل جزئياً","✖ غير محصل"))))
B10: 5 | C10: =IF('مستخلص 5'!E4="","",'مستخلص 5'!E4) | D10: =IF(C10="","لم يصدر",IF('مستخلص 5'!H4="","جاري",'مستخلص 5'!H4)) | E10: =IF('مستخلص 5'!L4="","",'مستخلص 5'!L4) | F10: =IF('مستخلص 5'!N4="","",'مستخلص 5'!N4) | G10: ='مستخلص 5'!M111 | H10: ='مستخلص 5'!N111 | I10: =IF('الإعدادات'!$C$19=0,0,H10/'الإعدادات'!$C$19) | J10: ='مستخلص 5'!M112 | K10: ='مستخلص 5'!M113 | L10: ='مستخلص 5'!M114 | M10: ='مستخلص 5'!M115 | N10: ='مستخلص 5'!M116 | O10: ='مستخلص 5'!M118 | R10: =ROUND(O10-P10,2) | S10: =IF(C10="","",IF(O10<=0,"-",IF(P10>=O10,"✔ محصل بالكامل",IF(P10>0,"⚠ محصل جزئياً","✖ غير محصل"))))
B11: 6 | C11: =IF('مستخلص 6'!E4="","",'مستخلص 6'!E4) | D11: =IF(C11="","لم يصدر",IF('مستخلص 6'!H4="","جاري",'مستخلص 6'!H4)) | E11: =IF('مستخلص 6'!L4="","",'مستخلص 6'!L4) | F11: =IF('مستخلص 6'!N4="","",'مستخلص 6'!N4) | G11: ='مستخلص 6'!M111 | H11: ='مستخلص 6'!N111 | I11: =IF('الإعدادات'!$C$19=0,0,H11/'الإعدادات'!$C$19) | J11: ='مستخلص 6'!M112 | K11: ='مستخلص 6'!M113 | L11: ='مستخلص 6'!M114 | M11: ='مستخلص 6'!M115 | N11: ='مستخلص 6'!M116 | O11: ='مستخلص 6'!M118 | R11: =ROUND(O11-P11,2) | S11: =IF(C11="","",IF(O11<=0,"-",IF(P11>=O11,"✔ محصل بالكامل",IF(P11>0,"⚠ محصل جزئياً","✖ غير محصل"))))
B12: 7 | C12: =IF('مستخلص 7'!E4="","",'مستخلص 7'!E4) | D12: =IF(C12="","لم يصدر",IF('مستخلص 7'!H4="","جاري",'مستخلص 7'!H4)) | E12: =IF('مستخلص 7'!L4="","",'مستخلص 7'!L4) | F12: =IF('مستخلص 7'!N4="","",'مستخلص 7'!N4) | G12: ='مستخلص 7'!M111 | H12: ='مستخلص 7'!N111 | I12: =IF('الإعدادات'!$C$19=0,0,H12/'الإعدادات'!$C$19) | J12: ='مستخلص 7'!M112 | K12: ='مستخلص 7'!M113 | L12: ='مستخلص 7'!M114 | M12: ='مستخلص 7'!M115 | N12: ='مستخلص 7'!M116 | O12: ='مستخلص 7'!M118 | R12: =ROUND(O12-P12,2) | S12: =IF(C12="","",IF(O12<=0,"-",IF(P12>=O12,"✔ محصل بالكامل",IF(P12>0,"⚠ محصل جزئياً","✖ غير محصل"))))
B13: 8 | C13: =IF('مستخلص 8'!E4="","",'مستخلص 8'!E4) | D13: =IF(C13="","لم يصدر",IF('مستخلص 8'!H4="","جاري",'مستخلص 8'!H4)) | E13: =IF('مستخلص 8'!L4="","",'مستخلص 8'!L4) | F13: =IF('مستخلص 8'!N4="","",'مستخلص 8'!N4) | G13: ='مستخلص 8'!M111 | H13: ='مستخلص 8'!N111 | I13: =IF('الإعدادات'!$C$19=0,0,H13/'الإعدادات'!$C$19) | J13: ='مستخلص 8'!M112 | K13: ='مستخلص 8'!M113 | L13: ='مستخلص 8'!M114 | M13: ='مستخلص 8'!M115 | N13: ='مستخلص 8'!M116 | O13: ='مستخلص 8'!M118 | R13: =ROUND(O13-P13,2) | S13: =IF(C13="","",IF(O13<=0,"-",IF(P13>=O13,"✔ محصل بالكامل",IF(P13>0,"⚠ محصل جزئياً","✖ غير محصل"))))
B14: 9 | C14: =IF('مستخلص 9'!E4="","",'مستخلص 9'!E4) | D14: =IF(C14="","لم يصدر",IF('مستخلص 9'!H4="","جاري",'مستخلص 9'!H4)) | E14: =IF('مستخلص 9'!L4="","",'مستخلص 9'!L4) | F14: =IF('مستخلص 9'!N4="","",'مستخلص 9'!N4) | G14: ='مستخلص 9'!M111 | H14: ='مستخلص 9'!N111 | I14: =IF('الإعدادات'!$C$19=0,0,H14/'الإعدادات'!$C$19) | J14: ='مستخلص 9'!M112 | K14: ='مستخلص 9'!M113 | L14: ='مستخلص 9'!M114 | M14: ='مستخلص 9'!M115 | N14: ='مستخلص 9'!M116 | O14: ='مستخلص 9'!M118 | R14: =ROUND(O14-P14,2) | S14: =IF(C14="","",IF(O14<=0,"-",IF(P14>=O14,"✔ محصل بالكامل",IF(P14>0,"⚠ محصل جزئياً","✖ غير محصل"))))
B15: 10 | C15: =IF('مستخلص 10'!E4="","",'مستخلص 10'!E4) | D15: =IF(C15="","لم يصدر",IF('مستخلص 10'!H4="","جاري",'مستخلص 10'!H4)) | E15: =IF('مستخلص 10'!L4="","",'مستخلص 10'!L4) | F15: =IF('مستخلص 10'!N4="","",'مستخلص 10'!N4) | G15: ='مستخلص 10'!M111 | H15: ='مستخلص 10'!N111 | I15: =IF('الإعدادات'!$C$19=0,0,H15/'الإعدادات'!$C$19) | J15: ='مستخلص 10'!M112 | K15: ='مستخلص 10'!M113 | L15: ='مستخلص 10'!M114 | M15: ='مستخلص 10'!M115 | N15: ='مستخلص 10'!M116 | O15: ='مستخلص 10'!M118 | R15: =ROUND(O15-P15,2) | S15: =IF(C15="","",IF(O15<=0,"-",IF(P15>=O15,"✔ محصل بالكامل",IF(P15>0,"⚠ محصل جزئياً","✖ غير محصل"))))
B16: 11 | C16: =IF('مستخلص 11'!E4="","",'مستخلص 11'!E4) | D16: =IF(C16="","لم يصدر",IF('مستخلص 11'!H4="","جاري",'مستخلص 11'!H4)) | E16: =IF('مستخلص 11'!L4="","",'مستخلص 11'!L4) | F16: =IF('مستخلص 11'!N4="","",'مستخلص 11'!N4) | G16: ='مستخلص 11'!M111 | H16: ='مستخلص 11'!N111 | I16: =IF('الإعدادات'!$C$19=0,0,H16/'الإعدادات'!$C$19) | J16: ='مستخلص 11'!M112 | K16: ='مستخلص 11'!M113 | L16: ='مستخلص 11'!M114 | M16: ='مستخلص 11'!M115 | N16: ='مستخلص 11'!M116 | O16: ='مستخلص 11'!M118 | R16: =ROUND(O16-P16,2) | S16: =IF(C16="","",IF(O16<=0,"-",IF(P16>=O16,"✔ محصل بالكامل",IF(P16>0,"⚠ محصل جزئياً","✖ غير محصل"))))
B17: 12 | C17: =IF('مستخلص 12'!E4="","",'مستخلص 12'!E4) | D17: =IF(C17="","لم يصدر",IF('مستخلص 12'!H4="","جاري",'مستخلص 12'!H4)) | E17: =IF('مستخلص 12'!L4="","",'مستخلص 12'!L4) | F17: =IF('مستخلص 12'!N4="","",'مستخلص 12'!N4) | G17: ='مستخلص 12'!M111 | H17: ='مستخلص 12'!N111 | I17: =IF('الإعدادات'!$C$19=0,0,H17/'الإعدادات'!$C$19) | J17: ='مستخلص 12'!M112 | K17: ='مستخلص 12'!M113 | L17: ='مستخلص 12'!M114 | M17: ='مستخلص 12'!M115 | N17: ='مستخلص 12'!M116 | O17: ='مستخلص 12'!M118 | R17: =ROUND(O17-P17,2) | S17: =IF(C17="","",IF(O17<=0,"-",IF(P17>=O17,"✔ محصل بالكامل",IF(P17>0,"⚠ محصل جزئياً","✖ غير محصل"))))
B18: 13 | C18: =IF('مستخلص 13'!E4="","",'مستخلص 13'!E4) | D18: =IF(C18="","لم يصدر",IF('مستخلص 13'!H4="","جاري",'مستخلص 13'!H4)) | E18: =IF('مستخلص 13'!L4="","",'مستخلص 13'!L4) | F18: =IF('مستخلص 13'!N4="","",'مستخلص 13'!N4) | G18: ='مستخلص 13'!M111 | H18: ='مستخلص 13'!N111 | I18: =IF('الإعدادات'!$C$19=0,0,H18/'الإعدادات'!$C$19) | J18: ='مستخلص 13'!M112 | K18: ='مستخلص 13'!M113 | L18: ='مستخلص 13'!M114 | M18: ='مستخلص 13'!M115 | N18: ='مستخلص 13'!M116 | O18: ='مستخلص 13'!M118 | R18: =ROUND(O18-P18,2) | S18: =IF(C18="","",IF(O18<=0,"-",IF(P18>=O18,"✔ محصل بالكامل",IF(P18>0,"⚠ محصل جزئياً","✖ غير محصل"))))
B19: 14 | C19: =IF('مستخلص 14'!E4="","",'مستخلص 14'!E4) | D19: =IF(C19="","لم يصدر",IF('مستخلص 14'!H4="","جاري",'مستخلص 14'!H4)) | E19: =IF('مستخلص 14'!L4="","",'مستخلص 14'!L4) | F19: =IF('مستخلص 14'!N4="","",'مستخلص 14'!N4) | G19: ='مستخلص 14'!M111 | H19: ='مستخلص 14'!N111 | I19: =IF('الإعدادات'!$C$19=0,0,H19/'الإعدادات'!$C$19) | J19: ='مستخلص 14'!M112 | K19: ='مستخلص 14'!M113 | L19: ='مستخلص 14'!M114 | M19: ='مستخلص 14'!M115 | N19: ='مستخلص 14'!M116 | O19: ='مستخلص 14'!M118 | R19: =ROUND(O19-P19,2) | S19: =IF(C19="","",IF(O19<=0,"-",IF(P19>=O19,"✔ محصل بالكامل",IF(P19>0,"⚠ محصل جزئياً","✖ غير محصل"))))
B20: 15 | C20: =IF('مستخلص 15'!E4="","",'مستخلص 15'!E4) | D20: =IF(C20="","لم يصدر",IF('مستخلص 15'!H4="","جاري",'مستخلص 15'!H4)) | E20: =IF('مستخلص 15'!L4="","",'مستخلص 15'!L4) | F20: =IF('مستخلص 15'!N4="","",'مستخلص 15'!N4) | G20: ='مستخلص 15'!M111 | H20: ='مستخلص 15'!N111 | I20: =IF('الإعدادات'!$C$19=0,0,H20/'الإعدادات'!$C$19) | J20: ='مستخلص 15'!M112 | K20: ='مستخلص 15'!M113 | L20: ='مستخلص 15'!M114 | M20: ='مستخلص 15'!M115 | N20: ='مستخلص 15'!M116 | O20: ='مستخلص 15'!M118 | R20: =ROUND(O20-P20,2) | S20: =IF(C20="","",IF(O20<=0,"-",IF(P20>=O20,"✔ محصل بالكامل",IF(P20>0,"⚠ محصل جزئياً","✖ غير محصل"))))
B21: 16 | C21: =IF('مستخلص 16'!E4="","",'مستخلص 16'!E4) | D21: =IF(C21="","لم يصدر",IF('مستخلص 16'!H4="","جاري",'مستخلص 16'!H4)) | E21: =IF('مستخلص 16'!L4="","",'مستخلص 16'!L4) | F21: =IF('مستخلص 16'!N4="","",'مستخلص 16'!N4) | G21: ='مستخلص 16'!M111 | H21: ='مستخلص 16'!N111 | I21: =IF('الإعدادات'!$C$19=0,0,H21/'الإعدادات'!$C$19) | J21: ='مستخلص 16'!M112 | K21: ='مستخلص 16'!M113 | L21: ='مستخلص 16'!M114 | M21: ='مستخلص 16'!M115 | N21: ='مستخلص 16'!M116 | O21: ='مستخلص 16'!M118 | R21: =ROUND(O21-P21,2) | S21: =IF(C21="","",IF(O21<=0,"-",IF(P21>=O21,"✔ محصل بالكامل",IF(P21>0,"⚠ محصل جزئياً","✖ غير محصل"))))
B22: 17 | C22: =IF('مستخلص 17'!E4="","",'مستخلص 17'!E4) | D22: =IF(C22="","لم يصدر",IF('مستخلص 17'!H4="","جاري",'مستخلص 17'!H4)) | E22: =IF('مستخلص 17'!L4="","",'مستخلص 17'!L4) | F22: =IF('مستخلص 17'!N4="","",'مستخلص 17'!N4) | G22: ='مستخلص 17'!M111 | H22: ='مستخلص 17'!N111 | I22: =IF('الإعدادات'!$C$19=0,0,H22/'الإعدادات'!$C$19) | J22: ='مستخلص 17'!M112 | K22: ='مستخلص 17'!M113 | L22: ='مستخلص 17'!M114 | M22: ='مستخلص 17'!M115 | N22: ='مستخلص 17'!M116 | O22: ='مستخلص 17'!M118 | R22: =ROUND(O22-P22,2) | S22: =IF(C22="","",IF(O22<=0,"-",IF(P22>=O22,"✔ محصل بالكامل",IF(P22>0,"⚠ محصل جزئياً","✖ غير محصل"))))
B23: 18 | C23: =IF('مستخلص 18'!E4="","",'مستخلص 18'!E4) | D23: =IF(C23="","لم يصدر",IF('مستخلص 18'!H4="","جاري",'مستخلص 18'!H4)) | E23: =IF('مستخلص 18'!L4="","",'مستخلص 18'!L4) | F23: =IF('مستخلص 18'!N4="","",'مستخلص 18'!N4) | G23: ='مستخلص 18'!M111 | H23: ='مستخلص 18'!N111 | I23: =IF('الإعدادات'!$C$19=0,0,H23/'الإعدادات'!$C$19) | J23: ='مستخلص 18'!M112 | K23: ='مستخلص 18'!M113 | L23: ='مستخلص 18'!M114 | M23: ='مستخلص 18'!M115 | N23: ='مستخلص 18'!M116 | O23: ='مستخلص 18'!M118 | R23: =ROUND(O23-P23,2) | S23: =IF(C23="","",IF(O23<=0,"-",IF(P23>=O23,"✔ محصل بالكامل",IF(P23>0,"⚠ محصل جزئياً","✖ غير محصل"))))
B24: 19 | C24: =IF('مستخلص 19'!E4="","",'مستخلص 19'!E4) | D24: =IF(C24="","لم يصدر",IF('مستخلص 19'!H4="","جاري",'مستخلص 19'!H4)) | E24: =IF('مستخلص 19'!L4="","",'مستخلص 19'!L4) | F24: =IF('مستخلص 19'!N4="","",'مستخلص 19'!N4) | G24: ='مستخلص 19'!M111 | H24: ='مستخلص 19'!N111 | I24: =IF('الإعدادات'!$C$19=0,0,H24/'الإعدادات'!$C$19) | J24: ='مستخلص 19'!M112 | K24: ='مستخلص 19'!M113 | L24: ='مستخلص 19'!M114 | M24: ='مستخلص 19'!M115 | N24: ='مستخلص 19'!M116 | O24: ='مستخلص 19'!M118 | R24: =ROUND(O24-P24,2) | S24: =IF(C24="","",IF(O24<=0,"-",IF(P24>=O24,"✔ محصل بالكامل",IF(P24>0,"⚠ محصل جزئياً","✖ غير محصل"))))
B25: 20 | C25: =IF('مستخلص 20'!E4="","",'مستخلص 20'!E4) | D25: =IF(C25="","لم يصدر",IF('مستخلص 20'!H4="","جاري",'مستخلص 20'!H4)) | E25: =IF('مستخلص 20'!L4="","",'مستخلص 20'!L4) | F25: =IF('مستخلص 20'!N4="","",'مستخلص 20'!N4) | G25: ='مستخلص 20'!M111 | H25: ='مستخلص 20'!N111 | I25: =IF('الإعدادات'!$C$19=0,0,H25/'الإعدادات'!$C$19) | J25: ='مستخلص 20'!M112 | K25: ='مستخلص 20'!M113 | L25: ='مستخلص 20'!M114 | M25: ='مستخلص 20'!M115 | N25: ='مستخلص 20'!M116 | O25: ='مستخلص 20'!M118 | R25: =ROUND(O25-P25,2) | S25: =IF(C25="","",IF(O25<=0,"-",IF(P25>=O25,"✔ محصل بالكامل",IF(P25>0,"⚠ محصل جزئياً","✖ غير محصل"))))
B26: 21 | C26: =IF('مستخلص 21'!E4="","",'مستخلص 21'!E4) | D26: =IF(C26="","لم يصدر",IF('مستخلص 21'!H4="","جاري",'مستخلص 21'!H4)) | E26: =IF('مستخلص 21'!L4="","",'مستخلص 21'!L4) | F26: =IF('مستخلص 21'!N4="","",'مستخلص 21'!N4) | G26: ='مستخلص 21'!M111 | H26: ='مستخلص 21'!N111 | I26: =IF('الإعدادات'!$C$19=0,0,H26/'الإعدادات'!$C$19) | J26: ='مستخلص 21'!M112 | K26: ='مستخلص 21'!M113 | L26: ='مستخلص 21'!M114 | M26: ='مستخلص 21'!M115 | N26: ='مستخلص 21'!M116 | O26: ='مستخلص 21'!M118 | R26: =ROUND(O26-P26,2) | S26: =IF(C26="","",IF(O26<=0,"-",IF(P26>=O26,"✔ محصل بالكامل",IF(P26>0,"⚠ محصل جزئياً","✖ غير محصل"))))
B27: 22 | C27: =IF('مستخلص 22'!E4="","",'مستخلص 22'!E4) | D27: =IF(C27="","لم يصدر",IF('مستخلص 22'!H4="","جاري",'مستخلص 22'!H4)) | E27: =IF('مستخلص 22'!L4="","",'مستخلص 22'!L4) | F27: =IF('مستخلص 22'!N4="","",'مستخلص 22'!N4) | G27: ='مستخلص 22'!M111 | H27: ='مستخلص 22'!N111 | I27: =IF('الإعدادات'!$C$19=0,0,H27/'الإعدادات'!$C$19) | J27: ='مستخلص 22'!M112 | K27: ='مستخلص 22'!M113 | L27: ='مستخلص 22'!M114 | M27: ='مستخلص 22'!M115 | N27: ='مستخلص 22'!M116 | O27: ='مستخلص 22'!M118 | R27: =ROUND(O27-P27,2) | S27: =IF(C27="","",IF(O27<=0,"-",IF(P27>=O27,"✔ محصل بالكامل",IF(P27>0,"⚠ محصل جزئياً","✖ غير محصل"))))
B28: 23 | C28: =IF('مستخلص 23'!E4="","",'مستخلص 23'!E4) | D28: =IF(C28="","لم يصدر",IF('مستخلص 23'!H4="","جاري",'مستخلص 23'!H4)) | E28: =IF('مستخلص 23'!L4="","",'مستخلص 23'!L4) | F28: =IF('مستخلص 23'!N4="","",'مستخلص 23'!N4) | G28: ='مستخلص 23'!M111 | H28: ='مستخلص 23'!N111 | I28: =IF('الإعدادات'!$C$19=0,0,H28/'الإعدادات'!$C$19) | J28: ='مستخلص 23'!M112 | K28: ='مستخلص 23'!M113 | L28: ='مستخلص 23'!M114 | M28: ='مستخلص 23'!M115 | N28: ='مستخلص 23'!M116 | O28: ='مستخلص 23'!M118 | R28: =ROUND(O28-P28,2) | S28: =IF(C28="","",IF(O28<=0,"-",IF(P28>=O28,"✔ محصل بالكامل",IF(P28>0,"⚠ محصل جزئياً","✖ غير محصل"))))
B29: 24 | C29: =IF('مستخلص 24'!E4="","",'مستخلص 24'!E4) | D29: =IF(C29="","لم يصدر",IF('مستخلص 24'!H4="","جاري",'مستخلص 24'!H4)) | E29: =IF('مستخلص 24'!L4="","",'مستخلص 24'!L4) | F29: =IF('مستخلص 24'!N4="","",'مستخلص 24'!N4) | G29: ='مستخلص 24'!M111 | H29: ='مستخلص 24'!N111 | I29: =IF('الإعدادات'!$C$19=0,0,H29/'الإعدادات'!$C$19) | J29: ='مستخلص 24'!M112 | K29: ='مستخلص 24'!M113 | L29: ='مستخلص 24'!M114 | M29: ='مستخلص 24'!M115 | N29: ='مستخلص 24'!M116 | O29: ='مستخلص 24'!M118 | R29: =ROUND(O29-P29,2) | S29: =IF(C29="","",IF(O29<=0,"-",IF(P29>=O29,"✔ محصل بالكامل",IF(P29>0,"⚠ محصل جزئياً","✖ غير محصل"))))
B30: 25 | C30: =IF('مستخلص 25'!E4="","",'مستخلص 25'!E4) | D30: =IF(C30="","لم يصدر",IF('مستخلص 25'!H4="","جاري",'مستخلص 25'!H4)) | E30: =IF('مستخلص 25'!L4="","",'مستخلص 25'!L4) | F30: =IF('مستخلص 25'!N4="","",'مستخلص 25'!N4) | G30: ='مستخلص 25'!M111 | H30: ='مستخلص 25'!N111 | I30: =IF('الإعدادات'!$C$19=0,0,H30/'الإعدادات'!$C$19) | J30: ='مستخلص 25'!M112 | K30: ='مستخلص 25'!M113 | L30: ='مستخلص 25'!M114 | M30: ='مستخلص 25'!M115 | N30: ='مستخلص 25'!M116 | O30: ='مستخلص 25'!M118 | R30: =ROUND(O30-P30,2) | S30: =IF(C30="","",IF(O30<=0,"-",IF(P30>=O30,"✔ محصل بالكامل",IF(P30>0,"⚠ محصل جزئياً","✖ غير محصل"))))
B31: الإجمالي | G31: =SUM(G6:G30) | H31: =MAX(H6:H30) | I31: =IF('الإعدادات'!$C$19=0,0,H31/'الإعدادات'!$C$19) | J31: =SUM(J6:J30) | K31: =SUM(K6:K30) | L31: =SUM(L6:L30) | M31: =SUM(M6:M30) | N31: =SUM(N6:N30) | O31: =SUM(O6:O30) | P31: =SUM(P6:P30) | R31: =SUM(R6:R30)

Sheet الدفعات المقدمة
B1: 💵 الدفعات المقدمة واستردادها
B2: ='الإعدادات'!$C$6&" | العقد رقم: "&'الإعدادات'!$C$7&" | المالك: "&'الإعدادات'!$C$8&" | المقاول: "&'الإعدادات'!$C$9
B3: 🏠 لوحة التحكم | D3: ⚙ الإعدادات | E3: 📋 جدول الكميات | G3: 🗂 سجل المستخلصات | I3: 🔒 ضمان الأعمال | K3: 📄 مستخلص 1
B5: إعدادات الاسترداد والملخص | H5: كيف تعمل الصفحة؟
B6: نسبة الاسترداد من قيمة أعمال كل مستخلص | E6: 0.1 | H6: 1) سجّل كل دفعة مقدمة مصروفة وخطاب ضمانها في الجدول الأول. 2) يُستقطع من كل مستخلص (قيمة الأعمال الحالية × نسبة الاسترداد) تلقائياً ويظهر في المستخلص. 3) يتوقف الاسترداد تلقائياً عند اكتمال استرداد كامل الدفعة (لا يتجاوز الرصيد). 4) يمكنك إدخال نسبة مخصصة لمستخلص معين في العمود الأصفر (مثلاً لتسريع الاسترداد في الختامي).
B7: بدء الاسترداد من المستخلص رقم | E7: 1
B8: إجمالي الدفعات المقدمة المصروفة | E8: =D21
B9: نسبة الدفعة المقدمة من قيمة العقد | E9: =IF('الإعدادات'!$C$19=0,0,E8/'الإعدادات'!$C$19)
B10: إجمالي ما تم استرداده | E10: =I50
B11: الرصيد المتبقي للاسترداد | E11: =E8-E10
B13: سجل صرف الدفعات المقدمة وخطابات ضمانها
B14: م | C14: تاريخ الصرف | D14: المبلغ المصروف | E14: % من العقد | F14: رقم خطاب الضمان | G14: البنك | H14: تاريخ انتهاء الضمان | I14: الأيام المتبقية | J14: حالة الضمان | K14: ملاحظات
B15: 1 | E15: =IF('الإعدادات'!$C$19=0,0,D15/'الإعدادات'!$C$19) | I15: =IF(H15="","",H15-TODAY()) | J15: =IF(H15="","",IF(I15<0,"✖ منتهي",IF(I15<=30,"⚠ ينتهي قريباً","✔ ساري")))
B16: 2 | E16: =IF('الإعدادات'!$C$19=0,0,D16/'الإعدادات'!$C$19) | I16: =IF(H16="","",H16-TODAY()) | J16: =IF(H16="","",IF(I16<0,"✖ منتهي",IF(I16<=30,"⚠ ينتهي قريباً","✔ ساري")))
B17: 3 | E17: =IF('الإعدادات'!$C$19=0,0,D17/'الإعدادات'!$C$19) | I17: =IF(H17="","",H17-TODAY()) | J17: =IF(H17="","",IF(I17<0,"✖ منتهي",IF(I17<=30,"⚠ ينتهي قريباً","✔ ساري")))
B18: 4 | E18: =IF('الإعدادات'!$C$19=0,0,D18/'الإعدادات'!$C$19) | I18: =IF(H18="","",H18-TODAY()) | J18: =IF(H18="","",IF(I18<0,"✖ منتهي",IF(I18<=30,"⚠ ينتهي قريباً","✔ ساري")))
B19: 5 | E19: =IF('الإعدادات'!$C$19=0,0,D19/'الإعدادات'!$C$19) | I19: =IF(H19="","",H19-TODAY()) | J19: =IF(H19="","",IF(I19<0,"✖ منتهي",IF(I19<=30,"⚠ ينتهي قريباً","✔ ساري")))
B20: 6 | E20: =IF('الإعدادات'!$C$19=0,0,D20/'الإعدادات'!$C$19) | I20: =IF(H20="","",H20-TODAY()) | J20: =IF(H20="","",IF(I20<0,"✖ منتهي",IF(I20<=30,"⚠ ينتهي قريباً","✔ ساري")))
B21: الإجمالي | D21: =SUM(D15:D20) | E21: =SUM(E15:E20)
B23: جدول استرداد الدفعة المقدمة من المستخلصات
B24: رقم المستخلص | C24: التاريخ | D24: قيمة الأعمال الحالية | E24: النسبة الافتراضية | F24: نسبة مخصصة ✎ (اختياري) | G24: النسبة المطبقة | H24: الاسترداد المحسوب | I24: الاسترداد المعتمد | J24: المسترد التراكمي | K24: الرصيد المتبقي | L24: % المسترد
B25: 1 | C25: ='سجل المستخلصات'!C6 | D25: ='مستخلص 1'!M111 | E25: =$E$6 | G25: =IF(B25<$E$7,0,IF(F25="",E25,F25)) | H25: =MAX(0,ROUND(D25*G25,2)) | I25: =MIN(H25,MAX(0,$E$8-0)) | J25: =0+I25 | K25: =$E$8-J25 | L25: =IF($E$8=0,0,J25/$E$8)
B26: 2 | C26: ='سجل المستخلصات'!C7 | D26: ='مستخلص 2'!M111 | E26: =$E$6 | G26: =IF(B26<$E$7,0,IF(F26="",E26,F26)) | H26: =MAX(0,ROUND(D26*G26,2)) | I26: =MIN(H26,MAX(0,$E$8-J25)) | J26: =J25+I26 | K26: =$E$8-J26 | L26: =IF($E$8=0,0,J26/$E$8)
B27: 3 | C27: ='سجل المستخلصات'!C8 | D27: ='مستخلص 3'!M111 | E27: =$E$6 | G27: =IF(B27<$E$7,0,IF(F27="",E27,F27)) | H27: =MAX(0,ROUND(D27*G27,2)) | I27: =MIN(H27,MAX(0,$E$8-J26)) | J27: =J26+I27 | K27: =$E$8-J27 | L27: =IF($E$8=0,0,J27/$E$8)
B28: 4 | C28: ='سجل المستخلصات'!C9 | D28: ='مستخلص 4'!M111 | E28: =$E$6 | G28: =IF(B28<$E$7,0,IF(F28="",E28,F28)) | H28: =MAX(0,ROUND(D28*G28,2)) | I28: =MIN(H28,MAX(0,$E$8-J27)) | J28: =J27+I28 | K28: =$E$8-J28 | L28: =IF($E$8=0,0,J28/$E$8)
B29: 5 | C29: ='سجل المستخلصات'!C10 | D29: ='مستخلص 5'!M111 | E29: =$E$6 | G29: =IF(B29<$E$7,0,IF(F29="",E29,F29)) | H29: =MAX(0,ROUND(D29*G29,2)) | I29: =MIN(H29,MAX(0,$E$8-J28)) | J29: =J28+I29 | K29: =$E$8-J29 | L29: =IF($E$8=0,0,J29/$E$8)
B30: 6 | C30: ='سجل المستخلصات'!C11 | D30: ='مستخلص 6'!M111 | E30: =$E$6 | G30: =IF(B30<$E$7,0,IF(F30="",E30,F30)) | H30: =MAX(0,ROUND(D30*G30,2)) | I30: =MIN(H30,MAX(0,$E$8-J29)) | J30: =J29+I30 | K30: =$E$8-J30 | L30: =IF($E$8=0,0,J30/$E$8)
B31: 7 | C31: ='سجل المستخلصات'!C12 | D31: ='مستخلص 7'!M111 | E31: =$E$6 | G31: =IF(B31<$E$7,0,IF(F31="",E31,F31)) | H31: =MAX(0,ROUND(D31*G31,2)) | I31: =MIN(H31,MAX(0,$E$8-J30)) | J31: =J30+I31 | K31: =$E$8-J31 | L31: =IF($E$8=0,0,J31/$E$8)
B32: 8 | C32: ='سجل المستخلصات'!C13 | D32: ='مستخلص 8'!M111 | E32: =$E$6 | G32: =IF(B32<$E$7,0,IF(F32="",E32,F32)) | H32: =MAX(0,ROUND(D32*G32,2)) | I32: =MIN(H32,MAX(0,$E$8-J31)) | J32: =J31+I32 | K32: =$E$8-J32 | L32: =IF($E$8=0,0,J32/$E$8)
B33: 9 | C33: ='سجل المستخلصات'!C14 | D33: ='مستخلص 9'!M111 | E33: =$E$6 | G33: =IF(B33<$E$7,0,IF(F33="",E33,F33)) | H33: =MAX(0,ROUND(D33*G33,2)) | I33: =MIN(H33,MAX(0,$E$8-J32)) | J33: =J32+I33 | K33: =$E$8-J33 | L33: =IF($E$8=0,0,J33/$E$8)
B34: 10 | C34: ='سجل المستخلصات'!C15 | D34: ='مستخلص 10'!M111 | E34: =$E$6 | G34: =IF(B34<$E$7,0,IF(F34="",E34,F34)) | H34: =MAX(0,ROUND(D34*G34,2)) | I34: =MIN(H34,MAX(0,$E$8-J33)) | J34: =J33+I34 | K34: =$E$8-J34 | L34: =IF($E$8=0,0,J34/$E$8)
B35: 11 | C35: ='سجل المستخلصات'!C16 | D35: ='مستخلص 11'!M111 | E35: =$E$6 | G35: =IF(B35<$E$7,0,IF(F35="",E35,F35)) | H35: =MAX(0,ROUND(D35*G35,2)) | I35: =MIN(H35,MAX(0,$E$8-J34)) | J35: =J34+I35 | K35: =$E$8-J35 | L35: =IF($E$8=0,0,J35/$E$8)
B36: 12 | C36: ='سجل المستخلصات'!C17 | D36: ='مستخلص 12'!M111 | E36: =$E$6 | G36: =IF(B36<$E$7,0,IF(F36="",E36,F36)) | H36: =MAX(0,ROUND(D36*G36,2)) | I36: =MIN(H36,MAX(0,$E$8-J35)) | J36: =J35+I36 | K36: =$E$8-J36 | L36: =IF($E$8=0,0,J36/$E$8)
B37: 13 | C37: ='سجل المستخلصات'!C18 | D37: ='مستخلص 13'!M111 | E37: =$E$6 | G37: =IF(B37<$E$7,0,IF(F37="",E37,F37)) | H37: =MAX(0,ROUND(D37*G37,2)) | I37: =MIN(H37,MAX(0,$E$8-J36)) | J37: =J36+I37 | K37: =$E$8-J37 | L37: =IF($E$8=0,0,J37/$E$8)
B38: 14 | C38: ='سجل المستخلصات'!C19 | D38: ='مستخلص 14'!M111 | E38: =$E$6 | G38: =IF(B38<$E$7,0,IF(F38="",E38,F38)) | H38: =MAX(0,ROUND(D38*G38,2)) | I38: =MIN(H38,MAX(0,$E$8-J37)) | J38: =J37+I38 | K38: =$E$8-J38 | L38: =IF($E$8=0,0,J38/$E$8)
B39: 15 | C39: ='سجل المستخلصات'!C20 | D39: ='مستخلص 15'!M111 | E39: =$E$6 | G39: =IF(B39<$E$7,0,IF(F39="",E39,F39)) | H39: =MAX(0,ROUND(D39*G39,2)) | I39: =MIN(H39,MAX(0,$E$8-J38)) | J39: =J38+I39 | K39: =$E$8-J39 | L39: =IF($E$8=0,0,J39/$E$8)
B40: 16 | C40: ='سجل المستخلصات'!C21 | D40: ='مستخلص 16'!M111 | E40: =$E$6 | G40: =IF(B40<$E$7,0,IF(F40="",E40,F40)) | H40: =MAX(0,ROUND(D40*G40,2)) | I40: =MIN(H40,MAX(0,$E$8-J39)) | J40: =J39+I40 | K40: =$E$8-J40 | L40: =IF($E$8=0,0,J40/$E$8)
B41: 17 | C41: ='سجل المستخلصات'!C22 | D41: ='مستخلص 17'!M111 | E41: =$E$6 | G41: =IF(B41<$E$7,0,IF(F41="",E41,F41)) | H41: =MAX(0,ROUND(D41*G41,2)) | I41: =MIN(H41,MAX(0,$E$8-J40)) | J41: =J40+I41 | K41: =$E$8-J41 | L41: =IF($E$8=0,0,J41/$E$8)
B42: 18 | C42: ='سجل المستخلصات'!C23 | D42: ='مستخلص 18'!M111 | E42: =$E$6 | G42: =IF(B42<$E$7,0,IF(F42="",E42,F42)) | H42: =MAX(0,ROUND(D42*G42,2)) | I42: =MIN(H42,MAX(0,$E$8-J41)) | J42: =J41+I42 | K42: =$E$8-J42 | L42: =IF($E$8=0,0,J42/$E$8)
B43: 19 | C43: ='سجل المستخلصات'!C24 | D43: ='مستخلص 19'!M111 | E43: =$E$6 | G43: =IF(B43<$E$7,0,IF(F43="",E43,F43)) | H43: =MAX(0,ROUND(D43*G43,2)) | I43: =MIN(H43,MAX(0,$E$8-J42)) | J43: =J42+I43 | K43: =$E$8-J43 | L43: =IF($E$8=0,0,J43/$E$8)
...

Sheet ضمان الأعمال
B1: 🔒 ضمان الأعمال (المحتجزات) والضمانات البنكية
B2: ='الإعدادات'!$C$6&" | العقد رقم: "&'الإعدادات'!$C$7&" | المالك: "&'الإعدادات'!$C$8&" | المقاول: "&'الإعدادات'!$C$9
B3: 🏠 لوحة التحكم | D3: ⚙ الإعدادات | E3: 📋 جدول الكميات | G3: 🗂 سجل المستخلصات | I3: 💵 الدفعات المقدمة | K3: 📄 مستخلص 1
B5: إعدادات ضمان الأعمال والملخص | H5: شروط الإفراج (للتوثيق)
B6: نسبة ضمان الأعمال المستقطعة من كل مستخلص | E6: 0.1 | H6: مرحلة الإفراج | K6: نسبة الإفراج | L6: القيمة المتوقعة
B7: الحد الأقصى للضمان (% من قيمة العقد) — اتركه فارغاً بدون حد | H7: عند الاستلام الابتدائي | K7: 0.5 | L7: =ROUND($E$9*K7,2)
B8: قيمة الحد الأقصى | E8: =IF(E7="","بدون حد",E7*'الإعدادات'!$C$19) | H8: عند الاستلام النهائي (بعد فترة الصيانة) | K8: 0.5 | L8: =ROUND($E$9*K8,2)
B9: إجمالي المستقطع من المستخلصات | E9: =I41 | H9: أخرى | L9: =ROUND($E$9*K9,2)
B10: إجمالي المفرج عنه | E10: =F51 | H10: مدة فترة الضمان والصيانة (شهر) | L10: 12
B11: الرصيد المحتجز لدى المالك حالياً | E11: =E9-E10 | H11: تاريخ الإفراج النهائي المتوقع | L11: =IF(OR('الإعدادات'!C15="",L10=""),"",EDATE('الإعدادات'!C15,L10))
B14: جدول استقطاع ضمان الأعمال من المستخلصات
B15: رقم المستخلص | C15: التاريخ | D15: قيمة الأعمال الحالية | E15: النسبة الافتراضية | F15: نسبة مخصصة ✎ (اختياري) | G15: النسبة المطبقة | H15: الضمان المحسوب | I15: الضمان المعتمد | J15: الضمان التراكمي | K15: قيمة الأعمال التراكمية | L15: % من الأعمال
B16: 1 | C16: ='سجل المستخلصات'!C6 | D16: ='مستخلص 1'!M111 | E16: =$E$6 | G16: =IF(F16="",E16,F16) | H16: =MAX(0,ROUND(D16*G16,2)) | I16: =IF($E$7="",H16,MIN(H16,MAX(0,$E$7*'الإعدادات'!$C$19-0))) | J16: =0+I16 | K16: ='مستخلص 1'!N111 | L16: =IF(K16=0,0,J16/K16)
B17: 2 | C17: ='سجل المستخلصات'!C7 | D17: ='مستخلص 2'!M111 | E17: =$E$6 | G17: =IF(F17="",E17,F17) | H17: =MAX(0,ROUND(D17*G17,2)) | I17: =IF($E$7="",H17,MIN(H17,MAX(0,$E$7*'الإعدادات'!$C$19-J16))) | J17: =J16+I17 | K17: ='مستخلص 2'!N111 | L17: =IF(K17=0,0,J17/K17)
B18: 3 | C18: ='سجل المستخلصات'!C8 | D18: ='مستخلص 3'!M111 | E18: =$E$6 | G18: =IF(F18="",E18,F18) | H18: =MAX(0,ROUND(D18*G18,2)) | I18: =IF($E$7="",H18,MIN(H18,MAX(0,$E$7*'الإعدادات'!$C$19-J17))) | J18: =J17+I18 | K18: ='مستخلص 3'!N111 | L18: =IF(K18=0,0,J18/K18)
B19: 4 | C19: ='سجل المستخلصات'!C9 | D19: ='مستخلص 4'!M111 | E19: =$E$6 | G19: =IF(F19="",E19,F19) | H19: =MAX(0,ROUND(D19*G19,2)) | I19: =IF($E$7="",H19,MIN(H19,MAX(0,$E$7*'الإعدادات'!$C$19-J18))) | J19: =J18+I19 | K19: ='مستخلص 4'!N111 | L19: =IF(K19=0,0,J19/K19)
B20: 5 | C20: ='سجل المستخلصات'!C10 | D20: ='مستخلص 5'!M111 | E20: =$E$6 | G20: =IF(F20="",E20,F20) | H20: =MAX(0,ROUND(D20*G20,2)) | I20: =IF($E$7="",H20,MIN(H20,MAX(0,$E$7*'الإعدادات'!$C$19-J19))) | J20: =J19+I20 | K20: ='مستخلص 5'!N111 | L20: =IF(K20=0,0,J20/K20)
B21: 6 | C21: ='سجل المستخلصات'!C11 | D21: ='مستخلص 6'!M111 | E21: =$E$6 | G21: =IF(F21="",E21,F21) | H21: =MAX(0,ROUND(D21*G21,2)) | I21: =IF($E$7="",H21,MIN(H21,MAX(0,$E$7*'الإعدادات'!$C$19-J20))) | J21: =J20+I21 | K21: ='مستخلص 6'!N111 | L21: =IF(K21=0,0,J21/K21)
B22: 7 | C22: ='سجل المستخلصات'!C12 | D22: ='مستخلص 7'!M111 | E22: =$E$6 | G22: =IF(F22="",E22,F22) | H22: =MAX(0,ROUND(D22*G22,2)) | I22: =IF($E$7="",H22,MIN(H22,MAX(0,$E$7*'الإعدادات'!$C$19-J21))) | J22: =J21+I22 | K22: ='مستخلص 7'!N111 | L22: =IF(K22=0,0,J22/K22)
B23: 8 | C23: ='سجل المستخلصات'!C13 | D23: ='مستخلص 8'!M111 | E23: =$E$6 | G23: =IF(F23="",E23,F23) | H23: =MAX(0,ROUND(D23*G23,2)) | I23: =IF($E$7="",H23,MIN(H23,MAX(0,$E$7*'الإعدادات'!$C$19-J22))) | J23: =J22+I23 | K23: ='مستخلص 8'!N111 | L23: =IF(K23=0,0,J23/K23)
B24: 9 | C24: ='سجل المستخلصات'!C14 | D24: ='مستخلص 9'!M111 | E24: =$E$6 | G24: =IF(F24="",E24,F24) | H24: =MAX(0,ROUND(D24*G24,2)) | I24: =IF($E$7="",H24,MIN(H24,MAX(0,$E$7*'الإعدادات'!$C$19-J23))) | J24: =J23+I24 | K24: ='مستخلص 9'!N111 | L24: =IF(K24=0,0,J24/K24)
B25: 10 | C25: ='سجل المستخلصات'!C15 | D25: ='مستخلص 10'!M111 | E25: =$E$6 | G25: =IF(F25="",E25,F25) | H25: =MAX(0,ROUND(D25*G25,2)) | I25: =IF($E$7="",H25,MIN(H25,MAX(0,$E$7*'الإعدادات'!$C$19-J24))) | J25: =J24+I25 | K25: ='مستخلص 10'!N111 | L25: =IF(K25=0,0,J25/K25)
B26: 11 | C26: ='سجل المستخلصات'!C16 | D26: ='مستخلص 11'!M111 | E26: =$E$6 | G26: =IF(F26="",E26,F26) | H26: =MAX(0,ROUND(D26*G26,2)) | I26: =IF($E$7="",H26,MIN(H26,MAX(0,$E$7*'الإعدادات'!$C$19-J25))) | J26: =J25+I26 | K26: ='مستخلص 11'!N111 | L26: =IF(K26=0,0,J26/K26)
B27: 12 | C27: ='سجل المستخلصات'!C17 | D27: ='مستخلص 12'!M111 | E27: =$E$6 | G27: =IF(F27="",E27,F27) | H27: =MAX(0,ROUND(D27*G27,2)) | I27: =IF($E$7="",H27,MIN(H27,MAX(0,$E$7*'الإعدادات'!$C$19-J26))) | J27: =J26+I27 | K27: ='مستخلص 12'!N111 | L27: =IF(K27=0,0,J27/K27)
B28: 13 | C28: ='سجل المستخلصات'!C18 | D28: ='مستخلص 13'!M111 | E28: =$E$6 | G28: =IF(F28="",E28,F28) | H28: =MAX(0,ROUND(D28*G28,2)) | I28: =IF($E$7="",H28,MIN(H28,MAX(0,$E$7*'الإعدادات'!$C$19-J27))) | J28: =J27+I28 | K28: ='مستخلص 13'!N111 | L28: =IF(K28=0,0,J28/K28)
B29: 14 | C29: ='سجل المستخلصات'!C19 | D29: ='مستخلص 14'!M111 | E29: =$E$6 | G29: =IF(F29="",E29,F29) | H29: =MAX(0,ROUND(D29*G29,2)) | I29: =IF($E$7="",H29,MIN(H29,MAX(0,$E$7*'الإعدادات'!$C$19-J28))) | J29: =J28+I29 | K29: ='مستخلص 14'!N111 | L29: =IF(K29=0,0,J29/K29)
B30: 15 | C30: ='سجل المستخلصات'!C20 | D30: ='مستخلص 15'!M111 | E30: =$E$6 | G30: =IF(F30="",E30,F30) | H30: =MAX(0,ROUND(D30*G30,2)) | I30: =IF($E$7="",H30,MIN(H30,MAX(0,$E$7*'الإعدادات'!$C$19-J29))) | J30: =J29+I30 | K30: ='مستخلص 15'!N111 | L30: =IF(K30=0,0,J30/K30)
B31: 16 | C31: ='سجل المستخلصات'!C21 | D31: ='مستخلص 16'!M111 | E31: =$E$6 | G31: =IF(F31="",E31,F31) | H31: =MAX(0,ROUND(D31*G31,2)) | I31: =IF($E$7="",H31,MIN(H31,MAX(0,$E$7*'الإعدادات'!$C$19-J30))) | J31: =J30+I31 | K31: ='مستخلص 16'!N111 | L31: =IF(K31=0,0,J31/K31)
B32: 17 | C32: ='سجل المستخلصات'!C22 | D32: ='مستخلص 17'!M111 | E32: =$E$6 | G32: =IF(F32="",E32,F32) | H32: =MAX(0,ROUND(D32*G32,2)) | I32: =IF($E$7="",H32,MIN(H32,MAX(0,$E$7*'الإعدادات'!$C$19-J31))) | J32: =J31+I32 | K32: ='مستخلص 17'!N111 | L32: =IF(K32=0,0,J32/K32)
B33: 18 | C33: ='سجل المستخلصات'!C23 | D33: ='مستخلص 18'!M111 | E33: =$E$6 | G33: =IF(F33="",E33,F33) | H33: =MAX(0,ROUND(D33*G33,2)) | I33: =IF($E$7="",H33,MIN(H33,MAX(0,$E$7*'الإعدادات'!$C$19-J32))) | J33: =J32+I33 | K33: ='مستخلص 18'!N111 | L33: =IF(K33=0,0,J33/K33)
B34: 19 | C34: ='سجل المستخلصات'!C24 | D34: ='مستخلص 19'!M111 | E34: =$E$6 | G34: =IF(F34="",E34,F34) | H34: =MAX(0,ROUND(D34*G34,2)) | I34: =IF($E$7="",H34,MIN(H34,MAX(0,$E$7*'الإعدادات'!$C$19-J33))) | J34: =J33+I34 | K34: ='مستخلص 19'!N111 | L34: =IF(K34=0,0,J34/K34)
B35: 20 | C35: ='سجل المستخلصات'!C25 | D35: ='مستخلص 20'!M111 | E35: =$E$6 | G35: =IF(F35="",E35,F35) | H35: =MAX(0,ROUND(D35*G35,2)) | I35: =IF($E$7="",H35,MIN(H35,MAX(0,$E$7*'الإعدادات'!$C$19-J34))) | J35: =J34+I35 | K35: ='مستخلص 20'!N111 | L35: =IF(K35=0,0,J35/K35)
B36: 21 | C36: ='سجل المستخلصات'!C26 | D36: ='مستخلص 21'!M111 | E36: =$E$6 | G36: =IF(F36="",E36,F36) | H36: =MAX(0,ROUND(D36*G36,2)) | I36: =IF($E$7="",H36,MIN(H36,MAX(0,$E$7*'الإعدادات'!$C$19-J35))) | J36: =J35+I36 | K36: ='مستخلص 21'!N111 | L36: =IF(K36=0,0,J36/K36)
B37: 22 | C37: ='سجل المستخلصات'!C27 | D37: ='مستخلص 22'!M111 | E37: =$E$6 | G37: =IF(F37="",E37,F37) | H37: =MAX(0,ROUND(D37*G37,2)) | I37: =IF($E$7="",H37,MIN(H37,MAX(0,$E$7*'الإعدادات'!$C$19-J36))) | J37: =J36+I37 | K37: ='مستخلص 22'!N111 | L37: =IF(K37=0,0,J37/K37)
B38: 23 | C38: ='سجل المستخلصات'!C28 | D38: ='مستخلص 23'!M111 | E38: =$E$6 | G38: =IF(F38="",E38,F38) | H38: =MAX(0,ROUND(D38*G38,2)) | I38: =IF($E$7="",H38,MIN(H38,MAX(0,$E$7*'الإعدادات'!$C$19-J37))) | J38: =J37+I38 | K38: ='مستخلص 23'!N111 | L38: =IF(K38=0,0,J38/K38)
B39: 24 | C39: ='سجل المستخلصات'!C29 | D39: ='مستخلص 24'!M111 | E39: =$E$6 | G39: =IF(F39="",E39,F39) | H39: =MAX(0,ROUND(D39*G39,2)) | I39: =IF($E$7="",H39,MIN(H39,MAX(0,$E$7*'الإعدادات'!$C$19-J38))) | J39: =J38+I39 | K39: ='مستخلص 24'!N111 | L39: =IF(K39=0,0,J39/K39)
B40: 25 | C40: ='سجل المستخلصات'!C30 | D40: ='مستخلص 25'!M111 | E40: =$E$6 | G40: =IF(F40="",E40,F40) | H40: =MAX(0,ROUND(D40*G40,2)) | I40: =IF($E$7="",H40,MIN(H40,MAX(0,$E$7*'الإعدادات'!$C$19-J39))) | J40: =J39+I40 | K40: ='مستخلص 25'!N111 | L40: =IF(K40=0,0,J40/K40)
B41: الإجمالي | D41: =SUM(D16:D40) | H41: =SUM(H16:H40) | I41: =SUM(I16:I40)
B43: سجل الإفراج عن ضمان الأعمال
B44: م | C44: تاريخ الإفراج | D44: المرحلة / السبب | F44: المبلغ المفرج عنه | G44: % من المحتجز | H44: رقم الشيك / التحويل | I44: ملاحظات
...

Sheet مستخلص 1
A1: ="مستخلص أعمال رقم ( 1 ) — "&'الإعدادات'!$C$6
A2: ='الإعدادات'!$C$6&" | العقد رقم: "&'الإعدادات'!$C$7&" | المالك: "&'الإعدادات'!$C$8&" | المقاول: "&'الإعدادات'!$C$9
A3: 🏠 | B3: 🗂 سجل المستخلصات | C3: 📋 BOQ | F3: 💵 المقدمة | H3: 🔒 الضمان | N3: المستخلص التالي (2) ▶
A4: رقم | B4: 1 | C4: تاريخ المستخلص | G4: الحالة | J4: الفترة من | M4: إلى
A5: المشروع | B5: ='الإعدادات'!$C$6 | C5: المالك | E5: ='الإعدادات'!$C$8 | J5: المقاول | L5: ='الإعدادات'!$C$9
A6: البند | B6: بيان الأعمال | C6: الوحدة | D6: الكمية التعاقدية | E6: سعر الوحدة | F6: الكمية المنفذة من واقع التمتير الفعلي | I6: نسبة الإنجاز / الاستحقاق للبند | L6: قيمة الأعمال المنفذة | O6: نسبة الإنجاز الفعلية | P6: ملاحظات
F7: سابق | G7: حالي ✎ | H7: إجمالي | I7: سابقة | J7: حالية ✎ (اختياري) | K7: المعتمدة | L7: سابقة | M7: حالية | N7: إجمالية
A8: =IF('جدول الكميات'!A6="","",'جدول الكميات'!A6) | B8: =IF('جدول الكميات'!C6="","",'جدول الكميات'!C6) | C8: =IF('جدول الكميات'!D6="","",'جدول الكميات'!D6) | D8: ='جدول الكميات'!E6 | E8: ='جدول الكميات'!F6 | F8: 0 | H8: =F8+G8 | I8: 1 | K8: =IF(J8="",I8,J8) | L8: 0 | M8: =N8-L8 | N8: =ROUND(H8*E8*K8,2) | O8: =IF(D8*E8=0,0,N8/(D8*E8))
A9: =IF('جدول الكميات'!A7="","",'جدول الكميات'!A7) | B9: =IF('جدول الكميات'!C7="","",'جدول الكميات'!C7) | C9: =IF('جدول الكميات'!D7="","",'جدول الكميات'!D7) | D9: ='جدول الكميات'!E7 | E9: ='جدول الكميات'!F7 | F9: 0 | H9: =F9+G9 | I9: 1 | K9: =IF(J9="",I9,J9) | L9: 0 | M9: =N9-L9 | N9: =ROUND(H9*E9*K9,2) | O9: =IF(D9*E9=0,0,N9/(D9*E9))
A10: =IF('جدول الكميات'!A8="","",'جدول الكميات'!A8) | B10: =IF('جدول الكميات'!C8="","",'جدول الكميات'!C8) | C10: =IF('جدول الكميات'!D8="","",'جدول الكميات'!D8) | D10: ='جدول الكميات'!E8 | E10: ='جدول الكميات'!F8 | F10: 0 | H10: =F10+G10 | I10: 1 | K10: =IF(J10="",I10,J10) | L10: 0 | M10: =N10-L10 | N10: =ROUND(H10*E10*K10,2) | O10: =IF(D10*E10=0,0,N10/(D10*E10))
A11: =IF('جدول الكميات'!A9="","",'جدول الكميات'!A9) | B11: =IF('جدول الكميات'!C9="","",'جدول الكميات'!C9) | C11: =IF('جدول الكميات'!D9="","",'جدول الكميات'!D9) | D11: ='جدول الكميات'!E9 | E11: ='جدول الكميات'!F9 | F11: 0 | H11: =F11+G11 | I11: 1 | K11: =IF(J11="",I11,J11) | L11: 0 | M11: =N11-L11 | N11: =ROUND(H11*E11*K11,2) | O11: =IF(D11*E11=0,0,N11/(D11*E11))
A12: =IF('جدول الكميات'!A10="","",'جدول الكميات'!A10) | B12: =IF('جدول الكميات'!C10="","",'جدول الكميات'!C10) | C12: =IF('جدول الكميات'!D10="","",'جدول الكميات'!D10) | D12: ='جدول الكميات'!E10 | E12: ='جدول الكميات'!F10 | F12: 0 | H12: =F12+G12 | I12: 1 | K12: =IF(J12="",I12,J12) | L12: 0 | M12: =N12-L12 | N12: =ROUND(H12*E12*K12,2) | O12: =IF(D12*E12=0,0,N12/(D12*E12))
A13: =IF('جدول الكميات'!A11="","",'جدول الكميات'!A11) | B13: =IF('جدول الكميات'!C11="","",'جدول الكميات'!C11) | C13: =IF('جدول الكميات'!D11="","",'جدول الكميات'!D11) | D13: ='جدول الكميات'!E11 | E13: ='جدول الكميات'!F11 | F13: 0 | H13: =F13+G13 | I13: 1 | K13: =IF(J13="",I13,J13) | L13: 0 | M13: =N13-L13 | N13: =ROUND(H13*E13*K13,2) | O13: =IF(D13*E13=0,0,N13/(D13*E13))
A14: =IF('جدول الكميات'!A12="","",'جدول الكميات'!A12) | B14: =IF('جدول الكميات'!C12="","",'جدول الكميات'!C12) | C14: =IF('جدول الكميات'!D12="","",'جدول الكميات'!D12) | D14: ='جدول الكميات'!E12 | E14: ='جدول الكميات'!F12 | F14: 0 | H14: =F14+G14 | I14: 1 | K14: =IF(J14="",I14,J14) | L14: 0 | M14: =N14-L14 | N14: =ROUND(H14*E14*K14,2) | O14: =IF(D14*E14=0,0,N14/(D14*E14))
A15: =IF('جدول الكميات'!A13="","",'جدول الكميات'!A13) | B15: =IF('جدول الكميات'!C13="","",'جدول الكميات'!C13) | C15: =IF('جدول الكميات'!D13="","",'جدول الكميات'!D13) | D15: ='جدول الكميات'!E13 | E15: ='جدول الكميات'!F13 | F15: 0 | H15: =F15+G15 | I15: 1 | K15: =IF(J15="",I15,J15) | L15: 0 | M15: =N15-L15 | N15: =ROUND(H15*E15*K15,2) | O15: =IF(D15*E15=0,0,N15/(D15*E15))
A16: =IF('جدول الكميات'!A14="","",'جدول الكميات'!A14) | B16: =IF('جدول الكميات'!C14="","",'جدول الكميات'!C14) | C16: =IF('جدول الكميات'!D14="","",'جدول الكميات'!D14) | D16: ='جدول الكميات'!E14 | E16: ='جدول الكميات'!F14 | F16: 0 | H16: =F16+G16 | I16: 1 | K16: =IF(J16="",I16,J16) | L16: 0 | M16: =N16-L16 | N16: =ROUND(H16*E16*K16,2) | O16: =IF(D16*E16=0,0,N16/(D16*E16))
A17: =IF('جدول الكميات'!A15="","",'جدول الكميات'!A15) | B17: =IF('جدول الكميات'!C15="","",'جدول الكميات'!C15) | C17: =IF('جدول الكميات'!D15="","",'جدول الكميات'!D15) | D17: ='جدول الكميات'!E15 | E17: ='جدول الكميات'!F15 | F17: 0 | H17: =F17+G17 | I17: 1 | K17: =IF(J17="",I17,J17) | L17: 0 | M17: =N17-L17 | N17: =ROUND(H17*E17*K17,2) | O17: =IF(D17*E17=0,0,N17/(D17*E17))
A18: =IF('جدول الكميات'!A16="","",'جدول الكميات'!A16) | B18: =IF('جدول الكميات'!C16="","",'جدول الكميات'!C16) | C18: =IF('جدول الكميات'!D16="","",'جدول الكميات'!D16) | D18: ='جدول الكميات'!E16 | E18: ='جدول الكميات'!F16 | F18: 0 | H18: =F18+G18 | I18: 1 | K18: =IF(J18="",I18,J18) | L18: 0 | M18: =N18-L18 | N18: =ROUND(H18*E18*K18,2) | O18: =IF(D18*E18=0,0,N18/(D18*E18))
A19: =IF('جدول الكميات'!A17="","",'جدول الكميات'!A17) | B19: =IF('جدول الكميات'!C17="","",'جدول الكميات'!C17) | C19: =IF('جدول الكميات'!D17="","",'جدول الكميات'!D17) | D19: ='جدول الكميات'!E17 | E19: ='جدول الكميات'!F17 | F19: 0 | H19: =F19+G19 | I19: 1 | K19: =IF(J19="",I19,J19) | L19: 0 | M19: =N19-L19 | N19: =ROUND(H19*E19*K19,2) | O19: =IF(D19*E19=0,0,N19/(D19*E19))
... A107: =IF('جدول الكميات'!A105="","",'جدول الكميات'!A105) | B107: =IF('جدول الكميات'!C105="","",'جدول الكميات'!C105) | C107: =IF('جدول الكميات'!D105="","",'جدول الكميات'!D105) | D107: ='جدول الكميات'!E105 | E107: ='جدول الكميات'!F105 | F107: 0 | H107: =F107+G107 | I107: 1 | K107: =IF(J107="",I107,J107) | L107: 0 | M107: =N107-L107 | N107: =ROUND(H107*E107*K107,2) | O107: =IF(D107*E107=0,0,N107/(D107*E107))
A108: إجمالي قيمة الأعمال | L108: =SUM(L8:L107) | M108: =SUM(M8:M107) | N108: =SUM(N8:N107) | O108: =IF('الإعدادات'!$C$19=0,0,N108/'الإعدادات'!$C$19)
A110: ملاحظات المستخلص | I110: البيان | L110: المستخلص السابق | M110: المستخلص الحالي | N110: إجمالي الأعمال
I111: إجمالي قيمة الأعمال | L111: 0 | M111: =M108 | N111: =L111+M111
I112: ="ضريبة القيمة المضافة ("&TEXT('الإعدادات'!$C$18,"0%")&")" | L112: 0 | M112: =ROUND(M111*'الإعدادات'!$C$18,2) | N112: =L112+M112
I113: الإجمالي شامل الضريبة | L113: 0 | M113: =ROUND(M111+M112,2) | N113: =L113+M113
I114: (-) خصم استرداد الدفعة المقدمة | L114: 0 | M114: ='الدفعات المقدمة'!I25 | N114: =L114+M114
I115: ="(-) خصم ضمان الأعمال ("&TEXT('ضمان الأعمال'!$E$6,"0%")&")" | L115: 0 | M115: ='ضمان الأعمال'!I16 | N115: =L115+M115
I116: (-) خصومات أخرى / غرامات / مواد مورّدة من المالك ✎ | L116: 0 | N116: =L116+M116
I117: إجمالي الخصومات | L117: 0 | M117: =SUM(M114:M116) | N117: =L117+M117
I118: صافي قيمة المستخلص المستحق | L118: 0 | M118: =ROUND(M113-M117,2) | N118: =L118+M118
A121: ='الإعدادات'!B36 | C121: ='الإعدادات'!B37 | H121: ='الإعدادات'!B38 | M121: ='الإعدادات'!B39
A122: =IF('الإعدادات'!C36="","الاسم: ..................","الاسم: "&'الإعدادات'!C36) | C122: =IF('الإعدادات'!C37="","الاسم: ..................","الاسم: "&'الإعدادات'!C37) | H122: =IF('الإعدادات'!C38="","الاسم: ..................","الاسم: "&'الإعدادات'!C38) | M122: =IF('الإعدادات'!C39="","الاسم: ..................","الاسم: "&'الإعدادات'!C39)
A123: التوقيع: .............................. | C123: التوقيع: .............................. | H123: التوقيع: .............................. | M123: التوقيع: ..............................
A124: التاريخ: / / | C124: التاريخ: / / | H124: التاريخ: / / | M124: التاريخ: / /

Sheet مستخلص 2
A1: ="مستخلص أعمال رقم ( 2 ) — "&'الإعدادات'!$C$6
A2: ='الإعدادات'!$C$6&" | العقد رقم: "&'الإعدادات'!$C$7&" | المالك: "&'الإعدادات'!$C$8&" | المقاول: "&'الإعدادات'!$C$9
A3: 🏠 | B3: 🗂 سجل المستخلصات | C3: 📋 BOQ | F3: 💵 المقدمة | H3: 🔒 الضمان | L3: ◀ المستخلص السابق (1) | N3: المستخلص التالي (3) ▶
A4: رقم | B4: 2 | C4: تاريخ المستخلص | G4: الحالة | J4: الفترة من | M4: إلى
A5: المشروع | B5: ='الإعدادات'!$C$6 | C5: المالك | E5: ='الإعدادات'!$C$8 | J5: المقاول | L5: ='الإعدادات'!$C$9
A6: البند | B6: بيان الأعمال | C6: الوحدة | D6: الكمية التعاقدية | E6: سعر الوحدة | F6: الكمية المنفذة من واقع التمتير الفعلي | I6: نسبة الإنجاز / الاستحقاق للبند | L6: قيمة الأعمال المنفذة | O6: نسبة الإنجاز الفعلية | P6: ملاحظات
