Workbook

Sheet لوحة التحكم
B1: 📊 لوحة التحكم — متابعة مستخلصات المشروع
B2: 🎁 نسخة مجانية محدودة (3 مستخلصات • 10 بنود) — للنسخة الكاملة (25 مستخلص • 100 بند • بدون قيود) اضغط هنا ⬅ accopro.net
B3: ⚙ الإعدادات | D3: 📋 جدول الكميات | F3: 🗂 سجل المستخلصات | H3: 💵 الدفعات المقدمة | J3: 🔒 ضمان الأعمال | L3: 📄 مستخلص 1
P4: بيانات الرسم البياني (مساعدة)
B5: قيمة العقد (بدون ضريبة) | E5: الأعمال المنفذة تراكمياً | H5: نسبة الإنجاز المالي | K5: نسبة المدة المنقضية | P5: المستخلص | Q5: الأعمال الحالية | R5: الأعمال التراكمية | S5: المحصّل | U5: الحالة | V5: القيمة
B6: ='الإعدادات'!$C$19 -> 278913 | E6: ='سجل المستخلصات'!G9 -> 212382.5 | H6: =IF('الإعدادات'!$C$19=0,0,'سجل المستخلصات'!G9/'الإعدادات'!$C$19) -> 0.76146504 | K6: =IF(OR('الإعدادات'!C13="",'الإعدادات'!C14=""),0,MAX(0,MIN(1,(TODAY()-'الإعدادات'!C13)/'الإعدادات'!C14))) -> 0.58082192 | P6: ="م"&1 -> م1 | Q6: ='سجل المستخلصات'!G6 -> 95284 | R6: ='سجل المستخلصات'!H6 -> 95284 | S6: ='سجل المستخلصات'!P6 -> 90519.8 | U6: المحصّل | V6: ='سجل المستخلصات'!P9 -> 138684.55
B7: ="شاملة الضريبة: "&TEXT('الإعدادات'!C20,"#,##0") -> شاملة الضريبة: 320,750 | E7: ="المتبقي من العقد: "&TEXT('الإعدادات'!$C$19-'سجل المستخلصات'!G9,"#,##0") -> المتبقي من العقد: 66,530 | H7: قيمة المنفذ ÷ قيمة العقد | K7: =IF('الإعدادات'!C15="","","تاريخ الانتهاء: "&TEXT('الإعدادات'!C15,"yyyy/mm/dd")) -> تاريخ الانتهاء: 2027/03/01 | P7: ="م"&2 -> م2 | Q7: ='سجل المستخلصات'!G7 -> 86078.5 | R7: ='سجل المستخلصات'!H7 -> 181362.5 | S7: ='سجل المستخلصات'!P7 -> 48164.75 | U7: مستحق غير محصل | V7: =MAX(0,'سجل المستخلصات'!R9) -> 61578.83
P8: ="م"&3 -> م3 | Q8: ='سجل المستخلصات'!G8 -> 31020 | R8: ='سجل المستخلصات'!H8 -> 212382.5 | S8: ='سجل المستخلصات'!P8 -> 0 | U8: ضمان محتجز | V8: ='ضمان الأعمال'!E11 -> 21238.25
B9: صافي المستحق التراكمي | E9: إجمالي المحصّل | H9: المتبقي لدى المالك (غير محصل) | K9: آخر مستخلص صادر | U9: متبقي من العقد (لم ينفذ) | V9: =MAX(0,'الإعدادات'!C20-'سجل المستخلصات'!K9) -> 76510.07
B10: ='سجل المستخلصات'!O9 -> 200263.38 | E10: ='سجل المستخلصات'!P9 -> 138684.55 | H10: ='سجل المستخلصات'!R9 -> 61578.83 | K10: =SUMPRODUCT(MAX(('سجل المستخلصات'!C6:C8<>"")*'سجل المستخلصات'!B6:B8)) -> 3
B11: بعد الضريبة والخصومات | E11: =TEXT(IF('سجل المستخلصات'!O9=0,0,'سجل المستخلصات'!P9/'سجل المستخلصات'!O9),"0%")&" من المستحق" -> 69% من المستحق | H11: مستحقات متأخرة | K11: =IF($K$10=0,"","صافي: "&TEXT(INDEX('سجل المستخلصات'!O6:O8,$K$10),"#,##0")&" | "&TEXT(INDEX('سجل المستخلصات'!C6:C8,$K$10),"yyyy/mm/dd")) -> صافي: 29,469 | 2026/09/10
B13: الدفعات المقدمة المصروفة | E13: رصيد الدفعة المقدمة المتبقي | H13: ضمان الأعمال المحتجز | K13: تنبيهات الضمانات البنكية
B14: ='الدفعات المقدمة'!E8 -> 28000 | E14: ='الدفعات المقدمة'!E11 -> 6761.75 | H14: ='ضمان الأعمال'!E11 -> 21238.25 | K14: =COUNTIF('الدفعات المقدمة'!I15:I20,"<=30")+COUNTIF('ضمان الأعمال'!K33:K38,"<=30") -> 1
B15: ="المسترد: "&TEXT('الدفعات المقدمة'!E10,"#,##0") -> المسترد: 21,238 | E15: =TEXT('الدفعات المقدمة'!L28,"0%")&" تم استرداده" -> 76% تم استرداده | H15: ="المفرج عنه: "&TEXT('ضمان الأعمال'!E10,"#,##0") -> المفرج عنه: 0, | K15: ضمانات منتهية أو تنتهي خلال 30 يوماً
B17: الملخص المالي التراكمي | H17: حالة تنفيذ البنود
B18: إجمالي قيمة الأعمال المنفذة | E18: ='سجل المستخلصات'!G9 -> 212382.5 | G18: =IF($E$18=0,0,E18/$E$18) -> 1 | H18: إجمالي عدد البنود | J18: =SUMPRODUCT(('جدول الكميات'!C6:C15<>"")*1) -> 10
B19: ضريبة القيمة المضافة | E19: ='سجل المستخلصات'!J9 -> 31857.38 | G19: =IF($E$18=0,0,E19/$E$18) -> 0.15000002 | H19: ✔ بنود مكتملة 100% | J19: =COUNTIF('جدول الكميات'!M6:M15,"✔*") -> 4 | K19: =IF($J$18=0,0,J19/$J$18) -> 0.4
B20: الإجمالي شامل الضريبة | E20: ='سجل المستخلصات'!K9 -> 244239.88 | G20: =IF($E$18=0,0,E20/$E$18) -> 1.15 | H20: ⚠ مركبة بالكامل وبها نواقص | J20: =COUNTIF('جدول الكميات'!M6:M15,"⚠*") -> 0 | K20: =IF($J$18=0,0,J20/$J$18) -> 0
B21: (-) استرداد الدفعة المقدمة | E21: ='سجل المستخلصات'!L9 -> 21238.25 | G21: =IF($E$18=0,0,E21/$E$18) -> 0.1 | H21: ◔ بنود جارية | J21: =COUNTIF('جدول الكميات'!M6:M15,"◔*") -> 6 | K21: =IF($J$18=0,0,J21/$J$18) -> 0.6
B22: (-) ضمان الأعمال | E22: ='سجل المستخلصات'!M9 -> 21238.25 | G22: =IF($E$18=0,0,E22/$E$18) -> 0.1 | H22: ○ بنود لم تبدأ | J22: =COUNTIF('جدول الكميات'!M6:M15,"○*") -> 0 | K22: =IF($J$18=0,0,J22/$J$18) -> 0
B23: (-) خصومات أخرى | E23: ='سجل المستخلصات'!N9 -> 1500 | G23: =IF($E$18=0,0,E23/$E$18) -> 0.0070627288 | H23: ✖ بنود تجاوزت الكمية التعاقدية | J23: =SUMPRODUCT(('جدول الكميات'!E6:E15>0)*('جدول الكميات'!I6:I15>'جدول الكميات'!E6:E15)) -> 0 | K23: =IF($J$18=0,0,J23/$J$18) -> 0
B24: صافي المستحق للمقاول | E24: ='سجل المستخلصات'!O9 -> 200263.38 | G24: =IF($E$18=0,0,E24/$E$18) -> 0.94293729 | H24: متوسط نسبة الإنجاز الفعلية للبنود | J24: =IF(J18=0,0,SUMPRODUCT(('جدول الكميات'!C6:C15<>"")*('جدول الكميات'!L6:L15))/J18) -> 0.83796296
B25: المحصّل | E25: ='سجل المستخلصات'!P9 -> 138684.55 | G25: =IF($E$18=0,0,E25/$E$18) -> 0.65299424 | H25: الأداء (الإنجاز المالي مقابل المدة) | J25: =H6-K6 -> 0.18064313 | L25: =IF(K6=0,"-",IF(H6>=K6,"✔ متقدم / حسب الجدول",IF(K6-H6<=0.1,"⚠ تأخر بسيط","✖ متأخر"))) -> ✔ متقدم / حسب الجدول
B26: المتبقي غير المحصل | E26: ='سجل المستخلصات'!R9 -> 61578.83 | G26: =IF($E$18=0,0,E26/$E$18) -> 0.28994305
B28: التقدم حسب أقسام الأعمال
B29: القسم | E29: قيمة العقد | G29: الوزن النسبي | H29: القيمة المنفذة | J29: المتبقي | L29: نسبة الإنجاز
B30: =IF('الإعدادات'!C22="","",'الإعدادات'!C22) -> أعمال الهيكل والترميم | E30: =IF(B30="",0,SUMIF('جدول الكميات'!B6:B15,B30,'جدول الكميات'!G6:G15)) -> 0 | G30: =IF('الإعدادات'!$C$19=0,0,E30/'الإعدادات'!$C$19) -> 0 | H30: =IF(B30="",0,SUMIF('جدول الكميات'!B6:B15,B30,'جدول الكميات'!K6:K15)) -> 0 | J30: =E30-H30 -> 0 | L30: =IF(E30=0,0,H30/E30) -> 0
B31: =IF('الإعدادات'!C23="","",'الإعدادات'!C23) -> الواجهات والزجاج | E31: =IF(B31="",0,SUMIF('جدول الكميات'!B6:B15,B31,'جدول الكميات'!G6:G15)) -> 51991 | G31: =IF('الإعدادات'!$C$19=0,0,E31/'الإعدادات'!$C$19) -> 0.1864058 | H31: =IF(B31="",0,SUMIF('جدول الكميات'!B6:B15,B31,'جدول الكميات'!K6:K15)) -> 50825.5 | J31: =E31-H31 -> 1165.5 | L31: =IF(E31=0,0,H31/E31) -> 0.97758266
B32: =IF('الإعدادات'!C24="","",'الإعدادات'!C24) -> الأعمال المعدنية | E32: =IF(B32="",0,SUMIF('جدول الكميات'!B6:B15,B32,'جدول الكميات'!G6:G15)) -> 122622 | G32: =IF('الإعدادات'!$C$19=0,0,E32/'الإعدادات'!$C$19) -> 0.43964247 | H32: =IF(B32="",0,SUMIF('جدول الكميات'!B6:B15,B32,'جدول الكميات'!K6:K15)) -> 122622 | J32: =E32-H32 -> 0 | L32: =IF(E32=0,0,H32/E32) -> 1
B33: =IF('الإعدادات'!C25="","",'الإعدادات'!C25) -> التشطيبات الداخلية | E33: =IF(B33="",0,SUMIF('جدول الكميات'!B6:B15,B33,'جدول الكميات'!G6:G15)) -> 0 | G33: =IF('الإعدادات'!$C$19=0,0,E33/'الإعدادات'!$C$19) -> 0 | H33: =IF(B33="",0,SUMIF('جدول الكميات'!B6:B15,B33,'جدول الكميات'!K6:K15)) -> 0 | J33: =E33-H33 -> 0 | L33: =IF(E33=0,0,H33/E33) -> 0
B34: =IF('الإعدادات'!C26="","",'الإعدادات'!C26) -> دورات المياه | E34: =IF(B34="",0,SUMIF('جدول الكميات'!B6:B15,B34,'جدول الكميات'!G6:G15)) -> 104300 | G34: =IF('الإعدادات'!$C$19=0,0,E34/'الإعدادات'!$C$19) -> 0.37395173 | H34: =IF(B34="",0,SUMIF('جدول الكميات'!B6:B15,B34,'جدول الكميات'!K6:K15)) -> 38935 | J34: =E34-H34 -> 65365 | L34: =IF(E34=0,0,H34/E34) -> 0.37329818
B35: =IF('الإعدادات'!C27="","",'الإعدادات'!C27) -> الأعمال الكهربائية | E35: =IF(B35="",0,SUMIF('جدول الكميات'!B6:B15,B35,'جدول الكميات'!G6:G15)) -> 0 | G35: =IF('الإعدادات'!$C$19=0,0,E35/'الإعدادات'!$C$19) -> 0 | H35: =IF(B35="",0,SUMIF('جدول الكميات'!B6:B15,B35,'جدول الكميات'!K6:K15)) -> 0 | J35: =E35-H35 -> 0 | L35: =IF(E35=0,0,H35/E35) -> 0
B36: =IF('الإعدادات'!C28="","",'الإعدادات'!C28) -> الأعمال الصحية والتكييف | E36: =IF(B36="",0,SUMIF('جدول الكميات'!B6:B15,B36,'جدول الكميات'!G6:G15)) -> 0 | G36: =IF('الإعدادات'!$C$19=0,0,E36/'الإعدادات'!$C$19) -> 0 | H36: =IF(B36="",0,SUMIF('جدول الكميات'!B6:B15,B36,'جدول الكميات'!K6:K15)) -> 0 | J36: =E36-H36 -> 0 | L36: =IF(E36=0,0,H36/E36) -> 0
B37: =IF('الإعدادات'!C29="","",'الإعدادات'!C29) -> أعمال عامة وخارجية | E37: =IF(B37="",0,SUMIF('جدول الكميات'!B6:B15,B37,'جدول الكميات'!G6:G15)) -> 0 | G37: =IF('الإعدادات'!$C$19=0,0,E37/'الإعدادات'!$C$19) -> 0 | H37: =IF(B37="",0,SUMIF('جدول الكميات'!B6:B15,B37,'جدول الكميات'!K6:K15)) -> 0 | J37: =E37-H37 -> 0 | L37: =IF(E37=0,0,H37/E37) -> 0
B38: =IF('الإعدادات'!C30="","",'الإعدادات'!C30) | E38: =IF(B38="",0,SUMIF('جدول الكميات'!B6:B15,B38,'جدول الكميات'!G6:G15)) -> 0 | G38: =IF('الإعدادات'!$C$19=0,0,E38/'الإعدادات'!$C$19) -> 0 | H38: =IF(B38="",0,SUMIF('جدول الكميات'!B6:B15,B38,'جدول الكميات'!K6:K15)) -> 0 | J38: =E38-H38 -> 0 | L38: =IF(E38=0,0,H38/E38) -> 0
B39: =IF('الإعدادات'!C31="","",'الإعدادات'!C31) | E39: =IF(B39="",0,SUMIF('جدول الكميات'!B6:B15,B39,'جدول الكميات'!G6:G15)) -> 0 | G39: =IF('الإعدادات'!$C$19=0,0,E39/'الإعدادات'!$C$19) -> 0 | H39: =IF(B39="",0,SUMIF('جدول الكميات'!B6:B15,B39,'جدول الكميات'!K6:K15)) -> 0 | J39: =E39-H39 -> 0 | L39: =IF(E39=0,0,H39/E39) -> 0
B40: =IF('الإعدادات'!C32="","",'الإعدادات'!C32) | E40: =IF(B40="",0,SUMIF('جدول الكميات'!B6:B15,B40,'جدول الكميات'!G6:G15)) -> 0 | G40: =IF('الإعدادات'!$C$19=0,0,E40/'الإعدادات'!$C$19) -> 0 | H40: =IF(B40="",0,SUMIF('جدول الكميات'!B6:B15,B40,'جدول الكميات'!K6:K15)) -> 0 | J40: =E40-H40 -> 0 | L40: =IF(E40=0,0,H40/E40) -> 0
B41: =IF('الإعدادات'!C33="","",'الإعدادات'!C33) | E41: =IF(B41="",0,SUMIF('جدول الكميات'!B6:B15,B41,'جدول الكميات'!G6:G15)) -> 0 | G41: =IF('الإعدادات'!$C$19=0,0,E41/'الإعدادات'!$C$19) -> 0 | H41: =IF(B41="",0,SUMIF('جدول الكميات'!B6:B15,B41,'جدول الكميات'!K6:K15)) -> 0 | J41: =E41-H41 -> 0 | L41: =IF(E41=0,0,H41/E41) -> 0
B42: الإجمالي | E42: =SUM(E30:E41) -> 278913 | G42: =SUM(G30:G41) -> 1 | H42: =SUM(H30:H41) -> 212382.5 | J42: =SUM(J30:J41) -> 66530.5 | L42: =IF(E42=0,0,H42/E42) -> 0.76146504
B43: =IF(ABS(E42-'الإعدادات'!$C$19)>0.01,"⚠ يوجد بنود بدون قسم أو بقسم غير موجود في الإعدادات بقيمة: "&TEXT('الإعدادات'!$C$19-E42,"#,##0"),"✔ جميع البنود مصنفة على الأقسام") -> ✔ جميع البنود مصنفة على الأقسام
...

Sheet ⭐ النسخة الكاملة
B1: ⭐ احصل على النسخة الكاملة من قالب مستخلصات المقاولات
B3: 🛒 اضغط هنا للشراء: accopro.net
B6: الخاصية | C6: النسخة المجانية | D6: النسخة الكاملة ⭐
B7: عدد المستخلصات المربوطة | C7: 3 مستخلصات | D7: 25 مستخلص
B8: عدد بنود جدول الكميات | C8: 10 بنود | D8: 100 بند
B9: ترحيل الكميات تلقائياً بين المستخلصات | C9: ✔ | D9: ✔
B10: الضريبة واسترداد الدفعة المقدمة وضمان الأعمال | C10: ✔ | D10: ✔
B11: نسبة الإنجاز/الاستحقاق للبند (نواقص مثل الإكسسوارات) | C11: 🔒 | D11: ✔
B12: نسب استرداد وضمان مخصصة لكل مستخلص | C12: 🔒 | D12: ✔
B13: بدء الاسترداد من مستخلص محدد وحد أقصى للضمان | C13: 🔒 | D13: ✔
B14: تعدد الدفعات المقدمة وخطابات ضمانها | C14: دفعة واحدة | D14: ✔ حتى 6
B15: سجل الإفراج عن ضمان الأعمال | C15: 🔒 | D15: ✔
B16: متابعة الضمانات البنكية وتنبيهات الانتهاء | C16: ضمان واحد | D16: ✔ حتى 6
B17: الرسوم البيانية في لوحة التحكم | C17: 🔒 | D17: ✔
... B19: بدون علامة النسخة المجانية في الطباعة | C19: 🔒 | D19: ✔
B21: ⬅ للترقية للنسخة الكاملة زُر الموقع: https://accopro.net/

Sheet التعليمات
B1: 📘 طريقة استخدام القالب
B2: 🎁 نسخة مجانية محدودة (3 مستخلصات • 10 بنود) — للنسخة الكاملة (25 مستخلص • 100 بند • بدون قيود) اضغط هنا ⬅ accopro.net
B3: 🏠
B6: فكرة القالب
C7: قالب متكامل لإعداد مستخلصات المقاولات حتى 3 مستخلص و10 بند، جميع الصفحات مربوطة ببعضها؛ الكميات السابقة تنتقل تلقائياً من كل مستخلص إلى الذي يليه، وتتجمع النتائج في السجل ولوحة التحكم.
B9: خطوات العمل
B10: 1 | C10: صفحة (الإعدادات): أدخل بيانات المشروع والعقد ونسبة الضريبة وأسماء أقسام الأعمال وأسماء المعتمدين.
B11: 2 | C11: صفحة (جدول الكميات): أدخل البنود: رقم البند، القسم، الوصف، الوحدة، الكمية، سعر الوحدة (حتى 10 بند).
B12: 3 | C12: صفحة (الدفعات المقدمة): سجل الدفعات المقدمة وخطابات ضمانها ونسبة الاسترداد من كل مستخلص.
B13: 4 | C13: صفحة (ضمان الأعمال): حدد نسبة الضمان والحد الأقصى، وسجل الإفراجات والضمانات البنكية.
B14: 5 | C14: في كل مستخلص: أدخل التاريخ والحالة والفترة، ثم الكمية الحالية فقط لكل بند (العمود الأصفر 'حالي').
B15: 6 | C15: نسبة الإنجاز/الاستحقاق للبند (اختياري): مثال 1000 شباك مركبة بالكامل لكن تنقصها الإكسسوارات ← اكتب الكمية 1000 في عمود (حالي) واكتب 70% في عمود (حالية ✎)؛ تُحتسب القيمة 70% فقط، وتظهر نسبة الإنجاز الفعلية 70%، ويظهر البند في لوحة التحكم ضمن (مركبة بالكامل وبها نواقص).
B16: 7 | C16: عند استكمال النواقص: في المستخلص الجديد اكتب 100% في عمود (حالية ✎) بدون كمية؛ فيُصرف الفرق (30%) تلقائياً في هذا المستخلص ويتحول البند إلى (مكتمل). النسبة تنتقل للمستخلصات التالية حتى تغيّرها.
B17: 8 | C17: الخصومات الأخرى / الغرامات تُكتب يدوياً أسفل كل مستخلص في الخانة الصفراء.
B18: 9 | C18: صفحة (سجل المستخلصات): أدخل المبالغ المحصلة وتواريخها لمتابعة المستحقات.
B19: 10 | C19: صفحة (لوحة التحكم): تتحدث تلقائياً بالكامل ولا تحتاج أي إدخال.
B21: المعادلات الأساسية
B22: • | C22: قيمة البند الإجمالية = الكمية الإجمالية × سعر الوحدة × نسبة الإنجاز/الاستحقاق المعتمدة.
B23: • | C23: نسبة الإنجاز الفعلية = القيمة المستحقة ÷ (الكمية التعاقدية × سعر الوحدة)؛ بينما نسبة الكمية = المنفذ ÷ التعاقدي.
B24: • | C24: القيمة الحالية = القيمة الإجمالية − القيمة السابقة (من المستخلص السابق).
B25: • | C25: استرداد الدفعة المقدمة = قيمة الأعمال الحالية × نسبة الاسترداد، بحد أقصى الرصيد المتبقي من الدفعة.
B26: • | C26: ضمان الأعمال = قيمة الأعمال الحالية × نسبة الضمان، بحد أقصى (اختياري) نسبة من قيمة العقد.
B27: • | C27: صافي المستخلص = (قيمة الأعمال + الضريبة) − (استرداد الدفعة + ضمان الأعمال + الخصومات الأخرى).
B29: التخصيص بحرية دون التأثير على لوحة التحكم
B30: • | C30: يمكن تعديل أي نص أو اسم قسم أو بند أو وحدة أو سعر أو نسبة؛ لوحة التحكم تعتمد على الإجماليات فقط.
B31: • | C31: أضف البنود الجديدة (أعمال إضافية / أوامر تغيير) في الصفوف الفارغة بنهاية جدول الكميات — لا تُدرج صفوفاً بين البنود ولا تحذف صفوفاً، حتى تبقى المستخلصات مرتبطة بنفس البنود.
B32: • | C32: لإخفاء الصفوف الفارغة عند الطباعة: استخدم التصفية في جدول الكميات أو أخفِ الصفوف الفارغة في المستخلص.
B33: • | C33: يمكن تغيير الألوان والخطوط والشعار وعناوين الأعمدة بحرية. لا تغيّر ترتيب الأعمدة أو أسماء الصفحات.
B34: • | C34: المستخلص رقم 3 يحمل دائماً الكميات التراكمية لآخر وضع (لأن المستخلصات غير الصادرة كمياتها الحالية صفر).
B36: دليل الألوان والتنبيهات
B37: • | C37: الخلايا الصفراء بخط أزرق = إدخال. البيضاء/الرمادية = معادلات. الأرقام الخضراء = مسحوبة من صفحة أخرى.
B38: • | C38: خلفية حمراء على الكمية الإجمالية = البند تجاوز الكمية التعاقدية.
B39: • | C39: المستخلص يعتبر 'صادراً' بمجرد إدخال تاريخه؛ وغير الصادر يظهر رمادياً في السجل.
B41: ملاحظة
B42: • | C42: هذه نسخة مجانية محدودة (3 مستخلصات و10 بنود) ببيانات مثال للتجربة؛ امسح الخلايا الصفراء وابدأ ببياناتك. الخصائص المقفلة 🔒 والنسخة الكاملة (25 مستخلص و100 بند) من: https://accopro.net/

Sheet الإعدادات
B1: ⚙ الإعدادات العامة للمشروع
B2: 🎁 نسخة مجانية محدودة (3 مستخلصات • 10 بنود) — للنسخة الكاملة (25 مستخلص • 100 بند • بدون قيود) اضغط هنا ⬅ accopro.net
B3: 🏠 لوحة التحكم | C3: 📋 جدول الكميات | D3: 🗂 سجل المستخلصات | E3: 💵 الدفعات المقدمة | G3: 🔒 ضمان الأعمال
B5: بيانات المشروع والعقد | G5: دليل الألوان
B6: اسم المشروع | C6: مشروع تأهيل أبراج طيبة - المنطقة المركزية شارع الهجرة | G6: خلية إدخال — اكتب هنا
B7: رقم العقد | C7: CT-2025-014 | G7: خلية محسوبة بمعادلة — لا تعدلها
B8: المالك / العميل | C8: شركة ثروات الرائدة العقارية | G8: عنوان / رأس جدول
B9: المقاول | C9: مؤسسة البناء المتقن للمقاولات
B10: الاستشاري / الجهة المشرفة | C10: مكتب الهندسة الاستشارية | G10: • غيّر أسماء الأقسام بحرية؛ ستتحدث القوائم ولوحة التحكم تلقائياً.
B11: موقع المشروع | C11: المدينة المنورة - المنطقة المركزية | G11: • نسبة الضريبة تطبق على جميع المستخلصات.
B12: تاريخ توقيع العقد | C12: 46068 | G12: • نسب الدفعة المقدمة والضمان تُضبط من صفحاتها الخاصة.
B13: تاريخ بدء التنفيذ (استلام الموقع) | C13: 46082
B14: مدة العقد (يوم) | C14: 365
B15: تاريخ الانتهاء المخطط | C15: =IF(OR(C13="",C14=""),"",C13+C14) -> 46447
B16: العملة | C16: ريال سعودي
B17: النسب والقيم المالية العامة
B18: نسبة ضريبة القيمة المضافة | C18: 0.15
B19: قيمة العقد (محسوبة من جدول الكميات) | C19: ='جدول الكميات'!G16 -> 278913
B20: قيمة العقد شاملة الضريبة | C20: =C19*(1+C18) -> 320749.95
B21: أقسام الأعمال (تظهر في جدول الكميات ولوحة التحكم)
B22: القسم 1 | C22: أعمال الهيكل والترميم
B23: القسم 2 | C23: الواجهات والزجاج
B24: القسم 3 | C24: الأعمال المعدنية
B25: القسم 4 | C25: التشطيبات الداخلية
B26: القسم 5 | C26: دورات المياه
B27: القسم 6 | C27: الأعمال الكهربائية
B28: القسم 7 | C28: الأعمال الصحية والتكييف
B29: القسم 8 | C29: أعمال عامة وخارجية
B30: القسم 9
B31: القسم 10
B32: القسم 11
B33: القسم 12
B35: أسماء المعتمدين (تظهر أسفل كل مستخلص)
B36: مهندس الموقع (المقاول) | C36: م. أحمد محمد
B37: مدير المشروع (المقاول) | C37: م. خالد عبدالله
B38: المهندس المشرف (الاستشاري) | C38: م. سامي علي
B39: ممثل المالك | C39: أ. فهد سعد

Sheet جدول الكميات
A1: 📋 جدول الكميات والأسعار (BOQ) — ومتابعة تنفيذ البنود
A2: 🎁 نسخة مجانية محدودة (3 مستخلصات • 10 بنود) — للنسخة الكاملة (25 مستخلص • 100 بند • بدون قيود) اضغط هنا ⬅ accopro.net
A3: 🏠 لوحة التحكم | C3: ⚙ الإعدادات | D3: 🗂 سجل المستخلصات | F3: 💵 الدفعات المقدمة | H3: 🔒 ضمان الأعمال | J3: 📄 مستخلص 1
A4: أضف البنود في الصفوف الفارغة (حتى 10 بند). الأعمدة الصفراء إدخال، والأعمدة من I إلى M تُحسب تلقائياً من المستخلصات. (نسبة الكمية) = ما تم تركيبه، و(نسبة الإنجاز الفعلية) = القيمة المستحقة ÷ قيمة البند، فتظهر النواقص (مثل الإكسسوارات) حتى لو اكتملت الكمية. لا تحذف صفوفاً ولا تُدرج صفوفاً بين البنود.
A5: رقم البند | B5: القسم | C5: بيان الأعمال | D5: الوحدة | E5: الكمية التعاقدية | F5: سعر الوحدة | G5: الإجمالي | H5: الوزن النسبي | I5: الكمية المنفذة حتى تاريخه | J5: نسبة الكمية المنفذة | K5: القيمة المستحقة حتى تاريخه | L5: نسبة الإنجاز الفعلية | M5: حالة البند | N5: ملاحظات / النواقص
A6: 1 | B6: الواجهات والزجاج | C6: توريد وتركيب هندريل زجاج مع كبسة أستيل لدور الميزانين | D6: م.ط | E6: 7.54 | F6: 650 | G6: =ROUND(E6*F6,2) -> 4901 | H6: =IF($G$16=0,0,G6/$G$16) -> 0.017571788 | I6: ='مستخلص 3'!H8 -> 7.54 | J6: =IF(E6=0,0,I6/E6) -> 1 | K6: ='مستخلص 3'!N8 -> 4901 | L6: =IF(G6=0,0,K6/G6) -> 1 | M6: =IF(C6="","",IF(I6=0,"○ لم يبدأ",IF(AND(G6>0,K6>=G6),"✔ مكتمل",IF(AND(E6>0,I6>=E6),"⚠ مركب بالكامل - نواقص","◔ جاري")))) -> ✔ مكتمل
A7: 2 | B7: دورات المياه | C7: توريد وتركيب مرايات لحمامات الدور الأرضي | D7: عدد | E7: 5 | F7: 800 | G7: =ROUND(E7*F7,2) -> 4000 | H7: =IF($G$16=0,0,G7/$G$16) -> 0.01434139 | I7: ='مستخلص 3'!H9 -> 4.25 | J7: =IF(E7=0,0,I7/E7) -> 0.85 | K7: ='مستخلص 3'!N9 -> 3400 | L7: =IF(G7=0,0,K7/G7) -> 0.85 | M7: =IF(C7="","",IF(I7=0,"○ لم يبدأ",IF(AND(G7>0,K7>=G7),"✔ مكتمل",IF(AND(E7>0,I7>=E7),"⚠ مركب بالكامل - نواقص","◔ جاري")))) -> ◔ جاري
A8: 3 | B8: الواجهات والزجاج | C8: تركيب زجاج هندريل لدور الميزانين | D8: م.ط | E8: 9.4 | F8: 150 | G8: =ROUND(E8*F8,2) -> 1410 | H8: =IF($G$16=0,0,G8/$G$16) -> 0.0050553398 | I8: ='مستخلص 3'!H10 -> 7.99 | J8: =IF(E8=0,0,I8/E8) -> 0.85 | K8: ='مستخلص 3'!N10 -> 1198.5 | L8: =IF(G8=0,0,K8/G8) -> 0.85 | M8: =IF(C8="","",IF(I8=0,"○ لم يبدأ",IF(AND(G8>0,K8>=G8),"✔ مكتمل",IF(AND(E8>0,I8>=E8),"⚠ مركب بالكامل - نواقص","◔ جاري")))) -> ◔ جاري
A9: 4 | B9: الواجهات والزجاج | C9: فك وإعادة تركيب زجاج هندريل دور الميزانين | D9: م.ط | E9: 5.4 | F9: 300 | G9: =ROUND(E9*F9,2) -> 1620 | H9: =IF($G$16=0,0,G9/$G$16) -> 0.0058082628 | I9: ='مستخلص 3'!H11 -> 3.67 | J9: =IF(E9=0,0,I9/E9) -> 0.67962963 | K9: ='مستخلص 3'!N11 -> 1101 | L9: =IF(G9=0,0,K9/G9) -> 0.67962963 | M9: =IF(C9="","",IF(I9=0,"○ لم يبدأ",IF(AND(G9>0,K9>=G9),"✔ مكتمل",IF(AND(E9>0,I9>=E9),"⚠ مركب بالكامل - نواقص","◔ جاري")))) -> ◔ جاري
A10: 5 | B10: الأعمال المعدنية | C10: فك وتلحيم مواسير أستيل (كبسة) فوق الزجاج وإعادة تركيبه لدور الميزانين | D10: م.ط | E10: 31.48 | F10: 150 | G10: =ROUND(E10*F10,2) -> 4722 | H10: =IF($G$16=0,0,G10/$G$16) -> 0.01693001 | I10: ='مستخلص 3'!H12 -> 31.48 | J10: =IF(E10=0,0,I10/E10) -> 1 | K10: ='مستخلص 3'!N12 -> 4722 | L10: =IF(G10=0,0,K10/G10) -> 1 | M10: =IF(C10="","",IF(I10=0,"○ لم يبدأ",IF(AND(G10>0,K10>=G10),"✔ مكتمل",IF(AND(E10>0,I10>=E10),"⚠ مركب بالكامل - نواقص","◔ جاري")))) -> ✔ مكتمل
A11: 6 | B11: دورات المياه | C11: فك وإعادة تركيب أبواب الشوارات للحمامات (ثابت ومتحرك) | D11: عدد | E11: 33 | F11: 300 | G11: =ROUND(E11*F11,2) -> 9900 | H11: =IF($G$16=0,0,G11/$G$16) -> 0.035494939 | I11: ='مستخلص 3'!H13 -> 28.05 | J11: =IF(E11=0,0,I11/E11) -> 0.85 | K11: ='مستخلص 3'!N13 -> 8415 | L11: =IF(G11=0,0,K11/G11) -> 0.85 | M11: =IF(C11="","",IF(I11=0,"○ لم يبدأ",IF(AND(G11>0,K11>=G11),"✔ مكتمل",IF(AND(E11>0,I11>=E11),"⚠ مركب بالكامل - نواقص","◔ جاري")))) -> ◔ جاري
A12: 7 | B12: الواجهات والزجاج | C12: تركيب شبابيك للواجهات الخلفية والجانبية بين الأبراج | D12: عدد | E12: 343 | F12: 120 | G12: =ROUND(E12*F12,2) -> 41160 | H12: =IF($G$16=0,0,G12/$G$16) -> 0.1475729 | I12: ='مستخلص 3'!H14 -> 343 | J12: =IF(E12=0,0,I12/E12) -> 1 | K12: ='مستخلص 3'!N14 -> 41160 | L12: =IF(G12=0,0,K12/G12) -> 1 | M12: =IF(C12="","",IF(I12=0,"○ لم يبدأ",IF(AND(G12>0,K12>=G12),"✔ مكتمل",IF(AND(E12>0,I12>=E12),"⚠ مركب بالكامل - نواقص","◔ جاري")))) -> ✔ مكتمل | N12: مركبة بالكامل - تنقصها الإكسسوارات (مقابض ومحابس)
A13: 8 | B13: الواجهات والزجاج | C13: فك شبابيك الواجهات الخلفية مرة أخرى من أجل أعمال التلابيس | D13: عدد | E13: 58 | F13: 50 | G13: =ROUND(E13*F13,2) -> 2900 | H13: =IF($G$16=0,0,G13/$G$16) -> 0.010397507 | I13: ='مستخلص 3'!H15 -> 49.3 | J13: =IF(E13=0,0,I13/E13) -> 0.85 | K13: ='مستخلص 3'!N15 -> 2465 | L13: =IF(G13=0,0,K13/G13) -> 0.85 | M13: =IF(C13="","",IF(I13=0,"○ لم يبدأ",IF(AND(G13>0,K13>=G13),"✔ مكتمل",IF(AND(E13>0,I13>=E13),"⚠ مركب بالكامل - نواقص","◔ جاري")))) -> ◔ جاري
A14: 9 | B14: الأعمال المعدنية | C14: توريد وتركيب درابزين حديد لسلالم الطوارئ | D14: م.ط | E14: 262 | F14: 450 | G14: =ROUND(E14*F14,2) -> 117900 | H14: =IF($G$16=0,0,G14/$G$16) -> 0.42271246 | I14: ='مستخلص 3'!H16 -> 262 | J14: =IF(E14=0,0,I14/E14) -> 1 | K14: ='مستخلص 3'!N16 -> 117900 | L14: =IF(G14=0,0,K14/G14) -> 1 | M14: =IF(C14="","",IF(I14=0,"○ لم يبدأ",IF(AND(G14>0,K14>=G14),"✔ مكتمل",IF(AND(E14>0,I14>=E14),"⚠ مركب بالكامل - نواقص","◔ جاري")))) -> ✔ مكتمل
A15: 10 | B15: دورات المياه | C15: توريد وتركيب بارتشن ثابت (قواطع داخلية للحمامات) | D15: عدد | E15: 226 | F15: 400 | G15: =ROUND(E15*F15,2) -> 90400 | H15: =IF($G$16=0,0,G15/$G$16) -> 0.32411541 | I15: ='مستخلص 3'!H17 -> 67.8 | J15: =IF(E15=0,0,I15/E15) -> 0.3 | K15: ='مستخلص 3'!N17 -> 27120 | L15: =IF(G15=0,0,K15/G15) -> 0.3 | M15: =IF(C15="","",IF(I15=0,"○ لم يبدأ",IF(AND(G15>0,K15>=G15),"✔ مكتمل",IF(AND(E15>0,I15>=E15),"⚠ مركب بالكامل - نواقص","◔ جاري")))) -> ◔ جاري
A16: الإجمالي | G16: =SUM(G6:G15) -> 278913 | H16: =SUM(H6:H15) -> 1 | K16: =SUM(K6:K15) -> 212382.5 | L16: =IF(G16=0,0,K16/G16) -> 0.76146504

Sheet سجل المستخلصات
B1: 🗂 سجل المستخلصات والتحصيل
B2: 🎁 نسخة مجانية محدودة (3 مستخلصات • 10 بنود) — للنسخة الكاملة (25 مستخلص • 100 بند • بدون قيود) اضغط هنا ⬅ accopro.net
B3: 🏠 لوحة التحكم | D3: ⚙ الإعدادات | F3: 📋 جدول الكميات | H3: 💵 الدفعات المقدمة | J3: 🔒 ضمان الأعمال | L3: 📄 مستخلص 1
B4: هذه الصفحة تتجمع تلقائياً من المستخلصات. أدخل فقط المبالغ المحصلة وتواريخ التحصيل (الأعمدة الصفراء). اضغط على رقم المستخلص للانتقال إليه.
B5: رقم المستخلص | C5: تاريخ المستخلص | D5: الحالة | E5: الفترة من | F5: الفترة إلى | G5: قيمة الأعمال الحالية | H5: قيمة الأعمال التراكمية | I5: نسبة الإنجاز التراكمية | J5: ضريبة القيمة المضافة | K5: الإجمالي شامل الضريبة | L5: استرداد الدفعة المقدمة | M5: ضمان الأعمال | N5: خصومات أخرى | O5: صافي المستحق | P5: المبلغ المحصّل ✎ | Q5: تاريخ التحصيل ✎ | R5: المتبقي غير المحصل | S5: حالة التحصيل
B6: 1 | C6: =IF('مستخلص 1'!E4="","",'مستخلص 1'!E4) -> 46173 | D6: =IF(C6="","لم يصدر",IF('مستخلص 1'!H4="","جاري",'مستخلص 1'!H4)) -> جاري | E6: =IF('مستخلص 1'!L4="","",'مستخلص 1'!L4) -> 46082 | F6: =IF('مستخلص 1'!N4="","",'مستخلص 1'!N4) -> 46173 | G6: ='مستخلص 1'!M21 -> 95284 | H6: ='مستخلص 1'!N21 -> 95284 | I6: =IF('الإعدادات'!$C$19=0,0,H6/'الإعدادات'!$C$19) -> 0.34162624 | J6: ='مستخلص 1'!M22 -> 14292.6 | K6: ='مستخلص 1'!M23 -> 109576.6 | L6: ='مستخلص 1'!M24 -> 9528.4 | M6: ='مستخلص 1'!M25 -> 9528.4 | N6: ='مستخلص 1'!M26 -> 0 | O6: ='مستخلص 1'!M28 -> 90519.8 | P6: =ROUND(O6*1.0,2) -> 90519.8 | Q6: 46193 | R6: =ROUND(O6-P6,2) -> 0 | S6: =IF(C6="","",IF(O6<=0,"-",IF(P6>=O6,"✔ محصل بالكامل",IF(P6>0,"⚠ محصل جزئياً","✖ غير محصل")))) -> ✔ محصل بالكامل
B7: 2 | C7: =IF('مستخلص 2'!E4="","",'مستخلص 2'!E4) -> 46218 | D7: =IF(C7="","لم يصدر",IF('مستخلص 2'!H4="","جاري",'مستخلص 2'!H4)) -> جاري | E7: =IF('مستخلص 2'!L4="","",'مستخلص 2'!L4) -> 46174 | F7: =IF('مستخلص 2'!N4="","",'مستخلص 2'!N4) -> 46218 | G7: ='مستخلص 2'!M21 -> 86078.5 | H7: ='مستخلص 2'!N21 -> 181362.5 | I7: =IF('الإعدادات'!$C$19=0,0,H7/'الإعدادات'!$C$19) -> 0.65024757 | J7: ='مستخلص 2'!M22 -> 12911.78 | K7: ='مستخلص 2'!M23 -> 98990.28 | L7: ='مستخلص 2'!M24 -> 8607.85 | M7: ='مستخلص 2'!M25 -> 8607.85 | N7: ='مستخلص 2'!M26 -> 1500 | O7: ='مستخلص 2'!M28 -> 80274.58 | P7: =ROUND(O7*0.6,2) -> 48164.75 | Q7: 46238 | R7: =ROUND(O7-P7,2) -> 32109.83 | S7: =IF(C7="","",IF(O7<=0,"-",IF(P7>=O7,"✔ محصل بالكامل",IF(P7>0,"⚠ محصل جزئياً","✖ غير محصل")))) -> ⚠ محصل جزئياً
B8: 3 | C8: =IF('مستخلص 3'!E4="","",'مستخلص 3'!E4) -> 46275 | D8: =IF(C8="","لم يصدر",IF('مستخلص 3'!H4="","جاري",'مستخلص 3'!H4)) -> جاري | E8: =IF('مستخلص 3'!L4="","",'مستخلص 3'!L4) -> 46219 | F8: =IF('مستخلص 3'!N4="","",'مستخلص 3'!N4) -> 46275 | G8: ='مستخلص 3'!M21 -> 31020 | H8: ='مستخلص 3'!N21 -> 212382.5 | I8: =IF('الإعدادات'!$C$19=0,0,H8/'الإعدادات'!$C$19) -> 0.76146504 | J8: ='مستخلص 3'!M22 -> 4653 | K8: ='مستخلص 3'!M23 -> 35673 | L8: ='مستخلص 3'!M24 -> 3102 | M8: ='مستخلص 3'!M25 -> 3102 | N8: ='مستخلص 3'!M26 -> 0 | O8: ='مستخلص 3'!M28 -> 29469 | R8: =ROUND(O8-P8,2) -> 29469 | S8: =IF(C8="","",IF(O8<=0,"-",IF(P8>=O8,"✔ محصل بالكامل",IF(P8>0,"⚠ محصل جزئياً","✖ غير محصل")))) -> ✖ غير محصل
B9: الإجمالي | G9: =SUM(G6:G8) -> 212382.5 | H9: =MAX(H6:H8) -> 212382.5 | I9: =IF('الإعدادات'!$C$19=0,0,H9/'الإعدادات'!$C$19) -> 0.76146504 | J9: =SUM(J6:J8) -> 31857.38 | K9: =SUM(K6:K8) -> 244239.88 | L9: =SUM(L6:L8) -> 21238.25 | M9: =SUM(M6:M8) -> 21238.25 | N9: =SUM(N6:N8) -> 1500 | O9: =SUM(O6:O8) -> 200263.38 | P9: =SUM(P6:P8) -> 138684.55 | R9: =SUM(R6:R8) -> 61578.83

Sheet الدفعات المقدمة
B1: 💵 الدفعات المقدمة واستردادها
B2: 🎁 نسخة مجانية محدودة (3 مستخلصات • 10 بنود) — للنسخة الكاملة (25 مستخلص • 100 بند • بدون قيود) اضغط هنا ⬅ accopro.net
B3: 🏠 لوحة التحكم | D3: ⚙ الإعدادات | E3: 📋 جدول الكميات | G3: 🗂 سجل المستخلصات | I3: 🔒 ضمان الأعمال | K3: 📄 مستخلص 1
B5: إعدادات الاسترداد والملخص | H5: كيف تعمل الصفحة؟
B6: نسبة الاسترداد من قيمة أعمال كل مستخلص | E6: 0.1 | H6: 1) سجّل كل دفعة مقدمة مصروفة وخطاب ضمانها في الجدول الأول. 2) يُستقطع من كل مستخلص (قيمة الأعمال الحالية × نسبة الاسترداد) تلقائياً ويظهر في المستخلص. 3) يتوقف الاسترداد تلقائياً عند اكتمال استرداد كامل الدفعة (لا يتجاوز الرصيد). 4) يمكنك إدخال نسبة مخصصة لمستخلص معين في العمود الأصفر (مثلاً لتسريع الاسترداد في الختامي).
B7: بدء الاسترداد من المستخلص رقم | E7: 1
B8: إجمالي الدفعات المقدمة المصروفة | E8: =D21 -> 28000
B9: نسبة الدفعة المقدمة من قيمة العقد | E9: =IF('الإعدادات'!$C$19=0,0,E8/'الإعدادات'!$C$19) -> 0.10038973
B10: إجمالي ما تم استرداده | E10: =I28 -> 21238.25
B11: الرصيد المتبقي للاسترداد | E11: =E8-E10 -> 6761.75
B13: سجل صرف الدفعات المقدمة وخطابات ضمانها
B14: م | C14: تاريخ الصرف | D14: المبلغ المصروف | E14: % من العقد | F14: رقم خطاب الضمان | G14: البنك | H14: تاريخ انتهاء الضمان | I14: الأيام المتبقية | J14: حالة الضمان | K14: ملاحظات
B15: 1 | C15: 46091 | D15: 28000 | E15: =IF('الإعدادات'!$C$19=0,0,D15/'الإعدادات'!$C$19) -> 0.10038973 | F15: LG-558210 | G15: البنك الأهلي السعودي | H15: 46456 | I15: =IF(H15="","",H15-TODAY()) -> 162 | J15: =IF(H15="","",IF(I15<0,"✖ منتهي",IF(I15<=30,"⚠ ينتهي قريباً","✔ ساري"))) -> ✔ ساري
B16: 2 | C16: 🔒 دفعات مقدمة متعددة — متاحة في النسخة الكاملة
B17: 3 | C17: 🔒 دفعات مقدمة متعددة — متاحة في النسخة الكاملة
B18: 4 | C18: 🔒 دفعات مقدمة متعددة — متاحة في النسخة الكاملة
B19: 5 | C19: 🔒 دفعات مقدمة متعددة — متاحة في النسخة الكاملة
B20: 6 | C20: 🔒 دفعات مقدمة متعددة — متاحة في النسخة الكاملة
B21: الإجمالي | D21: =SUM(D15:D20) -> 28000 | E21: =SUM(E15:E20) -> 0.10038973
B23: جدول استرداد الدفعة المقدمة من المستخلصات
B24: رقم المستخلص | C24: التاريخ | D24: قيمة الأعمال الحالية | E24: النسبة الافتراضية | F24: نسبة مخصصة ✎ (اختياري) | G24: النسبة المطبقة | H24: الاسترداد المحسوب | I24: الاسترداد المعتمد | J24: المسترد التراكمي | K24: الرصيد المتبقي | L24: % المسترد
B25: 1 | C25: ='سجل المستخلصات'!C6 -> 46173 | D25: ='مستخلص 1'!M21 -> 95284 | E25: =$E$6 -> 0.1 | G25: =IF(B25<$E$7,0,IF(F25="",E25,F25)) -> 0.1 | H25: =MAX(0,ROUND(D25*G25,2)) -> 9528.4 | I25: =MIN(H25,MAX(0,$E$8-0)) -> 9528.4 | J25: =0+I25 -> 9528.4 | K25: =$E$8-J25 -> 18471.6 | L25: =IF($E$8=0,0,J25/$E$8) -> 0.3403
B26: 2 | C26: ='سجل المستخلصات'!C7 -> 46218 | D26: ='مستخلص 2'!M21 -> 86078.5 | E26: =$E$6 -> 0.1 | G26: =IF(B26<$E$7,0,IF(F26="",E26,F26)) -> 0.1 | H26: =MAX(0,ROUND(D26*G26,2)) -> 8607.85 | I26: =MIN(H26,MAX(0,$E$8-J25)) -> 8607.85 | J26: =J25+I26 -> 18136.25 | K26: =$E$8-J26 -> 9863.75 | L26: =IF($E$8=0,0,J26/$E$8) -> 0.64772321
B27: 3 | C27: ='سجل المستخلصات'!C8 -> 46275 | D27: ='مستخلص 3'!M21 -> 31020 | E27: =$E$6 -> 0.1 | G27: =IF(B27<$E$7,0,IF(F27="",E27,F27)) -> 0.1 | H27: =MAX(0,ROUND(D27*G27,2)) -> 3102 | I27: =MIN(H27,MAX(0,$E$8-J26)) -> 3102 | J27: =J26+I27 -> 21238.25 | K27: =$E$8-J27 -> 6761.75 | L27: =IF($E$8=0,0,J27/$E$8) -> 0.75850893
B28: الإجمالي | D28: =SUM(D25:D27) -> 212382.5 | H28: =SUM(H25:H27) -> 21238.25 | I28: =SUM(I25:I27) -> 21238.25 | K28: =E8-I28 -> 6761.75 | L28: =IF(E8=0,0,I28/E8) -> 0.75850893

Sheet ضمان الأعمال
B1: 🔒 ضمان الأعمال (المحتجزات) والضمانات البنكية
B2: 🎁 نسخة مجانية محدودة (3 مستخلصات • 10 بنود) — للنسخة الكاملة (25 مستخلص • 100 بند • بدون قيود) اضغط هنا ⬅ accopro.net
B3: 🏠 لوحة التحكم | D3: ⚙ الإعدادات | E3: 📋 جدول الكميات | G3: 🗂 سجل المستخلصات | I3: 💵 الدفعات المقدمة | K3: 📄 مستخلص 1
B5: إعدادات ضمان الأعمال والملخص | H5: شروط الإفراج (للتوثيق)
B6: نسبة ضمان الأعمال المستقطعة من كل مستخلص | E6: 0.1 | H6: مرحلة الإفراج | K6: نسبة الإفراج | L6: القيمة المتوقعة
B7: الحد الأقصى للضمان (% من قيمة العقد) — اتركه فارغاً بدون حد | H7: عند الاستلام الابتدائي | K7: 0.5 | L7: =ROUND($E$9*K7,2) -> 10619.13
B8: قيمة الحد الأقصى | E8: =IF(E7="","بدون حد",E7*'الإعدادات'!$C$19) -> بدون حد | H8: عند الاستلام النهائي (بعد فترة الصيانة) | K8: 0.5 | L8: =ROUND($E$9*K8,2) -> 10619.13
B9: إجمالي المستقطع من المستخلصات | E9: =I19 -> 21238.25 | H9: أخرى | L9: =ROUND($E$9*K9,2) -> 0
B10: إجمالي المفرج عنه | E10: =F29 -> 0 | H10: مدة فترة الضمان والصيانة (شهر) | L10: 12
B11: الرصيد المحتجز لدى المالك حالياً | E11: =E9-E10 -> 21238.25 | H11: تاريخ الإفراج النهائي المتوقع | L11: =IF(OR('الإعدادات'!C15="",L10=""),"",EDATE('الإعدادات'!C15,L10)) -> 46813
B14: جدول استقطاع ضمان الأعمال من المستخلصات
B15: رقم المستخلص | C15: التاريخ | D15: قيمة الأعمال الحالية | E15: النسبة الافتراضية | F15: نسبة مخصصة ✎ (اختياري) | G15: النسبة المطبقة | H15: الضمان المحسوب | I15: الضمان المعتمد | J15: الضمان التراكمي | K15: قيمة الأعمال التراكمية | L15: % من الأعمال
B16: 1 | C16: ='سجل المستخلصات'!C6 -> 46173 | D16: ='مستخلص 1'!M21 -> 95284 | E16: =$E$6 -> 0.1 | G16: =IF(F16="",E16,F16) -> 0.1 | H16: =MAX(0,ROUND(D16*G16,2)) -> 9528.4 | I16: =IF($E$7="",H16,MIN(H16,MAX(0,$E$7*'الإعدادات'!$C$19-0))) -> 9528.4 | J16: =0+I16 -> 9528.4 | K16: ='مستخلص 1'!N21 -> 95284 | L16: =IF(K16=0,0,J16/K16) -> 0.1
B17: 2 | C17: ='سجل المستخلصات'!C7 -> 46218 | D17: ='مستخلص 2'!M21 -> 86078.5 | E17: =$E$6 -> 0.1 | G17: =IF(F17="",E17,F17) -> 0.1 | H17: =MAX(0,ROUND(D17*G17,2)) -> 8607.85 | I17: =IF($E$7="",H17,MIN(H17,MAX(0,$E$7*'الإعدادات'!$C$19-J16))) -> 8607.85 | J17: =J16+I17 -> 18136.25 | K17: ='مستخلص 2'!N21 -> 181362.5 | L17: =IF(K17=0,0,J17/K17) -> 0.1
B18: 3 | C18: ='سجل المستخلصات'!C8 -> 46275 | D18: ='مستخلص 3'!M21 -> 31020 | E18: =$E$6 -> 0.1 | G18: =IF(F18="",E18,F18) -> 0.1 | H18: =MAX(0,ROUND(D18*G18,2)) -> 3102 | I18: =IF($E$7="",H18,MIN(H18,MAX(0,$E$7*'الإعدادات'!$C$19-J17))) -> 3102 | J18: =J17+I18 -> 21238.25 | K18: ='مستخلص 3'!N21 -> 212382.5 | L18: =IF(K18=0,0,J18/K18) -> 0.1
B19: الإجمالي | D19: =SUM(D16:D18) -> 212382.5 | H19: =SUM(H16:H18) -> 21238.25 | I19: =SUM(I16:I18) -> 21238.25
B21: سجل الإفراج عن ضمان الأعمال
B22: م | C22: تاريخ الإفراج | D22: المرحلة / السبب | F22: المبلغ المفرج عنه | G22: % من المحتجز | H22: رقم الشيك / التحويل | I22: ملاحظات
B23: 1 | C23: 🔒 النسخة الكاملة | G23: =IF($E$9=0,0,F23/$E$9) -> 0
B24: 2 | G24: =IF($E$9=0,0,F24/$E$9) -> 0
B25: 3 | G25: =IF($E$9=0,0,F25/$E$9) -> 0
B26: 4 | G26: =IF($E$9=0,0,F26/$E$9) -> 0
B27: 5 | G27: =IF($E$9=0,0,F27/$E$9) -> 0
B28: 6 | G28: =IF($E$9=0,0,F28/$E$9) -> 0
B29: الإجمالي | F29: =SUM(F23:F28) -> 0 | G29: =SUM(G23:G28) -> 0
B31: الضمانات البنكية للعقد (ابتدائي / حسن تنفيذ / بديل محتجزات)
B32: م | C32: نوع الضمان | E32: رقم الخطاب | F32: البنك | G32: القيمة | H32: % من العقد | I32: تاريخ الإصدار | J32: تاريخ الانتهاء | K32: الأيام المتبقية | L32: الحالة
B33: 1 | C33: ضمان نهائي (حسن تنفيذ) | E33: PB-771034 | F33: مصرف الراجحي | G33: 28000 | H33: =IF('الإعدادات'!$C$19=0,0,G33/'الإعدادات'!$C$19) -> 0.10038973 | I33: 46073 | J33: 46315 | K33: =IF(J33="","",J33-TODAY()) -> 21 | L33: =IF(J33="","",IF(K33<0,"✖ منتهي",IF(K33<=30,"⚠ ينتهي قريباً","✔ ساري"))) -> ⚠ ينتهي قريباً
B34: 2 | C34: 🔒 متابعة أكثر من ضمان بنكي — متاحة في النسخة الكاملة | K34: =IF(J34="","",J34-TODAY()) | L34: =IF(J34="","",IF(K34<0,"✖ منتهي",IF(K34<=30,"⚠ ينتهي قريباً","✔ ساري")))
B35: 3 | C35: 🔒 متابعة أكثر من ضمان بنكي — متاحة في النسخة الكاملة | K35: =IF(J35="","",J35-TODAY()) | L35: =IF(J35="","",IF(K35<0,"✖ منتهي",IF(K35<=30,"⚠ ينتهي قريباً","✔ ساري")))
B36: 4 | C36: 🔒 متابعة أكثر من ضمان بنكي — متاحة في النسخة الكاملة | K36: =IF(J36="","",J36-TODAY()) | L36: =IF(J36="","",IF(K36<0,"✖ منتهي",IF(K36<=30,"⚠ ينتهي قريباً","✔ ساري")))
B37: 5 | C37: 🔒 متابعة أكثر من ضمان بنكي — متاحة في النسخة الكاملة | K37: =IF(J37="","",J37-TODAY()) | L37: =IF(J37="","",IF(K37<0,"✖ منتهي",IF(K37<=30,"⚠ ينتهي قريباً","✔ ساري")))
B38: 6 | C38: 🔒 متابعة أكثر من ضمان بنكي — متاحة في النسخة الكاملة | K38: =IF(J38="","",J38-TODAY()) | L38: =IF(J38="","",IF(K38<0,"✖ منتهي",IF(K38<=30,"⚠ ينتهي قريباً","✔ ساري")))

Sheet مستخلص 1
A1: ="مستخلص أعمال رقم ( 1 ) — "&'الإعدادات'!$C$6 -> مستخلص أعمال رقم ( 1 ) — مشروع تأهيل أبراج طيبة - المنطقة المركزية شارع الهجرة
A2: 🎁 نسخة مجانية محدودة (3 مستخلصات • 10 بنود) — للنسخة الكاملة (25 مستخلص • 100 بند • بدون قيود) اضغط هنا ⬅ accopro.net
A3: 🏠 | B3: 🗂 سجل المستخلصات | C3: 📋 BOQ | F3: 💵 المقدمة | H3: 🔒 الضمان | N3: المستخلص التالي (2) ▶
A4: رقم | B4: 1 | C4: تاريخ المستخلص | E4: 46173 | G4: الحالة | H4: جاري | J4: الفترة من | L4: 46082 | M4: إلى | N4: 46173
A5: المشروع | B5: ='الإعدادات'!$C$6 -> مشروع تأهيل أبراج طيبة - المنطقة المركزية شارع الهجرة | C5: المالك | E5: ='الإعدادات'!$C$8 -> شركة ثروات الرائدة العقارية | J5: المقاول | L5: ='الإعدادات'!$C$9 -> مؤسسة البناء المتقن للمقاولات
A6: البند | B6: بيان الأعمال | C6: الوحدة | D6: الكمية التعاقدية | E6: سعر الوحدة | F6: الكمية المنفذة من واقع التمتير الفعلي | I6: نسبة الإنجاز / الاستحقاق للبند | L6: قيمة الأعمال المنفذة | O6: نسبة الإنجاز الفعلية | P6: ملاحظات
F7: سابق | G7: حالي ✎ | H7: إجمالي | I7: سابقة | J7: حالية 🔒 النسخة الكاملة | K7: المعتمدة | L7: سابقة | M7: حالية | N7: إجمالية
A8: =IF('جدول الكميات'!A6="","",'جدول الكميات'!A6) -> 1 | B8: =IF('جدول الكميات'!C6="","",'جدول الكميات'!C6) -> توريد وتركيب هندريل زجاج مع كبسة أستيل لدور الميزانين | C8: =IF('جدول الكميات'!D6="","",'جدول الكميات'!D6) -> م.ط | D8: ='جدول الكميات'!E6 -> 7.54 | E8: ='جدول الكميات'!F6 -> 650 | F8: 0 | G8: 3.77 | H8: =F8+G8 -> 3.77 | I8: 1 | K8: =IF(J8="",I8,J8) -> 1 | L8: 0 | M8: =N8-L8 -> 2450.5 | N8: =ROUND(H8*E8*K8,2) -> 2450.5 | O8: =IF(D8*E8=0,0,N8/(D8*E8)) -> 0.5
A9: =IF('جدول الكميات'!A7="","",'جدول الكميات'!A7) -> 2 | B9: =IF('جدول الكميات'!C7="","",'جدول الكميات'!C7) -> توريد وتركيب مرايات لحمامات الدور الأرضي | C9: =IF('جدول الكميات'!D7="","",'جدول الكميات'!D7) -> عدد | D9: ='جدول الكميات'!E7 -> 5 | E9: ='جدول الكميات'!F7 -> 800 | F9: 0 | G9: 1.75 | H9: =F9+G9 -> 1.75 | I9: 1 | K9: =IF(J9="",I9,J9) -> 1 | L9: 0 | M9: =N9-L9 -> 1400 | N9: =ROUND(H9*E9*K9,2) -> 1400 | O9: =IF(D9*E9=0,0,N9/(D9*E9)) -> 0.35
A10: =IF('جدول الكميات'!A8="","",'جدول الكميات'!A8) -> 3 | B10: =IF('جدول الكميات'!C8="","",'جدول الكميات'!C8) -> تركيب زجاج هندريل لدور الميزانين | C10: =IF('جدول الكميات'!D8="","",'جدول الكميات'!D8) -> م.ط | D10: ='جدول الكميات'!E8 -> 9.4 | E10: ='جدول الكميات'!F8 -> 150 | F10: 0 | G10: 3.29 | H10: =F10+G10 -> 3.29 | I10: 1 | K10: =IF(J10="",I10,J10) -> 1 | L10: 0 | M10: =N10-L10 -> 493.5 | N10: =ROUND(H10*E10*K10,2) -> 493.5 | O10: =IF(D10*E10=0,0,N10/(D10*E10)) -> 0.35
A11: =IF('جدول الكميات'!A9="","",'جدول الكميات'!A9) -> 4 | B11: =IF('جدول الكميات'!C9="","",'جدول الكميات'!C9) -> فك وإعادة تركيب زجاج هندريل دور الميزانين | C11: =IF('جدول الكميات'!D9="","",'جدول الكميات'!D9) -> م.ط | D11: ='جدول الكميات'!E9 -> 5.4 | E11: ='جدول الكميات'!F9 -> 300 | F11: 0 | G11: 1.51 | H11: =F11+G11 -> 1.51 | I11: 1 | K11: =IF(J11="",I11,J11) -> 1 | L11: 0 | M11: =N11-L11 -> 453 | N11: =ROUND(H11*E11*K11,2) -> 453 | O11: =IF(D11*E11=0,0,N11/(D11*E11)) -> 0.27962963
A12: =IF('جدول الكميات'!A10="","",'جدول الكميات'!A10) -> 5 | B12: =IF('جدول الكميات'!C10="","",'جدول الكميات'!C10) -> فك وتلحيم مواسير أستيل (كبسة) فوق الزجاج وإعادة تركيبه لدور الميزانين | C12: =IF('جدول الكميات'!D10="","",'جدول الكميات'!D10) -> م.ط | D12: ='جدول الكميات'!E10 -> 31.48 | E12: ='جدول الكميات'!F10 -> 150 | F12: 0 | G12: 15.74 | H12: =F12+G12 -> 15.74 | I12: 1 | K12: =IF(J12="",I12,J12) -> 1 | L12: 0 | M12: =N12-L12 -> 2361 | N12: =ROUND(H12*E12*K12,2) -> 2361 | O12: =IF(D12*E12=0,0,N12/(D12*E12)) -> 0.5
A13: =IF('جدول الكميات'!A11="","",'جدول الكميات'!A11) -> 6 | B13: =IF('جدول الكميات'!C11="","",'جدول الكميات'!C11) -> فك وإعادة تركيب أبواب الشوارات للحمامات (ثابت ومتحرك) | C13: =IF('جدول الكميات'!D11="","",'جدول الكميات'!D11) -> عدد | D13: ='جدول الكميات'!E11 -> 33 | E13: ='جدول الكميات'!F11 -> 300 | F13: 0 | G13: 11.55 | H13: =F13+G13 -> 11.55 | I13: 1 | K13: =IF(J13="",I13,J13) -> 1 | L13: 0 | M13: =N13-L13 -> 3465 | N13: =ROUND(H13*E13*K13,2) -> 3465 | O13: =IF(D13*E13=0,0,N13/(D13*E13)) -> 0.35
A14: =IF('جدول الكميات'!A12="","",'جدول الكميات'!A12) -> 7 | B14: =IF('جدول الكميات'!C12="","",'جدول الكميات'!C12) -> تركيب شبابيك للواجهات الخلفية والجانبية بين الأبراج | C14: =IF('جدول الكميات'!D12="","",'جدول الكميات'!D12) -> عدد | D14: ='جدول الكميات'!E12 -> 343 | E14: ='جدول الكميات'!F12 -> 120 | F14: 0 | G14: 205.8 | H14: =F14+G14 -> 205.8 | I14: 1 | K14: =IF(J14="",I14,J14) -> 1 | L14: 0 | M14: =N14-L14 -> 24696 | N14: =ROUND(H14*E14*K14,2) -> 24696 | O14: =IF(D14*E14=0,0,N14/(D14*E14)) -> 0.6
A15: =IF('جدول الكميات'!A13="","",'جدول الكميات'!A13) -> 8 | B15: =IF('جدول الكميات'!C13="","",'جدول الكميات'!C13) -> فك شبابيك الواجهات الخلفية مرة أخرى من أجل أعمال التلابيس | C15: =IF('جدول الكميات'!D13="","",'جدول الكميات'!D13) -> عدد | D15: ='جدول الكميات'!E13 -> 58 | E15: ='جدول الكميات'!F13 -> 50 | F15: 0 | G15: 20.3 | H15: =F15+G15 -> 20.3 | I15: 1 | K15: =IF(J15="",I15,J15) -> 1 | L15: 0 | M15: =N15-L15 -> 1015 | N15: =ROUND(H15*E15*K15,2) -> 1015 | O15: =IF(D15*E15=0,0,N15/(D15*E15)) -> 0.35
A16: =IF('جدول الكميات'!A14="","",'جدول الكميات'!A14) -> 9 | B16: =IF('جدول الكميات'!C14="","",'جدول الكميات'!C14) -> توريد وتركيب درابزين حديد لسلالم الطوارئ | C16: =IF('جدول الكميات'!D14="","",'جدول الكميات'!D14) -> م.ط | D16: ='جدول الكميات'!E14 -> 262 | E16: ='جدول الكميات'!F14 -> 450 | F16: 0 | G16: 131 | H16: =F16+G16 -> 131 | I16: 1 | K16: =IF(J16="",I16,J16) -> 1 | L16: 0 | M16: =N16-L16 -> 58950 | N16: =ROUND(H16*E16*K16,2) -> 58950 | O16: =IF(D16*E16=0,0,N16/(D16*E16)) -> 0.5
A17: =IF('جدول الكميات'!A15="","",'جدول الكميات'!A15) -> 10 | B17: =IF('جدول الكميات'!C15="","",'جدول الكميات'!C15) -> توريد وتركيب بارتشن ثابت (قواطع داخلية للحمامات) | C17: =IF('جدول الكميات'!D15="","",'جدول الكميات'!D15) -> عدد | D17: ='جدول الكميات'!E15 -> 226 | E17: ='جدول الكميات'!F15 -> 400 | F17: 0 | H17: =F17+G17 -> 0 | I17: 1 | K17: =IF(J17="",I17,J17) -> 1 | L17: 0 | M17: =N17-L17 -> 0 | N17: =ROUND(H17*E17*K17,2) -> 0 | O17: =IF(D17*E17=0,0,N17/(D17*E17)) -> 0
A18: إجمالي قيمة الأعمال | L18: =SUM(L8:L17) -> 0 | M18: =SUM(M8:M17) -> 95284 | N18: =SUM(N8:N17) -> 95284 | O18: =IF('الإعدادات'!$C$19=0,0,N18/'الإعدادات'!$C$19) -> 0.34162624
A20: ملاحظات المستخلص | I20: البيان | L20: المستخلص السابق | M20: المستخلص الحالي | N20: إجمالي الأعمال
I21: إجمالي قيمة الأعمال | L21: 0 | M21: =M18 -> 95284 | N21: =L21+M21 -> 95284
I22: ="ضريبة القيمة المضافة ("&TEXT('الإعدادات'!$C$18,"0%")&")" -> ضريبة القيمة المضافة (15%) | L22: 0 | M22: =ROUND(M21*'الإعدادات'!$C$18,2) -> 14292.6 | N22: =L22+M22 -> 14292.6
I23: الإجمالي شامل الضريبة | L23: 0 | M23: =ROUND(M21+M22,2) -> 109576.6 | N23: =L23+M23 -> 109576.6
I24: (-) خصم استرداد الدفعة المقدمة | L24: 0 | M24: ='الدفعات المقدمة'!I25 -> 9528.4 | N24: =L24+M24 -> 9528.4
I25: ="(-) خصم ضمان الأعمال ("&TEXT('ضمان الأعمال'!$E$6,"0%")&")" -> (-) خصم ضمان الأعمال (10%) | L25: 0 | M25: ='ضمان الأعمال'!I16 -> 9528.4 | N25: =L25+M25 -> 9528.4
I26: (-) خصومات أخرى / غرامات / مواد مورّدة من المالك ✎ | L26: 0 | N26: =L26+M26 -> 0
I27: إجمالي الخصومات | L27: 0 | M27: =SUM(M24:M26) -> 19056.8 | N27: =L27+M27 -> 19056.8
I28: صافي قيمة المستخلص المستحق | L28: 0 | M28: =ROUND(M23-M27,2) -> 90519.8 | N28: =L28+M28 -> 90519.8
A31: ='الإعدادات'!B36 -> مهندس الموقع (المقاول) | C31: ='الإعدادات'!B37 -> مدير المشروع (المقاول) | H31: ='الإعدادات'!B38 -> المهندس المشرف (الاستشاري) | M31: ='الإعدادات'!B39 -> ممثل المالك
A32: =IF('الإعدادات'!C36="","الاسم: ..................","الاسم: "&'الإعدادات'!C36) -> الاسم: م. أحمد محمد | C32: =IF('الإعدادات'!C37="","الاسم: ..................","الاسم: "&'الإعدادات'!C37) -> الاسم: م. خالد عبدالله | H32: =IF('الإعدادات'!C38="","الاسم: ..................","الاسم: "&'الإعدادات'!C38) -> الاسم: م. سامي علي | M32: =IF('الإعدادات'!C39="","الاسم: ..................","الاسم: "&'الإعدادات'!C39) -> الاسم: أ. فهد سعد
A33: التوقيع: .............................. | C33: التوقيع: .............................. | H33: التوقيع: .............................. | M33: التوقيع: ..............................
A34: التاريخ: / / | C34: التاريخ: / / | H34: التاريخ: / / | M34: التاريخ: / /

Sheet مستخلص 2
A1: ="مستخلص أعمال رقم ( 2 ) — "&'الإعدادات'!$C$6 -> مستخلص أعمال رقم ( 2 ) — مشروع تأهيل أبراج طيبة - المنطقة المركزية شارع الهجرة
A2: 🎁 نسخة مجانية محدودة (3 مستخلصات • 10 بنود) — للنسخة الكاملة (25 مستخلص • 100 بند • بدون قيود) اضغط هنا ⬅ accopro.net
A3: 🏠 | B3: 🗂 سجل المستخلصات | C3: 📋 BOQ | F3: 💵 المقدمة | H3: 🔒 الضمان | L3: ◀ المستخلص السابق (1) | N3: المستخلص التالي (3) ▶
A4: رقم | B4: 2 | C4: تاريخ المستخلص | E4: 46218 | G4: الحالة | H4: جاري | J4: الفترة من | L4: 46174 | M4: إلى | N4: 46218
A5: المشروع | B5: ='الإعدادات'!$C$6 -> مشروع تأهيل أبراج طيبة - المنطقة المركزية شارع الهجرة | C5: المالك | E5: ='الإعدادات'!$C$8 -> شركة ثروات الرائدة العقارية | J5: المقاول | L5: ='الإعدادات'!$C$9 -> مؤسسة البناء المتقن للمقاولات
A6: البند | B6: بيان الأعمال | C6: الوحدة | D6: الكمية التعاقدية | E6: سعر الوحدة | F6: الكمية المنفذة من واقع التمتير الفعلي | I6: نسبة الإنجاز / الاستحقاق للبند | L6: قيمة الأعمال المنفذة | O6: نسبة الإنجاز الفعلية | P6: ملاحظات
F7: سابق | G7: حالي ✎ | H7: إجمالي | I7: سابقة | J7: حالية 🔒 النسخة الكاملة | K7: المعتمدة | L7: سابقة | M7: حالية | N7: إجمالية
A8: =IF('جدول الكميات'!A6="","",'جدول الكميات'!A6) -> 1 | B8: =IF('جدول الكميات'!C6="","",'جدول الكميات'!C6) -> توريد وتركيب هندريل زجاج مع كبسة أستيل لدور الميزانين | C8: =IF('جدول الكميات'!D6="","",'جدول الكميات'!D6) -> م.ط | D8: ='جدول الكميات'!E6 -> 7.54 | E8: ='جدول الكميات'!F6 -> 650 | F8: ='مستخلص 1'!H8 -> 3.77 | G8: 3.77 | H8: =F8+G8 -> 7.54 | I8: ='مستخلص 1'!K8 -> 1 | K8: =IF(J8="",I8,J8) -> 1 | L8: ='مستخلص 1'!N8 -> 2450.5 | M8: =N8-L8 -> 2450.5 | N8: =ROUND(H8*E8*K8,2) -> 4901 | O8: =IF(D8*E8=0,0,N8/(D8*E8)) -> 1
A9: =IF('جدول الكميات'!A7="","",'جدول الكميات'!A7) -> 2 | B9: =IF('جدول الكميات'!C7="","",'جدول الكميات'!C7) -> توريد وتركيب مرايات لحمامات الدور الأرضي | C9: =IF('جدول الكميات'!D7="","",'جدول الكميات'!D7) -> عدد | D9: ='جدول الكميات'!E7 -> 5 | E9: ='جدول الكميات'!F7 -> 800 | F9: ='مستخلص 1'!H9 -> 1.75 | G9: 1.5 | H9: =F9+G9 -> 3.25 | I9: ='مستخلص 1'!K9 -> 1 | K9: =IF(J9="",I9,J9) -> 1 | L9: ='مستخلص 1'!N9 -> 1400 | M9: =N9-L9 -> 1200 | N9: =ROUND(H9*E9*K9,2) -> 2600 | O9: =IF(D9*E9=0,0,N9/(D9*E9)) -> 0.65
A10: =IF('جدول الكميات'!A8="","",'جدول الكميات'!A8) -> 3 | B10: =IF('جدول الكميات'!C8="","",'جدول الكميات'!C8) -> تركيب زجاج هندريل لدور الميزانين | C10: =IF('جدول الكميات'!D8="","",'جدول الكميات'!D8) -> م.ط | D10: ='جدول الكميات'!E8 -> 9.4 | E10: ='جدول الكميات'!F8 -> 150 | F10: ='مستخلص 1'!H10 -> 3.29 | G10: 2.82 | H10: =F10+G10 -> 6.11 | I10: ='مستخلص 1'!K10 -> 1 | K10: =IF(J10="",I10,J10) -> 1 | L10: ='مستخلص 1'!N10 -> 493.5 | M10: =N10-L10 -> 423 | N10: =ROUND(H10*E10*K10,2) -> 916.5 | O10: =IF(D10*E10=0,0,N10/(D10*E10)) -> 0.65
A11: =IF('جدول الكميات'!A9="","",'جدول الكميات'!A9) -> 4 | B11: =IF('جدول الكميات'!C9="","",'جدول الكميات'!C9) -> فك وإعادة تركيب زجاج هندريل دور الميزانين | C11: =IF('جدول الكميات'!D9="","",'جدول الكميات'!D9) -> م.ط | D11: ='جدول الكميات'!E9 -> 5.4 | E11: ='جدول الكميات'!F9 -> 300 | F11: ='مستخلص 1'!H11 -> 1.51 | G11: 1.3 | H11: =F11+G11 -> 2.81 | I11: ='مستخلص 1'!K11 -> 1 | K11: =IF(J11="",I11,J11) -> 1 | L11: ='مستخلص 1'!N11 -> 453 | M11: =N11-L11 -> 390 | N11: =ROUND(H11*E11*K11,2) -> 843 | O11: =IF(D11*E11=0,0,N11/(D11*E11)) -> 0.52037037
A12: =IF('جدول الكميات'!A10="","",'جدول الكميات'!A10) -> 5 | B12: =IF('جدول الكميات'!C10="","",'جدول الكميات'!C10) -> فك وتلحيم مواسير أستيل (كبسة) فوق الزجاج وإعادة تركيبه لدور الميزانين | C12: =IF('جدول الكميات'!D10="","",'جدول الكميات'!D10) -> م.ط | D12: ='جدول الكميات'!E10 -> 31.48 | E12: ='جدول الكميات'!F10 -> 150 | F12: ='مستخلص 1'!H12 -> 15.74 | G12: 15.74 | H12: =F12+G12 -> 31.48 | I12: ='مستخلص 1'!K12 -> 1 | K12: =IF(J12="",I12,J12) -> 1 | L12: ='مستخلص 1'!N12 -> 2361 | M12: =N12-L12 -> 2361 | N12: =ROUND(H12*E12*K12,2) -> 4722 | O12: =IF(D12*E12=0,0,N12/(D12*E12)) -> 1
A13: =IF('جدول الكميات'!A11="","",'جدول الكميات'!A11) -> 6 | B13: =IF('جدول الكميات'!C11="","",'جدول الكميات'!C11) -> فك وإعادة تركيب أبواب الشوارات للحمامات (ثابت ومتحرك) | C13: =IF('جدول الكميات'!D11="","",'جدول الكميات'!D11) -> عدد | D13: ='جدول الكميات'!E11 -> 33 | E13: ='جدول الكميات'!F11 -> 300 | F13: ='مستخلص 1'!H13 -> 11.55 | G13: 9.9 | H13: =F13+G13 -> 21.45 | I13: ='مستخلص 1'!K13 -> 1 | K13: =IF(J13="",I13,J13) -> 1 | L13: ='مستخلص 1'!N13 -> 3465 | M13: =N13-L13 -> 2970 | N13: =ROUND(H13*E13*K13,2) -> 6435 | O13: =IF(D13*E13=0,0,N13/(D13*E13)) -> 0.65
A14: =IF('جدول الكميات'!A12="","",'جدول الكميات'!A12) -> 7 | B14: =IF('جدول الكميات'!C12="","",'جدول الكميات'!C12) -> تركيب شبابيك للواجهات الخلفية والجانبية بين الأبراج | C14: =IF('جدول الكميات'!D12="","",'جدول الكميات'!D12) -> عدد | D14: ='جدول الكميات'!E12 -> 343 | E14: ='جدول الكميات'!F12 -> 120 | F14: ='مستخلص 1'!H14 -> 205.8 | G14: 137.2 | H14: =F14+G14 -> 343 | I14: ='مستخلص 1'!K14 -> 1 | K14: =IF(J14="",I14,J14) -> 1 | L14: ='مستخلص 1'!N14 -> 24696 | M14: =N14-L14 -> 16464 | N14: =ROUND(H14*E14*K14,2) -> 41160 | O14: =IF(D14*E14=0,0,N14/(D14*E14)) -> 1
A15: =IF('جدول الكميات'!A13="","",'جدول الكميات'!A13) -> 8 | B15: =IF('جدول الكميات'!C13="","",'جدول الكميات'!C13) -> فك شبابيك الواجهات الخلفية مرة أخرى من أجل أعمال التلابيس | C15: =IF('جدول الكميات'!D13="","",'جدول الكميات'!D13) -> عدد | D15: ='جدول الكميات'!E13 -> 58 | E15: ='جدول الكميات'!F13 -> 50 | F15: ='مستخلص 1'!H15 -> 20.3 | G15: 17.4 | H15: =F15+G15 -> 37.7 | I15: ='مستخلص 1'!K15 -> 1 | K15: =IF(J15="",I15,J15) -> 1 | L15: ='مستخلص 1'!N15 -> 1015 | M15: =N15-L15 -> 870 | N15: =ROUND(H15*E15*K15,2) -> 1885 | O15: =IF(D15*E15=0,0,N15/(D15*E15)) -> 0.65
A16: =IF('جدول الكميات'!A14="","",'جدول الكميات'!A14) -> 9 | B16: =IF('جدول الكميات'!C14="","",'جدول الكميات'!C14) -> توريد وتركيب درابزين حديد لسلالم الطوارئ | C16: =IF('جدول الكميات'!D14="","",'جدول الكميات'!D14) -> م.ط | D16: ='جدول الكميات'!E14 -> 262 | E16: ='جدول الكميات'!F14 -> 450 | F16: ='مستخلص 1'!H16 -> 131 | G16: 131 | H16: =F16+G16 -> 262 | I16: ='مستخلص 1'!K16 -> 1 | K16: =IF(J16="",I16,J16) -> 1 | L16: ='مستخلص 1'!N16 -> 58950 | M16: =N16-L16 -> 58950 | N16: =ROUND(H16*E16*K16,2) -> 117900 | O16: =IF(D16*E16=0,0,N16/(D16*E16)) -> 1
A17: =IF('جدول الكميات'!A15="","",'جدول الكميات'!A15) -> 10 | B17: =IF('جدول الكميات'!C15="","",'جدول الكميات'!C15) -> توريد وتركيب بارتشن ثابت (قواطع داخلية للحمامات) | C17: =IF('جدول الكميات'!D15="","",'جدول الكميات'!D15) -> عدد | D17: ='جدول الكميات'!E15 -> 226 | E17: ='جدول الكميات'!F15 -> 400 | F17: ='مستخلص 1'!H17 -> 0 | H17: =F17+G17 -> 0 | I17: ='مستخلص 1'!K17 -> 1 | K17: =IF(J17="",I17,J17) -> 1 | L17: ='مستخلص 1'!N17 -> 0 | M17: =N17-L17 -> 0 | N17: =ROUND(H17*E17*K17,2) -> 0 | O17: =IF(D17*E17=0,0,N17/(D17*E17)) -> 0
A18: إجمالي قيمة الأعمال | L18: =SUM(L8:L17) -> 95284 | M18: =SUM(M8:M17) -> 86078.5 | N18: =SUM(N8:N17) -> 181362.5 | O18: =IF('الإعدادات'!$C$19=0,0,N18/'الإعدادات'!$C$19) -> 0.65024757
A20: ملاحظات المستخلص | I20: البيان | L20: المستخلص السابق | M20: المستخلص الحالي | N20: إجمالي الأعمال
A21: الخصومات الأخرى تمثل غرامة تأخير توريد حسب خطاب الاستشاري | I21: إجمالي قيمة الأعمال | L21: ='مستخلص 1'!N21 -> 95284 | M21: =M18 -> 86078.5 | N21: =L21+M21 -> 181362.5
I22: ="ضريبة القيمة المضافة ("&TEXT('الإعدادات'!$C$18,"0%")&")" -> ضريبة القيمة المضافة (15%) | L22: ='مستخلص 1'!N22 -> 14292.6 | M22: =ROUND(M21*'الإعدادات'!$C$18,2) -> 12911.78 | N22: =L22+M22 -> 27204.38
I23: الإجمالي شامل الضريبة | L23: ='مستخلص 1'!N23 -> 109576.6 | M23: =ROUND(M21+M22,2) -> 98990.28 | N23: =L23+M23 -> 208566.88
I24: (-) خصم استرداد الدفعة المقدمة | L24: ='مستخلص 1'!N24 -> 9528.4 | M24: ='الدفعات المقدمة'!I26 -> 8607.85 | N24: =L24+M24 -> 18136.25
I25: ="(-) خصم ضمان الأعمال ("&TEXT('ضمان الأعمال'!$E$6,"0%")&")" -> (-) خصم ضمان الأعمال (10%) | L25: ='مستخلص 1'!N25 -> 9528.4 | M25: ='ضمان الأعمال'!I17 -> 8607.85 | N25: =L25+M25 -> 18136.25
I26: (-) خصومات أخرى / غرامات / مواد مورّدة من المالك ✎ | L26: ='مستخلص 1'!N26 -> 0 | M26: 1500 | N26: =L26+M26 -> 1500
I27: إجمالي الخصومات | L27: ='مستخلص 1'!N27 -> 19056.8 | M27: =SUM(M24:M26) -> 18715.7 | N27: =L27+M27 -> 37772.5
I28: صافي قيمة المستخلص المستحق | L28: ='مستخلص 1'!N28 -> 90519.8 | M28: =ROUND(M23-M27,2) -> 80274.58 | N28: =L28+M28 -> 170794.38
A31: ='الإعدادات'!B36 -> مهندس الموقع (المقاول) | C31: ='الإعدادات'!B37 -> مدير المشروع (المقاول) | H31: ='الإعدادات'!B38 -> المهندس المشرف (الاستشاري) | M31: ='الإعدادات'!B39 -> ممثل المالك
A32: =IF('الإعدادات'!C36="","الاسم: ..................","الاسم: "&'الإعدادات'!C36) -> الاسم: م. أحمد محمد | C32: =IF('الإعدادات'!C37="","الاسم: ..................","الاسم: "&'الإعدادات'!C37) -> الاسم: م. خالد عبدالله | H32: =IF('الإعدادات'!C38="","الاسم: ..................","الاسم: "&'الإعدادات'!C38) -> الاسم: م. سامي علي | M32: =IF('الإعدادات'!C39="","الاسم: ..................","الاسم: "&'الإعدادات'!C39) -> الاسم: أ. فهد سعد
A33: التوقيع: .............................. | C33: التوقيع: .............................. | H33: التوقيع: .............................. | M33: التوقيع: ..............................
A34: التاريخ: / / | C34: التاريخ: / / | H34: التاريخ: / / | M34: التاريخ: / /

Sheet مستخلص 3
A1: ="مستخلص أعمال رقم ( 3 ) — "&'الإعدادات'!$C$6 -> مستخلص أعمال رقم ( 3 ) — مشروع تأهيل أبراج طيبة - المنطقة المركزية شارع الهجرة
A2: 🎁 نسخة مجانية محدودة (3 مستخلصات • 10 بنود) — للنسخة الكاملة (25 مستخلص • 100 بند • بدون قيود) اضغط هنا ⬅ accopro.net
A3: 🏠 | B3: 🗂 سجل المستخلصات | C3: 📋 BOQ | F3: 💵 المقدمة | H3: 🔒 الضمان | L3: ◀ المستخلص السابق (2) | N3: 🔒 مستخلص 4 حتى 25 — النسخة الكاملة
A4: رقم | B4: 3 | C4: تاريخ المستخلص | E4: 46275 | G4: الحالة | H4: جاري | J4: الفترة من | L4: 46219 | M4: إلى | N4: 46275
A5: المشروع | B5: ='الإعدادات'!$C$6 -> مشروع تأهيل أبراج طيبة - المنطقة المركزية شارع الهجرة | C5: المالك | E5: ='الإعدادات'!$C$8 -> شركة ثروات الرائدة العقارية | J5: المقاول | L5: ='الإعدادات'!$C$9 -> مؤسسة البناء المتقن للمقاولات
A6: البند | B6: بيان الأعمال | C6: الوحدة | D6: الكمية التعاقدية | E6: سعر الوحدة | F6: الكمية المنفذة من واقع التمتير الفعلي | I6: نسبة الإنجاز / الاستحقاق للبند | L6: قيمة الأعمال المنفذة | O6: نسبة الإنجاز الفعلية | P6: ملاحظات
F7: سابق | G7: حالي ✎ | H7: إجمالي | I7: سابقة | J7: حالية 🔒 النسخة الكاملة | K7: المعتمدة | L7: سابقة | M7: حالية | N7: إجمالية
A8: =IF('جدول الكميات'!A6="","",'جدول الكميات'!A6) -> 1 | B8: =IF('جدول الكميات'!C6="","",'جدول الكميات'!C6) -> توريد وتركيب هندريل زجاج مع كبسة أستيل لدور الميزانين | C8: =IF('جدول الكميات'!D6="","",'جدول الكميات'!D6) -> م.ط | D8: ='جدول الكميات'!E6 -> 7.54 | E8: ='جدول الكميات'!F6 -> 650 | F8: ='مستخلص 2'!H8 -> 7.54 | H8: =F8+G8 -> 7.54 | I8: ='مستخلص 2'!K8 -> 1 | K8: =IF(J8="",I8,J8) -> 1 | L8: ='مستخلص 2'!N8 -> 4901 | M8: =N8-L8 -> 0 | N8: =ROUND(H8*E8*K8,2) -> 4901 | O8: =IF(D8*E8=0,0,N8/(D8*E8)) -> 1
A9: =IF('جدول الكميات'!A7="","",'جدول الكميات'!A7) -> 2 | B9: =IF('جدول الكميات'!C7="","",'جدول الكميات'!C7) -> توريد وتركيب مرايات لحمامات الدور الأرضي | C9: =IF('جدول الكميات'!D7="","",'جدول الكميات'!D7) -> عدد | D9: ='جدول الكميات'!E7 -> 5 | E9: ='جدول الكميات'!F7 -> 800 | F9: ='مستخلص 2'!H9 -> 3.25 | G9: 1 | H9: =F9+G9 -> 4.25 | I9: ='مستخلص 2'!K9 -> 1 | K9: =IF(J9="",I9,J9) -> 1 | L9: ='مستخلص 2'!N9 -> 2600 | M9: =N9-L9 -> 800 | N9: =ROUND(H9*E9*K9,2) -> 3400 | O9: =IF(D9*E9=0,0,N9/(D9*E9)) -> 0.85
A10: =IF('جدول الكميات'!A8="","",'جدول الكميات'!A8) -> 3 | B10: =IF('جدول الكميات'!C8="","",'جدول الكميات'!C8) -> تركيب زجاج هندريل لدور الميزانين | C10: =IF('جدول الكميات'!D8="","",'جدول الكميات'!D8) -> م.ط | D10: ='جدول الكميات'!E8 -> 9.4 | E10: ='جدول الكميات'!F8 -> 150 | F10: ='مستخلص 2'!H10 -> 6.11 | G10: 1.88 | H10: =F10+G10 -> 7.99 | I10: ='مستخلص 2'!K10 -> 1 | K10: =IF(J10="",I10,J10) -> 1 | L10: ='مستخلص 2'!N10 -> 916.5 | M10: =N10-L10 -> 282 | N10: =ROUND(H10*E10*K10,2) -> 1198.5 | O10: =IF(D10*E10=0,0,N10/(D10*E10)) -> 0.85
A11: =IF('جدول الكميات'!A9="","",'جدول الكميات'!A9) -> 4 | B11: =IF('جدول الكميات'!C9="","",'جدول الكميات'!C9) -> فك وإعادة تركيب زجاج هندريل دور الميزانين | C11: =IF('جدول الكميات'!D9="","",'جدول الكميات'!D9) -> م.ط | D11: ='جدول الكميات'!E9 -> 5.4 | E11: ='جدول الكميات'!F9 -> 300 | F11: ='مستخلص 2'!H11 -> 2.81 | G11: 0.86 | H11: =F11+G11 -> 3.67 | I11: ='مستخلص 2'!K11 -> 1 | K11: =IF(J11="",I11,J11) -> 1 | L11: ='مستخلص 2'!N11 -> 843 | M11: =N11-L11 -> 258 | N11: =ROUND(H11*E11*K11,2) -> 1101 | O11: =IF(D11*E11=0,0,N11/(D11*E11)) -> 0.67962963
A12: =IF('جدول الكميات'!A10="","",'جدول الكميات'!A10) -> 5 | B12: =IF('جدول الكميات'!C10="","",'جدول الكميات'!C10) -> فك وتلحيم مواسير أستيل (كبسة) فوق الزجاج وإعادة تركيبه لدور الميزانين | C12: =IF('جدول الكميات'!D10="","",'جدول الكميات'!D10) -> م.ط | D12: ='جدول الكميات'!E10 -> 31.48 | E12: ='جدول الكميات'!F10 -> 150 | F12: ='مستخلص 2'!H12 -> 31.48 | H12: =F12+G12 -> 31.48 | I12: ='مستخلص 2'!K12 -> 1 | K12: =IF(J12="",I12,J12) -> 1 | L12: ='مستخلص 2'!N12 -> 4722 | M12: =N12-L12 -> 0 | N12: =ROUND(H12*E12*K12,2) -> 4722 | O12: =IF(D12*E12=0,0,N12/(D12*E12)) -> 1
A13: =IF('جدول الكميات'!A11="","",'جدول الكميات'!A11) -> 6 | B13: =IF('جدول الكميات'!C11="","",'جدول الكميات'!C11) -> فك وإعادة تركيب أبواب الشوارات للحمامات (ثابت ومتحرك) | C13: =IF('جدول الكميات'!D11="","",'جدول الكميات'!D11) -> عدد | D13: ='جدول الكميات'!E11 -> 33 | E13: ='جدول الكميات'!F11 -> 300 | F13: ='مستخلص 2'!H13 -> 21.45 | G13: 6.6 | H13: =F13+G13 -> 28.05 | I13: ='مستخلص 2'!K13 -> 1 | K13: =IF(J13="",I13,J13) -> 1 | L13: ='مستخلص 2'!N13 -> 6435 | M13: =N13-L13 -> 1980 | N13: =ROUND(H13*E13*K13,2) -> 8415 | O13: =IF(D13*E13=0,0,N13/(D13*E13)) -> 0.85
A14: =IF('جدول الكميات'!A12="","",'جدول الكميات'!A12) -> 7 | B14: =IF('جدول الكميات'!C12="","",'جدول الكميات'!C12) -> تركيب شبابيك للواجهات الخلفية والجانبية بين الأبراج | C14: =IF('جدول الكميات'!D12="","",'جدول الكميات'!D12) -> عدد | D14: ='جدول الكميات'!E12 -> 343 | E14: ='جدول الكميات'!F12 -> 120 | F14: ='مستخلص 2'!H14 -> 343 | H14: =F14+G14 -> 343 | I14: ='مستخلص 2'!K14 -> 1 | K14: =IF(J14="",I14,J14) -> 1 | L14: ='مستخلص 2'!N14 -> 41160 | M14: =N14-L14 -> 0 | N14: =ROUND(H14*E14*K14,2) -> 41160 | O14: =IF(D14*E14=0,0,N14/(D14*E14)) -> 1
A15: =IF('جدول الكميات'!A13="","",'جدول الكميات'!A13) -> 8 | B15: =IF('جدول الكميات'!C13="","",'جدول الكميات'!C13) -> فك شبابيك الواجهات الخلفية مرة أخرى من أجل أعمال التلابيس | C15: =IF('جدول الكميات'!D13="","",'جدول الكميات'!D13) -> عدد | D15: ='جدول الكميات'!E13 -> 58 | E15: ='جدول الكميات'!F13 -> 50 | F15: ='مستخلص 2'!H15 -> 37.7 | G15: 11.6 | H15: =F15+G15 -> 49.3 | I15: ='مستخلص 2'!K15 -> 1 | K15: =IF(J15="",I15,J15) -> 1 | L15: ='مستخلص 2'!N15 -> 1885 | M15: =N15-L15 -> 580 | N15: =ROUND(H15*E15*K15,2) -> 2465 | O15: =IF(D15*E15=0,0,N15/(D15*E15)) -> 0.85
A16: =IF('جدول الكميات'!A14="","",'جدول الكميات'!A14) -> 9 | B16: =IF('جدول الكميات'!C14="","",'جدول الكميات'!C14) -> توريد وتركيب درابزين حديد لسلالم الطوارئ | C16: =IF('جدول الكميات'!D14="","",'جدول الكميات'!D14) -> م.ط | D16: ='جدول الكميات'!E14 -> 262 | E16: ='جدول الكميات'!F14 -> 450 | F16: ='مستخلص 2'!H16 -> 262 | H16: =F16+G16 -> 262 | I16: ='مستخلص 2'!K16 -> 1 | K16: =IF(J16="",I16,J16) -> 1 | L16: ='مستخلص 2'!N16 -> 117900 | M16: =N16-L16 -> 0 | N16: =ROUND(H16*E16*K16,2) -> 117900 | O16: =IF(D16*E16=0,0,N16/(D16*E16)) -> 1
A17: =IF('جدول الكميات'!A15="","",'جدول الكميات'!A15) -> 10 | B17: =IF('جدول الكميات'!C15="","",'جدول الكميات'!C15) -> توريد وتركيب بارتشن ثابت (قواطع داخلية للحمامات) | C17: =IF('جدول الكميات'!D15="","",'جدول الكميات'!D15) -> عدد | D17: ='جدول الكميات'!E15 -> 226 | E17: ='جدول الكميات'!F15 -> 400 | F17: ='مستخلص 2'!H17 -> 0 | G17: 67.8 | H17: =F17+G17 -> 67.8 | I17: ='مستخلص 2'!K17 -> 1 | K17: =IF(J17="",I17,J17) -> 1 | L17: ='مستخلص 2'!N17 -> 0 | M17: =N17-L17 -> 27120 | N17: =ROUND(H17*E17*K17,2) -> 27120 | O17: =IF(D17*E17=0,0,N17/(D17*E17)) -> 0.3
A18: إجمالي قيمة الأعمال | L18: =SUM(L8:L17) -> 181362.5 | M18: =SUM(M8:M17) -> 31020 | N18: =SUM(N8:N17) -> 212382.5 | O18: =IF('الإعدادات'!$C$19=0,0,N18/'الإعدادات'!$C$19) -> 0.76146504
A20: ملاحظات المستخلص | I20: البيان | L20: المستخلص السابق | M20: المستخلص الحالي | N20: إجمالي الأعمال
I21: إجمالي قيمة الأعمال | L21: ='مستخلص 2'!N21 -> 181362.5 | M21: =M18 -> 31020 | N21: =L21+M21 -> 212382.5
I22: ="ضريبة القيمة المضافة ("&TEXT('الإعدادات'!$C$18,"0%")&")" -> ضريبة القيمة المضافة (15%) | L22: ='مستخلص 2'!N22 -> 27204.38 | M22: =ROUND(M21*'الإعدادات'!$C$18,2) -> 4653 | N22: =L22+M22 -> 31857.38
I23: الإجمالي شامل الضريبة | L23: ='مستخلص 2'!N23 -> 208566.88 | M23: =ROUND(M21+M22,2) -> 35673 | N23: =L23+M23 -> 244239.88
I24: (-) خصم استرداد الدفعة المقدمة | L24: ='مستخلص 2'!N24 -> 18136.25 | M24: ='الدفعات المقدمة'!I27 -> 3102 | N24: =L24+M24 -> 21238.25
I25: ="(-) خصم ضمان الأعمال ("&TEXT('ضمان الأعمال'!$E$6,"0%")&")" -> (-) خصم ضمان الأعمال (10%) | L25: ='مستخلص 2'!N25 -> 18136.25 | M25: ='ضمان الأعمال'!I18 -> 3102 | N25: =L25+M25 -> 21238.25
I26: (-) خصومات أخرى / غرامات / مواد مورّدة من المالك ✎ | L26: ='مستخلص 2'!N26 -> 1500 | N26: =L26+M26 -> 1500
I27: إجمالي الخصومات | L27: ='مستخلص 2'!N27 -> 37772.5 | M27: =SUM(M24:M26) -> 6204 | N27: =L27+M27 -> 43976.5
I28: صافي قيمة المستخلص المستحق | L28: ='مستخلص 2'!N28 -> 170794.38 | M28: =ROUND(M23-M27,2) -> 29469 | N28: =L28+M28 -> 200263.38
A31: ='الإعدادات'!B36 -> مهندس الموقع (المقاول) | C31: ='الإعدادات'!B37 -> مدير المشروع (المقاول) | H31: ='الإعدادات'!B38 -> المهندس المشرف (الاستشاري) | M31: ='الإعدادات'!B39 -> ممثل المالك
A32: =IF('الإعدادات'!C36="","الاسم: ..................","الاسم: "&'الإعدادات'!C36) -> الاسم: م. أحمد محمد | C32: =IF('الإعدادات'!C37="","الاسم: ..................","الاسم: "&'الإعدادات'!C37) -> الاسم: م. خالد عبدالله | H32: =IF('الإعدادات'!C38="","الاسم: ..................","الاسم: "&'الإعدادات'!C38) -> الاسم: م. سامي علي | M32: =IF('الإعدادات'!C39="","الاسم: ..................","الاسم: "&'الإعدادات'!C39) -> الاسم: أ. فهد سعد
A33: التوقيع: .............................. | C33: التوقيع: .............................. | H33: التوقيع: .............................. | M33: التوقيع: ..............................
A34: التاريخ: / / | C34: التاريخ: / / | H34: التاريخ: / / | M34: التاريخ: / /
