Workbook
Name ContractValue: 'بيانات العقد'!$C$16
Name VOApproved: 'بيانات العقد'!$C$17
Name RevisedContract: 'بيانات العقد'!$C$18
Name AdvPct: 'بيانات العقد'!$C$20
Name AdvAmount: 'بيانات العقد'!$C$21
Name RecRate: 'بيانات العقد'!$C$23
Name RecStart: 'بيانات العقد'!$C$24
Name RecFull: 'بيانات العقد'!$C$25
Name RetPct: 'بيانات العقد'!$C$27
Name RetCap: 'بيانات العقد'!$C$29
Name VATPct: 'بيانات العقد'!$C$31
Name VATBeforeRet: 'بيانات العقد'!$C$32
Name WHTPct: 'بيانات العقد'!$C$33
Name PenInVAT: 'بيانات العقد'!$C$34
Name PenCap: 'بيانات العقد'!$C$45
Name StartDate: 'بيانات العقد'!$C$11
Name EndDate: 'بيانات العقد'!$C$13
Name AdvDate: 'بيانات العقد'!$C$22
Name L_Sections: 'بيانات العقد'!$F$6:$F$17
Name L_IPCStatus: 'بيانات العقد'!$G$6:$G$17
Name L_VOStatus: 'بيانات العقد'!$H$6:$H$17
Name L_TDType: 'بيانات العقد'!$I$6:$I$17
Name GAPct: 'الموازنة والتكاليف'!$E$6
Name ContPct: 'الموازنة والتكاليف'!$E$7
Name BAC: 'الموازنة والتكاليف'!$J$26

Sheet التعليمات
B1: 📘 ملف مستخلصات المشروع رقم 01 — 20 مستخلص مترابط
B2: =IF('بيانات العقد'!$C$5="","مشروع رقم 01 — أدخل بيانات العقد",'بيانات العقد'!$C$5&" | عقد رقم: "&'بيانات العقد'!$C$6)&" | المبالغ بـ "&'بيانات العقد'!$C$14
B3: ⚙ ابدأ ببيانات العقد | C3: 🧾 الانتقال إلى المستخلص الأول
B5: دليل الألوان
B6: إدخال يدوي | C6: خلايا صفراء بخط أزرق — هي الخلايا الوحيدة التي تُعدّل.
B7: معادلة محسوبة | C7: خط أسود — لا تكتب فوقها.
B8: ربط | C8: خط أخضر — قيمة مسحوبة من شيت آخر (مثل «السابق» من المستخلص الذي قبله).
B9: تنبيه | C9: تظليل أحمر: تجاوز الكمية التعاقدية، كود مكرر، تأخر عن البرنامج.
B11: خطوات العمل
B12: بيانات العقد | C12: أدخل بيانات المشروع والنسب التعاقدية (مرة واحدة).
B13: جدول الكميات | C13: أدخل بنود جدول الكميات والأسعار (حتى 100 بند).
B14: مستخلص 01 | C14: في كل مستخلص: أدخل الفترة والتواريخ والحالة والنسبة المخططة، ثم «الكمية الحالية» لكل بند، ورصيد المواد والغرامات والإفراج عن الضمان إن وجد، وبيانات التحصيل. «السابق» يُسحب آلياً من المستخلص الذي قبله، والتراكمي = السابق + الحالي.
B15: الأوامر التغييرية | C15: سجل الأوامر التغييرية واختر رقم المستخلص الذي تُدرج به.
B16: الاستقطاعات الفنية | C16: سجل الاستقطاعات الفنية برقم المستخلص، وحدد مستخلص الإفراج عند المعالجة.
B17: الموازنة والتكاليف | C17: أدخل الموازنة التقديرية لكل قسم حسب عناصر التكلفة مرة واحدة، ثم التكاليف الفعلية المباشرة لكل فترة مستخلص؛ يحسب الشيت الربح والهامش وCPI والتكلفة المتوقعة عند الإنجاز والموقف النقدي (شيت داخلي لا يُطبع مع المستخلص).
B18: سجل المستخلصات | C18: يتجمع كل شيء آلياً في السجل، ومنه ينتقل إلى ملف التقارير المجمع لكل المشاريع.
B20: التوافق مع الأنظمة السعودية
B21: ضريبة القيمة المضافة | C21: 15% (نظام ضريبة القيمة المضافة). وعاء الضريبة = صافي المستخلص بعد استرداد الدفعة المقدمة، ويشمل المحتجزات إذا فُوترت مع المستخلص، ولا تُخفضه غرامات التأخير افتراضياً — كلها قابلة للضبط في «بيانات العقد».
B22: الفاتورة الضريبية | C22: يُسجل رقم وتاريخ الفاتورة الضريبية لكل مستخلص. الفاتورة نفسها تُصدر من نظام فوترة إلكترونية متوافق مع متطلبات «فاتورة» لهيئة الزكاة والضريبة والجمارك (رمز QR والربط في المرحلة الثانية) — المستخلص ليس بديلاً عنها.
B23: الرقم الضريبي | C23: 15 رقماً يبدأ وينتهي بالرقم 3 — مع تحقق آلي من الصيغة للمقاول وصاحب العمل.
B24: الدفعة المقدمة | C24: في العقود الحكومية لا تتجاوز 10% من قيمة العقد وبمقابل ضمان بنكي مساوٍ لها، وتُسترد من المستخلصات.
B25: الضمان النهائي | C25: 5% من قيمة العقد (خطاب ضمان بنكي) مع تنبيه آلي قبل انتهاء الصلاحية بـ 30 يوماً.
B26: غرامات التأخير | C26: حد أقصى قابل للضبط (افتراضياً 10% من قيمة العقد) مع تنبيه عند تجاوزه.
B27: ضريبة الاستقطاع | C27: لا تُطبق على المقاول المقيم (0%)، وتُستخدم فقط للمدفوعات لغير المقيم وفق نظام ضريبة الدخل.
B28: المستندات النظامية | C28: قائمة تحقق لكل مستخلص: الزكاة، التأمينات الاجتماعية (GOSI)، نطاقات، السجل التجاري والغرفة، الضمانات، التأمين (CAR).
B29: التاريخ الهجري | C29: تظهر فترة كل مستخلص بالتاريخ الهجري بجوار الميلادي.
B30: تنبيه مهم | C30: النسب والحدود الافتراضية مبنية على الممارسة الشائعة؛ تُراجع مع شروط عقدك والمستشار القانوني والضريبي قبل الاعتماد.
B32: الربط مع ملف التقارير
B33: • | C33: اسم هذا الملف يجب أن يبقى «IPC_Project_01.xlsx» داخل فولدر «Project_01»، والفولدر بجوار ملف «Projects_Billing_Reports.xlsx».
B34: • | C34: بعد حفظ هذا الملف، افتح ملف التقارير واضغط «تمكين المحتوى / تحديث» ليتم سحب الأرقام الجديدة.
B35: • | C35: لا تحذف صفوفاً أو أعمدة ولا تغيّر أسماء الشيتات حتى لا ينقطع الربط.

Sheet بيانات العقد
B1: ⚙ بيانات العقد والإعدادات التعاقدية — مشروع رقم 01
B2: =IF('بيانات العقد'!$C$5="","مشروع رقم 01 — أدخل بيانات العقد",'بيانات العقد'!$C$5&" | عقد رقم: "&'بيانات العقد'!$C$6)&" | المبالغ بـ "&'بيانات العقد'!$C$14
B3: 🗂 سجل المستخلصات | C3: 📋 جدول الكميات | D3: 🔁 التغييرية | F3: ✂ الاستقطاعات | G3: 💰 الموازنة | H3: 🧾 مستخلص 01
B4: البيان | C4: القيمة | D4: ملاحظات / الأساس التعاقدي | F4: القوائم المنسدلة (قابلة للتعديل)
B5: اسم المشروع | C5: مشروع إنشاء مبنى إداري - الرياض | D5: يظهر في جميع الشيتات وفي ملف التقارير المجمع | F5: أقسام الأعمال | G5: حالة المستخلص | H5: حالة الأمر التغييري | I5: نوع الاستقطاع الفني
B6: رقم العقد | C6: CT-2026-014 | F6: أعمال الحفر والردم | G6: مسودة | H6: معتمد | I6: أعمال غير مطابقة
B7: صاحب العمل (المالك) | C7: شركة رؤية للتطوير العقاري | F7: الخرسانة العادية والمسلحة | G7: مقدم للاستشاري | H7: قيد الدراسة | I7: أعمال ناقصة
B8: الاستشاري / المهندس | C8: مكتب البنيان للاستشارات الهندسية | F8: أعمال المباني | G8: تحت المراجعة | H8: مرفوض | I8: ملاحظات فنية
B9: المقاول | C9: شركة البناء الحديث للمقاولات | F9: أعمال العزل | G9: معتمد | I9: اختبارات غير مستكملة
B10: تاريخ توقيع العقد | C10: 46068 | F10: أعمال التشطيبات | G10: مرفوض | I10: مستندات غير مستكملة
B11: تاريخ بدء الأعمال (أمر المباشرة) | C11: 46082 | D11: بداية احتساب المدة الزمنية | F11: الأعمال الكهربائية | I11: أخرى
B12: مدة العقد (بالشهور) | C12: 18 | F12: الأعمال الصحية
B13: تاريخ الانتهاء التعاقدي | C13: =IF(OR(C11="",C12=""),"",EDATE(C11,C12)-1) | D13: محسوب = البدء + المدة | F13: أعمال التكييف
B14: العملة | C14: ريال سعودي | F14: أعمال الموقع العام
B15: القيم التعاقدية
B16: قيمة العقد الأصلية | C16: ='جدول الكميات'!H106 | D16: مرتبطة تلقائياً بإجمالي جدول الكميات
B17: صافي الأوامر التغييرية المعتمدة | C17: =SUMIFS('الأوامر التغييرية'!$G$6:$G$55,'الأوامر التغييرية'!$H$6:$H$55,"معتمد") | D17: مرتبطة بشيت الأوامر التغييرية (المعتمدة فقط)
B18: قيمة العقد المعدلة | C18: =C16+C17 | D18: الأصلية + صافي التغييرية المعتمدة
B19: الدفعة المقدمة واستردادها
B20: نسبة الدفعة المقدمة | C20: 0.1 | D20: من قيمة العقد الأصلية — في العقود الحكومية لا تتجاوز 10% وبمقابل ضمان بنكي مساوٍ لها
B21: قيمة الدفعة المقدمة | C21: =C16*C20 | D21: محسوبة
B22: تاريخ صرف الدفعة المقدمة | C22: 46091 | D22: تُصدر عنها فاتورة ضريبية عند الاستلام، ويُخفض الاسترداد وعاء الضريبة في المستخلصات التالية
B23: نسبة الاسترداد من قيمة الأعمال | C23: 0.125 | D23: تُخصم من كل مستخلص كنسبة من (الأعمال المنفذة + التغييرية)
B24: بدء الاسترداد عند نسبة إنجاز | C24: 0 | D24: مثال FIDIC: يبدأ الاسترداد بعد تجاوز 10% من قيمة العقد
B25: استرداد كامل الرصيد عند نسبة إنجاز | C25: 0.8 | D25: عند بلوغ هذه النسبة يُسترد كامل الرصيد المتبقي
B26: ضمان الأعمال
B27: نسبة ضمان الأعمال (المحتجزات) | C27: 0.1 | D27: تُحتجز من إجمالي قيمة الأعمال التراكمية
B28: الحد الأقصى للضمان (% من العقد المعدل) | C28: 0.05 | D28: يتوقف الاحتجاز عند بلوغ الحد
B29: الحد الأقصى للضمان (قيمة) | C29: =C18*C28 | D29: محسوب
B30: الضرائب (هيئة الزكاة والضريبة والجمارك)
B31: نسبة ضريبة القيمة المضافة | C31: 0.15 | D31: 15% وفق نظام ضريبة القيمة المضافة في المملكة (منذ يوليو 2020)
B32: احتساب الضريبة قبل خصم الضمان؟ | C32: نعم | D32: نعم: الفاتورة الضريبية تصدر بكامل قيمة المستخلص شاملة المحتجزات — لا: تُفوتر المحتجزات وتُحتسب ضريبتها عند الإفراج
B33: نسبة ضريبة الاستقطاع (للمقاول غير المقيم فقط) | C33: 0 | D33: 0% للمقاول المقيم بالمملكة — تُطبق فقط على المدفوعات لغير المقيم وفق نظام ضريبة الدخل
B34: خصم الغرامات من وعاء ض.ق.م؟ | C34: لا | D34: لا: غرامات التأخير تعويض وليست تخفيضاً لقيمة التوريد فلا تُخفض وعاء الضريبة (راجع مستشارك الضريبي)
B35: البيانات النظامية والضمانات البنكية (المملكة العربية السعودية)
B36: نوع العقد | C36: خاص - FIDIC | D36: يحدد المرجعية: نظام المنافسات والمشتريات الحكومية ولائحته التنفيذية أو شروط العقد الخاص (FIDIC)
B37: الرقم الضريبي للمقاول | C37: 310123456700003 | D37: 15 رقماً يبدأ وينتهي بالرقم 3 (يظهر في الفاتورة الضريبية)
B38: السجل التجاري للمقاول | C38: 1010123456
B39: الرقم الضريبي لصاحب العمل | C39: 300987654300003 | D39: مطلوب في الفاتورة الضريبية بين المنشآت (B2B)
B40: نسبة الضمان النهائي | C40: 0.05 | D40: خطاب ضمان بنكي — 5% من قيمة العقد في العقود الحكومية (أو حسب العقد)
...

Sheet جدول الكميات
A1: 📋 جدول الكميات والأسعار التعاقدي (BOQ)
A2: =IF('بيانات العقد'!$C$5="","مشروع رقم 01 — أدخل بيانات العقد",'بيانات العقد'!$C$5&" | عقد رقم: "&'بيانات العقد'!$C$6)&" | المبالغ بـ "&'بيانات العقد'!$C$14
A3: 🗂 سجل المستخلصات | B3: ⚙ بيانات العقد | C3: 🔁 التغييرية | D3: ✂ الاستقطاعات | F3: 💰 الموازنة | G3: 🧾 مستخلص 01
A4: أدخل بنود العقد في الخلايا الصفراء فقط (حتى 100 بند) — الإجمالي يغذي قيمة العقد وكل المستخلصات تلقائياً.
A5: م | B5: كود البند | C5: القسم | D5: وصف البند | E5: الوحدة | F5: الكمية التعاقدية | G5: سعر الوحدة | H5: الإجمالي | I5: الوزن النسبي
A6: =IF(B6="","",COUNTA($B$6:B6)) | B6: 01-001 | C6: أعمال الحفر والردم | D6: حفر عام للأساسات حتى المنسوب التصميمي مع نقل الناتج خارج الموقع | E6: م3 | F6: 4500 | G6: 25 | H6: =F6*G6 | I6: =IF($H$106>0,H6/$H$106,0)
A7: =IF(B7="","",COUNTA($B$6:B7)) | B7: 01-002 | C7: أعمال الحفر والردم | D7: ردم بالتربة المختارة على طبقات مع الدمك حتى 95% بروكتور معدل | E7: م3 | F7: 2200 | G7: 18 | H7: =F7*G7 | I7: =IF($H$106>0,H7/$H$106,0)
A8: =IF(B8="","",COUNTA($B$6:B8)) | B8: 01-003 | C8: أعمال الحفر والردم | D8: إحلال تربة بمواد مختارة (Sub-base) مع الدمك والاختبارات | E8: م3 | F8: 1800 | G8: 75 | H8: =F8*G8 | I8: =IF($H$106>0,H8/$H$106,0)
A9: =IF(B9="","",COUNTA($B$6:B9)) | B9: 02-001 | C9: الخرسانة العادية والمسلحة | D9: خرسانة عادية للنظافة قوة 20 ميجا باسكال | E9: م3 | F9: 380 | G9: 380 | H9: =F9*G9 | I9: =IF($H$106>0,H9/$H$106,0)
A10: =IF(B10="","",COUNTA($B$6:B10)) | B10: 02-002 | C10: الخرسانة العادية والمسلحة | D10: خرسانة مسلحة للقواعد والميد قوة 35 ميجا باسكال (بدون حديد) | E10: م3 | F10: 950 | G10: 950 | H10: =F10*G10 | I10: =IF($H$106>0,H10/$H$106,0)
A11: =IF(B11="","",COUNTA($B$6:B11)) | B11: 02-003 | C11: الخرسانة العادية والمسلحة | D11: خرسانة مسلحة للأعمدة والجدران الخرسانية قوة 35 ميجا باسكال | E11: م3 | F11: 420 | G11: 1150 | H11: =F11*G11 | I11: =IF($H$106>0,H11/$H$106,0)
A12: =IF(B12="","",COUNTA($B$6:B12)) | B12: 02-004 | C12: الخرسانة العادية والمسلحة | D12: خرسانة مسلحة للأسقف والكمرات والدرج قوة 35 ميجا باسكال | E12: م3 | F12: 1650 | G12: 1050 | H12: =F12*G12 | I12: =IF($H$106>0,H12/$H$106,0)
A13: =IF(B13="","",COUNTA($B$6:B13)) | B13: 02-005 | C13: الخرسانة العادية والمسلحة | D13: توريد وتركيب حديد تسليح عالي المقاومة (مطابق للمواصفات السعودية) | E13: طن | F13: 480 | G13: 3400 | H13: =F13*G13 | I13: =IF($H$106>0,H13/$H$106,0)
A14: =IF(B14="","",COUNTA($B$6:B14)) | B14: 03-001 | C14: أعمال المباني | D14: مباني بلوك أسمنتي مصمت سماكة 20 سم | E14: م2 | F14: 7800 | G14: 75 | H14: =F14*G14 | I14: =IF($H$106>0,H14/$H$106,0)
A15: =IF(B15="","",COUNTA($B$6:B15)) | B15: 03-002 | C15: أعمال المباني | D15: مباني بلوك أسمنتي سماكة 15 سم للقواطع | E15: م2 | F15: 3600 | G15: 60 | H15: =F15*G15 | I15: =IF($H$106>0,H15/$H$106,0)
A16: =IF(B16="","",COUNTA($B$6:B16)) | B16: 04-001 | C16: أعمال العزل | D16: عزل مائي للأساسات بالبيتومين على وجهين | E16: م2 | F16: 2400 | G16: 30 | H16: =F16*G16 | I16: =IF($H$106>0,H16/$H$106,0)
A17: =IF(B17="","",COUNTA($B$6:B17)) | B17: 04-002 | C17: أعمال العزل | D17: عزل مائي وحراري للأسطح بالممبرين والبوليسترين | E17: م2 | F17: 1900 | G17: 120 | H17: =F17*G17 | I17: =IF($H$106>0,H17/$H$106,0)
... A35: =IF(B35="","",COUNTA($B$6:B35)) | B35: 09-002 | C35: أعمال الموقع العام | D35: أعمال بلاط متداخل (إنترلوك) سماكة 8 سم | E35: م2 | F35: 3500 | G35: 70 | H35: =F35*G35 | I35: =IF($H$106>0,H35/$H$106,0)
A36: =IF(B36="","",COUNTA($B$6:B36)) | H36: =F36*G36 | I36: =IF($H$106>0,H36/$H$106,0)
A37: =IF(B37="","",COUNTA($B$6:B37)) | H37: =F37*G37 | I37: =IF($H$106>0,H37/$H$106,0)
A38: =IF(B38="","",COUNTA($B$6:B38)) | H38: =F38*G38 | I38: =IF($H$106>0,H38/$H$106,0)
A39: =IF(B39="","",COUNTA($B$6:B39)) | H39: =F39*G39 | I39: =IF($H$106>0,H39/$H$106,0)
A40: =IF(B40="","",COUNTA($B$6:B40)) | H40: =F40*G40 | I40: =IF($H$106>0,H40/$H$106,0)
A41: =IF(B41="","",COUNTA($B$6:B41)) | H41: =F41*G41 | I41: =IF($H$106>0,H41/$H$106,0)
A42: =IF(B42="","",COUNTA($B$6:B42)) | H42: =F42*G42 | I42: =IF($H$106>0,H42/$H$106,0)
A43: =IF(B43="","",COUNTA($B$6:B43)) | H43: =F43*G43 | I43: =IF($H$106>0,H43/$H$106,0)
A44: =IF(B44="","",COUNTA($B$6:B44)) | H44: =F44*G44 | I44: =IF($H$106>0,H44/$H$106,0)
A45: =IF(B45="","",COUNTA($B$6:B45)) | H45: =F45*G45 | I45: =IF($H$106>0,H45/$H$106,0)
A46: =IF(B46="","",COUNTA($B$6:B46)) | H46: =F46*G46 | I46: =IF($H$106>0,H46/$H$106,0)
A47: =IF(B47="","",COUNTA($B$6:B47)) | H47: =F47*G47 | I47: =IF($H$106>0,H47/$H$106,0)
... A105: =IF(B105="","",COUNTA($B$6:B105)) | H105: =F105*G105 | I105: =IF($H$106>0,H105/$H$106,0)
A106: إجمالي قيمة العقد الأصلية | H106: =SUM(H6:H105) | I106: =SUM(I6:I105)

Sheet الأوامر التغييرية
A1: 🔁 سجل الأوامر التغييرية (Variation Orders)
A2: =IF('بيانات العقد'!$C$5="","مشروع رقم 01 — أدخل بيانات العقد",'بيانات العقد'!$C$5&" | عقد رقم: "&'بيانات العقد'!$C$6)&" | المبالغ بـ "&'بيانات العقد'!$C$14
A3: 🗂 سجل المستخلصات | B3: ⚙ بيانات العقد | C3: 📋 جدول الكميات | D3: ✂ الاستقطاعات | F3: 💰 الموازنة | G3: 🧾 مستخلص 01
A4: «قيمة الأمر» تعدّل قيمة العقد عند الاعتماد — «القيمة المدرجة» تُصرف في المستخلص المحدد (للصرف على دفعات: كرر الأمر في سطر جديد بقيمة أمر = 0 ومستخلص مختلف).
A5: م | B5: رقم الأمر | C5: تاريخ الأمر | D5: وصف الأمر التغييري | E5: النوع | F5: قيمة الأمر | G5: الأثر على العقد (±) | H5: الحالة | I5: القيمة المدرجة بالمستخلص | J5: الأثر على المستخلص (±) | K5: رقم المستخلص المدرج به | L5: ملاحظات
A6: =IF(B6="","",COUNTA($B$6:B6)) | B6: VO-01 | C6: 46160 | D6: إضافة غرفة محولات ولوحة جهد متوسط خارجية | E6: إضافة | F6: 250000 | G6: =IF(E6="خصم",-1,1)*N(F6) | H6: معتمد | I6: 250000 | J6: =IF(E6="خصم",-1,1)*N(I6) | K6: 4
A7: =IF(B7="","",COUNTA($B$6:B7)) | B7: VO-02 | C7: 46205 | D7: تعديل مواصفة البورسلين بموافقة المالك | E7: خصم | F7: 64000 | G7: =IF(E7="خصم",-1,1)*N(F7) | H7: معتمد | I7: 64000 | J7: =IF(E7="خصم",-1,1)*N(I7) | K7: 5
A8: =IF(B8="","",COUNTA($B$6:B8)) | B8: VO-03 | C8: 46259 | D8: أعمال تنسيق موقع وزراعة إضافية | E8: إضافة | F8: 180000 | G8: =IF(E8="خصم",-1,1)*N(F8) | H8: قيد الدراسة | J8: =IF(E8="خصم",-1,1)*N(I8)
A9: =IF(B9="","",COUNTA($B$6:B9)) | G9: =IF(E9="خصم",-1,1)*N(F9) | J9: =IF(E9="خصم",-1,1)*N(I9)
A10: =IF(B10="","",COUNTA($B$6:B10)) | G10: =IF(E10="خصم",-1,1)*N(F10) | J10: =IF(E10="خصم",-1,1)*N(I10)
A11: =IF(B11="","",COUNTA($B$6:B11)) | G11: =IF(E11="خصم",-1,1)*N(F11) | J11: =IF(E11="خصم",-1,1)*N(I11)
A12: =IF(B12="","",COUNTA($B$6:B12)) | G12: =IF(E12="خصم",-1,1)*N(F12) | J12: =IF(E12="خصم",-1,1)*N(I12)
A13: =IF(B13="","",COUNTA($B$6:B13)) | G13: =IF(E13="خصم",-1,1)*N(F13) | J13: =IF(E13="خصم",-1,1)*N(I13)
A14: =IF(B14="","",COUNTA($B$6:B14)) | G14: =IF(E14="خصم",-1,1)*N(F14) | J14: =IF(E14="خصم",-1,1)*N(I14)
A15: =IF(B15="","",COUNTA($B$6:B15)) | G15: =IF(E15="خصم",-1,1)*N(F15) | J15: =IF(E15="خصم",-1,1)*N(I15)
A16: =IF(B16="","",COUNTA($B$6:B16)) | G16: =IF(E16="خصم",-1,1)*N(F16) | J16: =IF(E16="خصم",-1,1)*N(I16)
A17: =IF(B17="","",COUNTA($B$6:B17)) | G17: =IF(E17="خصم",-1,1)*N(F17) | J17: =IF(E17="خصم",-1,1)*N(I17)
A18: =IF(B18="","",COUNTA($B$6:B18)) | G18: =IF(E18="خصم",-1,1)*N(F18) | J18: =IF(E18="خصم",-1,1)*N(I18)
A19: =IF(B19="","",COUNTA($B$6:B19)) | G19: =IF(E19="خصم",-1,1)*N(F19) | J19: =IF(E19="خصم",-1,1)*N(I19)
A20: =IF(B20="","",COUNTA($B$6:B20)) | G20: =IF(E20="خصم",-1,1)*N(F20) | J20: =IF(E20="خصم",-1,1)*N(I20)
... A55: =IF(B55="","",COUNTA($B$6:B55)) | G55: =IF(E55="خصم",-1,1)*N(F55) | J55: =IF(E55="خصم",-1,1)*N(I55)
A56: الإجمالي | F56: =SUM(F6:F55) | G56: =SUM(G6:G55) | H56: ="معتمد: "&COUNTIF(H6:H55,"معتمد") | I56: =SUM(I6:I55) | J56: =SUM(J6:J55)

Sheet الاستقطاعات الفنية
A1: ✂ سجل الاستقطاعات الفنية (Technical Deductions)
A2: =IF('بيانات العقد'!$C$5="","مشروع رقم 01 — أدخل بيانات العقد",'بيانات العقد'!$C$5&" | عقد رقم: "&'بيانات العقد'!$C$6)&" | المبالغ بـ "&'بيانات العقد'!$C$14
A3: 🗂 سجل المستخلصات | B3: ⚙ بيانات العقد | C3: 📋 جدول الكميات | D3: 🔁 التغييرية | F3: 💰 الموازنة | G3: 🧾 مستخلص 01
A4: يُخصم المبلغ من المستخلص المحدد ويستمر محتجزاً تراكمياً حتى يتم الإفراج عنه في «مستخلص الإفراج».
A5: م | B5: رقم الاستقطاع | C5: التاريخ | D5: رقم المستخلص | E5: كود البند | F5: وصف البند (آلي) | G5: سبب الاستقطاع | H5: نوع الاستقطاع | I5: المبلغ المستقطع | J5: تم الإفراج؟ | K5: مستخلص الإفراج | L5: الرصيد المحتجز | M5: ملاحظات
A6: =IF(B6="","",COUNTA($B$6:B6)) | B6: TD-01 | C6: 46145 | D6: 2 | E6: 02-002 | F6: =IF(E6="","",IFERROR(INDEX('جدول الكميات'!$D$6:$D$105,MATCH(E6,'جدول الكميات'!$B$6:$B$105,0)),"⚠ كود غير موجود")) | G6: تعشيش في خرسانة بعض القواعد يلزم معالجته | H6: أعمال غير مطابقة | I6: 17000 | J6: نعم | K6: 4 | L6: =IF(J6="نعم",0,N(I6))
A7: =IF(B7="","",COUNTA($B$6:B7)) | B7: TD-02 | C7: 46177 | D7: 3 | E7: 04-001 | F7: =IF(E7="","",IFERROR(INDEX('جدول الكميات'!$D$6:$D$105,MATCH(E7,'جدول الكميات'!$B$6:$B$105,0)),"⚠ كود غير موجود")) | G7: عدم تقديم نتائج اختبار التصاق العزل | H7: اختبارات غير مستكملة | I7: 8000 | J7: لا | L7: =IF(J7="نعم",0,N(I7))
A8: =IF(B8="","",COUNTA($B$6:B8)) | B8: TD-03 | C8: 46238 | D8: 5 | E8: 02-004 | F8: =IF(E8="","",IFERROR(INDEX('جدول الكميات'!$D$6:$D$105,MATCH(E8,'جدول الكميات'!$B$6:$B$105,0)),"⚠ كود غير موجود")) | G8: ملاحظات على استواء أسطح بلاطات الدور الأول | H8: ملاحظات فنية | I8: 24000 | J8: لا | L8: =IF(J8="نعم",0,N(I8))
A9: =IF(B9="","",COUNTA($B$6:B9)) | B9: TD-04 | C9: 46268 | D9: 6 | E9: 03-001 | F9: =IF(E9="","",IFERROR(INDEX('جدول الكميات'!$D$6:$D$105,MATCH(E9,'جدول الكميات'!$B$6:$B$105,0)),"⚠ كود غير موجود")) | G9: مباني بلوك غير مطابقة للمواصفات (عدم ضبط الرأسية) | H9: أعمال غير مطابقة | I9: 13000 | J9: لا | L9: =IF(J9="نعم",0,N(I9))
A10: =IF(B10="","",COUNTA($B$6:B10)) | F10: =IF(E10="","",IFERROR(INDEX('جدول الكميات'!$D$6:$D$105,MATCH(E10,'جدول الكميات'!$B$6:$B$105,0)),"⚠ كود غير موجود")) | L10: =IF(J10="نعم",0,N(I10))
A11: =IF(B11="","",COUNTA($B$6:B11)) | F11: =IF(E11="","",IFERROR(INDEX('جدول الكميات'!$D$6:$D$105,MATCH(E11,'جدول الكميات'!$B$6:$B$105,0)),"⚠ كود غير موجود")) | L11: =IF(J11="نعم",0,N(I11))
A12: =IF(B12="","",COUNTA($B$6:B12)) | F12: =IF(E12="","",IFERROR(INDEX('جدول الكميات'!$D$6:$D$105,MATCH(E12,'جدول الكميات'!$B$6:$B$105,0)),"⚠ كود غير موجود")) | L12: =IF(J12="نعم",0,N(I12))
A13: =IF(B13="","",COUNTA($B$6:B13)) | F13: =IF(E13="","",IFERROR(INDEX('جدول الكميات'!$D$6:$D$105,MATCH(E13,'جدول الكميات'!$B$6:$B$105,0)),"⚠ كود غير موجود")) | L13: =IF(J13="نعم",0,N(I13))
A14: =IF(B14="","",COUNTA($B$6:B14)) | F14: =IF(E14="","",IFERROR(INDEX('جدول الكميات'!$D$6:$D$105,MATCH(E14,'جدول الكميات'!$B$6:$B$105,0)),"⚠ كود غير موجود")) | L14: =IF(J14="نعم",0,N(I14))
A15: =IF(B15="","",COUNTA($B$6:B15)) | F15: =IF(E15="","",IFERROR(INDEX('جدول الكميات'!$D$6:$D$105,MATCH(E15,'جدول الكميات'!$B$6:$B$105,0)),"⚠ كود غير موجود")) | L15: =IF(J15="نعم",0,N(I15))
A16: =IF(B16="","",COUNTA($B$6:B16)) | F16: =IF(E16="","",IFERROR(INDEX('جدول الكميات'!$D$6:$D$105,MATCH(E16,'جدول الكميات'!$B$6:$B$105,0)),"⚠ كود غير موجود")) | L16: =IF(J16="نعم",0,N(I16))
A17: =IF(B17="","",COUNTA($B$6:B17)) | F17: =IF(E17="","",IFERROR(INDEX('جدول الكميات'!$D$6:$D$105,MATCH(E17,'جدول الكميات'!$B$6:$B$105,0)),"⚠ كود غير موجود")) | L17: =IF(J17="نعم",0,N(I17))
A18: =IF(B18="","",COUNTA($B$6:B18)) | F18: =IF(E18="","",IFERROR(INDEX('جدول الكميات'!$D$6:$D$105,MATCH(E18,'جدول الكميات'!$B$6:$B$105,0)),"⚠ كود غير موجود")) | L18: =IF(J18="نعم",0,N(I18))
A19: =IF(B19="","",COUNTA($B$6:B19)) | F19: =IF(E19="","",IFERROR(INDEX('جدول الكميات'!$D$6:$D$105,MATCH(E19,'جدول الكميات'!$B$6:$B$105,0)),"⚠ كود غير موجود")) | L19: =IF(J19="نعم",0,N(I19))
A20: =IF(B20="","",COUNTA($B$6:B20)) | F20: =IF(E20="","",IFERROR(INDEX('جدول الكميات'!$D$6:$D$105,MATCH(E20,'جدول الكميات'!$B$6:$B$105,0)),"⚠ كود غير موجود")) | L20: =IF(J20="نعم",0,N(I20))
A21: =IF(B21="","",COUNTA($B$6:B21)) | F21: =IF(E21="","",IFERROR(INDEX('جدول الكميات'!$D$6:$D$105,MATCH(E21,'جدول الكميات'!$B$6:$B$105,0)),"⚠ كود غير موجود")) | L21: =IF(J21="نعم",0,N(I21))
... A105: =IF(B105="","",COUNTA($B$6:B105)) | F105: =IF(E105="","",IFERROR(INDEX('جدول الكميات'!$D$6:$D$105,MATCH(E105,'جدول الكميات'!$B$6:$B$105,0)),"⚠ كود غير موجود")) | L105: =IF(J105="نعم",0,N(I105))
A106: الإجمالي | I106: =SUM(I6:I105) | J106: =I106-L106 | L106: =SUM(L6:L105)

Sheet الموازنة والتكاليف
B1: 💰 الموازنة التقديرية والتكاليف الفعلية والربحية (Budget & Cost Control) — داخلي
B2: =IF('بيانات العقد'!$C$5="","مشروع رقم 01 — أدخل بيانات العقد",'بيانات العقد'!$C$5&" | عقد رقم: "&'بيانات العقد'!$C$6)&" | المبالغ بـ "&'بيانات العقد'!$C$14
B3: 🗂 سجل المستخلصات | C3: ⚙ بيانات العقد | D3: 📋 جدول الكميات | F3: 🔁 التغييرية | G3: ✂ الاستقطاعات | H3: 🧾 مستخلص 01
B5: إعدادات الموازنة
B6: نسبة المصروفات العمومية والإدارية (من التكلفة المباشرة) | E6: 0.06 | F6: تُحمّل على الموازنة وعلى التكلفة الفعلية لكل مستخلص
B7: نسبة احتياطي الطوارئ (من التكلفة المباشرة) | E7: 0.03 | F7: تُضاف للموازنة فقط
B8: نسبة الربح المستهدفة من الإدارة | E8: 0.12 | F8: للمقارنة مع الربح المخطط والفعلي
B9: أولاً: الموازنة التقديرية حسب أقسام الأعمال وعناصر التكلفة (إدخال)
B10: القسم | D10: القيمة التعاقدية للقسم | E10: المواد | F10: العمالة | G10: مقاولو الباطن | H10: المعدات | I10: مصروفات الموقع | J10: إجمالي التكلفة المباشرة | K10: الربح المباشر للقسم | L10: هامش القسم
B11: =IF('بيانات العقد'!F6="","",'بيانات العقد'!F6) | D11: =IF(B11="",0,SUMIF('جدول الكميات'!$C$6:$C$105,B11,'جدول الكميات'!$H$6:$H$105)) | E11: 33600 | F11: 33600 | G11: 44800 | H11: 100800 | I11: 11200 | J11: =SUM(E11:I11) | K11: =D11-J11 | L11: =IF(D11>0,K11/D11,0)
B12: =IF('بيانات العقد'!F7="","",'بيانات العقد'!F7) | D12: =IF(B12="",0,SUMIF('جدول الكميات'!$C$6:$C$105,B12,'جدول الكميات'!$H$6:$H$105)) | E12: 2153500 | F12: 783100 | G12: 391600 | H12: 391600 | I12: 195800 | J12: =SUM(E12:I12) | K12: =D12-J12 | L12: =IF(D12>0,K12/D12,0)
B13: =IF('بيانات العقد'!F8="","",'بيانات العقد'!F8) | D13: =IF(B13="",0,SUMIF('جدول الكميات'!$C$6:$C$105,B13,'جدول الكميات'!$H$6:$H$105)) | E13: 328400 | F13: 229900 | G13: 32800 | H13: 19700 | I13: 46000 | J13: =SUM(E13:I13) | K13: =D13-J13 | L13: =IF(D13>0,K13/D13,0)
B14: =IF('بيانات العقد'!F9="","",'بيانات العقد'!F9) | D14: =IF(B14="",0,SUMIF('جدول الكميات'!$C$6:$C$105,B14,'جدول الكميات'!$H$6:$H$105)) | E14: 117000 | F14: 46800 | G14: 58500 | I14: 11700 | J14: =SUM(E14:I14) | K14: =D14-J14 | L14: =IF(D14>0,K14/D14,0)
B15: =IF('بيانات العقد'!F10="","",'بيانات العقد'!F10) | D15: =IF(B15="",0,SUMIF('جدول الكميات'!$C$6:$C$105,B15,'جدول الكميات'!$H$6:$H$105)) | E15: 1664600 | F15: 832300 | G15: 599300 | H15: 66600 | I15: 166500 | J15: =SUM(E15:I15) | K15: =D15-J15 | L15: =IF(D15>0,K15/D15,0)
B16: =IF('بيانات العقد'!F11="","",'بيانات العقد'!F11) | D16: =IF(B16="",0,SUMIF('جدول الكميات'!$C$6:$C$105,B16,'جدول الكميات'!$H$6:$H$105)) | E16: 400200 | F16: 100000 | G16: 450200 | I16: 50000 | J16: =SUM(E16:I16) | K16: =D16-J16 | L16: =IF(D16>0,K16/D16,0)
B17: =IF('بيانات العقد'!F12="","",'بيانات العقد'!F12) | D17: =IF(B17="",0,SUMIF('جدول الكميات'!$C$6:$C$105,B17,'جدول الكميات'!$H$6:$H$105)) | E17: 165300 | F17: 41300 | G17: 186000 | I17: 20700 | J17: =SUM(E17:I17) | K17: =D17-J17 | L17: =IF(D17>0,K17/D17,0)
B18: =IF('بيانات العقد'!F13="","",'بيانات العقد'!F13) | D18: =IF(B18="",0,SUMIF('جدول الكميات'!$C$6:$C$105,B18,'جدول الكميات'!$H$6:$H$105)) | E18: 387400 | F18: 43000 | G18: 387400 | I18: 43000 | J18: =SUM(E18:I18) | K18: =D18-J18 | L18: =IF(D18>0,K18/D18,0)
B19: =IF('بيانات العقد'!F14="","",'بيانات العقد'!F14) | D19: =IF(B19="",0,SUMIF('جدول الكميات'!$C$6:$C$105,B19,'جدول الكميات'!$H$6:$H$105)) | E19: 113800 | F19: 56900 | G19: 56900 | H19: 42700 | I19: 14200 | J19: =SUM(E19:I19) | K19: =D19-J19 | L19: =IF(D19>0,K19/D19,0)
B20: =IF('بيانات العقد'!F15="","",'بيانات العقد'!F15) | D20: =IF(B20="",0,SUMIF('جدول الكميات'!$C$6:$C$105,B20,'جدول الكميات'!$H$6:$H$105)) | J20: =SUM(E20:I20) | K20: =D20-J20 | L20: =IF(D20>0,K20/D20,0)
B21: =IF('بيانات العقد'!F16="","",'بيانات العقد'!F16) | D21: =IF(B21="",0,SUMIF('جدول الكميات'!$C$6:$C$105,B21,'جدول الكميات'!$H$6:$H$105)) | J21: =SUM(E21:I21) | K21: =D21-J21 | L21: =IF(D21>0,K21/D21,0)
B22: =IF('بيانات العقد'!F17="","",'بيانات العقد'!F17) | D22: =IF(B22="",0,SUMIF('جدول الكميات'!$C$6:$C$105,B22,'جدول الكميات'!$H$6:$H$105)) | J22: =SUM(E22:I22) | K22: =D22-J22 | L22: =IF(D22>0,K22/D22,0)
B23: إجمالي التكلفة المباشرة | D23: =SUM(D11:D22) | E23: =SUM(E11:E22) | F23: =SUM(F11:F22) | G23: =SUM(G11:G22) | H23: =SUM(H11:H22) | I23: =SUM(I11:I22) | J23: =SUM(J11:J22)
B24: يُضاف: المصروفات العمومية والإدارية | J24: =ROUND(J23*GAPct,2)
B25: يُضاف: احتياطي الطوارئ | J25: =ROUND(J23*ContPct,2)
B26: إجمالي الموازنة عند الإنجاز (BAC) | J26: =SUM(J23:J25)
B27: الربح المخطط (قيمة العقد الأصلية − الموازنة) | J27: =D23-J26 | K27: =IF(D23>0,J27/D23,0) | L27: =IF(J26=0,"",IF(K27>=$E$8,"✔ يحقق المستهدف","⚠ أقل من المستهدف"))
B29: ثانياً: التكاليف الفعلية لكل فترة مستخلص (إدخال التكاليف المباشرة) والربحية والقيمة المكتسبة
B30: رقم المستخلص | C30: الفترة إلى | D30: المواد | E30: العمالة | F30: مقاولو الباطن | G30: المعدات | H30: مصروفات الموقع | I30: مصروفات عمومية (محسوبة) | J30: إجمالي تكلفة الفترة | K30: التكلفة التراكمية | L30: الإيراد التراكمي (إجمالي قيمة الأعمال) | M30: الربح التراكمي | N30: هامش الربح | O30: القيمة المكتسبة بالتكلفة (EV) | P30: مؤشر أداء التكلفة CPI | Q30: التكلفة المتوقعة عند الإنجاز EAC | R30: الربح المتوقع عند الإنجاز | S30: الموقف النقدي (محصل + مقدمة − تكلفة)
B31: 1 | C31: =IF('سجل المستخلصات'!C6="","",'سجل المستخلصات'!C6) | D31: 65629.71 | E31: 26499.01 | F31: 27000.76 | G31: 7632.7 | H31: 6837.14 | I31: =ROUND(SUM(D31:H31)*GAPct,2) | J31: =SUM(D31:I31) | K31: =IF(AND(C31="",J31=0),"",SUM($J$31:J31)) | L31: =IF(C31="","",N('سجل المستخلصات'!K6)) | M31: =IF(OR(L31="",K31=""),"",L31-K31) | N31: =IF(OR(M31="",N(L31)=0),"",M31/L31) | O31: =IF(C31="","",BAC*N('سجل المستخلصات'!L6)) | P31: =IF(OR(O31="",N(K31)=0),"",O31/K31) | Q31: =IF(P31="","",IF(P31>0,BAC/P31,BAC)) | R31: =IF(Q31="","",RevisedContract-Q31) | S31: =IF(C31="","",SUMIF('سجل المستخلصات'!$A$6:$A$25,"<="&B31,'سجل المستخلصات'!$AA$6:$AA$25)+IF(AND(AdvDate<>"",N(AdvDate)<=N(C31)),AdvAmount,0)-N(K31))
B32: 2 | C32: =IF('سجل المستخلصات'!C7="","",'سجل المستخلصات'!C7) | D32: 305101.85 | E32: 123189.6 | F32: 125522.17 | G32: 35483.17 | H32: 31784.77 | I32: =ROUND(SUM(D32:H32)*GAPct,2) | J32: =SUM(D32:I32) | K32: =IF(AND(C32="",J32=0),"",SUM($J$31:J32)) | L32: =IF(C32="","",N('سجل المستخلصات'!K7)) | M32: =IF(OR(L32="",K32=""),"",L32-K32) | N32: =IF(OR(M32="",N(L32)=0),"",M32/L32) | O32: =IF(C32="","",BAC*N('سجل المستخلصات'!L7)) | P32: =IF(OR(O32="",N(K32)=0),"",O32/K32) | Q32: =IF(P32="","",IF(P32>0,BAC/P32,BAC)) | R32: =IF(Q32="","",RevisedContract-Q32) | S32: =IF(C32="","",SUMIF('سجل المستخلصات'!$A$6:$A$25,"<="&B32,'سجل المستخلصات'!$AA$6:$AA$25)+IF(AND(AdvDate<>"",N(AdvDate)<=N(C32)),AdvAmount,0)-N(K32))
B33: 3 | C33: =IF('سجل المستخلصات'!C8="","",'سجل المستخلصات'!C8) | D33: 308771.43 | E33: 124671.25 | F33: 127031.87 | G33: 35909.95 | H33: 32167.06 | I33: =ROUND(SUM(D33:H33)*GAPct,2) | J33: =SUM(D33:I33) | K33: =IF(AND(C33="",J33=0),"",SUM($J$31:J33)) | L33: =IF(C33="","",N('سجل المستخلصات'!K8)) | M33: =IF(OR(L33="",K33=""),"",L33-K33) | N33: =IF(OR(M33="",N(L33)=0),"",M33/L33) | O33: =IF(C33="","",BAC*N('سجل المستخلصات'!L8)) | P33: =IF(OR(O33="",N(K33)=0),"",O33/K33) | Q33: =IF(P33="","",IF(P33>0,BAC/P33,BAC)) | R33: =IF(Q33="","",RevisedContract-Q33) | S33: =IF(C33="","",SUMIF('سجل المستخلصات'!$A$6:$A$25,"<="&B33,'سجل المستخلصات'!$AA$6:$AA$25)+IF(AND(AdvDate<>"",N(AdvDate)<=N(C33)),AdvAmount,0)-N(K33))
B34: 4 | C34: =IF('سجل المستخلصات'!C9="","",'سجل المستخلصات'!C9) | D34: 278313.98 | E34: 112373.58 | F34: 114501.35 | G34: 32367.76 | H34: 28994.08 | I34: =ROUND(SUM(D34:H34)*GAPct,2) | J34: =SUM(D34:I34) | K34: =IF(AND(C34="",J34=0),"",SUM($J$31:J34)) | L34: =IF(C34="","",N('سجل المستخلصات'!K9)) | M34: =IF(OR(L34="",K34=""),"",L34-K34) | N34: =IF(OR(M34="",N(L34)=0),"",M34/L34) | O34: =IF(C34="","",BAC*N('سجل المستخلصات'!L9)) | P34: =IF(OR(O34="",N(K34)=0),"",O34/K34) | Q34: =IF(P34="","",IF(P34>0,BAC/P34,BAC)) | R34: =IF(Q34="","",RevisedContract-Q34) | S34: =IF(C34="","",SUMIF('سجل المستخلصات'!$A$6:$A$25,"<="&B34,'سجل المستخلصات'!$AA$6:$AA$25)+IF(AND(AdvDate<>"",N(AdvDate)<=N(C34)),AdvAmount,0)-N(K34))
B35: 5 | C35: =IF('سجل المستخلصات'!C10="","",'سجل المستخلصات'!C10) | D35: 278313.91 | E35: 112373.55 | F35: 114501.32 | G35: 32367.75 | H35: 28994.07 | I35: =ROUND(SUM(D35:H35)*GAPct,2) | J35: =SUM(D35:I35) | K35: =IF(AND(C35="",J35=0),"",SUM($J$31:J35)) | L35: =IF(C35="","",N('سجل المستخلصات'!K10)) | M35: =IF(OR(L35="",K35=""),"",L35-K35) | N35: =IF(OR(M35="",N(L35)=0),"",M35/L35) | O35: =IF(C35="","",BAC*N('سجل المستخلصات'!L10)) | P35: =IF(OR(O35="",N(K35)=0),"",O35/K35) | Q35: =IF(P35="","",IF(P35>0,BAC/P35,BAC)) | R35: =IF(Q35="","",RevisedContract-Q35) | S35: =IF(C35="","",SUMIF('سجل المستخلصات'!$A$6:$A$25,"<="&B35,'سجل المستخلصات'!$AA$6:$AA$25)+IF(AND(AdvDate<>"",N(AdvDate)<=N(C35)),AdvAmount,0)-N(K35))
B36: 6 | C36: =IF('سجل المستخلصات'!C11="","",'سجل المستخلصات'!C11) | D36: 311906.57 | E36: 125937.11 | F36: 128321.7 | G36: 36274.56 | H36: 32493.67 | I36: =ROUND(SUM(D36:H36)*GAPct,2) | J36: =SUM(D36:I36) | K36: =IF(AND(C36="",J36=0),"",SUM($J$31:J36)) | L36: =IF(C36="","",N('سجل المستخلصات'!K11)) | M36: =IF(OR(L36="",K36=""),"",L36-K36) | N36: =IF(OR(M36="",N(L36)=0),"",M36/L36) | O36: =IF(C36="","",BAC*N('سجل المستخلصات'!L11)) | P36: =IF(OR(O36="",N(K36)=0),"",O36/K36) | Q36: =IF(P36="","",IF(P36>0,BAC/P36,BAC)) | R36: =IF(Q36="","",RevisedContract-Q36) | S36: =IF(C36="","",SUMIF('سجل المستخلصات'!$A$6:$A$25,"<="&B36,'سجل المستخلصات'!$AA$6:$AA$25)+IF(AND(AdvDate<>"",N(AdvDate)<=N(C36)),AdvAmount,0)-N(K36))
B37: 7 | C37: =IF('سجل المستخلصات'!C12="","",'سجل المستخلصات'!C12) | I37: =ROUND(SUM(D37:H37)*GAPct,2) | J37: =SUM(D37:I37) | K37: =IF(AND(C37="",J37=0),"",SUM($J$31:J37)) | L37: =IF(C37="","",N('سجل المستخلصات'!K12)) | M37: =IF(OR(L37="",K37=""),"",L37-K37) | N37: =IF(OR(M37="",N(L37)=0),"",M37/L37) | O37: =IF(C37="","",BAC*N('سجل المستخلصات'!L12)) | P37: =IF(OR(O37="",N(K37)=0),"",O37/K37) | Q37: =IF(P37="","",IF(P37>0,BAC/P37,BAC)) | R37: =IF(Q37="","",RevisedContract-Q37) | S37: =IF(C37="","",SUMIF('سجل المستخلصات'!$A$6:$A$25,"<="&B37,'سجل المستخلصات'!$AA$6:$AA$25)+IF(AND(AdvDate<>"",N(AdvDate)<=N(C37)),AdvAmount,0)-N(K37))
B38: 8 | C38: =IF('سجل المستخلصات'!C13="","",'سجل المستخلصات'!C13) | I38: =ROUND(SUM(D38:H38)*GAPct,2) | J38: =SUM(D38:I38) | K38: =IF(AND(C38="",J38=0),"",SUM($J$31:J38)) | L38: =IF(C38="","",N('سجل المستخلصات'!K13)) | M38: =IF(OR(L38="",K38=""),"",L38-K38) | N38: =IF(OR(M38="",N(L38)=0),"",M38/L38) | O38: =IF(C38="","",BAC*N('سجل المستخلصات'!L13)) | P38: =IF(OR(O38="",N(K38)=0),"",O38/K38) | Q38: =IF(P38="","",IF(P38>0,BAC/P38,BAC)) | R38: =IF(Q38="","",RevisedContract-Q38) | S38: =IF(C38="","",SUMIF('سجل المستخلصات'!$A$6:$A$25,"<="&B38,'سجل المستخلصات'!$AA$6:$AA$25)+IF(AND(AdvDate<>"",N(AdvDate)<=N(C38)),AdvAmount,0)-N(K38))
B39: 9 | C39: =IF('سجل المستخلصات'!C14="","",'سجل المستخلصات'!C14) | I39: =ROUND(SUM(D39:H39)*GAPct,2) | J39: =SUM(D39:I39) | K39: =IF(AND(C39="",J39=0),"",SUM($J$31:J39)) | L39: =IF(C39="","",N('سجل المستخلصات'!K14)) | M39: =IF(OR(L39="",K39=""),"",L39-K39) | N39: =IF(OR(M39="",N(L39)=0),"",M39/L39) | O39: =IF(C39="","",BAC*N('سجل المستخلصات'!L14)) | P39: =IF(OR(O39="",N(K39)=0),"",O39/K39) | Q39: =IF(P39="","",IF(P39>0,BAC/P39,BAC)) | R39: =IF(Q39="","",RevisedContract-Q39) | S39: =IF(C39="","",SUMIF('سجل المستخلصات'!$A$6:$A$25,"<="&B39,'سجل المستخلصات'!$AA$6:$AA$25)+IF(AND(AdvDate<>"",N(AdvDate)<=N(C39)),AdvAmount,0)-N(K39))
B40: 10 | C40: =IF('سجل المستخلصات'!C15="","",'سجل المستخلصات'!C15) | I40: =ROUND(SUM(D40:H40)*GAPct,2) | J40: =SUM(D40:I40) | K40: =IF(AND(C40="",J40=0),"",SUM($J$31:J40)) | L40: =IF(C40="","",N('سجل المستخلصات'!K15)) | M40: =IF(OR(L40="",K40=""),"",L40-K40) | N40: =IF(OR(M40="",N(L40)=0),"",M40/L40) | O40: =IF(C40="","",BAC*N('سجل المستخلصات'!L15)) | P40: =IF(OR(O40="",N(K40)=0),"",O40/K40) | Q40: =IF(P40="","",IF(P40>0,BAC/P40,BAC)) | R40: =IF(Q40="","",RevisedContract-Q40) | S40: =IF(C40="","",SUMIF('سجل المستخلصات'!$A$6:$A$25,"<="&B40,'سجل المستخلصات'!$AA$6:$AA$25)+IF(AND(AdvDate<>"",N(AdvDate)<=N(C40)),AdvAmount,0)-N(K40))
B41: 11 | C41: =IF('سجل المستخلصات'!C16="","",'سجل المستخلصات'!C16) | I41: =ROUND(SUM(D41:H41)*GAPct,2) | J41: =SUM(D41:I41) | K41: =IF(AND(C41="",J41=0),"",SUM($J$31:J41)) | L41: =IF(C41="","",N('سجل المستخلصات'!K16)) | M41: =IF(OR(L41="",K41=""),"",L41-K41) | N41: =IF(OR(M41="",N(L41)=0),"",M41/L41) | O41: =IF(C41="","",BAC*N('سجل المستخلصات'!L16)) | P41: =IF(OR(O41="",N(K41)=0),"",O41/K41) | Q41: =IF(P41="","",IF(P41>0,BAC/P41,BAC)) | R41: =IF(Q41="","",RevisedContract-Q41) | S41: =IF(C41="","",SUMIF('سجل المستخلصات'!$A$6:$A$25,"<="&B41,'سجل المستخلصات'!$AA$6:$AA$25)+IF(AND(AdvDate<>"",N(AdvDate)<=N(C41)),AdvAmount,0)-N(K41))
B42: 12 | C42: =IF('سجل المستخلصات'!C17="","",'سجل المستخلصات'!C17) | I42: =ROUND(SUM(D42:H42)*GAPct,2) | J42: =SUM(D42:I42) | K42: =IF(AND(C42="",J42=0),"",SUM($J$31:J42)) | L42: =IF(C42="","",N('سجل المستخلصات'!K17)) | M42: =IF(OR(L42="",K42=""),"",L42-K42) | N42: =IF(OR(M42="",N(L42)=0),"",M42/L42) | O42: =IF(C42="","",BAC*N('سجل المستخلصات'!L17)) | P42: =IF(OR(O42="",N(K42)=0),"",O42/K42) | Q42: =IF(P42="","",IF(P42>0,BAC/P42,BAC)) | R42: =IF(Q42="","",RevisedContract-Q42) | S42: =IF(C42="","",SUMIF('سجل المستخلصات'!$A$6:$A$25,"<="&B42,'سجل المستخلصات'!$AA$6:$AA$25)+IF(AND(AdvDate<>"",N(AdvDate)<=N(C42)),AdvAmount,0)-N(K42))
...

Sheet سجل المستخلصات
A1: 🗂 سجل المستخلصات — مشروع رقم 01 (يُحدَّث آلياً من شيتات المستخلصات ويغذي ملف التقارير)
A2: =IF('بيانات العقد'!$C$5="","مشروع رقم 01 — أدخل بيانات العقد",'بيانات العقد'!$C$5&" | عقد رقم: "&'بيانات العقد'!$C$6)&" | المبالغ بـ "&'بيانات العقد'!$C$14
B3: ⚙ بيانات العقد | D3: 📋 جدول الكميات | F3: 🔁 التغييرية | H3: ✂ الاستقطاعات | J3: 💰 الموازنة | AI3: آخر مستخلص: | AJ3: =SUMPRODUCT(MAX((C6:C25<>"")*A6:A25))
A4: بيانات المستخلص | G4: قيمة الأعمال ونسب الإنجاز | O4: الاستقطاعات (تراكمي) | U4: صافي المستحق والضرائب | AA4: التحصيل | AF4: الفوترة والمستندات
A5: رقم المستخلص | B5: الفترة من | C5: الفترة إلى | D5: تاريخ التقديم | E5: تاريخ الاعتماد | F5: حالة المستخلص | G5: قيمة الأعمال المنفذة التراكمية | H5: أعمال الفترة | I5: الأوامر التغييرية التراكمية | J5: رصيد المواد بالموقع | K5: إجمالي القيمة التراكمية | L5: نسبة الإنجاز الفعلية | M5: نسبة الإنجاز المخططة | N5: الانحراف عن المخطط | O5: استرداد الدفعة المقدمة التراكمي | P5: ضمان الأعمال المحتسب | Q5: المفرج عنه من الضمان | R5: صافي الضمان المحتجز | S5: الاستقطاعات الفنية المحتجزة | T5: الغرامات والخصومات التراكمية | U5: الصافي التراكمي قبل الضرائب | V5: ضريبة القيمة المضافة | W5: ضريبة الاستقطاع (غير المقيم) | X5: صافي المستحق التراكمي | Y5: المعتمد في المستخلصات السابقة | Z5: صافي المستحق للمستخلص الحالي | AA5: المبلغ المحصل | AB5: تاريخ التحصيل | AC5: المتبقي غير المحصل | AD5: مدة التحصيل (يوم) | AE5: حالة التحصيل | AF5: رقم الفاتورة الضريبية | AG5: حالة المستندات النظامية
A6: 1 | B6: =IF(OR('مستخلص 01'!$J$7="",'مستخلص 01'!$J$6=""),"",'مستخلص 01'!$J$6) | C6: =IF('مستخلص 01'!$J$7="","",'مستخلص 01'!$J$7) | D6: =IF(OR('مستخلص 01'!$J$7="",'مستخلص 01'!$J$8=""),"",'مستخلص 01'!$J$8) | E6: =IF(OR('مستخلص 01'!$J$7="",'مستخلص 01'!$J$9=""),"",'مستخلص 01'!$J$9) | F6: =IF(OR('مستخلص 01'!$J$7="",'مستخلص 01'!$J$5=""),"",'مستخلص 01'!$J$5) | G6: =IF('مستخلص 01'!$J$7="","",'مستخلص 01'!$L$19) | H6: =IF('مستخلص 01'!$J$7="","",'مستخلص 01'!$J$19) | I6: =IF('مستخلص 01'!$J$7="","",'مستخلص 01'!$L$20) | J6: =IF('مستخلص 01'!$J$7="","",'مستخلص 01'!$L$21) | K6: =IF('مستخلص 01'!$J$7="","",'مستخلص 01'!$L$22) | L6: =IF('مستخلص 01'!$J$7="","",'مستخلص 01'!$L$6) | M6: =IF(OR('مستخلص 01'!$J$7="",'مستخلص 01'!$L$8=""),"",'مستخلص 01'!$L$8) | N6: =IF(OR('مستخلص 01'!$J$7="",M6=""),"",L6-M6) | O6: =IF('مستخلص 01'!$J$7="","",-'مستخلص 01'!$L$23) | P6: =IF('مستخلص 01'!$J$7="","",-'مستخلص 01'!$L$24) | Q6: =IF('مستخلص 01'!$J$7="","",'مستخلص 01'!$L$25) | R6: =IF('مستخلص 01'!$J$7="","",P6-Q6) | S6: =IF('مستخلص 01'!$J$7="","",-'مستخلص 01'!$L$26) | T6: =IF('مستخلص 01'!$J$7="","",-'مستخلص 01'!$L$27) | U6: =IF('مستخلص 01'!$J$7="","",'مستخلص 01'!$L$28) | V6: =IF('مستخلص 01'!$J$7="","",'مستخلص 01'!$L$29) | W6: =IF('مستخلص 01'!$J$7="","",-'مستخلص 01'!$L$30) | X6: =IF('مستخلص 01'!$J$7="","",'مستخلص 01'!$L$31) | Y6: =IF('مستخلص 01'!$J$7="","",'مستخلص 01'!$H$31) | Z6: =IF('مستخلص 01'!$J$7="","",'مستخلص 01'!$J$31) | AA6: =IF('مستخلص 01'!$J$7="","",N('مستخلص 01'!$E$15)) | AB6: =IF(OR('مستخلص 01'!$J$7="",'مستخلص 01'!$K$15=""),"",'مستخلص 01'!$K$15) | AC6: =IF('مستخلص 01'!$J$7="","",Z6-AA6) | AD6: =IF(OR(AB6="",E6=""),"",AB6-E6) | AE6: =IF('مستخلص 01'!$J$7="","",IF(N(AA6)=0,IF(E6="","⏳ بانتظار الاعتماد","✖ غير محصل"),IF(AC6<=1,"✔ محصل بالكامل","⚠ محصل جزئياً"))) | AF6: =IF(OR('مستخلص 01'!$J$7="",'مستخلص 01'!$E$16=""),"",'مستخلص 01'!$E$16) | AG6: =IF('مستخلص 01'!$J$7="","",'مستخلص 01'!$E$43)
A7: 2 | B7: =IF(OR('مستخلص 02'!$J$7="",'مستخلص 02'!$J$6=""),"",'مستخلص 02'!$J$6) | C7: =IF('مستخلص 02'!$J$7="","",'مستخلص 02'!$J$7) | D7: =IF(OR('مستخلص 02'!$J$7="",'مستخلص 02'!$J$8=""),"",'مستخلص 02'!$J$8) | E7: =IF(OR('مستخلص 02'!$J$7="",'مستخلص 02'!$J$9=""),"",'مستخلص 02'!$J$9) | F7: =IF(OR('مستخلص 02'!$J$7="",'مستخلص 02'!$J$5=""),"",'مستخلص 02'!$J$5) | G7: =IF('مستخلص 02'!$J$7="","",'مستخلص 02'!$L$19) | H7: =IF('مستخلص 02'!$J$7="","",'مستخلص 02'!$J$19) | I7: =IF('مستخلص 02'!$J$7="","",'مستخلص 02'!$L$20) | J7: =IF('مستخلص 02'!$J$7="","",'مستخلص 02'!$L$21) | K7: =IF('مستخلص 02'!$J$7="","",'مستخلص 02'!$L$22) | L7: =IF('مستخلص 02'!$J$7="","",'مستخلص 02'!$L$6) | M7: =IF(OR('مستخلص 02'!$J$7="",'مستخلص 02'!$L$8=""),"",'مستخلص 02'!$L$8) | N7: =IF(OR('مستخلص 02'!$J$7="",M7=""),"",L7-M7) | O7: =IF('مستخلص 02'!$J$7="","",-'مستخلص 02'!$L$23) | P7: =IF('مستخلص 02'!$J$7="","",-'مستخلص 02'!$L$24) | Q7: =IF('مستخلص 02'!$J$7="","",'مستخلص 02'!$L$25) | R7: =IF('مستخلص 02'!$J$7="","",P7-Q7) | S7: =IF('مستخلص 02'!$J$7="","",-'مستخلص 02'!$L$26) | T7: =IF('مستخلص 02'!$J$7="","",-'مستخلص 02'!$L$27) | U7: =IF('مستخلص 02'!$J$7="","",'مستخلص 02'!$L$28) | V7: =IF('مستخلص 02'!$J$7="","",'مستخلص 02'!$L$29) | W7: =IF('مستخلص 02'!$J$7="","",-'مستخلص 02'!$L$30) | X7: =IF('مستخلص 02'!$J$7="","",'مستخلص 02'!$L$31) | Y7: =IF('مستخلص 02'!$J$7="","",'مستخلص 02'!$H$31) | Z7: =IF('مستخلص 02'!$J$7="","",'مستخلص 02'!$J$31) | AA7: =IF('مستخلص 02'!$J$7="","",N('مستخلص 02'!$E$15)) | AB7: =IF(OR('مستخلص 02'!$J$7="",'مستخلص 02'!$K$15=""),"",'مستخلص 02'!$K$15) | AC7: =IF('مستخلص 02'!$J$7="","",Z7-AA7) | AD7: =IF(OR(AB7="",E7=""),"",AB7-E7) | AE7: =IF('مستخلص 02'!$J$7="","",IF(N(AA7)=0,IF(E7="","⏳ بانتظار الاعتماد","✖ غير محصل"),IF(AC7<=1,"✔ محصل بالكامل","⚠ محصل جزئياً"))) | AF7: =IF(OR('مستخلص 02'!$J$7="",'مستخلص 02'!$E$16=""),"",'مستخلص 02'!$E$16) | AG7: =IF('مستخلص 02'!$J$7="","",'مستخلص 02'!$E$43)
A8: 3 | B8: =IF(OR('مستخلص 03'!$J$7="",'مستخلص 03'!$J$6=""),"",'مستخلص 03'!$J$6) | C8: =IF('مستخلص 03'!$J$7="","",'مستخلص 03'!$J$7) | D8: =IF(OR('مستخلص 03'!$J$7="",'مستخلص 03'!$J$8=""),"",'مستخلص 03'!$J$8) | E8: =IF(OR('مستخلص 03'!$J$7="",'مستخلص 03'!$J$9=""),"",'مستخلص 03'!$J$9) | F8: =IF(OR('مستخلص 03'!$J$7="",'مستخلص 03'!$J$5=""),"",'مستخلص 03'!$J$5) | G8: =IF('مستخلص 03'!$J$7="","",'مستخلص 03'!$L$19) | H8: =IF('مستخلص 03'!$J$7="","",'مستخلص 03'!$J$19) | I8: =IF('مستخلص 03'!$J$7="","",'مستخلص 03'!$L$20) | J8: =IF('مستخلص 03'!$J$7="","",'مستخلص 03'!$L$21) | K8: =IF('مستخلص 03'!$J$7="","",'مستخلص 03'!$L$22) | L8: =IF('مستخلص 03'!$J$7="","",'مستخلص 03'!$L$6) | M8: =IF(OR('مستخلص 03'!$J$7="",'مستخلص 03'!$L$8=""),"",'مستخلص 03'!$L$8) | N8: =IF(OR('مستخلص 03'!$J$7="",M8=""),"",L8-M8) | O8: =IF('مستخلص 03'!$J$7="","",-'مستخلص 03'!$L$23) | P8: =IF('مستخلص 03'!$J$7="","",-'مستخلص 03'!$L$24) | Q8: =IF('مستخلص 03'!$J$7="","",'مستخلص 03'!$L$25) | R8: =IF('مستخلص 03'!$J$7="","",P8-Q8) | S8: =IF('مستخلص 03'!$J$7="","",-'مستخلص 03'!$L$26) | T8: =IF('مستخلص 03'!$J$7="","",-'مستخلص 03'!$L$27) | U8: =IF('مستخلص 03'!$J$7="","",'مستخلص 03'!$L$28) | V8: =IF('مستخلص 03'!$J$7="","",'مستخلص 03'!$L$29) | W8: =IF('مستخلص 03'!$J$7="","",-'مستخلص 03'!$L$30) | X8: =IF('مستخلص 03'!$J$7="","",'مستخلص 03'!$L$31) | Y8: =IF('مستخلص 03'!$J$7="","",'مستخلص 03'!$H$31) | Z8: =IF('مستخلص 03'!$J$7="","",'مستخلص 03'!$J$31) | AA8: =IF('مستخلص 03'!$J$7="","",N('مستخلص 03'!$E$15)) | AB8: =IF(OR('مستخلص 03'!$J$7="",'مستخلص 03'!$K$15=""),"",'مستخلص 03'!$K$15) | AC8: =IF('مستخلص 03'!$J$7="","",Z8-AA8) | AD8: =IF(OR(AB8="",E8=""),"",AB8-E8) | AE8: =IF('مستخلص 03'!$J$7="","",IF(N(AA8)=0,IF(E8="","⏳ بانتظار الاعتماد","✖ غير محصل"),IF(AC8<=1,"✔ محصل بالكامل","⚠ محصل جزئياً"))) | AF8: =IF(OR('مستخلص 03'!$J$7="",'مستخلص 03'!$E$16=""),"",'مستخلص 03'!$E$16) | AG8: =IF('مستخلص 03'!$J$7="","",'مستخلص 03'!$E$43)
A9: 4 | B9: =IF(OR('مستخلص 04'!$J$7="",'مستخلص 04'!$J$6=""),"",'مستخلص 04'!$J$6) | C9: =IF('مستخلص 04'!$J$7="","",'مستخلص 04'!$J$7) | D9: =IF(OR('مستخلص 04'!$J$7="",'مستخلص 04'!$J$8=""),"",'مستخلص 04'!$J$8) | E9: =IF(OR('مستخلص 04'!$J$7="",'مستخلص 04'!$J$9=""),"",'مستخلص 04'!$J$9) | F9: =IF(OR('مستخلص 04'!$J$7="",'مستخلص 04'!$J$5=""),"",'مستخلص 04'!$J$5) | G9: =IF('مستخلص 04'!$J$7="","",'مستخلص 04'!$L$19) | H9: =IF('مستخلص 04'!$J$7="","",'مستخلص 04'!$J$19) | I9: =IF('مستخلص 04'!$J$7="","",'مستخلص 04'!$L$20) | J9: =IF('مستخلص 04'!$J$7="","",'مستخلص 04'!$L$21) | K9: =IF('مستخلص 04'!$J$7="","",'مستخلص 04'!$L$22) | L9: =IF('مستخلص 04'!$J$7="","",'مستخلص 04'!$L$6) | M9: =IF(OR('مستخلص 04'!$J$7="",'مستخلص 04'!$L$8=""),"",'مستخلص 04'!$L$8) | N9: =IF(OR('مستخلص 04'!$J$7="",M9=""),"",L9-M9) | O9: =IF('مستخلص 04'!$J$7="","",-'مستخلص 04'!$L$23) | P9: =IF('مستخلص 04'!$J$7="","",-'مستخلص 04'!$L$24) | Q9: =IF('مستخلص 04'!$J$7="","",'مستخلص 04'!$L$25) | R9: =IF('مستخلص 04'!$J$7="","",P9-Q9) | S9: =IF('مستخلص 04'!$J$7="","",-'مستخلص 04'!$L$26) | T9: =IF('مستخلص 04'!$J$7="","",-'مستخلص 04'!$L$27) | U9: =IF('مستخلص 04'!$J$7="","",'مستخلص 04'!$L$28) | V9: =IF('مستخلص 04'!$J$7="","",'مستخلص 04'!$L$29) | W9: =IF('مستخلص 04'!$J$7="","",-'مستخلص 04'!$L$30) | X9: =IF('مستخلص 04'!$J$7="","",'مستخلص 04'!$L$31) | Y9: =IF('مستخلص 04'!$J$7="","",'مستخلص 04'!$H$31) | Z9: =IF('مستخلص 04'!$J$7="","",'مستخلص 04'!$J$31) | AA9: =IF('مستخلص 04'!$J$7="","",N('مستخلص 04'!$E$15)) | AB9: =IF(OR('مستخلص 04'!$J$7="",'مستخلص 04'!$K$15=""),"",'مستخلص 04'!$K$15) | AC9: =IF('مستخلص 04'!$J$7="","",Z9-AA9) | AD9: =IF(OR(AB9="",E9=""),"",AB9-E9) | AE9: =IF('مستخلص 04'!$J$7="","",IF(N(AA9)=0,IF(E9="","⏳ بانتظار الاعتماد","✖ غير محصل"),IF(AC9<=1,"✔ محصل بالكامل","⚠ محصل جزئياً"))) | AF9: =IF(OR('مستخلص 04'!$J$7="",'مستخلص 04'!$E$16=""),"",'مستخلص 04'!$E$16) | AG9: =IF('مستخلص 04'!$J$7="","",'مستخلص 04'!$E$43)
A10: 5 | B10: =IF(OR('مستخلص 05'!$J$7="",'مستخلص 05'!$J$6=""),"",'مستخلص 05'!$J$6) | C10: =IF('مستخلص 05'!$J$7="","",'مستخلص 05'!$J$7) | D10: =IF(OR('مستخلص 05'!$J$7="",'مستخلص 05'!$J$8=""),"",'مستخلص 05'!$J$8) | E10: =IF(OR('مستخلص 05'!$J$7="",'مستخلص 05'!$J$9=""),"",'مستخلص 05'!$J$9) | F10: =IF(OR('مستخلص 05'!$J$7="",'مستخلص 05'!$J$5=""),"",'مستخلص 05'!$J$5) | G10: =IF('مستخلص 05'!$J$7="","",'مستخلص 05'!$L$19) | H10: =IF('مستخلص 05'!$J$7="","",'مستخلص 05'!$J$19) | I10: =IF('مستخلص 05'!$J$7="","",'مستخلص 05'!$L$20) | J10: =IF('مستخلص 05'!$J$7="","",'مستخلص 05'!$L$21) | K10: =IF('مستخلص 05'!$J$7="","",'مستخلص 05'!$L$22) | L10: =IF('مستخلص 05'!$J$7="","",'مستخلص 05'!$L$6) | M10: =IF(OR('مستخلص 05'!$J$7="",'مستخلص 05'!$L$8=""),"",'مستخلص 05'!$L$8) | N10: =IF(OR('مستخلص 05'!$J$7="",M10=""),"",L10-M10) | O10: =IF('مستخلص 05'!$J$7="","",-'مستخلص 05'!$L$23) | P10: =IF('مستخلص 05'!$J$7="","",-'مستخلص 05'!$L$24) | Q10: =IF('مستخلص 05'!$J$7="","",'مستخلص 05'!$L$25) | R10: =IF('مستخلص 05'!$J$7="","",P10-Q10) | S10: =IF('مستخلص 05'!$J$7="","",-'مستخلص 05'!$L$26) | T10: =IF('مستخلص 05'!$J$7="","",-'مستخلص 05'!$L$27) | U10: =IF('مستخلص 05'!$J$7="","",'مستخلص 05'!$L$28) | V10: =IF('مستخلص 05'!$J$7="","",'مستخلص 05'!$L$29) | W10: =IF('مستخلص 05'!$J$7="","",-'مستخلص 05'!$L$30) | X10: =IF('مستخلص 05'!$J$7="","",'مستخلص 05'!$L$31) | Y10: =IF('مستخلص 05'!$J$7="","",'مستخلص 05'!$H$31) | Z10: =IF('مستخلص 05'!$J$7="","",'مستخلص 05'!$J$31) | AA10: =IF('مستخلص 05'!$J$7="","",N('مستخلص 05'!$E$15)) | AB10: =IF(OR('مستخلص 05'!$J$7="",'مستخلص 05'!$K$15=""),"",'مستخلص 05'!$K$15) | AC10: =IF('مستخلص 05'!$J$7="","",Z10-AA10) | AD10: =IF(OR(AB10="",E10=""),"",AB10-E10) | AE10: =IF('مستخلص 05'!$J$7="","",IF(N(AA10)=0,IF(E10="","⏳ بانتظار الاعتماد","✖ غير محصل"),IF(AC10<=1,"✔ محصل بالكامل","⚠ محصل جزئياً"))) | AF10: =IF(OR('مستخلص 05'!$J$7="",'مستخلص 05'!$E$16=""),"",'مستخلص 05'!$E$16) | AG10: =IF('مستخلص 05'!$J$7="","",'مستخلص 05'!$E$43)
A11: 6 | B11: =IF(OR('مستخلص 06'!$J$7="",'مستخلص 06'!$J$6=""),"",'مستخلص 06'!$J$6) | C11: =IF('مستخلص 06'!$J$7="","",'مستخلص 06'!$J$7) | D11: =IF(OR('مستخلص 06'!$J$7="",'مستخلص 06'!$J$8=""),"",'مستخلص 06'!$J$8) | E11: =IF(OR('مستخلص 06'!$J$7="",'مستخلص 06'!$J$9=""),"",'مستخلص 06'!$J$9) | F11: =IF(OR('مستخلص 06'!$J$7="",'مستخلص 06'!$J$5=""),"",'مستخلص 06'!$J$5) | G11: =IF('مستخلص 06'!$J$7="","",'مستخلص 06'!$L$19) | H11: =IF('مستخلص 06'!$J$7="","",'مستخلص 06'!$J$19) | I11: =IF('مستخلص 06'!$J$7="","",'مستخلص 06'!$L$20) | J11: =IF('مستخلص 06'!$J$7="","",'مستخلص 06'!$L$21) | K11: =IF('مستخلص 06'!$J$7="","",'مستخلص 06'!$L$22) | L11: =IF('مستخلص 06'!$J$7="","",'مستخلص 06'!$L$6) | M11: =IF(OR('مستخلص 06'!$J$7="",'مستخلص 06'!$L$8=""),"",'مستخلص 06'!$L$8) | N11: =IF(OR('مستخلص 06'!$J$7="",M11=""),"",L11-M11) | O11: =IF('مستخلص 06'!$J$7="","",-'مستخلص 06'!$L$23) | P11: =IF('مستخلص 06'!$J$7="","",-'مستخلص 06'!$L$24) | Q11: =IF('مستخلص 06'!$J$7="","",'مستخلص 06'!$L$25) | R11: =IF('مستخلص 06'!$J$7="","",P11-Q11) | S11: =IF('مستخلص 06'!$J$7="","",-'مستخلص 06'!$L$26) | T11: =IF('مستخلص 06'!$J$7="","",-'مستخلص 06'!$L$27) | U11: =IF('مستخلص 06'!$J$7="","",'مستخلص 06'!$L$28) | V11: =IF('مستخلص 06'!$J$7="","",'مستخلص 06'!$L$29) | W11: =IF('مستخلص 06'!$J$7="","",-'مستخلص 06'!$L$30) | X11: =IF('مستخلص 06'!$J$7="","",'مستخلص 06'!$L$31) | Y11: =IF('مستخلص 06'!$J$7="","",'مستخلص 06'!$H$31) | Z11: =IF('مستخلص 06'!$J$7="","",'مستخلص 06'!$J$31) | AA11: =IF('مستخلص 06'!$J$7="","",N('مستخلص 06'!$E$15)) | AB11: =IF(OR('مستخلص 06'!$J$7="",'مستخلص 06'!$K$15=""),"",'مستخلص 06'!$K$15) | AC11: =IF('مستخلص 06'!$J$7="","",Z11-AA11) | AD11: =IF(OR(AB11="",E11=""),"",AB11-E11) | AE11: =IF('مستخلص 06'!$J$7="","",IF(N(AA11)=0,IF(E11="","⏳ بانتظار الاعتماد","✖ غير محصل"),IF(AC11<=1,"✔ محصل بالكامل","⚠ محصل جزئياً"))) | AF11: =IF(OR('مستخلص 06'!$J$7="",'مستخلص 06'!$E$16=""),"",'مستخلص 06'!$E$16) | AG11: =IF('مستخلص 06'!$J$7="","",'مستخلص 06'!$E$43)
A12: 7 | B12: =IF(OR('مستخلص 07'!$J$7="",'مستخلص 07'!$J$6=""),"",'مستخلص 07'!$J$6) | C12: =IF('مستخلص 07'!$J$7="","",'مستخلص 07'!$J$7) | D12: =IF(OR('مستخلص 07'!$J$7="",'مستخلص 07'!$J$8=""),"",'مستخلص 07'!$J$8) | E12: =IF(OR('مستخلص 07'!$J$7="",'مستخلص 07'!$J$9=""),"",'مستخلص 07'!$J$9) | F12: =IF(OR('مستخلص 07'!$J$7="",'مستخلص 07'!$J$5=""),"",'مستخلص 07'!$J$5) | G12: =IF('مستخلص 07'!$J$7="","",'مستخلص 07'!$L$19) | H12: =IF('مستخلص 07'!$J$7="","",'مستخلص 07'!$J$19) | I12: =IF('مستخلص 07'!$J$7="","",'مستخلص 07'!$L$20) | J12: =IF('مستخلص 07'!$J$7="","",'مستخلص 07'!$L$21) | K12: =IF('مستخلص 07'!$J$7="","",'مستخلص 07'!$L$22) | L12: =IF('مستخلص 07'!$J$7="","",'مستخلص 07'!$L$6) | M12: =IF(OR('مستخلص 07'!$J$7="",'مستخلص 07'!$L$8=""),"",'مستخلص 07'!$L$8) | N12: =IF(OR('مستخلص 07'!$J$7="",M12=""),"",L12-M12) | O12: =IF('مستخلص 07'!$J$7="","",-'مستخلص 07'!$L$23) | P12: =IF('مستخلص 07'!$J$7="","",-'مستخلص 07'!$L$24) | Q12: =IF('مستخلص 07'!$J$7="","",'مستخلص 07'!$L$25) | R12: =IF('مستخلص 07'!$J$7="","",P12-Q12) | S12: =IF('مستخلص 07'!$J$7="","",-'مستخلص 07'!$L$26) | T12: =IF('مستخلص 07'!$J$7="","",-'مستخلص 07'!$L$27) | U12: =IF('مستخلص 07'!$J$7="","",'مستخلص 07'!$L$28) | V12: =IF('مستخلص 07'!$J$7="","",'مستخلص 07'!$L$29) | W12: =IF('مستخلص 07'!$J$7="","",-'مستخلص 07'!$L$30) | X12: =IF('مستخلص 07'!$J$7="","",'مستخلص 07'!$L$31) | Y12: =IF('مستخلص 07'!$J$7="","",'مستخلص 07'!$H$31) | Z12: =IF('مستخلص 07'!$J$7="","",'مستخلص 07'!$J$31) | AA12: =IF('مستخلص 07'!$J$7="","",N('مستخلص 07'!$E$15)) | AB12: =IF(OR('مستخلص 07'!$J$7="",'مستخلص 07'!$K$15=""),"",'مستخلص 07'!$K$15) | AC12: =IF('مستخلص 07'!$J$7="","",Z12-AA12) | AD12: =IF(OR(AB12="",E12=""),"",AB12-E12) | AE12: =IF('مستخلص 07'!$J$7="","",IF(N(AA12)=0,IF(E12="","⏳ بانتظار الاعتماد","✖ غير محصل"),IF(AC12<=1,"✔ محصل بالكامل","⚠ محصل جزئياً"))) | AF12: =IF(OR('مستخلص 07'!$J$7="",'مستخلص 07'!$E$16=""),"",'مستخلص 07'!$E$16) | AG12: =IF('مستخلص 07'!$J$7="","",'مستخلص 07'!$E$43)
A13: 8 | B13: =IF(OR('مستخلص 08'!$J$7="",'مستخلص 08'!$J$6=""),"",'مستخلص 08'!$J$6) | C13: =IF('مستخلص 08'!$J$7="","",'مستخلص 08'!$J$7) | D13: =IF(OR('مستخلص 08'!$J$7="",'مستخلص 08'!$J$8=""),"",'مستخلص 08'!$J$8) | E13: =IF(OR('مستخلص 08'!$J$7="",'مستخلص 08'!$J$9=""),"",'مستخلص 08'!$J$9) | F13: =IF(OR('مستخلص 08'!$J$7="",'مستخلص 08'!$J$5=""),"",'مستخلص 08'!$J$5) | G13: =IF('مستخلص 08'!$J$7="","",'مستخلص 08'!$L$19) | H13: =IF('مستخلص 08'!$J$7="","",'مستخلص 08'!$J$19) | I13: =IF('مستخلص 08'!$J$7="","",'مستخلص 08'!$L$20) | J13: =IF('مستخلص 08'!$J$7="","",'مستخلص 08'!$L$21) | K13: =IF('مستخلص 08'!$J$7="","",'مستخلص 08'!$L$22) | L13: =IF('مستخلص 08'!$J$7="","",'مستخلص 08'!$L$6) | M13: =IF(OR('مستخلص 08'!$J$7="",'مستخلص 08'!$L$8=""),"",'مستخلص 08'!$L$8) | N13: =IF(OR('مستخلص 08'!$J$7="",M13=""),"",L13-M13) | O13: =IF('مستخلص 08'!$J$7="","",-'مستخلص 08'!$L$23) | P13: =IF('مستخلص 08'!$J$7="","",-'مستخلص 08'!$L$24) | Q13: =IF('مستخلص 08'!$J$7="","",'مستخلص 08'!$L$25) | R13: =IF('مستخلص 08'!$J$7="","",P13-Q13) | S13: =IF('مستخلص 08'!$J$7="","",-'مستخلص 08'!$L$26) | T13: =IF('مستخلص 08'!$J$7="","",-'مستخلص 08'!$L$27) | U13: =IF('مستخلص 08'!$J$7="","",'مستخلص 08'!$L$28) | V13: =IF('مستخلص 08'!$J$7="","",'مستخلص 08'!$L$29) | W13: =IF('مستخلص 08'!$J$7="","",-'مستخلص 08'!$L$30) | X13: =IF('مستخلص 08'!$J$7="","",'مستخلص 08'!$L$31) | Y13: =IF('مستخلص 08'!$J$7="","",'مستخلص 08'!$H$31) | Z13: =IF('مستخلص 08'!$J$7="","",'مستخلص 08'!$J$31) | AA13: =IF('مستخلص 08'!$J$7="","",N('مستخلص 08'!$E$15)) | AB13: =IF(OR('مستخلص 08'!$J$7="",'مستخلص 08'!$K$15=""),"",'مستخلص 08'!$K$15) | AC13: =IF('مستخلص 08'!$J$7="","",Z13-AA13) | AD13: =IF(OR(AB13="",E13=""),"",AB13-E13) | AE13: =IF('مستخلص 08'!$J$7="","",IF(N(AA13)=0,IF(E13="","⏳ بانتظار الاعتماد","✖ غير محصل"),IF(AC13<=1,"✔ محصل بالكامل","⚠ محصل جزئياً"))) | AF13: =IF(OR('مستخلص 08'!$J$7="",'مستخلص 08'!$E$16=""),"",'مستخلص 08'!$E$16) | AG13: =IF('مستخلص 08'!$J$7="","",'مستخلص 08'!$E$43)
A14: 9 | B14: =IF(OR('مستخلص 09'!$J$7="",'مستخلص 09'!$J$6=""),"",'مستخلص 09'!$J$6) | C14: =IF('مستخلص 09'!$J$7="","",'مستخلص 09'!$J$7) | D14: =IF(OR('مستخلص 09'!$J$7="",'مستخلص 09'!$J$8=""),"",'مستخلص 09'!$J$8) | E14: =IF(OR('مستخلص 09'!$J$7="",'مستخلص 09'!$J$9=""),"",'مستخلص 09'!$J$9) | F14: =IF(OR('مستخلص 09'!$J$7="",'مستخلص 09'!$J$5=""),"",'مستخلص 09'!$J$5) | G14: =IF('مستخلص 09'!$J$7="","",'مستخلص 09'!$L$19) | H14: =IF('مستخلص 09'!$J$7="","",'مستخلص 09'!$J$19) | I14: =IF('مستخلص 09'!$J$7="","",'مستخلص 09'!$L$20) | J14: =IF('مستخلص 09'!$J$7="","",'مستخلص 09'!$L$21) | K14: =IF('مستخلص 09'!$J$7="","",'مستخلص 09'!$L$22) | L14: =IF('مستخلص 09'!$J$7="","",'مستخلص 09'!$L$6) | M14: =IF(OR('مستخلص 09'!$J$7="",'مستخلص 09'!$L$8=""),"",'مستخلص 09'!$L$8) | N14: =IF(OR('مستخلص 09'!$J$7="",M14=""),"",L14-M14) | O14: =IF('مستخلص 09'!$J$7="","",-'مستخلص 09'!$L$23) | P14: =IF('مستخلص 09'!$J$7="","",-'مستخلص 09'!$L$24) | Q14: =IF('مستخلص 09'!$J$7="","",'مستخلص 09'!$L$25) | R14: =IF('مستخلص 09'!$J$7="","",P14-Q14) | S14: =IF('مستخلص 09'!$J$7="","",-'مستخلص 09'!$L$26) | T14: =IF('مستخلص 09'!$J$7="","",-'مستخلص 09'!$L$27) | U14: =IF('مستخلص 09'!$J$7="","",'مستخلص 09'!$L$28) | V14: =IF('مستخلص 09'!$J$7="","",'مستخلص 09'!$L$29) | W14: =IF('مستخلص 09'!$J$7="","",-'مستخلص 09'!$L$30) | X14: =IF('مستخلص 09'!$J$7="","",'مستخلص 09'!$L$31) | Y14: =IF('مستخلص 09'!$J$7="","",'مستخلص 09'!$H$31) | Z14: =IF('مستخلص 09'!$J$7="","",'مستخلص 09'!$J$31) | AA14: =IF('مستخلص 09'!$J$7="","",N('مستخلص 09'!$E$15)) | AB14: =IF(OR('مستخلص 09'!$J$7="",'مستخلص 09'!$K$15=""),"",'مستخلص 09'!$K$15) | AC14: =IF('مستخلص 09'!$J$7="","",Z14-AA14) | AD14: =IF(OR(AB14="",E14=""),"",AB14-E14) | AE14: =IF('مستخلص 09'!$J$7="","",IF(N(AA14)=0,IF(E14="","⏳ بانتظار الاعتماد","✖ غير محصل"),IF(AC14<=1,"✔ محصل بالكامل","⚠ محصل جزئياً"))) | AF14: =IF(OR('مستخلص 09'!$J$7="",'مستخلص 09'!$E$16=""),"",'مستخلص 09'!$E$16) | AG14: =IF('مستخلص 09'!$J$7="","",'مستخلص 09'!$E$43)
A15: 10 | B15: =IF(OR('مستخلص 10'!$J$7="",'مستخلص 10'!$J$6=""),"",'مستخلص 10'!$J$6) | C15: =IF('مستخلص 10'!$J$7="","",'مستخلص 10'!$J$7) | D15: =IF(OR('مستخلص 10'!$J$7="",'مستخلص 10'!$J$8=""),"",'مستخلص 10'!$J$8) | E15: =IF(OR('مستخلص 10'!$J$7="",'مستخلص 10'!$J$9=""),"",'مستخلص 10'!$J$9) | F15: =IF(OR('مستخلص 10'!$J$7="",'مستخلص 10'!$J$5=""),"",'مستخلص 10'!$J$5) | G15: =IF('مستخلص 10'!$J$7="","",'مستخلص 10'!$L$19) | H15: =IF('مستخلص 10'!$J$7="","",'مستخلص 10'!$J$19) | I15: =IF('مستخلص 10'!$J$7="","",'مستخلص 10'!$L$20) | J15: =IF('مستخلص 10'!$J$7="","",'مستخلص 10'!$L$21) | K15: =IF('مستخلص 10'!$J$7="","",'مستخلص 10'!$L$22) | L15: =IF('مستخلص 10'!$J$7="","",'مستخلص 10'!$L$6) | M15: =IF(OR('مستخلص 10'!$J$7="",'مستخلص 10'!$L$8=""),"",'مستخلص 10'!$L$8) | N15: =IF(OR('مستخلص 10'!$J$7="",M15=""),"",L15-M15) | O15: =IF('مستخلص 10'!$J$7="","",-'مستخلص 10'!$L$23) | P15: =IF('مستخلص 10'!$J$7="","",-'مستخلص 10'!$L$24) | Q15: =IF('مستخلص 10'!$J$7="","",'مستخلص 10'!$L$25) | R15: =IF('مستخلص 10'!$J$7="","",P15-Q15) | S15: =IF('مستخلص 10'!$J$7="","",-'مستخلص 10'!$L$26) | T15: =IF('مستخلص 10'!$J$7="","",-'مستخلص 10'!$L$27) | U15: =IF('مستخلص 10'!$J$7="","",'مستخلص 10'!$L$28) | V15: =IF('مستخلص 10'!$J$7="","",'مستخلص 10'!$L$29) | W15: =IF('مستخلص 10'!$J$7="","",-'مستخلص 10'!$L$30) | X15: =IF('مستخلص 10'!$J$7="","",'مستخلص 10'!$L$31) | Y15: =IF('مستخلص 10'!$J$7="","",'مستخلص 10'!$H$31) | Z15: =IF('مستخلص 10'!$J$7="","",'مستخلص 10'!$J$31) | AA15: =IF('مستخلص 10'!$J$7="","",N('مستخلص 10'!$E$15)) | AB15: =IF(OR('مستخلص 10'!$J$7="",'مستخلص 10'!$K$15=""),"",'مستخلص 10'!$K$15) | AC15: =IF('مستخلص 10'!$J$7="","",Z15-AA15) | AD15: =IF(OR(AB15="",E15=""),"",AB15-E15) | AE15: =IF('مستخلص 10'!$J$7="","",IF(N(AA15)=0,IF(E15="","⏳ بانتظار الاعتماد","✖ غير محصل"),IF(AC15<=1,"✔ محصل بالكامل","⚠ محصل جزئياً"))) | AF15: =IF(OR('مستخلص 10'!$J$7="",'مستخلص 10'!$E$16=""),"",'مستخلص 10'!$E$16) | AG15: =IF('مستخلص 10'!$J$7="","",'مستخلص 10'!$E$43)
A16: 11 | B16: =IF(OR('مستخلص 11'!$J$7="",'مستخلص 11'!$J$6=""),"",'مستخلص 11'!$J$6) | C16: =IF('مستخلص 11'!$J$7="","",'مستخلص 11'!$J$7) | D16: =IF(OR('مستخلص 11'!$J$7="",'مستخلص 11'!$J$8=""),"",'مستخلص 11'!$J$8) | E16: =IF(OR('مستخلص 11'!$J$7="",'مستخلص 11'!$J$9=""),"",'مستخلص 11'!$J$9) | F16: =IF(OR('مستخلص 11'!$J$7="",'مستخلص 11'!$J$5=""),"",'مستخلص 11'!$J$5) | G16: =IF('مستخلص 11'!$J$7="","",'مستخلص 11'!$L$19) | H16: =IF('مستخلص 11'!$J$7="","",'مستخلص 11'!$J$19) | I16: =IF('مستخلص 11'!$J$7="","",'مستخلص 11'!$L$20) | J16: =IF('مستخلص 11'!$J$7="","",'مستخلص 11'!$L$21) | K16: =IF('مستخلص 11'!$J$7="","",'مستخلص 11'!$L$22) | L16: =IF('مستخلص 11'!$J$7="","",'مستخلص 11'!$L$6) | M16: =IF(OR('مستخلص 11'!$J$7="",'مستخلص 11'!$L$8=""),"",'مستخلص 11'!$L$8) | N16: =IF(OR('مستخلص 11'!$J$7="",M16=""),"",L16-M16) | O16: =IF('مستخلص 11'!$J$7="","",-'مستخلص 11'!$L$23) | P16: =IF('مستخلص 11'!$J$7="","",-'مستخلص 11'!$L$24) | Q16: =IF('مستخلص 11'!$J$7="","",'مستخلص 11'!$L$25) | R16: =IF('مستخلص 11'!$J$7="","",P16-Q16) | S16: =IF('مستخلص 11'!$J$7="","",-'مستخلص 11'!$L$26) | T16: =IF('مستخلص 11'!$J$7="","",-'مستخلص 11'!$L$27) | U16: =IF('مستخلص 11'!$J$7="","",'مستخلص 11'!$L$28) | V16: =IF('مستخلص 11'!$J$7="","",'مستخلص 11'!$L$29) | W16: =IF('مستخلص 11'!$J$7="","",-'مستخلص 11'!$L$30) | X16: =IF('مستخلص 11'!$J$7="","",'مستخلص 11'!$L$31) | Y16: =IF('مستخلص 11'!$J$7="","",'مستخلص 11'!$H$31) | Z16: =IF('مستخلص 11'!$J$7="","",'مستخلص 11'!$J$31) | AA16: =IF('مستخلص 11'!$J$7="","",N('مستخلص 11'!$E$15)) | AB16: =IF(OR('مستخلص 11'!$J$7="",'مستخلص 11'!$K$15=""),"",'مستخلص 11'!$K$15) | AC16: =IF('مستخلص 11'!$J$7="","",Z16-AA16) | AD16: =IF(OR(AB16="",E16=""),"",AB16-E16) | AE16: =IF('مستخلص 11'!$J$7="","",IF(N(AA16)=0,IF(E16="","⏳ بانتظار الاعتماد","✖ غير محصل"),IF(AC16<=1,"✔ محصل بالكامل","⚠ محصل جزئياً"))) | AF16: =IF(OR('مستخلص 11'!$J$7="",'مستخلص 11'!$E$16=""),"",'مستخلص 11'!$E$16) | AG16: =IF('مستخلص 11'!$J$7="","",'مستخلص 11'!$E$43)
A17: 12 | B17: =IF(OR('مستخلص 12'!$J$7="",'مستخلص 12'!$J$6=""),"",'مستخلص 12'!$J$6) | C17: =IF('مستخلص 12'!$J$7="","",'مستخلص 12'!$J$7) | D17: =IF(OR('مستخلص 12'!$J$7="",'مستخلص 12'!$J$8=""),"",'مستخلص 12'!$J$8) | E17: =IF(OR('مستخلص 12'!$J$7="",'مستخلص 12'!$J$9=""),"",'مستخلص 12'!$J$9) | F17: =IF(OR('مستخلص 12'!$J$7="",'مستخلص 12'!$J$5=""),"",'مستخلص 12'!$J$5) | G17: =IF('مستخلص 12'!$J$7="","",'مستخلص 12'!$L$19) | H17: =IF('مستخلص 12'!$J$7="","",'مستخلص 12'!$J$19) | I17: =IF('مستخلص 12'!$J$7="","",'مستخلص 12'!$L$20) | J17: =IF('مستخلص 12'!$J$7="","",'مستخلص 12'!$L$21) | K17: =IF('مستخلص 12'!$J$7="","",'مستخلص 12'!$L$22) | L17: =IF('مستخلص 12'!$J$7="","",'مستخلص 12'!$L$6) | M17: =IF(OR('مستخلص 12'!$J$7="",'مستخلص 12'!$L$8=""),"",'مستخلص 12'!$L$8) | N17: =IF(OR('مستخلص 12'!$J$7="",M17=""),"",L17-M17) | O17: =IF('مستخلص 12'!$J$7="","",-'مستخلص 12'!$L$23) | P17: =IF('مستخلص 12'!$J$7="","",-'مستخلص 12'!$L$24) | Q17: =IF('مستخلص 12'!$J$7="","",'مستخلص 12'!$L$25) | R17: =IF('مستخلص 12'!$J$7="","",P17-Q17) | S17: =IF('مستخلص 12'!$J$7="","",-'مستخلص 12'!$L$26) | T17: =IF('مستخلص 12'!$J$7="","",-'مستخلص 12'!$L$27) | U17: =IF('مستخلص 12'!$J$7="","",'مستخلص 12'!$L$28) | V17: =IF('مستخلص 12'!$J$7="","",'مستخلص 12'!$L$29) | W17: =IF('مستخلص 12'!$J$7="","",-'مستخلص 12'!$L$30) | X17: =IF('مستخلص 12'!$J$7="","",'مستخلص 12'!$L$31) | Y17: =IF('مستخلص 12'!$J$7="","",'مستخلص 12'!$H$31) | Z17: =IF('مستخلص 12'!$J$7="","",'مستخلص 12'!$J$31) | AA17: =IF('مستخلص 12'!$J$7="","",N('مستخلص 12'!$E$15)) | AB17: =IF(OR('مستخلص 12'!$J$7="",'مستخلص 12'!$K$15=""),"",'مستخلص 12'!$K$15) | AC17: =IF('مستخلص 12'!$J$7="","",Z17-AA17) | AD17: =IF(OR(AB17="",E17=""),"",AB17-E17) | AE17: =IF('مستخلص 12'!$J$7="","",IF(N(AA17)=0,IF(E17="","⏳ بانتظار الاعتماد","✖ غير محصل"),IF(AC17<=1,"✔ محصل بالكامل","⚠ محصل جزئياً"))) | AF17: =IF(OR('مستخلص 12'!$J$7="",'مستخلص 12'!$E$16=""),"",'مستخلص 12'!$E$16) | AG17: =IF('مستخلص 12'!$J$7="","",'مستخلص 12'!$E$43)
