Workbook
Name S_Company: 'القوائم والإعدادات'!$B$5
Name S_VAT: 'القوائم والإعدادات'!$B$6
Name S_Ret: 'القوائم والإعدادات'!$B$7
Name S_SLA: 'القوائم والإعدادات'!$B$8
Name S_Cur: 'القوائم والإعدادات'!$B$9
Name L_YesNo: 'القوائم والإعدادات'!$A$14:$A$15
Name L_MARCode: 'القوائم والإعدادات'!$B$14:$B$17
Name L_Unit: 'القوائم والإعدادات'!$C$14:$C$24
Name L_Method: 'القوائم والإعدادات'!$D$14:$D$17
Name L_Disc: 'القوائم والإعدادات'!$E$14:$E$21
Name L_NCRCat: 'القوائم والإعدادات'!$F$14:$F$17
Name L_Sev: 'القوائم والإعدادات'!$G$14:$G$16
Name L_WIRRes: 'القوائم والإعدادات'!$H$14:$H$16
Name L_CostCat: 'القوائم والإعدادات'!$I$14:$I$22
Name L_IPCAppr: 'القوائم والإعدادات'!$J$14:$J$17
Name L_Proj: 'المشروعات'!$A$5:$A$304
Name L_MAR: 'اعتماد المواد'!$A$5:$A$304
Name L_PO: 'أوامر التوريد'!$A$5:$A$304
Name L_Item: 'رصيد المخزن'!$A$5:$A$304
Name L_IPC: 'المستخلصات'!$A$5:$A$304

Sheet الرئيسية
B1: =S_Company
B2: ="نظام إدارة المشروعات والمواقع • من استلام الموقع إلى التسليم النهائي • تحديث: "&TEXT(TODAY(),"yyyy/mm/dd")
B4: دورة العمل – اضغط على أي مرحلة للانتقال
B5: ① المشروعات | E5: ② استلام الموقع | H5: ③ اعتماد المواد | K5: ④ أوامر التوريد
B7: ⑤ استلام المواد | E7: ⑥ رصيد المخزن | H7: ⑦ صرف المواد | K7: ⑧ طلبات الفحص
B9: ⑨ عدم المطابقة | E9: ⑩ المستخلصات | H9: ⑪ سندات القبض | K9: ⑫ سندات الصرف
B11: ⑬ ملاحظات التسليم | E11: 🖨 طباعة سند قبض | H11: 🖨 طباعة سند صرف | K11: ⚙ القوائم والإعدادات
B14: المشروعات والتسليم
B15: عدد المشروعات | E15: إجمالي قيم العقود | H15: مشروعات متأخرة | K15: ملاحظات تسليم مفتوحة
B16: =COUNTA('المشروعات'!$B$5:$B$304) | E16: =SUM('المشروعات'!$F$5:$F$304) | H16: =COUNTIF('المشروعات'!$U$5:$U$304,"متأخر*") | K16: =COUNTIF('ملاحظات التسليم'!$K$5:$K$304,"مفتوح*")
B18: الاعتمادات والتوريد والمخزن
B19: طلبات اعتماد معلقة | E19: اعتمادات متأخرة الرد | H19: أوامر توريد غير مكتملة | K19: قيمة رصيد المخزن
B20: =COUNTIFS('اعتماد المواد'!$M$5:$M$304,"قيد المراجعة") | E20: =COUNTIFS('اعتماد المواد'!$O$5:$O$304,"متأخر*") | H20: =ROWS('أوامر التوريد'!$R$5:$R$304)-COUNTBLANK('أوامر التوريد'!$R$5:$R$304)-COUNTIF('أوامر التوريد'!$R$5:$R$304,"مكتمل") | K20: =SUM('رصيد المخزن'!$K$5:$K$304)
B22: إجمالي أوامر التوريد | E22: كميات مرفوضة (محاضر) | H22: أصناف تحتاج إعادة طلب | K22: أوامر لمواد غير معتمدة
B23: =SUM('أوامر التوريد'!$N$5:$N$304) | E23: =COUNTIF('استلام المواد'!$L$5:$L$304,">0") | H23: =COUNTIFS('رصيد المخزن'!$L$5:$L$304,"أعد الطلب") | K23: =COUNTIFS('أوامر التوريد'!$R$5:$R$304,"مادة غير معتمدة!")
B25: الجودة
B26: طلبات فحص بانتظار الاستشاري | E26: طلبات فحص مرفوضة | H26: NCR مفتوحة | K26: NCR متأخرة
B27: =COUNTIFS('طلبات الفحص'!$K$5:$K$304,"بانتظار الفحص") | E27: =COUNTIFS('طلبات الفحص'!$K$5:$K$304,"مرفوض") | H27: =COUNTIF('عدم المطابقة'!$L$5:$L$304,"مفتوح*") | K27: =COUNTIFS('عدم المطابقة'!$L$5:$L$304,"مفتوح – متأخر")
B29: الموقف المالي
B30: إجمالي المستخلصات | E30: إجمالي المقبوضات | H30: إجمالي المدفوعات | K30: صافي النقدية
B31: =SUM('المستخلصات'!$N$5:$N$304) | E31: =SUM('سندات القبض'!$K$5:$K$304) | H31: =SUM('سندات الصرف'!$L$5:$L$304) | K31: =SUM('سندات القبض'!$K$5:$K$304)-SUM('سندات الصرف'!$L$5:$L$304)
B33: مستحقات لم تُحصّل | E33: ضمان أعمال محتجز لدى الملاك | H33: نسبة التحصيل | K33: عدد السندات
B34: =SUM('المستخلصات'!$Q$5:$Q$304) | E34: =SUM('المستخلصات'!$I$5:$I$304) | H34: =IFERROR(SUM('المستخلصات'!$P$5:$P$304)/SUM('المستخلصات'!$N$5:$N$304),0) | K34: =COUNT('سندات القبض'!$K$5:$K$304)+COUNT('سندات الصرف'!$L$5:$L$304)
B36: ملخص المشروعات (أول 10)
B37: كود المشروع | C37: اسم المشروع | E37: نسبة الإنجاز | F37: المستخلصات | H37: المحصّل | I37: المنصرف | K37: صافي النقدية | L37: الحالة
B38: =IF('المشروعات'!$A$5="","",'المشروعات'!$A$5) | C38: =IF('المشروعات'!$B$5="","",'المشروعات'!$B$5) | E38: =IF('المشروعات'!$J$5="","",'المشروعات'!$J$5) | F38: =IF('المشروعات'!$L$5="","",'المشروعات'!$L$5) | H38: =IF('المشروعات'!$M$5="","",'المشروعات'!$M$5) | I38: =IF('المشروعات'!$N$5="","",'المشروعات'!$N$5) | K38: =IF('المشروعات'!$O$5="","",'المشروعات'!$O$5) | L38: =IF('المشروعات'!$U$5="","",'المشروعات'!$U$5)
B39: =IF('المشروعات'!$A$6="","",'المشروعات'!$A$6) | C39: =IF('المشروعات'!$B$6="","",'المشروعات'!$B$6) | E39: =IF('المشروعات'!$J$6="","",'المشروعات'!$J$6) | F39: =IF('المشروعات'!$L$6="","",'المشروعات'!$L$6) | H39: =IF('المشروعات'!$M$6="","",'المشروعات'!$M$6) | I39: =IF('المشروعات'!$N$6="","",'المشروعات'!$N$6) | K39: =IF('المشروعات'!$O$6="","",'المشروعات'!$O$6) | L39: =IF('المشروعات'!$U$6="","",'المشروعات'!$U$6)
B40: =IF('المشروعات'!$A$7="","",'المشروعات'!$A$7) | C40: =IF('المشروعات'!$B$7="","",'المشروعات'!$B$7) | E40: =IF('المشروعات'!$J$7="","",'المشروعات'!$J$7) | F40: =IF('المشروعات'!$L$7="","",'المشروعات'!$L$7) | H40: =IF('المشروعات'!$M$7="","",'المشروعات'!$M$7) | I40: =IF('المشروعات'!$N$7="","",'المشروعات'!$N$7) | K40: =IF('المشروعات'!$O$7="","",'المشروعات'!$O$7) | L40: =IF('المشروعات'!$U$7="","",'المشروعات'!$U$7)
B41: =IF('المشروعات'!$A$8="","",'المشروعات'!$A$8) | C41: =IF('المشروعات'!$B$8="","",'المشروعات'!$B$8) | E41: =IF('المشروعات'!$J$8="","",'المشروعات'!$J$8) | F41: =IF('المشروعات'!$L$8="","",'المشروعات'!$L$8) | H41: =IF('المشروعات'!$M$8="","",'المشروعات'!$M$8) | I41: =IF('المشروعات'!$N$8="","",'المشروعات'!$N$8) | K41: =IF('المشروعات'!$O$8="","",'المشروعات'!$O$8) | L41: =IF('المشروعات'!$U$8="","",'المشروعات'!$U$8)
B42: =IF('المشروعات'!$A$9="","",'المشروعات'!$A$9) | C42: =IF('المشروعات'!$B$9="","",'المشروعات'!$B$9) | E42: =IF('المشروعات'!$J$9="","",'المشروعات'!$J$9) | F42: =IF('المشروعات'!$L$9="","",'المشروعات'!$L$9) | H42: =IF('المشروعات'!$M$9="","",'المشروعات'!$M$9) | I42: =IF('المشروعات'!$N$9="","",'المشروعات'!$N$9) | K42: =IF('المشروعات'!$O$9="","",'المشروعات'!$O$9) | L42: =IF('المشروعات'!$U$9="","",'المشروعات'!$U$9)
B43: =IF('المشروعات'!$A$10="","",'المشروعات'!$A$10) | C43: =IF('المشروعات'!$B$10="","",'المشروعات'!$B$10) | E43: =IF('المشروعات'!$J$10="","",'المشروعات'!$J$10) | F43: =IF('المشروعات'!$L$10="","",'المشروعات'!$L$10) | H43: =IF('المشروعات'!$M$10="","",'المشروعات'!$M$10) | I43: =IF('المشروعات'!$N$10="","",'المشروعات'!$N$10) | K43: =IF('المشروعات'!$O$10="","",'المشروعات'!$O$10) | L43: =IF('المشروعات'!$U$10="","",'المشروعات'!$U$10)
B44: =IF('المشروعات'!$A$11="","",'المشروعات'!$A$11) | C44: =IF('المشروعات'!$B$11="","",'المشروعات'!$B$11) | E44: =IF('المشروعات'!$J$11="","",'المشروعات'!$J$11) | F44: =IF('المشروعات'!$L$11="","",'المشروعات'!$L$11) | H44: =IF('المشروعات'!$M$11="","",'المشروعات'!$M$11) | I44: =IF('المشروعات'!$N$11="","",'المشروعات'!$N$11) | K44: =IF('المشروعات'!$O$11="","",'المشروعات'!$O$11) | L44: =IF('المشروعات'!$U$11="","",'المشروعات'!$U$11)
B45: =IF('المشروعات'!$A$12="","",'المشروعات'!$A$12) | C45: =IF('المشروعات'!$B$12="","",'المشروعات'!$B$12) | E45: =IF('المشروعات'!$J$12="","",'المشروعات'!$J$12) | F45: =IF('المشروعات'!$L$12="","",'المشروعات'!$L$12) | H45: =IF('المشروعات'!$M$12="","",'المشروعات'!$M$12) | I45: =IF('المشروعات'!$N$12="","",'المشروعات'!$N$12) | K45: =IF('المشروعات'!$O$12="","",'المشروعات'!$O$12) | L45: =IF('المشروعات'!$U$12="","",'المشروعات'!$U$12)
B46: =IF('المشروعات'!$A$13="","",'المشروعات'!$A$13) | C46: =IF('المشروعات'!$B$13="","",'المشروعات'!$B$13) | E46: =IF('المشروعات'!$J$13="","",'المشروعات'!$J$13) | F46: =IF('المشروعات'!$L$13="","",'المشروعات'!$L$13) | H46: =IF('المشروعات'!$M$13="","",'المشروعات'!$M$13) | I46: =IF('المشروعات'!$N$13="","",'المشروعات'!$N$13) | K46: =IF('المشروعات'!$O$13="","",'المشروعات'!$O$13) | L46: =IF('المشروعات'!$U$13="","",'المشروعات'!$U$13)
B47: =IF('المشروعات'!$A$14="","",'المشروعات'!$A$14) | C47: =IF('المشروعات'!$B$14="","",'المشروعات'!$B$14) | E47: =IF('المشروعات'!$J$14="","",'المشروعات'!$J$14) | F47: =IF('المشروعات'!$L$14="","",'المشروعات'!$L$14) | H47: =IF('المشروعات'!$M$14="","",'المشروعات'!$M$14) | I47: =IF('المشروعات'!$N$14="","",'المشروعات'!$N$14) | K47: =IF('المشروعات'!$O$14="","",'المشروعات'!$O$14) | L47: =IF('المشروعات'!$U$14="","",'المشروعات'!$U$14)

Sheet دليل الاستخدام
B1: دليل استخدام النظام – خطوة بخطوة
B3: قبل البدء | C3: من (القوائم والإعدادات): اكتب اسم الشركة، ونسبة الضريبة وضمان الأعمال ومدة رد الاستشاري. الخلايا الصفراء فقط للإدخال – الرمادية معادلات لا تُكتب فيها.
B4: 1) المشروعات | C4: سجّل المشروع (الاسم، المالك، القيمة، المدة). الكود PRJ-xxx يتولد تلقائياً ويُستخدم في كل الشاشات من القائمة المنسدلة.
B5: 2) استلام الموقع | C5: سجّل محضر الاستلام (نموذج QF-SH-01 في ملف الوورد). تاريخ الاستلام ينتقل تلقائياً للمشروع ويبدأ منه احتساب المدة وتاريخ النهو.
B6: 3) اعتماد المواد | C6: كل مادة تُقدم للاستشاري بطلب MAR. عند إدخال كود الرد (A/B/C/D) تتغير الحالة، ويُنبهك النظام لو تأخر الرد عن المدة المحددة.
B7: 4) أوامر التوريد | C7: اختر رقم MAR المعتمد في أمر التوريد. لو المادة غير معتمدة (C/D أو قيد المراجعة) تظهر الحالة بالأحمر (مادة غير معتمدة!). أعطِ كل صنف كوداً ثابتاً.
B8: 5) استلام المواد | C8: اختر رقم أمر التوريد فتظهر بيانات الصنف تلقائياً. أدخل الوارد والمقبول – المرفوض والنتيجة تُحسب، والكمية المستلمة ترجع لأمر التوريد.
B9: 6) رصيد المخزن | C9: اكتب كود الصنف مرة واحدة – الوارد والمنصرف والرصيد والقيمة تتحدث تلقائياً. حدد حد إعادة الطلب ليظهر تنبيه (أعد الطلب).
B10: 7) صرف المواد | C10: اختر كود الصنف وأدخل الكمية والجهة المستلمة. لو الصرف أكبر من الرصيد يظهر تنبيه أحمر.
B11: 8) طلبات الفحص | C11: كل أعمال جاهزة تُقدم بطلب WIR، والنتيجة تُسجل عند رد الاستشاري.
B12: 9) عدم المطابقة | C12: أي مخالفة تُسجل NCR بتاريخ إغلاق مستهدف؛ تصبح (مفتوح – متأخر) تلقائياً إذا تجاوزته.
B13: 10) المستخلصات | C13: أدخل إجمالي الأعمال التراكمي فقط – السابق وهذا المستخلص والمحتجز والضريبة والصافي تُحسب تلقائياً، والمحصّل يأتي من سندات القبض.
B14: 11) سندات القبض | C14: كل مبلغ وارد بسند قبض مرتبط بالمشروع والمستخلص. الرقم RV-xxxx يتولد تلقائياً. للطباعة: شاشة (طباعة سند قبض) واختر الرقم ثم Ctrl+P.
... B18: البيانات التوضيحية | C18: الصفوف الأولى في كل شاشة أمثلة لتوضيح الربط. امسح الخلايا الصفراء فقط (وليس الرمادية) وابدأ ببياناتك.
B20: ↩ الرئيسية

Sheet المشروعات
A1: =S_Company&" | المشروعات"
A2: سجل المشروعات – البطاقة الرئيسية لكل مشروع
A3: ↩ الرئيسية | B3: ■ أصفر = إدخال يدوي ■ رمادي = معادلة تلقائية (لا تكتب فيها) — الصفوف الأولى أمثلة توضيحية؛ احذف قيم الإدخال واستبدلها ببياناتك
A4: كود المشروع | B4: اسم المشروع | C4: المالك / العميل | D4: الاستشاري | E4: الموقع | F4: قيمة العقد | G4: تاريخ استلام الموقع | H4: مدة التنفيذ (يوم) | I4: تاريخ النهو التعاقدي | J4: نسبة الإنجاز الفعلية | K4: نسبة المدة المنقضية | L4: إجمالي المستخلصات | M4: إجمالي المحصّل | N4: إجمالي المنصرف | O4: صافي التدفق النقدي | P4: تاريخ التسليم الابتدائي | Q4: تاريخ التسليم النهائي | R4: اعتمادات معلقة | S4: NCR مفتوحة | T4: ملاحظات تسليم مفتوحة | U4: حالة المشروع
A5: =IF(B5="","","PRJ-"&TEXT(ROW()-4,"000")) | B5: برج إداري – التجمع الخامس | C5: شركة النخبة للاستثمار العقاري | D5: المكتب الهندسي الاستشاري | E5: القاهرة الجديدة | F5: 48500000 | G5: =IF(B5="","",IFERROR(INDEX('استلام المواقع'!$D$5:$D$304,MATCH(A5,'استلام المواقع'!$B$5:$B$304,0)),"")) | H5: 540 | I5: =IF(OR(G5="",H5=""),"",G5+H5) | J5: 0.58 | K5: =IF(OR(I5="",H5=0),"",MAX(0,MIN(1,(IF(P5<>"",P5,TODAY())-G5)/H5))) | L5: =IF(B5="","",SUMIFS('المستخلصات'!$N$5:$N$304,'المستخلصات'!$B$5:$B$304,A5)) | M5: =IF(B5="","",SUMIFS('سندات القبض'!$K$5:$K$304,'سندات القبض'!$D$5:$D$304,A5)) | N5: =IF(B5="","",SUMIFS('سندات الصرف'!$L$5:$L$304,'سندات الصرف'!$D$5:$D$304,A5)) | O5: =IF(B5="","",M5-N5) | R5: =IF(B5="","",COUNTIFS('اعتماد المواد'!$B$5:$B$304,A5,'اعتماد المواد'!$M$5:$M$304,"قيد المراجعة")) | S5: =IF(B5="","",COUNTIFS('عدم المطابقة'!$C$5:$C$304,A5,'عدم المطابقة'!$L$5:$L$304,"مفتوح*")) | T5: =IF(B5="","",COUNTIFS('ملاحظات التسليم'!$B$5:$B$304,A5,'ملاحظات التسليم'!$K$5:$K$304,"مفتوح*")) | U5: =IF(B5="","",IF(Q5<>"","مسلّم نهائياً",IF(P5<>"","فترة الضمان",IF(G5="","بانتظار استلام الموقع",IF(TODAY()>I5,"متأخر عن التعاقد",IF(J5<K5-0.1,"متأخر عن الخطة","جاري التنفيذ"))))))
A6: =IF(B6="","","PRJ-"&TEXT(ROW()-4,"000")) | B6: مدرسة دولية – 6 أكتوبر | C6: مؤسسة المستقبل التعليمية | D6: دار الهندسة للاستشارات | E6: 6 أكتوبر | F6: 22750000 | G6: =IF(B6="","",IFERROR(INDEX('استلام المواقع'!$D$5:$D$304,MATCH(A6,'استلام المواقع'!$B$5:$B$304,0)),"")) | H6: 365 | I6: =IF(OR(G6="",H6=""),"",G6+H6) | J6: 0.33 | K6: =IF(OR(I6="",H6=0),"",MAX(0,MIN(1,(IF(P6<>"",P6,TODAY())-G6)/H6))) | L6: =IF(B6="","",SUMIFS('المستخلصات'!$N$5:$N$304,'المستخلصات'!$B$5:$B$304,A6)) | M6: =IF(B6="","",SUMIFS('سندات القبض'!$K$5:$K$304,'سندات القبض'!$D$5:$D$304,A6)) | N6: =IF(B6="","",SUMIFS('سندات الصرف'!$L$5:$L$304,'سندات الصرف'!$D$5:$D$304,A6)) | O6: =IF(B6="","",M6-N6) | R6: =IF(B6="","",COUNTIFS('اعتماد المواد'!$B$5:$B$304,A6,'اعتماد المواد'!$M$5:$M$304,"قيد المراجعة")) | S6: =IF(B6="","",COUNTIFS('عدم المطابقة'!$C$5:$C$304,A6,'عدم المطابقة'!$L$5:$L$304,"مفتوح*")) | T6: =IF(B6="","",COUNTIFS('ملاحظات التسليم'!$B$5:$B$304,A6,'ملاحظات التسليم'!$K$5:$K$304,"مفتوح*")) | U6: =IF(B6="","",IF(Q6<>"","مسلّم نهائياً",IF(P6<>"","فترة الضمان",IF(G6="","بانتظار استلام الموقع",IF(TODAY()>I6,"متأخر عن التعاقد",IF(J6<K6-0.1,"متأخر عن الخطة","جاري التنفيذ"))))))
A7: =IF(B7="","","PRJ-"&TEXT(ROW()-4,"000")) | G7: =IF(B7="","",IFERROR(INDEX('استلام المواقع'!$D$5:$D$304,MATCH(A7,'استلام المواقع'!$B$5:$B$304,0)),"")) | I7: =IF(OR(G7="",H7=""),"",G7+H7) | K7: =IF(OR(I7="",H7=0),"",MAX(0,MIN(1,(IF(P7<>"",P7,TODAY())-G7)/H7))) | L7: =IF(B7="","",SUMIFS('المستخلصات'!$N$5:$N$304,'المستخلصات'!$B$5:$B$304,A7)) | M7: =IF(B7="","",SUMIFS('سندات القبض'!$K$5:$K$304,'سندات القبض'!$D$5:$D$304,A7)) | N7: =IF(B7="","",SUMIFS('سندات الصرف'!$L$5:$L$304,'سندات الصرف'!$D$5:$D$304,A7)) | O7: =IF(B7="","",M7-N7) | R7: =IF(B7="","",COUNTIFS('اعتماد المواد'!$B$5:$B$304,A7,'اعتماد المواد'!$M$5:$M$304,"قيد المراجعة")) | S7: =IF(B7="","",COUNTIFS('عدم المطابقة'!$C$5:$C$304,A7,'عدم المطابقة'!$L$5:$L$304,"مفتوح*")) | T7: =IF(B7="","",COUNTIFS('ملاحظات التسليم'!$B$5:$B$304,A7,'ملاحظات التسليم'!$K$5:$K$304,"مفتوح*")) | U7: =IF(B7="","",IF(Q7<>"","مسلّم نهائياً",IF(P7<>"","فترة الضمان",IF(G7="","بانتظار استلام الموقع",IF(TODAY()>I7,"متأخر عن التعاقد",IF(J7<K7-0.1,"متأخر عن الخطة","جاري التنفيذ"))))))
A8: =IF(B8="","","PRJ-"&TEXT(ROW()-4,"000")) | G8: =IF(B8="","",IFERROR(INDEX('استلام المواقع'!$D$5:$D$304,MATCH(A8,'استلام المواقع'!$B$5:$B$304,0)),"")) | I8: =IF(OR(G8="",H8=""),"",G8+H8) | K8: =IF(OR(I8="",H8=0),"",MAX(0,MIN(1,(IF(P8<>"",P8,TODAY())-G8)/H8))) | L8: =IF(B8="","",SUMIFS('المستخلصات'!$N$5:$N$304,'المستخلصات'!$B$5:$B$304,A8)) | M8: =IF(B8="","",SUMIFS('سندات القبض'!$K$5:$K$304,'سندات القبض'!$D$5:$D$304,A8)) | N8: =IF(B8="","",SUMIFS('سندات الصرف'!$L$5:$L$304,'سندات الصرف'!$D$5:$D$304,A8)) | O8: =IF(B8="","",M8-N8) | R8: =IF(B8="","",COUNTIFS('اعتماد المواد'!$B$5:$B$304,A8,'اعتماد المواد'!$M$5:$M$304,"قيد المراجعة")) | S8: =IF(B8="","",COUNTIFS('عدم المطابقة'!$C$5:$C$304,A8,'عدم المطابقة'!$L$5:$L$304,"مفتوح*")) | T8: =IF(B8="","",COUNTIFS('ملاحظات التسليم'!$B$5:$B$304,A8,'ملاحظات التسليم'!$K$5:$K$304,"مفتوح*")) | U8: =IF(B8="","",IF(Q8<>"","مسلّم نهائياً",IF(P8<>"","فترة الضمان",IF(G8="","بانتظار استلام الموقع",IF(TODAY()>I8,"متأخر عن التعاقد",IF(J8<K8-0.1,"متأخر عن الخطة","جاري التنفيذ"))))))
A9: =IF(B9="","","PRJ-"&TEXT(ROW()-4,"000")) | G9: =IF(B9="","",IFERROR(INDEX('استلام المواقع'!$D$5:$D$304,MATCH(A9,'استلام المواقع'!$B$5:$B$304,0)),"")) | I9: =IF(OR(G9="",H9=""),"",G9+H9) | K9: =IF(OR(I9="",H9=0),"",MAX(0,MIN(1,(IF(P9<>"",P9,TODAY())-G9)/H9))) | L9: =IF(B9="","",SUMIFS('المستخلصات'!$N$5:$N$304,'المستخلصات'!$B$5:$B$304,A9)) | M9: =IF(B9="","",SUMIFS('سندات القبض'!$K$5:$K$304,'سندات القبض'!$D$5:$D$304,A9)) | N9: =IF(B9="","",SUMIFS('سندات الصرف'!$L$5:$L$304,'سندات الصرف'!$D$5:$D$304,A9)) | O9: =IF(B9="","",M9-N9) | R9: =IF(B9="","",COUNTIFS('اعتماد المواد'!$B$5:$B$304,A9,'اعتماد المواد'!$M$5:$M$304,"قيد المراجعة")) | S9: =IF(B9="","",COUNTIFS('عدم المطابقة'!$C$5:$C$304,A9,'عدم المطابقة'!$L$5:$L$304,"مفتوح*")) | T9: =IF(B9="","",COUNTIFS('ملاحظات التسليم'!$B$5:$B$304,A9,'ملاحظات التسليم'!$K$5:$K$304,"مفتوح*")) | U9: =IF(B9="","",IF(Q9<>"","مسلّم نهائياً",IF(P9<>"","فترة الضمان",IF(G9="","بانتظار استلام الموقع",IF(TODAY()>I9,"متأخر عن التعاقد",IF(J9<K9-0.1,"متأخر عن الخطة","جاري التنفيذ"))))))
A10: =IF(B10="","","PRJ-"&TEXT(ROW()-4,"000")) | G10: =IF(B10="","",IFERROR(INDEX('استلام المواقع'!$D$5:$D$304,MATCH(A10,'استلام المواقع'!$B$5:$B$304,0)),"")) | I10: =IF(OR(G10="",H10=""),"",G10+H10) | K10: =IF(OR(I10="",H10=0),"",MAX(0,MIN(1,(IF(P10<>"",P10,TODAY())-G10)/H10))) | L10: =IF(B10="","",SUMIFS('المستخلصات'!$N$5:$N$304,'المستخلصات'!$B$5:$B$304,A10)) | M10: =IF(B10="","",SUMIFS('سندات القبض'!$K$5:$K$304,'سندات القبض'!$D$5:$D$304,A10)) | N10: =IF(B10="","",SUMIFS('سندات الصرف'!$L$5:$L$304,'سندات الصرف'!$D$5:$D$304,A10)) | O10: =IF(B10="","",M10-N10) | R10: =IF(B10="","",COUNTIFS('اعتماد المواد'!$B$5:$B$304,A10,'اعتماد المواد'!$M$5:$M$304,"قيد المراجعة")) | S10: =IF(B10="","",COUNTIFS('عدم المطابقة'!$C$5:$C$304,A10,'عدم المطابقة'!$L$5:$L$304,"مفتوح*")) | T10: =IF(B10="","",COUNTIFS('ملاحظات التسليم'!$B$5:$B$304,A10,'ملاحظات التسليم'!$K$5:$K$304,"مفتوح*")) | U10: =IF(B10="","",IF(Q10<>"","مسلّم نهائياً",IF(P10<>"","فترة الضمان",IF(G10="","بانتظار استلام الموقع",IF(TODAY()>I10,"متأخر عن التعاقد",IF(J10<K10-0.1,"متأخر عن الخطة","جاري التنفيذ"))))))
A11: =IF(B11="","","PRJ-"&TEXT(ROW()-4,"000")) | G11: =IF(B11="","",IFERROR(INDEX('استلام المواقع'!$D$5:$D$304,MATCH(A11,'استلام المواقع'!$B$5:$B$304,0)),"")) | I11: =IF(OR(G11="",H11=""),"",G11+H11) | K11: =IF(OR(I11="",H11=0),"",MAX(0,MIN(1,(IF(P11<>"",P11,TODAY())-G11)/H11))) | L11: =IF(B11="","",SUMIFS('المستخلصات'!$N$5:$N$304,'المستخلصات'!$B$5:$B$304,A11)) | M11: =IF(B11="","",SUMIFS('سندات القبض'!$K$5:$K$304,'سندات القبض'!$D$5:$D$304,A11)) | N11: =IF(B11="","",SUMIFS('سندات الصرف'!$L$5:$L$304,'سندات الصرف'!$D$5:$D$304,A11)) | O11: =IF(B11="","",M11-N11) | R11: =IF(B11="","",COUNTIFS('اعتماد المواد'!$B$5:$B$304,A11,'اعتماد المواد'!$M$5:$M$304,"قيد المراجعة")) | S11: =IF(B11="","",COUNTIFS('عدم المطابقة'!$C$5:$C$304,A11,'عدم المطابقة'!$L$5:$L$304,"مفتوح*")) | T11: =IF(B11="","",COUNTIFS('ملاحظات التسليم'!$B$5:$B$304,A11,'ملاحظات التسليم'!$K$5:$K$304,"مفتوح*")) | U11: =IF(B11="","",IF(Q11<>"","مسلّم نهائياً",IF(P11<>"","فترة الضمان",IF(G11="","بانتظار استلام الموقع",IF(TODAY()>I11,"متأخر عن التعاقد",IF(J11<K11-0.1,"متأخر عن الخطة","جاري التنفيذ"))))))
A12: =IF(B12="","","PRJ-"&TEXT(ROW()-4,"000")) | G12: =IF(B12="","",IFERROR(INDEX('استلام المواقع'!$D$5:$D$304,MATCH(A12,'استلام المواقع'!$B$5:$B$304,0)),"")) | I12: =IF(OR(G12="",H12=""),"",G12+H12) | K12: =IF(OR(I12="",H12=0),"",MAX(0,MIN(1,(IF(P12<>"",P12,TODAY())-G12)/H12))) | L12: =IF(B12="","",SUMIFS('المستخلصات'!$N$5:$N$304,'المستخلصات'!$B$5:$B$304,A12)) | M12: =IF(B12="","",SUMIFS('سندات القبض'!$K$5:$K$304,'سندات القبض'!$D$5:$D$304,A12)) | N12: =IF(B12="","",SUMIFS('سندات الصرف'!$L$5:$L$304,'سندات الصرف'!$D$5:$D$304,A12)) | O12: =IF(B12="","",M12-N12) | R12: =IF(B12="","",COUNTIFS('اعتماد المواد'!$B$5:$B$304,A12,'اعتماد المواد'!$M$5:$M$304,"قيد المراجعة")) | S12: =IF(B12="","",COUNTIFS('عدم المطابقة'!$C$5:$C$304,A12,'عدم المطابقة'!$L$5:$L$304,"مفتوح*")) | T12: =IF(B12="","",COUNTIFS('ملاحظات التسليم'!$B$5:$B$304,A12,'ملاحظات التسليم'!$K$5:$K$304,"مفتوح*")) | U12: =IF(B12="","",IF(Q12<>"","مسلّم نهائياً",IF(P12<>"","فترة الضمان",IF(G12="","بانتظار استلام الموقع",IF(TODAY()>I12,"متأخر عن التعاقد",IF(J12<K12-0.1,"متأخر عن الخطة","جاري التنفيذ"))))))
A13: =IF(B13="","","PRJ-"&TEXT(ROW()-4,"000")) | G13: =IF(B13="","",IFERROR(INDEX('استلام المواقع'!$D$5:$D$304,MATCH(A13,'استلام المواقع'!$B$5:$B$304,0)),"")) | I13: =IF(OR(G13="",H13=""),"",G13+H13) | K13: =IF(OR(I13="",H13=0),"",MAX(0,MIN(1,(IF(P13<>"",P13,TODAY())-G13)/H13))) | L13: =IF(B13="","",SUMIFS('المستخلصات'!$N$5:$N$304,'المستخلصات'!$B$5:$B$304,A13)) | M13: =IF(B13="","",SUMIFS('سندات القبض'!$K$5:$K$304,'سندات القبض'!$D$5:$D$304,A13)) | N13: =IF(B13="","",SUMIFS('سندات الصرف'!$L$5:$L$304,'سندات الصرف'!$D$5:$D$304,A13)) | O13: =IF(B13="","",M13-N13) | R13: =IF(B13="","",COUNTIFS('اعتماد المواد'!$B$5:$B$304,A13,'اعتماد المواد'!$M$5:$M$304,"قيد المراجعة")) | S13: =IF(B13="","",COUNTIFS('عدم المطابقة'!$C$5:$C$304,A13,'عدم المطابقة'!$L$5:$L$304,"مفتوح*")) | T13: =IF(B13="","",COUNTIFS('ملاحظات التسليم'!$B$5:$B$304,A13,'ملاحظات التسليم'!$K$5:$K$304,"مفتوح*")) | U13: =IF(B13="","",IF(Q13<>"","مسلّم نهائياً",IF(P13<>"","فترة الضمان",IF(G13="","بانتظار استلام الموقع",IF(TODAY()>I13,"متأخر عن التعاقد",IF(J13<K13-0.1,"متأخر عن الخطة","جاري التنفيذ"))))))
A14: =IF(B14="","","PRJ-"&TEXT(ROW()-4,"000")) | G14: =IF(B14="","",IFERROR(INDEX('استلام المواقع'!$D$5:$D$304,MATCH(A14,'استلام المواقع'!$B$5:$B$304,0)),"")) | I14: =IF(OR(G14="",H14=""),"",G14+H14) | K14: =IF(OR(I14="",H14=0),"",MAX(0,MIN(1,(IF(P14<>"",P14,TODAY())-G14)/H14))) | L14: =IF(B14="","",SUMIFS('المستخلصات'!$N$5:$N$304,'المستخلصات'!$B$5:$B$304,A14)) | M14: =IF(B14="","",SUMIFS('سندات القبض'!$K$5:$K$304,'سندات القبض'!$D$5:$D$304,A14)) | N14: =IF(B14="","",SUMIFS('سندات الصرف'!$L$5:$L$304,'سندات الصرف'!$D$5:$D$304,A14)) | O14: =IF(B14="","",M14-N14) | R14: =IF(B14="","",COUNTIFS('اعتماد المواد'!$B$5:$B$304,A14,'اعتماد المواد'!$M$5:$M$304,"قيد المراجعة")) | S14: =IF(B14="","",COUNTIFS('عدم المطابقة'!$C$5:$C$304,A14,'عدم المطابقة'!$L$5:$L$304,"مفتوح*")) | T14: =IF(B14="","",COUNTIFS('ملاحظات التسليم'!$B$5:$B$304,A14,'ملاحظات التسليم'!$K$5:$K$304,"مفتوح*")) | U14: =IF(B14="","",IF(Q14<>"","مسلّم نهائياً",IF(P14<>"","فترة الضمان",IF(G14="","بانتظار استلام الموقع",IF(TODAY()>I14,"متأخر عن التعاقد",IF(J14<K14-0.1,"متأخر عن الخطة","جاري التنفيذ"))))))
A15: =IF(B15="","","PRJ-"&TEXT(ROW()-4,"000")) | G15: =IF(B15="","",IFERROR(INDEX('استلام المواقع'!$D$5:$D$304,MATCH(A15,'استلام المواقع'!$B$5:$B$304,0)),"")) | I15: =IF(OR(G15="",H15=""),"",G15+H15) | K15: =IF(OR(I15="",H15=0),"",MAX(0,MIN(1,(IF(P15<>"",P15,TODAY())-G15)/H15))) | L15: =IF(B15="","",SUMIFS('المستخلصات'!$N$5:$N$304,'المستخلصات'!$B$5:$B$304,A15)) | M15: =IF(B15="","",SUMIFS('سندات القبض'!$K$5:$K$304,'سندات القبض'!$D$5:$D$304,A15)) | N15: =IF(B15="","",SUMIFS('سندات الصرف'!$L$5:$L$304,'سندات الصرف'!$D$5:$D$304,A15)) | O15: =IF(B15="","",M15-N15) | R15: =IF(B15="","",COUNTIFS('اعتماد المواد'!$B$5:$B$304,A15,'اعتماد المواد'!$M$5:$M$304,"قيد المراجعة")) | S15: =IF(B15="","",COUNTIFS('عدم المطابقة'!$C$5:$C$304,A15,'عدم المطابقة'!$L$5:$L$304,"مفتوح*")) | T15: =IF(B15="","",COUNTIFS('ملاحظات التسليم'!$B$5:$B$304,A15,'ملاحظات التسليم'!$K$5:$K$304,"مفتوح*")) | U15: =IF(B15="","",IF(Q15<>"","مسلّم نهائياً",IF(P15<>"","فترة الضمان",IF(G15="","بانتظار استلام الموقع",IF(TODAY()>I15,"متأخر عن التعاقد",IF(J15<K15-0.1,"متأخر عن الخطة","جاري التنفيذ"))))))
A16: =IF(B16="","","PRJ-"&TEXT(ROW()-4,"000")) | G16: =IF(B16="","",IFERROR(INDEX('استلام المواقع'!$D$5:$D$304,MATCH(A16,'استلام المواقع'!$B$5:$B$304,0)),"")) | I16: =IF(OR(G16="",H16=""),"",G16+H16) | K16: =IF(OR(I16="",H16=0),"",MAX(0,MIN(1,(IF(P16<>"",P16,TODAY())-G16)/H16))) | L16: =IF(B16="","",SUMIFS('المستخلصات'!$N$5:$N$304,'المستخلصات'!$B$5:$B$304,A16)) | M16: =IF(B16="","",SUMIFS('سندات القبض'!$K$5:$K$304,'سندات القبض'!$D$5:$D$304,A16)) | N16: =IF(B16="","",SUMIFS('سندات الصرف'!$L$5:$L$304,'سندات الصرف'!$D$5:$D$304,A16)) | O16: =IF(B16="","",M16-N16) | R16: =IF(B16="","",COUNTIFS('اعتماد المواد'!$B$5:$B$304,A16,'اعتماد المواد'!$M$5:$M$304,"قيد المراجعة")) | S16: =IF(B16="","",COUNTIFS('عدم المطابقة'!$C$5:$C$304,A16,'عدم المطابقة'!$L$5:$L$304,"مفتوح*")) | T16: =IF(B16="","",COUNTIFS('ملاحظات التسليم'!$B$5:$B$304,A16,'ملاحظات التسليم'!$K$5:$K$304,"مفتوح*")) | U16: =IF(B16="","",IF(Q16<>"","مسلّم نهائياً",IF(P16<>"","فترة الضمان",IF(G16="","بانتظار استلام الموقع",IF(TODAY()>I16,"متأخر عن التعاقد",IF(J16<K16-0.1,"متأخر عن الخطة","جاري التنفيذ"))))))
A17: =IF(B17="","","PRJ-"&TEXT(ROW()-4,"000")) | G17: =IF(B17="","",IFERROR(INDEX('استلام المواقع'!$D$5:$D$304,MATCH(A17,'استلام المواقع'!$B$5:$B$304,0)),"")) | I17: =IF(OR(G17="",H17=""),"",G17+H17) | K17: =IF(OR(I17="",H17=0),"",MAX(0,MIN(1,(IF(P17<>"",P17,TODAY())-G17)/H17))) | L17: =IF(B17="","",SUMIFS('المستخلصات'!$N$5:$N$304,'المستخلصات'!$B$5:$B$304,A17)) | M17: =IF(B17="","",SUMIFS('سندات القبض'!$K$5:$K$304,'سندات القبض'!$D$5:$D$304,A17)) | N17: =IF(B17="","",SUMIFS('سندات الصرف'!$L$5:$L$304,'سندات الصرف'!$D$5:$D$304,A17)) | O17: =IF(B17="","",M17-N17) | R17: =IF(B17="","",COUNTIFS('اعتماد المواد'!$B$5:$B$304,A17,'اعتماد المواد'!$M$5:$M$304,"قيد المراجعة")) | S17: =IF(B17="","",COUNTIFS('عدم المطابقة'!$C$5:$C$304,A17,'عدم المطابقة'!$L$5:$L$304,"مفتوح*")) | T17: =IF(B17="","",COUNTIFS('ملاحظات التسليم'!$B$5:$B$304,A17,'ملاحظات التسليم'!$K$5:$K$304,"مفتوح*")) | U17: =IF(B17="","",IF(Q17<>"","مسلّم نهائياً",IF(P17<>"","فترة الضمان",IF(G17="","بانتظار استلام الموقع",IF(TODAY()>I17,"متأخر عن التعاقد",IF(J17<K17-0.1,"متأخر عن الخطة","جاري التنفيذ"))))))
A18: =IF(B18="","","PRJ-"&TEXT(ROW()-4,"000")) | G18: =IF(B18="","",IFERROR(INDEX('استلام المواقع'!$D$5:$D$304,MATCH(A18,'استلام المواقع'!$B$5:$B$304,0)),"")) | I18: =IF(OR(G18="",H18=""),"",G18+H18) | K18: =IF(OR(I18="",H18=0),"",MAX(0,MIN(1,(IF(P18<>"",P18,TODAY())-G18)/H18))) | L18: =IF(B18="","",SUMIFS('المستخلصات'!$N$5:$N$304,'المستخلصات'!$B$5:$B$304,A18)) | M18: =IF(B18="","",SUMIFS('سندات القبض'!$K$5:$K$304,'سندات القبض'!$D$5:$D$304,A18)) | N18: =IF(B18="","",SUMIFS('سندات الصرف'!$L$5:$L$304,'سندات الصرف'!$D$5:$D$304,A18)) | O18: =IF(B18="","",M18-N18) | R18: =IF(B18="","",COUNTIFS('اعتماد المواد'!$B$5:$B$304,A18,'اعتماد المواد'!$M$5:$M$304,"قيد المراجعة")) | S18: =IF(B18="","",COUNTIFS('عدم المطابقة'!$C$5:$C$304,A18,'عدم المطابقة'!$L$5:$L$304,"مفتوح*")) | T18: =IF(B18="","",COUNTIFS('ملاحظات التسليم'!$B$5:$B$304,A18,'ملاحظات التسليم'!$K$5:$K$304,"مفتوح*")) | U18: =IF(B18="","",IF(Q18<>"","مسلّم نهائياً",IF(P18<>"","فترة الضمان",IF(G18="","بانتظار استلام الموقع",IF(TODAY()>I18,"متأخر عن التعاقد",IF(J18<K18-0.1,"متأخر عن الخطة","جاري التنفيذ"))))))
... A304: =IF(B304="","","PRJ-"&TEXT(ROW()-4,"000")) | G304: =IF(B304="","",IFERROR(INDEX('استلام المواقع'!$D$5:$D$304,MATCH(A304,'استلام المواقع'!$B$5:$B$304,0)),"")) | I304: =IF(OR(G304="",H304=""),"",G304+H304) | K304: =IF(OR(I304="",H304=0),"",MAX(0,MIN(1,(IF(P304<>"",P304,TODAY())-G304)/H304))) | L304: =IF(B304="","",SUMIFS('المستخلصات'!$N$5:$N$304,'المستخلصات'!$B$5:$B$304,A304)) | M304: =IF(B304="","",SUMIFS('سندات القبض'!$K$5:$K$304,'سندات القبض'!$D$5:$D$304,A304)) | N304: =IF(B304="","",SUMIFS('سندات الصرف'!$L$5:$L$304,'سندات الصرف'!$D$5:$D$304,A304)) | O304: =IF(B304="","",M304-N304) | R304: =IF(B304="","",COUNTIFS('اعتماد المواد'!$B$5:$B$304,A304,'اعتماد المواد'!$M$5:$M$304,"قيد المراجعة")) | S304: =IF(B304="","",COUNTIFS('عدم المطابقة'!$C$5:$C$304,A304,'عدم المطابقة'!$L$5:$L$304,"مفتوح*")) | T304: =IF(B304="","",COUNTIFS('ملاحظات التسليم'!$B$5:$B$304,A304,'ملاحظات التسليم'!$K$5:$K$304,"مفتوح*")) | U304: =IF(B304="","",IF(Q304<>"","مسلّم نهائياً",IF(P304<>"","فترة الضمان",IF(G304="","بانتظار استلام الموقع",IF(TODAY()>I304,"متأخر عن التعاقد",IF(J304<K304-0.1,"متأخر عن الخطة","جاري التنفيذ"))))))

Sheet استلام المواقع
A1: =S_Company&" | استلام المواقع"
A2: محاضر استلام المواقع من المالك (QF-SH-01)
A3: ↩ الرئيسية | B3: ■ أصفر = إدخال يدوي ■ رمادي = معادلة تلقائية (لا تكتب فيها) — الصفوف الأولى أمثلة توضيحية؛ احذف قيم الإدخال واستبدلها ببياناتك
A4: رقم المحضر | B4: كود المشروع | C4: اسم المشروع | D4: تاريخ الاستلام | E4: الموقع خالٍ من العوائق | F4: تسليم نقاط الروبير | G4: تسليم المخططات المعتمدة | H4: تقرير التربة | I4: مياه/كهرباء مؤقتة | J4: الترخيص | K4: تحفظات المقاول | L4: نتيجة الاستلام
A5: =IF(B5="","","SH-"&TEXT(ROW()-4,"0000")) | B5: PRJ-001 | C5: =IF(B5="","",IFERROR(INDEX('المشروعات'!$B$5:$B$304,MATCH(B5,'المشروعات'!$A$5:$A$304,0)),"")) | D5: 45962 | E5: نعم | F5: نعم | G5: نعم | H5: نعم | I5: لا | J5: نعم | K5: الكهرباء المؤقتة على حساب المالك خلال 30 يوماً | L5: =IF(B5="","",IF(COUNTIF(E5:J5,"لا")>0,"استلام بتحفظات ("&COUNTIF(E5:J5,"لا")&")","استلام كامل"))
A6: =IF(B6="","","SH-"&TEXT(ROW()-4,"0000")) | B6: PRJ-002 | C6: =IF(B6="","",IFERROR(INDEX('المشروعات'!$B$5:$B$304,MATCH(B6,'المشروعات'!$A$5:$A$304,0)),"")) | D6: 46157 | E6: نعم | F6: نعم | G6: نعم | H6: نعم | I6: نعم | J6: نعم | L6: =IF(B6="","",IF(COUNTIF(E6:J6,"لا")>0,"استلام بتحفظات ("&COUNTIF(E6:J6,"لا")&")","استلام كامل"))
A7: =IF(B7="","","SH-"&TEXT(ROW()-4,"0000")) | C7: =IF(B7="","",IFERROR(INDEX('المشروعات'!$B$5:$B$304,MATCH(B7,'المشروعات'!$A$5:$A$304,0)),"")) | L7: =IF(B7="","",IF(COUNTIF(E7:J7,"لا")>0,"استلام بتحفظات ("&COUNTIF(E7:J7,"لا")&")","استلام كامل"))
A8: =IF(B8="","","SH-"&TEXT(ROW()-4,"0000")) | C8: =IF(B8="","",IFERROR(INDEX('المشروعات'!$B$5:$B$304,MATCH(B8,'المشروعات'!$A$5:$A$304,0)),"")) | L8: =IF(B8="","",IF(COUNTIF(E8:J8,"لا")>0,"استلام بتحفظات ("&COUNTIF(E8:J8,"لا")&")","استلام كامل"))
A9: =IF(B9="","","SH-"&TEXT(ROW()-4,"0000")) | C9: =IF(B9="","",IFERROR(INDEX('المشروعات'!$B$5:$B$304,MATCH(B9,'المشروعات'!$A$5:$A$304,0)),"")) | L9: =IF(B9="","",IF(COUNTIF(E9:J9,"لا")>0,"استلام بتحفظات ("&COUNTIF(E9:J9,"لا")&")","استلام كامل"))
A10: =IF(B10="","","SH-"&TEXT(ROW()-4,"0000")) | C10: =IF(B10="","",IFERROR(INDEX('المشروعات'!$B$5:$B$304,MATCH(B10,'المشروعات'!$A$5:$A$304,0)),"")) | L10: =IF(B10="","",IF(COUNTIF(E10:J10,"لا")>0,"استلام بتحفظات ("&COUNTIF(E10:J10,"لا")&")","استلام كامل"))
A11: =IF(B11="","","SH-"&TEXT(ROW()-4,"0000")) | C11: =IF(B11="","",IFERROR(INDEX('المشروعات'!$B$5:$B$304,MATCH(B11,'المشروعات'!$A$5:$A$304,0)),"")) | L11: =IF(B11="","",IF(COUNTIF(E11:J11,"لا")>0,"استلام بتحفظات ("&COUNTIF(E11:J11,"لا")&")","استلام كامل"))
A12: =IF(B12="","","SH-"&TEXT(ROW()-4,"0000")) | C12: =IF(B12="","",IFERROR(INDEX('المشروعات'!$B$5:$B$304,MATCH(B12,'المشروعات'!$A$5:$A$304,0)),"")) | L12: =IF(B12="","",IF(COUNTIF(E12:J12,"لا")>0,"استلام بتحفظات ("&COUNTIF(E12:J12,"لا")&")","استلام كامل"))
A13: =IF(B13="","","SH-"&TEXT(ROW()-4,"0000")) | C13: =IF(B13="","",IFERROR(INDEX('المشروعات'!$B$5:$B$304,MATCH(B13,'المشروعات'!$A$5:$A$304,0)),"")) | L13: =IF(B13="","",IF(COUNTIF(E13:J13,"لا")>0,"استلام بتحفظات ("&COUNTIF(E13:J13,"لا")&")","استلام كامل"))
A14: =IF(B14="","","SH-"&TEXT(ROW()-4,"0000")) | C14: =IF(B14="","",IFERROR(INDEX('المشروعات'!$B$5:$B$304,MATCH(B14,'المشروعات'!$A$5:$A$304,0)),"")) | L14: =IF(B14="","",IF(COUNTIF(E14:J14,"لا")>0,"استلام بتحفظات ("&COUNTIF(E14:J14,"لا")&")","استلام كامل"))
A15: =IF(B15="","","SH-"&TEXT(ROW()-4,"0000")) | C15: =IF(B15="","",IFERROR(INDEX('المشروعات'!$B$5:$B$304,MATCH(B15,'المشروعات'!$A$5:$A$304,0)),"")) | L15: =IF(B15="","",IF(COUNTIF(E15:J15,"لا")>0,"استلام بتحفظات ("&COUNTIF(E15:J15,"لا")&")","استلام كامل"))
A16: =IF(B16="","","SH-"&TEXT(ROW()-4,"0000")) | C16: =IF(B16="","",IFERROR(INDEX('المشروعات'!$B$5:$B$304,MATCH(B16,'المشروعات'!$A$5:$A$304,0)),"")) | L16: =IF(B16="","",IF(COUNTIF(E16:J16,"لا")>0,"استلام بتحفظات ("&COUNTIF(E16:J16,"لا")&")","استلام كامل"))
A17: =IF(B17="","","SH-"&TEXT(ROW()-4,"0000")) | C17: =IF(B17="","",IFERROR(INDEX('المشروعات'!$B$5:$B$304,MATCH(B17,'المشروعات'!$A$5:$A$304,0)),"")) | L17: =IF(B17="","",IF(COUNTIF(E17:J17,"لا")>0,"استلام بتحفظات ("&COUNTIF(E17:J17,"لا")&")","استلام كامل"))
A18: =IF(B18="","","SH-"&TEXT(ROW()-4,"0000")) | C18: =IF(B18="","",IFERROR(INDEX('المشروعات'!$B$5:$B$304,MATCH(B18,'المشروعات'!$A$5:$A$304,0)),"")) | L18: =IF(B18="","",IF(COUNTIF(E18:J18,"لا")>0,"استلام بتحفظات ("&COUNTIF(E18:J18,"لا")&")","استلام كامل"))
... A304: =IF(B304="","","SH-"&TEXT(ROW()-4,"0000")) | C304: =IF(B304="","",IFERROR(INDEX('المشروعات'!$B$5:$B$304,MATCH(B304,'المشروعات'!$A$5:$A$304,0)),"")) | L304: =IF(B304="","",IF(COUNTIF(E304:J304,"لا")>0,"استلام بتحفظات ("&COUNTIF(E304:J304,"لا")&")","استلام كامل"))

Sheet اعتماد المواد
A1: =S_Company&" | اعتماد المواد"
A2: سجل طلبات اعتماد المواد MAR (QF-MA-02)
A3: ↩ الرئيسية | B3: ■ أصفر = إدخال يدوي ■ رمادي = معادلة تلقائية (لا تكتب فيها) — الصفوف الأولى أمثلة توضيحية؛ احذف قيم الإدخال واستبدلها ببياناتك
A4: رقم الطلب | B4: كود المشروع | C4: اسم المشروع | D4: المادة | E4: رقم البند | F4: رقم المواصفة | G4: المصنّع / المنشأ | H4: المورّد | I4: المراجعة | J4: تاريخ التقديم | K4: تاريخ الرد | L4: كود الرد | M4: الحالة | N4: أيام المراجعة | O4: تنبيه | P4: صالح للتوريد؟
A5: =IF(B5="","","MAR-"&TEXT(ROW()-4,"0000")) | B5: PRJ-001 | C5: =IF(B5="","",IFERROR(INDEX('المشروعات'!$B$5:$B$304,MATCH(B5,'المشروعات'!$A$5:$A$304,0)),"")) | D5: حديد تسليح عالي المقاومة B500 | E5: 03-200 | F5: 03 21 00 | G5: حديد عز – مصر | H5: الموزع المعتمد للحديد | I5: 0 | J5: 45971 | K5: 45979 | L5: A | M5: =IF(B5="","",IF(L5="","قيد المراجعة",IF(L5="A","معتمد",IF(L5="B","معتمد بملاحظات",IF(L5="C","مرفوض – يعاد التقديم","مرفوض نهائياً"))))) | N5: =IF(J5="","",IF(K5="",TODAY(),K5)-J5) | O5: =IF(B5="","",IF(AND(L5="",N(N5)>S_SLA),"متأخر رد الاستشاري","")) | P5: =IF(B5="","",IF(OR(L5="A",L5="B"),"نعم","لا"))
A6: =IF(B6="","","MAR-"&TEXT(ROW()-4,"0000")) | B6: PRJ-001 | C6: =IF(B6="","",IFERROR(INDEX('المشروعات'!$B$5:$B$304,MATCH(B6,'المشروعات'!$A$5:$A$304,0)),"")) | D6: أسمنت بورتلاندي 42.5N | E6: 03-100 | F6: 03 30 00 | G6: أسمنت السويس | H6: مؤسسة مواد البناء | I6: 1 | J6: 45973 | K6: 45986 | L6: B | M6: =IF(B6="","",IF(L6="","قيد المراجعة",IF(L6="A","معتمد",IF(L6="B","معتمد بملاحظات",IF(L6="C","مرفوض – يعاد التقديم","مرفوض نهائياً"))))) | N6: =IF(J6="","",IF(K6="",TODAY(),K6)-J6) | O6: =IF(B6="","",IF(AND(L6="",N(N6)>S_SLA),"متأخر رد الاستشاري","")) | P6: =IF(B6="","",IF(OR(L6="A",L6="B"),"نعم","لا"))
A7: =IF(B7="","","MAR-"&TEXT(ROW()-4,"0000")) | B7: PRJ-001 | C7: =IF(B7="","",IFERROR(INDEX('المشروعات'!$B$5:$B$304,MATCH(B7,'المشروعات'!$A$5:$A$304,0)),"")) | D7: بلوك خرساني مصمت 20 سم | E7: 04-100 | F7: 04 22 00 | G7: مصنع البلوك الحديث | H7: مصنع البلوك الحديث | I7: 0 | J7: 46266 | M7: =IF(B7="","",IF(L7="","قيد المراجعة",IF(L7="A","معتمد",IF(L7="B","معتمد بملاحظات",IF(L7="C","مرفوض – يعاد التقديم","مرفوض نهائياً"))))) | N7: =IF(J7="","",IF(K7="",TODAY(),K7)-J7) | O7: =IF(B7="","",IF(AND(L7="",N(N7)>S_SLA),"متأخر رد الاستشاري","")) | P7: =IF(B7="","",IF(OR(L7="A",L7="B"),"نعم","لا"))
A8: =IF(B8="","","MAR-"&TEXT(ROW()-4,"0000")) | B8: PRJ-002 | C8: =IF(B8="","",IFERROR(INDEX('المشروعات'!$B$5:$B$304,MATCH(B8,'المشروعات'!$A$5:$A$304,0)),"")) | D8: خرسانة جاهزة C30 | E8: 03-300 | F8: 03 30 00 | G8: محطة خرسانة معتمدة | H8: شركة الخرسانة الجاهزة | I8: 0 | J8: 46167 | K8: 46175 | L8: A | M8: =IF(B8="","",IF(L8="","قيد المراجعة",IF(L8="A","معتمد",IF(L8="B","معتمد بملاحظات",IF(L8="C","مرفوض – يعاد التقديم","مرفوض نهائياً"))))) | N8: =IF(J8="","",IF(K8="",TODAY(),K8)-J8) | O8: =IF(B8="","",IF(AND(L8="",N(N8)>S_SLA),"متأخر رد الاستشاري","")) | P8: =IF(B8="","",IF(OR(L8="A",L8="B"),"نعم","لا"))
A9: =IF(B9="","","MAR-"&TEXT(ROW()-4,"0000")) | C9: =IF(B9="","",IFERROR(INDEX('المشروعات'!$B$5:$B$304,MATCH(B9,'المشروعات'!$A$5:$A$304,0)),"")) | M9: =IF(B9="","",IF(L9="","قيد المراجعة",IF(L9="A","معتمد",IF(L9="B","معتمد بملاحظات",IF(L9="C","مرفوض – يعاد التقديم","مرفوض نهائياً"))))) | N9: =IF(J9="","",IF(K9="",TODAY(),K9)-J9) | O9: =IF(B9="","",IF(AND(L9="",N(N9)>S_SLA),"متأخر رد الاستشاري","")) | P9: =IF(B9="","",IF(OR(L9="A",L9="B"),"نعم","لا"))
A10: =IF(B10="","","MAR-"&TEXT(ROW()-4,"0000")) | C10: =IF(B10="","",IFERROR(INDEX('المشروعات'!$B$5:$B$304,MATCH(B10,'المشروعات'!$A$5:$A$304,0)),"")) | M10: =IF(B10="","",IF(L10="","قيد المراجعة",IF(L10="A","معتمد",IF(L10="B","معتمد بملاحظات",IF(L10="C","مرفوض – يعاد التقديم","مرفوض نهائياً"))))) | N10: =IF(J10="","",IF(K10="",TODAY(),K10)-J10) | O10: =IF(B10="","",IF(AND(L10="",N(N10)>S_SLA),"متأخر رد الاستشاري","")) | P10: =IF(B10="","",IF(OR(L10="A",L10="B"),"نعم","لا"))
A11: =IF(B11="","","MAR-"&TEXT(ROW()-4,"0000")) | C11: =IF(B11="","",IFERROR(INDEX('المشروعات'!$B$5:$B$304,MATCH(B11,'المشروعات'!$A$5:$A$304,0)),"")) | M11: =IF(B11="","",IF(L11="","قيد المراجعة",IF(L11="A","معتمد",IF(L11="B","معتمد بملاحظات",IF(L11="C","مرفوض – يعاد التقديم","مرفوض نهائياً"))))) | N11: =IF(J11="","",IF(K11="",TODAY(),K11)-J11) | O11: =IF(B11="","",IF(AND(L11="",N(N11)>S_SLA),"متأخر رد الاستشاري","")) | P11: =IF(B11="","",IF(OR(L11="A",L11="B"),"نعم","لا"))
A12: =IF(B12="","","MAR-"&TEXT(ROW()-4,"0000")) | C12: =IF(B12="","",IFERROR(INDEX('المشروعات'!$B$5:$B$304,MATCH(B12,'المشروعات'!$A$5:$A$304,0)),"")) | M12: =IF(B12="","",IF(L12="","قيد المراجعة",IF(L12="A","معتمد",IF(L12="B","معتمد بملاحظات",IF(L12="C","مرفوض – يعاد التقديم","مرفوض نهائياً"))))) | N12: =IF(J12="","",IF(K12="",TODAY(),K12)-J12) | O12: =IF(B12="","",IF(AND(L12="",N(N12)>S_SLA),"متأخر رد الاستشاري","")) | P12: =IF(B12="","",IF(OR(L12="A",L12="B"),"نعم","لا"))
A13: =IF(B13="","","MAR-"&TEXT(ROW()-4,"0000")) | C13: =IF(B13="","",IFERROR(INDEX('المشروعات'!$B$5:$B$304,MATCH(B13,'المشروعات'!$A$5:$A$304,0)),"")) | M13: =IF(B13="","",IF(L13="","قيد المراجعة",IF(L13="A","معتمد",IF(L13="B","معتمد بملاحظات",IF(L13="C","مرفوض – يعاد التقديم","مرفوض نهائياً"))))) | N13: =IF(J13="","",IF(K13="",TODAY(),K13)-J13) | O13: =IF(B13="","",IF(AND(L13="",N(N13)>S_SLA),"متأخر رد الاستشاري","")) | P13: =IF(B13="","",IF(OR(L13="A",L13="B"),"نعم","لا"))
A14: =IF(B14="","","MAR-"&TEXT(ROW()-4,"0000")) | C14: =IF(B14="","",IFERROR(INDEX('المشروعات'!$B$5:$B$304,MATCH(B14,'المشروعات'!$A$5:$A$304,0)),"")) | M14: =IF(B14="","",IF(L14="","قيد المراجعة",IF(L14="A","معتمد",IF(L14="B","معتمد بملاحظات",IF(L14="C","مرفوض – يعاد التقديم","مرفوض نهائياً"))))) | N14: =IF(J14="","",IF(K14="",TODAY(),K14)-J14) | O14: =IF(B14="","",IF(AND(L14="",N(N14)>S_SLA),"متأخر رد الاستشاري","")) | P14: =IF(B14="","",IF(OR(L14="A",L14="B"),"نعم","لا"))
A15: =IF(B15="","","MAR-"&TEXT(ROW()-4,"0000")) | C15: =IF(B15="","",IFERROR(INDEX('المشروعات'!$B$5:$B$304,MATCH(B15,'المشروعات'!$A$5:$A$304,0)),"")) | M15: =IF(B15="","",IF(L15="","قيد المراجعة",IF(L15="A","معتمد",IF(L15="B","معتمد بملاحظات",IF(L15="C","مرفوض – يعاد التقديم","مرفوض نهائياً"))))) | N15: =IF(J15="","",IF(K15="",TODAY(),K15)-J15) | O15: =IF(B15="","",IF(AND(L15="",N(N15)>S_SLA),"متأخر رد الاستشاري","")) | P15: =IF(B15="","",IF(OR(L15="A",L15="B"),"نعم","لا"))
A16: =IF(B16="","","MAR-"&TEXT(ROW()-4,"0000")) | C16: =IF(B16="","",IFERROR(INDEX('المشروعات'!$B$5:$B$304,MATCH(B16,'المشروعات'!$A$5:$A$304,0)),"")) | M16: =IF(B16="","",IF(L16="","قيد المراجعة",IF(L16="A","معتمد",IF(L16="B","معتمد بملاحظات",IF(L16="C","مرفوض – يعاد التقديم","مرفوض نهائياً"))))) | N16: =IF(J16="","",IF(K16="",TODAY(),K16)-J16) | O16: =IF(B16="","",IF(AND(L16="",N(N16)>S_SLA),"متأخر رد الاستشاري","")) | P16: =IF(B16="","",IF(OR(L16="A",L16="B"),"نعم","لا"))
A17: =IF(B17="","","MAR-"&TEXT(ROW()-4,"0000")) | C17: =IF(B17="","",IFERROR(INDEX('المشروعات'!$B$5:$B$304,MATCH(B17,'المشروعات'!$A$5:$A$304,0)),"")) | M17: =IF(B17="","",IF(L17="","قيد المراجعة",IF(L17="A","معتمد",IF(L17="B","معتمد بملاحظات",IF(L17="C","مرفوض – يعاد التقديم","مرفوض نهائياً"))))) | N17: =IF(J17="","",IF(K17="",TODAY(),K17)-J17) | O17: =IF(B17="","",IF(AND(L17="",N(N17)>S_SLA),"متأخر رد الاستشاري","")) | P17: =IF(B17="","",IF(OR(L17="A",L17="B"),"نعم","لا"))
A18: =IF(B18="","","MAR-"&TEXT(ROW()-4,"0000")) | C18: =IF(B18="","",IFERROR(INDEX('المشروعات'!$B$5:$B$304,MATCH(B18,'المشروعات'!$A$5:$A$304,0)),"")) | M18: =IF(B18="","",IF(L18="","قيد المراجعة",IF(L18="A","معتمد",IF(L18="B","معتمد بملاحظات",IF(L18="C","مرفوض – يعاد التقديم","مرفوض نهائياً"))))) | N18: =IF(J18="","",IF(K18="",TODAY(),K18)-J18) | O18: =IF(B18="","",IF(AND(L18="",N(N18)>S_SLA),"متأخر رد الاستشاري","")) | P18: =IF(B18="","",IF(OR(L18="A",L18="B"),"نعم","لا"))
A19: =IF(B19="","","MAR-"&TEXT(ROW()-4,"0000")) | C19: =IF(B19="","",IFERROR(INDEX('المشروعات'!$B$5:$B$304,MATCH(B19,'المشروعات'!$A$5:$A$304,0)),"")) | M19: =IF(B19="","",IF(L19="","قيد المراجعة",IF(L19="A","معتمد",IF(L19="B","معتمد بملاحظات",IF(L19="C","مرفوض – يعاد التقديم","مرفوض نهائياً"))))) | N19: =IF(J19="","",IF(K19="",TODAY(),K19)-J19) | O19: =IF(B19="","",IF(AND(L19="",N(N19)>S_SLA),"متأخر رد الاستشاري","")) | P19: =IF(B19="","",IF(OR(L19="A",L19="B"),"نعم","لا"))
A20: =IF(B20="","","MAR-"&TEXT(ROW()-4,"0000")) | C20: =IF(B20="","",IFERROR(INDEX('المشروعات'!$B$5:$B$304,MATCH(B20,'المشروعات'!$A$5:$A$304,0)),"")) | M20: =IF(B20="","",IF(L20="","قيد المراجعة",IF(L20="A","معتمد",IF(L20="B","معتمد بملاحظات",IF(L20="C","مرفوض – يعاد التقديم","مرفوض نهائياً"))))) | N20: =IF(J20="","",IF(K20="",TODAY(),K20)-J20) | O20: =IF(B20="","",IF(AND(L20="",N(N20)>S_SLA),"متأخر رد الاستشاري","")) | P20: =IF(B20="","",IF(OR(L20="A",L20="B"),"نعم","لا"))
... A304: =IF(B304="","","MAR-"&TEXT(ROW()-4,"0000")) | C304: =IF(B304="","",IFERROR(INDEX('المشروعات'!$B$5:$B$304,MATCH(B304,'المشروعات'!$A$5:$A$304,0)),"")) | M304: =IF(B304="","",IF(L304="","قيد المراجعة",IF(L304="A","معتمد",IF(L304="B","معتمد بملاحظات",IF(L304="C","مرفوض – يعاد التقديم","مرفوض نهائياً"))))) | N304: =IF(J304="","",IF(K304="",TODAY(),K304)-J304) | O304: =IF(B304="","",IF(AND(L304="",N(N304)>S_SLA),"متأخر رد الاستشاري","")) | P304: =IF(B304="","",IF(OR(L304="A",L304="B"),"نعم","لا"))

Sheet أوامر التوريد
A1: =S_Company&" | أوامر التوريد"
A2: سجل أوامر التوريد – مربوط بالاعتمادات والاستلام (QF-PO-04)
A3: ↩ الرئيسية | B3: ■ أصفر = إدخال يدوي ■ رمادي = معادلة تلقائية (لا تكتب فيها) — الصفوف الأولى أمثلة توضيحية؛ احذف قيم الإدخال واستبدلها ببياناتك
A4: رقم أمر التوريد | B4: التاريخ | C4: كود المشروع | D4: المورّد | E4: رقم الاعتماد MAR | F4: المادة معتمدة؟ | G4: كود الصنف | H4: الصنف | I4: الوحدة | J4: الكمية | K4: سعر الوحدة | L4: الإجمالي | M4: الضريبة | N4: الإجمالي شامل الضريبة | O4: تاريخ التسليم المطلوب | P4: الكمية المستلمة المقبولة | Q4: المتبقي | R4: حالة التوريد
A5: =IF(C5="","","PO-"&TEXT(ROW()-4,"0000")) | B5: 45981 | C5: PRJ-001 | D5: الموزع المعتمد للحديد | E5: MAR-0001 | F5: =IF(E5="","",IFERROR(INDEX('اعتماد المواد'!$P$5:$P$304,MATCH(E5,'اعتماد المواد'!$A$5:$A$304,0)),"")) | G5: STL-16 | H5: حديد تسليح قطر 16 مم | I5: طن | J5: 120 | K5: 38500 | L5: =IF(J5="","",J5*K5) | M5: =IF(L5="","",L5*S_VAT) | N5: =IF(L5="","",L5+M5) | O5: 45996 | P5: =IF(A5="","",SUMIFS('استلام المواد'!$K$5:$K$304,'استلام المواد'!$C$5:$C$304,A5)) | Q5: =IF(A5="","",J5-P5) | R5: =IF(A5="","",IF(F5="لا","مادة غير معتمدة!",IF(P5>=J5,"مكتمل",IF(AND(O5<>"",TODAY()>O5),"متأخر التوريد",IF(P5>0,"توريد جزئي","لم يُورد بعد")))))
A6: =IF(C6="","","PO-"&TEXT(ROW()-4,"0000")) | B6: 45987 | C6: PRJ-001 | D6: مؤسسة مواد البناء | E6: MAR-0002 | F6: =IF(E6="","",IFERROR(INDEX('اعتماد المواد'!$P$5:$P$304,MATCH(E6,'اعتماد المواد'!$A$5:$A$304,0)),"")) | G6: CEM-425 | H6: أسمنت بورتلاندي 42.5N | I6: شيكارة | J6: 4000 | K6: 210 | L6: =IF(J6="","",J6*K6) | M6: =IF(L6="","",L6*S_VAT) | N6: =IF(L6="","",L6+M6) | O6: 46001 | P6: =IF(A6="","",SUMIFS('استلام المواد'!$K$5:$K$304,'استلام المواد'!$C$5:$C$304,A6)) | Q6: =IF(A6="","",J6-P6) | R6: =IF(A6="","",IF(F6="لا","مادة غير معتمدة!",IF(P6>=J6,"مكتمل",IF(AND(O6<>"",TODAY()>O6),"متأخر التوريد",IF(P6>0,"توريد جزئي","لم يُورد بعد")))))
A7: =IF(C7="","","PO-"&TEXT(ROW()-4,"0000")) | B7: 46178 | C7: PRJ-002 | D7: شركة الخرسانة الجاهزة | E7: MAR-0004 | F7: =IF(E7="","",IFERROR(INDEX('اعتماد المواد'!$P$5:$P$304,MATCH(E7,'اعتماد المواد'!$A$5:$A$304,0)),"")) | G7: RMC-C30 | H7: خرسانة جاهزة C30 | I7: م3 | J7: 850 | K7: 2650 | L7: =IF(J7="","",J7*K7) | M7: =IF(L7="","",L7*S_VAT) | N7: =IF(L7="","",L7+M7) | O7: 46325 | P7: =IF(A7="","",SUMIFS('استلام المواد'!$K$5:$K$304,'استلام المواد'!$C$5:$C$304,A7)) | Q7: =IF(A7="","",J7-P7) | R7: =IF(A7="","",IF(F7="لا","مادة غير معتمدة!",IF(P7>=J7,"مكتمل",IF(AND(O7<>"",TODAY()>O7),"متأخر التوريد",IF(P7>0,"توريد جزئي","لم يُورد بعد")))))
A8: =IF(C8="","","PO-"&TEXT(ROW()-4,"0000")) | F8: =IF(E8="","",IFERROR(INDEX('اعتماد المواد'!$P$5:$P$304,MATCH(E8,'اعتماد المواد'!$A$5:$A$304,0)),"")) | L8: =IF(J8="","",J8*K8) | M8: =IF(L8="","",L8*S_VAT) | N8: =IF(L8="","",L8+M8) | P8: =IF(A8="","",SUMIFS('استلام المواد'!$K$5:$K$304,'استلام المواد'!$C$5:$C$304,A8)) | Q8: =IF(A8="","",J8-P8) | R8: =IF(A8="","",IF(F8="لا","مادة غير معتمدة!",IF(P8>=J8,"مكتمل",IF(AND(O8<>"",TODAY()>O8),"متأخر التوريد",IF(P8>0,"توريد جزئي","لم يُورد بعد")))))
A9: =IF(C9="","","PO-"&TEXT(ROW()-4,"0000")) | F9: =IF(E9="","",IFERROR(INDEX('اعتماد المواد'!$P$5:$P$304,MATCH(E9,'اعتماد المواد'!$A$5:$A$304,0)),"")) | L9: =IF(J9="","",J9*K9) | M9: =IF(L9="","",L9*S_VAT) | N9: =IF(L9="","",L9+M9) | P9: =IF(A9="","",SUMIFS('استلام المواد'!$K$5:$K$304,'استلام المواد'!$C$5:$C$304,A9)) | Q9: =IF(A9="","",J9-P9) | R9: =IF(A9="","",IF(F9="لا","مادة غير معتمدة!",IF(P9>=J9,"مكتمل",IF(AND(O9<>"",TODAY()>O9),"متأخر التوريد",IF(P9>0,"توريد جزئي","لم يُورد بعد")))))
A10: =IF(C10="","","PO-"&TEXT(ROW()-4,"0000")) | F10: =IF(E10="","",IFERROR(INDEX('اعتماد المواد'!$P$5:$P$304,MATCH(E10,'اعتماد المواد'!$A$5:$A$304,0)),"")) | L10: =IF(J10="","",J10*K10) | M10: =IF(L10="","",L10*S_VAT) | N10: =IF(L10="","",L10+M10) | P10: =IF(A10="","",SUMIFS('استلام المواد'!$K$5:$K$304,'استلام المواد'!$C$5:$C$304,A10)) | Q10: =IF(A10="","",J10-P10) | R10: =IF(A10="","",IF(F10="لا","مادة غير معتمدة!",IF(P10>=J10,"مكتمل",IF(AND(O10<>"",TODAY()>O10),"متأخر التوريد",IF(P10>0,"توريد جزئي","لم يُورد بعد")))))
A11: =IF(C11="","","PO-"&TEXT(ROW()-4,"0000")) | F11: =IF(E11="","",IFERROR(INDEX('اعتماد المواد'!$P$5:$P$304,MATCH(E11,'اعتماد المواد'!$A$5:$A$304,0)),"")) | L11: =IF(J11="","",J11*K11) | M11: =IF(L11="","",L11*S_VAT) | N11: =IF(L11="","",L11+M11) | P11: =IF(A11="","",SUMIFS('استلام المواد'!$K$5:$K$304,'استلام المواد'!$C$5:$C$304,A11)) | Q11: =IF(A11="","",J11-P11) | R11: =IF(A11="","",IF(F11="لا","مادة غير معتمدة!",IF(P11>=J11,"مكتمل",IF(AND(O11<>"",TODAY()>O11),"متأخر التوريد",IF(P11>0,"توريد جزئي","لم يُورد بعد")))))
A12: =IF(C12="","","PO-"&TEXT(ROW()-4,"0000")) | F12: =IF(E12="","",IFERROR(INDEX('اعتماد المواد'!$P$5:$P$304,MATCH(E12,'اعتماد المواد'!$A$5:$A$304,0)),"")) | L12: =IF(J12="","",J12*K12) | M12: =IF(L12="","",L12*S_VAT) | N12: =IF(L12="","",L12+M12) | P12: =IF(A12="","",SUMIFS('استلام المواد'!$K$5:$K$304,'استلام المواد'!$C$5:$C$304,A12)) | Q12: =IF(A12="","",J12-P12) | R12: =IF(A12="","",IF(F12="لا","مادة غير معتمدة!",IF(P12>=J12,"مكتمل",IF(AND(O12<>"",TODAY()>O12),"متأخر التوريد",IF(P12>0,"توريد جزئي","لم يُورد بعد")))))
A13: =IF(C13="","","PO-"&TEXT(ROW()-4,"0000")) | F13: =IF(E13="","",IFERROR(INDEX('اعتماد المواد'!$P$5:$P$304,MATCH(E13,'اعتماد المواد'!$A$5:$A$304,0)),"")) | L13: =IF(J13="","",J13*K13) | M13: =IF(L13="","",L13*S_VAT) | N13: =IF(L13="","",L13+M13) | P13: =IF(A13="","",SUMIFS('استلام المواد'!$K$5:$K$304,'استلام المواد'!$C$5:$C$304,A13)) | Q13: =IF(A13="","",J13-P13) | R13: =IF(A13="","",IF(F13="لا","مادة غير معتمدة!",IF(P13>=J13,"مكتمل",IF(AND(O13<>"",TODAY()>O13),"متأخر التوريد",IF(P13>0,"توريد جزئي","لم يُورد بعد")))))
A14: =IF(C14="","","PO-"&TEXT(ROW()-4,"0000")) | F14: =IF(E14="","",IFERROR(INDEX('اعتماد المواد'!$P$5:$P$304,MATCH(E14,'اعتماد المواد'!$A$5:$A$304,0)),"")) | L14: =IF(J14="","",J14*K14) | M14: =IF(L14="","",L14*S_VAT) | N14: =IF(L14="","",L14+M14) | P14: =IF(A14="","",SUMIFS('استلام المواد'!$K$5:$K$304,'استلام المواد'!$C$5:$C$304,A14)) | Q14: =IF(A14="","",J14-P14) | R14: =IF(A14="","",IF(F14="لا","مادة غير معتمدة!",IF(P14>=J14,"مكتمل",IF(AND(O14<>"",TODAY()>O14),"متأخر التوريد",IF(P14>0,"توريد جزئي","لم يُورد بعد")))))
A15: =IF(C15="","","PO-"&TEXT(ROW()-4,"0000")) | F15: =IF(E15="","",IFERROR(INDEX('اعتماد المواد'!$P$5:$P$304,MATCH(E15,'اعتماد المواد'!$A$5:$A$304,0)),"")) | L15: =IF(J15="","",J15*K15) | M15: =IF(L15="","",L15*S_VAT) | N15: =IF(L15="","",L15+M15) | P15: =IF(A15="","",SUMIFS('استلام المواد'!$K$5:$K$304,'استلام المواد'!$C$5:$C$304,A15)) | Q15: =IF(A15="","",J15-P15) | R15: =IF(A15="","",IF(F15="لا","مادة غير معتمدة!",IF(P15>=J15,"مكتمل",IF(AND(O15<>"",TODAY()>O15),"متأخر التوريد",IF(P15>0,"توريد جزئي","لم يُورد بعد")))))
A16: =IF(C16="","","PO-"&TEXT(ROW()-4,"0000")) | F16: =IF(E16="","",IFERROR(INDEX('اعتماد المواد'!$P$5:$P$304,MATCH(E16,'اعتماد المواد'!$A$5:$A$304,0)),"")) | L16: =IF(J16="","",J16*K16) | M16: =IF(L16="","",L16*S_VAT) | N16: =IF(L16="","",L16+M16) | P16: =IF(A16="","",SUMIFS('استلام المواد'!$K$5:$K$304,'استلام المواد'!$C$5:$C$304,A16)) | Q16: =IF(A16="","",J16-P16) | R16: =IF(A16="","",IF(F16="لا","مادة غير معتمدة!",IF(P16>=J16,"مكتمل",IF(AND(O16<>"",TODAY()>O16),"متأخر التوريد",IF(P16>0,"توريد جزئي","لم يُورد بعد")))))
A17: =IF(C17="","","PO-"&TEXT(ROW()-4,"0000")) | F17: =IF(E17="","",IFERROR(INDEX('اعتماد المواد'!$P$5:$P$304,MATCH(E17,'اعتماد المواد'!$A$5:$A$304,0)),"")) | L17: =IF(J17="","",J17*K17) | M17: =IF(L17="","",L17*S_VAT) | N17: =IF(L17="","",L17+M17) | P17: =IF(A17="","",SUMIFS('استلام المواد'!$K$5:$K$304,'استلام المواد'!$C$5:$C$304,A17)) | Q17: =IF(A17="","",J17-P17) | R17: =IF(A17="","",IF(F17="لا","مادة غير معتمدة!",IF(P17>=J17,"مكتمل",IF(AND(O17<>"",TODAY()>O17),"متأخر التوريد",IF(P17>0,"توريد جزئي","لم يُورد بعد")))))
A18: =IF(C18="","","PO-"&TEXT(ROW()-4,"0000")) | F18: =IF(E18="","",IFERROR(INDEX('اعتماد المواد'!$P$5:$P$304,MATCH(E18,'اعتماد المواد'!$A$5:$A$304,0)),"")) | L18: =IF(J18="","",J18*K18) | M18: =IF(L18="","",L18*S_VAT) | N18: =IF(L18="","",L18+M18) | P18: =IF(A18="","",SUMIFS('استلام المواد'!$K$5:$K$304,'استلام المواد'!$C$5:$C$304,A18)) | Q18: =IF(A18="","",J18-P18) | R18: =IF(A18="","",IF(F18="لا","مادة غير معتمدة!",IF(P18>=J18,"مكتمل",IF(AND(O18<>"",TODAY()>O18),"متأخر التوريد",IF(P18>0,"توريد جزئي","لم يُورد بعد")))))
A19: =IF(C19="","","PO-"&TEXT(ROW()-4,"0000")) | F19: =IF(E19="","",IFERROR(INDEX('اعتماد المواد'!$P$5:$P$304,MATCH(E19,'اعتماد المواد'!$A$5:$A$304,0)),"")) | L19: =IF(J19="","",J19*K19) | M19: =IF(L19="","",L19*S_VAT) | N19: =IF(L19="","",L19+M19) | P19: =IF(A19="","",SUMIFS('استلام المواد'!$K$5:$K$304,'استلام المواد'!$C$5:$C$304,A19)) | Q19: =IF(A19="","",J19-P19) | R19: =IF(A19="","",IF(F19="لا","مادة غير معتمدة!",IF(P19>=J19,"مكتمل",IF(AND(O19<>"",TODAY()>O19),"متأخر التوريد",IF(P19>0,"توريد جزئي","لم يُورد بعد")))))
... A304: =IF(C304="","","PO-"&TEXT(ROW()-4,"0000")) | F304: =IF(E304="","",IFERROR(INDEX('اعتماد المواد'!$P$5:$P$304,MATCH(E304,'اعتماد المواد'!$A$5:$A$304,0)),"")) | L304: =IF(J304="","",J304*K304) | M304: =IF(L304="","",L304*S_VAT) | N304: =IF(L304="","",L304+M304) | P304: =IF(A304="","",SUMIFS('استلام المواد'!$K$5:$K$304,'استلام المواد'!$C$5:$C$304,A304)) | Q304: =IF(A304="","",J304-P304) | R304: =IF(A304="","",IF(F304="لا","مادة غير معتمدة!",IF(P304>=J304,"مكتمل",IF(AND(O304<>"",TODAY()>O304),"متأخر التوريد",IF(P304>0,"توريد جزئي","لم يُورد بعد")))))

Sheet استلام المواد
A1: =S_Company&" | استلام المواد"
A2: محاضر استلام وفحص المواد بالموقع MIR (QF-MR-05)
A3: ↩ الرئيسية | B3: ■ أصفر = إدخال يدوي ■ رمادي = معادلة تلقائية (لا تكتب فيها) — الصفوف الأولى أمثلة توضيحية؛ احذف قيم الإدخال واستبدلها ببياناتك
A4: رقم المحضر | B4: تاريخ الاستلام | C4: رقم أمر التوريد | D4: كود المشروع | E4: رقم الاعتماد | F4: كود الصنف | G4: الصنف | H4: الوحدة | I4: رقم إذن تسليم المورد | J4: الكمية الواردة | K4: الكمية المقبولة | L4: المرفوضة | M4: النتيجة | N4: سبب الرفض / ملاحظات | O4: أمين المخزن
A5: =IF(C5="","","MIR-"&TEXT(ROW()-4,"0000")) | B5: 45994 | C5: PO-0001 | D5: =IF(C5="","",IFERROR(INDEX('أوامر التوريد'!$C$5:$C$304,MATCH(C5,'أوامر التوريد'!$A$5:$A$304,0)),"")) | E5: =IF(C5="","",IFERROR(INDEX('أوامر التوريد'!$E$5:$E$304,MATCH(C5,'أوامر التوريد'!$A$5:$A$304,0)),"")) | F5: =IF(C5="","",IFERROR(INDEX('أوامر التوريد'!$G$5:$G$304,MATCH(C5,'أوامر التوريد'!$A$5:$A$304,0)),"")) | G5: =IF(C5="","",IFERROR(INDEX('أوامر التوريد'!$H$5:$H$304,MATCH(C5,'أوامر التوريد'!$A$5:$A$304,0)),"")) | H5: =IF(C5="","",IFERROR(INDEX('أوامر التوريد'!$I$5:$I$304,MATCH(C5,'أوامر التوريد'!$A$5:$A$304,0)),"")) | I5: DN-5521 | J5: 80 | K5: 80 | L5: =IF(J5="","",J5-K5) | M5: =IF(J5="","",IF(K5=0,"مرفوض",IF(K5<J5,"مقبول جزئياً","مقبول"))) | O5: أمين مخزن الموقع
A6: =IF(C6="","","MIR-"&TEXT(ROW()-4,"0000")) | B6: 46003 | C6: PO-0001 | D6: =IF(C6="","",IFERROR(INDEX('أوامر التوريد'!$C$5:$C$304,MATCH(C6,'أوامر التوريد'!$A$5:$A$304,0)),"")) | E6: =IF(C6="","",IFERROR(INDEX('أوامر التوريد'!$E$5:$E$304,MATCH(C6,'أوامر التوريد'!$A$5:$A$304,0)),"")) | F6: =IF(C6="","",IFERROR(INDEX('أوامر التوريد'!$G$5:$G$304,MATCH(C6,'أوامر التوريد'!$A$5:$A$304,0)),"")) | G6: =IF(C6="","",IFERROR(INDEX('أوامر التوريد'!$H$5:$H$304,MATCH(C6,'أوامر التوريد'!$A$5:$A$304,0)),"")) | H6: =IF(C6="","",IFERROR(INDEX('أوامر التوريد'!$I$5:$I$304,MATCH(C6,'أوامر التوريد'!$A$5:$A$304,0)),"")) | I6: DN-5610 | J6: 42 | K6: 40 | L6: =IF(J6="","",J6-K6) | M6: =IF(J6="","",IF(K6=0,"مرفوض",IF(K6<J6,"مقبول جزئياً","مقبول"))) | N6: 2 طن صدأ سطحي شديد | O6: أمين مخزن الموقع
A7: =IF(C7="","","MIR-"&TEXT(ROW()-4,"0000")) | B7: 45999 | C7: PO-0002 | D7: =IF(C7="","",IFERROR(INDEX('أوامر التوريد'!$C$5:$C$304,MATCH(C7,'أوامر التوريد'!$A$5:$A$304,0)),"")) | E7: =IF(C7="","",IFERROR(INDEX('أوامر التوريد'!$E$5:$E$304,MATCH(C7,'أوامر التوريد'!$A$5:$A$304,0)),"")) | F7: =IF(C7="","",IFERROR(INDEX('أوامر التوريد'!$G$5:$G$304,MATCH(C7,'أوامر التوريد'!$A$5:$A$304,0)),"")) | G7: =IF(C7="","",IFERROR(INDEX('أوامر التوريد'!$H$5:$H$304,MATCH(C7,'أوامر التوريد'!$A$5:$A$304,0)),"")) | H7: =IF(C7="","",IFERROR(INDEX('أوامر التوريد'!$I$5:$I$304,MATCH(C7,'أوامر التوريد'!$A$5:$A$304,0)),"")) | I7: C-889 | J7: 4000 | K7: 4000 | L7: =IF(J7="","",J7-K7) | M7: =IF(J7="","",IF(K7=0,"مرفوض",IF(K7<J7,"مقبول جزئياً","مقبول"))) | O7: أمين مخزن الموقع
A8: =IF(C8="","","MIR-"&TEXT(ROW()-4,"0000")) | B8: 46193 | C8: PO-0003 | D8: =IF(C8="","",IFERROR(INDEX('أوامر التوريد'!$C$5:$C$304,MATCH(C8,'أوامر التوريد'!$A$5:$A$304,0)),"")) | E8: =IF(C8="","",IFERROR(INDEX('أوامر التوريد'!$E$5:$E$304,MATCH(C8,'أوامر التوريد'!$A$5:$A$304,0)),"")) | F8: =IF(C8="","",IFERROR(INDEX('أوامر التوريد'!$G$5:$G$304,MATCH(C8,'أوامر التوريد'!$A$5:$A$304,0)),"")) | G8: =IF(C8="","",IFERROR(INDEX('أوامر التوريد'!$H$5:$H$304,MATCH(C8,'أوامر التوريد'!$A$5:$A$304,0)),"")) | H8: =IF(C8="","",IFERROR(INDEX('أوامر التوريد'!$I$5:$I$304,MATCH(C8,'أوامر التوريد'!$A$5:$A$304,0)),"")) | I8: RM-3310 | J8: 320 | K8: 320 | L8: =IF(J8="","",J8-K8) | M8: =IF(J8="","",IF(K8=0,"مرفوض",IF(K8<J8,"مقبول جزئياً","مقبول"))) | O8: أمين مخزن الموقع
A9: =IF(C9="","","MIR-"&TEXT(ROW()-4,"0000")) | D9: =IF(C9="","",IFERROR(INDEX('أوامر التوريد'!$C$5:$C$304,MATCH(C9,'أوامر التوريد'!$A$5:$A$304,0)),"")) | E9: =IF(C9="","",IFERROR(INDEX('أوامر التوريد'!$E$5:$E$304,MATCH(C9,'أوامر التوريد'!$A$5:$A$304,0)),"")) | F9: =IF(C9="","",IFERROR(INDEX('أوامر التوريد'!$G$5:$G$304,MATCH(C9,'أوامر التوريد'!$A$5:$A$304,0)),"")) | G9: =IF(C9="","",IFERROR(INDEX('أوامر التوريد'!$H$5:$H$304,MATCH(C9,'أوامر التوريد'!$A$5:$A$304,0)),"")) | H9: =IF(C9="","",IFERROR(INDEX('أوامر التوريد'!$I$5:$I$304,MATCH(C9,'أوامر التوريد'!$A$5:$A$304,0)),"")) | L9: =IF(J9="","",J9-K9) | M9: =IF(J9="","",IF(K9=0,"مرفوض",IF(K9<J9,"مقبول جزئياً","مقبول")))
A10: =IF(C10="","","MIR-"&TEXT(ROW()-4,"0000")) | D10: =IF(C10="","",IFERROR(INDEX('أوامر التوريد'!$C$5:$C$304,MATCH(C10,'أوامر التوريد'!$A$5:$A$304,0)),"")) | E10: =IF(C10="","",IFERROR(INDEX('أوامر التوريد'!$E$5:$E$304,MATCH(C10,'أوامر التوريد'!$A$5:$A$304,0)),"")) | F10: =IF(C10="","",IFERROR(INDEX('أوامر التوريد'!$G$5:$G$304,MATCH(C10,'أوامر التوريد'!$A$5:$A$304,0)),"")) | G10: =IF(C10="","",IFERROR(INDEX('أوامر التوريد'!$H$5:$H$304,MATCH(C10,'أوامر التوريد'!$A$5:$A$304,0)),"")) | H10: =IF(C10="","",IFERROR(INDEX('أوامر التوريد'!$I$5:$I$304,MATCH(C10,'أوامر التوريد'!$A$5:$A$304,0)),"")) | L10: =IF(J10="","",J10-K10) | M10: =IF(J10="","",IF(K10=0,"مرفوض",IF(K10<J10,"مقبول جزئياً","مقبول")))
A11: =IF(C11="","","MIR-"&TEXT(ROW()-4,"0000")) | D11: =IF(C11="","",IFERROR(INDEX('أوامر التوريد'!$C$5:$C$304,MATCH(C11,'أوامر التوريد'!$A$5:$A$304,0)),"")) | E11: =IF(C11="","",IFERROR(INDEX('أوامر التوريد'!$E$5:$E$304,MATCH(C11,'أوامر التوريد'!$A$5:$A$304,0)),"")) | F11: =IF(C11="","",IFERROR(INDEX('أوامر التوريد'!$G$5:$G$304,MATCH(C11,'أوامر التوريد'!$A$5:$A$304,0)),"")) | G11: =IF(C11="","",IFERROR(INDEX('أوامر التوريد'!$H$5:$H$304,MATCH(C11,'أوامر التوريد'!$A$5:$A$304,0)),"")) | H11: =IF(C11="","",IFERROR(INDEX('أوامر التوريد'!$I$5:$I$304,MATCH(C11,'أوامر التوريد'!$A$5:$A$304,0)),"")) | L11: =IF(J11="","",J11-K11) | M11: =IF(J11="","",IF(K11=0,"مرفوض",IF(K11<J11,"مقبول جزئياً","مقبول")))
A12: =IF(C12="","","MIR-"&TEXT(ROW()-4,"0000")) | D12: =IF(C12="","",IFERROR(INDEX('أوامر التوريد'!$C$5:$C$304,MATCH(C12,'أوامر التوريد'!$A$5:$A$304,0)),"")) | E12: =IF(C12="","",IFERROR(INDEX('أوامر التوريد'!$E$5:$E$304,MATCH(C12,'أوامر التوريد'!$A$5:$A$304,0)),"")) | F12: =IF(C12="","",IFERROR(INDEX('أوامر التوريد'!$G$5:$G$304,MATCH(C12,'أوامر التوريد'!$A$5:$A$304,0)),"")) | G12: =IF(C12="","",IFERROR(INDEX('أوامر التوريد'!$H$5:$H$304,MATCH(C12,'أوامر التوريد'!$A$5:$A$304,0)),"")) | H12: =IF(C12="","",IFERROR(INDEX('أوامر التوريد'!$I$5:$I$304,MATCH(C12,'أوامر التوريد'!$A$5:$A$304,0)),"")) | L12: =IF(J12="","",J12-K12) | M12: =IF(J12="","",IF(K12=0,"مرفوض",IF(K12<J12,"مقبول جزئياً","مقبول")))
A13: =IF(C13="","","MIR-"&TEXT(ROW()-4,"0000")) | D13: =IF(C13="","",IFERROR(INDEX('أوامر التوريد'!$C$5:$C$304,MATCH(C13,'أوامر التوريد'!$A$5:$A$304,0)),"")) | E13: =IF(C13="","",IFERROR(INDEX('أوامر التوريد'!$E$5:$E$304,MATCH(C13,'أوامر التوريد'!$A$5:$A$304,0)),"")) | F13: =IF(C13="","",IFERROR(INDEX('أوامر التوريد'!$G$5:$G$304,MATCH(C13,'أوامر التوريد'!$A$5:$A$304,0)),"")) | G13: =IF(C13="","",IFERROR(INDEX('أوامر التوريد'!$H$5:$H$304,MATCH(C13,'أوامر التوريد'!$A$5:$A$304,0)),"")) | H13: =IF(C13="","",IFERROR(INDEX('أوامر التوريد'!$I$5:$I$304,MATCH(C13,'أوامر التوريد'!$A$5:$A$304,0)),"")) | L13: =IF(J13="","",J13-K13) | M13: =IF(J13="","",IF(K13=0,"مرفوض",IF(K13<J13,"مقبول جزئياً","مقبول")))
A14: =IF(C14="","","MIR-"&TEXT(ROW()-4,"0000")) | D14: =IF(C14="","",IFERROR(INDEX('أوامر التوريد'!$C$5:$C$304,MATCH(C14,'أوامر التوريد'!$A$5:$A$304,0)),"")) | E14: =IF(C14="","",IFERROR(INDEX('أوامر التوريد'!$E$5:$E$304,MATCH(C14,'أوامر التوريد'!$A$5:$A$304,0)),"")) | F14: =IF(C14="","",IFERROR(INDEX('أوامر التوريد'!$G$5:$G$304,MATCH(C14,'أوامر التوريد'!$A$5:$A$304,0)),"")) | G14: =IF(C14="","",IFERROR(INDEX('أوامر التوريد'!$H$5:$H$304,MATCH(C14,'أوامر التوريد'!$A$5:$A$304,0)),"")) | H14: =IF(C14="","",IFERROR(INDEX('أوامر التوريد'!$I$5:$I$304,MATCH(C14,'أوامر التوريد'!$A$5:$A$304,0)),"")) | L14: =IF(J14="","",J14-K14) | M14: =IF(J14="","",IF(K14=0,"مرفوض",IF(K14<J14,"مقبول جزئياً","مقبول")))
A15: =IF(C15="","","MIR-"&TEXT(ROW()-4,"0000")) | D15: =IF(C15="","",IFERROR(INDEX('أوامر التوريد'!$C$5:$C$304,MATCH(C15,'أوامر التوريد'!$A$5:$A$304,0)),"")) | E15: =IF(C15="","",IFERROR(INDEX('أوامر التوريد'!$E$5:$E$304,MATCH(C15,'أوامر التوريد'!$A$5:$A$304,0)),"")) | F15: =IF(C15="","",IFERROR(INDEX('أوامر التوريد'!$G$5:$G$304,MATCH(C15,'أوامر التوريد'!$A$5:$A$304,0)),"")) | G15: =IF(C15="","",IFERROR(INDEX('أوامر التوريد'!$H$5:$H$304,MATCH(C15,'أوامر التوريد'!$A$5:$A$304,0)),"")) | H15: =IF(C15="","",IFERROR(INDEX('أوامر التوريد'!$I$5:$I$304,MATCH(C15,'أوامر التوريد'!$A$5:$A$304,0)),"")) | L15: =IF(J15="","",J15-K15) | M15: =IF(J15="","",IF(K15=0,"مرفوض",IF(K15<J15,"مقبول جزئياً","مقبول")))
A16: =IF(C16="","","MIR-"&TEXT(ROW()-4,"0000")) | D16: =IF(C16="","",IFERROR(INDEX('أوامر التوريد'!$C$5:$C$304,MATCH(C16,'أوامر التوريد'!$A$5:$A$304,0)),"")) | E16: =IF(C16="","",IFERROR(INDEX('أوامر التوريد'!$E$5:$E$304,MATCH(C16,'أوامر التوريد'!$A$5:$A$304,0)),"")) | F16: =IF(C16="","",IFERROR(INDEX('أوامر التوريد'!$G$5:$G$304,MATCH(C16,'أوامر التوريد'!$A$5:$A$304,0)),"")) | G16: =IF(C16="","",IFERROR(INDEX('أوامر التوريد'!$H$5:$H$304,MATCH(C16,'أوامر التوريد'!$A$5:$A$304,0)),"")) | H16: =IF(C16="","",IFERROR(INDEX('أوامر التوريد'!$I$5:$I$304,MATCH(C16,'أوامر التوريد'!$A$5:$A$304,0)),"")) | L16: =IF(J16="","",J16-K16) | M16: =IF(J16="","",IF(K16=0,"مرفوض",IF(K16<J16,"مقبول جزئياً","مقبول")))
A17: =IF(C17="","","MIR-"&TEXT(ROW()-4,"0000")) | D17: =IF(C17="","",IFERROR(INDEX('أوامر التوريد'!$C$5:$C$304,MATCH(C17,'أوامر التوريد'!$A$5:$A$304,0)),"")) | E17: =IF(C17="","",IFERROR(INDEX('أوامر التوريد'!$E$5:$E$304,MATCH(C17,'أوامر التوريد'!$A$5:$A$304,0)),"")) | F17: =IF(C17="","",IFERROR(INDEX('أوامر التوريد'!$G$5:$G$304,MATCH(C17,'أوامر التوريد'!$A$5:$A$304,0)),"")) | G17: =IF(C17="","",IFERROR(INDEX('أوامر التوريد'!$H$5:$H$304,MATCH(C17,'أوامر التوريد'!$A$5:$A$304,0)),"")) | H17: =IF(C17="","",IFERROR(INDEX('أوامر التوريد'!$I$5:$I$304,MATCH(C17,'أوامر التوريد'!$A$5:$A$304,0)),"")) | L17: =IF(J17="","",J17-K17) | M17: =IF(J17="","",IF(K17=0,"مرفوض",IF(K17<J17,"مقبول جزئياً","مقبول")))
